Workbook

Sheet Unplanned leaves
A1: Total Leaves | B1: =SUM(B21:F21) -> 4
B2: Resource Name
A3: Sprint | B3: Prisla Sabatini | C3: Mahesh Muppala | D3: Nithish Manian | E3: Vinoth Vedapuri | F3: Aravindh Jayapal | G3: Remarks
A4: 26.3 DS Sprint 3(6-Feb-2026 to 19-Feb-2026) | B4: 0 | C4: 0 | D4: 0 | E4: 0 | F4: 0
A5: 26.4 DS Sprint 1(20-Feb-2026 to 05-Mar-2026) | B5: 0 | C5: 0 | D5: 0 | E5: 0 | F5: 0
A6: 26.4 DS Sprint 2(06-Mar-2026 to 19-Mar-2026) | B6: 1 | C6: 0 | D6: 0 | E6: 0 | F6: 0
A7: 26.4 DS Sprint 3(20-Mar-2026 to 02-Apr-2026) | B7: 0 | C7: 0 | D7: 1 | E7: 0 | F7: 0
A8: 26.5 DS Sprint 1(03-Apr-2026 to 16-Apr-2026) | B8: 0 | C8: 0 | D8: 0 | E8: 0 | F8: 0
A9: 26.5 DS Sprint 2(17-Apr-2026 to 30-Apr-2026) | B9: 0 | C9: 0 | D9: 0 | E9: 0 | F9: 0
A10: 26.5 DS Sprint 3(01-May-2026 to 14-May-2026) | B10: 1 | C10: 0 | D10: 0 | E10: 0 | F10: 0
A11: 26.7 DS Sprint 1(15-May-2026 to 28-May-2026) | B11: 0 | C11: 0 | D11: 0 | E11: 1 | F11: 0
A21: Total | B21: =SUM(B4:B20) -> 2 | C21: =SUM(C4:C20) -> 0 | D21: =SUM(D4:D20) -> 1 | E21: =SUM(E4:E20) -> 1 | F21: =SUM(F4:F20) -> 0

Sheet Dashboard
A1: Current Sprint | B1: {=INDEX($B$2:$B$101,MATCH(1,(($D$2:$D$101 >=TODAY())*($C$2:$C$101<=TODAY())),0))} -> 26.7 DS Sprint 1 | C1: Current Sprint Sheet | D1: =CONCATENATE(B1,"-Status") -> 26.7 DS Sprint 1-Status | E1: Sprint Start Date | F1: =VLOOKUP($B$1,$B$1:$C$101,2) -> 46157 | G1: Sprint End Date | H1: =VLOOKUP($B$1,$B$1:$D$101,3) -> 46170 | I1: Application Name | J1: MSB Dev | K1: Users | L1: prislasabatini.irudayaraj@relevantz.com;mahesh.chandrasekharraju@relevantz.com;aravindh.jayapal@relevantz.com;nithish.manian@relevantz.com;vinothkumar.vedapuri@relevantz.com | M1: Teams Name(GP-MSB.PartnerIntegrations (PI)) | N1: 19:bd003fe8174540cbb372a488e0fe06dd@thread.v2
A2: Sprint Type | B2: Sprint # | C2: Sprint Start Date | D2: Sprint End Date | E2: Assigned | F2: Completed | G2: Story points introduced/removed | H2: Sprint Summary | I2: Accomplishments | J2: Remarks | K2: Retro Points (Internal & External) | L2: Unplanned Leaves | M2: Data sanity Audit Status | N2: AuditDate | O2: Backlog Health
A3: =IF(AND($D$1>=C3,$D$1<=D3),"CurrentSprint","NA") -> NA | B3: 13.5 DS Sprint 2 | C3: 45303 | D3: 45316 | E3: 20 | F3: 21 | J3: Stretch Story completed with points - 1 | K3: Internal: External:
A4: =IF(AND($D$1>=C4,$D$1<=D4),"CurrentSprint","NA") -> NA | B4: 13.5 DS Sprint 3 | C4: 45317 | D4: 45330 | E4: 31 | F4: 30 | J4: Stretch Story completed with points - 2 | K4: Internal: External:
A5: =IF(AND($D$1>=C5,$D$1<=D5),"CurrentSprint","NA") -> NA | B5: 13.6 DS Sprint 1 | C5: 45331 | D5: 45344 | E5: 33 | F5: 33 | G5: 26sp - On Hold | J5: Two 13 sp Stories went on Hold [Epic story splitted into 6 stories from client side] | K5: Internal: External:
A6: =IF(AND($D$1>=C6,$D$1<=D6),"CurrentSprint","NA") -> NA | B6: 13.6 DS Sprint 2 | C6: 45345 | D6: 45358 | E6: 35 | F6: 22 | J6: Development completed and Testing is inprogress (Story-43092 with 13sp) | K6: Internal: External:
A7: =IF(AND($D$1>=C7,$D$1<=D7),"CurrentSprint","NA") -> NA | B7: 13.6 DS Sprint 3 | C7: 45359 | D7: 45372 | E7: 47 | F7: 47 | J7: Regression sprint | K7: Internal: External:
A8: =IF(AND($D$1>=C8,$D$1<=D8),"CurrentSprint","NA") -> NA | B8: 13.7 DS Sprint 1 | C8: 45373 | D8: 45386 | E8: 25 | F8: 10 | J8: Stretch Story completed with 2sp Development completed and Testing is inprogress (Story-43584 & 43693 with 16sp) Automation story was going to carry with 1sp | K8: Internal: External:
A9: =IF(AND($D$1>=C9,$D$1<=D9),"CurrentSprint","NA") -> NA | B9: 13.7 DS Sprint 2 | C9: 45387 | D9: 45400 | E9: 26 | F9: 21 | G9: 5sp - On Hold | J9: Stretch Stories completed with 7sp 5sp story is on hold [Development completed and not able to test because Destiny(Vendor) side getting error for refund payments] | K9: Internal: External:
A10: =IF(AND($D$1>=C10,$D$1<=D10),"CurrentSprint","NA") -> NA | B10: 13.7 DS Sprint 3 | C10: 45401 | D10: 45414 | E10: 43 | F10: 29 | G10: 9-SP Stretch | J10: Regression sprint. Stretch Stories completed with 6sp. Regression story(QA) get carry forwarded with 20SP because new code build not yet deployed(May-1st) on Staging & Staging CA. New story 44472 was picked up on the last day of the sprint. | K10: Internal: External:
A11: =IF(AND($D$1>=C11,$D$1<=D11),"CurrentSprint","NA") -> NA | B11: 13.8 DS Sprint 1 | C11: 45415 | D11: 45428 | E11: 18 | F11: 23 | G11: 3 - SP On Hold 25 - SP Stretch | J11: 3sp story is on hold [The whole EPIC-43987 is going to revisit with new solution]. Stretch Stories: 8sp are completed 7sp are raised PR's (carry forwarded) 10sp are inprogress (carry forwarded) | K11: Internal: External:
A12: =IF(AND($D$1>=C12,$D$1<=D12),"CurrentSprint","NA") -> NA | B12: 13.8 DS Sprint 2 | C12: 45429 | D12: 45442 | E12: 31 | F12: 25 | G12: 9 - SP Stretch | J12: One committed story get carry forwarded with 8SP because client kept PR on hold and to revisit on API query with new pattern. Stretch Stories: 2sp are completed 3sp are Testing 4sp are inprogress (carry forwarded) | K12: Internal: External:
A13: =IF(AND($D$1>=C13,$D$1<=D13),"CurrentSprint","NA") -> NA | B13: 13.8 DS Sprint 3 | C13: 45443 | D13: 45456 | E13: 36 | F13: 36 | G13: 2- SP Strech On Hold | J13: Regression sprint. | K13: Internal: External:
A14: =IF(AND($D$1>=C14,$D$1<=D14),"CurrentSprint","NA") -> NA | B14: 14.0 DS Sprint 1 | C14: 45457 | D14: 45470 | E14: 29 | F14: 32 | G14: 7 - SP Stretch | J14: Stretch Stories: 45092 & 45127 Partially completed. Total 4SP carry forwarded. | K14: Internal: External:
A15: =IF(AND($D$1>=C15,$D$1<=D15),"CurrentSprint","NA") -> NA | B15: 14.0 DS Sprint 2 | C15: 45471 | D15: 45484 | E15: 27 | F15: 32 | G15: 16 - SP Stretch | J15: Stretch Stories: 5sp are completed 11sp are inprogress (carry forwarded) | K15: Internal: External:
A16: =IF(AND($D$1>=C16,$D$1<=D16),"CurrentSprint","NA") -> NA | B16: 14.0 DS Sprint 3 | C16: 45485 | D16: 45498 | E16: 40 | F16: 56 | G16: 24 - SP Stretch | J16: Regression sprint. Stretch Stories: 16sp are completed 8sp are inprogress (carry forwarded) | K16: Internal: External:
A17: =IF(AND($D$1>=C17,$D$1<=D17),"CurrentSprint","NA") -> NA | B17: 14.1 DS Sprint 1 | C17: 45499 | D17: 45512 | E17: 36 | F17: 41 | G17: 20 - SP Stretch | J17: Stretch Stories: 1) 5sp are completed 2) 13sp are Testing 3)2sp defect taken on last day of the sprint. We fixed and testing pending. | K17: Internal: External:
A18: =IF(AND($D$1>=C18,$D$1<=D18),"CurrentSprint","NA") -> NA | B18: 14.1 DS Sprint 2 | C18: 45513 | D18: 45526 | E18: 36 | F18: 49 | G18: 20 - SP Stretch | J18: Stretch Stories: 1) 13sp are completed 2) 7sp are inprogress | K18: Internal: External:
A19: =IF(AND($D$1>=C19,$D$1<=D19),"CurrentSprint","NA") -> NA | B19: 14.1 DS Sprint 3 | C19: 45527 | D19: 45540 | E19: 36 | F19: 23 | J19: Regression sprint. REgression story is carry forwarded due to hot fixes | K19: Internal: External:
A20: =IF(AND($D$1>=C20,$D$1<=D20),"CurrentSprint","NA") -> NA | B20: 14.2 DS Sprint 1 | C20: 45541 | D20: 45554 | E20: 28 | F20: 28 | G20: 13 - SP Stretch | J20: One committed story get carry forwarded with 8SP(Development completed and code merged, Only testing need to be done). Stretch Stories: 1) 8sp are completed 2) 5sp are inprogress (carry forwarded) | K20: Internal: External:
A21: =IF(AND($D$1>=C21,$D$1<=D21),"CurrentSprint","NA") -> NA | B21: 14.2 DS Sprint 2 | C21: 45555 | D21: 45568 | E21: 33 | F21: 22 | G21: 10 - SP Stretch | J21: Three committed story got carry forwarded with 16SP(1 story is on review with 5sp and 2 stories are on testing with 11sp) - Due to Hotfix Stretch Stories: 1) 5sp are Completed 2) 5sp are Testing (carry forwarded) Internal CRC - 2 External CRC - 3 QA Defects - 6 Escaped Defects - 0 | K21: Internal: External:
A22: =IF(AND($D$1>=C22,$D$1<=D22),"CurrentSprint","NA") -> NA | B22: 14.2 DS Sprint 3 | C22: 45569 | D22: 45582 | E22: 36 | F22: 41 | G22: Introduced - 5 | I22: Regression Sprint | J22: Regression sprint. Stretch Stories: 5sp are completed 7sp are PR's raised (carry forwarded) Internal CRC - 0 External CRC - 1 QA Defects - 4 Escaped Defects - 0 | K22: Internal: External:
A23: =IF(AND($D$1>=C23,$D$1<=D23),"CurrentSprint","NA") -> NA | B23: 14.3 DS Sprint 1 | C23: 45583 | D23: 45596 | E23: 23 | F23: 44 | G23: Introduced - 21 | I23: DataHub MSBP Api's | J23: Stretch Stories: 21sp are completed 2sp are Testing (carry forwarded) - Stretch 3sp are inprogress (carry forwarded) - Stretch Internal CRC - 0 External CRC - 3 QA Defects - 3 Escaped Defects - 7 | K23: Internal: External:
A24: =IF(AND($D$1>=C24,$D$1<=D24),"CurrentSprint","NA") -> NA | B24: 14.3 DS Sprint 2 | C24: 45597 | D24: 45610 | E24: 23 | F24: 18 | I24: MSB-Web UserHub DataHub | J24: One Story and One Defect is Carry Forwarded. Internal CRC - 0 External CRC - 0 QA Defects - 2 Escaped Defects - 1 | K24: Internal: External:
A25: =IF(AND($D$1>=C25,$D$1<=D25),"CurrentSprint","NA") -> NA | B25: 14.3 DS Sprint 3 | C25: 45611 | D25: 45624 | E25: 37 | F25: 39 | G25: Introduced - 7 | I25: Regression Sprint | J25: Regression sprint and One Story is Carry Forwarded. Stretch Stories: 7sp are completed Internal CRC - 0 External CRC - 0 QA Defects - 1 Escaped Defects -2 | K25: Internal: External:
A26: =IF(AND($D$1>=C26,$D$1<=D26),"CurrentSprint","NA") -> NA | B26: 14.4 DS Sprint 1 | C26: 45625 | D26: 45638 | E26: 21 | F26: 27 | G26: Introduced - 14 | I26: DataHub MSBP Api's Mobilepay Api's | J26: MSB DevServices team name got changed to MSB PartnerIntegrations (msb-pi) One committed story got carry forwarded with 8SP(Development completed and testing need to be done). Stretch Stories: 14sp are completed 13sp are Code Review (carry forwarded) - Stretch Internal CRC - 0 External CRC - 0 QA Defects - 1 Escaped Defects - 4 | K26: Internal: External:
A27: =IF(AND($D$1>=C27,$D$1<=D27),"CurrentSprint","NA") -> NA | B27: 14.4 DS Sprint 2 | C27: 45639 | D27: 45666 | E27: 38 | F27: 41 | G27: Introduced - 3 | I27: DataHub MSB-Web MSBP Api's Mobilepay Api's | J27: Stretch Stories: 3sp are completed 3sp are Testing (carry forwarded) - Stretch 5sp are Review (carry forwarded) - Stretch 13sp are inprogress (carry forwarded) - Stretch Internal CRC - 0 External CRC - 2 QA Defects - 3 Escaped Defects - 0 | K27: Internal: External:
A28: =IF(AND($D$1>=C28,$D$1<=D28),"CurrentSprint","NA") -> NA | B28: 14.4 DS Sprint 3 | C28: 45667 | D28: 45680 | E28: 45 | F28: 45 | I28: Regression Sprint | J28: Internal CRC - 0 External CRC - 0 QA Defects - 1 Escaped Defects - 1 | K28: Internal: External:
A29: =IF(AND($D$1>=C29,$D$1<=D29),"CurrentSprint","NA") -> NA | B29: 14.5 DS Sprint 1 | C29: 45681 | D29: 45694 | E29: 37 | F29: 34 | G29: Introduced - 2 | I29: UserHub DataHub | J29: One committed story got carry forwarded with 5SP(Development completed and testing need to be done). Stretch Stories: 2sp are completed 1sp are Review (carry forwarded) - Stretch 29sp are inprogress (carry forwarded) - Stretch Internal CRC - 4 External CRC - 7 QA Defects - 2 Escaped Defects - 1 | K29: Internal: External:
A30: =IF(AND($D$1>=C30,$D$1<=D30),"CurrentSprint","NA") -> NA | B30: 14.5 DS Sprint 2 | C30: 45695 | D30: 45708 | E30: 29 | F30: 48 | G30: Introduced - 19 | I30: DataHub REST Api's Integration Api's | J30: Stretch Stories: 19sp are completed 2sp are Review (carry forwarded) - Stretch 5sp are inprogress (carry forwarded) - Stretch Internal CRC - 8 External CRC - 1 QA Defects - 4 Escaped Defects - 3 | K30: Internal: External:
A31: =IF(AND($D$1>=C31,$D$1<=D31),"CurrentSprint","NA") -> NA | B31: 14.5 DS Sprint 3 | C31: 45709 | D31: 45722 | E31: 44 | F31: 50 | G31: Introduced - 6 | I31: Regression Sprint | J31: Stretch Stories: 6sp are completed Internal CRC - 7 External CRC - 1 QA Defects - 0 Escaped Defects - 1 | K31: Internal: External:
A32: =IF(AND($D$1>=C32,$D$1<=D32),"CurrentSprint","NA") -> NA | B32: 14.6 DS Sprint 1 | C32: 45723 | D32: 45736 | E32: 31 | F32: 47 | G32: Introduced - 16 | I32: DataHub MSB-Web MSB Pay Api's PowerSchool Data Plugin | J32: Stretch Stories: 16sp are completed 3sp are Testing (carry forwarded) - Stretch Peer Test Defects - 5 Internal CRC - 10 External CRC - 0 QA Defects - 0 Escaped Defects - 1 | K32: Internal: External:
A33: =IF(AND($D$1>=C33,$D$1<=D33),"CurrentSprint","NA") -> NA | B33: 14.6 DS Sprint 2 | C33: 45737 | D33: 45750 | E33: 47 | F33: 41 | G33: Introduced - 7 | I33: DataHub UserHub MSB-Web MSB Pay Api's PowerSchool Data Plugin | J33: One committed story got carry forwarded with 13SP. Stretch Stories: 7sp are completed 2sp are Review (carry forwarded) - Stretch Peer Test Defects - 3 Internal CRC - 6 External CRC - 3 QA Defects - 1 Escaped Defects - 1 | K33: Internal: External:
A34: =IF(AND($D$1>=C34,$D$1<=D34),"CurrentSprint","NA") -> NA | B34: 14.6 DS Sprint 3 | C34: 45751 | D34: 45764 | E34: 81 | F34: 78 | I34: Regression Sprint | J34: One committed story (development completed but not merged) was carried forward with 3 story points because it was moved to the 14.7 release. Peer Test Defects - 0 Internal CRC - 10 External CRC - 4 QA Defects - 1 Escaped Defects - 2 | K34: Internal: External:
A35: =IF(AND($D$1>=C35,$D$1<=D35),"CurrentSprint","NA") -> NA | B35: 14.7 DS Sprint 1 | C35: 45765 | D35: 45778 | E35: 43 | F35: 46 | G35: Introduced - 6 | I35: DataHub MSB-Web MSB Dev Portal MSBP Api's REST Api's | J35: One committed story got carry forwarded with 3SP(Due to BB and BB also fixed. Testing need to be done). Stretch Stories: 6sp are completed 5sp are Testing (carry forwarded) - Stretch 4sp are Review (carry forwarded) - Stretch 4sp are Development (carry forwarded) - Stretch Peer Test Defects - 0 Internal CRC - 3 External CRC - 5 QA Defects - 2 Escaped Defects - 1 | K35: Internal: External:
A36: =IF(AND($D$1>=C36,$D$1<=D36),"CurrentSprint","NA") -> NA | B36: 14.7 DS Sprint 2 | C36: 45779 | D36: 45792 | E36: 11 | F36: 23 | G36: Introduced - 12 | I36: DataHub REST Api's | J36: Stretch Stories: 12sp are completed 3sp are Testing (carry forwarded) - Stretch Peer Test Defects - 0 Internal CRC - 7 External CRC - 3 QA Defects - 2 Escaped Defects - 1 | K36: Internal: External:
A37: =IF(AND($D$1>=C37,$D$1<=D37),"CurrentSprint","NA") -> NA | B37: 14.7 DS Sprint 3 | C37: 45793 | D37: 45806 | E37: 37 | F37: 37 | I37: Regression Sprint | J37: Peer Test Defects - 0 Internal CRC - 1 External CRC - 0 QA Defects - 0 Escaped Defects - 2 | K37: Internal: External:
A38: =IF(AND($D$1>=C38,$D$1<=D38),"CurrentSprint","NA") -> NA | B38: 15.0 DS Sprint 1 | C38: 45807 | D38: 45820 | E38: 16 | F38: 23 | G38: Introduced - 7 | H38: 1) Implemented batch deletion records on full sync for both student & enrollment. 2) Included the fee attributes in Export file. 3) Added new two columns(Last Student Sync & Last Fee Sync) on Integrations page. 4) Couple of defect fixed on DH. | I38: 1) Implemented batch deletion records on full sync for both student & enrollment. 2) Included the fee attributes in Export file. 3) Added new two columns(Last Student Sync & Last Fee Sync) on Integrations page. 4) Couple of defect fixed on DH. | J38: Stretch Stories: 7sp are completed Peer Test Defects - 0 Internal CRC - 1 External CRC - 2 QA Defects - 4 Escaped Defects - 0 | K38: Internal: What went well? Completed committed stories and pulled the additional stretch stories. What didn't go well? None Challenges None
A39: =IF(AND($D$1>=C39,$D$1<=D39),"CurrentSprint","NA") -> NA | B39: 15.0 DS Sprint 2 | C39: 45821 | D39: 45834 | E39: 14 | F39: 14 | G39: Introduced - 5 | H39: 1) Updated the default behavior to enable Update Fees Real-Time option Datahub to IncidentIQ Provider 2) Included the fee attributes in Destiny 3) Added Modules options to the Payment Method REST API endpoints | I39: 1) Updated the default behavior to enable Update Fees Real-Time option Datahub to IncidentIQ Provider 2) Included the fee attributes in Destiny 3) Added Modules options to the Payment Method REST API endpoints | J39: One committed defect got carry forwarded with 5SP(Due to relying on George and he is busy with release, this has caused a delay in resolving the defect.). Peer Test Defects - 0 Internal CRC - 3 External CRC - 4 QA Defects - 1 Escaped Defects - 0 | K39: Internal: What went well? Completed 90% committed stories What didn't go well? One committed defect got carry forwarded. The issue is only observed in the test environment, whereas other environments are functioning correctly. Challenges None
A40: =IF(AND($D$1>=C40,$D$1<=D40),"CurrentSprint","NA") -> NA | B40: 15.0 DS Sprint 3 | C40: 45835 | D40: 45848 | E40: 32 | F40: 35 | G40: Introduced - 3 | H40: 1) Added new automation 2) Fixed automation failures 3) Regression testing | I40: 1) Added new automation 2) Fixed automation failures 3) Regression testing | J40: Stretch Stories: 3sp are completed Peer Test Defects - 0 Internal CRC - 0 External CRC - 0 QA Defects - 1 Escaped Defects - 0 | K40: Internal: What went well? 1)Completed regression testing in all environments 2)Wrote the new automation and also fixed the failures What didn't go well? None Challenges None
...

Sheet Defect-template
A1: S.No | B1: Sprint # | C1: Story/Defect ID | D1: Parent Story | E1: Developer | F1: Issue Type | G1: Issue Description | H1: Priority | I1: Defect Source | J1: Type | K1: Status | L1: Root Cause Category | M1: Comments

Sheet 26.7 DS Sprint 1-Status
A1: S.No | B1: Application Name | C1: Sprint Start Date | D1: Sprint End Date | E1: Sprint | F1: Developer | G1: Story ID/Defect ID | H1: Description | I1: Status | J1: Estimated(hrs/sp) | K1: Actual(hrs/sp) | L1: Actual Hours Worklog | M1: Dev start date | N1: Dev end date | O1: Unit testing | P1: Peer Tested By | Q1: Peer Tested Defects, if any | R1: Peer Reviewed By | S1: Peer Code Review Comments, if any | T1: PR Number/Link | U1: PR Created Date | V1: Reviewer 1 | W1: PR Approved Date | X1: Code Review Comments, if any | Y1: Reviewer 2 | Z1: Approved Date | AA1: Code Review Comments, if any2 | AB1: Internal PO -POV Comments | AC1: Client PO -POV Comments | AD1: Comments
A2: 1 | B2: =Dashboard!$J$1 -> MSB Dev | C2: 46157 | D2: 46170 | E2: 26.7 DS Sprint 1 | F2: Mahesh | G2: 20633 | H2: Mobile Pay - API - Disallow payment if gateway is not set or store is disabled | I2: Defect Needs More Info | J2: 5 | K2: =Table14567891011121331415171816201921222324252627282930313233343536373839[[#This Row],[Actual Hours Worklog]] / 4 -> 0
A3: 2 | B3: =Dashboard!$J$1 -> MSB Dev | C3: 46157 | D3: 46170 | E3: 26.7 DS Sprint 1 | F3: Mahesh | G3: 53028 | H3: MobilePay - API - Disallow clerks from Settings or Invoices (Cherry Creek) | I3: Story Being Developed | J3: 3 | K3: =Table14567891011121331415171816201921222324252627282930313233343536373839[[#This Row],[Actual Hours Worklog]] / 4 -> 0 | M3: 46157
A4: 3 | B4: =Dashboard!$J$1 -> MSB Dev | C4: 46157 | D4: 46170 | E4: 26.7 DS Sprint 1 | F4: Mahesh | G4: 53125 | H4: MSB - REST API - POST Invoice - Remove Provider Restriction on GL Account Selection | I4: Story Approved | J4: 3 | K4: =Table14567891011121331415171816201921222324252627282930313233343536373839[[#This Row],[Actual Hours Worklog]] / 4 -> 0
A5: 4 | B5: =Dashboard!$J$1 -> MSB Dev | C5: 46157 | D5: 46170 | E5: 26.7 DS Sprint 1 | F5: Prisla | G5: 27214 | H5: Datahub - Housekeeping Setup - Client Not Persisting | I5: Defect Found | J5: 1 | K5: =Table14567891011121331415171816201921222324252627282930313233343536373839[[#This Row],[Actual Hours Worklog]] / 4 -> 0
A6: 5 | B6: =Dashboard!$J$1 -> MSB Dev | C6: 46157 | D6: 46170 | E6: 26.7 DS Sprint 1 | F6: Prisla | G6: 27224 | H6: MSB Login – MFA Email Code Not Received on Multiple Resend Attempts | I6: Defect Found | J6: 1 | K6: =Table14567891011121331415171816201921222324252627282930313233343536373839[[#This Row],[Actual Hours Worklog]] / 4 -> 0
A7: 6 | B7: =Dashboard!$J$1 -> MSB Dev | C7: 46157 | D7: 46170 | E7: 26.7 DS Sprint 1 | F7: Prisla | G7: 53027 | H7: Datahub - Manage Fees - Change default for fee create date filter | I7: Story Approved | J7: 1 | K7: =Table14567891011121331415171816201921222324252627282930313233343536373839[[#This Row],[Actual Hours Worklog]] / 4 -> 0
A8: 7 | B8: =Dashboard!$J$1 -> MSB Dev | C8: 46157 | D8: 46170 | E8: 26.7 DS Sprint 1 | F8: Prisla | G8: 51192 | H8: MSB - Checkout API - Cart Cache cart webhook configuration (Performance) | I8: Story Approved | J8: 3 | K8: =Table14567891011121331415171816201921222324252627282930313233343536373839[[#This Row],[Actual Hours Worklog]] / 4 -> 0
A9: 8 | B9: =Dashboard!$J$1 -> MSB Dev | C9: 46157 | D9: 46170 | E9: 26.7 DS Sprint 1 | F9: Prisla | G9: 53180 | H9: MSB - REST API - Invoicing - Clean Up Postman Collection and Dev Portal | I9: Story Need More Info | J9: 2 | K9: =Table14567891011121331415171816201921222324252627282930313233343536373839[[#This Row],[Actual Hours Worklog]] / 4 -> 0
A10: 9 | B10: =Dashboard!$J$1 -> MSB Dev | C10: 46157 | D10: 46170 | E10: 26.7 DS Sprint 1 | F10: Aravindh | G10: 52899 | H10: Developer Portal - Notification Hub - Add swagger content | I10: Story Being Developed | J10: 2 | K10: =Table14567891011121331415171816201921222324252627282930313233343536373839[[#This Row],[Actual Hours Worklog]] / 4 -> 0
A11: 10 | B11: =Dashboard!$J$1 -> MSB Dev | C11: 46157 | D11: 46170 | E11: 26.7 DS Sprint 1 | F11: Aravindh | G11: 52958 | H11: UserHub - Identity Provider - Improve logging | I11: Story Approved | J11: 3 | K11: =Table14567891011121331415171816201921222324252627282930313233343536373839[[#This Row],[Actual Hours Worklog]] / 4 -> 0
A12: 11 | B12: =Dashboard!$J$1 -> MSB Dev | C12: 46157 | D12: 46170 | E12: 26.7 DS Sprint 1 | F12: Aravindh | G12: 52961 | H12: UserHub - Identity Providers - UI enhancements | I12: Story Need More Info | J12: 5 | K12: 0
A13: 12 | B13: =Dashboard!$J$1 -> MSB Dev | C13: 46157 | D13: 46170
A14: 13 | B14: =Dashboard!$J$1 -> MSB Dev | C14: 46157 | D14: 46170

Sheet 26.7 DS Sprint 1-Defect
A1: S.No | B1: Sprint # | C1: Story/Defect ID | D1: Parent Story | E1: Developer | F1: Issue Type | G1: Issue Description | H1: Priority | I1: Defect Source | J1: Type | K1: Status | L1: Root Cause Category | M1: Comments
B2: 26.7 DS Sprint 1 | C2: 20633 | E2: Mahesh | F2: Defect | G2: Mobile Pay - API - Disallow payment if gateway is not set or store is disabled | H2: Minor | I2: Manual | J2: External | K2: Inprogress
B3: 26.7 DS Sprint 1 | C3: 27214 | E3: Prisla | F3: Defect | G3: Datahub - Housekeeping Setup - Client Not Persisting | H3: Minor | I3: Manual | J3: External | K3: Inprogress
B4: 26.7 DS Sprint 1 | C4: 27224 | E4: Prisla | F4: Defect | G4: MSB Login – MFA Email Code Not Received on Multiple Resend Attempts | H4: Minor | I4: Manual | J4: External | K4: Inprogress

Sheet 26.5 DS Sprint 3-Status
A1: S.No | B1: Application Name | C1: Sprint Start Date | D1: Sprint End Date | E1: Sprint | F1: Developer | G1: Story ID/Defect ID | H1: Description | I1: Status | J1: Estimated(hrs/sp) | K1: Actual(hrs/sp) | L1: Actual Hours Worklog | M1: Dev start date | N1: Dev end date | O1: Unit testing | P1: Peer Tested By | Q1: Peer Tested Defects, if any | R1: Peer Reviewed By | S1: Peer Code Review Comments, if any | T1: PR Number/Link | U1: PR Created Date | V1: Reviewer 1 | W1: PR Approved Date | X1: Code Review Comments, if any | Y1: Reviewer 2 | Z1: Approved Date | AA1: Code Review Comments, if any2 | AB1: Internal PO -POV Comments | AC1: Client PO -POV Comments | AD1: Comments
A2: 1 | B2: =Dashboard!$J$1 -> MSB Dev | C2: 46143 | D2: 46156 | E2: 26.5 DS Sprint 3 | F2: Mahesh | G2: 53068 | H2: MSB - Partner Integrations - New Automation [26.5] | I2: Story Completed | J2: 13 | K2: =Table145678910111213314151718162019212223242526272829303132333435363738[[#This Row],[Actual Hours Worklog]] / 4 -> 30.5 | L2: 122 | M2: 46146 | N2: 46156 | O2: NA | P2: Prisla | Q2: None | R2: Prisla | S2: No Comments | T2: https://dev.azure.com/heartlandschools/MySchoolBucks/_git/MSBAutomation/pullrequest/48901 https://dev.azure.com/heartlandschools/MySchoolBucks/_git/MSBAutomation/pullrequest/48989 https://dev.azure.com/heartlandschools/MySchoolBucks/_git/MSBAutomation/pullrequest/49019 https://dev.azure.com/heartlandschools/MySchoolBucks/_git/MSBAutomation/pullrequest/49053 https://dev.azure.com/heartlandschools/MySchoolBucks/_git/MSBAutomation/pullrequest/48964 https://dev.azure.com/heartlandschools/MySchoolBucks/_git/MSBAutomation/pullrequest/48947 https://dev.azure.com/heartlandschools/MySchoolBucks/_git/MSBAutomation/pullrequest/49003 https://dev.azure.com/heartlandschools/MySchoolBucks/_git/MSBAutomation/pullrequest/48955 | U2: 46149 | V2: Prisla | W2: 46150 | X2: No Comments | Y2: Alex | Z2: 46150 | AA2: No Comments | AB2: NA | AC2: NA | AD2: Comments : The story was created as a common task to implement automation for this release stories. Facing environment issue to run the automation and that is the reason took more time to complete the automation for all the members. Time Entries : Aravindh:39hrs Prisla: 35hrs Mahesh:48hrs
A3: 2 | B3: =Dashboard!$J$1 -> MSB Dev | C3: 46143 | D3: 46156 | E3: 26.5 DS Sprint 3 | F3: Nithish | G3: 53072 | H3: MSB - Partner Integrations - Regression [26.5] | I3: Story Completed | J3: 13 | K3: =Table145678910111213314151718162019212223242526272829303132333435363738[[#This Row],[Actual Hours Worklog]] / 4 -> 11.125 | L3: 44.5 | M3: NA | N3: NA | O3: NA | P3: NA | Q3: NA | R3: NA | S3: NA | T3: NA | U3: NA | V3: NA | W3: NA | X3: NA | Y3: NA | Z3: NA | AA3: NA | AB3: NA | AC3: NA | AD3: Comments : Added only for testing purpose Time Entries: Nithish: 44.5 hr
A4: 3 | B4: =Dashboard!$J$1 -> MSB Dev | C4: 46143 | D4: 46156 | E4: 26.5 DS Sprint 3 | F4: Aravindh | G4: 52895 | H4: Notification Hub - API - Get notifications by userID (Client Services) | I4: Story Completed | J4: 2 | K4: =Table145678910111213314151718162019212223242526272829303132333435363738[[#This Row],[Actual Hours Worklog]] / 4 -> 5.625 | L4: 22.5 | M4: 46146 | N4: 46147 | O4: Manual (TestCases-50) | P4: Mahesh | Q4: 1. If provider createdstartdate and createdenddate as null. throw exception | R4: Mahesh | S4: 1. change to valid error messages 2. change to "GetEmailsResponse" 3. change validation and throw valid error | T4: https://dev.azure.com/heartlandschools/MySchoolBucks/_git/SchoolBucks/pullrequest/48839 | U4: 46147 | V4: Prisla | W4: 46148 | X4: No Comments | Y4: Alex | Z4: 46148 | AA4: No Comments | AB4: NA | AC4: NA | AD4: Comments : The story was carried over from the last sprint due to bouncebacks. Time Entries : Aravindh:15hr Prisla: 4hr Nithish:3.5hr
A5: 4 | B5: =Dashboard!$J$1 -> MSB Dev | C5: 46143 | D5: 46156 | E5: 26.5 DS Sprint 3 | F5: Prisla | G5: 52897 | H5: MSB - Checkout API - Create Cart performance (Destiny Fundraising Mgr) | I5: Story Completed | J5: 1 | K5: =Table145678910111213314151718162019212223242526272829303132333435363738[[#This Row],[Actual Hours Worklog]] / 4 -> 3 | L5: 12 | M5: 46147 | N5: 46148 | O5: Manual (TestCases-10) | P5: Mahesh | Q5: None | R5: Mahesh | S5: No Comments | T5: https://dev.azure.com/heartlandschools/MySchoolBucks/_git/SchoolBucks/pullrequest/48866 | U5: 46148 | V5: Alex | W5: 46148 | X5: No Comments | Y5: NA | Z5: NA | AA5: NA | AB5: NA | AC5: NA | AD5: Comments : The story was carried over from the last sprint due to an investigation into performance issues. Done some tuning on the code to improve performance and now waiting for the logs to verify. Time Entries: Prisla: 9hr Nithish: 3hr
A6: 5 | B6: =Dashboard!$J$1 -> MSB Dev | C6: 46143 | D6: 46156 | E6: 26.5 DS Sprint 3 Stretch | F6: Ken | G6: 27360 | H6: MSB - WEb - Course Fee Import option always shown, even when FF disabled | I6: Defect Fixed | J6: 1 | K6: =Table145678910111213314151718162019212223242526272829303132333435363738[[#This Row],[Actual Hours Worklog]] / 4 -> 0.75 | L6: 3 | M6: NA | N6: NA | O6: NA | P6: NA | Q6: NA | R6: NA | S6: NA | T6: NA | U6: NA | V6: NA | W6: NA | X6: NA | Y6: NA | Z6: NA | AA6: NA | AB6: NA | AC6: NA | AD6: Comments : Client fixed this defect added only for testing purpose Time Entries: Nithish: 3hr
A7: 6 | B7: =Dashboard!$J$1 -> MSB Dev | C7: 46143 | D7: 46156 | E7: 26.5 DS Sprint 3 Stretch | F7: Mahesh | G7: 27375 | H7: DataHub – Enrollment Full Sync Not Working for All OneRoster Provider Types | I7: Defect Fixed | J7: 2 | K7: =Table145678910111213314151718162019212223242526272829303132333435363738[[#This Row],[Actual Hours Worklog]] / 4 -> 2.25 | L7: 9 | M7: 46150 | N7: 46150 | O7: Manual (TestCases-10) | P7: Aravindh | Q7: None | R7: Aravindh | S7: No Comments | T7: https://dev.azure.com/heartlandschools/MySchoolBucks/_git/SchoolBucks/pullrequest/48938 | U7: 46150 | V7: Prisla | W7: 46153 | X7: No Comments | Y7: Ken | Z7: 46153 | AA7: Don't instantiate a new object mapper. We should already have one at the (super) class level. | AB7: NA | AC7: NA | AD7: Time Entries: Mahesh: 6hr Nithish: 3hr
A8: 7 | B8: =Dashboard!$J$1 -> MSB Dev | C8: 46143 | D8: 46156 | E8: 26.5 DS Sprint 3 Stretch | F8: Ken | G8: 27361 | H8: MSB - Course Fee Import Default Value Incorrect | I8: Defect Fixed | J8: 1 | K8: =Table145678910111213314151718162019212223242526272829303132333435363738[[#This Row],[Actual Hours Worklog]] / 4 -> 0.75 | L8: 3 | M8: NA | N8: NA | O8: NA | P8: NA | Q8: NA | R8: NA | S8: NA | T8: NA | U8: NA | V8: NA | W8: NA | X8: NA | Y8: NA | Z8: NA | AA8: NA | AB8: NA | AC8: NA | AD8: Comments : Client fixed this defect added only for testing purpose Time Entries: Nithish: 3hr
A9: 8 | B9: =Dashboard!$J$1 -> MSB Dev | C9: 46143 | D9: 46156 | K9: =Table145678910111213314151718162019212223242526272829303132333435363738[[#This Row],[Actual Hours Worklog]] / 4 -> 0
A10: 9 | B10: =Dashboard!$J$1 -> MSB Dev | C10: 46143 | D10: 46156 | K10: =Table145678910111213314151718162019212223242526272829303132333435363738[[#This Row],[Actual Hours Worklog]] / 4 -> 0
A11: 10 | B11: =Dashboard!$J$1 -> MSB Dev | C11: 46143 | D11: 46156 | K11: =Table145678910111213314151718162019212223242526272829303132333435363738[[#This Row],[Actual Hours Worklog]] / 4 -> 0

Sheet 26.5 DS Sprint 3-Defect
A1: S.No | B1: Sprint # | C1: Story/Defect ID | D1: Parent Story | E1: Developer | F1: Issue Type | G1: Issue Description | H1: Priority | I1: Defect Source | J1: Type | K1: Status | L1: Root Cause Category | M1: Comments
B2: 26.5 DS Sprint 3 | C2: 52895 | E2: Aravindh | F2: Bounceback | G2: Get SMS by UserID, passing only the UserID returns an error "Filter rowCount value must be in range [1..1000]" | H2: Minor | I2: Manual | J2: Internal | K2: Closed | L2: Development | M2: Missed in development
B3: 26.5 DS Sprint 3 Stretch | C3: 27375 | E3: Mahesh | F3: Defect | G3: DataHub – Enrollment Full Sync Not Working for All OneRoster Provider Types | H3: Major | I3: Manual | J3: Internal | K3: Closed | L3: Development | M3: JSON response was not mapped to the Enrollment object

Sheet 26.5 DS Sprint 2-Status
A1: S.No | B1: Application Name | C1: Sprint Start Date | D1: Sprint End Date | E1: Sprint | F1: Developer | G1: Story ID/Defect ID | H1: Description | I1: Status | J1: Estimated(hrs/sp) | K1: Actual(hrs/sp) | L1: Actual Hours Worklog | M1: Dev start date | N1: Dev end date | O1: Unit testing | P1: Peer Tested By | Q1: Peer Tested Defects, if any | R1: Peer Reviewed By | S1: Peer Code Review Comments, if any | T1: PR Number/Link | U1: PR Created Date | V1: Reviewer 1 | W1: PR Approved Date | X1: Code Review Comments, if any | Y1: Reviewer 2 | Z1: Approved Date | AA1: Code Review Comments, if any2 | AB1: Internal PO -POV Comments | AC1: Client PO -POV Comments | AD1: Comments
A2: 1 | B2: =Dashboard!$J$1 -> MSB Dev | C2: 46129 | D2: 46142 | E2: 26.5 DS Sprint 2 | F2: Mahesh | G2: 52444 | H2: DataHub - API - deprecate HSSConnect API v1 | I2: Story Completed | J2: 1 | K2: =Table1456789101112133141517181620192122232425262728293031323334353637[[#This Row],[Actual Hours Worklog]] / 4 -> 1 | L2: 4 | M2: 46125 | N2: 46127 | O2: Manual (TestCases-30) | P2: Aravindh | Q2: None | R2: Aravindh | S2: No Comments | T2: https://dev.azure.com/heartlandschools/MySchoolBucks/_git/SchoolBucks/pullrequest/48419 | U2: 46127 | V2: Prisla | W2: 46127 | X2: No Comments | Y2: Ken | Z2: 46127 | AA2: No Comments | AB2: NA | AC2: NA | AD2: Last sprint development was completed and QA need to test. Time Entries: Nithish: 4hrs
A3: 2 | B3: =Dashboard!$J$1 -> MSB Dev | C3: 46129 | D3: 46142 | E3: 26.5 DS Sprint 2 | F3: Mahesh | G3: 52063 | H3: MobilePay - API - Shifts - Add Credit card subtotals to Close Out (Clark Cty) | I3: Story Completed | J3: 3 | K3: =Table1456789101112133141517181620192122232425262728293031323334353637[[#This Row],[Actual Hours Worklog]] / 4 -> 1.75 | L3: 7 | M3: 46129 | N3: 46129 | O3: Manual (TestCases-10) | P3: Aravindh | Q3: None | R3: Aravindh | S3: No Comments | T3: https://dev.azure.com/heartlandschools/MySchoolBucks/_git/SchoolBucks/pullrequest/48493 | U3: 46129 | V3: Prisla | W3: 46132 | X3: No Comments | Y3: Alex | Z3: 46132 | AA3: No Comments | AB3: No Comments | AC3: No Comments | AD3: Time Entries: Mahesh: 5hrs Nithish: 2hrs
A4: 3 | B4: =Dashboard!$J$1 -> MSB Dev | C4: 46129 | D4: 46142 | E4: 26.5 DS Sprint 2 | F4: Mahesh | G4: 52858 | H4: MSB - Checkout API - Process Cart - Add DBA Name as separate field in response (Destiny Fundraising Mgr) | I4: Story Completed | J4: 2 | K4: =Table1456789101112133141517181620192122232425262728293031323334353637[[#This Row],[Actual Hours Worklog]] / 4 -> 2.25 | L4: 9 | M4: 46132 | N4: 46132 | O4: Manual (TestCases-10) | P4: Aravindh | Q4: None | R4: Aravindh | S4: No Comments | T4: https://dev.azure.com/heartlandschools/MySchoolBucks/_git/SchoolBucks/pullrequest/48513 | U4: 46132 | V4: Prisla | W4: 46132 | X4: No Comments | Y4: Ken | Z4: 46132 | AA4: No Comments | AB4: No Comments | AC4: No Comments | AD4: Time Entries: Mahesh: 6hrs Prisla: 1hrs Nithish: 2hrs
A5: 4 | B5: =Dashboard!$J$1 -> MSB Dev | C5: 46129 | D5: 46142 | E5: 26.5 DS Sprint 2 | F5: Mahesh | G5: 52891 | H5: UserHub - Configure SAML PowerSchool - strip or ignore extra characters | I5: Story Completed | J5: 1 | K5: =Table1456789101112133141517181620192122232425262728293031323334353637[[#This Row],[Actual Hours Worklog]] / 4 -> 1 | L5: 4 | M5: 46132 | N5: 46132 | O5: Manual (TestCases-10) | P5: Aravindh | Q5: None | R5: Aravindh | S5: No Comments | T5: https://dev.azure.com/heartlandschools/MySchoolBucks/_git/SchoolBucks/pullrequest/48516 | U5: 46132 | V5: Prisla | W5: 46132 | X5: No Comments | Y5: Ken | Z5: 46132 | AA5: No Comments | AB5: No Comments | AC5: No Comments | AD5: Time Entries: Mahesh: 3hrs Prisla: 1hrs
A6: 5 | B6: =Dashboard!$J$1 -> MSB Dev | C6: 46129 | D6: 46142 | E6: 26.5 DS Sprint 2 | F6: Mahesh | G6: 52897 | H6: MSB - Checkout API - Create Cart performance (Destiny Fundraising Mgr) | I6: Story Being Developed | J6: 5 | K6: =Table1456789101112133141517181620192122232425262728293031323334353637[[#This Row],[Actual Hours Worklog]] / 4 -> 0 | M6: 46133 | N6: 46135 | O6: NA | P6: Prisla | Q6: None | R6: Prisla | S6: No Comments | T6: https://dev.azure.com/heartlandschools/MySchoolBucks/_git/SchoolBucks/pullrequest/48614 https://dev.azure.com/heartlandschools/MySchoolBucks/_git/SchoolBucks/pullrequest/48719 | U6: 46135 | V6: Prisla | W6: 46135 | X6: No Comments | Y6: George | Z6: 46139 | AA6: Requested to add more logs and also in Update cart API | AB6: NA | AC6: NA | AD6: The story requested an investigation into performance issues. After analysis, no tuning opportunities were found, and no delays were observed in local, test, or staging environments. The issue occurs only in the production environment, so additional logs were added to the full cart creation process for further analysis. The story has been carried forward as we need to check the logs. We are awaiting the logs and have also informed the client.
A7: 6 | B7: =Dashboard!$J$1 -> MSB Dev | C7: 46129 | D7: 46142 | E7: 26.5 DS Sprint 2 | F7: Prisla | G7: 52537 | H7: MSB - REST API - Block "Archived" GL Accounts on POST/PUT (Invoice Template, Invoices, Fees) | I7: Story Completed | J7: 8 | K7: =Table1456789101112133141517181620192122232425262728293031323334353637[[#This Row],[Actual Hours Worklog]] / 4 -> 7.25 | L7: 29 | M7: 46129 | N7: 46133 | O7: Manual (TestCases-30) | P7: Mahesh | Q7: None | R7: Mahesh | S7: No Comments | T7: https://dev.azure.com/heartlandschools/MySchoolBucks/_git/SchoolBucks/pullrequest/48530 | U7: 46133 | V7: Ken | W7: 46133 | X7: No Comments | Y7: NA | Z7: NA | AA7: NA | AB7: No Comments | AC7: No Comments | AD7: Time Entries: Prisla: 14hrs Nithish: 15hrs
A8: 7 | B8: =Dashboard!$J$1 -> MSB Dev | C8: 46129 | D8: 46142 | E8: 26.5 DS Sprint 2 | F8: Aravindh | G8: 52831 | H8: MSB – DataHub – Export Classes and Terms to XLSX | I8: Story Completed | J8: 5 | K8: =Table1456789101112133141517181620192122232425262728293031323334353637[[#This Row],[Actual Hours Worklog]] / 4 -> 4.5 | L8: 18 | M8: 46129 | N8: 46129 | O8: Manual (TestCases-10) | P8: Mahesh | Q8: None | R8: Mahesh | S8: No Comments | T8: https://dev.azure.com/heartlandschools/MySchoolBucks/_git/SchoolBucks/pullrequest/48495 | U8: 46129 | V8: Prisla | W8: 46132 | X8: No Comments | Y8: Alex | Z8: 46132 | AA8: No Comments | AB8: No Comments | AC8: No Comments | AD8: Time Entries: Aravindh:18hrs
A9: 8 | B9: =Dashboard!$J$1 -> MSB Dev | C9: 46129 | D9: 46142 | E9: 26.5 DS Sprint 2 | F9: Aravindh | G9: 52895 | H9: Notification Hub - API - Get notifications by userID (Client Services) | I9: Story Being Tested | J9: 8 | K9: =Table1456789101112133141517181620192122232425262728293031323334353637[[#This Row],[Actual Hours Worklog]] / 4 -> 0 | M9: 46134 | N9: 46140 | O9: Manual (TestCases-60) | P9: Mahesh | Q9: 1. ApplicationId filter is not working properly when developerAcct is not system Level 2. Page and rowcount should be integer in collection insteadOf string 3. Only userId id mandatory. Other field should be set default. If not provided | R9: Mahesh | S9: 1. Should be else if insteadOf if condition 2. It should be SMS attributes insteadOf email 3.No need the filterParams instead you can add UserRequest | T9: https://dev.azure.com/heartlandschools/MySchoolBucks/_git/SchoolBucks/pullrequest/48679 | U9: 46140 | V9: Prisla | W9: 46141 | X9: 1. log message should be sms instead of email 2. Add Separate common method for date validation 3. use the same error message as email "UserId is required" 4. method name should start with lowercase | Y9: Alex | Z9: 46141 | AA9: No Comments | AB9: No Comments | AC9: The result should be show last 7 day data by default | AD9: Comments : The implementation was completed based on the acceptance criteria (AC), and a proof of value (POV) was presented to the client. During the POV, the client requested a few additional changes, after which the AC was updated accordingly. The developer submitted the code for peer review more than three times, and the peer reviewer identified several issues. Some testing scenarios were missed during testing and the internal POV. During the peer review process, the peer reviewer identified and consolidated the issues and communicated them to the team. After code implementation Alex requested to change some requestBody [Differ from Story AC] and we worked on it. The story has been carried forward because of bouncebacks Time Entries : Aravindh : 24hrs
A10: 9 | B10: =Dashboard!$J$1 -> MSB Dev | C10: 46129 | D10: 46142 | E10: 26.5 DS Sprint 2 | F10: Ken | G10: 51604 | H10: MSB - Course Fees - handle import from file | I10: Story Completed | J10: 2 | K10: =Table1456789101112133141517181620192122232425262728293031323334353637[[#This Row],[Actual Hours Worklog]] / 4 -> 1 | L10: 4 | M10: NA | N10: NA | O10: NA | P10: NA | Q10: NA | R10: NA | S10: NA | T10: NA | U10: NA | V10: NA | W10: NA | X10: NA | Y10: NA | Z10: NA | AA10: NA | AB10: NA | AC10: NA | AD10: Client developed the story added only for testing purpose Time Entries: Nithish: 4hrs
A11: 10 | B11: =Dashboard!$J$1 -> MSB Dev | C11: 46129 | D11: 46142 | E11: 26.5 DS Sprint 2 | F11: Alex | G11: 27089 | H11: MSB - MFA - Unable to add MFA method on login | I11: Defect Fixed | J11: 1 | K11: =Table1456789101112133141517181620192122232425262728293031323334353637[[#This Row],[Actual Hours Worklog]] / 4 -> 0.75 | L11: 3 | M11: NA | N11: NA | O11: NA | P11: NA | Q11: NA | R11: NA | S11: NA | T11: NA | U11: NA | V11: NA | W11: NA | X11: NA | Y11: NA | Z11: NA | AA11: NA | AB11: NA | AC11: NA | AD11: Client fixed the defect added only for testing purpose Time Entries: Nithish: 3hrs
A12: 11 | B12: =Dashboard!$J$1 -> MSB Dev | C12: 46129 | D12: 46142 | E12: 26.5 DS Sprint 2 Stretch | F12: Mahesh | G12: 27223 | H12: MSB – Getting Started – Developer Account Confirmation Email Not Received in NH | I12: Defect Rejected | J12: 1 | K12: =Table1456789101112133141517181620192122232425262728293031323334353637[[#This Row],[Actual Hours Worklog]] / 4 -> 1.5 | L12: 6 | M12: 46136 | N12: 46136 | O12: NA | P12: NA | Q12: NA | R12: NA | S12: NA | T12: NA | U12: NA | V12: NA | W12: NA | X12: NA | Y12: NA | Z12: NA | AA12: NA | AB12: NA | AC12: NA | AD12: Issue not able to reproduce and rejected Time Entries: Mahesh: 6hrs
A13: 12 | B13: =Dashboard!$J$1 -> MSB Dev | C13: 46129 | D13: 46142 | E13: 26.5 DS Sprint 2 Stretch | F13: Mahesh | G13: 52962 | H13: UserHub - Identity Providers - Export | I13: Story Completed | J13: 3 | K13: =Table1456789101112133141517181620192122232425262728293031323334353637[[#This Row],[Actual Hours Worklog]] / 4 -> 3.25 | L13: 13 | M13: 46139 | N13: 46140 | O13: Manual (TestCases-10) | P13: Aravindh | Q13: None | R13: Aravindh | S13: No Comments | T13: https://dev.azure.com/heartlandschools/MySchoolBucks/_git/SchoolBucks/pullrequest/48683 | U13: 46140 | V13: Prisla | W13: 46140 | X13: No Comments | Y13: Alex | Z13: 46140 | AA13: No Comments | AB13: No Comments | AC13: No Comments | AD13: Time Entries: Mahesh: 11hrs Prisla: 1hrs Nithish: 1hrs
A14: 13 | B14: =Dashboard!$J$1 -> MSB Dev | C14: 46129 | D14: 46142 | E14: 26.5 DS Sprint 2 Stretch | F14: Prisla | G14: 52903 | H14: MSB - REST API - Validate GL Account status on POST/PUT (Stores, Products) | I14: Story Completed | J14: 8 | K14: =Table1456789101112133141517181620192122232425262728293031323334353637[[#This Row],[Actual Hours Worklog]] / 4 -> 5.5 | L14: 22 | M14: 46133 | N14: 46133 | O14: Manual (TestCases-20) | P14: Mahesh | Q14: None | R14: Mahesh | S14: No Comments | T14: https://dev.azure.com/heartlandschools/MySchoolBucks/_git/SchoolBucks/pullrequest/48568 | U14: 46134 | V14: Ken | W14: 46134 | X14: No Comments | Y14: NA | Z14: NA | AA14: NA | AB14: No Comments | AC14: No Comments | AD14: Time Entries: Prisla: 13hrs Nithish: 9hrs
A15: 14 | B15: =Dashboard!$J$1 -> MSB Dev | C15: 46129 | D15: 46142 | E15: 26.5 DS Sprint 2 Stretch | F15: Prisla | G15: 52963 | H15: UserHub - Identity Providers - Add/ Edit validations | I15: Story Completed | J15: 1 | K15: =Table1456789101112133141517181620192122232425262728293031323334353637[[#This Row],[Actual Hours Worklog]] / 4 -> 1.75 | L15: 7 | M15: 46139 | N15: 46140 | O15: Manual (TestCases-5) | P15: Mahesh | Q15: None | R15: Mahesh | S15: No Comments | T15: https://dev.azure.com/heartlandschools/MySchoolBucks/_git/SchoolBucks/pullrequest/48670 | U15: 46139 | V15: Ken | W15: 46140 | X15: No Comments | Y15: NA | Z15: NA | AA15: NA | AB15: No Comments | AC15: No Comments | AD15: Time Entries: Prisla: 6hrs Nithish: 1hrs
A16: 15 | B16: =Dashboard!$J$1 -> MSB Dev | C16: 46129 | D16: 46142 | E16: 26.5 DS Sprint 2 Stretch | F16: Ken | G16: 27235 | H16: MSBP - API - Incorrect Greenlight registration status returned for new sign up | I16: Defect Fixed | J16: 3 | K16: =Table1456789101112133141517181620192122232425262728293031323334353637[[#This Row],[Actual Hours Worklog]] / 4 -> 1 | L16: 4 | M16: NA | N16: NA | O16: NA | P16: NA | Q16: NA | R16: NA | S16: NA | T16: NA | U16: NA | V16: NA | W16: NA | X16: NA | Y16: NA | Z16: NA | AA16: NA | AB16: NA | AC16: NA | AD16: Client fixed the defect added only for testing purpose Time Entries: Nithish: 4hrs

Sheet 26.5 DS Sprint 2-Defect
A1: S.No | B1: Sprint # | C1: Story/Defect ID | D1: Parent Story | E1: Developer | F1: Issue Type | G1: Issue Description | H1: Priority | I1: Defect Source | J1: Type | K1: Status | L1: Root Cause Category | M1: Comments
B2: 26.5 DS Sprint 2 | C2: 52537 | E2: Prisla | F2: Bounceback | G2: POST Invoice: Even when passing a valid glSalesTaxAcctID value, an incorrect validation message is returned: "FAILED CREATION: GL Sales Tax Account [glacct10] is not of type [expenditure] and cannot be used." Instead, the invoice should be created successfully. | H2: Minor | I2: Manual | J2: Internal | K2: Closed | L2: Development | M2: Missed in development
B3: 26.5 DS Sprint 2 | C3: 52537 | E3: Prisla | F3: Bounceback | G3: POST Invoice: When passing a disabled or archived value in the glExpenditureAcctID field, the invoice is created incorrectly. Instead throw validation message "FAILED CREATION: GL Expenditure Account [glacct14] is not active and cannot be used." is missing. | H3: Minor | I3: Manual | J3: Internal | K3: Closed | L3: Development | M3: Missed in development
B4: 26.5 DS Sprint 2 Stretch | C4: 27223 | E4: Mahesh | F4: Defect | G4: MSB – Getting Started – Developer Account Confirmation Email Not Received in NH | H4: Minor | I4: Manual | J4: Internal | K4: Closed | L4: Existing_Issues | M4: Issue not able to reproduce and rejected

Sheet 26.5 DS Sprint 1-Status
A1: S.No | B1: Application Name | C1: Sprint Start Date | D1: Sprint End Date | E1: Sprint | F1: Developer | G1: Story ID/Defect ID | H1: Description | I1: Status | J1: Estimated(hrs/sp) | K1: Actual(hrs/sp) | L1: Actual Hours Worklog | M1: Dev start date | N1: Dev end date | O1: Unit testing | P1: Peer Tested By | Q1: Peer Tested Defects, if any | R1: Peer Reviewed By | S1: Peer Code Review Comments, if any | T1: PR Number/Link | U1: PR Created Date | V1: Reviewer 1 | W1: PR Approved Date | X1: Code Review Comments, if any | Y1: Reviewer 2 | Z1: Approved Date | AA1: Code Review Comments, if any2 | AB1: Internal PO -POV Comments | AC1: Client PO -POV Comments | AD1: Comments
A2: 1 | B2: =Dashboard!$J$1 -> MSB Dev | C2: 46115 | D2: 46128 | E2: 26.5 DS Sprint 1 | F2: Mahesh | G2: 52428 | H2: MobilePay - API - GET /payments & GET /payments/subtotal - Support search by Student Number | I2: Story Completed | J2: 5 | K2: =Table14567891011121331415171816201921222324252627282930313233343536[[#This Row],[Actual Hours Worklog]] / 4 -> 4 | L2: 16 | M2: 46115 | N2: 46119 | O2: Manual (TestCases-10) | P2: Aravindh | Q2: None | R2: Aravindh | S2: No Comments | T2: https://dev.azure.com/heartlandschools/MySchoolBucks/_git/SchoolBucks/pullrequest/48265 | U2: 46119 | V2: Prisla | W2: 46120 | X2: No Comments | Y2: Ken | Z2: 46120 | AA2: No Comments | AB2: No Comments | AC2: No Comments | AD2: Time Enrties : Mahesh: 11hrs Prisla: 1hrs Nithish: 4hrs
A3: 2 | B3: =Dashboard!$J$1 -> MSB Dev | C3: 46115 | D3: 46128 | E3: 26.5 DS Sprint 1 | F3: Mahesh | G3: 52429 | H3: MobilePay - API - GET /payments & GET /payments/subtotal - Support filter by ShiftKey (Multiple Values) | I3: Story Completed | J3: 5 | K3: =Table14567891011121331415171816201921222324252627282930313233343536[[#This Row],[Actual Hours Worklog]] / 4 -> 4.75 | L3: 19 | M3: 46120 | N3: 46120 | O3: Manual (TestCases-10) | P3: Prisla | Q3: None | R3: Prisla | S3: No Comments | T3: https://dev.azure.com/heartlandschools/MySchoolBucks/_git/SchoolBucks/pullrequest/48290 | U3: 46120 | V3: Prisla | W3: 46120 | X3: No Comments | Y3: Ken | Z3: 46121 | AA3: No Comments | AB3: No Comments | AC3: No Comments | AD3: Time Enrties : Mahesh: 12hrs Prisla: 1hrs Nithish: 6hrs
A4: 3 | B4: =Dashboard!$J$1 -> MSB Dev | C4: 46115 | D4: 46128 | E4: 26.5 DS Sprint 1 | F4: Prisla | G4: 52336 | H4: MSB - Mobile Pay API - Document Close Out behavior R&D | I4: Story Completed | J4: 3 | K4: =Table14567891011121331415171816201921222324252627282930313233343536[[#This Row],[Actual Hours Worklog]] / 4 -> 5.75 | L4: 23 | M4: 46115 | N4: 46126 | O4: NA | P4: NA | Q4: NA | R4: NA | S4: NA | T4: NA | U4: NA | V4: NA | W4: NA | X4: NA | Y4: NA | Z4: NA | AA4: NA | AB4: NA | AC4: NA | AD4: Apr-13: This story was part of R&D for Shift Close Out behavior and required documentation. The documentation has been completed, and a discussion was held with the PO regarding the current API behavior. Next, we need to discuss with the mobile team to understand how they have implemented the logic on their side, and then finalize the approach for handling batchId in payments. Time Enrties : Prisla: 23hrs
A5: 4 | B5: =Dashboard!$J$1 -> MSB Dev | C5: 46115 | D5: 46128 | E5: 26.5 DS Sprint 1 | F5: Prisla | G5: 27100 | H5: DH - HSS Connect - Include/Exclude filter school not respecting properly after running full sync without any filter | I5: Defect Fixed | J5: 1 | K5: =Table14567891011121331415171816201921222324252627282930313233343536[[#This Row],[Actual Hours Worklog]] / 4 -> 3.25 | L5: 13 | M5: 46115 | N5: 46115 | O5: Manual (TestCases-5) | P5: Aravindh | Q5: None | R5: Aravindh | S5: No Comments | T5: https://dev.azure.com/heartlandschools/MySchoolBucks/_git/SchoolBucks/pullrequest/48180 | U5: 46113 | V5: Ken | W5: 46120 | X5: No Comments | Y5: NA | Z5: NA | AA5: NA | AB5: NA | AC5: NA | AD5: Testing took longer because there were more scenarios to cover, and each sync run requires time to complete. Time Enrties : Prisla: 8hrs Nithish: 5hrs
A6: 5 | B6: =Dashboard!$J$1 -> MSB Dev | C6: 46115 | D6: 46128 | E6: 26.5 DS Sprint 1 | F6: Aravindh | G6: 52251 | H6: MSB - Dev Portal - Add UserHub API page | I6: Story Completed | J6: 5 | K6: =Table14567891011121331415171816201921222324252627282930313233343536[[#This Row],[Actual Hours Worklog]] / 4 -> 7.25 | L6: 29 | M6: 46115 | N6: 46120 | O6: Manual (TestCases-5) | P6: Mahesh | Q6: None | R6: Mahesh | S6: No Comments | T6: https://dev.azure.com/heartlandschools/MySchoolBucks/_git/SchoolBucks/pullrequest/48361 | U6: 46122 | V6: Prisla | W6: 46122 | X6: No Comments | Y6: Alex | Z6: 46125 | AA6: No Comments | AB6: No Comments | AC6: No Comments | AD6: Comment: We upgraded the Java version from 17 to 21. Due to this change, we are facing issues in the local environment. This has increased the time required for development and testing. Time Entries: Aravindh : 21hrs Prisla : 3hrs Nithish : 5hrs
A7: 6 | B7: =Dashboard!$J$1 -> MSB Dev | C7: 46115 | D7: 46128 | E7: 26.5 DS Sprint 1 | F7: Aravindh | G7: 52054 | H7: MSB - Manage Integrations - Add new customer self service page - View REST API integrations | I7: Story Completed | J7: 3 | K7: =Table14567891011121331415171816201921222324252627282930313233343536[[#This Row],[Actual Hours Worklog]] / 4 -> 6.75 | L7: 27 | M7: 46126 | N7: 46121 | O7: Manual (TestCases-5) | P7: Mahesh | Q7: None | R7: Mahesh | S7: No Comments | T7: https://dev.azure.com/heartlandschools/MySchoolBucks/_git/SchoolBucks/pullrequest/48358 https://dev.azure.com/heartlandschools/MySchoolBucks/_git/SchoolBucks/pullrequest/48402 | U7: 46122 | V7: Prisla | W7: 46122 | X7: No Comments | Y7: Alex | Z7: 46125 | AA7: No Comments | AB7: No Comments | AC7: No Comments | AD7: Comment: We upgraded the Java version from 17 to 21. Due to this change, we are facing issues in the local environment. This has increased the time required for development and testing. Time Entries: Aravindh : 18hrs Prisla : 7hrs Nithish : 2hrs
A8: 7 | B8: =Dashboard!$J$1 -> MSB Dev | C8: 46115 | D8: 46128 | E8: 26.5 DS Sprint 1 | F8: Aravindh | G8: 26980 | H8: Datahub - Integration API - Post/PUT fee does not allow $0 fee amount (Tracks) | I8: Defect Fixed | J8: 2 | K8: =Table14567891011121331415171816201921222324252627282930313233343536[[#This Row],[Actual Hours Worklog]] / 4 -> 4.5 | L8: 18 | M8: 46126 | N8: 46127 | O8: Manual (TestCases-35) | P8: Mahesh | Q8: None | R8: Mahesh | S8: No Comments | T8: https://dev.azure.com/heartlandschools/MySchoolBucks/_git/SchoolBucks/pullrequest/48421 | U8: 46127 | V8: Prisla | W8: 46127 | X8: No Comments | Y8: Ken | Z8: 46127 | AA8: No Comments | AB8: The team asked: If we already have a FeeAmount value and the OriginalFeeAmount is 0 or null, why do we need to update the OriginalFeeAmount to 0 or null? when update fee call | AC8: The client’s suggested fee amount is greater than the original fee amount, so we should set the original fee amount to the fee amount. | AD8: Comment: 1. Aravindh has completed his implementation for the committed stories and is currently running out of work, so this committed defect was assigned to him on Apr-14. 2. The acceptance criteria for this defect were not clear, and we had a couple of doubts during the analysis. We requested clarification from the client, and after the acceptance criteria were updated, we started working on it. Time Entries: Aravindh : 12hrs Prisla : 4hrs Nithish : 2hrs
A9: 8 | B9: =Dashboard!$J$1 -> MSB Dev | C9: 46115 | D9: 46128 | E9: 26.5 DS Sprint 1 Stretch | F9: Mahesh | G9: 52426 | H9: MSB - Developer Portal - Update Developer Account ID generation | I9: Story Completed | J9: 2 | K9: =Table14567891011121331415171816201921222324252627282930313233343536[[#This Row],[Actual Hours Worklog]] / 4 -> 4 | L9: 16 | M9: 46121 | N9: 46122 | O9: Manual (TestCases-5) | P9: Prisla | Q9: None | R9: Prisla | S9: No Comments | T9: https://dev.azure.com/heartlandschools/MySchoolBucks/_git/SchoolBucks/pullrequest/48347 | U9: 46122 | V9: Prisla | W9: 46122 | X9: No Comments | Y9: Alex | Z9: 46125 | AA9: No Comments | AB9: No Comments | AC9: No Comments | AD9: The application was upgraded the Java and JBoss versions, which impacted the local environment. Fixing the local environment took additional time, and this was the reason for the delay in implementing the story Time Enrties : Mahesh: 12hrs Prisla: 2hrs Nithish: 2hrs
A10: 9 | B10: =Dashboard!$J$1 -> MSB Dev | C10: 46115 | D10: 46128 | E10: 26.5 DS Sprint 1 Stretch | F10: Mahesh | G10: 52444 | H10: DataHub - API - deprecate HSSConnect API v1 | I10: Story Ready For Testing | J10: 3 | K10: =Table14567891011121331415171816201921222324252627282930313233343536[[#This Row],[Actual Hours Worklog]] / 4 -> 0 | M10: 46125 | N10: 46127 | O10: Manual (TestCases-30) | P10: Aravindh | Q10: None | R10: Aravindh | S10: No Comments | T10: https://dev.azure.com/heartlandschools/MySchoolBucks/_git/SchoolBucks/pullrequest/48419 | U10: 46127 | V10: Prisla | W10: 46127 | X10: No Comments | Y10: Ken | Z10: 46127 | AA10: No Comments | AB10: NA | AC10: NA
A11: 10 | B11: =Dashboard!$J$1 -> MSB Dev | C11: 46115 | D11: 46128 | E11: 26.5 DS Sprint 1 Stretch | F11: Mahesh | G11: 52063 | H11: MobilePay - API - Shifts - Add Credit card subtotals to Close Out (Clark Cty) | I11: Story Being Developed | J11: 3 | K11: =Table14567891011121331415171816201921222324252627282930313233343536[[#This Row],[Actual Hours Worklog]] / 4 -> 0 | M11: 46128
A12: 11 | B12: =Dashboard!$J$1 -> MSB Dev | C12: 46115 | D12: 46128 | E12: 26.5 DS Sprint 1 Stretch | F12: Aravindh | G12: 52831 | H12: MSB – DataHub – Export Classes and Terms to XLSX | I12: Story Being Developed | J12: 5 | K12: =Table14567891011121331415171816201921222324252627282930313233343536[[#This Row],[Actual Hours Worklog]] / 4 -> 0 | M12: 46128

Sheet 26.5 DS Sprint 1-Defect
A1: S.No | B1: Sprint # | C1: Story/Defect ID | D1: Parent Story | E1: Developer | F1: Issue Type | G1: Issue Description | H1: Priority | I1: Defect Source | J1: Type | K1: Status | L1: Root Cause Category | M1: Comments
B2: 26.5 DS Sprint 1 | C2: 27100 | E2: Prisla | F2: Defect | G2: DH - HSS Connect - Include/Exclude filter school not respecting properly after running full sync without any filter | I2: Manual | J2: Internal | K2: Closed | L2: Existing_Issues | M2: Existing issue DH - include/exclude filter school not respecting properly for adapter type HSS Connect
B3: 26.5 DS Sprint 1 | C3: 26980 | E3: Aravindh | F3: Defect | G3: 26980Datahub - Integration API - Post/PUT fee does not allow $0 fee amount (Tracks) | I3: Manual | J3: Internal | K3: Closed | L3: Existing_Issues | M3: Tracks team want to allow $0 fee amount when POST replace existing param as true & PUTfFee
B4: 26.5 DS Sprint 1 | C4: 52054 | E4: Aravindh | F4: Bounceback | G4: In the MSB Dev Portal – Getting Started, a new Integration Type named “MySchoolBucks API,Single Sign-on” is displayed, which is not part of the story requirements. It has been removed | I4: Manual | J4: Internal | K4: Closed | L4: Development | M4: Missed in development
B5: 26.5 DS Sprint 1 | C5: 52054 | E5: Aravindh | F5: Bounceback | G5: If the developer account has both MSB Checkout and REST API, it currently shows “MySchoolBucks, MSB Checkout”. Instead, it should display “MSB Checkout, MySchoolBucks API | I5: Manual | J5: Internal | K5: Closed | L5: Development | M5: Missed in development

Sheet 26.4 DS Sprint 3-Status
A1: S.No | B1: Application Name | C1: Sprint Start Date | D1: Sprint End Date | E1: Sprint | F1: Developer | G1: Story ID/Defect ID | H1: Description | I1: Status | J1: Estimated(hrs/sp) | K1: Actual(hrs/sp) | L1: Actual Hours Worklog | M1: Dev start date | N1: Dev end date | O1: Unit testing | P1: Peer Tested By | Q1: Peer Tested Defects, if any | R1: Peer Reviewed By | S1: Peer Code Review Comments, if any | T1: PR Number/Link | U1: PR Created Date | V1: Reviewer 1 | W1: PR Approved Date | X1: Code Review Comments, if any | Y1: Reviewer 2 | Z1: Approved Date | AA1: Code Review Comments, if any2 | AB1: Internal PO -POV Comments | AC1: Client PO -POV Comments | AD1: Comments
A2: 1 | B2: =Dashboard!$J$1 -> MSB Dev | C2: 46101 | D2: 46114 | E2: 26.4 DS Sprint 3 | F2: Mahesh | G2: 52364 | H2: MSB - REST API - POST/PUT Invoice - Allow create/update for inactive students (MSB Activities)-Automation (26.4) | I2: Story Completed | J2: 2 | K2: =Table145678910111213314151718162019212223242526272829303132333435[[#This Row],[Actual Hours Worklog]] / 4 -> 1.5 | L2: 6 | M2: 46104 | N2: 46105 | O2: NA | P2: Aravindh | Q2: None | R2: Aravindh | S2: No Comments | T2: https://dev.azure.com/heartlandschools/MySchoolBucks/_git/MSBAutomation/pullrequest/47954 | U2: 46104 | V2: Alex | W2: 46105 | X2: No Comments | Y2: NA | Z2: NA | AA2: NA | AB2: NA | AC2: NA | AD2: Time Enrties : Mahesh: 6hrs
A3: 2 | B3: =Dashboard!$J$1 -> MSB Dev | C3: 46101 | D3: 46114 | E3: 26.4 DS Sprint 3 | F3: Mahesh | G3: 52384 | H3: MSB - Manage Integrations - Fee integrations - Respect School filters in data summary | I3: Story Completed | J3: 3 | K3: =Table145678910111213314151718162019212223242526272829303132333435[[#This Row],[Actual Hours Worklog]] / 4 -> 3 | L3: 12 | M3: 46101 | N3: 46101 | O3: Manual (TestCases-10) | P3: Aravindh | Q3: None | R3: Aravindh | S3: No Comments | T3: https://dev.azure.com/heartlandschools/MySchoolBucks/_git/SchoolBucks/pullrequest/47929 | U3: 46101 | V3: George | W3: 46101 | X3: No Comments | Y3: Alex | Z3: 46101 | AA3: No Comments | AB3: No Comments | AC3: No Comments | AD3: Time Enrties : Mahesh: 6hrs Nithish: 6hrs
A4: 3 | B4: =Dashboard!$J$1 -> MSB Dev | C4: 46101 | D4: 46114 | E4: 26.4 DS Sprint 3 | F4: Aravindh | G4: 52369 | H4: Datahub - Developer Account Cleanup - Automation (26.4) | I4: Story Completed | J4: 2 | K4: =Table145678910111213314151718162019212223242526272829303132333435[[#This Row],[Actual Hours Worklog]] / 4 -> 1.5 | L4: 6 | M4: 46099 | N4: 46099 | O4: NA | P4: Mahesh | Q4: No Comments | R4: Mahesh | S4: No Comments | T4: https://dev.azure.com/heartlandschools/MySchoolBucks/_git/MSBAutomation/pullrequest/47847 | U4: 46098 | V4: Alex | W4: 46105 | X4: No Comments | Y4: NA | Z4: NA | AA4: NA | AB4: NA | AC4: NA | AD4: Time Enrties : Aravindh: 6hrs
