Workbook

Sheet Defect-template
A1: S.No | B1: Sprint # | C1: Story/Defect ID | D1: Parent Story | E1: Developer | F1: Issue Type | G1: Issue Description | H1: Priority | I1: Defect Source | J1: Type | K1: Status | L1: Root Cause Category | M1: Comments

Sheet Dashboard
A1: Current Sprint | B1: {=INDEX($B$2:$B$110,MATCH(1,(($D$2:$D$110 >=TODAY())*($C$2:$C$110<=TODAY())),0))} -> 26.07 Sprint 1 | C1: Current Sprint Sheet | D1: =CONCATENATE(B1,"-Status") -> 26.07 Sprint 1-Status | E1: Sprint Start Date | F1: =VLOOKUP($B$1,$B$1:$C$110,2) -> 46136 | G1: Sprint End Date | H1: =VLOOKUP($B$1,$B$1:$D$110,3) -> 46163 | I1: Application Name | J1: FOH | K1: Users | L1: ashwin.maheswaran@relevantz.com;jagan.selvaraj@relevantz.com;alpha.jose@relevantz.com;atchaiah.karumanchi@relevantz.com;arvinthabaskar.reddipalayam@relevantz.com;venkatesan.rangaraj@relevantz.com;sabir.shaikh@relevantz.com;subbulakshmi.namasivayam@relevantz.com;vidhya.subramani@relevantz.com;balamurugan.kandasamy@relevantz.com | M1: Teams Name(GP-Mosaic.FOH) | N1: 19:db174c78ee9b4c94bad431f6465b5e46@thread.v2
A2: Sprint Type | B2: Sprint # | C2: Sprint Start Date | D2: Sprint End Date | E2: Assigned | F2: Completed | G2: Story points introduced/removed | H2: Sprint Summary | I2: Accomplishments | J2: Remarks | K2: Retro Points (Internal & External) | L2: Planned Leaves | M2: Total Leaves | N2: Data sanity Audit Status | O2: AuditDate | P2: Backlog Health
A3: =IF(AND($D$1>=C3,$D$1<=D3),"CurrentSprint","NA") -> NA | B3: 4.15 - Sprint 4 | C3: 45296 | D3: 45309 | E3: 28 | F3: 28 | G3: 0 | J3: Regression Sprint so completed all the modules testing, No code review comments / Defects applicable. Also we fixed few regression defects. | K3: Internal: External:
A4: =IF(AND($D$1>=C4,$D$1<=D4),"CurrentSprint","NA") -> NA | B4: 4.16 - Sprint 1 | C4: 45310 | D4: 45323 | E4: 26 | F4: 23 | G4: 0 | J4: Developers supported to clear the QA backlogs. [Testing Stories = 18, Development Stories = 8 Total Sprint Stories =20 completed = 20; Stretch Stories = 6 completed = 3] | K4: Internal: External:
A5: =IF(AND($D$1>=C5,$D$1<=D5),"CurrentSprint","NA") -> NA | B5: 4.16 - Sprint 2 | C5: 45324 | D5: 45337 | E5: 41 | F5: 39 | G5: 0 | J5: Developers supported to clear the QA backlogs. | K5: Internal: External:
A6: =IF(AND($D$1>=C6,$D$1<=D6),"CurrentSprint","NA") -> NA | B6: 4.16 - Sprint 3 | C6: 45338 | D6: 45351 | E6: 35 | F6: 35 | G6: 0 | J6: Got appreciation for a feature developed in the sprint and also in the sprint review demo from stake holder (#42670) | K6: Internal: External:
A7: =IF(AND($D$1>=C7,$D$1<=D7),"CurrentSprint","NA") -> NA | B7: 4.16 - Sprint 4 | C7: 45352 | D7: 45365 | E7: 19 | F7: 30 | G7: 0 | J7: Stretch Story: 11-SP | K7: Internal: External:
A8: =IF(AND($D$1>=C8,$D$1<=D8),"CurrentSprint","NA") -> NA | B8: 4.16 - Sprint 5 | C8: 45366 | D8: 45379 | E8: 38 | F8: 38 | G8: 0 | J8: Regression Sprint so completed all the modules testing, No code review comments / Defects applicable. Also we fixed few regression defects. Appreciation on Retro:Regression went well | K8: Internal: External:
A9: =IF(AND($D$1>=C9,$D$1<=D9),"CurrentSprint","NA") -> NA | B9: 4.17 - Sprint 1 | C9: 45380 | D9: 45393 | E9: 32 | F9: 32 | J9: Regression wrap up was done in this sprint and along with that completed few stretch stories(Sprint Story only 13SP for the regression wrap up). | K9: Internal: External:
A10: =IF(AND($D$1>=C10,$D$1<=D10),"CurrentSprint","NA") -> NA | B10: 4.17 - Sprint 2 | C10: 45394 | D10: 45407 | E10: 21 | F10: 39 | G10: 0 | J10: Completed all the assigned stories and addition to that completed Stretch Stories - 18 SP. | K10: Internal: External:
A11: =IF(AND($D$1>=C11,$D$1<=D11),"CurrentSprint","NA") -> NA | B11: 4.17 - Sprint 3 | C11: 45408 | D11: 45421 | E11: 29 | F11: 10 | G11: 0 | J11: Completed all the stories - 29 SP in Sprint and 10 SP in stretch. Onsite team was on PTO, so no one there to approve the PR. Carryforwading 21 SP in sprint and 8 SP in stretch to next sprint as per Gary's suggestion. | K11: Internal: External:
A12: =IF(AND($D$1>=C12,$D$1<=D12),"CurrentSprint","NA") -> NA | B12: 4.17 - Sprint 4 | C12: 45422 | D12: 45435 | E12: 13 | F12: 13 | G12: 0 | J12: Regression Sprint(Targeted) so completed all the modules testing, Also we fixed few regression defects. Stretch Story: 5-SP Appreciation on Retro:Regression went well | K12: Internal: External:
A13: =IF(AND($D$1>=C13,$D$1<=D13),"CurrentSprint","NA") -> NA | B13: 4.18 - Sprint 1 | C13: 45436 | D13: 45449 | E13: 40 | F13: 32 | G13: 0 | J13: Carryforwaded one story 8 SP, as POV with onsite team need to done. | K13: Internal: External:
A14: =IF(AND($D$1>=C14,$D$1<=D14),"CurrentSprint","NA") -> NA | B14: 4.18 - Sprint 2 | C14: 45450 | D14: 45463 | E14: 13 | F14: 21 | G14: 0 | J14: Completed all the committed stories. Stretch Story: 8-SP | K14: Internal: External:
A15: =IF(AND($D$1>=C15,$D$1<=D15),"CurrentSprint","NA") -> NA | B15: 4.18 - Sprint 3 | C15: 45464 | D15: 45491 | E15: 44 | F15: 44 | G15: 22 | J15: Completed all the committed stories. Supported to clear the QA backlogs. Stretch Story: 22-SP. Appreciation on Retro: For helping on QA backlogs | K15: Internal: External:
A16: =IF(AND($D$1>=C16,$D$1<=D16),"CurrentSprint","NA") -> NA | B16: 4.18 - Sprint 4 | C16: 45492 | D16: 45505 | E16: 37 | F16: 37 | G16: 37 | J16: No delevopment stories added to sprint. Supported to clear the QA backlogs. Stretch Story: 37-SP. | K16: Internal: External:
A17: =IF(AND($D$1>=C17,$D$1<=D17),"CurrentSprint","NA") -> NA | B17: 4.18 - Sprint 5 | C17: 45506 | D17: 45519 | E17: 15 | F17: 15 | G17: 3 | J17: Completed the committed stories. Supported to clear the QA backlogs. 14-SP completed development and waiting to raise PR. Stretch Story: 3-SP. | K17: Internal: External:
A18: =IF(AND($D$1>=C18,$D$1<=D18),"CurrentSprint","NA") -> NA | B18: 4.18 - Sprint 6 | C18: 45520 | D18: 45533 | E18: 21 | F18: 21 | G18: 7 | J18: Completed the committed stories. Supported to clear the QA backlogs. Stretch Story: 11-SP. | K18: Internal: External:
A19: =IF(AND($D$1>=C19,$D$1<=D19),"CurrentSprint","NA") -> NA | B19: 4.18 - Sprint 7 | C19: 45534 | D19: 45547 | E19: 38 | F19: 38 | G19: 8 | J19: Note: 1. Related to fix for 4.17: There was an issue with Student Import potential match catch logic. From Steve: a parsing issue - the birthdate of 09112009 fails to parse w/the code being used. It's trying to parse with only this pattern MM/dd/yyyy (hardcoded) 2. Related to hotfix for CPS: There was an issue found at MSB end in their API. Data is not being sent to Mosaic due an issue with the date. It can be fixed at either end (MSB or Mosaic) but if is fixed in Mosaic it will be a simple fix because if MSB team fix it may take much more time. The real issue is MSB is expecting for a date time for start and end date. Currently we send only date and due to that data is not pulled properly. Completed all regression stories in sprint. Stretch Story: 8-SP | K19: Internal: External:
A20: =IF(AND($D$1>=C20,$D$1<=D20),"CurrentSprint","NA") -> NA | B20: 4.19 - Sprint 1 | C20: 45548 | D20: 45561 | E20: 31 | F20: 31 | G20: 0 | J20: CRC Internal -- 2 CRC External -- 0 QA Defects -- 3 (1-Rejected) Escaped Defects -- 0 Completed all the committed stories. Supported to clear the QA backlogs. Stretch Story: 18-SP. 45834 is POC which is Carry Forwarded | K20: Internal: External: Appreciation on Retro: For helping on QA backlogs
A21: =IF(AND($D$1>=C21,$D$1<=D21),"CurrentSprint","NA") -> NA | B21: 4.19 - Sprint 2 | C21: 45562 | D21: 45589 | E21: 33 | F21: 45.5 | G21: Introduced - 12.5 | J21: CRC Internal -- 4 CRC External -- 0 QA Defects -- 8 (2-Rejected) Escaped Defects -- 0 Supported to clear the QA backlogs. Stretch Story: 20-SP. | K21: Internal: Alpha recieved appreciation for support in dashboard. Jagan and Arvinth recieved appreciation for good presentation in sprint review. External: Recieved appreciation from Tino for Dashbord Story done by Subha. Appreciation on Retro: For helping on QA backlogs
A22: =IF(AND($D$1>=C22,$D$1<=D22),"CurrentSprint","NA") -> NA | B22: 4.19 - Sprint 3 | C22: 45590 | D22: 45603 | E22: 16 | F22: 35 | G22: Introduced - 19 | I22: Feature Flags, Student Barcode Report Update, Louisiana SFS-8A Report update, and Defects | J22: CRC Internal -- 0 CRC External -- 1 QA Defects -- 2 Escaped Defects -- 0 Supported to clear the QA backlogs. Stretch Story: 19-SP. | K22: Internal: External:
A23: =IF(AND($D$1>=C23,$D$1<=D23),"CurrentSprint","NA") -> NA | B23: 4.19 - Sprint 4 | C23: 45604 | D23: 45617 | E23: 25 | F23: 33 | G23: Introduced - 8 | I23: Improvements to Scheduler Task, Showing Actual Bank Deposit Amount in Online Payment Detail Report, Update to Alachua Meal Count export(2 decimal places to labor hours), and Defects | J23: CRC Internal -- 0 CRC External -- 0 QA Defects -- 3 (2-Rejected) Escaped Defects -- 0 Stretch Story: 8-SP. | K23: Internal: Online payment report story done without any deviation. External:
A24: =IF(AND($D$1>=C24,$D$1<=D24),"CurrentSprint","NA") -> NA | B24: 4.19 - Sprint 5 | C24: 45618 | D24: 45645 | E24: 60 | F24: 70 | G24: Introduced - 10 | I24: Add Ability to Print Machine Info, Add date of inactive to Student Maintenance, Add Notes to Elig Record Report, Add Active Filter to User Assignments Report, Defects, and then begin 4.19 Regression Testing. | J24: CRC Internal -- 2 CRC External -- 1 QA Defects -- 3 Escaped Defects -- 0 Stretch Story: 10-SP. | K24: Internal:Change comment,Change in adding the SQL paramer External:Merge conflict with revision history
A25: =IF(AND($D$1>=C25,$D$1<=D25),"CurrentSprint","NA") -> NA | B25: 4.20 - Sprint 1 | C25: 45646 | D25: 45673 | E25: 35 | F25: 46 | G25: Introduced - 12 | I25: multiple Defects for 4.19 and complete 4.19 Regression, Add report for “Schools not in School Group”, and Add new report type to POS Roster Reports | J25: Release Date - March 2025 (Tentative) CRC Internal -- 1 CRC External -- 0 QA Defects -- 15 (1-Rejected) Escaped Defects -- 0 Stretch Story: 12-SP. | K25: Internal: External: Appreciation on Retro: For helping on QA backlogs
A26: =IF(AND($D$1>=C26,$D$1<=D26),"CurrentSprint","NA") -> NA | B26: 4.20 - Sprint 2 | C26: 45674 | D26: 45687 | E26: 22 | F26: 27 | G26: Introduced - 5 | I26: Menu Management Improvements(Assign POS Menus to multiple POS numbers & Re-Alphabetize Menu Products), Dashboard update(CPS), Speed-e Mode option to fulfill Meal Order or not, and use CEP Reimbursement Calculations in Claim Report(KDE) | J26: Release Date - March 2025 (Tentative) CRC Internal -- 0 CRC External -- 0 QA Defects -- 0 Escaped Defects -- 0 Stretch Story: 5-SP. | K26: Internal: External: Appreciation on Retro: Mike(QA) appreciated for helping on QA backlogs
A27: =IF(AND($D$1>=C27,$D$1<=D27),"CurrentSprint","NA") -> NA | B27: 4.20 - Sprint 3 | C27: 45688 | D27: 45701 | E27: 25 | F27: 31 | G27: Introduced - 6 | I27: Add Student Effective Date and Eligibility Reason to Student Maint., Attaching Verification Reports, Add Serving Period Program and Serving Period droplist to Special Provision Edit Check Report, Performance Improvements to Imports(CPS), and Defect Fixes | J27: Release Date - March 2025 (Tentative) CRC Internal -- 0 CRC External -- 0 QA Defects -- 0 Escaped Defects -- 0 Stretch Story: 6-SP. | K27: Internal: External: Appreciation on Retro: Mike(QA) appreciated for helping on QA backlogs
A28: =IF(AND($D$1>=C28,$D$1<=D28),"CurrentSprint","NA") -> NA | B28: 4.20 - Sprint 4 | C28: 45702 | D28: 45715 | E28: 38 | F28: 38 | G28: Introduced - 0 | I28: 4.20 Regression Testing | J28: Release Date - March 2025 (Tentative) CRC Internal -- 0 CRC External -- 0 QA Defects -- 13 Escaped Defects -- 0 Stretch Story: 0 | K28: Internal: External: Appreciation on Retro: Mike(QA) appreciated for helping on QA backlogs and Regression Testing completion
A29: =IF(AND($D$1>=C29,$D$1<=D29),"CurrentSprint","NA") -> NA | B29: 4.21 - Sprint 1 | C29: 45716 | D29: 45729 | E29: 26 | F29: 31 | G29: Introduced - 5 | I29: Tyler-MUNIS Financial Export(NC), Adding Checks to Student Account Summary Report, Label Format Options to Barcode Report | J29: CRC Internal -- 4 CRC External -- 0 QA Defects -- 0 Escaped Defects -- 0 Stretch Story: 0 | K29: Internal: External:
A30: =IF(AND($D$1>=C30,$D$1<=D30),"CurrentSprint","NA") -> NA | B30: 4.21 - Sprint 2 | C30: 45730 | D30: 45743 | E30: 32 | F30: 32 | G30: Introduced - 0 | I30: North Carolina Export, Ability to see transactions marked for review(SL), A La Carte Report Update, Ability to Add Transactions after Re-opening a day, and adding CEP ISP calculations to Chartwell’s Export | J30: CRC Internal -- 1 CRC External -- 2 QA Defects -- 0 Escaped Defects -- 0 Stretch Story: 0 | K30: Internal: External: Appreciation on Retro: Mike(QA) appreciated for helping on QA backlogs
A31: =IF(AND($D$1>=C31,$D$1<=D31),"CurrentSprint","NA") -> NA | B31: 4.21 - Sprint 3 | C31: 45744 | D31: 45757 | E31: 31 | F31: 34 | G31: Introduced - 3 | I31: CPS Dashboard Improvements, IEG Updates, ‘Carryover Expiration Date’ added as Import field, adding, NC SFS-4 Export update, and Adding ISP values for Mult schools. | J31: CRC Internal -- 3 CRC External -- 1 QA Defects -- 0 Escaped Defects -- 0 Stretch Story: 0 | K31: Internal: External:
A32: =IF(AND($D$1>=C32,$D$1<=D32),"CurrentSprint","NA") -> NA | B32: 4.21 - Sprint 4 | C32: 45758 | D32: 45771 | E32: 41 | F32: 33 | G32: Introduced - 0 | I32: 4.21 Regression Testing | J32: CRC Internal -- 1 CRC External -- 0 QA Defects -- 3 Escaped Defects -- 0 Stretch Story: 0 | K32: Internal: External: Appreciation for completing most of the regression stories eventhough it is a full regression
A33: =IF(AND($D$1>=C33,$D$1<=D33),"CurrentSprint","NA") -> NA | B33: 4.22 - Sprint 1 | C33: 45772 | D33: 45785 | E33: 35 | F33: 31 | G33: Introduced - 3 | I33: Wrap up 4.21 Regression(Defects found), Adding new templates to Custom Reports, Tier Model, Add Menu Product Sold Qtys to Daily Sales Preview, and MSB Reconciliation. | J33: CRC Internal -- 5 CRC External -- 0 QA Defects -- 2 Escaped Defects -- 0 Stretch Story: 0 | K33: Internal: External:
... A44: =IF(AND($D$1>=C44,$D$1<=D44),"CurrentSprint","NA") -> NA | B44: 4.25 - Sprint 1 | C44: 45926 | D44: 45939 | E44: 22 | F44: 31 | G44: Introduced - 23 | I44: Modifications to Operating Days, new filter for ‘Participation by’ to Standard Claim Report | J44: CRC Internal -- 0 Peer testing - 0 CRC External -- 0 QA Defects --1 Escaped Defects -- 0 POV Comments - 0 Stretch Story: 7 | K44: Internal: External: What went well: Completed more than Forecast , Esclations (not too bad this week), mike completed testing before PTO, Team completed rest of testing after Mike PTO What didn't go well: Apigee issue (platformops and apigee team)
A45: =IF(AND($D$1>=C45,$D$1<=D45),"CurrentSprint","NA") -> NA | B45: 4.25 - Sprint 2 | C45: 45940 | D45: 45953 | E45: 26 | F45: 26 | G45: Introduced - 18 | H45: New Dashboard Widgets, Ability to flip between Apigee & Existing endpoints, ‘Participation By’ filter to Supplemental Programs Claim Report, Tyler Munis Export Modifications, update to VA SNP-12 Report, Add Active Flag to Student Export Setup, and 4.24 Release Prep | I45: New Dashboard Widgets, Ability to flip between Apigee & Existing endpoints,Tyler Munis Export Modifications, update to VA SNP-12 Report, Add Active Flag to Student Export Setup, and 4.24 Release Prep. | J45: CRC Internal -- 2 Peer testing - 0 CRC External -- 0 QA Defects -- 0 Escaped Defects -- 0 POV Comments - 0 Stretch Story: 4 | K45: Internal: External: completed more than forecast
A46: =IF(AND($D$1>=C46,$D$1<=D46),"CurrentSprint","NA") -> NA | B46: 4.25 - Sprint 3 | C46: 45954 | D46: 45967 | E46: 33 | F46: 38 | G46: Introduced - 21 | H46: Adding a Student Debt Chart to the Dashboard, Replacing Master Serving Period with Serving Period Program, New ‘Group By School’ filter to Students w/out an Elig. Determination Report, DC Import Improvements, and NJ Master Eligibility List report Modifications | I46: Adding a Student Debt Chart to the Dashboard, New ‘Group By School’ filter to Students w/out an Elig. Determination Report, DC Import Improvements, and NJ Master Eligibility List report Modifications | J46: CRC Internal -- 1 Peer testing - 0 CRC External -- 0 QA Defects -- 1 Escaped Defects -- 0 POV Comments - 0 Stretch Story: 9 | K46: Internal: External: What went well: Releases, Exceeded Forecast What didn't go well: Esclations (Note: Esclations from coustomer support are handled by client developer Steve)
A47: =IF(AND($D$1>=C47,$D$1<=D47),"CurrentSprint","NA") -> NA | B47: 4.25 - Sprint 4 | C47: 45968 | D47: 45981 | E47: 22 | F47: 28 | G47: Introduced - 11 | H47: IL WINS Export Scheduler Task, Importing Custom Report Format, Close Year Updates, New ‘Letter Sent Status’ filter to Student Letters, Defect Fixes | I47: Close Year screen updates, Letter sent status in student letter, Import Format in Custom report, MSA Client Communication, NSSID in Visual Report, Defect Fixes | J47: CRC Internal -- 3 Peer testing - 1 CRC External -- 0 QA Defects -- 0 Escaped Defects -- 0 POV Comments - 0 Stretch Story: 10 | K47: Internal: External: What went well: Hit Forecast, SYNK progress in stretch What didn't go well: CPS Release, Apigee work, MSB Endpoint Change.
A48: =IF(AND($D$1>=C48,$D$1<=D48),"CurrentSprint","NA") -> NA | B48: 4.25 - Sprint 5 | C48: 45982 | D48: 46009 | E48: 52 | F48: 57 | G48: Introduced - 13 | H48: Remediating SNYK Findings, New Templates for Custom Reports, New Data Sources for Report Designer, and 4.25 Regression Testing | I48: Completed Synk findings critical issues, completed 4.25 regression testing with defect fixes. | J48: CRC Internal -- 0 Peer testing - 1 CRC External -- 0 QA Defects -- 0 Escaped Defects -- 0 POV Comments - 0 Stretch Story: 6 | K48: Internal: External: What went well: Insane no.of stories completed(Sp's), started using Browser Stack for automation. What didn't go well: Escalations, MSB Endpoint Change.(Note: Esclations from coustomer support are handled by client developer Steve)
A49: =IF(AND($D$1>=C49,$D$1<=D49),"CurrentSprint","NA") -> NA | B49: 26.1 - Sprint 1 | C49: 46010 | D49: 46037 | E49: 33 | F49: 49 | G49: Introduced - 29 | H49: Support for Multiple Languages in SL, Add Report Type filter to Student Meal Report, Add ‘Student Notes’ and ‘Elig. Record Notes’ to Custom Student Report, Adding ‘Serving Line Note changes’ & ‘Grade changes’ to Event Type filter for Student History Report, and Automation | I49: Completed adding Report Type filter to Student Meal Report, Adding ‘Student Notes’ and ‘Elig. Record Notes’ to Custom Student Report, Adding ‘Serving Line Note changes’ & ‘Grade changes’ to Event Type filter for Student History Report, and Automation | J49: CRC Internal -- 1 Peer testing - 2 CRC External -- 0 QA Defects -- 0 Escaped Defects -- 0 POV Comments - 0 Stretch Story: 13 | K49: Internal: External: What went well: Completed the forecast and almost the same in the stretch. 2. Holidays. 3. 502 gateway Apigee issues solving (prod) What didn't go well: 365 migration, MSB from www to etransfer issue.
A50: =IF(AND($D$1>=C50,$D$1<=D50),"CurrentSprint","NA") -> NA | B50: 26.1 - Sprint 2 | C50: 46038 | D50: 46051 | E50: 35 | F50: 41 | G50: Introduced -17 | H50: Add “Required for all Students” to System Setting for MSB Spending Limits, New Report Type to Meal Report, Add Bank Deposit Report as a Close Day Report, and Mosaic BOH Knowledge transfer. | I50: Completed adding “Required for all Students” to System Setting for MSB Spending Limits, New Report Type to Meal Report, Bank Deposit Report as a Close Day Report | J50: CRC Internal -- 1 Peer testing - 1 CRC External -- 0 QA Defects -- 1 Escaped Defects -- 0 POV Comments - 1 Stretch Story: 10 CRC RC: update script was not included and the temp table was not dropped before initialization | K50: Internal: External: What went well: Completed commit and stretch items. 2. 4.24 Hot fix/4.25 Beta 3. BOH KT What didn't go well: 1. Vending QA, 2. Missing App switcher script in 4.25 Beta 3. App switcher button is not always working. Recieved appretiaton from QA during retro that offshore helped to close the testing stories during the sprint end.
...

Sheet 26.07 Sprint 1-Status
A1: S.No | B1: Application Name | C1: Sprint Start Date | D1: Sprint End Date | E1: Sprint | F1: Developer | G1: Story ID/Defect ID | H1: Description | I1: Status | J1: Estimated(hrs/sp) | K1: Actual(hrs/sp) | L1: Actual Worklog (Hours) | M1: Dev Start Date | N1: Dev End Date | O1: Unit testing | P1: Peer Tested By | Q1: Peer Tested Comments, if any | R1: Peer Reviewed By | S1: Peer Code Review Comments, if any | T1: PR Number/Link | U1: PR Created Date | V1: PR Approved Date | W1: Onsite Lead Code Review | X1: Code Review Comments, if any | Y1: Client Code Review | Z1: Approved Date | AA1: Code Review Comments, if any2 | AB1: Internal PO -POV Comments | AC1: Client PO -POV Comments | AD1: Comments | AE1: Does this story meet expectations?
A2: 1 | B2: FOH | C2: 46136 | D2: 46163 | E2: 26.07 Sprint 1 | F2: Alpha/Atchaiah | G2: 52794 | H2: Mosaic - FOH 26.5 (Regression) - Reports - Eligibility (F&R) | I2: Story Completed | J2: 3 | K2: 6 | L2: 24 | M2: 46136 | N2: 46155 | O2: NA | P2: NA | Q2: NA | R2: NA | S2: NA | T2: NA | U2: NA | V2: NA | W2: NA | X2: NA | Y2: NA | Z2: NA | AA2: NA | AB2: NA | AC2: NA | AD2: Regression Testing
A3: 2 | B3: FOH | C3: 46136 | D3: 46163 | E3: 26.07 Sprint 1 | F3: Atchaiah/Alpha | G3: 52791 | H3: Mosaic - FOH 26.5(Regression) - Utilities | I3: Story Completed | J3: 5 | K3: 11 | L3: 44 | M3: 46136 | N3: 46155 | O3: NA | P3: NA | Q3: NA | R3: NA | S3: NA | T3: NA | U3: NA | V3: NA | W3: NA | X3: NA | Y3: NA | Z3: NA | AA3: NA | AB3: NA | AC3: NA | AD3: Regression Testing
A4: 3 | B4: FOH | C4: 46136 | D4: 46163 | E4: 26.07 Sprint 1 | F4: Arvinth | G4: 52796 | H4: Mosaic - FOH 26.5(Regression) - Reports - (Excluding Free/Reduced) | I4: Story Completed | J4: 8 | K4: 11.75 | L4: 47 | M4: 46136 | N4: 46155 | O4: NA | P4: NA | Q4: NA | R4: NA | S4: NA | T4: NA | U4: NA | V4: NA | W4: NA | X4: NA | Y4: NA | Z4: NA | AA4: NA | AB4: NA | AC4: NA | AD4: Regression Testing
A5: 4 | B5: FOH | C5: 46136 | D5: 46163 | E5: 26.07 Sprint 1 | F5: Atchaiah | G5: 52649 | H5: MFOH [BAU] - Automation (51453) | I5: Story Completed | J5: 1 | K5: 1 | L5: 4 | M5: 46140 | N5: 46140 | O5: NA | P5: NA | Q5: NA | R5: NA | S5: NA | T5: 48710 | U5: 46140 | V5: 46140 | W5: NA | X5: NA | Y5: Steve | Z5: 46140 | AA5: None | AB5: NA | AC5: NA
A6: 5 | B6: FOH | C6: 46136 | D6: 46163 | E6: 26.07 Sprint 1 | F6: Atchaiah | G6: 52650 | H6: MFOH [BAU] - Automation (50645) | I6: Story Completed | J6: 3 | K6: 3 | L6: 12 | M6: 46141 | N6: 46142 | O6: NA | P6: NA | Q6: NA | R6: NA | S6: NA | T6: 48889 | U6: 46148 | V6: 46148 | W6: NA | X6: NA | Y6: Steve | Z6: 46148 | AA6: None | AB6: NA | AC6: NA
A7: 8 | B7: FOH | C7: 46136 | D7: 46163 | E7: 26.07 Sprint 1 | F7: Alpha | G7: 52854 | H7: Mosaic FOH - Snyk Findings - Path Traversal - UtilitiesController.cs- Unsanitized input flows into global::System.IO.StreamWriter - Part 2 | I7: Story Completed | J7: 3 | K7: 2 | L7: 8 | M7: 46148 | N7: 46149 | O7: Alpha | P7: Arvinth | Q7: None | R7: Arvinth | S7: None | T7: 48960 | U7: 46153 | V7: 46153 | W7: NA | X7: NA | Y7: Ying | Z7: 46153 | AA7: None | AB7: NA | AC7: NA
A8: 10 | B8: FOH | C8: 46136 | D8: 46163 | E8: 26.07 Sprint 1 | F8: Alpha | G8: 52450 | H8: MFOH - Convert the Carriage return in the Serving Line Notes (Student Import) | I8: Story Being Developed | J8: 2 | K8: 1 | L8: 4 | M8: 46153
A9: 18 | B9: FOH | C9: 46136 | D9: 46163 | E9: 26.07 Sprint 1 | F9: Arvinth | G9: 52851 | H9: Mosaic FOH - Snyk Findings - Path Traversal - UtilitiesController.cs- Unsanitized input flows into global::System.IO.Directory.Exists- Part 2 | I9: Story Completed | J9: 3 | K9: 2.5 | L9: 10 | M9: 46149 | N9: 46150 | O9: Arvinth | P9: Alpha | Q9: None | R9: Alpha | S9: None | T9: 48966 | U9: 46153 | V9: 46153 | W9: Venkat | X9: None | Y9: Ying | Z9: 46153 | AA9: None | AB9: None | AC9: NA
A10: 21 | B10: FOH | C10: 46136 | D10: 46163 | E10: 26.07 Sprint 1 | F10: Arvinth | G10: 27157 | H10: MFoH - (Regression 26.5) Custom Report Import - Clicking Cancel button on import screen throws error | I10: Story Completed | J10: 3 | K10: 1.75 | L10: 7 | M10: 46150 | N10: 46153 | O10: Arvinth | P10: Alpha | Q10: None | R10: Alpha | S10: None | T10: 48991 | U10: 46154 | V10: 46154 | W10: Venkat | X10: None | Y10: Ying | Z10: 46154 | AA10: None | AB10: None | AC10: NA
A11: 6 | B11: FOH | C11: 46136 | D11: 46163 | E11: 26.07 Sprint 1 | F11: Alpha | G11: 27345 | H11: MFOH (26.5 Regression) - Error records are shown in Add count for Test Import Data | I11: Story Completed | J11: 0 | K11: 0 | L11: 0 | M11: 46146 | N11: 46147 | O11: Alpha | P11: Arvinth | Q11: None | R11: Arvinth | S11: Add conditional return ststement. | T11: 48881 | U11: 46148 | V11: 46148 | W11: Venkat | X11: None | Y11: Ying | Z11: 46148 | AA11: None | AB11: NA | AC11: NA | AD11: Regression Defects
A12: 7 | B12: FOH | C12: 46136 | D12: 46163 | E12: 26.07 Sprint 1 | F12: Alpha | G12: 27346 | H12: MFOH (26.5 Regression) - Import Name is partially displayed when there is a dot in the Name | I12: Story Completed | J12: 0 | K12: 0 | L12: 0 | M12: 46147 | N12: 46147 | O12: Alpha | P12: Arvinth | Q12: None | R12: Arvinth | S12: None | T12: 48882 | U12: 46148 | V12: 46148 | W12: Venkat | X12: None | Y12: Ying | Z12: 46148 | AA12: None | AB12: NA | AC12: NA | AD12: Regression Defects
A13: 11 | B13: FOH | C13: 46136 | D13: 46163 | E13: 26.07 Sprint 1 | F13: Arvinth | G13: 27336 | H13: MFOH (26.5 Regression) - Throwing error when Serving Line Note is more then 150 characters | I13: Story Completed | J13: 0 | K13: 0 | L13: 0 | M13: 46146 | N13: 46146 | O13: Arvinth | P13: Alpha | Q13: None | R13: Alpha | S13: None | T13: 48846 | U13: 46147 | V13: 46147 | W13: NA | X13: NA | Y13: Ying | Z13: 46147 | AA13: None | AB13: NA | AC13: NA | AD13: Regression Defects
A14: 12 | B14: FOH | C14: 46136 | D14: 46163 | E14: 26.07 Sprint 1 | F14: Arvinth | G14: 27340 | H14: MFOH (26.5 Regression) - Louisiana SFS-7 Report Data tab, table sort design issue | I14: Story Completed | J14: 0 | K14: 0 | L14: 0 | M14: 46146 | N14: 46146 | O14: Arvinth | P14: Alpha | Q14: None | R14: Alpha | S14: None | T14: 48847 | U14: 46147 | V14: 46147 | W14: NA | X14: NA | Y14: Ying | Z14: 46147 | AA14: None | AB14: NA | AC14: NA | AD14: Regression Defects
A15: 13 | B15: FOH | C15: 46136 | D15: 46163 | E15: 26.07 Sprint 1 | F15: Arvinth | G15: 27342 | H15: MFOH (26.5 Regression) - Getting console error in Report Sharing Setup | I15: Story Completed | J15: 0 | K15: 0 | L15: 0 | M15: 46146 | N15: 46146 | O15: Arvinth | P15: Alpha | Q15: None | R15: Alpha | S15: None | T15: 48848 | U15: 46147 | V15: 46147 | W15: NA | X15: NA | Y15: Ying | Z15: 46147 | AA15: None | AB15: NA | AC15: NA | AD15: Regression Defects
A16: 14 | B16: FOH | C16: 46136 | D16: 46163 | E16: 26.07 Sprint 1 | F16: Arvinth | G16: 27337 | H16: MFOH (26.5 Regression) - A console error occurs when values are entered into the text box in the Kentucky D2 Report | I16: Story Completed | J16: 0 | K16: 0 | L16: 0 | M16: 46147 | N16: 46147 | O16: Arvinth | P16: Alpha | Q16: None | R16: Alpha | S16: None | T16: 48885 | U16: 46148 | V16: 46148 | W16: NA | X16: NA | Y16: Ying | Z16: 46148 | AA16: None | AB16: NA | AC16: NA | AD16: Regression Defects
A17: 15 | B17: FOH | C17: 46136 | D17: 46163 | E17: 26.07 Sprint 1 | F17: Arvinth | G17: 27338 | H17: MFOH (26.5 Regression) - A console error occurs when values are entered into the text box in the Louisiana SFS-7 Report | I17: Story Completed | J17: 0 | K17: 0 | L17: 0 | M17: 46147 | N17: 46147 | O17: Arvinth | P17: Alpha | Q17: None | R17: Alpha | S17: None | T17: 48886 | U17: 46148 | V17: 46148 | W17: NA | X17: NA | Y17: Ying | Z17: 46148 | AA17: None | AB17: NA | AC17: NA | AD17: Regression Defects
A18: 16 | B18: FOH | C18: 46136 | D18: 46163 | E18: 26.07 Sprint 1 | F18: Arvinth | G18: 27339 | H18: MFOH (26.5 Regression) - A console error occurs when values are entered into the text box in the Louisiana SFS-8B Report | I18: Story Completed | J18: 0 | K18: 0 | L18: 0 | M18: 46147 | N18: 46147 | O18: Arvinth | P18: Alpha | Q18: None | R18: Alpha | S18: None | T18: 48887 | U18: 46148 | V18: 46148 | W18: NA | X18: NA | Y18: Ying | Z18: 46148 | AA18: None | AB18: NA | AC18: NA | AD18: Regression Defects
A19: 17 | B19: FOH | C19: 46136 | D19: 46163 | E19: 26.07 Sprint 1 | F19: Arvinth | G19: 27341 | H19: MFOH (26.5 Regression) - A console error occurs when values are entered into the text box in the Virginia SNP-14 Report | I19: Story Completed | J19: 0 | K19: 0 | L19: 0 | M19: 46147 | N19: 46147 | O19: Arvinth | P19: Alpha | Q19: None | R19: Alpha | S19: None | T19: 48888 | U19: 46148 | V19: 46148 | W19: NA | X19: NA | Y19: Ying | Z19: 46148 | AA19: None | AB19: NA | AC19: NA | AD19: Regression Defects
A20: 9 | B20: FOH | C20: 46136 | D20: 46163 | E20: 26.07 Sprint 1 Stretch | F20: Atchaiah | G20: 53167 | H20: MFOH [BAU] - Automation (51454) | I20: Story Being Developed | J20: 3 | M20: 46149
A21: 19 | B21: FOH | C21: 46136 | D21: 46163 | E21: 26.07 Sprint 1 Stretch | F21: Alpha | G21: 48515 | H21: MFOH [WAVE] - Add a Language tab to Student Status | I21: Story Being Developed | J21: 5 | K21: 2.5 | L21: 10
A22: 20 | B22: FOH | C22: 46136 | D22: 46163 | E22: 26.07 Sprint 1 Stretch | F22: Atchaiah | G22: 53272 | H22: MFOH - Automation (Kaleida Changes) | I22: Story Being Developed | J22: 3 | M22: 46155
A23: 22 | B23: FOH | C23: 46136 | D23: 46163 | E23: 26.07 Sprint 1 Stretch | F23: Arvinth | G23: 52175 | H23: [WAVE] Mosaic FOH - Language - Menu Product Translation | I23: Story Being Developed | J23: 13 | K23: 1.5 | L23: 6 | M23: 46156

Sheet 26.07 Sprint 1-Defect
A1: S.No | B1: Sprint # | C1: Story/Defect ID | D1: Parent Story | E1: Developer | F1: Issue Type | G1: Issue Description | H1: Priority | I1: Defect Source | J1: Type | K1: Status | L1: Root Cause Category | M1: Comments
B2: 26.07 Sprint 1 | D2: 51323 | E2: Sabir | F2: Defect | G2: The partial view 'VoidReasonMaintenance_General' was not found | H2: Major | I2: Manual | J2: External | K2: Defect Fixed | L2: Development | M2: Missed commiting file before PR

Sheet 26.05 Sprint 4-Status
A1: S.No | B1: Application Name | C1: Sprint Start Date | D1: Sprint End Date | E1: Sprint | F1: Developer | G1: Story ID/Defect ID | H1: Description | I1: Status | J1: Estimated(hrs/sp) | K1: Actual(hrs/sp) | L1: Actual Worklog (Hours) | M1: Dev Start Date | N1: Dev End Date | O1: Unit testing | P1: Peer Tested By | Q1: Peer Tested Comments, if any | R1: Peer Reviewed By | S1: Peer Code Review Comments, if any | T1: PR Number/Link | U1: PR Created Date | V1: PR Approved Date | W1: Onsite Lead Code Review | X1: Code Review Comments, if any | Y1: Client Code Review | Z1: Approved Date | AA1: Code Review Comments, if any2 | AB1: Internal PO -POV Comments | AC1: Client PO -POV Comments | AD1: Comments | AE1: Does this story meet expectations?
A2: 1 | B2: FOH | C2: 46122 | D2: 46135 | E2: 26.05 Sprint 4 | F2: Alpha/Atchaiah | G2: 52792 | H2: Mosaic - FOH 26.5 (Regression) - Eligibility (F&R) | I2: Story Completed | J2: 5 | K2: 7.75 | L2: 31 | M2: 46122 | N2: 46127 | O2: NA | P2: NA | Q2: NA | R2: NA | S2: NA | T2: NA | U2: NA | V2: NA | W2: NA | X2: NA | Y2: NA | Z2: NA | AA2: NA | AB2: NA | AC2: NA | AD2: We also fixed regression defects in this story
A3: 2 | B3: =Dashboard!$J$1 -> FOH | C3: 46122 | D3: 46135 | E3: 26.05 Sprint 4 | F3: Ashwin/Atchaiah | G3: 52788 | H3: Mosaic - FOH 26.5(Regression) - End of Day | I3: Story Completed | J3: 5 | K3: 5.75 | L3: 23 | M3: 46122 | N3: 46132 | O3: NA | P3: NA | Q3: NA | R3: NA | S3: NA | T3: NA | U3: NA | V3: NA | W3: NA | X3: NA | Y3: NA | Z3: NA | AA3: NA | AB3: NA | AC3: NA | AD3: We also fixed regression defects in this story
A4: 3 | B4: =Dashboard!$J$1 -> FOH | C4: 46122 | D4: 46135 | E4: 26.05 Sprint 4 | F4: Ashwin/Atchaiah | G4: 52790 | H4: Mosaic - FOH 26.5 (Regression) - POS(Menu Option) | I4: Story Completed | J4: 2 | K4: 2.75 | L4: 11 | M4: 46126 | N4: 46128 | O4: NA | P4: NA | Q4: NA | R4: NA | S4: NA | T4: NA | U4: NA | V4: NA | W4: NA | X4: NA | Y4: NA | Z4: NA | AA4: NA | AB4: NA | AC4: NA | AD4: We also fixed regression defects in this story
A5: 4 | B5: =Dashboard!$J$1 -> FOH | C5: 46122 | D5: 46135 | E5: 26.05 Sprint 4 | F5: Atchaiah/Venkat | G5: 52787 | H5: Mosaic - FOH 26.5(Regression) - Students | I5: Story Completed | J5: 5 | K5: 2.5 | L5: 30.5 | M5: 46122 | N5: 46129 | O5: NA | P5: NA | Q5: NA | R5: NA | S5: NA | T5: NA | U5: NA | V5: NA | W5: NA | X5: NA | Y5: NA | Z5: NA | AA5: NA | AB5: NA | AC5: NA | AD5: We also fixed regression defects in this story
A6: 5 | B6: =Dashboard!$J$1 -> FOH | C6: 46122 | D6: 46135 | E6: 26.05 Sprint 4 | F6: Atchaiah/Subbu | G6: 52797 | H6: Mosaic - FOH 26.5(Regression) - Setup | I6: Story Completed | J6: 8 | K6: 10.25 | L6: 41 | M6: 46122 | N6: 46129 | O6: NA | P6: NA | Q6: NA | R6: NA | S6: NA | T6: NA | U6: NA | V6: NA | W6: NA | X6: NA | Y6: NA | Z6: NA | AA6: NA | AB6: NA | AC6: NA | AD6: We also fixed regression defects in this story
A7: 6 | B7: FOH | C7: 46122 | D7: 46135 | E7: 26.05 Sprint 4 | F7: Alpha | G7: 52335 | H7: Mosaic FOH - QA/PM - Spending Limits from MSB - End-to-End Test in Prod | I7: Story Completed | J7: 1 | K7: 1 | L7: 4 | M7: NA | N7: NA | O7: NA | P7: NA | Q7: NA | R7: NA | S7: NA | T7: NA | U7: NA | V7: NA | W7: NA | X7: NA | Y7: NA | Z7: NA | AA7: NA | AB7: NA | AC7: NA | AD7: Manual Testing story
A8: 7 | B8: FOH | C8: 46122 | D8: 46135 | E8: 26.05 Sprint 4 | F8: Ashwin | G8: 27239 | H8: MFOH (26.5 Regression) - In Open Previous Day, apply filter is not working after clicking reset selection in any filter | I8: Defect Fixed | J8: 0 | K8: 0 | L8: 0 | M8: 46132 | N8: 46132 | O8: Ashwin | P8: Arvinth | Q8: None | R8: Alpha | S8: None | T8: 48589 | U8: 46134 | V8: 46134 | W8: NA | X8: NA | Y8: Ying | Z8: 46134 | AA8: None | AB8: NA | AC8: NA | AD8: Regression defect
A9: 8 | B9: FOH | C9: 46122 | D9: 46135 | E9: 26.05 Sprint 4 | F9: Ashwin | G9: 27240 | H9: MFOH (26.5 Regression) - Checkbox is unchecking after clicking cancel | I9: Defect Fixed | J9: 0 | K9: 0 | L9: 0 | M9: 46132 | N9: 46132 | O9: Ashwin | P9: Arvinth | Q9: None | R9: Alpha | S9: Remove unwanted code | T9: 48590 | U9: 46134 | V9: 46134 | W9: NA | X9: NA | Y9: Ying | Z9: 46134 | AA9: None | AB9: NA | AC9: NA | AD9: Regression defect
A10: 9 | B10: FOH | C10: 46122 | D10: 46135 | E10: 26.05 Sprint 4 | F10: Ashwin | G10: 27250 | H10: MFOH (26.5 Regression) - While trying to assign a Bus/Route using an existing Route Name, a validation message appears. After clicking OK on the error | I10: Defect Fixed | J10: 0 | K10: 0 | L10: 0 | M10: 46134 | N10: 46134 | O10: Ashwin | P10: Arvinth | Q10: None | R10: Alpha | S10: None | T10: 48593 | U10: 46134 | V10: 46134 | W10: NA | X10: NA | Y10: Ying | Z10: 46134 | AA10: None | AB10: NA | AC10: NA | AD10: Regression defect
A11: 10 | B11: FOH | C11: 46122 | D11: 46135 | E11: 26.05 Sprint 4 | F11: Arvinth | G11: 27242 | H11: MFOH (26.5 Regression) - Horizontal/VerticalScroll bar is showing in Employee screen | I11: Defect Fixed | J11: 0 | K11: 0 | L11: 0 | M11: 46132 | N11: 46132 | O11: Arvinth | P11: NA | Q11: NA | R11: NA | S11: NA | T11: 48544 | U11: 46133 | V11: 46133 | W11: NA | X11: NA | Y11: Ying | Z11: 46133 | AA11: None | AB11: NA | AC11: NA | AD11: Regression defect
A12: 11 | B12: FOH | C12: 46122 | D12: 46135 | E12: 26.05 Sprint 4 | F12: Arvinth | G12: 27244 | H12: MFOH (26.5 Regression) - Horizontal Scroll bar is showing in Meals Price Template popup | I12: Defect Fixed | J12: 0 | K12: 0 | L12: 0 | M12: 46132 | N12: 46132 | O12: Arvinth | P12: NA | Q12: NA | R12: NA | S12: NA | T12: 48545 | U12: 46133 | V12: 46133 | W12: NA | X12: NA | Y12: Ying | Z12: 46133 | AA12: None | AB12: NA | AC12: NA | AD12: Regression defect
A13: 12 | B13: FOH | C13: 46122 | D13: 46135 | E13: 26.05 Sprint 4 | F13: Arvinth/Venkat | G13: 27245 | H13: MFOH (26.5 Regression) - Meal Price Template is not showing while adding or updating the Menu product images | I13: Defect Fixed | J13: 0 | K13: 0 | L13: 0 | M13: 46134 | N13: 46134 | O13: Arvinth | P13: NA | Q13: NA | R13: NA | S13: NA | T13: 48599 | U13: 46134 | V13: 46134 | W13: NA | X13: NA | Y13: Ying | Z13: 46134 | AA13: None | AB13: NA | AC13: NA | AD13: Regression defect
A14: 13 | B14: FOH | C14: 46122 | D14: 46135 | E14: 26.05 Sprint 4 | F14: Arvinth | G14: 27246 | H14: MFOH (26.5 Regression) - In Vega UI, Not getting "No Manager Servers Found" error message popup | I14: Defect Fixed | J14: 0 | K14: 0 | L14: 0 | M14: 46132 | N14: 46132 | O14: Arvinth | P14: NA | Q14: NA | R14: NA | S14: NA | T14: 48546 | U14: 46134 | V14: 46134 | W14: NA | X14: NA | Y14: Ying | Z14: 46134 | AA14: None | AB14: NA | AC14: NA | AD14: Regression defect
A15: 14 | B15: FOH | C15: 46122 | D15: 46135 | E15: 26.05 Sprint 4 | F15: Venkat | G15: 27248 | H15: MFOH (26.5 Regression) - If I Uncheck any row checkbox then the header checkbox is unchecked | I15: Defect Fixed | J15: 0 | K15: 0 | L15: 0 | M15: 46132 | N15: 46132 | O15: Venkat | P15: Arvinth | Q15: None | R15: Arvinth | S15: None | T15: 48553 | U15: 46133 | V15: 46133 | W15: NA | X15: NA | Y15: Ying | Z15: 46133 | AA15: None | AB15: NA | AC15: NA | AD15: Regression defect
A16: 15 | B16: FOH | C16: 46122 | D16: 46135 | E16: 26.05 Sprint 4 | F16: Venkat | G16: 27249 | H16: MFOH (26.5 Regression) - Check all checkbox not unchecking when any of the below row checkbox is unchecked | I16: Defect Fixed | J16: 0 | K16: 0 | L16: 0 | M16: 46132 | N16: 46132 | O16: Venkat | P16: Arvinth | Q16: None | R16: Arvinth | S16: None | T16: 48554 | U16: 46133 | V16: 46133 | W16: NA | X16: NA | Y16: Ying | Z16: 46133 | AA16: None | AB16: NA | AC16: NA | AD16: Regression defect
A17: 16 | B17: FOH | C17: 46122 | D17: 46135 | E17: 26.05 Sprint 4 | F17: Venkat | G17: 27251 | H17: MFOH (26.5 Regression) - Sorting is not working properly in Student Search | I17: Defect Fixed | J17: 0 | K17: 0 | L17: 0 | M17: 46134 | N17: 46134 | O17: Venkat | P17: Arvinth | Q17: None | R17: Arvinth | S17: None | T17: 48592 | U17: 46134 | V17: 46134 | W17: NA | X17: NA | Y17: Ying | Z17: 46134 | AA17: None | AB17: NA | AC17: NA | AD17: Regression defect
A18: 17 | B18: FOH | C18: 46122 | D18: 46135 | E18: 26.05 Sprint 4 Stretch | F18: Alpha | G18: 27213 | H18: MFOH - Fix the dashboard issues with Save in Edit Mode and the character length of site | I18: Story Ready For Testing | J18: 2 | K18: 0.75 | L18: 3 | M18: 46128 | N18: 46128 | O18: Alpha | P18: NA | Q18: NA | R18: NA | S18: NA | T18: 48468 | U18: 46128 | V18: 46128 | W18: NA | X18: NA | Y18: Steve | Z18: 46128 | AA18: None | AB18: NA | AC18: NA
A19: 18 | B19: FOH | C19: 46122 | D19: 46135 | E19: 26.05 Sprint 4 Stretch | F19: Atchaiah | G19: 52649 | H19: MFOH [BAU] - Automation (51453) | I19: Story Being Developed | J19: 1 | M19: 46122 | AD19: Carry forward due to release regression.
A20: 19 | B20: FOH | C20: 46122 | D20: 46135 | E20: 26.05 Sprint 4 Stretch | F20: Venkat | G20: 52827 | H20: MFOH - Update Federal IEGs (2026-27) | I20: Story Ready For Testing | J20: 2 | K20: 1.5 | L20: 6 | M20: 46122 | N20: 46125 | O20: Venkat | P20: Alpha | Q20: None | R20: Alpha | S20: None | T20: 48388 | U20: 46125 | V20: 46125 | W20: NA | X20: NA | Y20: Steve | Z20: 46125 | AA20: None | AB20: None | AC20: None
A21: 20 | B21: FOH | C21: 46122 | D21: 46135 | E21: 26.05 Sprint 4 Stretch | F21: Alpha | G21: 52794 | H21: Mosaic - FOH 26.5 (Regression) - Reports - Eligibility (F&R) | I21: Story Being Tested | J21: 3 | M21: 46127
A22: 21 | B22: FOH | C22: 46122 | D22: 46135 | E22: 26.05 Sprint 4 Stretch | F22: Atchaiah | G22: 52791 | H22: Mosaic - FOH 26.5(Regression) - Utilities | I22: Story Being Tested | J22: 5 | K22: 1.5 | L22: 6

Sheet 26.05 Sprint 4-Defect
A1: S.No | B1: Sprint # | C1: Story/Defect ID | D1: Parent Story | E1: Developer | F1: Issue Type | G1: Issue Description | H1: Priority | I1: Defect Source | J1: Type | K1: Status | L1: Root Cause Category | M1: Comments
B2: 26.05 Sprint 4 | C2: 27245 | D2: NA | E2: Arvinth/Venkat | F2: Bounceback/Sub-Defect | G2: MFOH (26.5 Regression) - Meal Price Template is not showing while adding or updating the Menu product images | H2: Minor | I2: Manual | J2: Internal | K2: Defect Fixed | L2: Existing_Issues | M2: Data not retaining while uploading image

Sheet 26.05 Sprint 3-Status
A1: S.No | B1: Application Name | C1: Sprint Start Date | D1: Sprint End Date | E1: Sprint | F1: Developer | G1: Story ID/Defect ID | H1: Description | I1: Status | J1: Estimated(hrs/sp) | K1: Actual(hrs/sp) | L1: Actual Worklog (Hours) | M1: Dev Start Date | N1: Dev End Date | O1: Unit testing | P1: Peer Tested By | Q1: Peer Tested Comments, if any | R1: Peer Reviewed By | S1: Peer Code Review Comments, if any | T1: PR Number/Link | U1: PR Created Date | V1: PR Approved Date | W1: Onsite Lead Code Review | X1: Code Review Comments, if any | Y1: Client Code Review | Z1: Approved Date | AA1: Code Review Comments, if any2 | AB1: Internal PO -POV Comments | AC1: Client PO -POV Comments | AD1: Comments | AE1: Does this story meet expectations?
A2: 1 | B2: FOH | C2: 46108 | D2: 46121 | E2: 26.05 Sprint 3 | F2: Arvinth/Venkat | G2: 51698 | H2: Mosaic FOH - Snyk Findings - Path Traversal - UtilitiesController.cs- Unsanitized input flows into global::System.IO.Directory.Exists | I2: Story Completed | J2: 5 | K2: 4.75 | L2: 18 | M2: 46119 | N2: 46120 | O2: Venkat | P2: Ashwin | Q2: None | R2: Alpha | S2: None | T2: 48316 | U2: 46120 | V2: 46120 | W2: NA | X2: NA | Y2: Steve | Z2: 46120 | AA2: None | AB2: NA | AC2: NA
A3: 2 | B3: FOH | C3: 46108 | D3: 46121 | E3: 26.05 Sprint 3 | F3: Atchaiah | G3: 52527 | H3: MFOH-FOHBetaReleaseCheckOut Test changes update | I3: Story Completed | J3: 2 | K3: 2 | L3: 8 | M3: 46107 | N3: 46108 | O3: NA | P3: NA | Q3: NA | R3: NA | S3: NA | T3: 48057 | U3: 46108 | V3: 46108 | W3: NA | X3: NA | Y3: Steve | Z3: 46108 | AA3: None | AB3: NA | AC3: NA
A4: 3 | B4: FOH | C4: 46108 | D4: 46121 | E4: 26.05 Sprint 3 | F4: Ashwin | G4: 52372 | H4: MFOH [WAVE] - Add a 'Reimbursable Meal' column to Real Time Transactions grid | I4: Story Completed | J4: 3 | K4: 1.5 | L4: 6 | M4: 46108 | N4: 46111 | O4: Ashwin | P4: Arvinth | Q4: None | R4: Arvinth | S4: None | T4: 48169 | U4: 46113 | V4: 46113 | W4: NA | X4: NA | Y4: Steve | Z4: 46113 | AA4: None | AB4: NA | AC4: NA
A5: 4 | B5: FOH | C5: 46108 | D5: 46121 | E5: 26.05 Sprint 3 | F5: Alpha/Subbu | G5: 51891 | H5: MFOH [WAVE] - Modify the Dashboard Setup Maintenance (Allow to add Widgets one by one) | I5: Story Completed | J5: 5 | K5: 1.5 | L5: 6 | M5: 46108 | N5: 46111 | O5: Alpha | P5: Subbu | Q5: 2 new peer testing comments; the new parameter name was not replaced in all the areas. Additionally, we have fixed the 3 existing issues as well. | R5: NA | S5: NA | T5: NA | U5: NA | V5: NA | W5: NA | X5: NA | Y5: NA | Z5: NA | AA5: NA | AB5: NA | AC5: NA
A6: 5 | B6: FOH | C6: 46108 | D6: 46121 | E6: 26.05 Sprint 3 | F6: Ashwin | G6: 52328 | H6: MFOH - Modify the labels in the Home Site when the student has an offsite sale in a different school | I6: Story Completed | J6: 3 | K6: 1.25 | L6: 5 | M6: 46112 | N6: 46114 | O6: Ashwin | P6: Arvinth | Q6: None | R6: Arvinth | S6: None | T6: 48168 | U6: 46113 | V6: 46113 | W6: NA | X6: NA | Y6: Steve | Z6: 46113 | AA6: None | AB6: NA | AC6: NA
A7: 6 | B7: FOH | C7: 46108 | D7: 46121 | E7: 26.05 Sprint 3 | F7: Alpha | G7: 27127 | H7: MFOH - The SAVE is broken (Custom Reports) | I7: Story Being Tested | J7: 2 | K7: 0.75 | L7: 3 | M7: 46118 | N7: 46118 | O7: Alpha | P7: NA | Q7: NA | R7: Venkat | S7: None | T7: 48242 | U7: 46118 | V7: 46118 | W7: NA | X7: NA | Y7: Steve | Z7: 46118 | AA7: None | AB7: NA | AC7: NA | AD7: Testing is in progress by Oniste QA.
A8: 7 | B8: FOH | C8: 46108 | D8: 46121 | E8: 26.05 Sprint 3 | F8: Alpha | G8: 27136 | H8: MFOH - Custom Report Import Format is broken | I8: Story Completed | J8: 2 | K8: 0.75 | L8: 3 | M8: 46118 | N8: 46118 | O8: Alpha | P8: NA | Q8: NA | R8: Venkat | S8: None | T8: 48243 | U8: 46118 | V8: 46118 | W8: NA | X8: NA | Y8: Steve | Z8: 46118 | AA8: None | AB8: NA | AC8: NA
A9: 8 | B9: FOH | C9: 46108 | D9: 46121 | E9: 26.05 Sprint 3 | F9: Alpha | G9: 51697 | H9: Mosaic FOH - Snyk Findings - Path Traversal - UtilitiesController.cs- Unsanitized input flows into global::System.IO.StreamWriter | I9: Story Completed | J9: 2 | K9: 0 | L9: 0 | M9: NA | N9: NA | O9: NA | P9: NA | Q9: NA | R9: NA | S9: NA | T9: NA | U9: NA | V9: NA | W9: NA | X9: NA | Y9: NA | Z9: NA | AA9: NA | AB9: NA | AC9: NA
A10: 9 | B10: FOH | C10: 46108 | D10: 46121 | E10: 26.05 Sprint 3 | F10: Ashwin/Alpha | G10: 26996 | H10: MFOH - Daily School Attendance Import - Add support to import 0 as an attendance number | I10: Story Completed | J10: 1 | K10: 0.5 | L10: 2 | M10: 46119 | N10: 46119 | O10: Ashwin | P10: Alpha | Q10: None | R10: Arvinth | S10: None | T10: 48270 | U10: 46119 | V10: 46119 | W10: NA | X10: NA | Y10: Steve | Z10: 46119 | AA10: None | AB10: NA | AC10: NA
A11: 10 | B11: FOH | C11: 46108 | D11: 46121 | E11: 26.05 Sprint 3 | F11: Ashwin/Alpha | G11: 26902 | H11: MFOH - POS Roster Report Serving Line Note Length | I11: Story Completed | J11: 2 | K11: 2 | L11: 8 | M11: 46119 | N11: 46119 | O11: Ashwin | P11: Alpha | Q11: None | R11: Arvinth | S11: None | T11: 48271 | U11: 46119 | V11: 46119 | W11: NA | X11: NA | Y11: Steve | Z11: 46119 | AA11: None | AB11: NA | AC11: NA
A12: 11 | B12: FOH | C12: 46108 | D12: 46121 | E12: 26.05 Sprint 3 | F12: Atchaiah | G12: 49620 | H12: [WAVE] Mosaic FOH- Test Import of Student Application data into Mosaic from WebSMARTT | I12: Story Completed | J12: 2 | K12: 2 | L12: 8 | M12: 46119 | N12: 46120 | O12: NA | P12: NA | Q12: NA | R12: NA | S12: NA | T12: NA | U12: NA | V12: NA | W12: NA | X12: NA | Y12: NA | Z12: NA | AA12: NA | AB12: NA | AC12: NA
A13: 12 | B13: FOH | C13: 46108 | D13: 46121 | E13: 26.05 Sprint 3 | F13: Venkat | G13: 27125 | H13: MFOH - Meal Report - Aggerate Totals: No - Does not list schools in order | I13: Story Completed | J13: 2 | K13: 1.25 | L13: 5 | M13: 46120 | N13: 46120 | O13: Venkat | P13: Alpha | Q13: None | R13: Alpha | S13: None | T13: 48251 | U13: 46118 | V13: 46118 | W13: NA | X13: NA | Y13: Steve | Z13: 46118 | AA13: 46118 | AB13: NA | AC13: NA
A14: 13 | B14: FOH | C14: 46108 | D14: 46121 | E14: 26.05 Sprint 3 | F14: Atchaiah | G14: 49622 | H14: [WAVE] Mosaic FOH- Test Import of Student Application history data into Mosaic from WebSMARTT | I14: Story Completed | J14: 1 | K14: 1 | L14: 4 | M14: 46120 | N14: 46121 | O14: NA | P14: NA | Q14: NA | R14: NA | S14: NA | T14: NA | U14: NA | V14: NA | W14: NA | X14: NA | Y14: NA | Z14: NA | AA14: NA | AB14: NA | AC14: NA
A15: 14 | B15: FOH | C15: 46108 | D15: 46121 | E15: 26.05 Sprint 3 | F15: Atchaiah | G15: 49623 | H15: [WAVE] Mosaic FOH- Test Import of POS transactions data into Mosaic from WebSMARTT | I15: Story Completed | J15: 1 | K15: 1 | L15: 4 | M15: 46121 | N15: 46121 | O15: NA | P15: NA | Q15: NA | R15: NA | S15: NA | T15: NA | U15: NA | V15: NA | W15: NA | X15: NA | Y15: NA | Z15: NA | AA15: NA | AB15: NA | AC15: NA
A16: 15 | B16: FOH | C16: 46108 | D16: 46121 | E16: 26.05 Sprint 3 | F16: Atchaiah | G16: 49624 | H16: [WAVE] Mosaic FOH- Test Import of Student Record history data into Mosaic from WebSMARTT | I16: Story Completed | J16: 1 | K16: 1 | L16: 4 | M16: 46121 | N16: 46121 | O16: NA | P16: NA | Q16: NA | R16: NA | S16: NA | T16: NA | U16: NA | V16: NA | W16: NA | X16: NA | Y16: NA | Z16: NA | AA16: NA | AB16: NA | AC16: NA
A17: 16 | B17: FOH | C17: 46108 | D17: 46121 | E17: 26.05 Sprint 3 Stretch | F17: Venkat | G17: 52256 | H17: Mosaic FOH - Open Previous Day Maintenance - Add Multiselect Site & Convert Screen to Vega | I17: Story Being Developed | J17: 3 | K17: 2 | L17: 8 | M17: 46108 | N17: 46115 | O17: Venkat | P17: Alpha | Q17: Error during delete the existing entry. | R17: Alpha | S17: Revision histories, commented codes and formatting, unused codes and improvements to the codes. | AD17: Moved into stretch and worked on the remaining sprint items.
A18: 17 | B18: FOH | C18: 46108 | D18: 46121 | E18: 26.05 Sprint 3 Stretch | F18: Atchaiah | G18: 52569 | H18: MFOH [BAU] - Automation (51314) | I18: Story Completed | J18: 2 | K18: 2 | L18: 8 | M18: 46111 | N18: 46112 | O18: NA | P18: NA | Q18: NA | R18: NA | S18: NA | T18: 48162 | U18: 46113 | V18: 46113 | W18: NA | X18: NA | Y18: Steve | Z18: 46113 | AA18: None | AB18: NA | AC18: NA
A19: 18 | B19: FOH | C19: 46108 | D19: 46121 | E19: 26.05 Sprint 3 Stretch | F19: Atchaiah | G19: 52570 | H19: MFOH [BAU] - Automation (49449) | I19: Story Completed | J19: 1 | K19: 1 | L19: 4 | M19: 46113 | N19: 46114 | O19: NA | P19: NA | Q19: NA | R19: NA | S19: NA | T19: 48211 | U19: 46114 | V19: 46114 | W19: NA | X19: NA | Y19: Steve | Z19: 46114 | AA19: None | AB19: NA | AC19: NA
A20: 19 | B20: FOH | C20: 46108 | D20: 46121 | E20: 26.05 Sprint 3 Stretch | F20: Arvinth/Ashwin | G20: 51944 | H20: Mosaic FOH - Implement New Design for the Admin View of Real-time Transactions | I20: Story Completed | J20: 13 | K20: 8.5 | L20: 34 | M20: 46111 | N20: 46114 | O20: Arvinth/Ashwin | P20: Alpha | Q20: Increase the grid height. Apply filter is not enabling sometimes. | R20: Alpha | S20: None | T20: 48322 | U20: 46121 | V20: 46121 | W20: NA | X20: NA | Y20: Steve | Z20: 46121 | AA20: None | AB20: NA | AC20: NA
A21: 20 | B21: FOH | C21: 46108 | D21: 46121 | E21: 26.05 Sprint 3 Stretch | F21: Atchaiah | G21: 52649 | H21: MFOH [BAU] - Automation (51453) | I21: Story Being Developed | J21: 1 | K21: 0 | L21: 0 | M21: 46118 | AD21: Kept on hold due to test legacy import sprint items

Sheet 26.05 Sprint 3-Defect
A1: S.No | B1: Sprint # | C1: Story/Defect ID | D1: Parent Story | E1: Developer | F1: Issue Type | G1: Issue Description | H1: Priority | I1: Defect Source | J1: Type | K1: Status | L1: Root Cause Category | M1: Comments

Sheet 26.5 - Sprint 2-Status
A1: S.No | B1: Application Name | C1: Sprint Start Date | D1: Sprint End Date | E1: Sprint | F1: Developer | G1: Story ID/Defect ID | H1: Description | I1: Status | J1: Estimated(hrs/sp) | K1: Actual(hrs/sp) | L1: Actual Worklog (Hours) | M1: Dev Start Date | N1: Dev End Date | O1: Unit testing | P1: Peer Tested By | Q1: Peer Tested Comments, if any | R1: Peer Reviewed By | S1: Peer Code Review Comments, if any | T1: PR Number/Link | U1: PR Created Date | V1: PR Approved Date | W1: Onsite Lead Code Review | X1: Code Review Comments, if any | Y1: Client Code Review | Z1: Approved Date | AA1: Code Review Comments, if any2 | AB1: Internal PO -POV Comments | AC1: Client PO -POV Comments | AD1: Comments | AE1: Does this story meet expectations?
A2: 1 | B2: FOH | C2: 46094 | D2: 46107 | E2: 26.5 - Sprint 2 | F2: Arvinth | G2: 52287 | H2: Mosaic FOH - Exports - Tyler Technologies Financial Export (Cherokee County Schools, SC) | I2: Story Completed | J2: 13 | K2: 9 | L2: 36 | M2: 46094 | N2: 46106 | O2: Arvinth | P2: Ashwin | Q2: None | R2: Alpha | S2: None | T2: 48019 | U2: 46106 | V2: 46106 | W2: NA | X2: NA | Y2: Steve | Z2: 46106 | AA2: None | AB2: None | AC2: None | AE2: Meets Expectation
A3: 2 | B3: FOH | C3: 46094 | D3: 46107 | E3: 26.5 - Sprint 2 | F3: Atchaiah | G3: 52279 | H3: MFOH - Automation (Professional standards screens) | I3: Story Completed | J3: 2 | K3: 2 | L3: 8 | M3: 46094 | N3: 46097 | O3: NA | P3: NA | Q3: NA | R3: NA | S3: NA | T3: 47856 | U3: 46098 | V3: 46098 | W3: NA | X3: NA | Y3: Steve | Z3: 46098 | AA3: None | AB3: NA | AC3: NA | AE3: Meets Expectation
A4: 3 | B4: FOH | C4: 46094 | D4: 46107 | E4: 26.5 - Sprint 2 | F4: Ashwin | G4: 52229 | H4: Mosaic FOH - Custom Reports - Sort Alphabetically | I4: Story Completed | J4: 3 | K4: 1.5 | L4: 6 | M4: 46094 | N4: 46097 | O4: Ashwin | P4: Arvinth | Q4: None | R4: Arvinth | S4: None | T4: 47860 | U4: 46098 | V4: 46098 | W4: NA | X4: NA | Y4: Steve | Z4: 46098 | AA4: None | AB4: None | AC4: None | AE4: Meets Expectation
A5: 4 | B5: FOH | C5: 46094 | D5: 46107 | E5: 26.5 - Sprint 2 | F5: Ashwin | G5: 26967 | H5: MFOH (26.1) - Close Day - Reopened By does not list the User | I5: Story Completed | J5: 3 | K5: 1.5 | L5: 6 | M5: 46097 | N5: 46098 | O5: Ashwin | P5: Arvinth | Q5: None | R5: Arvinth | S5: None | T5: 47859 | U5: 46098 | V5: 46098 | W5: NA | X5: NA | Y5: Steve | Z5: 46098 | AA5: None | AB5: None | AC5: None | AE5: Meets Expectation
A6: 5 | B6: FOH | C6: 46094 | D6: 46107 | E6: 26.5 - Sprint 2 | F6: Atchaiah | G6: 52338 | H6: Mosaic FOH - QA - POS API Apigee; WAF (Time Log) | I6: Story Completed | J6: 8 | K6: 3.75 | L6: 15 | M6: 46101 | N6: 46105 | O6: NA | P6: NA | Q6: NA | R6: NA | S6: NA | T6: NA | U6: NA | V6: NA | W6: NA | X6: NA | Y6: NA | Z6: NA | AA6: NA | AB6: NA | AC6: NA | AD6: carryforwaded from the client as we get WAF issues in server
A7: 6 | B7: FOH | C7: 46094 | D7: 46107 | E7: 26.5 - Sprint 2 | F7: Venkat | G7: 52253 | H7: MFOH - Bundle Sites based on Site ID (Georgia DE106 Export) | I7: Story Completed | J7: 3 | K7: 2.87 | L7: 11.5 | M7: 46094 | N7: 46098 | O7: Venkat | P7: Ashwin | Q7: NA | R7: Arvinth | S7: NA | T7: 47932 | U7: 46101 | V7: 46101 | W7: NA | X7: NA | Y7: Steve | Z7: 46101 | AA7: None | AB7: None | AC7: None | AE7: Meets Expectation
A8: 7 | B8: FOH | C8: 46094 | D8: 46107 | E8: 26.5 - Sprint 2 Stretch | F8: Atchaiah | G8: 52331 | H8: MFOH - Automation - Kaleida changes update to the Report Scheduler | I8: Story Completed | J8: 2 | K8: 2 | L8: 12 | M8: 46098 | N8: 46099 | O8: NA | P8: NA | Q8: NA | R8: NA | S8: NA | T8: 47893 | U8: 46099 | V8: 46099 | W8: NA | X8: NA | Y8: Steve | Z8: 46099 | AA8: None | AB8: NA | AC8: NA | AD8: Worked on the Professional standards screens for 1SP additionally. | AE8: Meets Expectation
A9: 8 | B9: FOH | C9: 46094 | D9: 46107 | E9: 26.5 - Sprint 2 Stretch | F9: Arvinth | G9: 52420 | H9: MFOH - Create a Script to generate some sample data from Prod sites for Aramark | I9: Story Completed | J9: 3 | K9: 3 | L9: 12 | M9: 46099 | N9: 46100 | O9: Arvinth | P9: NA | Q9: NA | R9: NA | S9: NA | T9: NA | U9: NA | V9: NA | W9: NA | X9: NA | Y9: NA | Z9: NA | AA9: NA | AB9: NA | AC9: NA | AD9: Gary requested this script | AE9: Meets Expectation
A10: 9 | B10: FOH | C10: 46094 | D10: 46107 | E10: 26.5 - Sprint 2 Stretch | F10: Alpha | G10: 51891 | H10: MFOH [WAVE] - Modify the Dashboard Setup Maintenance (Allow to add Widgets one by one) | I10: Story Ready For Testing | J10: 13 | K10: 10.5 | L10: 42 | M10: 46094 | N10: 46106 | O10: Alpha | P10: Subbulakshmi | Q10: Cosmetic issues, existing Dashboard is not working properly for the new implementation | R10: Arvinth | S10: Label change, Missing parameter in one method. | T10: 48024 | U10: 46106 | V10: 46106 | W10: NA | X10: NA | Y10: Steve | Z10: 46106 | AA10: None
A11: 10 | B11: FOH | C11: 46094 | D11: 46107 | E11: 26.5 - Sprint 2 Stretch | F11: Venkat | G11: 52256 | H11: Mosaic FOH - Open Previous Day Maintenance - Add Multiselect Site & Convert Screen to Vega | I11: Story Being Developed | J11: 5 | K11: 4.5 | L11: 18 | M11: 46101
A12: 11 | B12: FOH | C12: 46094 | D12: 46107 | E12: 26.5 - Sprint 2 Stretch | F12: Ashwin | G12: 51944 | H12: [WAVE] Mosaic FOH - Implement New Design for the Admin View of Real-time Transactions | I12: Story Being Developed | J12: 13 | K12: 0 | L12: 0 | M12: 46098
A13: 12 | B13: FOH | C13: 46094 | D13: 46107 | E13: 26.5 - Sprint 2 Stretch | F13: Ashwin | G13: 26996 | H13: MFOH - Daily School Attendance Import - Add support to import 0 as an attendance number | I13: Story Being Developed | J13: 0 | K13: 0 | L13: 0 | M13: 46099
A14: 13 | B14: FOH | C14: 46094 | D14: 46107 | E14: 26.5 - Sprint 2 Stretch | F14: Ashwin | G14: 26902 | H14: MFOH - POS Roster Report Serving Line Note Length | I14: Story Being Developed | J14: 2 | K14: 0 | L14: 0 | M14: 46100

Sheet 26.5 - Sprint 2-Defect
A1: S.No | B1: Sprint # | C1: Story/Defect ID | D1: Parent Story | E1: Developer | F1: Issue Type | G1: Issue Description | H1: Priority | I1: Defect Source | J1: Type | K1: Status | L1: Root Cause Category | M1: Comments

Sheet 26.5 - Sprint 1-Status
A1: S.No | B1: Application Name | C1: Sprint Start Date | D1: Sprint End Date | E1: Sprint | F1: Developer | G1: Story ID/Defect ID | H1: Description | I1: Status | J1: Estimated(hrs/sp) | K1: Actual(hrs/sp) | L1: Actual Worklog (Hours) | M1: Dev Start Date | N1: Dev End Date | O1: Unit testing | P1: Peer Tested By | Q1: Peer Tested Comments, if any | R1: Peer Reviewed By | S1: Peer Code Review Comments, if any | T1: PR Number/Link | U1: PR Created Date | V1: PR Approved Date | W1: Onsite Lead Code Review | X1: Code Review Comments, if any | Y1: Client Code Review | Z1: Approved Date | AA1: Code Review Comments, if any2 | AB1: Internal PO -POV Comments | AC1: Client PO -POV Comments | AD1: Comments | AE1: Does this story meet expectations?
A2: 1 | B2: FOH | C2: 46080 | D2: 46093 | E2: 26.5 - Sprint 1 | F2: Alpha/Atchaiah | G2: 51934 | H2: Mosaic - FOH 26.1(Regression) - Reports - (Excluding Free/Reduced) | I2: Story Completed | J2: 8 | K2: 9.75 | L2: 39 | M2: 46080 | N2: 46092 | O2: NA | P2: NA | Q2: NA | R2: NA | S2: NA | T2: NA | U2: NA | V2: NA | W2: NA | X2: NA | Y2: NA | Z2: NA | AA2: NA | AB2: NA | AC2: NA | AD2: We also fixed regression defects in this story
A3: 2 | B3: FOH | C3: 46080 | D3: 46093 | E3: 26.5 - Sprint 1 | F3: Atchaiah | G3: 51931 | H3: Mosaic - FOH 26.1 (Regression) - Reports - Eligibility (F&R) | I3: Story Completed | J3: 3 | K3: 3.75 | L3: 15 | M3: 46080 | N3: 46092 | O3: NA | P3: NA | Q3: NA | R3: NA | S3: NA | T3: NA | U3: NA | V3: NA | W3: NA | X3: NA | Y3: NA | Z3: NA | AA3: NA | AB3: NA | AC3: NA | AD3: We also fixed regression defects in this story
A4: 3 | B4: FOH | C4: 46080 | D4: 46093 | E4: 26.5 - Sprint 1 | F4: Ashwin/Arvinth/Atchaiah | G4: 51938 | H4: Mosaic - FOH 26.1(Regression) - Setup | I4: Story Completed | J4: 8 | K4: 10.5 | L4: 42 | M4: 46080 | N4: 46092 | O4: NA | P4: NA | Q4: NA | R4: NA | S4: NA | T4: NA | U4: NA | V4: NA | W4: NA | X4: NA | Y4: NA | Z4: NA | AA4: NA | AB4: NA | AC4: NA | AD4: We also fixed regression defects in this story
A5: 4 | B5: FOH | C5: 46080 | D5: 46093 | E5: 26.5 - Sprint 1 | F5: Subha | G5: 26862 | H5: MFOH (26.1 release) - Dashboard resulted twice when searched through the search option | I5: Story Completed | J5: 2 | K5: 1.75 | L5: 7 | M5: 46080 | N5: 46080 | O5: Subha | P5: Alpha | Q5: None | R5: Alpha | S5: None | T5: 47629 | U5: 46086 | V5: 46086 | W5: NA | X5: NA | Y5: Steve | Z5: 46086 | AA5: None | AB5: None | AC5: NA
A6: 5 | B6: FOH | C6: 46080 | D6: 46093 | E6: 26.5 - Sprint 1 | F6: Alpha | G6: 52034 | H6: Mosaic FOH - Tyler Munis Financial Export - ROA/RFD Calculation Modification | I6: Story Completed | J6: 3 | K6: 2.5 | L6: 10 | M6: 46085 | N6: 46087 | O6: Alpha | P6: Ashwin | Q6: None | R6: Arvinth | S6: None | T6: 47673 | U6: 46090 | V6: 46090 | W6: NA | X6: NA | Y6: Steve | Z6: 46090 | AA6: None | AB6: None | AC6: NA
A7: 6 | B7: FOH | C7: 46080 | D7: 46093 | E7: 26.5 - Sprint 1 | F7: Arvinth | G7: 52026 | H7: Mosaic FOH - Add new field District.MSBID (to 26.5) | I7: Story Completed | J7: 2 | K7: 1.5 | L7: 6 | M7: 46086 | N7: 46087 | O7: Arvinth | P7: Ashwin | Q7: None | R7: Alpha | S7: None | T7: 47676 | U7: 46090 | V7: 46090 | W7: NA | X7: NA | Y7: Steve | Z7: 46090 | AA7: None | AB7: None | AC7: NA
A8: 7 | B8: FOH | C8: 46080 | D8: 46093 | E8: 26.5 - Sprint 1 | F8: Arvinth | G8: 52103 | H8: Mosaic FOH - Pendo Snippet Updates, Phase 1 | I8: Story Completed | J8: 3 | K8: 1.25 | L8: 5 | M8: 46090 | N8: 46091 | O8: Arvinth | P8: Ashwin | Q8: None | R8: Alpha | S8: None | T8: 47719 | U8: 46091 | V8: 46091 | W8: NA | X8: NA | Y8: Steve | Z8: 46091 | AA8: None | AB8: None | AC8: NA
