Workbook

Sheet Dashboard
A1: Current Sprint | B1: {=INDEX($B$2:$B$101,MATCH(1,(($D$2:$D$101 >=TODAY())*($C$2:$C$101<=TODAY())),0))} -> 26.7 M Sprint 1 | C1: Current Sprint Sheet | D1: =CONCATENATE(B1,"-Status") -> 26.7 M Sprint 1-Status | E1: Sprint Start Date | F1: =VLOOKUP($B$1,$B$1:$C$101,2) -> 46157 | G1: Sprint End Date | H1: =VLOOKUP($B$1,$B$1:$D$101,3) -> 46170 | I1: Application NAme | J1: MSB Mobile | K1: Users | L1: sambath.selvam@relevantz.com;rupesh.kumar@relevantz.com;vaishnavi.shanmugavel@relevantz.com;ashwin.majella@relevantz.com;premkumar.rajendran@relevantz.com;bavithra.arasakumaran@relevantz.com;gursewak.jaspal@relevantz.com;amrit.harjit@relevantz.com;jagdeep.singh@relevantz.com | M1: Teams Name(GP-MSB.Mobile) | N1: 19:aa5856a8e6e3487ab79589431d926322@thread.v2
A2: Sprint Type | B2: Sprint # | C2: Sprint Start Date | D2: Sprint End Date | E2: Assigned | F2: Completed | G2: Story Points Story points introduced/removed | H2: Sprint Summary | I2: Accomplishments | J2: Remarks | K2: Retro Points (Internal & External) | L2: Unplanned Leaves | M2: Data sanity Audit Status | N2: AuditDate | O2: Completed Stretch | P2: Backlog Health
A3: =IF(AND($D$1>=C3,$D$1<=D3),"CurrentSprint","NA") -> NA | B3: 13.5 Spirnt 2 | C3: 45301 | D3: 45314 | E3: 26 | F3: 26 | J3: 7 Story point introduced in mid of the sprint NOTE: MAUI stories are also in progress, but paused due to high priority defects. | K3: Internal: External: | O3: 7
A4: =IF(AND($D$1>=C4,$D$1<=D4),"CurrentSprint","NA") -> NA | B4: 13.5 Sprint 3 | C4: 45315 | D4: 45328 | E4: 15 | F4: 17 | J4: Strech Stories are holded by client because of regression defects NOTE: MAUI stories are also in progress, but paused due to high priority regression defects. | K4: Internal: External: | O4: 8
A5: =IF(AND($D$1>=C5,$D$1<=D5),"CurrentSprint","NA") -> NA | B5: 13.6 Sprint 1 | C5: 45329 | D5: 45342 | E5: 17 | F5: 12 | J5: The development of the 43394 story is complete, but a new POV scope has been added. So this story is carried to the next sprint. NOTE: Comments added respective stories | K5: Internal: External: | O5: 3
A6: =IF(AND($D$1>=C6,$D$1<=D6),"CurrentSprint","NA") -> NA | B6: 13.6 Sprint 2 | C6: 45343 | D6: 45356 | E6: 24 | F6: 19 | J6: MAUI Stories Update 42130 story is carried due to the bounce backs. 42138 story is completed and its under the testing. MAUI Stretch Stories Update 42131 story is compled but gokul have the build issue in Mac Mini so he is fixing the issue. 42142 story is completed, Testing is under progress. | K6: Internal: External: | O6: 4
A7: =IF(AND($D$1>=C7,$D$1<=D7),"CurrentSprint","NA") -> NA | B7: 13.6 Sprint 3 | C7: 45357 | D7: 45370 | E7: 13 | F7: 13 | G7: 13 | J7: All MAUI Stories are moved to Stretch, Working with POV comments and bounebacks. 42130 - Maui Story is completed and now it's ready for testing | K7: Internal: External: | O7: 2
A8: =IF(AND($D$1>=C8,$D$1<=D8),"CurrentSprint","NA") -> NA | B8: 13.7 Sprint 1 | C8: 45371 | D8: 45384 | E8: 14 | F8: 14 | G8: 11 | J8: 42129 - Login Maui story bounce back issue fixed, and it is needed some foundation level fix so sean is looking into that issue. 42131,42138 - Gokul is fixing the internal testing issues, once done, wrap up all the committed MAUI stories, and close it as soon as possible. NOTE: Detailed comments added in respective stories. | K8: Internal: External:
A9: =IF(AND($D$1>=C9,$D$1<=D9),"CurrentSprint","NA") -> NA | B9: 13.7 Sprint 2 | C9: 45385 | D9: 45398 | E9: 21 | F9: 15 | G9: 16 | J9: 43928 is dev completed, New changes add at end of the sprint, and POV and Testing is Pending. Defect 19537 is fixed, but added peer review comments so this defect is carried to the next sprint MAUI Stories are still in External Testing. NOTE: Detailed comments added in respective stories. | K9: Internal: External:
A10: =IF(AND($D$1>=C10,$D$1<=D10),"CurrentSprint","NA") -> NA | B10: 13.7 Sprint 3 | C10: 45399 | D10: 45412 | E10: 12 | F10: 12 | G10: 17 | J10: The story 43928 has been completed but it hasn't been tested yet, thus we need help testing it. so the brain will support the tests Completing high priority tasks by fixing regression defects, and after those are finished, moving on to stretch stories. Pulled the new MAUI stretch stories and Working on it. Note: Not pulled new committed stoies to work because this is a regression sprint. | K10: Internal: External:
A11: =IF(AND($D$1>=C11,$D$1<=D11),"CurrentSprint","NA") -> NA | B11: 13.8 Sprint 1 | C11: 45413 | D11: 45426 | E11: 10 | F11: 10 | J11: Regression Sprint. We are working on stretch stories for MAUI. and for this sprint, no newly committed stories were pulled. | K11: Internal: External:
A12: =IF(AND($D$1>=C12,$D$1<=D12),"CurrentSprint","NA") -> NA | B12: 13.8 Sprint 2 | C12: 45427 | D12: 45440 | E12: 22 | F12: 17 | J12: Some stories cannot be tested since the iOS device and simulator are not operating, therefore they are carried over to the next sprint. | K12: Internal: External:
A13: =IF(AND($D$1>=C13,$D$1<=D13),"CurrentSprint","NA") -> NA | B13: 13.8 Sprint 3 | C13: 45441 | D13: 45454 | E13: 25 | F13: 21 | J13: This sprint, we are worked on regression issues, therefore some of the committed stories only partially worked. | K13: Internal: External:
A14: =IF(AND($D$1>=C14,$D$1<=D14),"CurrentSprint","NA") -> NA | B14: 14.0 Sprint 1 | C14: 45455 | D14: 45468 | E14: 14 | F14: 11 | G14: 2 | J14: Due to POV comments, the story 42133 is carried over to the next sprint. | K14: Internal: External:
A15: =IF(AND($D$1>=C15,$D$1<=D15),"CurrentSprint","NA") -> NA | B15: 14.0 Sprint 2 | C15: 45469 | D15: 45484 | E15: 11 | F15: 15.5 | G15: 6.5 | J15: Completed 1 stretch story. | K15: Internal: External:
A16: =IF(AND($D$1>=C16,$D$1<=D16),"CurrentSprint","NA") -> NA | B16: 14.0 Sprint 3 | C16: 45485 | D16: 45498 | E16: 13 | F16: 13 | G16: 26 | J16: Completed 1 stretch story, and currently working on MAUI stretch stories. | K16: Internal: External:
A17: =IF(AND($D$1>=C17,$D$1<=D17),"CurrentSprint","NA") -> NA | B17: 14.1 Sprint 1 | C17: 45499 | D17: 45512 | E17: 11 | F17: 11 | G17: 29 | J17: Completed 2 strech stories and 1 committed story, and we are worked on MAUI Strech stories. | K17: Internal: External:
A18: =IF(AND($D$1>=C18,$D$1<=D18),"CurrentSprint","NA") -> NA | B18: 14.1 Sprint 2 | C18: 45513 | D18: 45526 | E18: 7 | F18: 7 | G18: 25 | J18: we are cotinued to working on MAUI stretch stories | K18: Internal: External:
A19: =IF(AND($D$1>=C19,$D$1<=D19),"CurrentSprint","NA") -> NA | B19: 14.1 Sprint 3 | C19: 45527 | D19: 45540 | E19: 29 | F19: 27.5 | G19: 21 | J19: Cotinued to working on MAUI stretch stories | K19: Internal: External:
A20: =IF(AND($D$1>=C20,$D$1<=D20),"CurrentSprint","NA") -> NA | B20: 14.2 Sprint 1 | C20: 45541 | D20: 45554 | E20: 8.5 | F20: 13.5 | G20: 16 | J20: Cotinued to working on MAUI stretch stories. Regression defects are worked and the SP are burned down to the regression Stories | K20: Internal: External:
A21: =IF(AND($D$1>=C21,$D$1<=D21),"CurrentSprint","NA") -> NA | B21: 14.2 M Sprint 2 | C21: 45555 | D21: 45568 | E21: 4 | F21: 4 | G21: 14 | J21: CRC Peer - 0, Onsite - 0, Client - 0. Internal Defect - 0, External Defect - 0.
A22: =IF(AND($D$1>=C22,$D$1<=D22),"CurrentSprint","NA") -> NA | B22: 14.2 M Sprint 3 | C22: 45569 | D22: 45582 | E22: 13 | F22: 16 | G22: 21
A23: =IF(AND($D$1>=C23,$D$1<=D23),"CurrentSprint","NA") -> NA | B23: 14.3 M Sprint 1 | C23: 45583 | D23: 45596 | E23: 19 | F23: 14 | G23: 15
A24: =IF(AND($D$1>=C24,$D$1<=D24),"CurrentSprint","NA") -> NA | B24: 14.3 M Sprint 2 | C24: 45597 | D24: 45610 | E24: 17.5 | F24: 6.5 | G24: 8 | I24: Maui Stories-Development and testing completed. | J24: Testing was delayed due to a deployment issue in the build pipeline, GSOC scope change and DS dependency
A25: =IF(AND($D$1>=C25,$D$1<=D25),"CurrentSprint","NA") -> NA | B25: 14.3 M Sprint 3 | C25: 45611 | D25: 45628 | E25: 18 | F25: 5 | G25: 10 | I25: Development completed for most of the MAUI stories from stretch. | J25: MSBP regression could not be completed due to external dependency for greenLight testing(functionality).The workflow in GLs end was changed which was not intimated until Letashia tested it and found it. GL cannot be tested offshore due to region specific restriction. Dotnet 9 update caused the bottom sheet issues(Internal Component) so MAUI stories could not be tested. | K25: Most of the stories are blocked due the .Net 9 update
A26: =IF(AND($D$1>=C26,$D$1<=D26),"CurrentSprint","NA") -> NA | B26: 14.4 M Sprint 1 | C26: 45629 | D26: 45638 | E26: 11 | F26: 11.3 | G26: 25 | I26: Completed Regression testing before the release | J26: Dotnet 9 and Telerik updated caused the bottom sheet issues(Internal Component) and input modal crash issue respectively. So MAUI stories could not be tested. The Blockers were addressed by Client Dev. | K26: Most of the stories are blocked due to .Net 9 and Telerik updates. Client decided to go with MAUI controls instead of telerik for Datepicker and Input Modal entry control due to the long time blocker.
A27: =IF(AND($D$1>=C27,$D$1<=D27),"CurrentSprint","NA") -> NA | B27: 14.4 M Sprint 2 | C27: 45639 | D27: 45666 | E27: 10 | F27: 16 | G27: 5 | I27: Maui- commited stories completed within the sprint target date | J27: Fixing Dotnet9 issues.
A28: =IF(AND($D$1>=C28,$D$1<=D28),"CurrentSprint","NA") -> NA | B28: 14.4 M Sprint 3 | C28: 45667 | D28: 45680 | E28: 12 | F28: 13 | G28: 12 | I28: Maui- commited stories completed. MSBP regression testing completed. Major defects found | J28: Continue to working on MAUI Stretch Stories | O28: 1
A29: =IF(AND($D$1>=C29,$D$1<=D29),"CurrentSprint","NA") -> NA | B29: 14.5 M Sprint 1 | C29: 45681 | D29: 45694 | E29: 12 | F29: 12 | G29: 28 | I29: Maui- Completed all committed stories and started working on stretch stories. Issues found were fixed and tested withing the sprint timeline | K29: Moving the status and logging time sheet and adding comments to the story before sprint planning | O29: 8
A30: =IF(AND($D$1>=C30,$D$1<=D30),"CurrentSprint","NA") -> NA | B30: 14.5 M Sprint 2 | C30: 45695 | D30: 45708 | E30: 21 | F30: 35 | G30: 14 | I30: Most of the committed stories completed, and one of the story is get delayed to due to tesing and bounce backs | J30: we can't run the code in iOS simulator or iOS device. we have bloker on this. | O30: 8
A31: =IF(AND($D$1>=C31,$D$1<=D31),"CurrentSprint","NA") -> NA | B31: 14.5 M Sprint 3 | C31: 45709 | D31: 45722 | E31: 21 | F31: 33.5 | G31: 2.5 | I31: Completed Regression testing. Team picked the defects from stretch and completed fixing those. Retesting completed for those defects. | O31: 14
A32: =IF(AND($D$1>=C32,$D$1<=D32),"CurrentSprint","NA") -> NA | B32: 14.6 M Sprint 1 | C32: 45723 | D32: 45740 | E32: 26.5 | F32: 52.88 | G32: 0 | I32: Completed the development and testing for the defects found and started finding issues in Maui as part of Maui regression(Post migration testing) | J32: Client has approved to work in Defects, considering the Migration to MAUI is done for Major Stories. Telerik CollectionView control is having some issues some of which are still open issues tickets. Hence we are migrating to native collection view and it is missing some features of Telerik control. So working on it to manully replicate the features in native control. Please Note: All the Defects found were logged directly to Commit. These defects were found during Post migration Maui Regression testing. | O32: 0
A33: =IF(AND($D$1>=C33,$D$1<=D33),"CurrentSprint","NA") -> NA | B33: 14.6 M Sprint 2 | C33: 45741 | D33: 45750 | E33: 14.5 | F33: 10.5 | G33: 0 | I33: Completed fixing and testing the Maui-Staging regression defects. Added camera support for Tickets Box office in MSBA | O33: 5
A34: =IF(AND($D$1>=C34,$D$1<=D34),"CurrentSprint","NA") -> NA | B34: 14.6 M Sprint 3 | C34: 45751 | D34: 45764 | E34: 5 | F34: 4.5 | G34: 0 | I34: Completed MSBP Xamarin regression testing. Worked on few MSB Anywhere stories and defects from the stretch | O34: 29.25
A35: =IF(AND($D$1>=C35,$D$1<=D35),"CurrentSprint","NA") -> NA | B35: 14.7 M Sprint 1 | C35: 45765 | D35: 45778 | E35: 3 | F35: 1 | G35: 2 | I35: Completed MSBP CA regression testing. Development completed for stories/defects from the stretch. updated the test cases for the stories under development. | J35: Due to app crash in iOS and android, testing was delayed by 1 day. later we found an workaround to test that. Now that issue has been fixed. Build issues in main brach caused delay in development. | O35: 7
A36: =IF(AND($D$1>=C36,$D$1<=D36),"CurrentSprint","NA") -> NA | B36: 14.7 M Sprint 2 | C36: 45779 | D36: 45792 | E36: 18.5 | F36: 18.5 | G36: 0 | I36: New requirement 'Family Pass' and 'Events' has been developed and tested successfully - Cross sell popup - Hooray screen - FP Payment method | J36: NA CRC Peer - 0, Onsite - 0, Client - 0. Internal Defect - 0, External Defect - 0. | O36: 2
A37: =IF(AND($D$1>=C37,$D$1<=D37),"CurrentSprint","NA") -> NA | B37: 14.7 M Sprint 3 | C37: 45793 | D37: 45806 | E37: 12 | F37: 7 | G37: 0 | I37: 1. Completed testing and development for MSBA Maui defects found during Xamarin to Maui conversion. | J37: Due to an iOS app crash, testing and development activities were blocked. The issue was brought up during daily standup and Sean was working on it. CRC Peer - 0, Onsite - 0, Client - 0. Internal Defect - 0, External Defect - 0. | O37: 0
A38: =IF(AND($D$1>=C38,$D$1<=D38),"CurrentSprint","NA") -> NA | B38: 15.0 M Sprint 1 | C38: 45807 | D38: 45820 | E38: 42 | F38: 23 | G38: 0 | I38: 1. Completed MSBA MAUI Regression defects 2.Regression testing completed for MSBP 14.7 Xamarin version 3.Smoke testing against prod environment completed for Xamarin - MSB Parent app - MSB Anywhere app - MSBP CA app | J38: 1.Defects were tested and closed at the end of the sprint as we were unable to test in IOS devices due to build issues in iOS. 2.This was fixed by Client dev. Client is already aware of these issues. CRC Peer - 3, Onsite - 0, Client - 0. Internal Defect - 0, External Defect - 0. | O38: 8
A39: =IF(AND($D$1>=C39,$D$1<=D39),"CurrentSprint","NA") -> NA | B39: 15.0 M Sprint 2 | C39: 45821 | D39: 45833 | E39: 28.5 | F39: 22 | G39: 0 | I39: Completed the below items 1. MSBA Maui defects. 2. MSBP Maui defects 3. MSBP CA regression 4. MSBA Xamarin Regression 5. Appium set up in iOS and Android | J39: CRC Peer - 0, Onsite - 0, Client - 0. Internal Defect - 0, External Defect - 0. | O39: 4
A40: =IF(AND($D$1>=C40,$D$1<=D40),"CurrentSprint","NA") -> NA | B40: 15.0 M Sprint 3 | C40: 45834 | D40: 45848 | E40: 40 | F40: 10 | G40: 0 | I40: Completed the below items 1. MSBP Maui Regression 2. Appium setup in iOS and android 3. Few automation stories development completed, waiting for client review. 4. MSBA Stretch stories completed. | J40: CRC Peer - 0, Onsite - 0, Client - 0. Internal Defect - 1, External Defect - 0. 1. Due to Firewall update, all domain request failed, API and Logins were not working. 2. Bottom sheet issue and Acceptance criteria for automation stories modified at the end of the sprint timeline RCA: Due to issues with Owen's environment and there is no proper framework, automation fails in Owen's system. Some of the framework are not reusable due to that which is causing delay in automation work. Fix: Needs a discussion with Ashwin and Owen on this. | K40: Internal 1. Environment setup for Automation 2. MAUI MSBP Regression 3. Started working on Automation stories 4. Completed MSBP Events story Needs Improvement - 1. Last minute AC update leads to delay in completiong automation stories. 2.Delays due to Peer review from Owen(Client) 3.Bottom sheet issues in iOS caused delay 4. Delay in setting up the environment in local | O40: 14
...

Sheet Defect-template
A1: S.No | B1: Sprint # | C1: Story/Defect ID | D1: Parent Story | E1: Developer | F1: Issue Type | G1: Issue Description | H1: Priority | I1: Defect Source | J1: Type | K1: Status | L1: Root Cause Category | M1: Comments

Sheet Unplanned Leaves
A1: Total Leaves | B1: =SUM(B21:J21) -> 12
B2: Resource Name
A3: Sprint | B3: Amrit Pal Harjit Singh | C3: Ashwin Majella | D3: Bavithra Arasakumaran | E3: Gursewak Singh Jaspal Singh | F3: Jagdeep Singh | G3: Premkumar Rajendran | H3: Rupesh Kumar | I3: Sambath Selvam | J3: Vaishnavi Shanmugavel | K3: Remarks
A4: 26.3 M Sprint 2 (23-Jan-2026 to 5-Feb-2026) | B4: 1 | C4: 0 | D4: 0 | E4: 0 | F4: 0 | G4: 0 | H4: 0 | I4: 0 | J4: 1 | K4: 27-Jan-26 Vaishnavi - well its planned but updated at the last minute so it is unplanned leave in Leave tracker, 29-Jan-26 Amrit took sick leave
A5: 26.4 M Sprint 1 (20-Feb-2026 to 05-Mar-2026) | B5: 0 | C5: 0 | D5: 0 | E5: 1 | F5: 0 | G5: 0 | H5: 0 | I5: 0 | J5: 0 | K5: 9-Feb-26 Gursewak took the leave for family emergency.
A6: 26.3 M Sprint 3 (06-Feb-2026 to 19-Feb-2026) | B6: 0 | C6: 1 | D6: 0 | E6: 0 | F6: 0 | G6: 0 | H6: 0 | I6: 0 | J6: 0 | K6: 14 Feb - Ashwin Sick leave
A7: 26.4 M Sprint 1 (20-Feb-2026 to 05-Mar-2026) | B7: 0 | C7: 1 | D7: 1 | E7: 0 | F7: 0 | G7: 1 | H7: 0 | I7: 0 | J7: 0 | K7: 27 Feb - Ashwin Sick Leave, 3 Mar - Bavithra emergency leave met with small accident, Prem Sick leave.
A8: 26.4 M Sprint 3 (20-Mar-2026 to 02-Apr-2026) | B8: 0 | C8: 0 | D8: 1 | E8: 0 | F8: 0 | G8: 0 | H8: 0 | I8: 1 | J8: 0 | K8: 30 Mar - Bavithra Sick leave and Sambath network issue.
A9: 26.5 M Sprint 1 (03-Apr-2026 to 16-Apr-2026) | B9: 1 | C9: 0 | D9: 0 | E9: 0 | F9: 0 | G9: 1 | H9: 0 | I9: 0 | J9: 1 | K9: 6th Apr - Vaishnavi sick leave, 10th Apr - Prem Sick Leave 9th Apr- Amrit Unplanned sick leave
A21: Total | B21: =SUM(B4:B20) -> 2 | C21: =SUM(C4:C20) -> 2 | D21: =SUM(D4:D20) -> 2 | E21: =SUM(E4:E20) -> 1 | F21: =SUM(F4:F20) -> 0 | G21: =SUM(G4:G20) -> 2 | H21: =SUM(H4:H20) -> 0 | I21: =SUM(I4:I20) -> 1 | J21: =SUM(J4:J20) -> 2 | K21: =SUM(K5:K20) -> 0

Sheet 26.7 M Sprint 1-Status
A1: S.No | B1: Application Name | C1: Sprint Start Date | D1: Sprint End Date | E1: Sprint | F1: Developer | G1: Story ID/Defect ID | H1: Description | I1: Status | J1: Estimated(sp) | K1: Actual(sp) | L1: Actual Hours Worklog | M1: Dev Start Date | N1: Dev End Date | O1: Unit testing | P1: Peer Tested By | Q1: Peer Tested Defects, if any | R1: Peer Reviewed By | S1: Peer Code Review Comments, if any | T1: PR Number/Link | U1: PR Created Date | V1: PR Approved Date | W1: Reviewer 1 | X1: Code Review Comments, if any | Y1: Reviewer 2 | Z1: Approved Date | AA1: Code Review Comments, if any2 | AB1: Internal PO -POV Comments | AC1: Client PO -POV Comments | AD1: Comments | AE1: Does this story meet the expectations? | AF1: Comments | AG1: Sprint Tag
A2: 1 | B2: MSB Mobile | C2: 46143 | D2: 46156 | E2: 26.7 M Sprint 1 | F2: chandler/vaishnavi/ | G2: 27320 | H2: 27320 MSBP - Android - All text and sizes are inflated on pixel pro devices, sometimes pushing items off viewable area (26.5) | I2: Defect Being Tested | M2: NA | N2: NA | O2: NA | P2: NA | Q2: NA | R2: NA | S2: NA | T2: NA | U2: NA | V2: NA | W2: NA | X2: NA | Y2: NA | Z2: NA | AA2: NA | AB2: NA | AC2: NA | AD2: 15-May - chandler working on the fix.
A3: 2 | B3: MSB Mobile Kaleida | C3: 46157 | D3: 46170 | E3: 26.7 M Sprint 1 | F3: Jagdeep/vaishnavi | G3: 52343 | H3: [WAVE] MSBA - Kaleida - Update Offset Language - Difference(Over/Short) | I3: Story Being Tested | M3: 46147 | N3: 46148 | O3: NA | P3: Amrit/Vashnavi | Q3: NA | R3: Rupesh/Sambath | S3: NA | T3: https://dev.azure.com/heartlandschools/Mobile/_git/MSBA.MAUI/pullrequest/48842 | U3: 46147 | V3: 46149 | W3: Ashwin | X3: NA | Y3: Avery | Z3: 46149 | AA3: NA | AB3: POV done with Bavithra No Comment | AC3: POV done with Jason No Comment | AD3: 15-May- will work on the testing
A4: 3 | B4: MSB Mobile | C4: 46157 | D4: 46170 | E4: 26.7 M Sprint 1 | F4: Amrit/Gursewak | G4: 27283 | H4: MSBA - MAUI - iOS- meal payments screen changing formatting when cart preview is on with items in it | I4: Defect Ready For Testing | M4: 46150 | N4: 46153 | O4: NA | P4: Gursewak | Q4: Yes | R4: Rupesh/Sambath | S4: NA | T4: https://dev.azure.com/heartlandschools/Mobile/_git/MSBA.MAUI/pullrequest/48972 | U4: 46153 | V4: NA | W4: NA | X4: NA | Y4: NA | Z4: Na | AA4: NA | AB4: POV done with Bavithra No Comment | AC4: NA | AD4: 14 May - PR Pending from Ashwin and Client Side 15 May - Defect ready for testing
A5: 4 | B5: MSB Mobile Kaleida | C5: 46157 | D5: 46170 | E5: 26.7 M Sprint 1 | F5: Jagdeep | G5: 27276 | H5: MSBP - Android - Can double click and open multiple stacks of menus | I5: Defect Ready For Testing | M5: 46148 | N5: 46150 | O5: NA | P5: Gursewak | Q5: NA | R5: Rupesh/Sambath | S5: NA | T5: https://dev.azure.com/heartlandschools/Mobile/_git/MSBP.MAUI/pullrequest/48903 | U5: 46149 | V5: 46155 | W5: Ashwin | X5: NA | Y5: Avery | Z5: 46155 | AA5: NA | AB5: POV done with Bavithra No Comment | AC5: NA | AD5: Will pick this after completing the MSBA, MSBP CA, MSBP smoke tests
A6: 5 | B6: MSB Mobile Kaleida | C6: 46157 | D6: 46170 | E6: 26.7 M Sprint 1 | F6: Gursewak/Prem | G6: 27015 | H6: MSBA - MAUI - iphone - invoice add to cart button not formatted correctly (regression) | I6: Defect Fixed | M6: 46150 | N6: 46150 | O6: NA | P6: Yes | Q6: NA | R6: Rupesh/Sambath | S6: NA | T6: https://dev.azure.com/heartlandschools/Mobile/_git/MSBA.MAUI/pullrequest/48924 | U6: 46150 | V6: 46150 | W6: NA | X6: NA | Y6: NA | Z6: NA | AA6: NA | AB6: POV done with Bavithra No Comment | AC6: NA | AD6: Will pick this after completing the MSBA, MSBP CA, MSBP smoke tests 15 May - Testing completed
A7: 6 | B7: MSB Mobile | C7: 46157 | D7: 46170 | E7: 26.7 M Sprint 1 | F7: Amrit | G7: 27006 | H7: MSBA - MAUI - iOS - Cart has extra space underneath buttons (regression) | I7: Defect Ready For Testing | M7: 46150 | N7: 46153 | O7: NA | P7: Gursewak | Q7: Yes | R7: Rupesh/Sambath | S7: NA | T7: https://dev.azure.com/heartlandschools/Mobile/_git/MSBA.MAUI/pullrequest/48926 | U7: 46153 | V7: NA | W7: NA | X7: NA | Y7: NA | Z7: NA | AA7: NA | AB7: POV done with Ashwin No Comment | AC7: NA | AD7: 14 May - PR Pending from Ashwin and Client Side 15 May - Defect ready for testing
A8: 7 | B8: MSB Mobile Kaleida | C8: 46157 | D8: 46170 | E8: 26.7 M Sprint 1 | F8: Jagdeep | G8: 27255 | H8: MSBP - missing phone number page and profile phone pages do not match | I8: Defect Peer Review | M8: 46150 | N8: 46153 | O8: NA | P8: Amrit | Q8: NA | R8: Rupesh | S8: NA | T8: https://dev.azure.com/heartlandschools/Mobile/_git/MSBP.MAUI/pullrequest/49015 | U8: 46153 | V8: NA | W8: NA | X8: NA | Y8: NA | Z8: NA | AA8: NA | AB8: POV done with Bavithra No Comment | AC8: NA | AD8: 15 May - Waiting for aproval from Ashwin and Client side.
A9: 8 | B9: MSB Mobile Kaleida | C9: 46157 | D9: 46170 | E9: 26.7 M Sprint 1 | F9: Gursewak | G9: 26881 | H9: MSBA - Cart icon/badge is larger than expected (regression) | I9: Defect Ready For Testing | M9: 46150 | N9: 46153 | O9: NA | P9: Yes | Q9: NA | R9: Rupesh/Sambath | S9: NA | T9: https://dev.azure.com/heartlandschools/Mobile/_git/MSBA.MAUI/pullrequest/48932 | U9: 46153 | V9: 46153 | W9: NA | X9: NA | Y9: NA | Z9: NA | AA9: NA | AB9: POV done with Bavithra No Comment | AC9: NA | AD9: 15 May- Merged, ready for testing.
A10: 9 | B10: MSB Mobile | C10: 46157 | D10: 46170 | E10: 26.7 M Sprint 1 | F10: Vaishnavi/Prem | G10: 53092 | H10: REG - MSBP - Regression 26.5 | I10: Story Being Tested | M10: NA | N10: NA | O10: NA | P10: NA | Q10: NA | R10: NA | S10: NA | T10: NA | U10: NA | V10: NA | W10: NA | X10: NA | Y10: NA | Z10: NA | AA10: NA | AB10: NA | AC10: NA | AD10: Work on the invoice push notificaiton test cases
A11: 10 | B11: MSB Mobile | C11: 46157 | D11: 46170 | E11: 26.7 M Sprint 1 | F11: Rupesh/Vaishnavi | G11: 27394 | H11: MSBA - stock option formatting issues (regression) | I11: Defect Being Tested | M11: 46155 | AD11: WIll start the testing.
A12: 12 | B12: MSB Mobile Kaleida | C12: 46157 | D12: 46170 | E12: 26.7 M Sprint 1 | F12: Prem | G12: 53090 | H12: MSBP CA - Regression/Smoke Test Against Staging 26.5 RC | I12: Story Being Tested | J12: 1 | M12: NA | N12: NA | O12: NA | P12: NA` | Q12: NA | R12: NA | S12: NA | T12: NA | U12: NA | V12: NA | W12: NA | X12: NA | Y12: NA | Z12: NA | AA12: NA | AB12: NA | AC12: NA | AD12: 15 May - Testing is in Progress
A13: 13 | B13: MSB Mobile | C13: 46157 | D13: 46170 | E13: 26.7 M Sprint 1 Stretch | F13: Amrit/Prem | G13: 52344 | H13: [WAVE] MSBA - Update Components/Fonts to Kaleida - Hamburger Menu | I13: Story Ready For Testing | M13: 46132 | N13: 46134 | O13: NA | P13: Jagdeep | Q13: NA | R13: Jagdeep | S13: NA | T13: https://dev.azure.com/heartlandschools/Mobile/_git/MSBA.MAUI/pullrequest/48532 | U13: 46138 | V13: 46140 | W13: Sambath | X13: NA | Y13: Avery | Z13: 46140 | AA13: NA | AB13: POV done with Bavithra No Comment | AC13: NA | AD13: After completing the main commit stories/defects will work on these stories
A14: 14 | B14: MSB Mobile Kaleida | C14: 46157 | D14: 46170 | E14: 26.7 M Sprint 1 Stretch | F14: Gursewak | G14: 52346 | H14: [WAVE] MSBA - Update Components/Fonts to Kaleida - Header | I14: Story Ready For Testing | M14: 46133 | N14: 46142 | O14: NA | P14: Yes | Q14: NA | R14: Rupesh/Sambath | S14: Total Comments: 3 Rupesh Kumar (1 Comment) Please use static resource color from Kaleida. Sambath Selvam (2 Comments) Remove default value properties. Remove RowSpacing="0". | T14: https://dev.azure.com/heartlandschools/Mobile/_git/MSBA.MAUI/pullrequest/48736 | U14: 46142 | V14: 46142 | W14: Ashwin | X14: NA | Y14: Avery | Z14: 46148 | AA14: Total Comments: 5 Avery Wold (5 Comments) Remove this since Demo Mode is not used. Use "K" colors – KAppHeaderBackgroundColor. Fix KCircleButton property mismatch and incorrect styling. Use correct "K" color – KChipBackgroundColor. Remove unnecessary CornerRadius (handled by KCircleButton). Do not hardcode Black; use KPrimaryTextColor. | AB14: POV done with Bavithra No Comment | AC14: POV done with Jason No Comment | AD14: After completing the main commit stories/defects will work on these stories
A15: 15 | B15: MSB Mobile | C15: 46157 | D15: 46170 | E15: 26.7 M Sprint 1 Stretch | F15: Sambath | G15: 52347 | H15: 52347 [WAVE] MSBA - Update Components/Fonts to Kaleida - Transaction History | I15: Story Ready For Testing | M15: 46133 | N15: 46146 | O15: NA | P15: Rupesh | Q15: NA | R15: Rupesh | S15: remove the default value properties | T15: https://dev.azure.com/heartlandschools/Mobile/_git/MSBA.MAUI/pullrequest/48726 | U15: 46146 | V15: 46146 | W15: NA | X15: NA | Y15: Avery | Z15: 46153 | AA15: Count (10) Exiting Code:Shell.Current.DisplayAlertAsync changed to DialogService.ShowDialogAsync(), this is new change has added by avery (16). Exiting Code:Naming convension changed to ShowHideAdminLoginModalCommand instead of ShowHideBarcodeModalCommand (2) New change : Loading Inidicator changes, that is new changes (4) Kcolor missed in two places (2). Exiting Code:Font size removed from all Kcontrol, it take default font size from K library (21) KButton has been repalced with KIconButton (1) New change :Custom ItemTemplate was removed, instead used New KListTile control (1). Exiting Code:Image control has been replaced with Klable to show the icon only option (1) Exiting Code: For consistency with other buttons change this to HeightRequest="44" (2) Exiting Code:exiting EmailRefundPopup Code has been refacored based on avery suggesion (10). | AB15: POV Done | AD15: After completing the main commit stories/defects will work on these stories
A16: 16 | B16: MSB Mobile | C16: 46157 | D16: 46170 | E16: 26.7 M Sprint 1 Stretch | F16: Rupesh/Prem | G16: 52348 | H16: [WAVE] MSBA - Update Components/Fonts to Kaleida - Forgot Login Workflow | I16: Story Ready For Testing | M16: 46134 | N16: NA | O16: NA | P16: Jagdeep | Q16: NA | R16: Jagdeep/Sambath | S16: NA | T16: https://dev.azure.com/heartlandschools/Mobile/_git/MSBA.MAUI/pullrequest/48656 | U16: 46139 | V16: 46146 | W16: Ashwin | X16: NA | Y16: Avery | Z16: 46148 | AA16: Comments - 14 This should be using the Kaleida component(For BG image). - 5 Get rid of this since we do not have Demo mode - 5 KHeader is already defaulted to use KPrimaryColor, no need to add this." - 1 KHeader is already Bold, no need to add this - 1 This should probably be a KHeader(KLabel was used):- 1 Get rid of this old style and consider using the KHeader (Old style was used as it was before)- 6 This should probably be a KCircleButton(This was a Klabel ) - 3 This is the default, adding this is redundant - 9 Consider using the KLabelFootnote style for consistency.(Label was used) - 1 This is overcomplicated, can be simplified - 4 if this needs to be a Header based on the old style still attached consider using a KHeader, otherwise this could be simplified : - 1 This is not a phonenumber field and the name here should be updated to reflect that(This was existing one)- 1 KPasswordField has a build in error message, simplify it- 4 | AB16: POV done with Ashwin No Comment | AC16: NA | AD16: After completing the main commit stories/defects will work on these stories
A17: 17 | B17: MSB Mobile | C17: 46157 | D17: 46170 | E17: 26.7 M Sprint 1 | F17: Rupesh | G17: 27406 | H17: MSBA - Shift Mode - Unable to Start Shift - Errors with Starting Shifts | I17: Defect Found | J17: 3 | M17: 46157
A18: 18 | B18: MSB Mobile Kaleida | C18: 46157 | D18: 46170 | E18: 26.7 M Sprint 1 | F18: Gursewak | G18: 53208 | H18: MSBA - TECH DEBT - Unit Tests - Update to .NET10 | I18: Story Being Developed | J18: 3 | M18: 46157 | AD18: 15 May - start working on it.
A19: 19 | B19: MSB Mobile Kaleida | C19: 46157 | D19: 46170 | E19: 26.7 M Sprint 1 | F19: Jagdeep | G19: 53209 | H19: MSBP - TECH DEBT - Unit Tests - Update to .NET10 | I19: Story Being Developed | J19: 3 | M19: 46157 | N19: NA | O19: NA | P19: NA` | Q19: NA | R19: NA | S19: NA | T19: NA | U19: NA | V19: NA | W19: NA | X19: NA | Y19: NA | Z19: NA | AA19: NA | AB19: NA | AC19: NA | AD19: 15 May - start working on it. | AG19: Main

Sheet 26.5 M Sprint 3-Status
A1: S.No | B1: Application Name | C1: Sprint Start Date | D1: Sprint End Date | E1: Sprint | F1: Developer | G1: Story ID/Defect ID | H1: Description | I1: Status | J1: Estimated(sp) | K1: Actual(sp) | L1: Actual Hours Worklog | M1: Dev Start Date | N1: Dev End Date | O1: Unit testing | P1: Peer Tested By | Q1: Peer Tested Defects, if any | R1: Peer Reviewed By | S1: Peer Code Review Comments, if any | T1: PR Number/Link | U1: PR Created Date | V1: PR Approved Date | W1: Reviewer 1 | X1: Code Review Comments, if any | Y1: Reviewer 2 | Z1: Approved Date | AA1: Code Review Comments, if any2 | AB1: Internal PO -POV Comments | AC1: Client PO -POV Comments | AD1: Comments | AE1: Does this story meet the expectations? | AF1: Comments | AG1: Sprint Tag
A2: 2 | B2: MSB Mobile | C2: 46143 | D2: 46156 | E2: 26.5 M Sprint 3 Stretch | F2: Amrit/Prem | G2: 52344 | H2: [WAVE] MSBA - Update Components/Fonts to Kaleida - Hamburger Menu | I2: Story Ready For Testing | J2: 3 | L2: 8.5 | M2: 46132 | N2: 46134 | O2: NA | P2: Jagdeep | Q2: NA | R2: Jagdeep | S2: NA | T2: https://dev.azure.com/heartlandschools/Mobile/_git/MSBA.MAUI/pullrequest/48532 | U2: 46138 | V2: 46140 | W2: Sambath | X2: NA | Y2: Avery | Z2: 46140 | AA2: NA | AB2: POV done with Bavithra No Comment | AC2: NA | AD2: 04,05-may- Amrit PTO 6 May - Space issue InProgress for small devices android, Transaction history crash is being fixed by sambath in different PR 7 May - Transaction History Sambath PR is in Review, Space Issue we are not doing as discussed with client. 8 May - Waiting for Sambath PR to be merged for transaction history PR. 11 May - Story Moved to Need more info its pending until 52347 is merged 12 May - Story ready for testing 52347 is merged | AE2: Exceeds Expectation | AF2: Due to regression testing and other high priority defects/stories, this story was not picked up by the tester | AG2: Stretch
A3: 4 | B3: MSB Mobile Kaleida | C3: 46143 | D3: 46156 | E3: 26.5 M Sprint 3 Stretch | F3: Gursewak | G3: 52346 | H3: [WAVE] MSBA - Update Components/Fonts to Kaleida - Header | I3: Story Ready For Testing | J3: 2 | L3: 4 | M3: 46133 | N3: 46142 | O3: NA | P3: Yes | Q3: NA | R3: Rupesh/Sambath | S3: Total Comments: 3 Rupesh Kumar (1 Comment) Please use static resource color from Kaleida. Sambath Selvam (2 Comments) Remove default value properties. Remove RowSpacing="0". | T3: https://dev.azure.com/heartlandschools/Mobile/_git/MSBA.MAUI/pullrequest/48736 | U3: 46142 | V3: 46142 | W3: Ashwin | X3: NA | Y3: Avery | Z3: 46148 | AA3: Total Comments: 5 Avery Wold (5 Comments) Remove this since Demo Mode is not used. Use "K" colors – KAppHeaderBackgroundColor. Fix KCircleButton property mismatch and incorrect styling. Use correct "K" color – KChipBackgroundColor. Remove unnecessary CornerRadius (handled by KCircleButton). Do not hardcode Black; use KPrimaryTextColor. | AB3: POV done with Bavithra No Comment | AC3: POV done with Jason No Comment | AD3: 04 May - PR review pending from Sambath, Ashwin,client side. 05 May - Client review pending. 06 May - Avery added some comments, start working on it, will test and update the PR. 06 May - EOD - Ready for test.. 08-May- QA team working on the main commit defects/stories follwed by regression testing. | AE3: Exceeds Expectation | AF3: Due to regression testing and other high priority defects/stories, this story was not picked up by the tester | AG3: Stretch
A4: 5 | B4: MSB Mobile | C4: 46143 | D4: 46156 | E4: 26.5 M Sprint 3 Stretch | F4: Sambath | G4: 52347 | H4: 52347 [WAVE] MSBA - Update Components/Fonts to Kaleida - Transaction History | I4: Story Ready For Testing | J4: 8 | L4: 35 | M4: 46133 | N4: 46146 | O4: NA | P4: Rupesh | Q4: NA | R4: Rupesh | S4: remove the default value properties | T4: https://dev.azure.com/heartlandschools/Mobile/_git/MSBA.MAUI/pullrequest/48726 | U4: 46146 | V4: 46146 | W4: NA | X4: NA | Y4: Avery | Z4: 46153 | AA4: Count (10) Exiting Code:Shell.Current.DisplayAlertAsync changed to DialogService.ShowDialogAsync(), this is new change has added by avery (16). Exiting Code:Naming convension changed to ShowHideAdminLoginModalCommand instead of ShowHideBarcodeModalCommand (2) New change : Loading Inidicator changes, that is new changes (4) Kcolor missed in two places (2). Exiting Code:Font size removed from all Kcontrol, it take default font size from K library (21) KButton has been repalced with KIconButton (1) New change :Custom ItemTemplate was removed, instead used New KListTile control (1). Exiting Code:Image control has been replaced with Klable to show the icon only option (1) Exiting Code: For consistency with other buttons change this to HeightRequest="44" (2) Exiting Code:exiting EmailRefundPopup Code has been refacored based on avery suggesion (10). | AB4: POV Done | AD4: i have to run the POV with client, 07-May - Resolving merge conflicts, testing the app 08-May - Found some issue in KPopup and checked with avery, he modifed in library and i need to work updating the new Kpopup feature into app. 11- May - Working with code review changes 12- it is moved to ready for testing | AE4: Meets Expectation | AF4: Due to regression testing and other high priority defects/stories, this story was not picked up by the tester 14-May -26 - This story only covers Kcontrol and font and kcolor changes, but I also worked on other code refactor changes based on Avery’s suggestions. We need to plan what changes are included in this story, because if we spend time on items outside the AC, it will take longer and lead to more review comments | AG4: Stretch
A5: 6 | B5: MSB Mobile | C5: 46143 | D5: 46156 | E5: 26.5 M Sprint 3 Stretch | F5: Rupesh/Prem | G5: 52348 | H5: [WAVE] MSBA - Update Components/Fonts to Kaleida - Forgot Login Workflow | I5: Story Ready For Testing | J5: 3 | L5: 6 | M5: 46134 | N5: NA | O5: NA | P5: Jagdeep | Q5: NA | R5: Jagdeep/Sambath | S5: NA | T5: https://dev.azure.com/heartlandschools/Mobile/_git/MSBA.MAUI/pullrequest/48656 | U5: 46139 | V5: 46146 | W5: Ashwin | X5: NA | Y5: Avery | Z5: 46148 | AA5: Comments - 14 This should be using the Kaleida component(For BG image). - 5 Get rid of this since we do not have Demo mode - 5 KHeader is already defaulted to use KPrimaryColor, no need to add this." - 1 KHeader is already Bold, no need to add this - 1 This should probably be a KHeader(KLabel was used):- 1 Get rid of this old style and consider using the KHeader (Old style was used as it was before)- 6 This should probably be a KCircleButton(This was a Klabel ) - 3 This is the default, adding this is redundant - 9 Consider using the KLabelFootnote style for consistency.(Label was used) - 1 This is overcomplicated, can be simplified - 4 if this needs to be a Header based on the old style still attached consider using a KHeader, otherwise this could be simplified : - 1 This is not a phonenumber field and the name here should be updated to reflect that(This was existing one)- 1 KPasswordField has a build in error message, simplify it- 4 | AB5: POV done with Ashwin No Comment | AC5: NA | AD5: 04 May : POV’d by Jason, I have published the PR for review. 05 May : Client approval is pending. Received pr comments , resolved and sent them back for review. 08 - QA team working on the main commit defects/stories follwed by regression testing. 08 May - Testing is in Progress 11 May - Tested and Raised a BB.And assigned back to dev to fix the same 12 May - Received some BB’s related to Primary button, I connected with Avery and he made some changes, need to pull Kaleida and test it and if everything looks okay, will raise the PR. | AE5: Exceeds Expectation | AF5: Due to regression testing and other high priority defects/stories, this story was not picked up by the tester | AG5: Stretch
A6: 9 | B6: MSB Mobile Kaleida | C6: 46143 | D6: 46156 | E6: 26.5 M Sprint 3 | F6: Amrit/Vaishnavi | G6: 52633 | H6: MSBP - Store Catalog - General header changed to Products | I6: Story Completed | J6: 1 | L6: 4 | M6: 46139 | N6: 46139 | O6: NA | P6: Jagdeep | Q6: NA | R6: Rupesh/Sambath | S6: NA | T6: https://dev.azure.com/heartlandschools/Mobile/_git/MSBP.MAUI/pullrequest/48662 | U6: 46139 | V6: 46139 | W6: Ashwin | X6: NA | Y6: Avery | Z6: 46142 | AA6: NA | AB6: POV done with Bavithra No Comment | AC6: NA | AD6: 4-May-Will be starting the testing. | AE6: Exceeds Expectation | AG6: Main
A7: 12 | B7: MSB Mobile Kaleida | C7: 46143 | D7: 46156 | E7: 26.5 M Sprint 3 | F7: Amrit/Vaishnavi | G7: 26882 | H7: MSBA - Cart Icon does not have the correct MSBA blue background | I7: Defect Fixed | J7: 1 | L7: 4 | M7: 46141 | N7: 46141 | O7: NA | P7: Rupesh | Q7: NA | R7: Rupesh/Sambath | S7: NA | T7: https://dev.azure.com/heartlandschools/Mobile/_git/MSBA.MAUI/pullrequest/48721 | U7: 46142 | V7: 46142 | W7: Ashwin | X7: NA | Y7: NA | Z7: 46142 | AA7: NA | AB7: POV done with Bavithra No Comment | AC7: NA | AD7: 4-May-Will be starting the testing. | AE7: Exceeds Expectation | AG7: Main
A8: 13 | B8: MSB Mobile | C8: 46143 | D8: 46156 | E8: 26.5 M Sprint 3 | F8: Rupesh/Vaishnavi | G8: 52964 | H8: MSBA - Admin Settings - BETA build - Require Elevated Privileges | I8: Story Completed | J8: 3 | L8: 18 | M8: 46141 | N8: 46153 | O8: NA | P8: Jagdeep | Q8: NA | R8: Jagdeep/Sambath | S8: Can we use StaticResource colors instead of hardcoded value. | T8: https://dev.azure.com/heartlandschools/Mobile/_git/MSBA.MAUI/pullrequest/48865 | U8: 46148 | V8: 46148 | W8: Ashwin | X8: NA | Y8: Avery | Z8: 46150 | AA8: Comments - 3 -This array is duplicated from ViewModelBase.cs Add a protected helper method to ViewModelBase for consistency -This is missing an await -The ApplyPendingChange() and RevertPendingChange() methods add ~200 lines - Instead consider simpler approach. | AB8: POV done with Bavithra No Comment | AC8: NA | AD8: 04 May : Other day, I had a plan to do the POV, however during UT, i found some issue, so will be working on that issue and then will run the POV. 05 May : Found some issue during peer testing, will be fixing those. 06 May : did the POV both internal and external and raised the PR.. 07-Vaishnavi- Will be updating the test cases for this story 08 - Received few comment from Avery, will resolve it today. 11 May - Receive one BB, will be working on that. | AE8: Exceeds Expectation | AG8: Main
A9: 15 | B9: MSB Mobile Kaleida | C9: 46143 | D9: 46156 | E9: 26.5 M Sprint 3 | F9: Jagdeep/Prem | G9: 48498 | H9: [WAVE] MSBA - Receipt Screen - Show Confirmation/Green Check once SMS/Email Sent | I9: Story Completed | J9: 1 | L9: 11 | M9: 46142 | N9: 46146 | O9: NA | P9: Rupesh | Q9: NA | R9: Rupesh/Sambath | S9: NA | T9: https://dev.azure.com/heartlandschools/Mobile/_git/MSBA.MAUI/pullrequest/48815 | U9: 46146 | V9: 46147 | W9: Ashwin | X9: NA | Y9: Avery | Z9: 46147 | AA9: Count :- 2 1. WasSent should be reset to false in OnError handler, failed sends should show 'Send' not 'Resend' 2. Change OriginalButtonText from field to property. | AB9: POV done with Bavithra No Comment | AC9: POV done with Jason No Comment | AD9: 04 May - Will continue work on this defect and will do POV today. 05 May - Will work for to resolve PR comment.(Comment Resolved Story under peer a review) 06 May - Story ready for testing. 07 May - Test Case updation and testing completed | AE9: Exceeds Expectation | AG9: Main
A10: 16 | B10: MSB Mobile Kaleida | C10: 46143 | D10: 46156 | E10: 26.5 M Sprint 3 Stretch | F10: Gursewak/Sambath/Prem | G10: 27318 | H10: MSBA - Kaleida - I/A - Unable to navigate back from Admin Settings when shift is already active | I10: Defect Fixed | J10: 3 | L10: 14 | M10: 46146 | N10: 46149 | O10: NA | P10: Yes | Q10: NA | R10: NA | S10: NA | T10: https://dev.azure.com/heartlandschools/Mobile/_git/MSBA.MAUI/pullrequest/48817?base=2&iteration=3 | U10: 46149 | V10: 46149 | W10: Ashwin | X10: NA | Y10: Avery | Z10: 46149 | AA10: NA | AB10: POV done with Bavithra No Comment | AC10: NA | AD10: 04 May - Will start working on this defect. 04 May-EOD-Worked on analyzing and reproducing the issue, then started working on a fix. After that, the issue was resolved and tested on iPhone and iPad. Reviewed the code with Ashwin, and he suggested finding an alternative approach to resolve the problem. I will work with Sambath on this. 05 May - As ashwin suggested need to work with Sambath on this defect. 06 May - Ashwin sent message on slack for more clarification from Jason, waiting for reply. 07 May - As Sambath discussed with Ashwin, need to check on Meal Money page and Transaction Page, if it is not effect on these pages we will inform to client., Sambath also support me on the same today. 07 May - EOD - Merged, ready for test. QA team working on the main commit defects/stories follwed by regression testing. 08 Apr - Testing Completed | AE10: Exceeds Expectation | AF10: NA | AG10: Stretch
A11: 17 | B11: MSB Mobile | C11: 46143 | D11: 46156 | E11: 26.5 M Sprint 3 | F11: chandler/vaishnavi/ | G11: 27320 | H11: 27320 MSBP - Android - All text and sizes are inflated on pixel pro devices, sometimes pushing items off viewable area (26.5) | I11: Defect Being Tested | J11: 2 | M11: NA | N11: NA | O11: NA | P11: NA | Q11: NA | R11: NA | S11: NA | T11: NA | U11: NA | V11: NA | W11: NA | X11: NA | Y11: NA | Z11: NA | AA11: NA | AB11: NA | AC11: NA | AD11: This is issue is not reproduced in emaulator, need to test with device, so once received new device, i will continue to work. Waiting for new device to fix this issue. 7- May - will relate the new user stories to solve the correct way with responsive design. will relate the new epic which we'll refine. Added by RJ may be it could move to rejected status.. . 08-Apr - Prem/Vaishnavi - As per disucssion with Letashia, we will work on the testing with different devices.. 11-May - testing in progress. . 12-May- chandler working on the fix. 14-May- testing in progress. still facing few issues with pixel devices. will be sending those to letashia's review. | AG11: Main
A12: 18 | B12: MSB Mobile Kaleida | C12: 46143 | D12: 46156 | E12: 26.5 M Sprint 3 | F12: Prem | G12: 52989 | H12: MSB - Web - Parent Portal - Re-attach orphaned Invoices to students that were deleted and returned - MOBILE TESTING STORY | I12: Story Completed | J12: 2 | L12: 8 | M12: NA | N12: NA | O12: NA | P12: NA | Q12: NA | R12: NA | S12: NA | T12: NA | U12: NA | V12: NA | W12: NA | X12: NA | Y12: NA | Z12: NA | AA12: NA | AB12: NA | AC12: NA | AD12: 05 May - will start working on test case updation and will continue once the test case updation gets done 06 May - Test case updation and testing is completed | AE12: Exceeds Expectation | AG12: Main
A13: 19 | B13: MSB Mobile Kaleida | C13: 46143 | D13: 46156 | E13: 26.5 M Sprint 3 Stretch | F13: Jagdeep/vaishnavi | G13: 52343 | H13: [WAVE] MSBA - Kaleida - Update Offset Language - Difference(Over/Short) | I13: Story Being Tested | J13: 2 | L13: 5 | M13: 46147 | N13: 46148 | O13: NA | P13: Amrit/Vashnavi | Q13: NA | R13: Rupesh/Sambath | S13: NA | T13: https://dev.azure.com/heartlandschools/Mobile/_git/MSBA.MAUI/pullrequest/48842 | U13: 46147 | V13: 46149 | W13: Ashwin | X13: NA | Y13: Avery | Z13: 46149 | AA13: NA | AB13: POV done with Bavithra No Comment | AC13: POV done with Jason No Comment | AD13: 05 May - Starting work on this story. 06 May - Will create apk file and will share to Vashnavi for internal testing with printer.(POV done , Story under peer review , waiting Approval from Ashwin and client side). 08 May - Story ready for testing.QA team working on the main commit defects/stories follwed by regression testing.. 12-May - Due to regression testing, testing is on hold for this story. | AF13: Due to regression testing and other high priority defects/stories, this story was not worked by the tester | AG13: Stretch
A14: 20 | B14: MSB Mobile | C14: 46143 | D14: 46156 | E14: 26.5 M Sprint 3 Stretch | F14: Rupesh | G14: 27234 | H14: MSBA - Cart consolidated after promocode addition causing issue when allow user to set qty = no (26.7) | I14: Defect Blocked | J14: 2 | L14: 4 | M14: 46147 | N14: NA | O14: NA | P14: NA | Q14: NA | R14: NA | S14: NA | T14: NA | U14: NA | V14: NA | W14: NA | X14: NA | Y14: NA | Z14: NA | AA14: NA | AB14: NA | AC14: NA | AD14: 06 May - Development is in progress. 07 May - looks like api issue, I will get all the api response and see where it is breaking. 08 May - Ashwin asked me to try one approach(Same product with different stock option) and then see how orders are getting created. 11 May - Created a doc with all the possible scenarios, Ashwin reviewed and asked to make some changes. | AE14: Exceeds Expectation | AF14: When allow user to set qty = no (26.7) the issue is that the API result when applying promocode is combining the products into a single order. The fix for this should be that for products with allow user to set qty set to no should create separate orders for each product and not combine it under one order. Request: curl --location --request PUT 'https://test.www.myschoolbucks.com/mobilepay/3.0/checkout/process/' \ --header 'apiKey: EX87L7NSH3WM5X5FB25LMM1PBY5ELW' \ --header 'token: 94VWV2BY31EJYP5' \ --header 'mfaSessionKey: KH4AYWBNTIIKQR6' \ --header 'Content-Type: application/json' \ --header 'Cookie: JSESSIONID=YpWUueQMj9D00UJCi41sOKYJF07oXEwEi_gXVTnU.schoolbucks-cluster-5965cd768c-ktlbx; TS01dc4fc6=010e7b7cc2cf32352e80dfb1c4ca91a26abc4b34a2d73c7d46c0a91c1342c1bb6dcbd91c913ca9c8f24714f13e25787edf3de8a672' \ --data '{ "fundingDetailsInvoices": {}, "fundingDetailsMeals": {}, "storeItems": [ { "productRef": "KytlcCcpfSR1I3krJXdy", "quantity": 1, "unitPrice": 100.00, "stockOptionID": "opt1607", "studentKey": null, "formFields": null, "ignoreAddOn": false, "ignoreInventory": false, "ignoreSalesTax": false }, { "productRef": "KytlcCcpfSR1I3krJXdy", "quantity": 1, "unitPrice": 100.00, "stockOptionID": "opt1607", "studentKey": null, "formFields": null, "ignoreAddOn": false, "ignoreInventory": false, "ignoreSalesTax": false } ], "paymentMethodDetails": { "paymentMethodType": "Cash", "signatureImageFormat": "JPG" }, "promoCodeId": "regressiontest1", "appVersion": "15", "deviceDesc": "417591003b5efa57" }' Response: { "result": 1, "message": "", "basketKey": "", "programFee": 0.00, "salesTax": 0.00, "subtotal": 190.00, "subTotalBeforePromoCodes": 200.00, "promoCodeTotal": -10.00, "appliedPromoCodes": [ { "amount": 10.00, "quantity": -1, "amountIsPercentage": false, "minimumOrderTotal": 10.00, "name": "regressiontest1", "id": "regressiontest1", "desc": "", "error": "" } ], "failedPromoCodes": [], "orders": [ { "clientKey": "ZZJ22K7JR50ZCV3", "fees": 0.00, "salesTax": 0.00, "orderSubtotal": 190.00, "cardEntryType": [], "storeItems": [ { "studentKey": "", "imageLink": "", "name": "TestRupesh2", "unitPrice": 90.00, "unitPriceBeforePromoCode": 100.00, "amount": 90.00, "amountBeforePromoCode": 100.00, "quantity": 1, "availableQuantity": 1, "clientKey": "ZZJ22K7JR50ZCV3", "productRef": "KytlcCcpfSR1I3krJXdy", "productID": "prod448", "storeID": "10OQG", "clientID": "", "stockOptionID": "opt1607", "propertyValues": [] }, { "studentKey": "", "imageLink": "", "name": "TestRupesh2", "unitPrice": 100.00, "unitPriceBeforePromoCode": 100.00, "amount": 100.00, "amountBeforePromoCode": 100.00, "quantity": 1, "availableQuantity": 1, "clientKey": "ZZJ22K7JR50ZCV3", "productRef": "KytlcCcpfSR1I3krJXdy", "productID": "prod448", "storeID": "10OQG", "clientID": "", "stockOptionID": "opt1607", "propertyValues": [] } ], "invoiceItems": [], "mealPayments": [], "gatewayDetails": [ { "paymentMethodType": "cash", "userName": null, "password": null, "siteID": null, "licenseID": null, "deviceID": null, "developerID": null, "versionNumber": null, "url": null, "message": "Order not for (Chip/Contactless) credit card txn" } ] } ], "redirectUrl": "", "returnToSiteUrl": "" } After this when we try to checkout since the qty is changed the below API is throwing an error. curl --location 'https://test.www.myschoolbucks.com/mobilepay/3.0/checkout/paymentMethods' \ --header 'apiKey: EX87L7NSH3WM5X5FB25LMM1PBY5ELW' \ --header 'token: 94VWV2BY31EJYP5' \ --header 'mfaSessionKey: KH4AYWBNTIIKQR6' \ --header 'Content-Type: application/json' \ --header 'Cookie: JSESSIONID=3bTmR4zbXdLD6PJOXcyyd4m0kEZWnDxzbbmatjWD.schoolbucks-cluster-7d6d5594b-7nrrl; TS01dc4fc6=010e7b7cc2d0b63ca816bf6e93c45505976c7223911e6c4b234f37a1bd14afa6ff3a6e811f963dde0197c017fec585426131190645' \ --data '{ "storeItems": [ { "productRef": "KytlcCcpfSR1I3krJXdy", "quantity": 2, "unitPrice": 100.00, "stockOptionID": "opt1607", "studentKey": null } ] } Response: { "result": 2, "message": "Unable to create basket items from checkout request. Ex: KytlcCcpfSR1I3krJXdy:You are not allowed to set the quantity." } | AG14: Stretch
A15: 21 | B15: MSB Mobile | C15: 46143 | D15: 46156 | E15: 26.5 M Sprint 3 | F15: Vaishnavi | G15: 52988 | H15: MSB - Web - Parent Portal - Allow Payment on Invoices for Deleted Students - MOBILE TESTING STORY | I15: Story Completed | J15: 3 | L15: 5 | M15: NA | N15: NA | O15: NA | P15: NA | Q15: NA | R15: NA | S15: NA | T15: NA | U15: NA | V15: NA | W15: NA | X15: NA | Y15: NA | Z15: NA | AA15: NA | AB15: NA | AC15: NA | AD15: 05 May - will start working on test case updation and will continue once the test case updation gets done. 06-May- will work on the testing. Had the doubts clarified from letashia yesterday. 07-As per Jason and troy discussion, this story can be closed as it needs a future enhancement. Will be confirming with Letashia and closing this story today. . 08-Apr - Prem/Vaishnavi - As per disucssion with Letashia, we will work on the testing with different devices. | AG15: Main
A16: 22 | B16: MSB Mobile | C16: 46143 | D16: 46156 | E16: 26.5 M Sprint 3 Stretch | F16: Amrit/Gursewak | G16: 27283 | H16: MSBA - MAUI - iOS- meal payments screen changing formatting when cart preview is on with items in it | I16: Defect Peer Review | J16: 1 | L16: 6 | M16: 46150 | N16: 46153 | O16: NA | P16: Gursewak | Q16: NA | R16: Rupesh/Sambath | S16: NA | T16: https://dev.azure.com/heartlandschools/Mobile/_git/MSBA.MAUI/pullrequest/48972 | U16: 46153 | V16: NA | W16: NA | X16: NA | Y16: NA | Z16: Na | AA16: NA | AB16: POV done with Bavithra No Comment | AC16: NA | AD16: 6 May - Reproducing and analyzing defect 7 May - Issue is in particular iPad 9 26.3.1 real device we will have to test internally in this device 8 May - TODO PEER Testing today 08 May -Gursewak - Support to Amrit for Peer testing. 11 May - Defect PR Created POV Pending 12 May - PR Approved by Rupesh pending from Samath 13 May - PR Approved by Rupesh pending from Samath 14 May - PR Pending from Client Side | AE16: Exceeds Expectation | AF16: Peer review | AG16: Stretch
A17: 23 | B17: MSB Mobile Kaleida | C17: 46143 | D17: 46156 | E17: 26.5 M Sprint 3 Stretch | F17: Jagdeep | G17: 27276 | H17: MSBP - Android - Can double click and open multiple stacks of menus | I17: Defect Ready For Testing | J17: 3 | L17: 9 | M17: 46148 | N17: 46150 | O17: NA | P17: Gursewak | Q17: NA | R17: Rupesh/Sambath | S17: NA | T17: https://dev.azure.com/heartlandschools/Mobile/_git/MSBP.MAUI/pullrequest/48903 | U17: 46149 | V17: 46155 | W17: Ashwin | X17: NA | Y17: Avery | Z17: 46155 | AA17: NA | AB17: POV done with Bavithra No Comment | AC17: NA | AD17: 6 May- Starting work on this defect. 7 May - will continue work on this defect. 8 May - Defect under Peer review . 14 May - Defect ready for testing. | AF17: Due to regression testing and other high priority defects/stories, this story was not worked by the tester | AG17: Stretch
A18: 25 | B18: MSB Mobile Kaleida | C18: 46143 | D18: 46156 | E18: 26.5 M Sprint 3 Stretch | F18: Gursewak | G18: 27015 | H18: MSBA - MAUI - iphone - invoice add to cart button not formatted correctly (regression) | I18: Defect Ready For Testing | J18: 1 | L18: 2.5 | M18: 46150 | N18: 46150 | O18: NA | P18: Yes | Q18: NA | R18: Rupesh/Sambath | S18: NA | T18: https://dev.azure.com/heartlandschools/Mobile/_git/MSBA.MAUI/pullrequest/48924 | U18: 46150 | V18: 46150 | W18: NA | X18: NA | Y18: NA | Z18: NA | AA18: NA | AB18: POV done with Bavithra No Comment | AC18: NA | AD18: 08 May, Start working on it, issue fixed, POV done, ready for review. 09 May - Ashwin marked the pull request as a draft 14 May - New release branch 26.5 is created, now change the branch, and ready for review. internal team review the PR. Ashwin and client side pending. 14 May - EOD - Merged, ready for test now. | AE18: Exceeds Expectation | AF18: NA | AG18: Stretch
A19: 26 | B19: MSB Mobile | C19: 46143 | D19: 46156 | E19: 26.5 M Sprint 3 Stretch | F19: Amrit | G19: 27006 | H19: MSBA - MAUI - iOS - Cart has extra space underneath buttons (regression) | I19: Defect Peer Review | J19: 1 | L19: 6 | M19: 46150 | N19: 46153 | O19: NA | P19: Gursewak | Q19: NA | R19: Rupesh/Sambath | S19: NA | T19: https://dev.azure.com/heartlandschools/Mobile/_git/MSBA.MAUI/pullrequest/48926 | U19: 46153 | V19: NA | W19: NA | X19: NA | Y19: NA | Z19: NA | AA19: NA | AB19: POV done with Ashwin No Comment | AC19: NA | AD19: 8 May - Analyzing and reproducing defect 11 May - Defect ready for PEER Review 12 May - PR In Review 13 May - PR Pending Internal review 14 May - PR Pending from Ashwin and Client Side | AE19: Exceeds Expectation | AF19: Peer review | AG19: Stretch
A20: 27 | B20: MSB Mobile Kaleida | C20: 46143 | D20: 46156 | E20: 26.5 M Sprint 3 Stretch | F20: Jagdeep | G20: 27255 | H20: MSBP - missing phone number page and profile phone pages do not match | I20: Defect Peer Review | J20: 1 | L20: 3 | M20: 46150 | N20: 46153 | O20: NA | P20: Amrit | Q20: NA | R20: Rupesh | S20: NA | T20: https://dev.azure.com/heartlandschools/Mobile/_git/MSBP.MAUI/pullrequest/49015 | U20: 46153 | V20: NA | W20: NA | X20: NA | Y20: NA | Z20: NA | AA20: NA | AB20: POV done with Bavithra No Comment | AC20: NA | AD20: 11 May - requirement cleared today will work and complete it. 12 May - Defect under peer review.(Sambath , ashwin, and client side pending). 14 May - Waiting for aproval from Ashwin and Client side. | AF20: Defect fixed still PR in Review, Ashwin and client side review pending | AG20: Stretch
A21: 28 | B21: MSB Mobile Kaleida | C21: 46143 | D21: 46156 | E21: 26.5 M Sprint 3 Stretch | F21: Gursewak | G21: 26881 | H21: MSBA - Cart icon/badge is larger than expected (regression) | I21: Defect Ready For Testing | J21: 1 | L21: 4.5 | M21: 46150 | N21: 46153 | O21: NA | P21: Yes | Q21: NA | R21: Rupesh/Sambath | S21: NA | T21: https://dev.azure.com/heartlandschools/Mobile/_git/MSBA.MAUI/pullrequest/48932 | U21: 46153 | V21: 46153 | W21: NA | X21: NA | Y21: NA | Z21: NA | AA21: NA | AB21: POV done with Bavithra No Comment | AC21: NA | AD21: 08 May- Working on it. 11 May - Will fix this issue, do the POV, and create the PR. 12 May - Ashwin and client side review pending. 14 May - New release branch 26.5 is created, now change the branch, and ready for review. internal team review the PR. Ashwin and client side pending. 14 May - EOD - Merged, ready for test now. | AE21: Exceeds Expectation | AF21: NA | AG21: Stretch
A22: 29 | B22: MSB Mobile | C22: 46143 | D22: 46156 | E22: 26.5 M Sprint 3 Stretch | F22: Vaishnavi/Prem | G22: 53092 | H22: REG - MSBP - Regression 26.5 | I22: Story Being Tested | J22: 8 | M22: NA | N22: NA | O22: NA | P22: NA | Q22: NA | R22: NA | S22: NA | T22: NA | U22: NA | V22: NA | W22: NA | X22: NA | Y22: NA | Z22: NA | AA22: NA | AB22: NA | AC22: NA | AD22: 12-May - Will work on the testing today. 14-May - Testing in progress. Vaishnavi - As per letashia, defect 27320 needs to be completed first, will be working on that. later will work on the pending regression test cases. | AG22: Stretch
A23: 30 | B23: MSB Mobile Kaleida | C23: 46143 | D23: 46156 | E23: 26.5 M Sprint 3 | F23: Jagdeep | G23: 27389 | H23: MSBP - MAUI - Android - Cart icon showing the badge count when no items available in the shopping cart (regression) | I23: Defect Fixed | J23: 0 | L23: 4 | M23: 46155 | N23: 46155 | O23: NA | P23: Gursewak | Q23: NA | R23: Rupesh/Sambath | S23: NA | T23: https://dev.azure.com/heartlandschools/Mobile/_git/MSBP.MAUI/pullrequest/49020 | U23: 46155 | V23: 46155 | W23: Ashwin | X23: NA | Y23: Avery | Z23: 46155 | AA23: NA | AB23: POV done with Ashwin No Comment | AC23: NA | AD23: 13 May - Start work on this defect. 14 May - Defect ready for testing. | AG23: Main
A24: 31 | B24: MSB Mobile | C24: 46143 | D24: 46156 | E24: 26.5 M Sprint 3 | F24: Rupesh | G24: 27394 | H24: MSBA - stock option formatting issues (regression) | I24: Defect Peer Review | J24: 0 | L24: 8 | M24: 46155 | AD24: 13 May - will analyse and then start the development. 14 May - will try to fix it and run the POV today. | AF24: Picked up on 13th May as this regression defect was created at the last moment. | AG24: Main
B25: MSB Mobile | C25: 46143 | D25: 46156 | E25: 26.5 M Sprint 3 | F25: Dev Team | G25: 87660 | H25: MSB Mobile - Exploratory Testing | I25: Story Completed | J25: 8 | L25: 62

Sheet 26.5 M Sprint 3-Defect
A1: S.No | B1: Sprint # | C1: Story/Defect ID | D1: Parent Story | E1: Developer | F1: Issue Type | G1: Issue Description | H1: Priority | I1: Defect Source | J1: Type | K1: Status | L1: Root Cause Category | M1: Who Reported It? | N1: Comments
B2: 26.5 M Sprint 3 | C2: 26882 MSBA - Cart Icon does not have the correct MSBA blue background | D2: 26882 MSBA - Cart Icon does not have the correct MSBA blue background | E2: Amrit/ | F2: Defect | H2: Minor | I2: Manual | J2: Internal | K2: Closed | L2: Development | M2: Relevantz QA | N2: Xamarin to Maui conversion defects
B3: 26.5 M Sprint 3 Stretch | C3: 27318 MSBA - Kaleida - I/A - Unable to navigate back from Admin Settings when shift is already active | D3: 27318 MSBA - Kaleida - I/A - Unable to navigate back from Admin Settings when shift is already active | E3: Gursewak/Sambath | F3: Defect | H3: Minor | I3: Manual | J3: Internal | K3: Closed | L3: Development | M3: Relevantz QA | N3: Maui to Kaleida conversion defects
