Workbook

Sheet Dashboard
A1: Current Sprint | B1: {=INDEX($B$2:$B$99,MATCH(1,(($D$2:$D$99 >=TODAY())*($C$2:$C$99<=TODAY())),0))} -> GGO 8.4.0 Sprint 4 | C1: Current Sprint Sheet | D1: =CONCATENATE(B1,"-Status") -> GGO 8.4.0 Sprint 4-Status | E1: Sprint Start Date | F1: =VLOOKUP($B$1,$B$1:$C$99,2) -> 46156 | G1: Sprint End Date | H1: =VLOOKUP($B$1,$B$1:$D$99,3) -> 46170 | I1: Application Name | J1: GGO Web | K1: Users | L1: jennifer.anthony@relevantz.com;saranya.namachivayam@relevantz.com;sathiyabharathi.paramasivam@relevantz.com;priyadharshini.ravichandran@relevantz.com;rajeshkannan.subramanian@relevantz.com;satarupa.mohanty@relevantz.com | M1: Teams Name(GP-GGO.Web) | N1: 19:ac26c2f1541e4a10bdec732dd7eb2936@thread.v2
A2: Sprint Type | B2: Sprint # | C2: Sprint Start Date | D2: Sprint End Date | E2: Assigned | F2: Completed | G2: Story points introduced/removed | H2: Sprint Summary | I2: Accomplishments | J2: Remarks | K2: Retro Points (Internal & External) | L2: Data sanity Audit Status | M2: AuditDate | N2: Planned Leaves | O2: Availed Leaves | P2: Backlog Health
A3: =IF(AND($D$1>=C3,$D$1<=D3),"CurrentSprint","NA") -> NA | B3: GGO 7.15.0 Sprint 4 | C3: 45303 | D3: 45316 | E3: 17 | F3: 15 | G3: 7 | J3: Completed all the introduced story in the mid of the sprint | K3: Internal: External:
A4: =IF(AND($D$1>=C4,$D$1<=D4),"CurrentSprint","NA") -> NA | B4: GGO 7.16.0 Sprint 1 | C4: 45317 | D4: 45330 | E4: 17 | F4: 14 | G4: 3 | J4: Actual estimated stories (17pts) got completed from our end with Development and Testing, From Onsite QA (Nate) took time for testing 3 point story because of PRD release and he took half day leave and he got only 4 hrs of time. So from this I would like to say, we should plan to complete the estimated stories 2 days prior, else Nate won't close on the last day of sprint. Introduced Story - 3 point is Development completed, only Testing pending. | K4: Internal: External:
A5: =IF(AND($D$1>=C5,$D$1<=D5),"CurrentSprint","NA") -> NA | B5: GGO 7.16.0 Sprint 2 | C5: 45331 | D5: 45344 | E5: 23 | F5: 22 | G5: 2 | J5: Completed all the stories on time, but we noticed one minor issue in GGO-13703 Bid-18 report on xls and xlsx formats. the column header occupying some aditional column . It require an report engine code changes.verified some other reports also having the same issue and it's an existing issue.completed introduced story as well | K5: Internal: External:
A6: =IF(AND($D$1>=C6,$D$1<=D6),"CurrentSprint","NA") -> NA | B6: GGO 7.16.0 Sprint 3 | C6: 45345 | D6: 45358 | E6: 27 | F6: 23 | G6: 7 | J6: GGO-13801-onsite QA(Nathan) raised one bug , we tried to reproduce the issue on rounding but we are not able to do that. We have asked for the steps to reproduce the issue. GGO-13738 -Development has been completed on this story, it require's IT team support to complete the testing. Introduced Story - 7 points (Except GGO-13738 testing) all completed | K6: Internal: External:
A7: =IF(AND($D$1>=C7,$D$1<=D7),"CurrentSprint","NA") -> NA | B7: GGO 7.16.0 Sprint 4 | C7: 45359 | D7: 45372 | E7: 20 | F7: 16 | G7: 5 | J7: GGO-13796 and GGO-13773 development has been completed.testing requires IT team support to complete,currently salesforce team doing some changes at their side we can't test salesforce api's .Introduced Story - 5 points Develpment has been completed for that. | K7: Internal: External:
A8: =IF(AND($D$1>=C8,$D$1<=D8),"CurrentSprint","NA") -> NA | B8: GGO 7.17.0 Sprint 1 | C8: 45373 | D8: 45386 | E8: 14 | F8: 11 | G8: 3 | J8: Since we need support from sales force team for testing GGO -13773 ,PAPI-702 saranya supported Mike wall for testing We got info from Doug about the 4 PROD issues in planning meeting 1. Convenience Fee Issue - Not able to reproduce by our team and Onsite QA in DEV, TST & CRT, it is occurring only in PRD, finding a way to check the values, settings in PROD to replicate in lower envrionment 2. Package Tax Issue - Round off to whole number instead of 2 decimal, this is our mistake that has got in to PRD 3 months before, when fixing old code to replace SQL CLR to C# method. 3. Item tax added to Package - This was old issue, but many clients started to raise concern about this issue now, because of our new implementation for Convenience Fee. 4. Payment show error when Actually it is success in PAPI for Few Clients in PRD - Still don't know the reason, analysing the root cause of this issue. | K8: Internal: External:
A9: =IF(AND($D$1>=C9,$D$1<=D9),"CurrentSprint","NA") -> NA | B9: GGO 7.17.0 Sprint 2 | C9: 45387 | D9: 45400 | E9: 19 | F9: 17 | G9: 0 | J9: This sprint we fixed production issues and macroscope security issues . PAPI-702 carried because card details need to verified with PAPI database, we don't have required permission for that, only onsite QA need to be verified. | K9: Internal: External:
A10: =IF(AND($D$1>=C10,$D$1<=D10),"CurrentSprint","NA") -> NA | B10: GGO 7.17.0 Sprint 3 | C10: 45401 | D10: 45414 | E10: 18 | F10: 11 | G10: 0 | J10: 2 stories got carried. 1. Due to salesforce team confirmed they can't do any changes. 2. Onshore Testing is pending | K10: Internal: External:
A11: =IF(AND($D$1>=C11,$D$1<=D11),"CurrentSprint","NA") -> NA | B11: GGO 7.17.0 Sprint 4 | C11: 45415 | D11: 45428 | E11: 14 | F11: 4 | G11: 0 | J11: CRT Regression Testing is still in Progress. 3 stores are blocked and carried because of IT dependencey (Certificate Issue and Permission issue for Report Instance folder in DEV & TST Environments), all the development and testing works are done from our end. | K11: Internal: External:
A12: =IF(AND($D$1>=C12,$D$1<=D12),"CurrentSprint","NA") -> NA | B12: GGO 7.18.0 Sprint 1 | C12: 45429 | D12: 45442 | E12: 15 | F12: 14 | G12: 0 | J12: Testing blocked due to certificate issue | K12: Internal: External:
A13: =IF(AND($D$1>=C13,$D$1<=D13),"CurrentSprint","NA") -> NA | B13: GGO 7.18.0 Sprint 2 | C13: 45443 | D13: 45456 | E13: 20 | F13: 16 | G13: 0 | K13: Internal: External:
A14: =IF(AND($D$1>=C14,$D$1<=D14),"CurrentSprint","NA") -> NA | B14: GGO 7.18.0 Sprint 3 | C14: 45457 | D14: 45470 | E14: 17 | F14: 15 | G14: 2 | K14: Internal: External:
A15: =IF(AND($D$1>=C15,$D$1<=D15),"CurrentSprint","NA") -> NA | B15: GGO 7.18.0 Sprint 4 | C15: 45471 | D15: 45484 | E15: 20 | F15: 20 | G15: 0 | K15: Internal: External:
A16: =IF(AND($D$1>=C16,$D$1<=D16),"CurrentSprint","NA") -> NA | B16: GGO 7.19.0 Sprint 1 | C16: 45485 | D16: 45498 | E16: 15 | F16: 15 | G16: 5 | J16: Two stretch stories got carried to next sprint. | K16: Internal: External:
A17: =IF(AND($D$1>=C17,$D$1<=D17),"CurrentSprint","NA") -> NA | B17: GGO 7.19.0 Sprint 2 | C17: 45499 | D17: 45511 | E17: 6 | F17: 6 | G17: 7 | J17: Two stretch stories got carried to next sprint. | K17: Internal: External:
A18: =IF(AND($D$1>=C18,$D$1<=D18),"CurrentSprint","NA") -> NA | B18: GGO 7.19.0 Sprint 3 | C18: 45512 | D18: 45526 | E18: 16 | F18: 16 | G18: 2 | K18: Internal: External:
A19: =IF(AND($D$1>=C19,$D$1<=D19),"CurrentSprint","NA") -> NA | B19: GGO 7.19.0 Sprint 4 | C19: 45527 | D19: 45540 | E19: 17 | F19: 14 | G19: 2 | J19: Automation Regression story got carried over as it was new for Offshore QA and there was some learning curve involved. | K19: Internal: External:
A20: =IF(AND($D$1>=C20,$D$1<=D20),"CurrentSprint","NA") -> NA | B20: GGO 7.20.0 Sprint 1 | C20: 45540 | D20: 45554 | E20: 15 | F20: 13 | G20: 2 | J20: 2 point carry forwarded to next sprint, development and testing completed from our end, but onsite QA didn't complete it. | K20: Internal: External:
A21: =IF(AND($D$1>=C21,$D$1<=D21),"CurrentSprint","NA") -> NA | B21: GGO 7.20.0 Sprint 2 | C21: 45555 | D21: 45568 | E21: 19 | F21: 14 | G21: 2 | J21: GGO-14067 got carried, We are migrating Bid-03 report to new RDLC framework, there is lot of existing logic present in RPT file. we need to exactly replicate same logic in SQL stored procedure for new RDLC format.understanding .rpt file logic is complication involved Peer CRC:0 Onsite CRC: 0 Client CRC: 0 Internal Defects: 0 External Defects: 0 | K21: Internal: External:
A22: =IF(AND($D$1>=C22,$D$1<=D22),"CurrentSprint","NA") -> NA | B22: GGO 7.20.0 Sprint 3 | C22: 45569 | D22: 45582 | E22: 17 | F22: 12 | J22: GGO-14067 got carried, Getting Timeout issue for large records,Suporterwise page breakup and some functionlity in spreadsheetlayout is pending Onsite CRC: 0 Onsite CRC: 0 Client CRC: 0 Internal Defects: 1 External Defects: 0 | K22: Internal: External:
A23: =IF(AND($D$1>=C23,$D$1<=D23),"CurrentSprint","NA") -> NA | B23: GGO 7.20.0 Sprint 4 | C23: 45583 | D23: 45596 | E23: 16 | F23: 13 | I23: 1. Login Page Privacy policy update in MFA login page of GGO application 2. Paymen Receipt in new RDLC replacing form display helps users to download receipt as PDF and send email with attachment. | J23: GGO-14067 got carried, Getting Timeout issue for large records Onsite CRC: 0 Client CRC: 0 Internal Defects: 1 External Defects: 0 | K23: Internal: External:
A24: =IF(AND($D$1>=C24,$D$1<=D24),"CurrentSprint","NA") -> NA | B24: GGO 7.21.0 Sprint 1 | C24: 45597 | D24: 45610 | E24: 18 | F24: 17 | G24: 3/0 | I24: 1.Fixed Timeout issue on Bid-03 RDLC report generation. 2.Completed two tickets introduced in the mid of the sprint | J24: Completed all story points on time Onsite CRC: 0 Client CRC: 0 Internal Defects: 2 External Defects: 0 | K24: Internal: External:
A25: =IF(AND($D$1>=C25,$D$1<=D25),"CurrentSprint","NA") -> NA | B25: GGO 7.21.0 Sprint 2 | C25: 45611 | D25: 45621 | E25: 14 | F25: 11 | I25: 1. Fixed Grid selection issue on Bid-03 RDLC report generation. 2. Fixed Azure Images issue replacing content server url with azure url 3. Investigated GGO to OB Queue flow to replace it with Quartz Job. 4. Allow GGO to validate and support different card card types (JCB, Diners club & Discover Debit) | J25: GGO-13319 story got rolled over due to Azure image access issue and a ticket with Microsoft has been opened​ by IT Onsite CRC: 0 Client CRC: 1 Internal Defects: 0 External Defects: 0 | K25: Internal: External:Rajesh and offshore for continued work on reports Priya, Nathan and Conor for testing a lot of stories and completing them
A26: =IF(AND($D$1>=C26,$D$1<=D26),"CurrentSprint","NA") -> NA | B26: GGO 7.21.0 Sprint 3 | C26: 45622 | D26: 45638 | E26: 14 | F26: 14 | G26: 7/0 | I26: 1. Application images moved in Azure , previously we stored the images in DB as bytes 2. 7.20.1 Successfully deployed to PRD 3. EMV Implementation -completed most of the cardreader functionality | J26: GGO-14325 - BID-06 story is a huge effort and cannot be completed in one sprint, hence it was taken as a strech goal Peer CRC:0 Onsite CRC: 0 Client CRC: 0 Internal Defects: 0 External Defects: 0 | K26: Internal: External:
A27: =IF(AND($D$1>=C27,$D$1<=D27),"CurrentSprint","NA") -> NA | B27: GGO 7.21.0 Sprint 4 | C27: 45639 | D27: 45666 | E27: 24 | F27: 19 | G27: 3/0 | I27: 1. Fixed Duplicate Event X Code issue that was a PROD bug for more than 5 years. 2. Good progress on Bid-06 RDLC update and feel confident in completing it next sprint 3. Popup warning for Convenience fee validation implemented 4. Quartz Job implemented for Bid-06 email flow with our own effort and stored the PDF in Azure. | J27: GGO-14427 - BID-06 - Part-3 story is a huge effort, this has got more than 100 scenario's, so it took more time for testing left out with 2 bugs at the end of sprint (development done for the bugs) only testing pending. Peer CRC:0 Onsite CRC: 0 Client CRC: 0 Internal Defects: 8 External Defects: 0 | K27: Internal: External: Offshore team made great progress on Bid-06 report
A28: =IF(AND($D$1>=C28,$D$1<=D28),"CurrentSprint","NA") -> NA | B28: GGO 7.22.0 Sprint 1 | C28: 45667 | D28: 45680 | E28: 21 | F28: 17 | G28: 4/0 | I28: 1.GGO-14484 Jan 21 Prod Release 2. Successfully completed Bid-06 with new report tool set 3. CRT regression testing completed | J28: GGO-14427 - BID-06 - Part-3 during the CRT testing noticed package item enabled scenario taking too long to complete the report - immediately addressed this Issue. GGO-14483 Completed CRT Release & Regression Testing Peer CRC:0 Onsite CRC: 0 Client CRC: 0 Internal Defects: 6 External Defects: 0 Reason for pending: GGO-14422, PAPI-789 - Development and Testing completed from our end, Pending testing from Nate (Onsite QA) because he was focusing more in CRT regression. GGO-14447 - Automation story completed from our end, pending review from Nate GGO-14450 - A.C change one day prior to Sprint end date, so it got carry forward to next sprint
A29: =IF(AND($D$1>=C29,$D$1<=D29),"CurrentSprint","NA") -> NA | B29: GGO 7.22.0 Sprint 2 | C29: 45681 | D29: 45694 | E29: 18 | F29: 11 | G29: 2/0 | I29: 1.Enhance RSVP Functionality with key features to enable better data gathering and management of attendee info. 2.Azure Thumbnail image creation issue fix - Add this project as part of GGO Solution and build it via Build pipeline and add it to GGO Artifact | J29: Peer CRC:0 Onsite CRC: 0 Client CRC: 0 Internal Defects: 0 External Defects: 1 Testing is pending by Onsite QA and we completed the stories (GGO-14503, GGO-14450) and deployed to TST 2 days prior Sprint end, that's the reason these stories got rolled over to next sprint.
A30: =IF(AND($D$1>=C30,$D$1<=D30),"CurrentSprint","NA") -> NA | B30: GGO 7.22.0 Sprint 3 | C30: 45695 | D30: 45708 | E30: 18 | F30: 8 | I30: 1.Adjust Admission Functionality and Infrastructure(Graph) update 2.Bid-19 and Bid-15 Report Updates | J30: Peer CRC:0 Onsite CRC: 0 Client CRC: 4 Internal Defects: 4 External Defects: 1 Reason for pending: GGO-14504 - The story was given Onisite QA for testing 3 days before the end of Sprint but Onsite QA logged bug on the last day of Thesprint. It was fixed and deployed before sprint prep, QA didn't get time to complete it. GGO-14070 - Development took a lot of time and got completed only on 1 day before Sprint end, the offshore QA logged a minor bug on the last day of sprint, fixed the bug and PR created for review. (Saranya worked on the RDLC report for the first time and there was a learning curve involved which took time)
A31: =IF(AND($D$1>=C31,$D$1<=D31),"CurrentSprint","NA") -> NA | B31: GGO 7.22.0 Sprint 4 | C31: 45709 | D31: 45722 | E31: 20 | F31: 15 | G31: 2/0 | I31: CRT Release & Regression testing for GGO 7.22.0 and PAPI 7.17.0 | J31: Peer CRC:0 Onsite CRC: 0 Client CRC: 0 Internal Defects: 4 External Defects: 0 Reason for pending: GGO-14510 - Bootstrap update - Development and Testing from Offshore got completed, the automation flow broken with this bootstrap update, so Nate created a automation change ticket under this story and this got carry forwarded to next sprint.
A32: NA | B32: GGO 7.23.0 Sprint 1 | C32: 45723 | D32: 45736 | E32: 19 | F32: 19 | G32: 7/0 | I32: Continued EMV Implementation and Infrastructure updates Allowed 19 digit card entry in GGAM, GGO and PAPI Cleared some Macroscope issues in PAPI Fixed cache issue in GGO Accomplishments: Addiitionally completed Developemnt for stretch goal stories | J32: Peer CRC:0 Onsite CRC: 0 Client CRC: 0 Internal Defects: 0 External Defects: 0 | K32: Internal Retro 1. Sathiya/ Rajesh and Saranya for providing help to Priya testing the stories 2. Team for completing all the story points
A33: NA | B33: GGO 7.23.0 Sprint 2 | C33: 45736 | D33: 45750 | E33: 13 | F33: 19 | G33: 10/0 | I33: Completed Duplicate even code story and Invoice import and Invoice Payment Pages story Fixed Quartz Job access issues and Email Queue Issues. Accomplishments: Completing the development and testing for lot of stretch goal stories on the current sprint | J33: Peer CRC:0 Onsite CRC: 0 Client CRC: 0 Internal Defects: 2 External Defects: 0 Pending Story: 2 Stories has been carried forward 1.GGO-14573 -Hard to reproduce in the lower environements. The offshore developers made several attempts to reproduce the issue, but because it’s related to performance, it took a considerable amount of time to replicate. That’s why it got carried over. 2.PAPI-839(Stretch Goal) -Dependency on Onsite QA to complete it(Offshore QA has already completed testing for this story) | K33: Retro: 1.Rajesh for supporting multiple escalation issues 2.Sathiya/ Rajesh and Saranya for covering such a wide spread of stories 3.Priya for completing the testing for the planned as well as lot of stretch jiras
A34: NA | B34: GGO 7.23.0 Sprint 3 | C34: 45751 | D34: 45764 | E34: 22 | F34: 24 | G34: 6/0 | I34: Completed Multiple RSVP Imports Accomplishments: Did some Redis changes which was very challenging and OP to GGO import timeouts(which is a esclation ticket) Completing the development for the stretch goal stories on the current sprint | J34: Peer CRC:0 Onsite CRC: 0 Client CRC: 0 Internal Defects: 1 External Defects: 0 Pending Story: 2 stories has been carried forward which includes 1 stretch PAPI-840(8spt)and GGO-14644[Stretch] -Development for this story was completed three days ahead of the sprint deadline. However, a last-minute AC request from the client required code modifications, which were implemented the timeline.The story was left in Peer Review upon completion, per the client's request to hold it and maintain this branch separately from the CERT branch.Offshore QA has completed verification in the lower environment. The story is now pending validation from Onsite QA. | K34: Rajesh and offshore for taking the redis changes which was very challenging
A35: NA | B35: GGO 7.23.0 Sprint 4 | C35: 45765 | D35: 45778 | E35: 23 | F35: 27 | G35: 5/0 | I35: Accomplishments: Completed CRT testing Completed all planned stories and more Okta 1 Proof of concept Completed more macroscopic stories | J35: Peer CRC:0 Onsite CRC: 0 Client CRC: 0 Internal Defects: 1 External Defects: 0 Pending Story: 2 stories has been carried forward GGO-13722 ->we documented the alternative encryption change, client wanted to add new feature flag based on that need to follow the old and new encryption flow GGO-13723 ->we documented the alternative encryption change, client wanted to add new feature flag based on that need to follow the old and new encryption flow | K35: To the whole team for helping remove all the blockers for testing Rajesh and offshore for helping with the fallback cases Rajesh for assisting with integrating the Okta proof-of-concept
A36: NA | B36: GGO 7.24.0 Sprint 1 | C36: 45779 | D36: 45792 | E36: 19 | F36: 16 | G36: 2/0 | I36: Accomplishments: Old Amex certification testing Nav Bar Updation Fixed Dashboard generation Issue and Enabled Online Bidding for the same Fixed Export Sales issue Completed more macroscopic stories | J36: Peer CRC:0 Onsite CRC: 0 Client CRC: 0 Internal Defects: 0 External Defects: 0 Pending Story: 2 stories has been carried forward GGO-14628->Hard to reproduce in the lower environements. The offshore developers and QA's made several attempts to reproduce the issue, However, on the last day of the sprint,we found one way to reproduce it. But team need to ensure this after providing the solutions and to check whether this the cause of this issue. Team is still working on it.That’s why it got carried over. GGO-14656->Reskin-V2 is a complete overhaul of the existing Master Page. The new layout seamlessly integrates Telerik controls, Bootstrap, and Kendo UI CSS, ensuring an optimized, modern, and adaptive user experience across all devices. As part of this redesign, we need to explore which Telerik control is best suited for the requested layout to achieve the desired functionality and responsiveness. Its taking more time to complete this story | K36: Rajesh and Sathiyabharathi for working on the Nav bar update. Rajesh for helping with the Escalation issue
A37: NA | B37: GGO 7.24.0 Sprint 2 | C37: 45793 | D37: 45806 | E37: 26 | F37: 23 | I37: Accomplishments: Completed Pendo Implementation Completed Nav Bar Implementation Fixed Amex card disable for select organizations Fixed Sale Grid Export issue | J37: Peer CRC:0 Onsite CRC: 0 Client CRC: 0 Internal Defects: 0 External Defects: 0 Pending Story: 1 story has been carried forward GGO-14628->Hard to reproduce in the lower environements. The offshore developers and QA's made several attempts to reproduce the issue. Team is still working on it.That’s why it was put on hold as it is of low priority | K37: Rajesh and Sathiyabharathi for the Nav bar update. Rajesh and offshore team on the quick implementation of pendo. Mike Horihan gave Kudos for the quick Pendo implementation
A38: NA | B38: GGO 7.24.0 Sprint 3 | C38: 45806 | D38: 45820 | E38: 14 | F38: 6 | G38: 5-removed | I38: Accomplishments: Completed Reskin User Profile Development | J38: Peer CRC:0 Onsite CRC: 0 Client CRC: 0 Internal Defects: 3 External Defects: 0 Pending Story: 2 stories has been carried forward GGO-14682 and GGO-14683 - Reskin-V2 is a complete overhaul of the existing Master Page. The new layout seamlessly integrates Telerik controls, Bootstrap, and Kendo UI CSS, ensuring an optimized, modern, and adaptive user experience across all devices. As part of this redesign, we need to explore which Telerik control is best suited for the requested layout to achieve the desired functionality and responsiveness. Its taking more time to complete this since UI design work is new to the development team and it is bit challenging too.Also for GGO-14682 ->Development took a lot of time and got completed only on 1 day before Sprint end, the offshore QA logged a bug on the last day of sprint | K38: 1.Sathiyabharathi and Saranya for implementing most the design changes and making sure the existing workflow is in in place +2 2.Priya for testing all the changes before sending to the PR to onsite and identifying the bugs early. 3.Rajesh for helping multiple offshore teams and get them all set up and going
A39: NA | B39: GGO 7.24.0 Sprint 4 | C39: 45820 | D39: 45834 | E39: 22 | F39: 22 | I39: Accomplishments: completed Reskin User Profile and Profject home. CRT Regression Completed for the release | J39: Peer CRC:0 Onsite CRC: 0 Client CRC: 0 Internal Defects: 0 External Defects: 0 Completed all the assigned stories | K39: Great job Team on completing all planned stories and more! It was well appreciated by everyone here at onsite. Sathiyabharathi and Saranya for focussing on project reskin Priya for completing CRT Regression and the sprint story testing Rajesh for managing all the different projects at the same time
A40: NA | B40: GGO 7.25.0 Sprint 1 | C40: 45834 | D40: 45848 | E40: 20 | F40: 10 | I40: Accomplishments:Project home page and great progress in Supporter reskin design | J40: Peer CRC:0 Onsite CRC: 0 Client CRC: 0 Internal Defects: 0 External Defects: 0 Pending :GGO-14687 and GGO-14802: 2 stories has been carried forward as we are currently working on the reskinning of the grid component. Once this is completed, the remaining stories for the upcoming sprints are expected to progress quickly. Informed to client as well | K40: GGO Dev offshore team for reskin progress Rajesh for figuring out the SalesForce production issue Priya for doing a thorough testing before sending to Dev and TST
...

Sheet Unplanned Leaves
B1: Resource Name
A2: Sprint Name | B2: Priyadharshini Ravichandran | C2: Saranya Namachivayam | D2: Jennifer | E2: Sathiyabharathi | F2: Rajesh | G2: Total Planned Leaves | H2: Remarks
A3: GGO 8.3.0 Sprint 1 (05-Feb-26 to 19-Feb-26) | B3: 1 | C3: 0 | D3: 0 | E3: 0 | F3: 0 | G3: =SUM(B3:F3) -> 1
A4: GGO 8.3.0 Sprint 2 (19-Feb-26 to 05-Mar-26) | B4: 0 | C4: 0 | D4: 0 | E4: 0 | F4: 0 | G4: =SUM(B4:F4) -> 0
A5: GGO 8.3.0 Sprint 3 (05-Mar-26 to 19-Mar-26) | B5: 0 | C5: 1 | D5: 0.5 | E5: 0 | F5: 0 | G5: =SUM(B5:F5) -> 1.5
A6: GGO 8.3.0 Sprint 4 (19-Mar-26 to 02-Apr-26) | B6: 1 | C6: 2 | D6: 0 | E6: 1 | F6: 1 | G6: =SUM(B6:F6) -> 5
A7: GGO 8.4.0 Sprint 1 (02-Apr-26 to 16-Apr-26) | B7: 1 | C7: 0 | D7: 1 | E7: 1 | F7: 0 | G7: =SUM(B7:F7) -> 3
A8: GGO 8.4.0 Sprint 2 (16-Apr-26 to 30-Apr-26) | B8: 0 | C8: 0 | D8: 0 | E8: 0 | F8: 0 | G8: 0
A9: GGO 8.4.0 Sprint 3 (30-Apr-26 to 14-May-26) | B9: 0 | C9: 0 | D9: 0.5 | E9: 1 | F9: 3 | G9: 4.5
E35: ]

Sheet GGO 8.4.0 Sprint 4-Status
A1: S.No | B1: Application Name | C1: Sprint Start Date | D1: Sprint End Date | E1: Sprint | F1: Developer | G1: Story ID/Defect ID | H1: Description | I1: Status | J1: Estimated(sp) | K1: Actual(sp) | L1: Actual Hours Worklog | M1: Dev Start Date | N1: Dev End Date | O1: Unit testing | P1: Peer Tested By | Q1: Peer Tested Defects, if any | R1: Peer Reviewed By | S1: Peer Code Review Comments, if any | T1: PR Number/Link | U1: PR Created Date | V1: PR Approved Date | W1: Reviewer 1 | X1: Code Review Comments, if any | Y1: Reviewer 2 | Z1: Approved Date | AA1: Code Review Comments, if any2 | AB1: Internal PO -POV Comments | AC1: Client PO -POV Comments | AD1: Comments
A2: 1 | B2: GGO Web | C2: 46156 | D2: 46170 | E2: GGO 8.4.0 Sprint 4 | F2: Saranya | G2: GGO-15245 | H2: Snyk Finding - Microsoft.AspNetCore.Server.Kestrel@2.2.0 update to 2.3.6 | I2: Being Developed | J2: 2 | M2: 46157
A3: 2 | B3: GGO Web | C3: 46156 | D3: 46170 | E3: GGO 8.4.0 Sprint 4 | G3: GGO-15170 | H3: Employee Controls for Reports | I3: Refinement | J3: 5
A4: 3 | B4: GGO Web | C4: 46156 | D4: 46170 | E4: GGO 8.4.0 Sprint 4 | F4: Saranya | G4: GGO-14513 | H4: Log Quartz Job errors in Elmah log | I4: Being Developed | J4: 2 | M4: 46157
A5: 4 | B5: GGO Web | C5: 46156 | D5: 46170 | E5: GGO 8.4.0 Sprint 4 | F5: Rajesh | G5: PAPI-291 | H5: PAPI is using an old version of LLBGEN i.e. 2.5. We need to upgrade to the latest LLBGen i.e. 5.8 | I5: Being Developed | J5: 3 | M5: 46157
A6: 5 | B6: GGO Web | C6: 46156 | D6: 46170 | E6: GGO 8.4.0 Sprint 4 | G6: GGO-15251 | H6: Project Builder - Feature Flag to turn off/on the changes | I6: Refinement | J6: 2
A7: 6 | B7: GGO Web | C7: 46156 | D7: 46170 | E7: GGO 8.4.0 Sprint 4 | F7: Sathiya | G7: GGO-15219 | H7: Project Builder - Create Project - Getting Started section | I7: Being Developed | J7: 5 | M7: 46157
A8: 7 | B8: GGO Web | C8: 46156 | D8: 46170 | E8: GGO 8.4.0 Sprint 4 | F8: Priya-QA | G8: GGO-15242 | H8: 19 May GGO 8.4.0 CRT Release & Regression testing | I8: Refinement | J8: 3
A9: 8 | B9: GGO Web | C9: 46156 | D9: 46170 | E9: GGO 8.4.0 Sprint 4 | F9: Priya-QA | G9: PAPI-898 | H9: 19 May PAPI 8.2.0 CRT Release & Regression testing | I9: Refinement | J9: 1

Sheet GGO 8.4.0 Sprint 4-Defect
A1: S.No | B1: Sprint # | C1: Story/Defect ID | D1: Parent Story | E1: Developer | F1: Issue Type | G1: Issue Description | H1: Priority | I1: Defect Source | J1: Type | K1: Status | L1: Root Cause Category | M1: Found By | N1: Comment | O1: RCA Comment
G2: NO Defects

Sheet GGO 8.4.0 Sprint 3-Status
A1: S.No | B1: Application Name | C1: Sprint Start Date | D1: Sprint End Date | E1: Sprint | F1: Developer | G1: Story ID/Defect ID | H1: Description | I1: Status | J1: Estimated(sp) | K1: Actual(sp) | L1: Actual Hours Worklog | M1: Dev Start Date | N1: Dev End Date | O1: Unit testing | P1: Peer Tested By | Q1: Peer Tested Defects, if any | R1: Peer Reviewed By | S1: Peer Code Review Comments, if any | T1: PR Number/Link | U1: PR Created Date | V1: PR Approved Date | W1: Reviewer 1 | X1: Code Review Comments, if any | Y1: Reviewer 2 | Z1: Approved Date | AA1: Code Review Comments, if any2 | AB1: Internal PO -POV Comments | AC1: Client PO -POV Comments | AD1: Comments
A2: 1 | B2: GGO Web | C2: 46142 | D2: 46156 | E2: GGO 8.4.0 Sprint 3 | F2: Saranya | G2: GGO-15229 | H2: Edit Payments - Create Refund page | I2: Completed | J2: 2 | K2: 2 | L2: 14 | M2: 46116 | N2: 46147 | O2: Done | P2: Priya | R2: Sathiya | T2: https://greatergiving.visualstudio.com/Greater%20Giving/_git/GGO/pullrequest/9520 | U2: 46141 | V2: 46147 | W2: Rajesh | Y2: Mike Horihan | Z2: 46148 | AD2: Created a enhanced refund page on 04/29/2026 Unit testing done and Created a PR on 04/30/2026. Testing Completed in the TST env
A3: 2 | B3: GGO Web | C3: 46142 | D3: 46156 | E3: GGO 8.4.0 Sprint 3 | F3: Rajesh | G3: GGO-15230 | H3: Validate Sales Force Invoice Posted Items API flow with real data | I3: Completed | J3: 2 | K3: 2 | L3: 12 | M3: 46143 | N3: 46155 | O3: Done | P3: Priya | R3: Saranya | T3: https://greatergiving.visualstudio.com/Greater%20Giving/_git/GGO/pullrequest/9562 | U3: 46155 | V3: NA | W3: NA | Y3: Mike Horihan | Z3: 46155 | AD3: Testing Completed in the TST env
A4: 3 | B4: GGO Web | C4: 46142 | D4: 46156 | E4: GGO 8.4.0 Sprint 3 | F4: Rajesh | G4: GGO-15216 | H4: Online Bidding setup opens Old UI instead of New Online Bidding UI | I4: Completed | J4: 1 | K4: 1 | L4: 11 | M4: 46143 | N4: 46143 | O4: Done | P4: Priya | R4: Saranya | T4: https://greatergiving.visualstudio.com/Greater%20Giving/_git/GGO/pullrequest/9532 | U4: 46147 | V4: NA | W4: NA | Y4: Mike Horihan | Z4: 46147 | AD4: Testing Completed in the TST env
A5: 4 | B5: GGO Web | C5: 46142 | D5: 46156 | E5: GGO 8.4.0 Sprint 3 | F5: Rajesh | G5: GGO-15218 | H5: New GGO Clients are not setup with bluetooth | I5: Completed | J5: 2 | K5: 2 | L5: 5 | M5: 46143 | N5: 46147 | O5: Done | P5: Priya | R5: Saranya | T5: https://greatergiving.visualstudio.com/Greater%20Giving/_git/GGO/pullrequest/9533 | U5: 46147 | V5: NA | W5: NA | Y5: Mike Horihan | Z5: 46147 | AD5: Testing Completed in the TST env
A6: 5 | B6: GGO Web | C6: 46142 | D6: 46156 | E6: GGO 8.4.0 Sprint 3 | F6: Sathiya | G6: GGO-14911 | H6: Sales & Payments - Manage Charge Batches | I6: Completed | J6: 5 | K6: 5 | L6: 44.5 | M6: 46146 | N6: 46148 | O6: Done | P6: Priya | R6: Rajesh | T6: https://dev.azure.com/greatergiving/Greater%20Giving/_git/GGO/pullrequest/9535 | U6: 46148 | V6: 46148 | W6: NA | Y6: Mike Horihan | Z6: 46148 | AD6: Copied all the necessary files from oldl ayout 05/04/2026 Created an enhanced charge batch page 05/05/2026 Unit testing done and Created a PR on 05/06/2026. Testing Completed in the TST env
A7: 6 | B7: GGO Web | C7: 46142 | D7: 46156 | E7: GGO 8.4.0 Sprint 3 | F7: Saranya | G7: GGO-14912 | H7: Sales & Payments - View Charge Batch Page | I7: Completed | J7: 5 | K7: 5 | L7: 54.5 | M7: 46146 | N7: 46150 | O7: Done | P7: Priya | R7: Sathiya | T7: https://greatergiving.visualstudio.com/Greater%20Giving/_git/GGO/pullrequest/9550 | U7: 46150 | V7: NA | W7: NA | Y7: Mike Horihan | Z7: 46153 | AD7: Copied all the necessary files from old ayout 05/04/2026 Created an enhanced charge batch page 05/05/2026 Created an enhanced declined page on 05/06/2026 Incorporated UI changes suggested by Jennifer on 05/07/2026 Unit testing done and Created a PR on 05/08/2026. Testing Completed in the TST env
A8: 7 | B8: GGO Web | C8: 46142 | D8: 46156 | E8: GGO 8.4.0 Sprint 3 | F8: Rajesh | G8: GGO-15150 | H8: BID-10 report not showing image | I8: Completed | J8: 2 | K8: 2 | L8: 5 | M8: 46146 | N8: 46148 | O8: Done | P8: Priya | R8: Sathiya | T8: https://greatergiving.visualstudio.com/Greater%20Giving/_git/GGO/pullrequest/9537 | U8: 46148 | V8: NA | W8: NA | Y8: Mike Horihan | Z8: 46148 | AD8: Testing Completed in the TST env
A9: 8 | B9: GGO Web | C9: 46142 | D9: 46156 | E9: GGO 8.4.0 Sprint 3 | F9: Saranya | G9: GGO-15157 | H9: Lack of ConvenienceFeeRate in sectionGridSettings causes error | I9: Completed | J9: 1 | K9: 1 | L9: 9 | M9: 46153 | N9: 46153 | O9: Done | P9: Priya | R9: Rajesh | T9: https://greatergiving.visualstudio.com/Greater%20Giving/_git/GGO/pullrequest/9556 | U9: 46153 | W9: Rajesh | Y9: Mike Horihan | AD9: Fixed ConvenienceFeeRate issue in SectionGrid Settings, Unit testing done and Created a PR on 05/11/2026. Testing Completed in the TST env
A10: 9 | B10: GGO Web | C10: 46142 | D10: 46156 | E10: GGO 8.4.0 Sprint 3 [STRETCH] | F10: Sathiya | G10: GGO-15247 | H10: Snyk Finding - System.Security.Cryptography.Xml@8.0.2 update to 8.0.3 | I10: Completed | J10: 1 | K10: 1 | L10: 28 | M10: 46154 | N10: 46154 | O10: Done | P10: Priya | R10: Rajesh | T10: https://dev.azure.com/greatergiving/Greater%20Giving/_git/GGO/pullrequest/9560 | U10: 46154 | V10: 46154 | W10: Rajesh | Y10: Mike Horihan | Z10: 46154 | AA10: Also seeing the reference in GreaterGiving.Online.Website.Reskin | AD10: Updated package version did dev testing PR created 05/12/2026 Addressed code review comments . Updated package across all the solution did dev testing PR updated 05/13/2026. Testing Completed in the TST env
A11: 10 | B11: GGO Web | C11: 46142 | D11: 46156 | E11: GGO 8.4.0 Sprint 3 [STRETCH] | F11: Saranya | G11: GGO-15245 | H11: Snyk Finding - Microsoft.AspNetCore.Server.Kestrel@2.2.0 update to 2.3.6 | I11: Being Developed | J11: 2 | K11: 0 | L11: 12 | M11: 46155

Sheet GGO 8.4.0 Sprint 3-Defect
A1: S.No | B1: Sprint # | C1: Story/Defect ID | D1: Parent Story | E1: Developer | F1: Issue Type | G1: Issue Description | H1: Priority | I1: Defect Source | J1: Type | K1: Status | L1: Root Cause Category | M1: Found By | N1: Comment | O1: RCA Comment
G2: NO Defects

Sheet GGO 8.4.0 Sprint 2-Status
A1: S.No | B1: Application Name | C1: Sprint Start Date | D1: Sprint End Date | E1: Sprint | F1: Developer | G1: Story ID/Defect ID | H1: Description | I1: Status | J1: Estimated(sp) | K1: Actual(sp) | L1: Actual Hours Worklog | M1: Dev Start Date | N1: Dev End Date | O1: Unit testing | P1: Peer Tested By | Q1: Peer Tested Defects, if any | R1: Peer Reviewed By | S1: Peer Code Review Comments, if any | T1: PR Number/Link | U1: PR Created Date | V1: PR Approved Date | W1: Reviewer 1 | X1: Code Review Comments, if any | Y1: Reviewer 2 | Z1: Approved Date | AA1: Code Review Comments, if any2 | AB1: Internal PO -POV Comments | AC1: Client PO -POV Comments | AD1: Comments
A2: 1 | B2: GGO Web | C2: 46128 | D2: 46142 | E2: GGO 8.4.0 Sprint 2 | F2: Saranya | G2: GGO-14792 | H2: View Payments Page | I2: Completed | J2: 1 | K2: 1 | L2: 13 | M2: NA | N2: NA | O2: Done | P2: Priya | R2: Sathiya | T2: https://greatergiving.visualstudio .com/Greater%20Giving/_git/GGO/ pullrequest/9464 | U2: 46125 | V2: 46129 | W2: Rajesh | Y2: Mike Horihan | Z2: 46130 | AA2: No concerns have been noted up to this point; it will be rolled over. | AD2: Payments Grid new reskin design implementation started on 04/10/2026 Developement and testing completed. Created a PR on 04/13/2026
A3: 2 | B3: GGO Web | C3: 46128 | D3: 46142 | E3: GGO 8.4.0 Sprint 2 | F3: Saranya | G3: GGO-14818 | H3: View Payments Common controls | I3: Completed | J3: 1 | K3: 1 | L3: 12 | M3: NA | N3: NA | O3: Done | P3: Priya | R3: Sathiya | T3: https://greatergiving.visualstudio .com/Greater%20Giving/_git/GGO/ pullrequest/9464 | U3: 46125 | V3: 46129 | W3: Rajesh | Y3: Mike Horihan | Z3: 46130 | AA3: No concerns have been noted up to this point; | AD3: Implemented Payments Grid common controls and testing completed. Created a PR on 04/13/2026
A4: 3 | B4: GGO Web | C4: 46128 | D4: 46142 | E4: GGO 8.4.0 Sprint 2 | F4: Saranya | G4: GGO-14820 | H4: View Payments Advanced search | I4: Completed | J4: 2 | K4: 2 | L4: 29 | M4: 46129 | N4: 46134 | O4: Done | P4: Priya | R4: Rajesh | T4: https://greatergiving.visualstudio.com/Greater%20Giving/_git/GGO/pullrequest/9485 | U4: 46129 | V4: 46134 | W4: Rajesh | Y4: Mike Horihan | Z4: 46134 | AA4: Is there a common JavaScript file with this function in it to include instead of the inline javascript? | AD4: Implemented Payment Advanced search filters and Unit Testing done on 04/17/2026 Moved Payment Reference # serach into Advanced Search Filter and tested on 04/21/2026 Incorporated code review comments given by MikeH and tested on 04/22/2026
A5: 4 | B5: GGO Web | C5: 46128 | D5: 46142 | E5: GGO 8.4.0 Sprint 2 | F5: Sathiya | G5: GGO-14791 | H5: Create/Edit Sales page | I5: Completed | J5: 5 | K5: 5 | L5: 52 | M5: 46129 | N5: 46135 | O5: Done | P5: Priya | R5: Rajesh | T5: https://greatergiving.visualstudio.com/Greater%20Giving/_git/GGO/pullrequest/9501 | U5: 46135 | V5: 46140 | W5: Rajesh | Y5: Mike Horihan | Z5: 46140 | AD5: Started implementing Create/Edit Sales Page on 04/17/2026 Started to implement details tab on 04/20/2026. Started to implement purchaser tab on 04/21/2026. Started to implement admission tab on 04/22/2026 Admisson tab grid design update on 04/23/2026 Details tab rsvp url design update on 04/24/2026 Completed Testing
A6: 5 | B6: GGO Web | C6: 46128 | D6: 46142 | E6: GGO 8.4.0 Sprint 2 | F6: Sathiya | G6: GGO-15209 | H6: View Sales page for Non-Admin users | I6: Completed | J6: 3 | K6: 3 | L6: 21 | M6: 46139 | N6: 46140 | O6: Done | P6: Priya | R6: Saranya | T6: https://greatergiving.visualstudio.com/Greater%20Giving/_git/GGO/pullrequest/9516 | U6: 46140 | V6: 46141 | W6: Rajesh | Y6: Mike Horihan | Z6: 46141 | AD6: Design update for non-admin users on 04/28/2026 Jennifer gave some inputs changing the control design applied the design on 04/28/2026
A7: 6 | B7: GGO Web | C7: 46128 | D7: 46142 | E7: GGO 8.4.0 Sprint 2 | F7: Saranya | G7: GGO-14793 | H7: Create/Edit Payment page | I7: Completed | J7: 5 | K7: 5 | L7: 33 | M7: 46132 | N7: 46139 | O7: Done | P7: Priya | R7: Rajesh | T7: https://greatergiving.visualstudio.com/Greater%20Giving/_git/GGO/pullrequest/9512 | U7: 46139 | V7: 46140 | W7: Rajesh | Y7: Mike Horihan | Z7: 46141 | AD7: Started implementing Create/Edit Payment Page on 04/20/2026. Worked on Grid changes on 04/23/2026 Worked on alignment issues and new Datepicker on 04/24/2026 Implemented indeterminate checkbox on 04/27/2026 Verified in the Dev env. 4/28/2026 3:54 PM
A8: 7 | B8: GGO Web | C8: 46128 | D8: 46142 | E8: GGO 8.4.0 Sprint 2 | F8: Saranya | G8: GGO-15210 | H8: View Payments page for Non-Admin users | I8: Completed | J8: 3 | K8: 3 | L8: 12 | M8: 46139 | N8: 46140 | O8: Done | P8: Priya | R8: Sathiya | T8: https://greatergiving.visualstudio.com/Greater%20Giving/_git/GGO/pullrequest/9512 | U8: 46139 | V8: 46140 | W8: Rajesh | Y8: Mike Horihan | Z8: 46141 | AD8: Started implementing view payments for non-admin user on 04/27/2026 Unit testing done and created a PR on 04/28/2026
A9: 8 | B9: GGO Web | C9: 46128 | D9: 46142 | E9: GGO 8.4.0 Sprint 2 | F9: Rajesh | G9: GGO-15215 | H9: Update Username for receipt generation when receiving the request from NextGen | I9: Completed | J9: 1 | K9: 1 | L9: 10 | M9: 46132 | N9: 46135 | O9: Done | P9: Priya | R9: Saranya | T9: https://greatergiving.visualstudio.com/Greater%20Giving/_git/GGO/pullrequest/9503 | U9: 46135 | V9: NA | W9: NA | Y9: Patterson, Scott | Z9: 46136 | AD9: Implemented passing username as a parameter in cookie header from nextgen API instead of using AesopSession username on 04/20/2026 Fixed invoice generation error on 04/21/2026 Unit testing done and Created a PR on 04/23/06
A10: 9 | B10: GGO Web | C10: 46128 | D10: 46142 | E10: GGO 8.4.0 Sprint 2 [STRETCH] | F10: Saranya | G10: GGO-15229 | H10: Edit Payments - Create Refund page | I10: Being Developed | J10: 3 | K10: 1 | L10: 12 | M10: 46141 | N10: 46142 | T10: https://greatergiving.visualstudio.com/Greater%20Giving/_git/GGO/pullrequest/9520 | U10: 46141 | W10: Rajesh | Y10: Mike Horihan | AD10: Created a enhanced refund page on 04/29/2026 Unit testing done and Created a PR on 04/30/2026

Sheet GGO 8.4.0 Sprint 2-Defect
A1: S.No | B1: Sprint # | C1: Story/Defect ID | D1: Parent Story | E1: Developer | F1: Issue Type | G1: Issue Description | H1: Priority | I1: Defect Source | J1: Type | K1: Status | L1: Root Cause Category | M1: Found By | N1: Comment | O1: RCA Comment
G2: NO Defects

Sheet GGO 8.4.0 Sprint 1-Status
A1: S.No | B1: Application Name | C1: Sprint Start Date | D1: Sprint End Date | E1: Sprint | F1: Developer | G1: Story ID/Defect ID | H1: Description | I1: Status | J1: Estimated(sp) | K1: Actual(sp) | L1: Actual Hours Worklog | M1: Dev Start Date | N1: Dev End Date | O1: Unit testing | P1: Peer Tested By | Q1: Peer Tested Defects, if any | R1: Peer Reviewed By | S1: Peer Code Review Comments, if any | T1: PR Number/Link | U1: PR Created Date | V1: PR Approved Date | W1: Reviewer 1 | X1: Code Review Comments, if any | Y1: Reviewer 2 | Z1: Approved Date | AA1: Code Review Comments, if any2 | AB1: Internal PO -POV Comments | AC1: Client PO -POV Comments | AD1: Comments
A2: 1 | B2: GGO Web | C2: 46114 | D2: 46128 | E2: GGO 8.4.0 Sprint 1 | F2: Rajesh | G2: GGO-12244 | H2: LLBGen Upgrade to the latest version | I2: Completed | J2: 2 | K2: 2 | L2: 18 | M2: 46101 | N2: 46113 | O2: Done | P2: Priya | R2: Saranya | T2: https://greatergiving.visualstudio.com/Greater%20Giving/_git/GGO/pullrequest/9424 | U2: 46113 | V2: 46113 | W2: Rajesh | Y2: Mike Horihan | Z2: 46114 | AD2: Got LLBLGen 5.10.1 setup file and started to work on it on 03/30/2026 Completed development, PR created and sent it to Approval on 04/01/2026 Testing completed in the TST env.
A3: 2 | B3: GGO Web | C3: 46114 | D3: 46128 | E3: GGO 8.4.0 Sprint 1 | F3: Saranya | G3: GGO-15169 | H3: API update to provide card expiration date to next gen | I3: Completed | J3: 1 | K3: 1 | L3: 6 | M3: 46113 | N3: 46113 | O3: Done | P3: Priya | R3: Rajesh | T3: https://greatergiving.visualstudio.com/Greater%20Giving/_git/GGO/pullrequest/9426 | U3: 46114 | V3: 46116 | W3: Rajesh | Y3: Mike Horihan | Z3: 46118 | AD3: Development is completed in previous sprint itself. Testing completed in the TST env.
A4: 3 | B4: GGO Web | C4: 46114 | D4: 46128 | E4: GGO 8.4.0 Sprint 1 | F4: Rajesh | G4: GGO-15174 | H4: Remove Deleted Package from ap_OnlineBiddingSettings featuredPackageIDs Column | I4: Completed | J4: 2 | K4: 2 | L4: 4 | M4: 46115 | N4: 46115 | O4: Done | P4: Priya | R4: Rajesh | T4: https://greatergiving.visualstudio.com/Greater%20Giving/_git/GGO/pullrequest/9431 | U4: 46115 | V4: NA | W4: Na | Y4: Mike Horihan | Z4: 46115 | AD4: Development is completed. Unit testing is done and Created a PR on 04/03/2026. Testing completed in the TST env.
A5: 4 | B5: GGO Web | C5: 46114 | D5: 46128 | E5: GGO 8.4.0 Sprint 1 | F5: Saranya | G5: GGO-15186 | H5: Snyk Findings - form-data@4.0.0 | I5: Completed | J5: 2 | K5: 2 | L5: 12 | M5: 46115 | N5: 46118 | O5: Done | P5: Priya | R5: Rajesh | T5: https://greatergiving.visualstudio.com/Greater%20Giving/_git/GGO/pullrequest/9440 | U5: 46118 | W5: Rajesh | Y5: Mike Horihan | Z5: 46119 | AD5: Started upgrading form-data package from 4.0.0 to 4.0.4 for angular project and facing some issues on 04/03/2026 Fixed issue. Testing is done and Created PR on 04/06/2026. Testing completed in the TST env.
A6: 5 | B6: GGO Web | C6: 46114 | D6: 46128 | E6: GGO 8.4.0 Sprint 1 | F6: Saranya | G6: GGO-15187 | H6: Snyk Finding - ajv@8.12.0 | I6: Completed | J6: 2 | K6: 2 | L6: 7 | M6: 46115 | N6: 46115 | O6: Done | P6: Priya | R6: Rajesh | T6: https://greatergiving.visualstudio.com/Greater%20Giving/_git/GGO/pullrequest/9436 | U6: 46115 | V6: NA | W6: NA | Y6: Mike Horihan | Z6: 46118 | AD6: Upgraded ajv package from 8.8.0 to 8.18.0 for angular project. Testing is done and Created PR on 04/03/2026. Testing completed in the TST env.
A7: 6 | B7: GGO Web | C7: 46114 | D7: 46128 | E7: GGO 8.4.0 Sprint 1 | F7: Sathiya | G7: GGO-14790 | H7: View Sales page | I7: Completed | J7: 3 | K7: 3 | L7: 38.5 | M7: 46115 | N7: 46118 | O7: Done | P7: Priya | R7: Saranya | T7: https://dev.azure.com/greatergiving/Greater%20Giving/_git/GGO/pullrequest/9433 | U7: 46118 | V7: 46122 | W7: Rajesh | Y7: Mike Horihan | Z7: 46122 | AA7: There was an issue with the text alignment that has been addressed and completed. | AD7: Need to verify in local and dev since implementation is completed on 04/03/2026 Verified in DEV environment. Published the PR on 04/06/2026. Testing completed in the TST env.
A8: 7 | B8: GGO Web | C8: 46114 | D8: 46128 | E8: GGO 8.4.0 Sprint 1 | F8: Sathiya | G8: GGO-14819 | H8: View Sales Advanced search | I8: Completed | J8: 5 | K8: 5 | L8: 29 | M8: 46118 | N8: 46120 | O8: Done | P8: Priya | R8: Saranya | T8: https://greatergiving.visualstudio.com/Greater%20Giving/_git/GGO/pullrequest/9450 | U8: 46120 | V8: 46126 | W8: Rajesh | Y8: Mike Horihan | Z8: 46126 | AA8: Detected a few problems and rectified some; the remaining issues will be addressed in the forthcoming story. | AD8: Started View sales advanced search on 04/06/2026 Fixed issues in Frozen column on 04/09/2026 PackageNumber and BidderNumber search make confusion on grid result Asked PO for the clarification on 04/10/2026 Moved package search to advanced search section on 04/14/2026 Testing completed in the TST env.
A9: 8 | B9: GGO Web | C9: 46114 | D9: 46128 | E9: GGO 8.4.0 Sprint 1 | F9: Sathiya | G9: GGO-14817 | H9: View Sales common controls | I9: Completed | J9: 3 | K9: 3 | L9: 28 | M9: 46115 | N9: 46118 | O9: Done | P9: Priya | R9: Saranya | T9: https://dev.azure.com/greatergiving/Greater%20Giving/_git/GGO/pullrequest/9433 | U9: 46118 | V9: 46122 | W9: Rajesh | Y9: Mike Horihan | Z9: 46122 | AA9: Implemented successfully | AD9: Need to verify in local and dev since implementation is completed on 04/03/2026 Verified in DEV environment. Published the PR on 04/06/2026. Testing completed in the TST env.
A10: 9 | B10: GGO Web | C10: 46114 | D10: 46128 | E10: GGO 8.4.0 Sprint 1 [STRETCH] | F10: Sathiya | G10: GGO-15201 | H10: Investigate Snyk Finding - @angular/compiler-cli@16.2.8 | I10: Completed | J10: 2 | K10: 2 | L10: 7.5 | M10: 46125 | N10: NA | O10: NA | P10: NA | Q10: NA | R10: NA | S10: NA | T10: NA | U10: NA | V10: NA | W10: NA | X10: NA | Y10: NA | Z10: NA | AA10: NA | AB10: NA | AC10: NA | AD10: Snyk fix require to update angular version from 8 to 19+ and Updated comments in Jira on 04/14/2026
A11: 10 | B11: GGO Web | C11: 46114 | D11: 46128 | E11: GGO 8.4.0 Sprint 1 [STRETCH] | F11: Saranya | G11: GGO-15145 | H11: Error on Merge with proccessedInvoice | I11: Completed | J11: 2 | K11: 2 | L11: 14 | M11: 46120 | N11: 46122 | O11: Done | P11: Priya | R11: Rajesh | T11: https://greatergiving.visualstudio.com /Greater%20Giving/_git/GGO/ pullrequest/9455 | U11: 46121 | V11: 46123 | W11: Rajesh | Y11: Mike Horihan | Z11: 46123 | AD11: Started analyzing the issue and tried to reprduce the issue in TST ENV on 04/09/2026 Fixed the issue wih replacing target SupporterId with Source SupporterId while megring two supporters on 04/10/2026 Unit Testing is done on 04/11/2026
A12: 11 | B12: GGO Web | C12: 46114 | D12: 46128 | E12: GGO 8.4.0 Sprint 1 [STRETCH] | F12: Saranya | G12: GGO-14792 | H12: View Payments Page | I12: Being Developed | J12: 3 | K12: 2 | L12: 26 | M12: 46122 | N12: 46125 | O12: Done | P12: Priya | R12: Sathiya | T12: https://greatergiving.visualstudio .com/Greater%20Giving/_git/GGO/ pullrequest/9464 | U12: 46125 | W12: Rajesh | Y12: Mike Horihan | AA12: No concerns have been noted up to this point; it will be rolled over. | AD12: Payments Grid new reskin design implementation started on 04/10/2026 Developement and testing completed. Created a PR on 04/13/2026
A13: 12 | B13: GGO Web | C13: 46114 | D13: 46128 | E13: GGO 8.4.0 Sprint 1 [STRETCH] | F13: Saranya | G13: GGO-14818 | H13: View Payments Common controls | I13: Being Developed | J13: 1 | K13: 0 | L13: 15 | M13: 46125 | N13: 46125 | O13: Done | P13: Priya | R13: Sathiya | T13: https://greatergiving.visualstudio .com/Greater%20Giving/_git/GGO/ pullrequest/9464 | U13: 46125 | W13: Rajesh | Y13: Mike Horihan | AA13: No concerns have been noted up to this point; | AD13: Implemented Payments Grid common controls and testing completed. Created a PR on 04/13/2026
A14: 13 | B14: GGO Web | C14: 46114 | D14: 46128 | E14: GGO 8.4.0 Sprint 1 [STRETCH] | F14: Rajesh | G14: GGO-15204 | H14: Fundraising Signup Issue - Could not load file or assembly 'System.ValueTuple, Version=4.0.0.0, Culture=neutral, PublicKeyToken=cc7b13ffcd2ddd51' or one of its dependencies. The system cannot find the file specified. | I14: Completed | J14: 1 | K14: 1 | L14: 7 | M14: 46127 | N14: 46127 | O14: Done | P14: Priya | R14: Saranya | T14: https://greatergiving.visualstudio.com/Greater%20Giving/_git/GGO/pullrequest/9471 | U14: 46127 | V14: NA | W14: Rajesh | Y14: Mike Horihan | Z14: 46127
A15: 14 | B15: GGO Web | C15: 46114 | D15: 46128 | E15: GGO 8.4.0 Sprint 1 [STRETCH] | F15: Rajesh | G15: GGO-15206 | H15: Add Index to OnlineBidderKey for ap_OnlineBidder table | I15: Completed | J15: 1 | K15: 1 | L15: 1 | M15: 46127 | N15: 46127 | O15: Done | P15: Priya | R15: Sathiya | T15: https://greatergiving.visualstudio.com/Greater%20Giving/_git/GGO/pullrequest/9478 | U15: 46128 | V15: NA | W15: NA | Y15: Mike Horihan | Z15: 46128 | AD15: Migration script added for creating index for ap_OnlineBidder table for this issue and Unit testing done on 04/15/2026

Sheet GGO 8.4.0 Sprint 1-Defect
A1: S.No | B1: Sprint # | C1: Story/Defect ID | D1: Parent Story | E1: Developer | F1: Issue Type | G1: Issue Description | H1: Priority | I1: Defect Source | J1: Type | K1: Status | L1: Root Cause Category | M1: Found By | N1: Comment | O1: RCA Comment
G2: NO Defects

Sheet GGO 8.3.0 Sprint 4-Status
A1: S.No | B1: Application Name | C1: Sprint Start Date | D1: Sprint End Date | E1: Sprint | F1: Developer | G1: Story ID/Defect ID | H1: Description | I1: Status | J1: Estimated(sp) | K1: Actual(sp) | L1: Actual Hours Worklog | M1: Dev Start Date | N1: Dev End Date | O1: Unit testing | P1: Peer Tested By | Q1: Peer Tested Defects, if any | R1: Peer Reviewed By | S1: Peer Code Review Comments, if any | T1: PR Number/Link | U1: PR Created Date | V1: PR Approved Date | W1: Reviewer 1 | X1: Code Review Comments, if any | Y1: Reviewer 2 | Z1: Approved Date | AA1: Code Review Comments, if any2 | AB1: Internal PO -POV Comments | AC1: Client PO -POV Comments | AD1: Tester Comments | AE1: Developer Comments
A2: 1 | B2: GGO Web | C2: 46100 | D2: 46114 | E2: GGO 8.3.0 Sprint 4 | F2: Saranya | G2: GGO-15048 | H2: API Update for Next Gen - Invoicing Email | I2: Completed | J2: 1 | K2: 1 | L2: 22.5 | M2: NA | N2: NA | O2: Done | P2: Priya | R2: Sathiya | T2: https://greatergiving.visualstudio.com/Greater%20Giving/_git/GGO/pullrequest/9387 | U2: 46099 | V2: 46101 | W2: Rajesh | Y2: Mike Horihan | Z2: 46102 | AD2: Testing completed in the TST env
A3: 2 | B3: GGO Web | C3: 46100 | D3: 46114 | E3: GGO 8.3.0 Sprint 4 | F3: Sathiya | G3: GGO-15185 | H3: OB Edit Image Upload issue | I3: Completed | J3: 1 | K3: 1 | L3: 8 | M3: NA | N3: NA | O3: Done | P3: Priya | R3: Rajesh | S3: NA | T3: https://dev.azure.com/greatergiving/Greater%20Giving/_git/GGO/pullrequest/9393 | U3: 46101 | V3: 46101 | W3: Rajesh | X3: NA | Y3: NA | Z3: NA | AA3: NA | AB3: NA | AC3: NA+ | AD3: Testing completed in the TST env | AE3: Fixed the issue and created the PR on 03/20/26
A4: 3 | B4: GGO Web | C4: 46100 | D4: 46114 | E4: GGO 8.3.0 Sprint 4 | F4: Rajesh | G4: GGO-12244 | H4: LLBGen Upgrade to the latest version | I4: Ready for Testing | J4: 5 | K4: 3 | L4: 28 | M4: 46101 | N4: 46113 | T4: https://greatergiving.visualstudio.com/Greater%20Giving/_git/GGO/pullrequest/9424 | U4: 46113 | V4: 46113 | W4: Rajesh | Y4: Mike Horihan | Z4: 46114 | AE4: Got LLBLGen 5.10.1 setup file and started to work on it on 03/30/26 Completed development, PR created and sent it to Approval on 04/01/2026
A5: 4 | B5: GGO Web | C5: 46100 | D5: 46114 | E5: GGO 8.3.0 Sprint 4 | F5: Sathiya | G5: GGO-15167 | H5: OB Settings - Donation Bar | I5: Completed | J5: 3 | K5: 3 | L5: 25.5 | M5: 46104 | N5: 46106 | O5: Done | P5: Priya | R5: Rajesh | T5: https://dev.azure.com/greatergiving/Greater%20Giving/_git/GGO/pullrequest/9402 | U5: 46105 | V5: 46106 | W5: Rajesh | Y5: Mike Horihan | Z5: 46107 | AE5: Verified in dev flag value pushed to the OB queue correctly and created PR on 03/25/26
A6: 5 | B6: GGO Web | C6: 46100 | D6: 46114 | E6: GGO 8.3.0 Sprint 4 | F6: Saranya | G6: GGO-12200 | H6: Consolidate Nuget Packages | I6: Completed | J6: 3 | K6: 3 | L6: 52.5 | M6: 46101 | N6: 46111 | O6: Done | P6: Priya | T6: https://greatergiving.visualstudio.com/Greater%20Giving/_git/GGO/pullrequest/9413 | U6: 46111 | V6: 46112 | W6: Rajesh | Y6: Mike Horihan | Z6: 46112
A7: 6 | B7: GGO Web | C7: 46100 | D7: 46114 | E7: GGO 8.3.0 Sprint 4 | F7: Rajesh | G7: GGO-13962 | H7: Update NuGet Authenticate in Azure Pipeline | I7: Completed | J7: 2 | K7: 2 | L7: 6 | M7: 46101 | N7: 46105 | O7: Done | P7: Priya | R7: Rajesh | T7: https://greatergiving.visualstudio.com/Greater%20Giving/_git/GGO/pullrequest/9400 | U7: 46105 | V7: NA | W7: NA | Y7: Mike Horihan | Z7: 46106 | AE7: Started development on 03/20/26 Completed development and created PR on 03/24/26
A8: 7 | B8: GGO Web | C8: 46100 | D8: 46114 | E8: GGO 8.3.0 Sprint 4 | F8: Sathiya | G8: GGO-12282 | H8: Replace DLL direct references with NuGet packages | I8: Completed | J8: 2 | K8: 2 | L8: 15.5 | M8: 46106 | N8: 46106 | O8: Done | P8: Priya | R8: Rajesh | T8: https://greatergiving.visualstudio.com/Greater%20Giving/_git/GGO/pullrequest/9412 | U8: 46111 | V8: 46111 | W8: Rajesh | Y8: Mike Horihan | Z8: 46112 | AE8: [26-Mar-26] Except Nevron.dll we can't remove other dll's for above reason. all are third party dll's can't find in NuGet
A9: 8 | B9: GGO Web | C9: 46100 | D9: 46114 | E9: GGO 8.3.0 Sprint 4 | F9: Priya-QAa | G9: GGO-15182 | H9: 24 Mar GGO 8.3.0 CRT Release & Regression testing | I9: Completed | J9: 3 | K9: 3 | L9: 36 | M9: NA | N9: NA | O9: NA | P9: NA | Q9: NA | R9: NA | S9: NA | T9: NA | U9: NA | V9: NA | W9: NA | X9: NA | Y9: NA | Z9: NA | AA9: NA | AB9: NA | AD9: Testing completed in the CRT env
A10: 9 | B10: GGO Web | C10: 46100 | D10: 46114 | E10: GGO 8.3.0 Sprint 4 [STRETCH] | F10: Saranya | G10: GGO-15173 | H10: API Update for Card Entry Permissions in Go Time | I10: Completed | J10: 2 | K10: 2 | L10: 8 | M10: 46112 | N10: 46112 | O10: Done | P10: Priya | R10: Rajesh | T10: https://greatergiving.visualstudio.com/Greater%20Giving/_git/GGO/pullrequest/9422 | U10: 46112 | V10: 46112 | W10: Rajesh | Y10: Mike Horihan | Z10: 46113 | AE10: Analyzing existing GetCards API and added additional property(EditCreditCards) for NextGen and Testing completed in Local and Dev Env on 03/31/2026
A11: 10 | B11: GGO Web | C11: 46100 | D11: 46114 | E11: GGO 8.3.0 Sprint 4 [STRETCH] | F11: Saranya | G11: GGO-15169 | H11: API update to provide card expiration date to next gen | I11: Being Developed | J11: 2 | K11: 1 | L11: 8 | M11: 46113 | N11: 46113 | T11: https://greatergiving.visualstudio.com/Greater%20Giving/_git/GGO/pullrequest/9426 | U11: 46114 | W11: Rajesh | Y11: Mike Horihan | AE11: Analyzing existing GetCards API and added additional property(CardExpirationDate) for NextGen and Testing completed in Local and Dev Env on 04/01/2026

Sheet GGO 8.3.0 Sprint 4-Defect
A1: S.No | B1: Sprint # | C1: Story/Defect ID | D1: Parent Story | E1: Developer | F1: Issue Type | G1: Issue Description | H1: Priority | I1: Defect Source | J1: Type | K1: Status | L1: Root Cause Category | M1: Found By | N1: Comment | O1: RCA Comment
G2: NO Defects

Sheet GGO 8.3.0 Sprint 3-Status
A1: S.No | B1: Application Name | C1: Sprint Start Date | D1: Sprint End Date | E1: Sprint | F1: Developer | G1: Story ID/Defect ID | H1: Description | I1: Status | J1: Estimated(sp) | K1: Actual(sp) | L1: Actual Hours Worklog | M1: Dev Start Date | N1: Dev End Date | O1: Unit testing | P1: Peer Tested By | Q1: Peer Tested Defects, if any | R1: Peer Reviewed By | S1: Peer Code Review Comments, if any | T1: PR Number/Link | U1: PR Created Date | V1: PR Approved Date | W1: Reviewer 1 | X1: Code Review Comments, if any | Y1: Reviewer 2 | Z1: Approved Date | AA1: Code Review Comments, if any2 | AB1: Internal PO -POV Comments | AC1: Client PO -POV Comments | AD1: Tester Comments | AE1: Developer Comments
A2: 1 | B2: GGO Web | C2: 46086 | D2: 46100 | E2: GGO 8.3.0 Sprint 3 | F2: Rajesh | G2: GGO-15147 | H2: RSVP - Special Characters During Import for Apostrophe and Ampersand | I2: Completed | J2: 1 | K2: 1 | L2: 11 | M2: 46090 | N2: 46091 | O2: Done | P2: Priya | R2: Saranya | T2: https://greatergiving.visualstudio.com/Greater%20Giving/_git/GGO/pullrequest/9360 | U2: 46092 | V2: NA | W2: NA | Y2: Mike Horihan | Z2: 46092 | AE2: Fixed RSVP Special charcters issue during import on 03/09/2026 Tested and Created a PR on 03/10/2026
A3: 2 | B3: GGO Web | C3: 46086 | D3: 46100 | E3: GGO 8.3.0 Sprint 3 | F3: Rajesh | G3: GGO-15165 | H3: Unicode Characters in Item Descriptions | I3: Completed | J3: 2 | K3: 2 | L3: 6 | M3: 46087 | N3: 46087 | O3: Done | P3: Priya | R3: Saranya | T3: https://greatergiving.visualstudio.com/Greater%20Giving/_git/GGO/pullrequest/9348 | U3: 46087 | V3: NA | W3: NA | Y3: Mike Horihan | Z3: 46088 | AE3: Reproduced issue in TST environment, development completed by handling the Unicode char for the item and package description. 100% development completed and shared PR to client on 03/06/2026
A4: 3 | B4: GGO Web | C4: 46086 | D4: 46100 | E4: GGO 8.3.0 Sprint 3 | F4: Rajesh | G4: GGO-15047 | H4: API Update for Next Gen - Invoicing Available | I4: Completed | J4: 2 | K4: 2 | L4: 11 | M4: 46087 | N4: 46087 | O4: Done | P4: Priya | R4: Saranya | T4: https://greatergiving.visualstudio.com/Greater%20Giving/_git/GGO/pullrequest/9351 | U4: 46090 | V4: NA | W4: NA | Y4: Mike Horihan | Z4: 46090 | AE4: Created new GoTime API to check the invoicing status and return response to Mobile Team. 100% development completed and shared PR to client on 03/06/2026
A5: 4 | B5: GGO Web | C5: 46086 | D5: 46100 | E5: GGO 8.3.0 Sprint 3 | F5: Sathiya | G5: GGO-14809 | H5: Manage Project - RSVP Dashboard - Admission, Admission by Package and Meal Types grids | I5: Completed | J5: 3 | K5: 3 | L5: 25 | M5: 46087 | N5: 46091 | O5: Done | P5: Priya | R5: Rajesh | T5: https://greatergiving.visualstudio.com/Greater%20Giving/_git/GGO/pullrequest/9359 | U5: 46091 | V5: 46092 | W5: Rajesh | Y5: Mike Horihan | Z5: 46092 | AE5: Development started on 03/10/2026 Did local and dev testing and created PR on 03/10/2026
A6: 5 | B6: GGO Web | C6: 46086 | D6: 46100 | E6: GGO 8.3.0 Sprint 3 | F6: Sathiya | G6: GGO-14812 | H6: Manage Project - RSVP Dashboard | I6: Completed | J6: 5 | K6: 5 | L6: 47.25 | M6: 46091 | N6: 46097 | O6: Done | P6: Priya | R6: Saranya/Rajesh | T6: https://greatergiving.visualstudio.com/Greater%20Giving/_git/GGO/pullrequest/9380 | U6: 46097 | V6: 46098 | W6: Rajesh | Y6: Mike Horihan | Z6: 46098 | AE6: Implemented rsvp grid on 03/13/2026 Develoment completed fixing minor UI issues on 03/16/2026
A7: 6 | B7: GGO Web | C7: 46086 | D7: 46100 | E7: GGO 8.3.0 Sprint 3 | F7: Rajesh | G7: GGO-15162 | H7: Scroll bar issue in PRD - View Packages | I7: Completed | J7: 2 | K7: 2 | L7: 6 | M7: 46093 | N7: 46094 | O7: Done | P7: Priya | R7: Sathiya | T7: https://greatergiving.visualstudio.com/Greater%20Giving/_git/GGO/pullrequest/9371 | U7: 46094 | V7: NA | W7: Rajesh | Y7: Mike Horihan | Z7: 46094 | AE7: Reproduced issue in TST environment with help of customer service team took some time to fix this issue. 100 % development completed and shared PR to client on 03/13/2026
A8: 7 | B8: GGO Web | C8: 46086 | D8: 46100 | E8: GGO 8.3.0 Sprint 3 | F8: Saranya | G8: GGO-15038 | H8: Data not importing in from OP RSVP | I8: Completed | J8: 2 | K8: 2 | L8: 23 | M8: 46087 | N8: 46093 | O8: Done | P8: Priya | R8: Rajesh | T8: https://greatergiving.visualstudio.com/Greater%20Giving/_git/GGO/pullrequest/9368 | U8: 46093 | V8: 46093 | W8: Rajesh | Y8: Mike Horihan | Z8: 46094 | AE8: Trying to reproduce this issue. But unable to reproduce in Local, Dev, TST and CRT on 03/06//2026
A9: 8 | B9: GGO Web | C9: 46086 | D9: 46100 | E9: GGO 8.3.0 Sprint 3 | F9: Saranya | G9: GGO-15160 | H9: Streamline Support Redirect from Equipment Express | I9: Completed | J9: 3 | K9: 3 | L9: 23 | M9: 46091 | N9: 46093 | O9: Done | P9: Priya | R9: Rajesh | T9: https://greatergiving.visualstudio.com/Greater%20Giving/_git/GGO/pullrequest/9358 | U9: 46091 | V9: 46093 | W9: Rajesh | Y9: Mike Horihan | Z9: 46093 | AE9: Development 90% Completed. Created Banner and Popup to redirect Streamline support from Equipment Express. Testing is inprogress on 03/10/2026
