Workbook

Sheet Dashboard
A1: Current Sprint | B1: {=INDEX($B$2:$B$100,MATCH(1,(($D$2:$D$100 >=TODAY())*($C$2:$C$100<=TODAY())),0))} -> OB-OP 8.6.0 Sprint 4 | C1: Current Sprint Sheet | D1: =CONCATENATE(B1,"-Status") -> OB-OP 8.6.0 Sprint 4-Status | E1: Sprint Start Date | F1: =VLOOKUP($B$1,$B$1:$C$100,2) -> 46149 | G1: Sprint End Date | H1: =VLOOKUP($B$1,$B$1:$D$100,3) -> 46163 | I1: Application Name | J1: Donor Wave | K1: Users | L1: kannan.muthiah@relevantz.com;Ubaithullah.shahjahan@relevantz.com;irsath.kisar@relevantz.com;arivalagan.ramasamy@relevantz.com;saranya.palani@relevantz.com;murugesan.manthiramoorthy@relevantz.com | M1: Teams Name(GP-GGO.Donor Wave) | N1: 19:1e26e53c861e4b028fd5faa4b55c0a68@thread.v2
A2: Sprint Type | B2: Sprint # | C2: Sprint Start Date | D2: Sprint End Date | E2: Assigned | F2: Completed | G2: Story points introduced/removed | H2: Sprint Summary | I2: Accomplishments | J2: Remarks | K2: Retro Points (Internal & External) | L2: Data sanity Audit Status | M2: AuditDate | N2: Planned Leaves | O2: Availed Leaves | P2: Backlog Health
A3: =IF(AND($D$1>=C3,$D$1<=D3),"CurrentSprint","NA") -> NA | B3: OBOP 7.10.0 Sprint 4 | C3: 45296 | D3: 45309 | E3: 12 | F3: 9 | G3: 5/0 | J3: Offshore team faced some challenges while implementing the Rich textbox. | K3: Internal: External:
A4: =IF(AND($D$1>=C4,$D$1<=D4),"CurrentSprint","NA") -> NA | B4: OBOP 7.11.0 Sprint 1,2 | C4: 45310 | D4: 45337 | E4: 25 | F4: 23 | G4: 0/0 | J4: Offshore team got appreciations for more than expected story points completed. Prabhu and Rajesh for helping with the hotfix as well. | K4: Internal: External:
A5: =IF(AND($D$1>=C5,$D$1<=D5),"CurrentSprint","NA") -> NA | B5: OBOP 7.11.0 Sprint 3 | C5: 45338 | D5: 45351 | E5: 13 | F5: 13 | G5: 0 | J5: Overall good sprint, Prabhu and offshore team got appreciated for DNN libraries documentation. | K5: Internal: External:
A6: =IF(AND($D$1>=C6,$D$1<=D6),"CurrentSprint","NA") -> NA | B6: OBOP 7.11.0 Sprint 4 | C6: 45352 | D6: 45365 | E6: 9 | F6: 9 | G6: 0/0 | J6: Offshore team got appreciations for investigating the AHA templates-DNN7(OP) and group filter story(OB). | K6: Internal: External:
A7: =IF(AND($D$1>=C7,$D$1<=D7),"CurrentSprint","NA") -> NA | B7: OBOP 7.12.0 Sprint 1 | C7: 45366 | D7: 45379 | E7: 11 | F7: 11 | G7: 2/0 | J7: Appreciated for completing all the work with good production release. | K7: Internal: External:
A8: =IF(AND($D$1>=C8,$D$1<=D8),"CurrentSprint","NA") -> NA | B8: OBOP 7.12.0 Sprint 2 | C8: 45380 | D8: 45393 | E8: 13 | F8: 10 | G8: 5/0 | J8: 2 DNN-7 story getting carried. Prabhu and Offshore team got appreciated for doing great job in learning and updating AHA templates. | K8: Internal: External:
A9: =IF(AND($D$1>=C9,$D$1<=D9),"CurrentSprint","NA") -> NA | B9: OBOP 7.12.0 Sprint 3 | C9: 45394 | D9: 45407 | E9: 7 | F9: 7 | G9: 0/0 | J9: Client appreciated for completing Recaptcha DNN9 conversion. Addition to this development completed for one stretch story. | K9: Internal: External:
A10: =IF(AND($D$1>=C10,$D$1<=D10),"CurrentSprint","NA") -> NA | B10: OBOP 7.12.0 Sprint 4 | C10: 45408 | D10: 45421 | E10: 15 | F10: 15 | G10: 6/0 | J10: Overall good sprint, Team completed more than expected story points. | K10: Internal: External:
A11: =IF(AND($D$1>=C11,$D$1<=D11),"CurrentSprint","NA") -> NA | B11: OBOP 7.13.1 Sprint 1 | C11: 45422 | D11: 45435 | E11: 17 | F11: 17 | G11: 0/0 | J11: Prabhu got appriciated for getting all AHA fixes completed and Mercy got appriciated for finding lot of issues. | K11: Internal: External:
A12: =IF(AND($D$1>=C12,$D$1<=D12),"CurrentSprint","NA") -> NA | B12: OBOP 7.13.1 Sprint 2 | C12: 45436 | D12: 45449 | E12: 28 | F12: 23 | G12: 8/0 | J12: Completed most of assigned stories/defects | K12: Internal: External:
A13: =IF(AND($D$1>=C13,$D$1<=D13),"CurrentSprint","NA") -> NA | B13: OBOP 7.13.1 Sprint 3 | C13: 45450 | D13: 45463 | E13: 17 | F13: 16 | G13: 5/0 | J13: Appreciated for completing all the work | K13: Internal: External:
A14: =IF(AND($D$1>=C14,$D$1<=D14),"CurrentSprint","NA") -> NA | B14: OBOP 7.13.1 Sprint 4 | C14: 45464 | D14: 45476 | E14: 8 | F14: 8 | G14: 1/0 | J14: Appreciated dev team for Investigation stories and Mercy for finding defect. | K14: Internal: External:
A15: =IF(AND($D$1>=C15,$D$1<=D15),"CurrentSprint","NA") -> NA | B15: OBOP 7.14.0 Sprint 1 | C15: 45477 | D15: 45491 | E15: 13 | F15: 13 | G15: 3/0 | J15: Appreciated Mercy for good testing | K15: Internal: External:
A16: =IF(AND($D$1>=C16,$D$1<=D16),"CurrentSprint","NA") -> NA | B16: OBOP 7.14.0 Sprint 2 | C16: 45492 | D16: 45505 | E16: 12 | F16: 12 | G16: 0/0 | J16: Completing another sprint successfully, Appriciated Prabhu and offshore for completing the work on messaging | K16: Internal: External:
A17: =IF(AND($D$1>=C17,$D$1<=D17),"CurrentSprint","NA") -> NA | B17: OBOP 7.14.0 Sprint 3 | C17: 45506 | D17: 45519 | E17: 11 | F17: 8 | G17: 0/0 | J17: Couldn't complete testing because of release pipeline certificate issue. | K17: Internal: External:
... A19: =IF(AND($D$1>=C19,$D$1<=D19),"CurrentSprint","NA") -> NA | B19: OBOP 8.2.0 Sprint 1 | C19: 45534 | D19: 45547 | E19: 12 | F19: 12 | G19: 0/0 | J19: Appreciated Prabhu for providing KT to quick invoice team | K19: Internal: External:
A20: =IF(AND($D$1>=C20,$D$1<=D20),"CurrentSprint","NA") -> NA | B20: OBOP 8.2.0 Sprint 2 | C20: 45548 | D20: 45561 | E20: 20 | F20: 15 | G20: 5/0 | K20: Internal: External:
A21: =IF(AND($D$1>=C21,$D$1<=D21),"CurrentSprint","NA") -> NA | B21: OBOP 8.2.0 Sprint 3 | C21: 45562 | D21: 45575 | E21: 20 | F21: 17 | G21: 3/3 | J21: TST was down which lead to rolling over one story Peer CRC: 0 Onsite CRC: 2 Client CRC: 0 Internal Defects :2 External Defects:0 Appreciated i)Prabhu for helping Alice on providing info on some stories ii)Mercy for helping out while Alice was unavailable iii) Rajesh and Prabhu for helping Joe set up GGO locally. iv) Lot of challenges while developing the OP page module and offshore continued working through it v) Rajesh for helping Prabhu and team with testing of OP stories. vi) Rajkumar and Prabhu for good coordination for getting the entire flow end to end on Quick invoicing | K21: Internal: External:
A22: =IF(AND($D$1>=C22,$D$1<=D22),"CurrentSprint","NA") -> NA | B22: OBOP 8.2.0 Sprint 4 | C22: 45576 | D22: 45589 | E22: 17 | F22: 17 | G22: 0/0 | I22: 1.Import quick invoice payment page designed, created in GGO and placed in between Registrations & RSVPs 2. Added new convenience fee sale and made reconcile with sale payment association 3.Pending quick invoice imports count included in existing left nav notification counter | J22: i) Appreciated the team for completing all the quick invoice stories. ii) Kudos to Farhath and Mercy for helping with the test planning and testing which made it easier for Alice. iii) Kudos to Prabhu and Rajkumar for coordinating with offshore teams and completing all the planned stories for the sprint iv) Appreciated Offshore for finishing the planned stories and meeting the deadline v) Rajesh and Prabhu helped Rajkumar & offshore with the OP and GGO integration. Peer CRC: 2 Onsite CRC: 0 Client CRC: 0 Internal Defects :0 External Defects:0
A23: =IF(AND($D$1>=C23,$D$1<=D23),"CurrentSprint","NA") -> NA | B23: OBOP 8.3.0 Sprint 1 | C23: 45590 | D23: 45603 | E23: 11 | F23: 8 | G23: 0/0 | I23: 1.Quick Invoice feature release into CRT 2.Added Privacy Police notice on both OB & OP 3.Default application text css changes & Text updates | J23: Nice job with the privacy policy implementation. One story has been moved to next sprint for testing alone Kudos to Offshore QA - has been very helpful , making sure all gaps are covered Peer CRC: 0 Onsite CRC: 0 Client CRC: 0 Internal Defects:2 External Defects: 0
A24: =IF(AND($D$1>=C24,$D$1<=D24),"CurrentSprint","NA") -> NA | B24: OBOP 8.3.0 Sprint 2 | C24: 45604 | D24: 45617 | E24: 14 | F24: 14 | G24: 3/0 | I24: 1.OP 8.2.0 release to CRT & PRD 2.App help url updates 3.Invoicing feature updates - Collected from pilot user's feedback 4.Escalation support | J24: Kudos shared to Mercy for the support in making a lot of test plans and doing thorough testing that really helped out with all the small areas we have to verify, especially with all of the stories we added during the quick invoice effort. Rajkumar and team for the merge field completion. Rajesh for helping with the merge strategies and Prabhu was very helpful for a couple of tickets Joe had. Peer CRC:0 Onsite CRC:0 Client CRC: 6 Internal Defects:2 External Defects: 0 A 3 point story was added towards the end of the Sprint as part of the strech goal and was rolled over to the next sprint
A25: =IF(AND($D$1>=C25,$D$1<=D25),"CurrentSprint","NA") -> NA | B25: OB-OP 8.3.0 Sprint 3 | C25: 45618 | D25: 45631 | E25: 21 | F25: 21 | G25: Ten/0 | I25: 1. We had 8.2.2 OP CRT release 2. completed final set of pending invoicing tasks 3.Macroscope fixes | J25: Kudos to Rajkumar and team for taking invoicing project to finish line, Offshore QA - Mercy and Farhath for putting some good notes for Alice which was helpful when she got back and Preethi and Karthi for managing all the dev work during the US thanksgiving holidays when everyone was away Kalai and Rajiv are very dynamic and all the deliveries were on time Prabhu and Rajesh for the KT and support to the invoicing team Peer CRC:0 Onsite CRC:2 Client CRC: 2 Internal Defects:1 External Defects: 0 A 2 point story was added towards the end of the Sprint as part of the strech goal and was rolled over to the next sprint
A26: =IF(AND($D$1>=C26,$D$1<=D26),"CurrentSprint","NA") -> NA | B26: OB-OP 8.3.0 Sprint 4 | C26: 45632 | D26: 45659 | E26: 11 | F26: 13 | G26: 15/0 | I26: 1.OB 7.12.1 release to CRT& PRD 2. OP 8.2.2 PRD Release 3.Complete Invoicing 4.Macroscope fix | J26: Kudos Offshore in general and offshore QA for keeping up with things when Onsite was away for holidays +2 Mercy for keeping up with test plans when Alice was out Raj kumar and team for a great impact on past few sprints +1 Peer CRC:0 Onsite CRC:1 Client CRC: 0 Internal Defects:0 External Defects: 0 Some of the stories are stretch and got carry forwarded because of client resources unavailability due to holidays
A27: =IF(AND($D$1>=C27,$D$1<=D27),"CurrentSprint","NA") -> NA | B27: OB-OP 8.4.0 Sprint 1 | C27: 45660 | D27: 45673 | E27: 16 | F27: 13 | G27: 0/0 | I27: 1. Release 8.3.0 to CRT and PRD 2. Macroscope fix in OP and OB | J27: Kudos to Given the release, towards the end of the sprint we were seeing a bunch of issues in OP and OB and Mercy was very helpful in testing those Given the product overlap across both teams and the staggered release for both teams, it was confusing but the team did a great job overall staying on top of everything Rajesh for helping Joe set up for the portals To the team on a great job on the overall Invoice project and release Peer CRC:0 Onsite CRC:2 Client CRC: 0 Internal Defects:0 External Defects: 0 3 point story carry forwarded to next sprint. Part of the performance improvement done.Restrictions on DNN9 core functionality prevents us from finding performance improvements. But there is more room left for improvements. So Story was carry forwarded
A28: =IF(AND($D$1>=C28,$D$1<=D28),"CurrentSprint","NA") -> NA | B28: OB-OP 8.4.0 Sprint 2 | C28: 45674 | D28: 45687 | E28: 16 | F28: 10 | G28: 5/0 | I28: RSVP enhancements, continuing with Macroscope work,OP MFA login production hotfix | J28: Peer CRC:0 Onsite CRC:0 Client CRC: 0 Internal Defects:1 External Defects: 0 2 RSVP stories got carried over to the next sprint, RSVP Multiple attendee dynamic control creation has been challenging. Completed major functionalities, local testing and dev testing is in progress and a 3 point story is dependent on that 8 point story so we couldn't proceed that without completing the main story
A29: =IF(AND($D$1>=C29,$D$1<=D29),"CurrentSprint","NA") -> NA | B29: OB-OP 8.4.0 Sprint 3 | C29: 45688 | D29: 45701 | E29: 14 | F29: 12 | G29: 1/0 | I29: Continue RSVP enhancements, Supported OP 8.3.2 Hotfix testing support for delay in OP site creation, RSVP index table update and Apigee threading exception | J29: Kudos to i) Rajesh to take the big feature and manage it +1 ii) Joe,Mike , Rajesh, Derek was handling all the rapid change in the sprint goal iii) Rajesh for handling all on both teams GGO and OB/OP iv) Offshore dev and QA for working hard on multiple attendees and getting all the scenarios covered Peer CRC:2 Onsite CRC:2 Client CRC: 0 Internal Defects:0 External Defects: 2 3 pt bug has been carry forwarded to next sprint as we couldn't able to reproduce the bug in our environment and trying to find the root cause for it
A30: =IF(AND($D$1>=C30,$D$1<=D30),"CurrentSprint","NA") -> NA | B30: OB-OP 8.4.0 Sprint 4 | C30: 45702 | D30: 45715 | E30: 9 | F30: 9 | G30: 6/3 | I30: New card type added with existing ones, OP 8.3.3 and 8.4.0 release to CRT | J30: Kudos to i) Everyone in the team for all the hard work this sprint ii) Joe , Rajesh, Mike and Carlos for all of the release stuff iii) Offshore for taking care of all the sprint stories Peer CRC:0 Onsite CRC:0 Client CRC: 0 Internal Defects:1 External Defects: 3 3 pt bug has been flagged in JIRA as blocker and removed from sprint during sprint end and another 3 pt bug which is in stretch has been carry forwarded to next sprint, in which we have completed the fix for 1 report, need to check for remaining 3 reports
A31: =IF(AND($D$1>=C31,$D$1<=D31),"CurrentSprint","NA") -> NA | B31: OB-OP 8.5.0 Sprint 1 | C31: 45716 | D31: 45729 | E31: 14 | F31: 11 | G31: 0/0 | I31: Release OP 8.4 to PRD, begin investigating OB UX and QoL fixes | J31: Kudos i) Prabhu and Rajesh on assisting Joe on a ticket related to convenience fee ii) Offshore QA Mercy for the test plan put together for catalog verification, very good testing and makes it more secure iii) Karthi and Preethi for great documentation on the investigation stories Peer CRC:0 Onsite CRC:0 Client CRC: 0 Internal Defects:0 External Defects: 2 One of the story got completed at the last minute because the fix wasn't working so the team had to coninue trying out different aproaches till it worked. It was sent for peer review on the last day and hence got carry forwarded to the next sprint for testing
A32: =IF(AND($D$1>=C32,$D$1<=D32),"CurrentSprint","NA") -> NA | B32: OB-OP 8.5.0 Sprint 2 | C32: 45729 | D32: 45743 | E32: 14 | F32: 19 | G32: 7/0 | I32: Begin work on OB UX settings and layouts | J32: Kudos i) We did a stretch AC on the layout and Prabhu assisted Joe on that ii) Prabhu for helping Alice with testing iii) Rajesh for helping Alice on the email issue +1 iv) Offshore for completing all the planned stories and adding some stretch stories Peer CRC:0 Onsite CRC:0 Client CRC: 1 Internal Defects:0 External Defects: 0 OB UX settings and layout implementation Escalation support for investigating the max bid label update Fixed Max Bid label OP negative payment fix
A33: =IF(AND($D$1>=C33,$D$1<=D33),"CurrentSprint","NA") -> NA | B33: OB-OP 8.5.0 Sprint 3 | C33: 45743 | D33: 45757 | E33: 14 | F33: 11 | G33: 0/0 | I33: Continue OB UX and high value OP items Accompolishments: Added new settings in Online bidding settings page Feature flag implementation for OB - sending data from GGO to OB | J33: Peer CRC:0 Onsite CRC:0 Client CRC: 0 Internal Defects:1 External Defects: 2 Pending reason One 3-point story was carried over to the next sprint. While development, local testing, and DEV testing were completed from our side, the peer review and testing for OB-3731 were delayed. This was primarily due to the extended time required for development and testing of OB-3708 (an 8-point story). As a result, OB-3731 has been moved to the next sprint. | K33: What went well? Offshore doing testing in Dev before going to TST helps mitigate issues later in the Sprint What didn’t go well? The development for OB settings page was a little challenging Kudos 1. Nice job team on OB settings page, the mockups really look good 2. Great QA team for being a sport , working last minute to test the stories +1 3. Offshore QA Mercy for finding the issues before it hit TST and helped in not sending it back to Dev later 4. Prabhu and Rajesh for their support to Alice 5. Prabhu, Offshore dev Preethi and Karthi for completing the OB settings page for spending extended hours in completing it +2
A34: =IF(AND($D$1>=C34,$D$1<=D34),"CurrentSprint","NA") -> NA | B34: OB-OP 8.5.0 Sprint 4 | C34: 45757 | D34: 45771 | E34: 11 | F34: 14 | G34: 5/0 | I34: Release and test OP 8.5 and OB 7.13 to CRT. Donor Project continuing work Accomplishment 1. Tested OP 8.5 and OB 7.13 in CRT 2. Upgraded Angular 12 to 13, version got upgraded but facing few routing issues | J34: Peer CRC:0 Onsite CRC:0 Client CRC: 0 Internal Defects:0 External Defects: 0 Pending reason 1 Bug has been carry forwarded to next sprint since it is taking more time than expected. Also PM cannot remember what this report looked like working in Prod, so we may need to do some discovery and explanation in order to come up with a good solution | K34: What went well? 1. CRT testing completed on time 2. Great progress on Angular update 3. Good initial progress on Donor project 4. Completed more stories than planned What didn’t go well? 1. The package dependency made the Angular update challenging 2. Fixing the section report issue has been more complex than planned Kudos Prabhu and Rajesh for supporting the CRT issue fix, Carlos as well Rajesh for leading the way on Donor Project +2 Offshore for the Angular update , that was a big jump +2
A35: =IF(AND($D$1>=C35,$D$1<=D35),"CurrentSprint","NA") -> NA | B35: OB-OP a7.14.0 Sprint 1 | C35: 45771 | D35: 45785 | E35: 15 | F35: 11 | G35: 0/0 | I35: OB & OP PRD release, continue with OB UX and Donor project Accomplishment 1. Passed the new settings value from GGO to OB and mapped the header values in OB side UI 2. Upgraded Angular 12 to 13, Updated node version from 14 to 16, fixing the errors | J35: Peer CRC:0 Onsite CRC:0 Client CRC: 3 Internal Defects:0 External Defects: 0 Pending reason OP-2747-It has been carry forwarded to next sprint since it is taking more time than expected. Also PM cannot remember what this report looked like working in Prod, so we may need to do some discovery and explanation in order to come up with a good solution OB-3680 - Story has been carry forwarded to next sprint - Dependent on OB-3755. Development and peer review is completed, Since PR was shared in the last day testing will be done in next sprint | K35: What went well? The new Donor platform setup went well On pace with OB UX What didn’t go well? Last minute unplanned PTO for team member led to delay in closing a few tickets New OB page and design turned out to be a little challenging Kudos Preethi for updating the node and Angular version as it requires a lot of tracking and patience. Thanks for doing it
A36: =IF(AND($D$1>=C36,$D$1<=D36),"CurrentSprint","NA") -> NA | B36: OB-OP 8.0 Sprint 2 | C36: 45785 | D36: 45799 | E36: 15 | F36: 15 | G36: 0/0 | I36: OB & OP PRD release, continue with OB UX and Donor project Accomplishment 1. The team completed all they planned for and more (initially firebase was spike later converted to story) 2. Fixed the warnings while compiling angular 13, ended up with 1 console error while running application | J36: Peer CRC:0 Onsite CRC:1 Client CRC: 0 Internal Defects:1 External Defects: 0 Escaped defect RCA - Should do proper code review and local testing,DEV testing covering all scenarios Review Comment - Add try catch block here when you connecting with DB to make operations | K36: What went well? The team completed all they planned for and more PRD releases were long and it went well What didn’t go well? Firebase notification was a little tricky to configure Handling Aesgcn decryption for existing URLs cost a little extra time to complete Docker desktop is not authorized so it forced the team to find a different way to communicate with the database Kudos Offshore and Dev Prabhu for completing the investigation and implementation of Firebase notification +2
A37: =IF(AND($D$1>=C37,$D$1<=D37),"CurrentSprint","NA") -> NA | B37: OB-OP 8.0 Sprint 3 | C37: 45800 | D37: 45814 | E37: 16 | F37: 14 | G37: 6/0 | I37: Continue OB UX work, setup for donor platform Accomplishment 1. Updated Node js to version 16 and then to 18, trying to fix the errors 2. Firebase notification is coming correctly to the bidders who are outbidden 3. New team members setup is completed and started the design story | J37: Peer CRC:0 Onsite CRC:0 Client CRC: 2 Internal Defects:0 External Defects: 0 Review comment - 1. Macroscope will ding us for putting apikeys or secrets in the repo. We need to add these as variables, even for local testing the same way we do for the SMS test keys 2. Let's add a general exception catch as well. Pending reason 1. OB-3675 -During the sprint, a few high-priority security issues were introduced that required quick attention. Addressing them took some time away from our originally planned work. Development work has been completed successfully, and dev environment testing was verified by the Relevantz offshore QA team. However, during deployment to the TST environment, we encountered issues related to pipeline variables. As a result, only testing is pending for this story. 2. DON-20 - Stretch story - Development completed, local testing is in progress, Once done will raise the PR in next sprint | K37: What went well? Onboarding went well What didn’t go well? 2 Security issues took about a week of 2 of the team members time New developers onboarding For multiple bidders, Firebase notification is not getting sent randomly Angular upgrade has been challenging Escalation support for OP Login issue Kudos Prabhu nice job get everybody onboarded +3 Takeaways 6/5/2025 Angular Update timebox effort should be significantly lowered - 10 hrs a Sprint Escalation Support should be filtered by Derek Anderson and Mike Horihan so that team can focus on OB UX overhaul and Donor project
A38: =IF(AND($D$1>=C38,$D$1<=D38),"CurrentSprint","NA") -> NA | B38: OB-OP 8.0 Sprint 4 | C38: 45814 | D38: 45826 | E38: 7 | F38: 2 | G38: 2/0 | I38: CRT Release and testing for OB and OP, continue with OB UX and Donor project Accomplishment Completed the design for login and registration page | J38: Peer CRC:0 Onsite CRC:0 Client CRC: 0 Internal Defects:0 External Defects: 0 Pending reason 1. DON-20, DON-21 - Local testing completed from offshore QA end and updated the comments in JIRA but since onsite QA was occupied with CRT testing, couldn't give signoff to this ticket. Gave the PR for DON-21 on tuesday (17/06) | K38: A special shout out to the new Donor team for coming up to speed very fast and taking control right away. Well done! Overall it was a good sprint even though we didn't meet the Sprint forecast this time. The onsite QA needs to signoff on those tickets before closing and given this was a regression sprint, the onsite QA had her hands full with CRT testing. Kudos New Donor team for completing a lot of the design work +1
A39: =IF(AND($D$1>=C39,$D$1<=D39),"CurrentSprint","NA") -> NA | B39: OB-OP 8.1 Sprint 1 | C39: 45827 | D39: 45841 | E39: 12 | F39: 7 | G39: 3/0 | I39: Release OB/OP to PRD, continue OB UX and Donor Platform Completed the design for registration page and password reset pages | J39: Peer CRC:0 Onsite CRC:0 Client CRC: 3 Internal Defects:0 External Defects: 0 Pending reason DON-16 - 5 point story - Development completed, local testing is completed,need to do some more common functionality in API Once done will raise the PR in next sprint, Initially this was a 3 point story, later due to more work on that the story point has been increased from 3 to 5 Review comment 1.Rename the varialbe 2.These 5 radio buttons should not be inputs. They will be checked off during client side input validation. 3.Remove hard-coded email. | K39: What went well? All planned stories got completed and more Quick turn around on the Hot Fix What didn’t go well? A number of security issues came through which was unplanned and high priority for some old modules The arc review is preventing us from implementing B2C Kudos Offshore team did a great job on OB and Donor work, completed everything +1 Appreciate Rajesh stepping in and covering for Prabhu Joe and Prabhu giving assistance on couple of stories for testing to Alice( specially on Donor project) Quick turn around on the Hot Fix Alice and Offshore QA team has done a great job on automation testing which made both the prod release testing quick +1
A40: =IF(AND($D$1>=C40,$D$1<=D40),"CurrentSprint","NA") -> NA | B40: OB-OP 8.1 Sprint 2 | C40: 45841 | D40: 45855 | E40: 14 | F40: 7 | G40: 0/0 | I40: More OB UX, Donor Platform infrastructure, and OP security remediation. Accomplishement Completed API Structure and serilog setup | J40: Peer CRC:0 Onsite CRC:0 Client CRC: 0 Internal Defects:0 External Defects: 0 Pending reason Don-39 - Incorporating Vega components into the input validation effort was more completex than initially thought Don-45 - B2C team not yet create Tenant & Singin and Singup page in Azure Portal | K40: What went well? API Setup from scratch and user creation and Serilog implementation What didn’t go well? Faced some of the validation issues from Vega controls Kudos Prabhu did a great job on api setup and user creation code review and suggession Offshore team did a great job on OB and Donor work Murugesan for detailed testing
A41: =IF(AND($D$1>=C41,$D$1<=D41),"CurrentSprint","NA") -> NA | B41: OB-OP 8.1 Sprint 3 | C41: 45855 | D41: 45869 | E41: 11 | F41: 8 | G41: 0/0 | I41: Continue OB UX (Package Cards, Donation Modal), Platform work, Security remediation Accomplishement Created Home page design | J41: Peer CRC:0 Onsite CRC:0 Client CRC: 0 Internal Defects:0 External Defects: 0 Pending reason Don-45 - B2C implementation requirement little bit changed integrate according to angular 19 | K41: What went well? Donor app progress was good A lot of positive comments from CS on the Donor Platform progress - well done team! “The login page looks great and it will be one of the most visited page” What didn’t go well? OB certificate issue blocked testing in Dev, TST and CRT OB build Pipeline issue The fixes for WhiteHat security findings was challenging Kudos Joe for taking care of all the scrum processes seamlessly in Rupa’s absence Prabhu for supporting Alice with Donor platform testing Mercy for cross site scripting testing and bringing up some issues Prabhu, Rajesh, Mike H and Joe for getting the Certificate issue resolved, it is very close to getting done Joe for fixing the Build pipeline and the whitehat security scanning +1 Arivalagan - the code he delivered for Don 39 and Don 40 is of high quality
...

Sheet Unplanned Leaves
A1: Total Planned Leaves
A2: Total Unplanned Leaves | B2: 0
B3: Resource Name
A4: Sprint Name | B4: Saranya Palani | C4: Ubaithulla | D4: Arivalagan | E4: Irsath | F4: Kannan | G4: Murugesan | H4: Remarks
A5: OB-OP 8.5 Sprint 1 (29-Jan-26 to 12-Feb-2026) | B5: 0 | C5: 0 | D5: 0 | E5: 0 | F5: 0 | G5: 0 | H5: No unplanned leaves
A6: OB-OP 8.5 Sprint 2 (12-Jan-26 to 26-Feb-2026) | B6: 0 | C6: 0 | D6: 0 | E6: 0 | F6: 0 | G6: 0 | H6: No unplanned leaves
A7: OB-OP 8.5 Sprint 3 (26-Feb-26 to 12-Feb-2026)0 | B7: 0 | C7: 0 | D7: 3/11/2026 - 1 | E7: 0 | F7: 0 | G7: 0 | H7: Wife admitted in hospital
A8: OB-OP 8.5 Sprint 4 (12-Mar-26 to 26-Mar-2026) | B8: 0 | C8: 0 | D8: 0 | E8: 0 | F8: 0 | G8: 0 | H8: No unplanned leaves
A9: OB-OP 8.6.0 Sprint 1 (26-Mar-26 to 09-Apr-2026) | B9: 0 | C9: 0 | D9: 0 | E9: 4 | F9: 0 | G9: 0 | H9: Paternity Leave - 6,7,8,9 Ubai didnt take the planned leave
A10: OB-OP 8.6.0 Sprint 2 (09-Apr-26 to 23-Apr-2026) | B10: 0 | C10: 0 | D10: 0 | E10: 0 | F10: 0 | G10: 0 | H10: No unplanned leaves
A11: OB-OP 8.6.0 Sprint 3 (24-Apr-26 to 07-May-2026) | B11: 0 | C11: 0 | D11: 0 | E11: 0 | F11: 0 | G11: 0 | H11: No unplanned leaves
A18: Total | B18: 0 | C18: 0 | D18: 1 | E18: 0 | F18: 0

Sheet OB-OP 8.6.0 Sprint 4-Status
A1: S.No | B1: Application Name | C1: Sprint Start Date | D1: Sprint End Date | E1: Sprint | F1: Developer | G1: Story ID/Defect ID | H1: Description | I1: Status | J1: Estimated(hrs/sp) | K1: Actual(hrs/sp) | L1: Actual Hours Worklog | M1: Dev Start Date | N1: Dev End Date | O1: Unit testing | P1: Peer Tested By | Q1: Peer Tested Defects, if any | R1: Peer Reviewed By | S1: Peer Code Review Comments, if any | T1: PR Number/Link | U1: PR Created Date | V1: PR Approved Date | W1: Onsite Lead Code Review | X1: Code Review Comments, if any | Y1: Client Code Review | Z1: Approved Date | AA1: Code Review Comments, if any2 | AB1: Internal PO -POV Comments | AC1: Client PO -POV Comments | AD1: Comments | AE1: QA Comments
A2: 1 | B2: Donor Wave | C2: 46149 | D2: 46163 | E2: OB-OP 8.6.0 Sprint 4 | F2: Irsath | G2: DON-331 | H2: Design and implement self check-in page for Supporters - Payment Methods | I2: Being Developed | K2: 3 | M2: 46150 | AD2: 5/8/2026 - Analysis completed started development. 5/11/2026 -Started the designing 5/12/2026 - Functionality has been completed
A3: 2 | B3: Donor Wave | C3: 46149 | D3: 46163 | E3: OB-OP 8.6.0 Sprint 4 | F3: Arivalagan/Saranya | G3: DON-137 | H3: Design and implement self check-in page for Supporters - Event details | I3: Peer Review | K3: 3 | M3: 46150 | P3: Murugesan .M | Q3: 1]location and events font size should match with figma 2] Event Details should be displayed on navigate option - 3] figma shows 434 width for complete check in btn , app shows 534 width and looks bit lengthy 4 ]event details should be static like back btn in check out page - 5] hyphen should not be displayed in the header in page tile as per figma - retested 6] the check in text is not required in the appln header as we have already respective page header in the check in page -this looks double entry - 7]profile initial and edit profile option is not displayed in the right top of the page - 8] Check in page should be displayed as in the figma like ticket [ top and bottom curve should come] - 9]Org icon size should be displayed as it is in the figma | AD3: 5/8/2026 - Analysis completed started development 5/11/2026-Started the design and functionality 5/12/2026-Design and functionality completed
A4: 3 | B4: Donor Wave | C4: 46149 | D4: 46163 | E4: OB-OP 8.6.0 Sprint 4 | F4: Kannan/Ubai | G4: DON-330 | H4: Design and implement self check-in page for Supporters - Tickets | I4: Being Developed | K4: 3 | M4: 46150 | P4: Murugesan .M | Q4: 1] user name and address should be displayed in the ticket , currently events name is displayed wrongly 2] ticket box should be displayed as in the figma 3] not checked in and checked in btn color code should be displayed as in the figma 4] Edit btn should be displayed as in the figma [bold and curve] - 5]Ticket icon should be displayed as in the figma besides your ticket text - 6]Your ticket text and purchased line should be matched with figma - Retested 7]Donor user name text and size style should be displayed as in the figma - 8]edit button functionality need to be fixed and address should be updated - 9]Ticket name font size looks 18 px in figma ,but the same looks 16 px in the application UI now 10]Complete check in button width looks 436 px in figma and current ui shows 528 px width 11]ticket Image size should rounded off as 13x13 as in the figma 12] Edit Address should be displayed instead of below edit profile address label text . | AD4: 5/8/2026 - Analysis completed (UX and API) 5/11/2026-Started the design 5/12/2026-DON-137 code merged and develop completed
A5: 4 | B5: Donor Wave | C5: 46149 | D5: 46163 | E5: OB-OP 8.6.0 Sprint 4 - [STRETCH] | F5: Saranya | G5: DON-325 | H5: Donor Check-in (Event details API) - Backend | I5: Being Developed | K5: 2 | M5: 46154 | AD5: 5/12/2026 - Analysis completed start the api intergration 5/13/2026 - API development completed
A6: 5 | B6: Donor Wave | C6: 46149 | D6: 46163 | E6: OB-OP 8.6.0 Sprint 4 - [STRETCH] | F6: Ubaithullah | G6: DON-328 | H6: Donor Check-in (Tickets API) - Backend | I6: Peer Review | K6: 2 | M6: 46154 | AD6: 5/12/2026 - Analysis and development completed
A7: 6 | B7: Donor Wave | C7: 46149 | D7: 46163 | E7: OB-OP 8.6.0 Sprint 4 - [STRETCH] | F7: Irsath/Ubaithullah | G7: DON-329 | H7: Donor check-in (Create GET/SET call) - Backend | I7: Being Developed | K7: 2 | M7: 46155 | AD7: 5/13/2026 - Analysis completed started development. 5/14/2026 - 30% API has been created 5/15/2026 - 60% API has been created

Sheet OB-OP 8.6.0 Sprint 4-Defect
A1: S.No | B1: Sprint | C1: Story/Defect ID | D1: Parent Story | E1: Developer | F1: Issue Type | G1: Issue Description | H1: Priority | I1: Defect Source | J1: Type | K1: Status | L1: Root Cause Category | M1: Comments | N1: Found By | O1: RCA Comment

Sheet OB-OP 8.6.0 Sprint 3-Status
A1: S.No | B1: Application Name | C1: Sprint Start Date | D1: Sprint End Date | E1: Sprint | F1: Developer | G1: Story ID/Defect ID | H1: Description | I1: Status | J1: Estimated(hrs/sp) | K1: Actual(hrs/sp) | L1: Actual Hours Worklog | M1: Dev Start Date | N1: Dev End Date | O1: Unit testing | P1: Peer Tested By | Q1: Peer Tested Defects, if any | R1: Peer Reviewed By | S1: Peer Code Review Comments, if any | T1: PR Number/Link | U1: PR Created Date | V1: PR Approved Date | W1: Onsite Lead Code Review | X1: Code Review Comments, if any | Y1: Client Code Review | Z1: Approved Date | AA1: Code Review Comments, if any2 | AB1: Internal PO -POV Comments | AC1: Client PO -POV Comments | AD1: Comments | AE1: QA Comments
A2: 1 | B2: Donor Wave | C2: 46135 | D2: 46149 | E2: OB-OP 8.6.0 Sprint 3 | F2: Irsath | G2: DON-348 | H2: Donor b2c Styling Update | I2: Completed | J2: 1 | K2: 1 | M2: 46136 | N2: 46139 | O2: Done | P2: Murugesan.M | Q2: Nil | R2: Ubaithullah | S2: Nil | T2: https://dev.azure.com/greatergiving/Greater%20Giving/_git/Donor/pullrequest/9479 | U2: 46139 | V2: 46143 | W2: Rajesh | X2: Nil | Y2: Joe | Z2: 46143 | AA2: Nil | AB2: Nil | AC2: Nil | AD2: 4/24/2026 - Deveopment has been completed. Waiting for B2C Team Change the setting of allow external javascript access. 4/28/2026 -Unit Testing has been completed | AE2: 4/27/2026-Completed testing on style .css file 5/6/2026-Tested config scema in dev env
A3: 2 | B3: Donor Wave | C3: 46135 | D3: 46149 | E3: OB-OP 8.6.0 Sprint 3 | F3: Saranya | G3: DON-351 | H3: Donor Maintenance Notifications | I3: Completed | J3: 2 | K3: 2 | M3: 46136 | N3: 46139 | O3: Done | P3: Murugesan.M | Q3: Nil | R3: Kannan | S3: Nil | T3: https://dev.azure.com/greatergiving/Greater%20Giving/_git/Donor/pullrequest/9509 | U3: 46140 | V3: 46142 | W3: Rajesh | X3: Nil | Y3: Joe | Z3: 46143 | AA3: Nil | AB3: Nil | AC3: Nil | AD3: 4/24/2026 - implemented the maintanance notification functionality 4/27/2026 -code refactoring 4/30/2026 - migration script based code changed | AE3: 4/24/2026-Completed first round of testing 4/29/2026- Completed testing and Prepared validation doc 5/4/2026 -Regression testing 5/7/2026 - Tested in develop branch
A4: 3 | B4: Donor Wave | C4: 46135 | D4: 46149 | E4: OB-OP 8.6.0 Sprint 3 | F4: Arivalagan | G4: DON-356 | H4: Expan-health-check | I4: Completed | J4: 2 | K4: 2 | M4: 46136 | N4: 46148 | O4: Done | P4: Murugesan.M | Q4: Nil | R4: Kannan | S4: Nil | T4: https://dev.azure.com/greatergiving/Greater%20Giving/_git/Donor/pullrequest/9536 | U4: 46146 | V4: 46149 | W4: Rajesh | X4: Nil | Y4: Joe | Z4: 46149 | AA4: Nil | AB4: Nil | AC4: Nil | AD4: 4/14/2026-Analysis and stated teh implementation 4/27/2026-Implemented Profile service in repository 4/28/2026-Code refactoring issue are fixed 4/29/2026-Review code fixed | AE4: 4/24/2026- Analysis and Test Scenarios preprations 4/29/2026- Completed first round of testing 4/30/2026- regression testing 5/7/2026 - Tested in dev env
A5: 4 | B5: Donor Wave | C5: 46135 | D5: 46149 | E5: OB-OP 8.6.0 Sprint 3 | F5: Ubaitullah | G5: DON-362 | H5: Profile update email | I5: Completed | J5: 1 | K5: 1 | M5: 46136 | N5: 46136 | O5: Done | P5: Murugesan.M | Q5: Nil | R5: Kannan | S5: Nil | T5: https://dev.azure.com/greatergiving/Greater%20Giving/_git/Donor/pullrequest/9505 | U5: 46136 | V5: 46141 | W5: Rajesh | X5: Nil | Y5: Joe | Z5: 46141 | AA5: Nil | AB5: Nil | AC5: Nil | AD5: 4/24/2026 - Developement completed, Provided to QA for testing | AE5: 4/24/2026-Completed first round of testing 4/28/2026- Completed testing and Prepared validation doc
A6: 5 | B6: Donor Wave | C6: 46135 | D6: 46149 | E6: OB-OP 8.6.0 Sprint 3 | F6: Ubaitullah/ Irsath/ Kannan/Arivalagan/Saranya | G6: DON-360 | H6: Donor Catch all | I6: Completed | J6: 5 | K6: 5 | M6: 46136 | N6: 46148 | O6: Done | P6: Murugesan.M | Q6: 1.Getting internal error 500 and unser unable to login to the appication and throwing an error in console as well | R6: Irsath/Ubai | S6: Nil | T6: https://greatergiving.visualstudio.com/Greater%20Giving/_git/Donor/pullrequest/9530 https://greatergiving.visualstudio.com/Greater%20Giving/_git/Donor/pullrequest/9514 https://greatergiving.visualstudio.com/Greater%20Giving/_git/Donor/pullrequest/9536 | U6: 5/28/2026 5/4/2026 5/5/2026 | V6: 5/5/2026 5/5/2026 5/6/2026 | W6: Rajesh | X6: Nil | Y6: Joe | Z6: 5/5/2026 5/5/2026 5/6/2026 | AA6: NIl | AB6: Nil | AC6: Nil | AD6: 4/27/2026 - Bug fixing 15% has been completed 4/28/2026 - Bug fixing 20% has been completed 4/29/2026 - Bug fixing 40% has been completed 4/30/2026 - Bug fixing 70% has been completed 5/4/2026 - - Bug fixing 90% has been completed 5/5/2026 - - Bug fixing 95% has been completed 5/6/2026 - - Bug fixes has been completed and given for PR | AE6: 4/27/2026 -Retested the fixed defects 4/28/2026-Retested the fixed two defects sna reopened one issue 4/29/2026-Retested the fixed defects 4/30/2026- regression testing 5/5/2026-Retested the fixes 5/6/2026- tested in Dev env 5/7/2026 - Tested in develop branch
A7: 6 | B7: Donor Wave | C7: 46135 | D7: 46149 | E7: OB-OP 8.6.0 Sprint 3 | F7: Kannan | G7: DON-353 | H7: Correlate Project Key to Signin/ Signup | I7: Completed | J7: 2 | K7: 2 | M7: 46136 | N7: 46140 | O7: Done | P7: Murugesan.M | Q7: Nil | R7: Ubaithullah | S7: Nil | T7: Pull Request 9491: DON-353 Correlate Project Key to Signin/ Signup | U7: 46146 | V7: 46147 | W7: Rajesh | X7: Nil | Y7: Joe | Z7: 46147 | AA7: Nil | AB7: Nil | AC7: Nil | AD7: 4/24/2026 - merged the DON-130 code and testing | AE7: 4/24/2026- Analysis and Test Scenarios preprations 4/28/2026- Completed first round of testing 4/29/2026- Completed testing and Prepared validation doc 5/5/2026-Regresstion testing 5/7/2026 - Tested in develop branch

Sheet OB-OP 8.6.0 Sprint 3-Defect
A1: S.No | B1: Sprint | C1: Story/Defect ID | D1: Parent Story | E1: Developer | F1: Issue Type | G1: Issue Description | H1: Priority | I1: Defect Source | J1: Type | K1: Status | L1: Root Cause Category | M1: Comments | N1: Found By | O1: RCA Comment

Sheet OB-OP 8.6.0 Sprint 2-Status
A1: S.No | B1: Application Name | C1: Sprint Start Date | D1: Sprint End Date | E1: Sprint | F1: Developer | G1: Story ID/Defect ID | H1: Description | I1: Status | J1: Estimated(hrs/sp) | K1: Actual(hrs/sp) | L1: Actual Hours Worklog | M1: Dev Start Date | N1: Dev End Date | O1: Unit testing | P1: Peer Tested By | Q1: Peer Tested Defects, if any | R1: Peer Reviewed By | S1: Peer Code Review Comments, if any | T1: PR Number/Link | U1: PR Created Date | V1: PR Approved Date | W1: Onsite Lead Code Review | X1: Code Review Comments, if any | Y1: Client Code Review | Z1: Approved Date | AA1: Code Review Comments, if any2 | AB1: Internal PO -POV Comments | AC1: Client PO -POV Comments | AD1: Comments | AE1: QA Comments
A2: 1 | B2: Donor Wave | C2: 46121 | D2: 46135 | E2: OB-OP 8.6 Sprint 2 | F2: Saranya | G2: DON-344 | H2: Manual Address Entry Fix | I2: Completed | J2: 3 | K2: 3 | M2: 46122 | N2: 46129 | O2: Done | P2: Murugesan .M | Q2: 1]Add address text and font size and color code should match with Figma 2]City input fields should accept only 50 chrs | R2: Arivu | S2: Nil | T2: https://dev.azure.com/greatergiving/Greater%20Giving/_git/Donor/pullrequest/9474 | U2: 46127 | V2: 46129 | W2: Rajesh | X2: Nil | Y2: Joe | Z2: 46129 | AA2: Nil | AB2: Nil | AC2: Nil | AD2: 4/10/2026 -Anaylyzing story 4/13/2026 - Start the development 4/14/2026 - implemented the add address manually functionality 4/15/2026 - code refactoring and unit testing 4/16/2026 -working on review comments | AE2: 4/10/2026 -Completed analysis 4/13/2026-Test Scenario Preparations 4/16/2026- Did first round of testing 4/17/2026 - Completed testing and prepared Validation document
A3: 2 | B3: Donor Wave | C3: 46121 | D3: 46135 | E3: OB-OP 8.6 Sprint 2 | F3: Kannan/ Ubhai | G3: DON-341 | H3: Donor - SNYK Remediation | I3: Completed | J3: 3 | K3: 3 | M3: 46122 | N3: 46125 | O3: Done | P3: Murugesan .M | Q3: Nil | R3: Irsath | S3: Nil | T3: Pull Request 9461: [DON-341] Donor - SNYK Remediation | U3: 46125 | V3: 46125 | W3: Rajesh | X3: Nil | Y3: Joe | Z3: 46125 | AA3: Nil | AB3: Nil | AC3: Nil | AD3: 4/10/2026 -Anaylyzing story 4/13/2026 - Start the development and created PR | AE3: 4/10/2026 -Completed analysis 4/13/2026 -Completed Regression Testing in local branch 4/14/2026 -Completed Regression Testing in Develop branch
A4: 3 | B4: Donor Wave | C4: 46121 | D4: 46135 | E4: OB-OP 8.6 Sprint 2 | F4: Arivalagan | G4: DON-130 | H4: Integrate login flow to Checkout | I4: Completed | J4: 5 | K4: 5 | M4: 46122 | N4: 46135 | O4: Done | P4: Murugesan .M | Q4: 1]Credit card payment is not working and gets failed in checkout flow | R4: Kannan | S4: Nil | T4: https://dev.azure.com/greatergiving/Greater%20Giving/_git/Donor/pullrequest/9470 | U4: 46127 | V4: 46135 | W4: Rajesh | X4: Nil | Y4: Joe | Z4: 46135 | AA4: Nil | AB4: Nil | AC4: Nil | AD4: 4/10/2026 -Integrate the API and started the development 4/13/2026-Authentication on checkout api 4/14/2026-implement the front end code functionality 4/15/2026-Unit testing 4/16/2026- Added project key functionaltiy 4/17/2026-Fixed design changes 4/20/2026-Added Project key functionaltiy 4/21/2026-Code refactoring 4/22/2026-Code refactoring and Bidder key implementation 4/23/2026-Unit testing | AE4: 4/10/2026 -Completed analysis 4/13/2026-Test Scenario Preparations 4/16/2026- Completed first round of testing 4/17/2026 - retested after changes and raised an observation 4/21/2026-Retested the changes 4/22/2026-Retested the changes
A5: 4 | B5: Donor Wave | C5: 46121 | D5: 46135 | E5: OB-OP 8.6 Sprint 2 - [Stretch] | F5: Irsath | G5: DON-348 | H5: Donor b2c Styling Update | I5: Being Developed | J5: 2 | M5: 46125 | N5: 46128 | O5: Done | P5: Murugesan .M | Q5: Nil | R5: Ubaithullah | S5: Nil | T5: https://dev.azure.com/greatergiving/Greater%20Giving/_git/Donor/pullrequest/9479 | U5: 46128 | W5: Rajesh | X5: Nil | Y5: Joe | AB5: Nil | AC5: Nil | AD5: 4/13/2026 - Analysis done started development 4/14/2026 - Development completed 4/15/2026 - New Requirement has been added working on that 4/16/2026 - Development and unit testing has been completed 4/21/2026 - New Requirement has been added and completed. | AE5: 4/13/2026-Completed analysis and Test Scenario Preparations 4/15/2026- Completed testing and prepared Validation document 4/21/2026- Did tetsting the flows in Dev Env
A6: 5 | B6: Donor Wave | C6: 46121 | D6: 46135 | E6: OB-OP 8.6 Sprint 2 - [Stretch] | F6: Kannan | G6: DON-191 | H6: Cookie Based Session Management Migration | I6: Completed | J6: 1 | K6: 1 | M6: 46126 | N6: 46127 | O6: Done | P6: Murugesan .M | Q6: 1] Showing 401 unauthorized error msg after clicking in B2c sign in button from login page | R6: Ubaithullah | S6: Nil | T6: Pull Request 9476: [DON-191] Cookie Based Session Management Migration | U6: 46127 | V6: 46129 | W6: Rajesh | X6: Nil | Y6: Joe | Z6: 46129 | AA6: Nil | AB6: Nil | AC6: Nil | AD6: 4/14/2026 - Analysis done started development 4/15/2026 - Development done and PR created | AE6: 4/14/2026 -did Regression Testing in local branch 4/15/2026- Completed Retesting after package updates
A7: 6 | B7: Donor Wave | C7: 46121 | D7: 46135 | E7: OB-OP 8.6 Sprint 2 - [Stretch] | F7: Ubaithullah | G7: DON-349 | H7: Remove b2c Dev Backdoor | I7: Completed | J7: 2 | K7: 2 | M7: 46126 | N7: 46127 | O7: Done | P7: Murugesan .M | Q7: Nil | R7: Kannan | S7: Nil | T7: https://dev.azure.com/greatergiving/Greater%20Giving/_git/Donor/pullrequest/9420 | U7: 46127 | V7: 46127 | W7: Rajesh | X7: Nil | Y7: Joe | Z7: 46127 | AA7: Nil | AB7: Nil | AC7: Nil | AD7: 4/14/2026 - Analysis and development completed 4/15/2026 - Testing Completed PR created | AE7: 4/14/2026 -did Regression Testing in local branch
A8: 7 | B8: Donor Wave | C8: 46121 | D8: 46135 | E8: OB-OP 8.6 Sprint 2 - [Stretch] | F8: Ubaithullah | G8: DON-352 | H8: Fix User Logout | I8: Completed | J8: 1 | K8: 1 | M8: 46128 | N8: 46130 | O8: Done | P8: Murugesan .M | Q8: Nil | R8: Kannan | S8: Nil | T8: https://dev.azure.com/greatergiving/Greater%20Giving/_git/Donor/pullrequest/9483 | U8: 46129 | V8: 46132 | W8: Rajesh | X8: Nil | Y8: Joe | Z8: 46132 | AA8: Nil | AB8: Nil | AC8: Nil | AD8: 4/16/2026 - Anlaysis completed and development started 4/18/2026 - Raised PR | AE8: 4/17/2026 - Analyzed the story and prepared Test Preparation 4/20/2026 - Performed Testing and prepared Validation doc
A9: 8 | B9: Donor Wave | C9: 46121 | D9: 46135 | E9: OB-OP 8.6 Sprint 2 | F9: Kannan/Irsath | G9: DON-347 | H9: Donor Environment Configuration | I9: Completed | J9: 2 | K9: 2 | M9: 46127 | N9: 46128 | O9: Done | P9: Murugesan .M | Q9: Nil | R9: Ubaithullah | S9: Nil | T9: Pull Request 9477: [DON-347] Angular version (21.2.0) update | U9: 46127 | V9: 46128 | W9: Rajesh | X9: Nil | Y9: Joe | Z9: 46128 | AA9: Nil | AB9: Nil | AC9: Nil | AD9: 4/15/2026 - Updated packages and PR created 4/16/2026 - Requested one more package update and its updated today 4/17/2026 - Worked on Database timeout issue
A10: 9 | B10: Donor Wave | C10: 46121 | D10: 46135 | E10: OB-OP 8.6 Sprint 2 - [Stretch] | F10: Kannan | G10: DON-353 | H10: Correlate Project Key to Signin/ Signup | I10: Being Developed | J10: 3 | M10: 46129 | AD10: 4/17/2026 Started analysis [Note]: Waiting for story point | AE10: 4/21/2026- did first round of testing
A11: 10 | B11: Donor Wave | C11: 46121 | D11: 46135 | E11: OB-OP 8.6 Sprint 2 - [Stretch] | F11: Irsath | G11: DON-354 | H11: Remove Password Requirement for Legacy Login | I11: Completed | J11: 1 | K11: 1 | M11: 46132 | N11: 46132 | O11: Done | P11: Murugesan .M | Q11: Nil | R11: Ubaithullah | S11: Nil | T11: https://dev.azure.com/greatergiving/Greater%20Giving/_git/Donor/pullrequest/9488 | U11: 46132 | V11: 46132 | W11: Rajesh | X11: Nil | Y11: Joe | Z11: 46134 | AA11: Nil | AB11: Nil | AC11: Nil | AD11: 4/20/2026 - Development has been completed and PR has been created
A12: 11 | B12: Donor Wave | C12: 46121 | D12: 46135 | E12: OB-OP 8.6 Sprint 2 - [Stretch] | F12: Saranya | G12: DON-351 | H12: Donor Maintenance Notifications | I12: Being Developed | J12: 3 | M12: 46134 | AD12: 4/22/2026 - Analysis completed 4/22/2026 - start the development 4/23/2026 - implemented the functionality

Sheet OB-OP 8.6.0 Sprint 2-Defect
A1: S.No | B1: Sprint | C1: Story/Defect ID | D1: Parent Story | E1: Developer | F1: Issue Type | G1: Issue Description | H1: Priority | I1: Defect Source | J1: Type | K1: Status | L1: Root Cause Category | M1: Comments | N1: Found By | O1: RCA Comment

Sheet OB-OP 8.6.0 Sprint 1-Status
A1: S.No | B1: Application Name | C1: Sprint Start Date | D1: Sprint End Date | E1: Sprint | F1: Developer | G1: Story ID/Defect ID | H1: Description | I1: Status | J1: Estimated(hrs/sp) | K1: Actual(hrs/sp) | L1: Actual Hours Worklog | M1: Dev Start Date | N1: Dev End Date | O1: Unit testing | P1: Peer Tested By | Q1: Peer Tested Defects, if any | R1: Peer Reviewed By | S1: Peer Code Review Comments, if any | T1: PR Number/Link | U1: PR Created Date | V1: PR Approved Date | W1: Onsite Lead Code Review | X1: Code Review Comments, if any | Y1: Client Code Review | Z1: Approved Date | AA1: Code Review Comments, if any2 | AB1: Internal PO -POV Comments | AC1: Client PO -POV Comments | AD1: Comments | AE1: QA Comments
A2: 1 | B2: Donor Wave | C2: 46107 | D2: 46121 | E2: OB-OP 8.6 Sprint 1 | F2: Irsath | G2: Don-333 | H2: Fix Payment Component | I2: Completed | J2: 2 | K2: 2 | L2: 48.75 | M2: 46108 | N2: 46112 | O2: Done | P2: Murugesan .M | Q2: 1.Amex card is not adding into donor platform , showing 'Failed to add credit card accountId : 757' 2.Visa card is not adding into donor platform , showing 'Failed to add credit card accountId : 757' | R2: Arivalagan | S2: Nil | T2: https://dev.azure.com/greatergiving/Greater%20Giving/_git/Donor/pullrequest/9415 | U2: 46118 | V2: 46120 | W2: Rajesh | X2: Nil | Y2: Joe | Z2: 46120 | AA2: Nil | AB2: Nil | AC2: Nil | AD2: 3/27/2026 - Analysis done started development 3/30/2026 - I have found few GDon API side issue during save credit card 3/31/2026 - Postal code issue has been fixed 4/6/2026 - Need to verify with different cards today, once murugesan confirms, will share the PR to Rajesh today 4/7/2026 - secret key needs to be changed in joe's machine - after that only he can test in his local, so pending for that | AE2: 03/27/2026 - Completed analysis and started test scenraios 4/1/2026 -Testing is in progress 4/3/2026 -Retested the fixes and completed testing 4/9/2026 -Regression testing on Develop branch
A3: 2 | B3: Donor Wave | C3: 46107 | D3: 46121 | E3: OB-OP 8.6 Sprint 1 | F3: Kannan | G3: DON-336 | H3: Household - Front End | I3: Completed | J3: 2 | K3: 2 | L3: 28.75 | M3: 46108 | N3: 46112 | O3: Done | P3: Murugesan .M | Q3: 1.Email should be displayed in the household section 2.Dot should be displayed as it is in the attached ref ticket 3.House hold inside data icon should be aligned with section round icon - pls ref below screenshot . [ currently it shows bit right side ] 4.Title should be Partner/Spouse . currently the title shows only spouse in the UI | R3: Ubai | S3: Nil | T3: Pull Request 9416: DON-336 Household - Front End | U3: 46112 | V3: 46120 | W3: Rajesh | X3: Nil | Y3: Joe | Z3: 46120 | AA3: Log the exception with account Id. Do not bubble the accountId in the exception revealing it | AB3: Nil | AC3: Nil | AD3: 3/27/2026 - Analysis started still waiting for the full flow requirement 3/30/2026 - Development completed based on API. Expecting minor when GDON API team implementing this feature 03/31/2026 - PR Created 4/6/2026 - Pending with Prabu approval, rajesh might review today and share to Joe 4/7/2026 - need to take latest develop and resolve conflicts and test once since many PRs went yesterday | AE3: 03/27/2026 - Completed analysis and started test scenraios 4/1/2026 -Completed one round of testing and shared the observations 4/6/2026 - Completed testing and Prepared validation doc 4/8/2026 -Regression testing on Develop branch
A4: 3 | B4: Donor Wave | C4: 46107 | D4: 46121 | E4: OB-OP 8.6 Sprint 1 | F4: saranya | G4: DON-316 | H4: Checkout - Implement Error banners | I4: Completed | J4: 2 | K4: 2 | L4: 67.35 | M4: 46108 | N4: 46108 | O4: Done | P4: Murugesan .M | Q4: Nil | R4: Kannan | S4: Nil | T4: https://dev.azure.com/greatergiving/Greater%20Giving/_git/Donor/pullrequest/9408 | U4: 46108 | V4: 46120 | W4: Rajesh | X4: Nil | Y4: Joe | Z4: 46120 | AA4: Nil | AB4: Nil | AC4: Nil | AD4: 3/27/2026 -Code refactoring and unit testing 4/2/2026 - code refactoring merge with DON-321 branch 4/3/2026 -merge with develop branch 4/6/2026 - Prabu approved the PR on friday, waiting for Joe's approval 4/7/2026 - Having conflict because of recent PR completion, mock data suggestion given by joe, need to implement that | AE4: 4/1/2026 -Completed one round of testing 4/3/2026 - Completed testing and Prepared validation doc 4/7/2026 -Regression testing in Local 4/8/2026 -Regression testing on Develop branch
A5: 4 | B5: Donor Wave | C5: 46107 | D5: 46121 | E5: OB-OP 8.6 Sprint 1 | F5: Ubaithullah | G5: DON-337 | H5: Household - Backend | I5: Completed | J5: 3 | K5: 3 | L5: 39.75 | M5: 46108 | N5: 46118 | O5: Done | P5: Murugesan .M | Q5: Nil | R5: Kannan | S5: Nil | T5: https://dev.azure.com/greatergiving/Greater%20Giving/_git/Donor/pullrequest/9417 | U5: 46112 | V5: 46119 | W5: Rajesh | X5: Nil | Y5: Joe | Z5: 46119 | AA5: Nil | AB5: Nil | AC5: Nil | AD5: 3/27/2026 - Checked with GDON team need to discuss with prabhu 3/30/2026 - Development and unit testing completed 3/31/2026 - Code Refactored and PR created 4/6/2026 - Pending with Prabu approval, rajesh might review today and share to Joe | AE5: 03/27/2026 - Completed analysis and started test scenraios 4/1/2026 -Completed testing and Prepared validation doc
A6: 5 | B6: Donor Wave | C6: 46107 | D6: 46121 | E6: OB-OP 8.6 Sprint 1 | F6: Arivalagan | G6: DON-317 | H6: Checkout-Header | I6: Completed | J6: 3 | K6: 3 | L6: 83.3 | M6: 46108 | N6: 46112 | O6: Done | P6: Murugesan .M | Q6: 1]Home text should be displayed instead of checkout while clicking back option in edit profile page 2]User should not be redirected to check out page after updating the edit profile , should go to home page after updating the profile. 3]G icon should display instead of greater giving text in the left header page for mobile landscape 4]Adding profile image is not updating in the user profile initials while editing profile | R6: Saranya | S6: Nil | T6: https://dev.azure.com/greatergiving/Greater%20Giving/_git/Donor/pullrequest/9420 | U6: 46112 | V6: 46120 | W6: Rajesh | X6: Nil | Y6: Joe | Z6: 46120 | AA6: Let's correct this string interpolation for Angular's binding system while we're in here. We miss this sometimes. | AB6: Nil | AC6: Nil | AD6: 3/27/2026-Analysis and started the development 3/30/2026-Completed logout and edit profile functionaltiy 3/31/2026 - Code refactored and Project key functionatliy is implemented 4/1/2026 - Code refactored and functionality testing 4/2/2026 -Code merged with DON-316 and fixed some functionality 4/7/2026 - many code changes related to other branches are in the PR, need to take latest develop and resolve conflict and test again 4/8/2026-Review comments fixed | AE6: 03/27/2026 - Completed analysis and started test scenraios 4/1/2026 -Testing is in progress 4/02/2026 - Completed testing and Prepared validation doc 4/7/2026 -Regression testing in Local 4/8/2026 -Regression testing on Develop branch
A7: 6 | B7: Donor Wave | C7: 46107 | D7: 46121 | E7: OB-OP 8.6 Sprint 1 | F7: saranya | G7: DON-335 | H7: Update Payment Receipt Call | I7: Completed | J7: 1 | K7: 1 | L7: 21.3 | M7: 46108 | N7: 46115 | O7: Done | P7: Murugesan .M | Q7: 1.Json reader exception is thrown while clicking on download receipt in the checkout page. - Report GUIID shows undefined when debugging it. | R7: Arivalagan | S7: Nil | T7: https://dev.azure.com/greatergiving/Greater%20Giving/_git/Donor/pullrequest/9434 | U7: 46115 | V7: 46118 | W7: Prabu | X7: Nil | Y7: Joe | Z7: 46118 | AA7: Nil | AB7: Nil | AC7: Nil | AD7: 3/27/2026 -Disscuss with GDON team 4/2/2026 - changed receipt generate values 4/3/2026 -unit testing and merge with develop branch 4/6/2026 - Prabu approved the PR on friday, waiting for Joe's approval | AE7: 03/27/2026 - Completed analysis and started test scenraios 4/3/2026 -Retested the fixes and Completed testing and Prepared validation doc
A8: 7 | B8: Donor Wave | C8: 46107 | D8: 46121 | E8: OB-OP 8.6 Sprint 1 | F8: Kannan/ Ubhai | G8: DON-321 | H8: Add Cancellation Token and Size Constraints to Download Feature | I8: Completed | J8: 2 | K8: 2 | L8: 31 | M8: 46119 | N8: 46119 | O8: Done | P8: Murugesan .M | Q8: Nil | R8: Ubai/Kannan | S8: Nil | T8: Pull Request 9396: DON-321 Add Cancellation Token and Size Constraints to Download Feature | U8: 46108 | V8: 46120 | W8: Prabu | X8: Nil | Y8: Joe | Z8: 46120 | AA8: Nil | AB8: Nil | AC8: Nil | AD8: PR Created last sprint itself waiting for Prabhu and Joe review. If any obervation from them, will work on it. Prabu approved, waiting for Joe's approval - 4/6/2026 PR suggestion branch came from joe - need to check that and update whichever is necessary - 4/7/2026 | AE8: 4/7/2026 -Regression testing in Local 4/8/2026 -Regression testing on Develop branch
A9: 8 | B9: Donor Wave | C9: 46107 | D9: 46121 | E9: OB-OP 8.6 Sprint 1 - [Stretch] | F9: Irsath | G9: DON-338 | H9: Update automapper | I9: Completed | J9: 1 | K9: 1 | L9: 11.5 | M9: 46114 | N9: 46114 | O9: Done | P9: Murugesan .M | Q9: Nil | R9: Kannan | S9: Nil | T9: https://dev.azure.com/greatergiving/Greater%20Giving/_git/Donor/pullrequest/9432 | U9: 46115 | V9: 46119 | W9: Prabu | X9: Nil | Y9: Joe | Z9: 46118 | AA9: Nil | AB9: Nil | AC9: Nil | AD9: 4/2/2026 - Development completed 4/3/2026 - Given for PR 4/6/2026 - Prabu approved the PR on friday, waiting for Joe's approval | AE9: 4/6/2026- regression testing in Local
A10: 9 | B10: Donor Wave | C10: 46107 | D10: 46121 | E10: OB-OP 8.6 Sprint 1 | F10: Ubaithullah | G10: DON-334 | H10: Migration script for CC types | I10: Completed | J10: 1 | K10: 1 | L10: 7 | M10: 46114 | N10: 46114 | O10: Done | P10: Murugesan .M | Q10: Nil | R10: Kannan | S10: Nil | T10: https://dev.azure.com/greatergiving/Greater%20Giving/_git/Donor/pullrequest/9427 | U10: 46114 | V10: 46119 | W10: Rajesh | X10: Nil | Y10: Joe | Z10: 46119 | AA10: Nil | AB10: Nil | AC10: Nil | AD10: 4/2/2026 - Development and unit testing completed, PR raised 4/7/2026 - Implemented the suggestions given by Rajesh, took latest develop and resolved conflicts, will be sharing the PR tonight | AE10: 4/02/2026 - Completed testing and Prepared validation doc
A11: 10 | B11: Donor Wave | C11: 46107 | D11: 46121 | E11: OB-OP 8.6 Sprint 1 - [Stretch] | F11: Kannan/ Ubhai /Irsath | G11: DON-340 | H11: Dev, TST, CRT environmental setup | I11: Completed | J11: 3 | K11: 3 | L11: 67.25 | M11: 46115 | N11: 46120 | O11: Done | P11: Murugesan .M | Q11: 1.Application is not loading due to HouseholdRepository service is missed in the service | R11: Saranya/Arivu | S11: Nil | T11: Pull Request 9448: [DON-340] Dev, TST, CRT environmental setup | U11: 46120 | V11: 46120 | W11: Rajesh | X11: Nil | Y11: Joe | Z11: 46120 | AA11: Nil | AB11: Nil | AC11: Nil | AD11: 4/3/2026 - Analysis done started development 4/6/2026 - Code comments and removed logs which are not needed (API end) 4/8/2026 - Code comments and created PR | AE11: 4/8/2026 -Regresstion testing on Develop branch
A12: 11 | B12: Donor Wave | C12: 46107 | D12: 46121 | E12: OB-OP 8.6 Sprint 1 - [Stretch] | F12: Arivalagan/Saranya | G12: DON-130 | H12: Integrate login flow to Checkout | I12: Being Developed | J12: 5 | L12: 22 | M12: 46118 | AD12: 4/6/2026-Analysis and started the development 4/9/2026-Code impelementation

Sheet OB-OP 8.6.0 Sprint 1-Defect
A1: S.No | B1: Sprint | C1: Story/Defect ID | D1: Parent Story | E1: Developer | F1: Issue Type | G1: Issue Description | H1: Priority | I1: Defect Source | J1: Type | K1: Status | L1: Root Cause Category | M1: Comments | N1: Found By | O1: RCA Comment

Sheet OB-OP 8.5 Sprint 4-Status
A1: S.No | B1: Application Name | C1: Sprint Start Date | D1: Sprint End Date | E1: Sprint | F1: Developer | G1: Story ID/Defect ID | H1: Description | I1: Status | J1: Estimated(hrs/sp) | K1: Actual(hrs/sp) | L1: Actual Hours Worklog | M1: Dev Start Date | N1: Dev End Date | O1: Unit testing | P1: Peer Tested By | Q1: Peer Tested Defects, if any | R1: Peer Reviewed By | S1: Peer Code Review Comments, if any | T1: PR Number/Link | U1: PR Created Date | V1: PR Approved Date | W1: Onsite Lead Code Review | X1: Code Review Comments, if any | Y1: Client Code Review | Z1: Approved Date | AA1: Code Review Comments, if any2 | AB1: Internal PO -POV Comments | AC1: Client PO -POV Comments | AD1: Comments | AE1: QA Comments
