Workbook

Sheet Dashboard
A1: Current Sprint | B1: {=INDEX($B$2:$B$101,MATCH(1,(($D$2:$D$101 >=TODAY())*($C$2:$C$101<=TODAY())),0))} -> 26.06 Sprint 2 | C1: Current Sprint Sheet | D1: =CONCATENATE(B1,"-Status") -> 26.06 Sprint 2-Status | E1: Sprint Start Date | F1: =VLOOKUP($B$1,$B$3:$C$101,2,FALSE) -> 46148 | G1: Sprint End Date | H1: =VLOOKUP($B$1,$B$3:$D$101,3,FALSE) -> 46161 | I1: Application Name | J1: MSB Accounting | K1: Users | L1: karthikeyan.ganesan@relevantz.com;abdulqadir.varawala@relevantz.com;pramod.korikkar@relevantz.com;rijo.ponthekkan@relevantz.com;sowjanya.krishnamoorthy@relevantz.com | M1: Teams Name(GP-MSB.Accounting) | N1: 19:8a9b6ea893c94a118cce0008488fa0fd@thread.v2
A2: Current Sprint | B2: Sprint # | C2: Sprint Start Date | D2: Sprint End Date | E2: Assigned | F2: Completed | G2: Story points introduced/removed | H2: Sprint Summary | I2: Accomplishments | J2: Remarks | K2: Retro Points (Internal & External) | L2: Planned Leaves | M2: Total Leaves | N2: Data sanity Audit Status | O2: AuditDate | P2: Backlog Health
A3: =IF(AND($D$1>=C3,$D$1<=D3),"CurrentSprint","NA") -> NA | B3: 13.5 Sprint 2 | C3: 45294 | D3: 45307 | E3: 22 | F3: 19 | G3: 0 | J3: Risks / Challenges 3 Escalations introduced. | K3: Internal: External:
A4: =IF(AND($D$1>=C4,$D$1<=D4),"CurrentSprint","NA") -> NA | B4: 13.5 Sprint 3 | C4: 45308 | D4: 45321 | E4: 21.5 | F4: 18.5 | G4: 3 - OnHold | J4: Escalations - 5 (29.75hrs) Defect 22651 (Misc Bank Charge Debit…) - Needed further PO research Regression Sprint. | K4: Internal: External:
A5: =IF(AND($D$1>=C5,$D$1<=D5),"CurrentSprint","NA") -> NA | B5: 13.6 Sprint 1 | C5: 45322 | D5: 45335 | E5: 22 | F5: 17 | G5: 0 | J5: 34016 - Bounceback reported , Last day of sprint was when BB identified. QA identified, this was not introduced new , but an existing prod defect still a blocker for the story completion.Retro Comments : | K5: Internal: External:
A6: =IF(AND($D$1>=C6,$D$1<=D6),"CurrentSprint","NA") -> NA | B6: 13.6 Sprint 2 | C6: 45336 | D6: 45349 | E6: 31 | F6: 19 | G6: 8 - On hold 6 - Testing 2- Introduced and completed. | J6: 5 Stories assigned during Start of the sprint. Risks / Challenges - 2 Escalations introduced and closed. Found additional issues with the Year End Process affecting 2 defects. Defects put on hold until analysis is completed. | K6: Internal: External:
A7: =IF(AND($D$1>=C7,$D$1<=D7),"CurrentSprint","NA") -> NA | B7: 13.6. Sprint 3 | C7: 45350 | D7: 45363 | E7: 27 | F7: 27 | G7: 0 | J7: Risks and Challenges: 4 escalations, 2 Defects found during regression. Completed all items assigned including the defects found from regression. | K7: Internal: External:
A8: =IF(AND($D$1>=C8,$D$1<=D8),"CurrentSprint","NA") -> NA | B8: 13.7. Sprint 1 | C8: 45364 | D8: 45377 | E8: 33 | F8: 31 | G8: 0 | J8: Risks and Challenges: 4 Escalations - 3 Bluebear, 1 Accounting. Lost DB access for 2 days - Affected closing stories earlier. Dev Testing Setup - Linking new schools with MSB. | K8: Internal: External:
A9: =IF(AND($D$1>=C9,$D$1<=D9),"CurrentSprint","NA") -> NA | B9: 13.7. Sprint 2 | C9: 45378 | D9: 45391 | E9: 30 | F9: 20 | G9: 0 | J9: 3 Stories got carried. (1 - Deployment delay from Client side, 2 - Development Inprogress) Client side Developer left in the beginning of the sprint. | K9: Internal: External:
A10: =IF(AND($D$1>=C10,$D$1<=D10),"CurrentSprint","NA") -> NA | B10: 13.7 Sprint 3 | C10: 45392 | D10: 45405 | E10: 19 | F10: 19 | G10: 0 | J10: Carried Stories completed. 4 sp were being worked by Michael, blocked because of need to coordinate more with platOps. Capturing only Relevantz SP's from this sprint onwards. | K10: Internal: External:
A11: =IF(AND($D$1>=C11,$D$1<=D11),"CurrentSprint","NA") -> NA | B11: 13.8. Sprint 1 | C11: 45406 | D11: 45419 | E11: 16 | F11: 11 | G11: 5sp-Testing , 5sp- In Development 3- Escalations Closed. 2 - Escalations in Progress 1- Defect Fixed. 1- Defect Identified for backlog. | J11: Found Defects during Smoke Testing 5 Escalations related to Accounting. Deployed Application to Production with ABP Upgrades (3.0 to 9.0) | K11: Internal: External:
A12: =IF(AND($D$1>=C12,$D$1<=D12),"CurrentSprint","NA") -> NA | B12: 13.8. Sprint 2 | C12: 45420 | D12: 45433 | E12: 20 | F12: 17 | G12: 3 new stories introduced and completed. | J12: 3 Sp in dev. | K12: Internal: External:
A13: =IF(AND($D$1>=C13,$D$1<=D13),"CurrentSprint","NA") -> NA | B13: 13.8. Sprint 3 | C13: 45434 | D13: 45447 | E13: 21 | F13: 17 | J13: 4 sp missed because of a story in testing was dependant on stretch item to be completed. | K13: Internal: External:
A14: =IF(AND($D$1>=C14,$D$1<=D14),"CurrentSprint","NA") -> NA | B14: 13.8. Sprint 4 | C14: 45448 | D14: 45461 | E14: 19 | F14: 12 | J14: 5sp was in progress. 3 sp dependant on the 5 sp story. Reforecast was sent out mid sprint changing priorities from a Regression to a development sprint. | K14: Internal: External:
A15: =IF(AND($D$1>=C15,$D$1<=D15),"CurrentSprint","NA") -> NA | B15: 13.8. Sprint 5 | C15: 45462 | D15: 45475 | E15: 16 | F15: 3 | J15: 13 sp Story got carried - Identified more difference in source data during Data fix. | K15: Internal: External:
A16: =IF(AND($D$1>=C16,$D$1<=D16),"CurrentSprint","NA") -> NA | B16: 13.8. Sprint 6 | C16: 45476 | D16: 45489 | E16: 18 | F16: 13 | J16: Major focus on the update Scripts for the Beginning Balance. 5 sp wasnt worked on at all as we had depdendencies on other stories 2 sp is a defect which is also a dependency. 10 sp was marked completed and pivoted into a new story. | K16: Internal: External:
A17: =IF(AND($D$1>=C17,$D$1<=D17),"CurrentSprint","NA") -> NA | B17: 13.8 Sprint 7 | C17: 45490 | D17: 45503 | E17: 32 | F17: 3 | K17: Internal: External:
A18: =IF(AND($D$1>=C18,$D$1<=D18),"CurrentSprint","NA") -> NA | B18: 13.8 Sprint 8 | C18: 45504 | D18: 45517 | E18: 17 | F18: 17 | K18: Internal: External:
A19: =IF(AND($D$1>=C19,$D$1<=D19),"CurrentSprint","NA") -> NA | B19: 14.1 Sprint 1 | C19: 45518 | D19: 45531 | E19: 10 | F19: 10 | J19: Started Working on Stretch items as part of the sprint. Pulled in a epic. | K19: Internal: External:
A20: =IF(AND($D$1>=C20,$D$1<=D20),"CurrentSprint","NA") -> NA | B20: 14.1 Sprint 2 | C20: 45532 | D20: 45545 | E20: 23 | F20: 10 | J20: Missed 13 sp because we couldnt completed regression in time because we had blocking items to complete | K20: Internal: External:
A21: =IF(AND($D$1>=C21,$D$1<=D21),"CurrentSprint","NA") -> NA | B21: 14.1 Sprint 3 | C21: 45546 | D21: 45559 | E21: 24 | F21: 21 | J21: 3 SP was in POV, dev completed but can't test now since we have a dependancy on other item. 26-Sep-24: CRC Peer - 0, Onsite - 0, Client - 0. Internal Defect - 3, External Defect - 0. | K21: Internal: External: | N21: Completed
A22: =IF(AND($D$1>=C22,$D$1<=D22),"CurrentSprint","NA") -> NA | B22: 14.2 Sprint 1 | C22: 45560 | D22: 45573 | E22: 15 | F22: 10 | G22: Introduced - 8 sp | K22: Internal: External:
A23: =IF(AND($D$1>=C23,$D$1<=D23),"CurrentSprint","NA") -> NA | B23: 14.2 Sprint 2 | C23: 45574 | D23: 45587 | E23: 28 | F23: 20 | J23: 8 sp - Detailed Accounting Analysis required | K23: Internal: External:
A24: =IF(AND($D$1>=C24,$D$1<=D24),"CurrentSprint","NA") -> NA | B24: 14.2 Sprint 3 | C24: 45588 | D24: 45601 | E24: 24 | F24: 13 | J24: 5sp - Accounting Data investigation. 8sp - Changes to the story late in the sprint. | K24: Internal: External:
A25: =IF(AND($D$1>=C25,$D$1<=D25),"CurrentSprint","NA") -> NA | B25: 14.3 Sprint 1 | C25: 45602 | D25: 45615 | E25: 14 | F25: 14 | I25: Completed new implementation approach for MSB batch import changes, added UI for associating schools to MSB Gateways, added automation tests | J25: 8 sp worked on by OnSite Dev (which is in Testing) CRC Peer - 0, Onsite - 0, Client - 0. Internal Defect - 1, External Defect - 4. | K25: Internal: Great job done by Rijo and Karthik in getting the MSB batch Import new design changes External: Appreciation recieved from Michael Rose for Sushmitha on her automation activities, from Sarah to Qadir for closing escalation with fix, from Michael Rose to Rijo and Karthik for MSB Batch Import new changes
A26: =IF(AND($D$1>=C26,$D$1<=D26),"CurrentSprint","NA") -> NA | B26: 14.3 Sprint 2 | C26: 45616 | D26: 45629 | E26: 16 | F26: 11 | I26: Import from MSB defects fixes​ Macroscope remediation​ Import from MSB redesign data scripts and UI story​ Identified the Root cause of missing installment payments In import From MSB | J26: 5 sp missed because the fix for the escalation defect is dependant on changes made in 46200 whcih is a stretch item still in progress. CRC Peer - , Onsite - , Client - . Internal Defect - , External Defect - . | K26: Internal: External:
A27: =IF(AND($D$1>=C27,$D$1<=D27),"CurrentSprint","NA") -> NA | B27: 14.3 Sprint 3 | C27: 45630 | D27: 45643 | E27: 17 | F27: 9 (Completed -17.7) | G27: Introduced Stretch - 8.7 (Completed) | I27: Macroscope remediation​ Import from MSB redesign completed, BrowserStack Integration for automated Tests Issues with Installment Payments / Refunds fixed. | J27: Commit Story - 8 is in progress 8 sp in Client POV before we create the PR, and Test. We found some additional work to be done for this story to manage existing data, so when we deploy , this scenario works seamlessly. CRC Peer - 0 , Onsite - 0, Client - 0 . Internal Defect - 1, External Defect - 1. | K27: Internal:Sushmita - Testing and Working On Automation Test Cases - Qadir External: 1) Sushmitha doing so well with both manual & Automation testing efforts - Michael Rose 2) Pramod - thanks for always being willing to roll with new processes and for all the great discussions on our upcoming work! - Sarah
A28: =IF(AND($D$1>=C28,$D$1<=D28),"CurrentSprint","NA") -> NA | B28: 14.4 Sprint 1 | C28: 45644 | D28: 45671 | E28: 22 | F28: 24 | I28: Shared gateway functional changes on Import from MSB. - This brings the end to the changes to ImportFromMSB. Import MSB batches - Background query changes to create batches from existing data 14.3 Regression Completed | J28: 2 sp story has been rolled over to the new sprint as a 8 sp story. We're still unsure of the reason the send email job isnt running. We've allocated more time to investigate the issue. Along the way we've found more issues on Production, which were Important to investigate to determine whether we need immediate fixes or not. CRC Peer - 0 , Onsite - 1, Client - 0. Internal Defect - 2, External Defect - 1 . What Went Well 1) Regression went relatively smoothly, with only 1 main issue. 2) We've got Import Batches now ! No more ImportFromMSB What didnt Go Well 1) Found issues in prod while researching Email Error Logs 2) Test MSB was down during holidays. 3) Possible configuration issue with gateway / not getting batch IDs. | K28: Internal : Rijo / Karthik - Great Coordination in handling the Import MSB batches. Pramod - Reminding team of using new MIDs during Regression. Sushmitha - identifying the edge cases External : Team - keeping focused on sprint goals - Michael Qadir - for taking a majority of the escalation work - Michael Qadir -Good job incorporating the new review points in the demo - Sarah
A29: =IF(AND($D$1>=C29,$D$1<=D29),"CurrentSprint","NA") -> NA | B29: 14.4 Sprint 2 | C29: 45672 | D29: 45685 | E29: 19 | F29: 23 | G29: 3 sp introduced. | I29: PROD deployment Completed. Team was quick to pivot to work on the story to hide batches as it could affect users in PROD. | J29: 3 sp from the Alpine DatePicker has been rolled over to the new sprint. We started it late in the sprint, and it was more complicated than we anticipated. We had to bring in a new story about hiding the batches once Journalled, because as part of the data fix, we had hidden them. Newly journalled batches were still being displayed. We needed to fix the inconsistency. CRC Peer - 0 , Onsite - 1, Client - 0. Internal Defect - 2, External Defect - 0 What Went Well 1) PROD deployment went well. 2) UI for the Job Queue - Will be helpful for the future. 3) Closed all items except Alpine component, completed 19 out of 19 SP including the 3 SP added later to sprint 4)Got client appreciation for Sushmitha for making progress with Automation test suite What didnt Go Well 1) Alpine Js datepicker story couldnt be completed as it was more complex than we anticipated.-3sp 2) Escalation fix got sidetracked. Defect create on it now. | K29: Internal : Sushmitha continuing the progress on the Automation
A30: =IF(AND($D$1>=C30,$D$1<=D30),"CurrentSprint","NA") -> NA | B30: 14.4 Sprint 3 | C30: 45686 | D30: 45699 | E30: 17 | F30: 22 | G30: 3 sp introduced. | I30: Regression was completed. Completed 1 story from the stretch and another from the stretch ready for POV. | J30: Missed 3 sp for the Alpine TextBoxes, Links because we had to focus on the edge case regression defects that were found with Importing batches. We completed 3 sp from the stretch as well, bringing in a new feature for Bank Deposit Summary Type setting in the School Settings . This was a story requested by Accounting Customers. CRC Peer - 0 , Onsite - 0, Client - 0. Internal Defect - 2, External Defect - 0 What Went Well 1) Regression was completed. 2) We added an additional story to the release - 23903, which was not planned. 3) Figured out the cause of the Jobs not running as per schedule in Cert and prod. 4) Karthik and Pramod got client appreciation for completing some stretch items and taking care of standups in the absense of scrum master and PO respectively. What didnt Go Well 1) Couldnt Close out Alpine Story. We were very close. 2) CERT deployment was delayed, and we missed completing one regression defect. | K30: Internal : Same as External External : Pramod for standing in For Sarah and RJ - RJ Karthik for closing out an item from stretch - James Qadir - For figuring out the issue with the job Queue.
A31: =IF(AND($D$1>=C31,$D$1<=D31),"CurrentSprint","NA") -> NA | B31: 14.5 Sprint 1 | C31: 45700 | D31: 45713 | E31: 17 | F31: 37 | I31: Deployment Completed to PROD. We pulled in 2 stories as escalations to be released as it was urgent | J31: CRC Peer - 0 , Onsite - 0, Client - 2. Bounceback -1 Internal Defect - 1, External Defect - 2 What Went Well Overall, a very good sprint. What didnt Go Well Highlighted an observeation with the client that server patch upgrade was also done during deployment causing server downtime while post deployment verification | K31: Internal : Same as External External : Team was hihgly appreciated for achieving more than the sprint commit
A32: =IF(AND($D$1>=C32,$D$1<=D32),"CurrentSprint","NA") -> NA | B32: 14.5 Sprint 2 | C32: 45714 | D32: 45727 | E32: 23 | F32: 32.5 | G32: Sprint Reforecast done - Pulled in additional 5 sp for relevantz. Pulled out 3 sp because it was blocked. Completed additional 3 Stories - 10 sp from stretch | J32: CRC Peer - 0 , Onsite - 0, Client - 1. Bounceback -0 Internal Defect - 0, External Defect - 4 What Went Well 1. Completed almost the committed SP by picking up items from stretch 2. Rijo and Karthik got client (Sarah and Qadir) appreciation for great demo and completing lots of work even with time off respectively. What didnt Go Well 2 Stories were blocked due to scrubbed prod db restoration issue on Dev server. Missed 8 SP there. | K32: Internal : Same as External External : Rijo - For explaining the context of the 3rd party fees mapping epic - great demo!
A33: =IF(AND($D$1>=C33,$D$1<=D33),"CurrentSprint","NA") -> NA | B33: 14.5 Sprint 3 | C33: 45728 | D33: 45741 | E33: 27 | F33: 34.5 | G33: We pulled in 5sp as defects we found during the sprint which should be a part of the release. | I33: Per Item Fees are now captured by MSB and now Accounting and we can see the proper total fo Tickets Products in MSB Accounting. Completed verifications for 2 districts for year end changes . | J33: CRC Peer - 1, Onsite - 0, Client - 0. Bounceback -0 Internal Defect - 1, External Defect - 3 What Went Well 1. Per item fees changes look good. 2. Nice Error Page What didnt Go Well 1 We need to break regression into smaller chunks 2 Jobs were not running on last day of sprint | K33: Internal : Same as External External : Appreciation to Sushmitha - from Wes Perkins (Client QA) for covering the QA activities while he was unable to help on testing due to issues with his laptop to the entire team - from accounting customers for good feature updates - from the MSB Accounting customer feedbacks as captured by Sarah and RJ from their "Connect Conference" with the customers to Pramod - from Michael Rose, Sarah and RJ for covering the activities for Sarah and RJ while they were absent for the team
A34: =IF(AND($D$1>=C34,$D$1<=D34),"CurrentSprint","NA") -> NA | B34: 14.6 Sprint 1 | C34: 45742 | D34: 45755 | E34: 22 | F34: 17.3 | G34: 2.25 (Defect 24968 ) | I34: Deployment Completed to PROD. 14.5 Release | J34: CRC Peer - 0, Onsite - 0, Client - 0. Bounceback -0 Internal Defect - 2, External Defect - 2 What Went Well 1) Deployment went Well 2) Identifying the underlying cases for the bank rec notification message. What didnt Go Well 1 We should have reforecast the story Rijo Was working after finding issues that we had not considered. (47244,47262,47263) | K34: Internal : Same as External External : Appreciation to Rijo - from James Varney (Client Dev) and Michael Rose for successfully leading the deployment in Qadir's absence Sushmitha and Karthik - from James Varney and Sarah for good Demo during Sprint review Karthik - from Sarah for identifying all underlying cases of bank rec completion notifications and not ending up just with a fix for the surface level defect that was reported
A35: =IF(AND($D$1>=C35,$D$1<=D35),"CurrentSprint","NA") -> NA | B35: 14.6 Sprint 2 | C35: 45756 | D35: 45769 | E35: 19 | F35: 19 | G35: None | I35: Completed the epic related to third party GL s from Msb and its mapping to Accounting, which is the major item for this release cycle. Getting started on the entire page migrations to Alpine js by the relevantz team. | J35: CRC Peer - 0, Onsite - 1, Client - 0. Bounceback -3 (2 from Client Dev) Internal Defect - 1, External Defect - 0 What Went Well 1. Completed the Epic story - 3rd party fee integration support 2. Completed all commited items. What didnt Go Well: Nil | K35: Internal : Appreciation to Sushmitha - For catching few edge cases in her QA activities Karthik - For quickly understanding the additional observation around AC points with me while my POVs and working on it Rijo - For his continuous focus and getting the first set of mapping stories done in this sprint Qadir - For syncing up with Sarah and closing the discussions for Dev team (All by Pramod) External : Sushmitha for covering all items in the absence of client QA by - Wes(Client QA) and the entire team Rijo for great demo with explanations for the Epic story - By entire team
A36: =IF(AND($D$1>=C36,$D$1<=D36),"CurrentSprint","NA") -> NA | B36: 14.6 Sprint 3 | C36: 45770 | D36: 45783 | E36: 21 | F36: 23 | G36: 2(Story 47936 re-estimated from 3 to 5 SP) | I36: Completed the fix for the GUIDs for the 3rd party fees. Regression Completed successfully. | J36: CRC Peer - 0, Onsite - 0, Client - 0. Bounceback -2 Internal Defect - 0, External Defect - 0 What Went Well 1. Completed Regression on time. 2. Completed all commited items. 3. Reforecasting our stories. What didnt Go Well: Nil | K36: Internal : Sushmitha - For her work on testing and automated Tests - Qadir/ Pramod External : Qadir - Good Review Demo - Wes / James Sushmitha - For her work on Automation - Owen Sieber Sushmitha - For testing scenarios where we found a big issue with the payment confirmation logic. - Michael Rose/ Sarah Rijo - Good Work on the GUID to String Changes and 3rd party Fees - James
A37: =IF(AND($D$1>=C37,$D$1<=D37),"CurrentSprint","NA") -> NA | B37: 14.7 Sprint 1 | C37: 45784 | D37: 45797 | E37: 22 | F37: 22 | G37: None | I37: Successful Production Deployment. Hitting our sprint targets despite some disruption with the new Synergy integration conflict and escalations | J37: CRC Peer - 0, Onsite - 0, Client - 0. Bounceback -1 Internal Defect - 2, External Defect - 1 | K37: Internal : External : Sushmitha - for catching sneaky issues in the overdraw warning - James/ Sarah / Qadir Rijo and Sushmitha -coordinating the issues on the Shared batches on Import Batches Feature - Wes /Qadir (Client QA)
A38: =IF(AND($D$1>=C38,$D$1<=D38),"CurrentSprint","NA") -> NA | B38: 14.7 Sprint 2 | C38: 45798 | D38: 45811 | E38: 24 | F38: 18 | G38: 2 (In stretch) | I38: Resolved all 3 escalations. Completed the automation test story. Completed 18 of 24 SP in spite of the issue with Dev database slowness which affected testing from this sprint. | J38: CRC Peer - 0, Onsite - 2, Client - 0. Bounceback -1 Internal Defect - 2, External Defect - 3 What went well: Completed 18 of 24 SP in spite of the issue with Dev database slowness which affected testing from this sprint. What didnt Go Well: 1) 3 Escalations 2) DEV Database slowness affected testing.on our stories. | K38: Internal : Qadir, Rijo and Karthik were focussed on getting the items completed, good progress by Sushmitha on automation - Pramod External : Sushmitha & Rijo - Good demos - James Entire team - Escalation was resolved when I got back from PTO - Sarah Pramod - covered POVs to keep things moving - Sarah
A39: =IF(AND($D$1>=C39,$D$1<=D39),"CurrentSprint","NA") -> NA | B39: 14.7 Sprint 3 | C39: 45812 | D39: 45825 | E39: 21 | F39: 31 | G39: 10 (In stretch) | I39: Got Regression Completed. HotFix Deployment went well. Get to start sprint completely fresh. | J39: CRC Peer - 0, Onsite - 0, Client - 0. Bounceback -2 Internal Defect - 3, External Defect - 2 What went well: Successful hotfix deployment and completed regression with minimal findings. What didnt Go Well: Scrubbed PROD DB Backup took some time to setup locally due to space. | K39: Internal : External : Michael Rose - Well executed sprint. I love the flexible sprint commit.
A40: =IF(AND($D$1>=C40,$D$1<=D40),"CurrentSprint","NA") -> NA | B40: 15.0 Sprint 1 | C40: 45826 | D40: 45839 | E40: 16 | F40: 8 | G40: 3 SP missed because Owen was on vacation and couldnt review. 5 SP missed because we planned 2 stories with 5 sp each which eventually needed to be completed together to release. We could have planned this better. 2 SP from stretch was blocked because we need customer confirmation | I40: Completed Production Deployment. Good Progress on Alpine Reports using Co Pilot. | J40: CRC Peer - 0, Onsite - 0, Client - 1. Bounceback -0 Internal Defect - 0 External Defect - 0 What went well: Successful Production deployment Co-Pilot Work on Alpine Reports. Continuous Progress on Automation Test Cases. What didnt Go Well: DEV and QA Sites were down for half the sprint. Work on the batches - As always we keep finding these edge case scenarios. | K40: Internal : Qadir - Sushmitha's Continous work on Automation. Pramod - Thinking ‘outside the box’ on our work & discussing scenarios / AC Pramod - Communication in the team. External : Michael Rose - Team resilience, even with PO transition. Michael Rose - Good demo on the use of Copilot by Qadir for Alpine Reports. Wes Perkins - Qadir on defect I had to test, Sushmitha for picking up while I was on vacation
...

Sheet Defect-template
A1: S.No | B1: Sprint # | C1: Story/Defect ID | D1: Parent Story | E1: Developer | F1: Issue Type | G1: Issue Description | H1: Priority | I1: Defect Source | J1: Type | K1: Status | L1: Root Cause Category | M1: Comments

Sheet 26.06 Sprint 2-Status
A1: S.No | B1: Application Name | C1: Sprint Start Date | D1: Sprint End Date | E1: Sprint | F1: Developer | G1: Story ID/Defect ID | H1: Description | I1: Status | J1: Estimated(sp) | K1: Actual(sp) | L1: Actual Hours Worklog | M1: Dev Start Date | N1: Dev End Date | O1: Unit testing | P1: Peer Tested By | Q1: Peer Tested Comments, if any | R1: Peer Reviewed By | S1: Peer Code Review Comments, if any | T1: PR Number/Link | U1: PR Created Date | V1: PR Approved Date | W1: Onsite Lead Code Review | X1: Onsite Lead Code Review Comments, if any | Y1: Client Code Review | Z1: PR Approved Date2 | AA1: Client Code Review Comments, if any | AB1: Internal PO -POV Comments | AC1: Client PO -POV Comments | AD1: Comments | AE1: Story met clarity expectations? | AF1: 46148 | AG1: 46149 | AH1: 46150 | AI1: 46153 | AJ1: 46154 | AK1: 46155 | AL1: 46156 | AM1: 46157 | AN1: 46160 | AO1: 46161
A2: 1 | B2: MSB Accounting | C2: 46148 | D2: 46161 | E2: MSB Accounting 26.06 Sprint 2 | F2: Client Dev | G2: 52474 | H2: MSB Onboarding - Complete User Experience with New Flow | I2: Story Completed | J2: 2 | AF2: Have created a bounce back for Sign & Exit | AG2: Waiting for the bounceback fix. | AH2: Waiting for the bounceback fix. | AI2: Waiting for the bounceback fix. | AJ2: Waiting for bounceback fix. | AK2: Have one doubt regarding save and exit. | AL2: Completed testing regarding save and exit. Have one more doubut, will discuss. | AM2: Completed testing and closed
A3: 2 | B3: MSB Accounting | C3: 46148 | D3: 46161 | E3: MSB Accounting 26.06 Sprint 2 | F3: Karthik | G3: 45225 | H3: MSB ACCT - BKK - Add Warnings and Blockers for Unclosed Years (26.5) | I3: Story Completed | J3: 2 | K3: 4 | L3: 16 | M3: 46150 | N3: 46150 | O3: Completed | P3: Rijo | Q3: Pass | R3: Qadir | S3: Pass | T3: https://dev.azure.com/heartlandschools/Accounting/_git/MSBAccounting-NewSchoolBooks/pullrequest/48944 | U3: 46150 | V3: 46150 | W3: Done | X3: Pass | Y3: Done | Z3: NA | AA3: Pass | AB3: Pass | AC3: Pass | AF3: Sowjanya started testing after completing test cases. 1 AC point covered. | AG3: Completed AC points. But need to validate few more things before closing. | AH3: Biunce back created - If the FY Close Warning Type is selected as “Warn Only” or “Warn and Stop Entries,” the system does not allow selecting the “Warning Date” and “New Entry Stop Date” as “0 days after fiscal year ends.” | AI3: PR for the bounce back completed. Waiting for the deployment for bb testing. | AJ3: Testing completed and Sowjanya will close this. | AK3: _
A4: 3 | B4: MSB Accounting | C4: 46148 | D4: 46161 | E4: MSB Accounting 26.06 Sprint 2 | F4: Rijo | G4: 22751 | H4: MSB ACCT - Integration - Renumber Merge deletes a mapped GL account in ImportFromMSB transaction causing error | I4: Defect Ready For Testing | J4: 5 | M4: 46148 | N4: 46150 | AF4: Completed warning part. Working on Account change. Need to do deep analysis for downstream impacts as well. | AG4: Dev and unit testing completed. Ready for POV. | AH4: POV completed with Pramod. Shared recording in the channel. And shared branch details for review. | AI4: Code review and peer testing completed by Qadir. Will be creating a PR once I get the approval from Jeanette. | AJ4: Waiting on Jeanette's approval. | AK4: Waiting on Jeanette's approval. | AL4: Waiting on Jeanette's approval. | AM4: Completed PR. Ready for testing.
A5: 4 | B5: MSB Accounting | C5: 46148 | D5: 46161 | E5: MSB Accounting 26.06 Sprint 2 Stretch | F5: Karthik | G5: 51720 | H5: MSB ACCT - BKK - Implement iTextSharpTool alternative opensource tool for report-to-PDF conversion | I5: Story Peer Review | J5: 8 | K5: 6 | L5: 24 | M5: 46148 | N5: 46154 | O5: Completed | R5: Qadir | S5: Reported a padding issue in the new version receipting PDF. | AB5: Pass | AC5: Pass | AF5: PDF changes in progress. Getting some UI alignment issues in reports. | AG5: Validating new reports with existing ones. Found 1 overlapping issue. Will be recording issues in an excel sheet. | AH5: Found 1 more UI issue and made fix. Continuing with custom template, there are 250+ templates. | AI5: Karthik PTO. | AJ5: Completed textoveralpping issue fix and POV with Pramod. | AK5: Waiting on Jeanette's approval. | AL5: Waiting on Jeanette's approval. | AM5: Jeanette added one more AC point and got 1 peer review comment from Qadir to work on.
A6: 5 | B6: MSB Accounting | C6: 46148 | D6: 46161 | E6: MSB Accounting 26.06 Sprint 2 | F6: Qadir | G6: SRX28874 | H6: MSB ACCT - Variance for second Bank Rec (Thatcher-July-BankB) | I6: Defect Being Fixed | J6: 0 | AF6: Waiting for Jeanette's approval about the fix we proposed. Made some progress with the analysis as well. | AG6: No progress. | AH6: Prod db copy restored on Dev. Will try to replicate the issue. | AI6: Not much updates. Was working on backround jobs escalations. | AJ6: Dev environment setup in progress. | AK6: No updates. Working on delayed batches escalation. | AL6: No updates. Working on delayed batches escalation. | AM6: No updates. Working on delayed batches escalation.
A7: 6 | B7: MSB Accounting | C7: 46148 | D7: 46161 | E7: MSB Accounting 26.06 Sprint 2 | F7: Qadir | G7: SRX28876 | H7: DUR - MSB ACCT - BKK - Kingsport City Schools (129907) - Dobyns-Bennett High School (DOB) | I7: Defect Being Fixed | J7: 0 | AF7: Still waiting for dev db to be restored with prod copy. Trying to use the db locally in the mean while. | AG7: No progress. Still waiting for dev db to be restored with prod copy. | AH7: Prod db copy restored on Dev. Will try to replicate the issue. | AI7: Not much updates. Was working on backround jobs escalations. | AJ7: Waiting on DBA setup. | AK7: No updates. Working on delayed batches escalation. | AL7: No updates. Working on delayed batches escalation. | AM7: Able to replicate the issue on Dev. Increasing the timeout should be the only option since it's an in-built feature.
A8: 7 | B8: MSB Accounting | C8: 46148 | D8: 46161 | E8: MSB Accounting 26.06 Sprint 2 | F8: Rijo | G8: 47478 | H8: MSB ACCT - BKK - Update Bank Deposit History Report to Reflect Changes to Import MSB Batches (26.5) | I8: Story Completed | J8: 1 | AG8: Created PR. | AH8: Deployed and ready for testing. | AI8: Being tested by client QA. | AJ8: Closed by Client QA
A9: 8 | B9: MSB Accounting | C9: 46148 | D9: 46161 | E9: MSB Accounting 26.06 Sprint 2 Stretch | F9: Rijo | G9: 47848 | H9: MSB ACCT - BKK - Rename "New Data" Feature Flag (26.5) | I9: Story Ready For Testing | J9: 3 | AG9: Will be creating PR after Qadir's review. POV already approved earlier. | AH9: Waiting for deployment. | AI9: Waiting for deployment. | AJ9: Will start testing once committed items completed. | AK9: Will start testing once committed items completed. | AL9: Will start testing once committed items completed. | AM9: Will start testing once committed items completed.
A10: 9 | B10: MSB Accounting | C10: 46148 | D10: 46161 | E10: MSB Accounting 26.06 Sprint 2 | F10: Rijo | G10: 27200 | H10: MSB ACCT - BKK - Cash Transfer does not save the "Notes" after editing | I10: Defect Fixed | J10: 1 | AG10: Will be creating PR after Qadir's review. POV already approved earlier. | AH10: Started testing. Notes text area size is larger than other pages. Rijo will be fixing it. | AI10: Notes resize done and PR completed. Can be verified after deployment. | AJ10: Completed testing and closed
A11: 10 | B11: MSB Accounting | C11: 46148 | D11: 46161 | E11: MSB Accounting 26.06 Sprint 2 Stretch | F11: Rijo | G11: 25390 | H11: MSB ACCT - BKK - Warning icon not displaying for overdrawn line items in a manual check while editing an existing record | I11: Product Owner - Verify | J11: 1 | AH11: Ready for POV. | AI11: Found some issue with overdraw amount calculation and fixed. Waiting for Pramod for the POV. | AJ11: POV completed with Pramod. Shared recording in the channel. | AL11: Waiting on Jeanette's approval. | AM11: Got POV approval and peer review done. Will be creating a PR soon.
A12: 11 | B12: MSB Accounting | C12: 46148 | D12: 46161 | E12: MSB Accounting 26.06 Sprint 2 | F12: Client Dev | G12: 52708 | H12: MSB Onboarding - Updated Program Selector Page | I12: Story Completed | J12: 3 | AI12: Test cases covered. Need to discuss few UI changes and clarify 1 scenario with client Dev before closing. | AJ12: Sowjanya need clarification about findings. | AK12: Need 1 more clarification from client dev. | AL12: Qadir will get this clarified. | AM12: Completed and closed
A13: 12 | B13: MSB Accounting | C13: 46148 | D13: 46161 | E13: MSB Accounting 26.06 Sprint 2 | F13: Qadir/Rijo | G13: SRX28912 | H13: MSB ACCT - BKK - Batches are not available for importing from 5/7 | I13: Defect Being Fixed | J13: 0 | AI13: Made scheduler jobs on A01 to keep the server active and running. It would resolve the issue with shutting down the server due to inactivity. But we are looking for a long term solution, but not as part of this escalation. | AJ13: Closed. | AM13: Will discuss with RJ to close batch missing related escalations since we got all batches.
A14: 13 | B14: MSB Accounting | C14: 46148 | D14: 46161 | E14: MSB Accounting 26.06 Sprint 2 Stretch | F14: Rijo | G14: 49563 | H14: MSB ACCT - BKK - New Feature: Credit Note and Debit Note-DB Changes | I14: Story Being Developed | J14: 5 | AJ14: Picked up and started analysis. | AK14: Not much progress. Analysis still in progress. | AL14: Created table structure, need some clarifications from Pramod. | AM14: Wil discuss with Pramod before the actual POV.
A15: 14 | B15: MSB Accounting | C15: 46148 | D15: 46161 | E15: MSB Accounting 26.06 Sprint 2 | F15: Rijo | G15: SRX28916 | H15: MSB ACCT - BKK - MSB batches are not available for importing from 5/12 | I15: Defect Being Fixed | AJ15: Started analysis. | AK15: Still server getting shutdown and jobs not getting completed in time. | AL15: Fix completed on PROD. Will get a confirmation and close. | AM15: Will discuss with RJ to close batch missing related escalations since we got all batches.
A16: 15 | B16: MSB Accounting | C16: 46148 | D16: 46161 | E16: MSB Accounting 26.06 Sprint 2 | F16: Client Dev | G16: 53136 | H16: MSB Onboarding - Update the Maintenance Form View | I16: Story Completed | J16: 3 | AK16: Started testing today. Started with maintanance page. Cleared doubt with James. Testing going on. | AL16: Testing in progress. | AM16: Completed and closed
A17: 16 | B17: MSB Accounting | C17: 46148 | D17: 46161 | E17: MSB Accounting 26.06 Sprint 2 Stretch | F17: Karthik | G17: 52626 | H17: MSB Accounting - Printing Reports Default | I17: Story Being Developed | J17: 5 | K17: 3 | L17: 12 | M17: 46155 | N17: 46156 | O17: Completed | P17: Rijo | Q17: Pass | R17: Qadir | S17: Pass | AB17: Pass | AK17: Completed dev changes. Updated 52 rdlc files. Dev testing in progress. | AL17: Dev testing completed, waiting for Pramod to run POV. | AM17: POV completed. Will be sharing the recording in the channel. Peer review also completed.
A18: 17 | B18: MSB Accounting | C18: 46148 | D18: 46161 | E18: MSB Accounting 26.06 Sprint 2 | F18: Qadir/ Clent Dev | G18: SRX28920 | H18: MSB ACCT - BKK - School Site Users Unable to Print Checks (CCSD) | I18: Defect Being Fixed | J18: 0 | AM18: Checked out the issue. Permission issue with forms. No need of any fix from our issue, just need to assign the permission to the user role.

Sheet 26.06 Sprint 2-Defect
A1: S.No | B1: Sprint # | C1: Story/Defect ID | D1: Parent Story | E1: Developer | F1: Issue Type | G1: Issue Description | H1: Priority | I1: Defect Source | J1: Type | K1: Status | L1: Root Cause Category | M1: Comments

Sheet 26.06 Sprint 1-Status
A1: S.No | B1: Application Name | C1: Sprint Start Date | D1: Sprint End Date | E1: Sprint | F1: Developer | G1: Story ID/Defect ID | H1: Description | I1: Status | J1: Estimated(sp) | K1: Actual(sp) | L1: Actual Hours Worklog | M1: Dev Start Date | N1: Dev End Date | O1: Unit testing | P1: Peer Tested By | Q1: Peer Tested Comments, if any | R1: Peer Reviewed By | S1: Peer Code Review Comments, if any | T1: PR Number/Link | U1: PR Created Date | V1: PR Approved Date | W1: Onsite Lead Code Review | X1: Onsite Lead Code Review Comments, if any | Y1: Client Code Review | Z1: PR Approved Date2 | AA1: Client Code Review Comments, if any | AB1: Internal PO -POV Comments | AC1: Client PO -POV Comments | AD1: Comments | AE1: Story met clarity expectations? | AF1: 46134 | AG1: 46135 | AH1: 46136 | AI1: 46139 | AJ1: 46140 | AK1: 46141 | AL1: 46142 | AM1: 46143 | AN1: 46146 | AO1: 46147
A2: 1 | B2: MSB Accounting | C2: 46134 | D2: 46147 | E2: MSB Accounting 26.06 Sprint 1 Stretch | F2: Client Dev | G2: 52277 | H2: MSB Onboarding - Sign & Submit | I2: Story Completed | J2: 1 | K2: 1 | L2: 4 | M2: NA | N2: NA | O2: NA | P2: NA | Q2: NA | R2: NA | S2: NA | T2: NA | U2: NA | V2: NA | W2: NA | X2: NA | Y2: NA | Z2: NA | AA2: NA | AB2: NA | AC2: NA | AD2: Worked by client dev. Only testing effort for us. | AE2: Meets Expectation | AF2: Created a bounceback on theprimary and secondary contact when i enter a phone number and its picking up another number | AG2: Waiting on Bounceback Fix | AH2: Waiting on the bounceback | AI2: Waiting on the bounceback | AJ2: When i add the phone number in contacts and save then click edit to check the number the number seems to be different-Again assigned to james | AK2: Bounceback reported to James. Sowjanya - PTO | AL2: Moved to testing and Wes pick up. | AM2: Wes completed
A3: 2 | B3: MSB Accounting | C3: 46134 | D3: 46147 | E3: MSB Accounting 26.06 Sprint 1 Stretch | F3: Qadir | G3: 52629 | H3: MSB Onboarding - Remove all old onboarding pages | I3: Story Completed | J3: 2 | K3: 1.75 | L3: 7 | M3: NA | N3: NA | O3: NA | P3: NA | Q3: NA | R3: NA | S3: NA | T3: NA | U3: NA | V3: NA | W3: NA | X3: NA | Y3: NA | Z3: NA | AA3: NA | AB3: NA | AC3: NA | AD3: Needed to remove the old pages from the new workflow. Dev was completed last sprint. Only testing in this sprint. | AE3: Meets Expectation | AF3: Started and check on the pages | AG3: - | AH3: need to verify create account page. | AI3: Completed | AJ3: - | AK3: - | AL3: -
A4: 3 | B4: MSB Accounting | C4: 46134 | D4: 46147 | E4: MSB Accounting 26.6 Sprint 1 | F4: Qadir/ Karthik | G4: SRX28874 | H4: MSB ACCT - Variance for second Bank Rec (Thatcher-July-BankB) | I4: Defect Being Fixed | J4: 0 | K4: 4.93 | L4: 19.75 | M4: 46134 | N4: NA | O4: NA | P4: NA | Q4: NA | R4: NA | S4: NA | T4: NA | U4: NA | V4: NA | W4: NA | X4: NA | Y4: NA | Z4: NA | AA4: NA | AB4: NA | AC4: NA | AD4: Qadir - Waiting for prod db copy to be restored on dev. Still Waiting for Jeanette verification. Request to restore db on Dev has been created on Apr 29th, still waiting for completion. | AE4: Meets Expectation | AF4: Still working on this. Looked at the prod data. Trying identify if the abnk rec lines are not being updated. | AG4: - | AH4: Found the root cause. Previous ending balance not calculated correctly. Checked with prev ending balance. | AI4: shared details with jeanette. Waiting on feedback. new Dev Database to be setup. | AJ4: jeanette needs DB Restored on DEV Request Made | AK4: Qadir will check about the DEV environment setup. | AL4: Waiting for Jeanette verification. | AN4: Qadir - Waiting for prod db copy to be restored on dev. Still Waiting for Jeanette verification. | AO4: Qadir - Waiting for prod db copy to be restored on dev. Still Waiting for Jeanette verification.
A5: 4 | B5: MSB Accounting | C5: 46134 | D5: 46147 | E5: MSB Accounting 26.6 Sprint 1 | F5: Qadir | G5: SRX28876 | H5: DUR - MSB ACCT - BKK - Kingsport City Schools (129907) - Dobyns-Bennett High School (DOB) | I5: Defect Being Fixed | J5: 0 | K5: 2.12 | L5: 8.5 | M5: 46134 | N5: NA | O5: NA | P5: NA | Q5: NA | R5: NA | S5: NA | T5: NA | U5: NA | V5: NA | W5: NA | X5: NA | Y5: NA | Z5: NA | AA5: NA | AB5: NA | AC5: NA | AD5: Waiting for prod db copy to be restored on dev. Request to restore db on Dev has been created on Apr 29th, still waiting for completion. | AE5: Meets Expectation | AF5: No Progress. | AG5: - | AH5: Code Fix. i have rewritten Acount SnapShot Report. Also, Looking at the beginning balances. | AI5: Dev Testing completed. need to make a PR for this today. | AJ5: PR made right now. | AK5: Will try to replicate this in DEV with latest DB, and will test the fix in the same environment if it replicated. | AL5: Will try to replicate in DEV. Also Qadil will check the DB update. | AN5: Waiting for prod db copy to be restored on dev. | AO5: Waiting for prod db copy to be restored on dev.
A6: 5 | B6: MSB Accounting | C6: 46134 | D6: 46147 | E6: MSB Accounting 26.6 Sprint 1 | F6: Rijo | G6: 52715 | H6: MSB ACCT - BKK - Regression - Entry Menu (Not Import MSB Batches) (26.4) | I6: Story Completed | J6: 2 | K6: 2.75 | L6: 11 | M6: NA | N6: NA | O6: NA | P6: NA | Q6: NA | R6: NA | S6: NA | T6: NA | U6: NA | V6: NA | W6: NA | X6: NA | Y6: NA | Z6: NA | AA6: NA | AB6: NA | AC6: NA | AD6: Regression testing. No code changes and PR. | AE6: Meets Expectation | AF6: Start Testing today | AG6: Completed 7 screens. All working as expected. | AH6: Completed | AI6: - | AJ6: - | AK6: - | AL6: -
A7: 6 | B7: MSB Accounting | C7: 46134 | D7: 46147 | E7: MSB Accounting 26.6 Sprint 1 | F7: Karthik | G7: 52714 | H7: MSB ACCT - BKK - Regression - Maintenance Menu (26.4) | I7: Story Completed | J7: 1 | K7: 1 | L7: 4 | M7: NA | N7: NA | O7: NA | P7: NA | Q7: NA | R7: NA | S7: NA | T7: NA | U7: NA | V7: NA | W7: NA | X7: NA | Y7: NA | Z7: NA | AA7: NA | AB7: NA | AC7: NA | AD7: Regression testing. No code changes and PR. | AE7: Meets Expectation | AG7: Completed. | AH7: - | AI7: - | AJ7: - | AK7: - | AL7: -
A8: 7 | B8: MSB Accounting | C8: 46134 | D8: 46147 | E8: MSB Accounting 26.6 Sprint 1 | F8: Client Dev | G8: 27265 | H8: MSB ACCT - BKK - [Regression] Upgrade 1099 Print Forms to the new UI look and feel | I8: Defect Fixed | J8: 2 | K8: 0.75 | L8: 3 | M8: NA | N8: NA | O8: NA | P8: NA | Q8: NA | R8: NA | S8: NA | T8: NA | U8: NA | V8: NA | W8: NA | X8: NA | Y8: NA | Z8: NA | AA8: NA | AB8: NA | AC8: NA | AD8: Worked by client dev. Only testing effort for us. | AE8: Meets Expectation | AG8: While testing found the popup size was too big | AH8: Waiting on the client dev to completed work | AI8: Found the pdf blank so retesting the scenario. Filling in the right data for the PO's / Invoices to fetch 1099 data | AJ8: Completed | AK8: - | AL8: -
A9: 8 | B9: MSB Accounting | C9: 46134 | D9: 46147 | E9: MSB Accounting 26.6 Sprint 1 | F9: Sowjanya | G9: 52724 | H9: MSB ACCT - BKK - Regression - 26.3 & 26.4 Stories and Defects | I9: Story Completed | J9: 8 | K9: 2.75 | L9: 11 | M9: NA | N9: NA | O9: NA | P9: NA | Q9: NA | R9: NA | S9: NA | T9: NA | U9: NA | V9: NA | W9: NA | X9: NA | Y9: NA | Z9: NA | AA9: NA | AB9: NA | AC9: NA | AD9: Regression testing. No code changes and PR. | AE9: Meets Expectation | AG9: Have completed 3 defects and 1 story | AH9: Completed 10 defects. 1 defect and 1 story pending. | AI9: Everything completed except 1 defect pending on receipting so pushed to wes for testing | AJ9: Completed | AK9: - | AL9: -
A10: 9 | B10: MSB Accounting | C10: 46134 | D10: 46147 | E10: MSB Accounting 26.6 Sprint 1 | F10: Rijo | G10: 52719 | H10: MSB ACCT - BKK - Regression - Administration Menu (26.4) | I10: Story Completed | J10: 2 | K10: 2 | L10: 8 | M10: NA | N10: NA | O10: NA | P10: NA | Q10: NA | R10: NA | S10: NA | T10: NA | U10: NA | V10: NA | W10: NA | X10: NA | Y10: NA | Z10: NA | AA10: NA | AB10: NA | AC10: NA | AD10: Regression testing. No code changes and PR. | AE10: Meets Expectation | AH10: Completed Role managment. | AI10: - | AJ10: - | AK10: - | AL10: -
A11: 10 | B11: MSB Accounting | C11: 46134 | D11: 46147 | E11: MSB Accounting 26.6 Sprint 1 | F11: Client Dev | G11: 27265 | H11: MSB ACCT - BKK - [Regression] Bank rec. id is displayed instead of date in Bank Rec. History Report (26.4) | I11: Defect Fixed | J11: 0 | K11: 0.75 | L11: 4 | M11: NA | N11: NA | O11: NA | P11: NA | Q11: NA | R11: NA | S11: NA | T11: NA | U11: NA | V11: NA | W11: NA | X11: NA | Y11: NA | Z11: NA | AA11: NA | AB11: NA | AC11: NA | AD11: Worked by client dev. Only testing effort for us. | AE11: Meets Expectation | AI11: Could not reproduce in CERT> | AJ11: - | AK11: - | AL11: -
A12: 11 | B12: MSB Accounting | C12: 46134 | D12: 46147 | E12: MSB Accounting 26.6 Sprint 1 | F12: Karthik | G12: 52936 | H12: MSB ACCT - BKK - Regression - Period End Menu (26.4) | I12: Story Completed | J12: 3 | K12: 3 | L12: 12 | M12: NA | N12: NA | O12: NA | P12: NA | Q12: NA | R12: NA | S12: NA | T12: NA | U12: NA | V12: NA | W12: NA | X12: NA | Y12: NA | Z12: NA | AA12: NA | AB12: NA | AC12: NA | AD12: Regression testing. No code changes and PR. | AE12: Meets Expectation | AI12: Completed bank Rec Month End year end . Working on 1099 reports. | AJ12: Completed 1099 Reporting Menu. Completed post Year End Observations. Existing Issue shared | AK12: Completed | AL12: -
A13: 12 | B13: MSB Accounting | C13: 46134 | D13: 46147 | E13: MSB Accounting 26.6 Sprint 1 | F13: Rijo | G13: 52718 | H13: MSB ACCT - BKK - Regression - Management Menu (26.4) | I13: Story Completed | J13: 2 | K13: 2.25 | L13: 9 | M13: NA | N13: NA | O13: NA | P13: NA | Q13: NA | R13: NA | S13: NA | T13: NA | U13: NA | V13: NA | W13: NA | X13: NA | Y13: NA | Z13: NA | AA13: NA | AB13: NA | AC13: NA | AD13: Regression testing. No code changes and PR. | AE13: Meets Expectation | AI13: Started today. Conmpleted 4 screens. Failed School Settings. 52912. | AJ13: Closed the issue with School Settings. Almost Completed special functions questions on hardware settings. | AK13: Completed | AL13: -
A14: 13 | B14: MSB Accounting | C14: 46134 | D14: 46147 | E14: MSB Accounting 26.6 Sprint 1 | F14: Qadir | G14: SRX28888 | H14: MSB ACCT - BKK - Duplicate Adjustment Entry on Bank Rec/Report (Pleasanton) | I14: Defect Fixed | J14: 0 | K14: 2.5 | L14: 10 | M14: 46136 | N14: 46141 | O14: Completed | P14: Rijo | Q14: Pass | R14: Karthik | S14: Pass | T14: NA | U14: NA | V14: NA | W14: NA | X14: NA | Y14: NA | Z14: NA | AA14: NA | AB14: NA | AC14: NA | AD14: Prod data fix, update query ran on prod db. No code changes and PR. | AE14: Meets Expectation | AI14: Had a discussion with the team on the root cause. Make the data fix. Make a request for Audit Logs. | AK14: Data fix done for this and verification is pending. Audit log analsis in progress. | AL14: Completed verification and new defect will be created to find the root cause.
A15: 14 | B15: MSB Accounting | C15: 46134 | D15: 46147 | E15: MSB Accounting 26.6 Sprint 1 | F15: Rijo | G15: 52912 | H15: MSB ACCT - BKK - Upgrade Purchase Order Entry Page and School Settings page with Shipping address validations | I15: Story Completed | J15: 2 | K15: 0.12 | L15: 0.5 | M15: NA | N15: NA | O15: Completed | P15: Karthik | Q15: Pass | R15: Qadir | S15: Pass | T15: https://dev.azure.com/heartlandschools/Accounting/_git/MSBAccounting-NewSchoolBooks/pullrequest/48608 | U15: 46135 | V15: 46135 | W15: Done | X15: Pass | Y15: Done | Z15: NA | AA15: Pass | AB15: Pass | AC15: Pass | AD15: Development was completed last sprint. | AE15: Meets Expectation | AJ15: Testing in progress. Almost completed. | AK15: Completed | AL15: -
A16: 15 | B16: MSB Accounting | C16: 46134 | D16: 46147 | E16: MSB Accounting 26.06 Sprint 1 Stretch | F16: Rijo | G16: 27200 | H16: MSB ACCT - BKK - Cash Transfer does not save the "Notes" after editing | I16: Product Owner - Verify | J16: 2 | K16: 1.5 | L16: 6 | M16: 46141 | N16: 46146 | O16: Completed | P16: NA | Q16: NA | R16: NA | S16: NA | T16: NA | U16: NA | V16: NA | W16: NA | X16: NA | Y16: NA | Z16: NA | AA16: NA | AB16: Pass | AC16: NA | AD16: Waiting for the client PO approval for the POV for the last 2 days. The review and PR is pending. | AE16: Meets Expectation | AK16: Made the fix, testing it out. Will be doing the POV by next day. | AL16: Rijo PTO | AM16: Holiday | AN16: Did the POV with Pramod and posted for Jeanette's approval. | AO16: Still waiting for Jeanette's approval.
A17: 16 | B17: MSB Accounting | C17: 46134 | D17: 46147 | E17: MSB Accounting 26.06 Sprint 1 Stretch | F17: Karthik | G17: 45225 | H17: MSB ACCT - BKK - Add Warnings and Blockers for Unclosed Years (26.5) | I17: Story Peer Review | J17: 3 | K17: 1.5 | L17: 6 | M17: 46141 | N17: 46141 | O17: Completed | P17: Rijo | Q17: Pass | R17: Qadir | S17: Pass | T17: https://dev.azure.com/heartlandschools/Accounting/_git/MSBAccounting-NewSchoolBooks/pullrequest/48844 | U17: 46147 | V17: 46147 | W17: Done | X17: Pass | Y17: Done | Z17: NA | AA17: Pass | AB17: Pass | AC17: Pass | AD17: Dev completed, and testing will be completed on next sprint. | AE17: Meets Expectation | AK17: Completed pending changes, and will create a PR once release branch created. | AL17: Found duplicate css and js with bank deposit entry screen. Made fix and Qadir will do peer review. | AM17: Holiday | AN17: Waiting for Qadir's review. | AO17: Needs to deploy
A18: 17 | B18: MSB Accounting | C18: 46134 | D18: 46147 | E18: MSB Accounting 26.06 Sprint 1 Stretch | F18: Client Dev | G18: 52474 | H18: MSB Onboarding - Complete User Experience with New Flow | I18: Story Being Tested | J18: 3 | K18: 3.33 | L18: 10 | M18: NA | N18: NA | O18: NA | P18: NA | Q18: NA | R18: NA | S18: NA | T18: NA | U18: NA | V18: NA | W18: NA | X18: NA | Y18: NA | Z18: NA | AA18: NA | AB18: NA | AC18: NA | AD18: Worked by client dev. Only testing effort for us. | AE18: Meets Expectation | AM18: Holiday | AN18: Found a possible issue, need to clarify with client dev. | AO18: Got clarified and need to create a bounceback
A19: 18 | B19: MSB Accounting | C19: 46134 | D19: 46147 | E19: MSB Accounting 26.6 Sprint 1 | F19: Karthik/Rijo | G19: 27326 | H19: MSB ACCT - BKK - [Regression] MSB Import Batch does not show the payment items (26.4) | I19: Defect Rejected | J19: 0 | K19: 2.25 | L19: 9 | M19: 46142 | N19: 46146 | O19: NA | P19: NA | Q19: NA | R19: NA | S19: NA | T19: NA | U19: NA | V19: NA | W19: NA | X19: NA | Y19: NA | Z19: NA | AA19: NA | AB19: NA | AC19: NA | AD19: Defect rejected. It was a set up issue with gateway assignment. User is not supposed to remove assigned schools for a shared batch. | AE19: Meets Expectation | AN19: Defect rejected. It was a set up issue with gateway assignment. User is not supposed to remove assigned schools for a shared batch.
A20: 19 | B20: MSB Accounting | C20: 46134 | D20: 46147 | E20: MSB Accounting 26.06 Sprint 1 Stretch | F20: Rijo | G20: 22751 | H20: MSB ACCT - Integration - Renumber Merge deletes a mapped GL account in ImportFromMSB transaction causing error | I20: Defect Being Fixed | J20: 5 | K20: 1.25 | L20: 5 | M20: 46147 | N20: NA | O20: NA | P20: NA | Q20: NA | R20: NA | S20: NA | T20: NA | U20: NA | V20: NA | W20: NA | X20: NA | Y20: NA | Z20: NA | AA20: NA | AB20: NA | AC20: NA | AD20: Defect fix still in progress. Added to stretch and started on the last day of the sprint. | AE20: Meets Expectation | AO20: Completed analysis and started dev changes. Working on user warning if a mapping existing for the GL account.
A21: 20 | B21: MSB Accounting | C21: 46134 | D21: 46147 | E21: MSB Accounting 26.06 Sprint 1 Stretch | F21: Karthik | G21: 26753 | H21: MSB ACCT - BKK - "Cancel" button is not enabled while viewing a Transfer and Receipt Entry | I21: Defect Peer Review | J21: 2 | K21: 0.5 | L21: 2 | M21: 46147 | N21: 46147 | O21: Completed | P21: NA | Q21: NA | R21: NA | S21: NA | T21: NA | U21: NA | V21: NA | W21: NA | X21: NA | Y21: NA | Z21: NA | AA21: NA | AB21: Pass | AC21: Pass | AD21: Dev completed, and testing will be completed on next sprint. | AE21: Meets Expectation | AO21: Have completed dev changes and POV

Sheet 26.06 Sprint 1-Defect
A1: S.No | B1: Sprint # | C1: Story/Defect ID | D1: Parent Story | E1: Developer | F1: Issue Type | G1: Issue Description | H1: Priority | I1: Defect Source | J1: Type | K1: Status | L1: Root Cause Category | M1: Comments
A2: 1 | B2: MSB Accounting | C2: SRX28874 | E2: Qadir/ Karthik | F2: Task | G2: MSB ACCT - Variance for second Bank Rec (Thatcher-July-BankB) | H2: Significant | I2: Manual | J2: External | K2: Defect Being Fixed | L2: Project_Management | M2: The customer completed reconciliation with an incorrect ending balance, which is causing a variance in the next month's reconciliation. We have suggested deleting the previous reconciliation and recreate with the correct ending balance. Currently we are waiting for Jeanette's verification on this fix.
A3: 2 | B3: MSB Accounting | C3: SRX28876 | E3: Qadir | F3: Defect | G3: DUR - MSB ACCT - BKK - Kingsport City Schools (129907) - Dobyns-Bennett High School (DOB) | H3: Significant | I3: Manual | J3: External | K3: Defect Being Fixed | L3: Project_Management | M3: Existing issue, Facing a timout issue during large Excel export in the report. Query performance improved. Issue not reproducible locally, so planning to validate in dev. Waiting for PlatOps to restore the latest DB.
A4: 3 | B4: MSB Accounting | C4: 27265 | E4: Client Dev | F4: Defect | G4: MSB ACCT - BKK - [Regression] Upgrade 1099 Print Forms to the new UI look and feel | H4: Minor | I4: Manual | J4: Internal | K4: Defect Fixed | L4: Development | M4: Issue with the new Kaleida UI changes. All changes are worked by client dev. Defect also handleb by same client dev.
A5: 4 | B5: MSB Accounting | C5: 27265 | E5: Client Dev | F5: Defect | G5: MSB ACCT - BKK - [Regression] Bank rec. id is displayed instead of date in Bank Rec. History Report (26.4) | H5: Minor | I5: Manual | J5: Internal | K5: Defect Fixed | L5: Development | M5: Issue with the new Kaleida UI changes. All changes are worked by client dev. Defect also handleb by same client dev.
A6: 5 | B6: MSB Accounting | C6: SRX28888 | E6: Qadir | F6: Defect | G6: MSB ACCT - BKK - Duplicate Adjustment Entry on Bank Rec/Report (Pleasanton) | H6: Significant | I6: Manual | J6: External | K6: Defect Fixed | L6: Project_Management | M6: The customer had a duplicate adjustment entry in bank reconciliation. We were unable to replicate the issue, so we created a new defect to investigate the root cause. We also performed a data fix to resolve the customer's blocker.
A7: 6 | B7: MSB Accounting | C7: 27200 | E7: Rijo | F7: Defect | G7: MSB ACCT - BKK - Cash Transfer does not save the "Notes" after editing | H7: Significant | I7: Manual | J7: External | K7: Defect Fixed | L7: Existing_Issues | M7: Existing issue. We had this in backlog for a long time since it is a low priority issue. The issue was "Submit" button getting disabled while opening popup.
A8: 7 | B8: MSB Accounting | C8: 27326 | E8: Karthik/Rijo | F8: Defect | G8: MSB ACCT - BKK - [Regression] MSB Import Batch does not show the payment items (26.4) | H8: Major | I8: Manual | J8: Internal | K8: Defect Rejected | L8: Enhancements | M8: Defect rejected. It was a set up issue with gateway assignment. User is not supposed to remove assigned schools for a shared batch.
A9: 8 | B9: MSB Accounting | C9: 22751 | E9: Rijo | F9: Defect | G9: MSB ACCT - Integration - Renumber Merge deletes a mapped GL account in ImportFromMSB transaction causing error | H9: Significant | I9: Manual | J9: Internal | K9: Defect Being Fixed | L9: Existing_Issues | M9: Existing issue. When the user change the account number using re-number merge, the mapped gl account in import msb becomes invalid. This is a scenario we haven't considered while designing the mapping.
A10: 9 | B10: MSB Accounting | C10: 26753 | E10: Karthik | F10: Defect | G10: MSB ACCT - BKK - "Cancel" button is not enabled while viewing a Transfer and Receipt Entry | H10: Significant | I10: Manual | J10: Internal | K10: Defect Fixed | L10: Existing_Issues | M10: Existing issue. The cancel button is in disabled state while viewing the transfer and receipt entry.

Sheet 26.04 Sprint 3-Status
A1: S.No | B1: Application Name | C1: Sprint Start Date | D1: Sprint End Date | E1: Sprint | F1: Developer | G1: Story ID/Defect ID | H1: Description | I1: Status | J1: Estimated(sp) | K1: Actual(sp) | L1: Actual Hours Worklog | M1: Dev Start Date | N1: Dev End Date | O1: Unit testing | P1: Peer Tested By | Q1: Peer Tested Comments, if any | R1: Peer Reviewed By | S1: Peer Code Review Comments, if any | T1: PR Number/Link | U1: PR Created Date | V1: PR Approved Date | W1: Onsite Lead Code Review | X1: Onsite Lead Code Review Comments, if any | Y1: Client Code Review | Z1: PR Approved Date2 | AA1: Client Code Review Comments, if any | AB1: Internal PO -POV Comments | AC1: Client PO -POV Comments | AD1: Comments | AE1: Story met clarity expectations? | AF1: 46120 | AG1: 46121 | AH1: 46122 | AI1: 46125 | AJ1: 46126 | AK1: 46127 | AL1: 46128 | AM1: 46129 | AN1: 46132 | AO1: 46133
A2: 1 | B2: MSB Accounting | C2: 46120 | D2: 46133 | E2: MSB Accounting 26.04 Sprint 3 Stretch | F2: Client Dev | G2: 52277 | H2: MSB Onboarding - Sign & Submit | I2: Story Ready For Testing | J2: 2 | K2: 4 | L2: 16 | M2: NA | N2: NA | O2: NA | P2: NA | Q2: NA | R2: NA | S2: NA | T2: NA | U2: NA | V2: NA | W2: NA | X2: NA | Y2: NA | Z2: NA | AA2: NA | AB2: NA | AC2: NA | AD2: Worked by client dev. Only testing effort for our team | AE2: Meets Expectation | AF2: Tested - Intermittent Issues while testing. | AG2: Observed an issue in Authorized Signers : when two contacts (primary and secondary) are configured, the secondary contact is not able to sign the documents getting an popup as "The agreement can no longer be modified" | AH2: James fixed the issue. Testing is in progress. | AI2: 1 scenario pending. Blocker with 2 people signing. | AJ2: Bounceback found. Wiating on client Dev. | AK2: No update on this. | AL2: On hold for Regression | AM2: On hold for Regression | AN2: On hold for Regression | AO2: On hold for Regression
A3: 2 | B3: MSB Accounting | C3: 46120 | D3: 46133 | E3: MSB Accounting 26.04 Sprint 3 Stretch | F3: Rijo | G3: 47478 | H3: MSB ACCT - BKK - Update Bank Deposit History Report to Reflect Changes to Import MSB Batches (26.5) | I3: Story Peer Review | J3: 2 | K3: 1.25 | L3: 5 | M3: 46120 | N3: 46120 | O3: Completed | P3: Karthik | Q3: Pass | R3: Qadir | S3: Pass | T3: NA | U3: NA | V3: NA | W3: NA | X3: NA | Y3: NA | Z3: NA | AA3: NA | AB3: NA | AC3: NA | AD3: Story on Hold. This will be for the next release | AE3: Meets Expectation | AF3: POV With Pramod completed. Posted on channel | AG3: Code Review in Progress. | AI3: Peer review complete. Waiting on CERT Develop status. | AJ3: Story on Hold for Release | AK3: Story on Hold for Release | AL3: Story on Hold for Release | AM3: Story on Hold for Release | AN3: Story on Hold for Release
A4: 3 | B4: MSB Accounting | C4: 46120 | D4: 46133 | E4: MSB Accounting 26.04 Sprint 3 Stretch | F4: Karthik | G4: 24926 | H4: MSB ACCT - BKK - GL Account Maintenance current balances do not display the most recent balances (26.5) | I4: Story Peer Review | J4: 2 | K4: 1 | L4: 4 | M4: 46120 | N4: 46121 | O4: NA | P4: NA | Q4: NA | R4: NA | S4: NA | T4: NA | U4: NA | V4: NA | W4: NA | X4: NA | Y4: NA | Z4: NA | AA4: NA | AB4: NA | AC4: NA | AD4: Story on Hold. This will be for the next release | AE4: Meets Expectation | AF4: Still doing dev testing in DEV environment. | AG4: Qadir To Review. | AI4: Qadir to still review whether the client's timezone should be valid for calculation of account balances since all entry times were earlier made with the server time. Question: How would this change impact 2 users using the application from different timezones when they make different but entries at the same time ? | AJ4: Story on Hold for Release | AK4: Story on Hold for Release | AL4: Story on Hold for Release | AM4: Story on Hold for Release | AN4: Story on Hold for Release
A5: 4 | B5: MSB Accounting | C5: 46120 | D5: 46133 | E5: MSB Accounting 26.04 Sprint 3 Stretch | F5: Karthik | G5: 45225 | H5: MSB ACCT - BKK - Add Warnings and Blockers for Unclosed Years (26.5) | I5: Story Approved | J5: 3 | K5: 1.5 | L5: 6 | M5: 46120 | O5: NA | P5: NA | Q5: NA | R5: NA | S5: NA | T5: NA | U5: NA | V5: NA | W5: NA | X5: NA | Y5: NA | Z5: NA | AA5: NA | AB5: NA | AC5: NA | AD5: Story on Hold. This will be for the next release | AE5: Meets Expectation | AF5: Waiting on jeanette | AG5: POV Comments - Working on fixing conflicts locally | AI5: need to completed a few POV changes. Putting story on hold for regression | AJ5: Story on Hold for Release | AK5: Story on Hold for Release | AL5: Story on Hold for Release | AM5: Story on Hold for Release | AN5: Story on Hold for Release
