Workbook

Sheet Dashboard
A1: Current Sprint | B1: {=INDEX($B$2:$B$97,MATCH(1,(($D$2:$D$97 >=TODAY())*($C$2:$C$97<=TODAY())),0))} -> GGO 8.4.0 Sprint 4 | C1: Current Sprint Sheet | D1: =CONCATENATE(B1,"-Status") -> GGO 8.4.0 Sprint 4-Status | E1: Sprint Start Date | F1: =VLOOKUP($B$1,$B$1:$C$97,2) -> 46156 | G1: Sprint End Date | H1: =VLOOKUP($B$1,$B$1:$D$97,3) -> 46170 | I1: Application Name | J1: GGO Donor Wave | K1: Users | L1: vishnuram.balaji@relevantz.com;charles.rapheal@relevantz.com | M1: Teams Name(GGO Donor_Web_API) | N1: 19:4ae543cca7444593b1d022935b8fb11d@thread.v2
A2: Sprint Type | B2: Sprint # | C2: Sprint Start Date | D2: Sprint End Date | E2: Assigned | F2: Completed | G2: Story points introduced/removed | H2: Sprint Summary | I2: Accomplishments | J2: Remarks | K2: Retro Points (Internal & External) | L2: Data sanity Audit Status | M2: AuditDate | N2: Planned Leaves | O2: Availed Leaves | P2: Backlog Health
A3: =IF(AND($D$1>=C3,$D$1<=D3),"CurrentSprint","NA") -> NA | B3: GGO 7.15.0 Sprint 4 | C3: 45303 | D3: 45316 | E3: 17 | F3: 15 | G3: 7 | J3: Completed all the introduced story in the mid of the sprint | K3: Internal: External:
A4: =IF(AND($D$1>=C4,$D$1<=D4),"CurrentSprint","NA") -> NA | B4: GGO 7.16.0 Sprint 1 | C4: 45317 | D4: 45330 | E4: 17 | F4: 14 | G4: 3 | J4: Actual estimated stories (17pts) got completed from our end with Development and Testing, From Onsite QA (Nate) took time for testing 3 point story because of PRD release and he took half day leave and he got only 4 hrs of time. So from this I would like to say, we should plan to complete the estimated stories 2 days prior, else Nate won't close on the last day of sprint. Introduced Story - 3 point is Development completed, only Testing pending. | K4: Internal: External:
A5: =IF(AND($D$1>=C5,$D$1<=D5),"CurrentSprint","NA") -> NA | B5: GGO 7.16.0 Sprint 2 | C5: 45331 | D5: 45344 | E5: 23 | F5: 22 | G5: 2 | J5: Completed all the stories on time, but we noticed one minor issue in GGO-13703 Bid-18 report on xls and xlsx formats. the column header occupying some aditional column . It require an report engine code changes.verified some other reports also having the same issue and it's an existing issue.completed introduced story as well | K5: Internal: External:
A6: =IF(AND($D$1>=C6,$D$1<=D6),"CurrentSprint","NA") -> NA | B6: GGO 7.16.0 Sprint 3 | C6: 45345 | D6: 45358 | E6: 27 | F6: 23 | G6: 7 | J6: GGO-13801-onsite QA(Nathan) raised one bug , we tried to reproduce the issue on rounding but we are not able to do that. We have asked for the steps to reproduce the issue. GGO-13738 -Development has been completed on this story, it require's IT team support to complete the testing. Introduced Story - 7 points (Except GGO-13738 testing) all completed | K6: Internal: External:
A7: =IF(AND($D$1>=C7,$D$1<=D7),"CurrentSprint","NA") -> NA | B7: GGO 7.16.0 Sprint 4 | C7: 45359 | D7: 45372 | E7: 20 | F7: 16 | G7: 5 | J7: GGO-13796 and GGO-13773 development has been completed.testing requires IT team support to complete,currently salesforce team doing some changes at their side we can't test salesforce api's .Introduced Story - 5 points Develpment has been completed for that. | K7: Internal: External:
A8: =IF(AND($D$1>=C8,$D$1<=D8),"CurrentSprint","NA") -> NA | B8: GGO 7.17.0 Sprint 1 | C8: 45373 | D8: 45386 | E8: 14 | F8: 11 | G8: 3 | J8: Since we need support from sales force team for testing GGO -13773 ,PAPI-702 saranya supported Mike wall for testing We got info from Doug about the 4 PROD issues in planning meeting 1. Convenience Fee Issue - Not able to reproduce by our team and Onsite QA in DEV, TST & CRT, it is occurring only in PRD, finding a way to check the values, settings in PROD to replicate in lower envrionment 2. Package Tax Issue - Round off to whole number instead of 2 decimal, this is our mistake that has got in to PRD 3 months before, when fixing old code to replace SQL CLR to C# method. 3. Item tax added to Package - This was old issue, but many clients started to raise concern about this issue now, because of our new implementation for Convenience Fee. 4. Payment show error when Actually it is success in PAPI for Few Clients in PRD - Still don't know the reason, analysing the root cause of this issue. | K8: Internal: External:
A9: =IF(AND($D$1>=C9,$D$1<=D9),"CurrentSprint","NA") -> NA | B9: GGO 7.17.0 Sprint 2 | C9: 45387 | D9: 45400 | E9: 19 | F9: 17 | G9: 0 | J9: This sprint we fixed production issues and macroscope security issues . PAPI-702 carried because card details need to verified with PAPI database, we don't have required permission for that, only onsite QA need to be verified. | K9: Internal: External:
A10: =IF(AND($D$1>=C10,$D$1<=D10),"CurrentSprint","NA") -> NA | B10: GGO 7.17.0 Sprint 3 | C10: 45401 | D10: 45414 | E10: 18 | F10: 11 | G10: 0 | J10: 2 stories got carried. 1. Due to salesforce team confirmed they can't do any changes. 2. Onshore Testing is pending | K10: Internal: External:
A11: =IF(AND($D$1>=C11,$D$1<=D11),"CurrentSprint","NA") -> NA | B11: GGO 7.17.0 Sprint 4 | C11: 45415 | D11: 45428 | E11: 14 | F11: 4 | G11: 0 | J11: CRT Regression Testing is still in Progress. 3 stores are blocked and carried because of IT dependencey (Certificate Issue and Permission issue for Report Instance folder in DEV & TST Environments), all the development and testing works are done from our end. | K11: Internal: External:
A12: =IF(AND($D$1>=C12,$D$1<=D12),"CurrentSprint","NA") -> NA | B12: GGO 7.18.0 Sprint 1 | C12: 45429 | D12: 45442 | E12: 15 | F12: 14 | G12: 0 | J12: Testing blocked due to certificate issue | K12: Internal: External:
A13: =IF(AND($D$1>=C13,$D$1<=D13),"CurrentSprint","NA") -> NA | B13: GGO 7.18.0 Sprint 2 | C13: 45443 | D13: 45456 | E13: 20 | F13: 16 | G13: 0 | K13: Internal: External:
A14: =IF(AND($D$1>=C14,$D$1<=D14),"CurrentSprint","NA") -> NA | B14: GGO 7.18.0 Sprint 3 | C14: 45457 | D14: 45470 | E14: 17 | F14: 15 | G14: 2 | K14: Internal: External:
A15: =IF(AND($D$1>=C15,$D$1<=D15),"CurrentSprint","NA") -> NA | B15: GGO 7.18.0 Sprint 4 | C15: 45471 | D15: 45484 | E15: 20 | F15: 20 | G15: 0 | K15: Internal: External:
A16: =IF(AND($D$1>=C16,$D$1<=D16),"CurrentSprint","NA") -> NA | B16: GGO 7.19.0 Sprint 1 | C16: 45485 | D16: 45498 | E16: 15 | F16: 15 | G16: 5 | J16: Two stretch stories got carried to next sprint. | K16: Internal: External:
A17: =IF(AND($D$1>=C17,$D$1<=D17),"CurrentSprint","NA") -> NA | B17: GGO 7.19.0 Sprint 2 | C17: 45499 | D17: 45511 | E17: 6 | F17: 6 | G17: 7 | J17: Two stretch stories got carried to next sprint. | K17: Internal: External:
A18: =IF(AND($D$1>=C18,$D$1<=D18),"CurrentSprint","NA") -> NA | B18: GGO 7.19.0 Sprint 3 | C18: 45512 | D18: 45526 | E18: 16 | F18: 16 | G18: 2 | K18: Internal: External:
A19: =IF(AND($D$1>=C19,$D$1<=D19),"CurrentSprint","NA") -> NA | B19: GGO 7.19.0 Sprint 4 | C19: 45527 | D19: 45540 | E19: 17 | F19: 14 | G19: 2 | J19: Automation Regression story got carried over as it was new for Offshore QA and there was some learning curve involved. | K19: Internal: External:
A20: =IF(AND($D$1>=C20,$D$1<=D20),"CurrentSprint","NA") -> NA | B20: GGO 7.20.0 Sprint 1 | C20: 45540 | D20: 45554 | E20: 15 | F20: 13 | G20: 2 | J20: 2 point carry forwarded to next sprint, development and testing completed from our end, but onsite QA didn't complete it. | K20: Internal: External:
A21: =IF(AND($D$1>=C21,$D$1<=D21),"CurrentSprint","NA") -> NA | B21: GGO 7.20.0 Sprint 2 | C21: 45555 | D21: 45568 | E21: 19 | F21: 14 | G21: 2 | J21: GGO-14067 got carried, We are migrating Bid-03 report to new RDLC framework, there is lot of existing logic present in RPT file. we need to exactly replicate same logic in SQL stored procedure for new RDLC format.understanding .rpt file logic is complication involved Peer CRC:0 Onsite CRC: 0 Client CRC: 0 Internal Defects: 0 External Defects: 0 | K21: Internal: External:
A22: =IF(AND($D$1>=C22,$D$1<=D22),"CurrentSprint","NA") -> NA | B22: GGO 7.20.0 Sprint 3 | C22: 45569 | D22: 45582 | E22: 17 | F22: 12 | J22: GGO-14067 got carried, Getting Timeout issue for large records,Suporterwise page breakup and some functionlity in spreadsheetlayout is pending Onsite CRC: 0 Onsite CRC: 0 Client CRC: 0 Internal Defects: 1 External Defects: 0 | K22: Internal: External:
A23: =IF(AND($D$1>=C23,$D$1<=D23),"CurrentSprint","NA") -> NA | B23: GGO 7.20.0 Sprint 4 | C23: 45583 | D23: 45596 | E23: 16 | F23: 13 | I23: 1. Login Page Privacy policy update in MFA login page of GGO application 2. Paymen Receipt in new RDLC replacing form display helps users to download receipt as PDF and send email with attachment. | J23: GGO-14067 got carried, Getting Timeout issue for large records Onsite CRC: 0 Client CRC: 0 Internal Defects: 1 External Defects: 0 | K23: Internal: External:
A24: =IF(AND($D$1>=C24,$D$1<=D24),"CurrentSprint","NA") -> NA | B24: GGO 7.21.0 Sprint 1 | C24: 45597 | D24: 45610 | E24: 18 | F24: 17 | G24: 3/0 | I24: 1.Fixed Timeout issue on Bid-03 RDLC report generation. 2.Completed two tickets introduced in the mid of the sprint | J24: Completed all story points on time Onsite CRC: 0 Client CRC: 0 Internal Defects: 2 External Defects: 0 | K24: Internal: External:
A25: =IF(AND($D$1>=C25,$D$1<=D25),"CurrentSprint","NA") -> NA | B25: GGO 7.21.0 Sprint 2 | C25: 45611 | D25: 45621 | E25: 14 | F25: 11 | I25: 1. Fixed Grid selection issue on Bid-03 RDLC report generation. 2. Fixed Azure Images issue replacing content server url with azure url 3. Investigated GGO to OB Queue flow to replace it with Quartz Job. 4. Allow GGO to validate and support different card card types (JCB, Diners club & Discover Debit) | J25: GGO-13319 story got rolled over due to Azure image access issue and a ticket with Microsoft has been opened​ by IT Onsite CRC: 0 Client CRC: 1 Internal Defects: 0 External Defects: 0 | K25: Internal: External:Rajesh and offshore for continued work on reports Priya, Nathan and Conor for testing a lot of stories and completing them
A26: =IF(AND($D$1>=C26,$D$1<=D26),"CurrentSprint","NA") -> NA | B26: GGO 7.21.0 Sprint 3 | C26: 45622 | D26: 45638 | E26: 14 | F26: 14 | G26: 7/0 | I26: 1. Application images moved in Azure , previously we stored the images in DB as bytes 2. 7.20.1 Successfully deployed to PRD 3. EMV Implementation -completed most of the cardreader functionality | J26: GGO-14325 - BID-06 story is a huge effort and cannot be completed in one sprint, hence it was taken as a strech goal Peer CRC:0 Onsite CRC: 0 Client CRC: 0 Internal Defects: 0 External Defects: 0 | K26: Internal: External:
A27: =IF(AND($D$1>=C27,$D$1<=D27),"CurrentSprint","NA") -> NA | B27: GGO 7.21.0 Sprint 4 | C27: 45639 | D27: 45666 | E27: 24 | F27: 19 | G27: 3/0 | I27: 1. Fixed Duplicate Event X Code issue that was a PROD bug for more than 5 years. 2. Good progress on Bid-06 RDLC update and feel confident in completing it next sprint 3. Popup warning for Convenience fee validation implemented 4. Quartz Job implemented for Bid-06 email flow with our own effort and stored the PDF in Azure. | J27: GGO-14427 - BID-06 - Part-3 story is a huge effort, this has got more than 100 scenario's, so it took more time for testing left out with 2 bugs at the end of sprint (development done for the bugs) only testing pending. Peer CRC:0 Onsite CRC: 0 Client CRC: 0 Internal Defects: 8 External Defects: 0 | K27: Internal: External: Offshore team made great progress on Bid-06 report
A28: =IF(AND($D$1>=C28,$D$1<=D28),"CurrentSprint","NA") -> NA | B28: GGO 7.22.0 Sprint 1 | C28: 45667 | D28: 45680 | E28: 21 | F28: 17 | G28: 4/0 | I28: 1.GGO-14484 Jan 21 Prod Release 2. Successfully completed Bid-06 with new report tool set 3. CRT regression testing completed | J28: GGO-14427 - BID-06 - Part-3 during the CRT testing noticed package item enabled scenario taking too long to complete the report - immediately addressed this Issue. GGO-14483 Completed CRT Release & Regression Testing Peer CRC:0 Onsite CRC: 0 Client CRC: 0 Internal Defects: 6 External Defects: 0 Reason for pending: GGO-14422, PAPI-789 - Development and Testing completed from our end, Pending testing from Nate (Onsite QA) because he was focusing more in CRT regression. GGO-14447 - Automation story completed from our end, pending review from Nate GGO-14450 - A.C change one day prior to Sprint end date, so it got carry forward to next sprint
A29: =IF(AND($D$1>=C29,$D$1<=D29),"CurrentSprint","NA") -> NA | B29: GGO 7.22.0 Sprint 2 | C29: 45681 | D29: 45694 | E29: 18 | F29: 11 | G29: 2/0 | I29: 1.Enhance RSVP Functionality with key features to enable better data gathering and management of attendee info. 2.Azure Thumbnail image creation issue fix - Add this project as part of GGO Solution and build it via Build pipeline and add it to GGO Artifact | J29: Peer CRC:0 Onsite CRC: 0 Client CRC: 0 Internal Defects: 0 External Defects: 1 Testing is pending by Onsite QA and we completed the stories (GGO-14503, GGO-14450) and deployed to TST 2 days prior Sprint end, that's the reason these stories got rolled over to next sprint.
A30: =IF(AND($D$1>=C30,$D$1<=D30),"CurrentSprint","NA") -> NA | B30: GGO 7.22.0 Sprint 3 | C30: 45695 | D30: 45708 | E30: 18 | F30: 8 | I30: 1.Adjust Admission Functionality and Infrastructure(Graph) update 2.Bid-19 and Bid-15 Report Updates | J30: Peer CRC:0 Onsite CRC: 0 Client CRC: 4 Internal Defects: 4 External Defects: 1 Reason for pending: GGO-14504 - The story was given Onisite QA for testing 3 days before the end of Sprint but Onsite QA logged bug on the last day of Thesprint. It was fixed and deployed before sprint prep, QA didn't get time to complete it. GGO-14070 - Development took a lot of time and got completed only on 1 day before Sprint end, the offshore QA logged a minor bug on the last day of sprint, fixed the bug and PR created for review. (Saranya worked on the RDLC report for the first time and there was a learning curve involved which took time)
A31: =IF(AND($D$1>=C31,$D$1<=D31),"CurrentSprint","NA") -> NA | B31: GGO 7.22.0 Sprint 4 | C31: 45709 | D31: 45722 | E31: 20 | F31: 15 | G31: 2/0 | I31: CRT Release & Regression testing for GGO 7.22.0 and PAPI 7.17.0 | J31: Peer CRC:0 Onsite CRC: 0 Client CRC: 0 Internal Defects: 4 External Defects: 0 Reason for pending: GGO-14510 - Bootstrap update - Development and Testing from Offshore got completed, the automation flow broken with this bootstrap update, so Nate created a automation change ticket under this story and this got carry forwarded to next sprint.
A32: NA | B32: GGO 7.23.0 Sprint 1 | C32: 45723 | D32: 45736 | E32: 19 | F32: 19 | G32: 7/0 | I32: Continued EMV Implementation and Infrastructure updates Allowed 19 digit card entry in GGAM, GGO and PAPI Cleared some Macroscope issues in PAPI Fixed cache issue in GGO Accomplishments: Addiitionally completed Developemnt for stretch goal stories | J32: Peer CRC:0 Onsite CRC: 0 Client CRC: 0 Internal Defects: 0 External Defects: 0 | K32: Internal Retro 1. Sathiya/ Rajesh and Saranya for providing help to Priya testing the stories 2. Team for completing all the story points
A33: NA | B33: GGO 7.23.0 Sprint 2 | C33: 45736 | D33: 45750 | E33: 13 | F33: 19 | G33: 10/0 | I33: Completed Duplicate even code story and Invoice import and Invoice Payment Pages story Fixed Quartz Job access issues and Email Queue Issues. Accomplishments: Completing the development and testing for lot of stretch goal stories on the current sprint | J33: Peer CRC:0 Onsite CRC: 0 Client CRC: 0 Internal Defects: 2 External Defects: 0 Pending Story: 2 Stories has been carried forward 1.GGO-14573 -Hard to reproduce in the lower environements. The offshore developers made several attempts to reproduce the issue, but because it’s related to performance, it took a considerable amount of time to replicate. That’s why it got carried over. 2.PAPI-839(Stretch Goal) -Dependency on Onsite QA to complete it(Offshore QA has already completed testing for this story) | K33: Retro: 1.Rajesh for supporting multiple escalation issues 2.Sathiya/ Rajesh and Saranya for covering such a wide spread of stories 3.Priya for completing the testing for the planned as well as lot of stretch jiras
A34: NA | B34: GGO 7.23.0 Sprint 3 | C34: 45751 | D34: 45764 | E34: 22 | F34: 24 | G34: 6/0 | I34: Completed Multiple RSVP Imports Accomplishments: Did some Redis changes which was very challenging and OP to GGO import timeouts(which is a esclation ticket) Completing the development for the stretch goal stories on the current sprint | J34: Peer CRC:0 Onsite CRC: 0 Client CRC: 0 Internal Defects: 1 External Defects: 0 Pending Story: 2 stories has been carried forward which includes 1 stretch PAPI-840(8spt)and GGO-14644[Stretch] -Development for this story was completed three days ahead of the sprint deadline. However, a last-minute AC request from the client required code modifications, which were implemented the timeline.The story was left in Peer Review upon completion, per the client's request to hold it and maintain this branch separately from the CERT branch.Offshore QA has completed verification in the lower environment. The story is now pending validation from Onsite QA. | K34: Rajesh and offshore for taking the redis changes which was very challenging
A35: NA | B35: GGO 7.23.0 Sprint 4 | C35: 45765 | D35: 45778 | E35: 23 | F35: 27 | G35: 5/0 | I35: Accomplishments: Completed CRT testing Completed all planned stories and more Okta 1 Proof of concept Completed more macroscopic stories | J35: Peer CRC:0 Onsite CRC: 0 Client CRC: 0 Internal Defects: 1 External Defects: 0 Pending Story: 2 stories has been carried forward GGO-13722 ->we documented the alternative encryption change, client wanted to add new feature flag based on that need to follow the old and new encryption flow GGO-13723 ->we documented the alternative encryption change, client wanted to add new feature flag based on that need to follow the old and new encryption flow | K35: To the whole team for helping remove all the blockers for testing Rajesh and offshore for helping with the fallback cases Rajesh for assisting with integrating the Okta proof-of-concept
A36: NA | B36: GGO 7.24.0 Sprint 1 | C36: 45779 | D36: 45792 | E36: 19 | F36: 16 | G36: 2/0 | I36: Accomplishments: Old Amex certification testing Nav Bar Updation Fixed Dashboard generation Issue and Enabled Online Bidding for the same Fixed Export Sales issue Completed more macroscopic stories | J36: Peer CRC:0 Onsite CRC: 0 Client CRC: 0 Internal Defects: 0 External Defects: 0 Pending Story: 2 stories has been carried forward GGO-14628->Hard to reproduce in the lower environements. The offshore developers and QA's made several attempts to reproduce the issue, However, on the last day of the sprint,we found one way to reproduce it. But team need to ensure this after providing the solutions and to check whether this the cause of this issue. Team is still working on it.That’s why it got carried over. GGO-14656->Reskin-V2 is a complete overhaul of the existing Master Page. The new layout seamlessly integrates Telerik controls, Bootstrap, and Kendo UI CSS, ensuring an optimized, modern, and adaptive user experience across all devices. As part of this redesign, we need to explore which Telerik control is best suited for the requested layout to achieve the desired functionality and responsiveness. Its taking more time to complete this story | K36: Rajesh and Sathiyabharathi for working on the Nav bar update. Rajesh for helping with the Escalation issue
A37: NA | B37: GGO 7.24.0 Sprint 2 | C37: 45793 | D37: 45806 | E37: 26 | F37: 23 | I37: Accomplishments: Completed Pendo Implementation Completed Nav Bar Implementation Fixed Amex card disable for select organizations Fixed Sale Grid Export issue | J37: Peer CRC:0 Onsite CRC: 0 Client CRC: 0 Internal Defects: 0 External Defects: 0 Pending Story: 1 story has been carried forward GGO-14628->Hard to reproduce in the lower environements. The offshore developers and QA's made several attempts to reproduce the issue. Team is still working on it.That’s why it was put on hold as it is of low priority | K37: Rajesh and Sathiyabharathi for the Nav bar update. Rajesh and offshore team on the quick implementation of pendo. Mike Horihan gave Kudos for the quick Pendo implementation
A38: NA | B38: GGO 7.24.0 Sprint 3 | C38: 45806 | D38: 45820 | E38: 9 | F38: 9 | G38: 3 | I38: Accomplishments: Completed Donor Web APIproject setup Completed Integration test Project setup Completed API Authentication for Donor Web API | J38: Peer CRC:0 Onsite CRC: 0 Client CRC: 0 Internal Defects: 0 External Defects: 0 Pending story: 1 Story has been carried forward GDON-7 -> Stretch | K38: New Donor team for completing the project setup, build issue and the publish fix. They are quick in implementing the changes Rajesh for helping multiple offshore teams and get them all set up and going
A39: NA | B39: GGO 7.24.0 Sprint 4 | C39: 45820 | D39: 45834 | E39: 10 | F39: 10 | G39: 5 | I39: Accomplishments: Completed Account Information for Donor Web API Completed Profile Information for Donor Web API Completed project release and pipeline set up | J39: Peer CRC:0 Onsite CRC: 0 Client CRC: 0 Internal Defects: 0 External Defects: 0 Pending story: 1 Story has been carried forward GDON-11 -> Stretch | K39: Good progress on the Donor API. Donor team dev and QA for completing all the donor team stories
A40: NA | B40: GGO 7.25.0 Sprint 1 | C40: 45834 | D40: 45848 | E40: 8 | F40: 8 | G40: donor | J40: Peer CRC:0 Onsite CRC: 0 Client CRC: 0 Internal Defects: 0 External Defects: 0 Pending story: 2 Story has been carried forward GDON-12 -> Stretch GDON-13 -> Stretch
...

Sheet Unplanned Leaves
A2: Total Unplanned Leaves | B2: 0
B3: Resource Name
A4: Sprint Name | B4: Charles Infant Rabi | C4: Vishnu | D4: Remarks
A5: GGO 8.3.0 Sprint 1 (05-Feb-26 to 19-Feb-26) | B5: 0 | C5: 0
A6: GGO 8.3.0 Sprint 2 (19-Feb-26 to 05-Mar-26) | B6: 0.5 1 | C6: 0 | D6: Charles: Due to Fever (26/02) 2nd half Planned leave (05/03)
A7: GGO 8.3.0 Sprint 3 (05-Mar-26 to 19-Mar-26) | B7: 0.5 | C7: 1 | D7: Charles: Personal work (10/03) - 2nd half Vishnu: Personal reasons
A8: GGO 8.3.0 Sprint 4 (19-Mar-26 to 02-Apr-26) | B8: 1 | C8: 0 | D8: Charles: Planned leave (30/03)
A9: GGO 8.4.0 Sprint 1 (02-Apr-26 to 16-Apr-26) | B9: 0 | C9: 1 | D9: Vishnu: Personal work (16/04/2026)
A10: GGO 8.4.0 Sprint 2 (16-Apr-26 to 30-Apr-26) | B10: 0 | C10: 0
A11: GGO 8.4.0 Sprint 3 (30-Apr-26 to 14-May-26) | B11: 1 | C11: 0.5 | D11: Charles: Family Function (04/05/2026) Vishnu: Personal work (13/05/2026)
A18: Total | B18: 4 | C18: 2.5

Sheet  GGO 8.4.0 Sprint 4-Status
A1: S.No | B1: Application Name | C1: Sprint Start Date | D1: Sprint End Date | E1: Sprint | F1: Developer | G1: Story ID / Defect ID | H1: Description | I1: Status | J1: Estimated (sp) | K1: Actual (sp) | L1: Actual Hours Worklog | M1: Dev Start Date | N1: Dev End Date | O1: Unit testing | P1: Peer Tested By | Q1: Peer Tested Defects, if any | R1: Peer Reviewed By | S1: Peer Code Review Comments, if any | T1: PR Number/Link | U1: PR Created Date | V1: PR Approved Date | W1: Reviewer 1 | X1: Code Review Comments, if any | Y1: Reviewer 2 | Z1: Approved Date | AA1: Code Review Comments, if any2 | AB1: Internal PO - POV Comments | AC1: Client PO - POV Comments | AD1: Comments
A2: 1 | B2: GGO Donor Wave | C2: 46156 | D2: 46170 | E2: GGO 8.4.0 Sprint 4 | F2: Vishnu | G2: GDON-104 | H2: Donor API - Update GetBidderHouseHoldAndTableInfo to include the Member details for OB | I2: Being Developed | J2: 3 | M2: 46157
A3: 2 | B3: GGO Donor Wave | C3: 46156 | D3: 46170 | E3: GGO 8.4.0 Sprint 4 | F3: Vishnu | G3: GDON-105 | H3: Donor API - Include Image Url in the GetCheckIn Details API | I3: Refinement | J3: 2
A4: 3 | B4: GGO Donor Wave | C4: 46156 | D4: 46170 | E4: GGO 8.4.0 Sprint 4 | F4: Vishnu | G4: GDON-106 | H4: GGO - Indicate when a Supporter has a donor profile | I4: Refinement | J4: 3
A5: 4 | B5: GGO Donor Wave | C5: 46156 | D5: 46170 | E5: GGO 8.4.0 Sprint 4 | F5: Vishnu | G5: GDON-107 | H5: GGO - Indicate when a Donor Self Checks In | I5: Refinement | J5: 3

Sheet GGO 8.4.0 Sprint 3-Status
A1: S.No | B1: Application Name | C1: Sprint Start Date | D1: Sprint End Date | E1: Sprint | F1: Developer | G1: Story ID / Defect ID | H1: Description | I1: Status | J1: Estimated (sp) | K1: Actual (sp) | L1: Actual Hours Worklog | M1: Dev Start Date | N1: Dev End Date | O1: Unit testing | P1: Peer Tested By | Q1: Peer Tested Defects, if any | R1: Peer Reviewed By | S1: Peer Code Review Comments, if any | T1: PR Number/Link | U1: PR Created Date | V1: PR Approved Date | W1: Reviewer 1 | X1: Code Review Comments, if any | Y1: Reviewer 2 | Z1: Approved Date | AA1: Code Review Comments, if any2 | AB1: Internal PO - POV Comments | AC1: Client PO - POV Comments | AD1: Comments
A2: 1 | B2: GGO Donor Wave | C2: 46142 | D2: 46156 | E2: GGO 8.4.0 Sprint 3 | F2: Vishnu | G2: GDON-100 | H2: Donor API - Update table info in GetHousehold API call | I2: Completed | J2: 2 | K2: 2 | L2: 16.5 | M2: 46146 | N2: 46146 | O2: Done | P2: Charles | R2: Rajesh | T2: https://dev.azure.com/greatergiving/Greater%20Giving/_git/GGO/pullrequest/9529 | U2: 46146 | V2: 46146 | W2: Rajesh | Y2: Mccarty, Joseph | Z2: 46146 | AD2: Testing in TST env., completed on 05/05/2026 at 19:00 pm Working fine as expected / Updated the QA notes and comments in JIRA
A3: 2 | B3: GGO Donor Wave | C3: 46142 | D3: 46156 | E3: GGO 8.4.0 Sprint 3 | F3: Vishnu | G3: GDON-101 | H3: Donor Check In Settings | I3: Completed | J3: 3 | K3: 3 | L3: 34.5 | M3: 46147 | N3: 46149 | O3: Done | P3: Charles | R3: Rajesh | T3: https://dev.azure.com/greatergiving/Greater%20Giving/_git/GGO/pullrequest/9546 | U3: 46149 | V3: 46153 | W3: Rajesh | Y3: Mccarty, Joseph | Z3: 46153 | AD3: Dev completed on 07/05/2026 Testing in TST env., completed on 12/05/2026 at 16:30 pm Working fine as expected / Updated the QA notes and comments in JIRA
A4: 3 | B4: GGO Donor Wave | C4: 46142 | D4: 46156 | E4: GGO 8.4.0 Sprint 3 | F4: Vishnu | G4: GDON-102 | H4: Donor API - Update Online Bidding Activity API and cleanup | I4: Completed | J4: 2 | K4: 2 | L4: 30 | M4: 46150 | N4: 46153 | O4: Done | P4: Charles | R4: Rajesh | T4: https://dev.azure.com/greatergiving/Greater%20Giving/_git/GGO/pullrequest/9553 | U4: 46153 | V4: 46154 | W4: Rajesh | Y4: Mccarty, Joseph | Z4: 46154 | AD4: Testing in DEV env., - Completed on 12/05/2026 and 13/05/2026 It is working fine as expected. Updated the QA notes and comments in JIRA Unable to test in TST env., as the TST DONOR URL is not accessible
A5: 4 | B5: GGO Donor Wave | C5: 46142 | D5: 46156 | E5: GGO 8.4.0 Sprint 3 | F5: Vishnu | G5: GDON-103 | H5: Donor API - Checkin Supporter API | I5: Completed | J5: 2 | K5: 2 | L5: 34 | M5: 46154 | N5: 46155 | O5: Done | P5: Charles | R5: Rajesh | T5: https://dev.azure.com/greatergiving/Greater%20Giving/_git/GGO/pullrequest/9559 | U5: 46155 | V5: 46155 | W5: Rajesh | Y5: Mccarty, Joseph | Z5: 46155 | AD5: Testing in TST env., completed on 14/05/2026 at 14:00 pm Working fine as expected Will update the QA notes and comments shortly

Sheet GGO 8.4.0 Sprint 2-Status
A1: S.No | B1: Application Name | C1: Sprint Start Date | D1: Sprint End Date | E1: Sprint | F1: Developer | G1: Story ID / Defect ID | H1: Description | I1: Status | J1: Estimated (sp) | K1: Actual (sp) | L1: Actual Hours Worklog | M1: Dev Start Date | N1: Dev End Date | O1: Unit testing | P1: Peer Tested By | Q1: Peer Tested Defects, if any | R1: Peer Reviewed By | S1: Peer Code Review Comments, if any | T1: PR Number/Link | U1: PR Created Date | V1: PR Approved Date | W1: Reviewer 1 | X1: Code Review Comments, if any | Y1: Reviewer 2 | Z1: Approved Date | AA1: Code Review Comments, if any2 | AB1: Internal PO - POV Comments | AC1: Client PO - POV Comments | AD1: Comments
A2: 1 | B2: GGO Donor Wave | C2: 46128 | D2: 46142 | E2: GGO 8.4.0 Sprint 2 | F2: Vishnu | G2: GDON-94 | H2: Create an Event Details API | I2: Completed | J2: 3 | K2: 3 | L2: 46.5 | M2: 46133 | N2: 46136 | O2: Done | P2: Charles | R2: Rajesh | T2: https://dev.azure.com/greatergiving/Greater%20Giving/_git/GGO/pullrequest/9507 | U2: 46136 | V2: 46139 | W2: Rajesh | Y2: Mccarty, Joseph | Z2: 46139 | AD2: Working fine as expected in DEV env., Testing completed on 27/04/2026 20:30PM Testing in TST env., completed on 28/04/2026 17:00PM and it is working fine as expected
A3: 2 | B3: GGO Donor Wave | C3: 46128 | D3: 46142 | E3: GGO 8.4.0 Sprint 2 | F3: Vishnu | G3: GDON-95 | H3: Create a Tickets API | I3: Being Developed | J3: 5 | L3: 45.5 | M3: 46139 | N3: 46141 | O3: Done | P3: Charles | R3: Rajesh | T3: https://dev.azure.com/greatergiving/Greater%20Giving/_git/GGO/pullrequest/9515 | U3: 46141 | V3: 46141 | W3: Rajesh | Y3: Mccarty, Joseph | Z3: 46141 | AD3: Testing in TST env., Inprogress
A4: 3 | B4: GGO Donor Wave | C4: 46128 | D4: 46142 | E4: GGO 8.4.0 Sprint 2 | F4: Vishnu | G4: GDON-98 | H4: Donor API - Get Household members | I4: Completed | J4: 2 | K4: 2 | L4: 39.5 | M4: 46127 | N4: 46133 | O4: Done | P4: Charles | R4: Rajesh | T4: https://dev.azure.com/greatergiving/Greater%20Giving/_git/GGO/pullrequest/9490 | U4: 46133 | V4: 46134 | W4: Rajesh | Y4: Mccarty, Joseph | Z4: 46134 | AD4: Working fine as expected in DEV env., Testing completed on 22/04/2026 17:00PM Testing completed in TST env., 23/04/2026 18:30 PM and it is working fine as expected.
A5: 4 | B5: GGO Donor Wave | C5: 46128 | D5: 46142 | E5: GGO 8.4.0 Sprint 2 | F5: Rajesh | G5: GDON-99 | H5: Donor API - Update create account password to a random string instead of getting from Donor App | I5: Completed | J5: 1 | K5: 1 | L5: 9.5 | M5: 46128 | N5: 46129 | O5: Done | P5: Charles | R5: Rajesh | T5: https://dev.azure.com/greatergiving/Greater%20Giving/_git/GGO/pullrequest/9486 | U5: 46129 | V5: 46129 | W5: Rajesh | Y5: Mccarty, Joseph | Z5: 46129 | AD5: Working fine as expected in TST env., - Testing completed on 20/04/2026 17:30 PM

Sheet GGO 8.4.0 Sprint 1-Status
A1: S.No | B1: Application Name | C1: Sprint Start Date | D1: Sprint End Date | E1: Sprint | F1: Developer | G1: Story ID / Defect ID | H1: Description | I1: Status | J1: Estimated (sp) | K1: Actual (sp) | L1: Actual Hours Worklog | M1: Dev Start Date | N1: Dev End Date | O1: Unit testing | P1: Peer Tested By | Q1: Peer Tested Defects, if any | R1: Peer Reviewed By | S1: Peer Code Review Comments, if any | T1: PR Number/Link | U1: PR Created Date | V1: PR Approved Date | W1: Reviewer 1 | X1: Code Review Comments, if any | Y1: Reviewer 2 | Z1: Approved Date | AA1: Code Review Comments, if any2 | AB1: Internal PO - POV Comments | AC1: Client PO - POV Comments | AD1: Comments
A2: 1 | B2: GGO Donor Wave | C2: 46114 | D2: 46128 | E2: GGO 8.4.0 Sprint 1 | F2: Rajesh | G2: GDON-78 | H2: Create Text Template | I2: Completed | J2: 3 | K2: 3 | L2: 26.5 | M2: 46122 | N2: 46126 | O2: Done | P2: Charles | R2: Vishnu | T2: https://dev.azure.com/greatergiving/Greater%20Giving/_git/GGO/pullrequest/9466 | U2: 46126 | V2: 46126 | W2: Rajesh | Y2: Horihan, Mike | Z2: 46126 | AD2: Working fine as expected in both DEV & TST env.,
A3: 2 | B3: GGO Donor Wave | C3: 46114 | D3: 46128 | E3: GGO 8.4.0 Sprint 1 | F3: Vishnu | G3: GDON-93 | H3: Update Online Bidding to Recognize HH vs Individual Bidder keys | I3: Completed | J3: 3 | K3: 3 | L3: 32.5 | M3: 46121 | N3: 46125 | O3: Done | P3: Charles | R3: Rajesh | T3: https://dev.azure.com/greatergiving/Greater%20Giving/_git/GGO/pullrequest/9462 | U3: 46125 | V3: 46125 | W3: Rajesh | Y3: Mccarty, Joseph | Z3: 46125 | AD3: In DEV Testing Result is coming as True for both the Bidderkeys - Individual and Household 1. True should be come only for Household Bidderkey 2. And It should be False for Individual Bidderkey Fixed the above issue and completed testing in TST env., it is working fine as expected now
A4: 3 | B4: GGO Donor Wave | C4: 46114 | D4: 46128 | E4: GGO 8.4.0 Sprint 1 | F4: Vishnu | G4: GDON-96 | H4: Donor API - Get Account and Project Info By BidderKey | I4: Completed | J4: 3 | K4: 3 | L4: 26 | M4: 46118 | N4: 46120 | O4: Done | P4: Charles | R4: Rajesh | T4: https://dev.azure.com/greatergiving/Greater%20Giving/_git/GGO/pullrequest/9449 | U4: 46120 | V4: 46121 | W4: Rajesh | Y4: Horihan, Mike | Z4: 46122 | AD4: Working fine as expected in both DEV & TST env.,
A5: 4 | B5: GGO Donor Wave | C5: 46114 | D5: 46128 | E5: GGO 8.4.0 Sprint 1 | F5: VIshnu | G5: GDON-97 | H5: Donor API - AddressTypeId is always returning as Type 2 in GetCreditCards API | I5: Completed | J5: 2 | K5: 2 | L5: 35.5 | M5: 46113 | N5: 46118 | O5: Done | P5: Charles | R5: Rajesh | T5: https://dev.azure.com/greatergiving/Greater%20Giving/_git/GGO/pullrequest/9438 | U5: 46118 | V5: 46121 | W5: Rajesh | Y5: Horihan, Mike | Z5: 46121 | AA5: Is this the way normally determine first name and last name? | AD5: Working fine as expected in both DEV & TST env.,
A6: 5 | B6: GGO Donor Wave | C6: 46114 | D6: 46128 | E6: GGO 8.4.0 Sprint 1 [Stretch] | F6: VIshnu | G6: GDON-98 | H6: Donor API - Get Household members | I6: Being Developed | J6: 3 | L6: 9 | M6: 46127 | AD6: Being Developed

Sheet GGO 8.3.0 Sprint 4-Status
A1: S.No | B1: Application Name | C1: Sprint Start Date | D1: Sprint End Date | E1: Sprint | F1: Developer | G1: Story ID / Defect ID | H1: Description | I1: Status | J1: Estimated (sp) | K1: Actual (sp) | L1: Actual Hours Worklog | M1: Dev Start Date | N1: Dev End Date | O1: Unit testing | P1: Peer Tested By | Q1: Peer Tested Defects, if any | R1: Peer Reviewed By | S1: Peer Code Review Comments, if any | T1: PR Number/Link | U1: PR Created Date | V1: PR Approved Date | W1: Reviewer 1 | X1: Code Review Comments, if any | Y1: Reviewer 2 | Z1: Approved Date | AA1: Code Review Comments, if any2 | AB1: Internal PO - POV Comments | AC1: Client PO - POV Comments | AD1: Tester Comments | AE1: Developer comments | AF1: Remarks
A2: 1 | B2: GGO Donor Wave | C2: 46100 | D2: 46114 | E2: GGO 8.3.0 Sprint 4 | F2: Vishnu | G2: GDON-90 | H2: Donor API - Cleanup donor API's | I2: Completed | J2: 3 | K2: 3 | L2: 36 | M2: 46101 | N2: 46104 | O2: Done | P2: Charles | R2: Rajesh | T2: https://dev.azure.com/greatergiving/Greater%20Giving/_git/GGO/pullrequest/9397 | U2: 46104 | V2: 46104 | W2: Rajesh | Y2: Mccarty, Joseph | Z2: 46104 | AD2: Testing activity in TST env., - Completed on 24/03/2026 20:00PM | AE2: Dev started on 17/03/2026 Dev Completed on 23/03/2026 | AF2: Collection of APIs - Based on different scenarios - TST env.,
A3: 2 | B3: GGO Donor Wave | C3: 46100 | D3: 46114 | E3: GGO 8.3.0 Sprint 4 | F3: Vishnu | G3: GDON-91 | H3: Validate Generate receipt requester identity | I3: Completed | J3: 2 | K3: 2 | L3: 38.5 | M3: 46108 | N3: 46112 | O3: Done | P3: Charles | R3: Rajesh | T3: https://dev.azure.com/greatergiving/Greater%20Giving/_git/GGO/pullrequest/9418 | U3: 46112 | V3: 46113 | W3: Rajesh | Y3: Mccarty, Joseph | Z3: 46113 | AD3: Testing activity in DEV env., - Completed on 01/04/2026 13:00PM Testing activity in TSTenv., completed on 02/04/2026 - 16:00PM | AE3: Dev started on 27/03/2026 Dev Completed on 31/03/2026
A4: 3 | B4: GGO Donor Wave | C4: 46100 | D4: 46114 | E4: GGO 8.3.0 Sprint 4 | F4: Vishnu | G4: GDON-92 | H4: Donor API - Update profile and supporter email address based on change email request from donor app | I4: Completed | J4: 2 | K4: 2 | L4: 43 | M4: 46105 | N4: 46107 | O4: Done | P4: Charles | R4: Rajesh | T4: https://dev.azure.com/greatergiving/Greater%20Giving/_git/GGO/pullrequest/9407 | U4: 46107 | V4: 46107 | W4: Rajesh | Y4: Mccarty, Joseph | Z4: 46107 | AD4: Testing activity in DEV env., completed on 26/03/2026 - 20:00PM Testing activity in TSTenv., completed on 27/03/2026 - 21:00PM | AE4: Dev started on 24/03/2026 Dev Completed on 26/03/2026
A5: 4 | B5: GGO Donor Wave | C5: 46100 | D5: 46114 | E5: GGO 8.3.0 Sprint 4 | F5: Rajesh | G5: GDON-74 | H5: Create Email Template | I5: Completed | J5: 5 | K5: 5 | L5: 22.5 | M5: 46101 | N5: 46108 | O5: Done | P5: Charles | R5: Vishnu | T5: https://dev.azure.com/greatergiving/Greater%20Giving/_git/GGO/pullrequest/9418 | U5: 46112 | V5: 46112 | W5: Rajesh | Y5: Mccarty, Joseph | Z5: 46112 | AD5: Testing activity in DEV env., completed on 30/03/2026 - 20:00PM Testing activity in TSTenv., completed on 01/04/2026 - 16:00PM | AE5: Dev started on 20/03/2026 Dev Completed on 27/03/2026
A6: 4 | B6: GGO Donor Wave | C6: 46100 | D6: 46114 | E6: GGO 8.3.0 Sprint 4 [Stretch] | F6: Vishnu | G6: GDON-97 | H6: Donor API - AddressTypeId is always returning as Type 2 in GetCreditCards API | I6: Being Developed | J6: 2 | K6: 1 | L6: 10.5 | M6: 46113

Sheet GGO 8.3.0 Sprint 4-Defect
A1: S.No | B1: Sprint | C1: Story/Defect ID | D1: Parent Story | E1: Developer | F1: Issue Type | G1: Issue Description | H1: Priority | I1: Defect Source | J1: Type | K1: Status | L1: Root Cause Category | M1: Comments | N1: Found By | O1: RCA Comment | AD1: Tester Comments | AE1: Developer comments | AF1: Remarks
G2: NO Defects | AE2: Dev Started on 05-Feb-2026

Sheet GGO 8.3.0 Sprint 3-Status
A1: S.No | B1: Application Name | C1: Sprint Start Date | D1: Sprint End Date | E1: Sprint | F1: Developer | G1: Story ID / Defect ID | H1: Description | I1: Status | J1: Estimated (sp) | K1: Actual (sp) | L1: Actual Hours Worklog | M1: Dev Start Date | N1: Dev End Date | O1: Unit testing | P1: Peer Tested By | Q1: Peer Tested Defects, if any | R1: Peer Reviewed By | S1: Peer Code Review Comments, if any | T1: PR Number/Link | U1: PR Created Date | V1: PR Approved Date | W1: Reviewer 1 | X1: Code Review Comments, if any | Y1: Reviewer 2 | Z1: Approved Date | AA1: Code Review Comments, if any2 | AB1: Internal PO - POV Comments | AC1: Client PO - POV Comments | AD1: Tester Comments | AE1: Developer comments | AF1: Remarks
A2: 1 | B2: GGO Donor Wave | C2: 46086 | D2: 46100 | E2: GGO 8.3.0 Sprint 3 | F2: Vishnu | G2: GDON-84 | H2: Donor Settings - Project Name to cascade to Ob Settings | I2: Completed | J2: 1 | K2: 1 | L2: 6 | O2: Done | P2: Charles | R2: Rajesh | T2: https://dev.azure.com/greatergiving/Greater%20Giving/_git/GGO/pullrequest/9341 | U2: 46085 | W2: Rajesh | AD2: Testing activity in DEV env., completed on 27/02/2026 / 18:30PM Testing activity in TST env., completed on 06/03/2026 - 15:00PM | AE2: Dev completed on 04/03/2026
A3: 2 | B3: GGO Donor Wave | C3: 46086 | D3: 46100 | E3: GGO 8.3.0 Sprint 3 | F3: Rajesh/Vishnu | G3: GDON-81 | H3: Donor Checkout - Generate email and send receipt | I3: Completed | J3: 5 | K3: 5 | L3: 17.5 | M3: 46087 | N3: 46094 | O3: Done | P3: Charles | R3: Vishnu | T3: https://dev.azure.com/greatergiving/Greater%20Giving/_git/GGO/pullrequest/9377 | U3: 46097 | V3: 46097 | W3: Vishnu | Y3: Mccarty, Joseph | Z3: 46097 | AD3: Testing activity in DEV env., completed on 16/03/2026 - 12:00PM Testing activity in TSTenv., completed on 17/03/2026 - 17:00PM | AE3: Dev started on 06/03/2026 Dev completed on 16/03/2026
A4: 3 | B4: GGO Donor Wave | C4: 46086 | D4: 46100 | E4: GGO 8.3.0 Sprint 3 | F4: Vishnu | G4: GDON-88 | H4: Donor API - Common credit card model for both OnlineBidding and CreditCard APIs | I4: Completed | J4: 3 | K4: 3 | L4: 40.5 | M4: 46087 | N4: 46091 | O4: Done | P4: Charles | R4: Rajesh | T4: https://dev.azure.com/greatergiving/Greater%20Giving/_git/GGO/pullrequest/9353 | U4: 46091 | V4: 46092 | W4: Rajesh | Y4: Mccarty, Joseph | Z4: 46092 | AD4: Testing activity in DEV env., completed on 10/03/2026 - 21:00PM Testing activity in TST env.,Completed on 11/03/2026 - 20:00PM | AE4: Dev Started on 06/03/2026 Dev Completed on 10/03/2026
A5: 4 | B5: GGO Donor Wave | C5: 46086 | D5: 46100 | E5: GGO 8.3.0 Sprint 3 | F5: Vishnu | G5: GDON-89 | H5: Donor API - Add payment source "DonorEngage" to differentiate the payment from Donor App | I5: Completed | J5: 3 | K5: 3 | L5: 32 | M5: 46092 | N5: 46093 | O5: Done | P5: Charles | R5: Rajesh | T5: https://dev.azure.com/greatergiving/Greater%20Giving/_git/GGO/pullrequest/9370 | U5: 46093 | V5: 46094 | W5: Rajesh | Y5: Horihan, Mike | Z5: 46094 | AD5: Testing activity in DEV env., completed on 13/03/2026 - 15:00PM Testing activity in TST env.,Completed on 16/03/2026 - 16:00PM | AE5: Dev started on 11/03/2026 Dev Completed on 12/03/2026
A6: 4 | B6: GGO Donor Wave | C6: 46086 | D6: 46100 | E6: GGO 8.3.0 Sprint 3 [Stretch] | F6: Vishnu | G6: GDON-90 | H6: Donor API - Cleanup donor API's | I6: Being Developed | J6: 3 | L6: 44.5 | M6: 46098 | AE6: Dev started on 17/03/2026 Dev Completed on | AF6: Collection of APIs - Scenarios based - TST env.,

Sheet GGO 8.3.0 Sprint 3-Defect
A1: S.No | B1: Sprint | C1: Story/Defect ID | D1: Parent Story | E1: Developer | F1: Issue Type | G1: Issue Description | H1: Priority | I1: Defect Source | J1: Type | K1: Status | L1: Root Cause Category | M1: Comments | N1: Found By | O1: RCA Comment | AD1: Tester Comments | AE1: Developer comments | AF1: Remarks
G2: NO Defects | AE2: Dev Started on 05-Feb-2026

Sheet GGO 8.3.0 Sprint 2-Status
A1: S.No | B1: Application Name | C1: Sprint Start Date | D1: Sprint End Date | E1: Sprint | F1: Developer | G1: Story ID / Defect ID | H1: Description | I1: Status | J1: Estimated (sp) | K1: Actual (sp) | L1: Actual Hours Worklog | M1: Dev Start Date | N1: Dev End Date | O1: Unit testing | P1: Peer Tested By | Q1: Peer Tested Defects, if any | R1: Peer Reviewed By | S1: Peer Code Review Comments, if any | T1: PR Number/Link | U1: PR Created Date | V1: PR Approved Date | W1: Reviewer 1 | X1: Code Review Comments, if any | Y1: Reviewer 2 | Z1: Approved Date | AA1: Code Review Comments, if any2 | AB1: Internal PO - POV Comments | AC1: Client PO - POV Comments | AD1: Tester Comments | AE1: Developer comments | AF1: Remarks
A2: 1 | B2: GGO Donor Wave | C2: 46072 | D2: 46086 | E2: GGO 8.3.0 Sprint 2 | F2: Rajesh | G2: GDON-80 | H2: Donor Checkout - Generate Receipt | I2: Completed | J2: 1 | K2: 1 | L2: 19.5 | M2: 46065 | N2: 46072 | O2: Done | P2: Charles | R2: Vishnu | T2: https://dev.azure.com/greatergiving/Greater%20Giving/_git/GGO/pullrequest/9304 | U2: 46072 | W2: Vishnu | Y2: Horihan, Mike | Z2: 46072 | AA2: Question: Is this file needed? It looks like config values come from the appsettings.json file. | AD2: Testing activity completed in DEV env., on 19/02/2026 / 12:30PM Testing activity completed in TST env., on 20/02/2026 / 15:00PM | AE2: Dev completed on 19/02/2026
A3: 2 | B3: GGO Donor Wave | C3: 46072 | D3: 46086 | E3: GGO 8.3.0 Sprint 2 | F3: Vishnu | G3: GDON-84 | H3: Donor Settings - Project Name to cascade to Ob Settings | I3: Verify | J3: 3 | K3: 2 | L3: 31.5 | M3: 46083 | N3: 46085 | O3: Done | P3: Charles | R3: Rajesh | T3: https://dev.azure.com/greatergiving/Greater%20Giving/_git/GGO/pullrequest/9341 | U3: 46085 | W3: Rajesh | AD3: Testing activity completed in DEV env., on 27/02/2026 / 18:30PM Testing activity in TST env., completed on 06/03/2026 - 15:00PM | AE3: Dev completed on 04/03/2026
A4: 3 | B4: GGO Donor Wave | C4: 46072 | D4: 46086 | E4: GGO 8.3.0 Sprint 2 | F4: Vishnu | G4: GDON-86 | H4: Display self checkout badge in GGO Manage Sales & Payments | I4: Completed | J4: 3 | K4: 3 | L4: 4.5 | M4: 46078 | N4: 46080 | O4: Done | P4: Charles | R4: Rajesh | T4: https://dev.azure.com/greatergiving/Greater%20Giving/_git/GGO/pullrequest/9324 | U4: 46079 | W4: Rajesh | Y4: Horihan, Mike | Z4: 46083 | AD4: Testing activity completed in DEV env., on 27/02/2026 / 18:30PM Testing activity completed in TST env., on 03/03/2026 / 14:30PM | AE4: Dev completed on 02/03/2026
A5: 4 | B5: GGO Donor Wave | C5: 46072 | D5: 46086 | E5: GGO 8.3.0 Sprint 2 | F5: Vishnu | G5: GDON-87 | H5: Donor API - Update Charge Card using selected card in Donor App | I5: Completed | J5: 3 | K5: 3 | L5: 35.5 | M5: 46073 | N5: 46077 | O5: Done | P5: Charles | R5: Rajesh | T5: https://dev.azure.com/greatergiving/Greater%20Giving/_git/GGO/pullrequest/9316 | U5: 46077 | W5: Rajesh | Y5: Mccarty, Joseph | Z5: 46077 | AD5: Testing activity in TST env., completed on 25/02/2026 / 14:30 PM | AE5: Dev completed on 24/02/2026 | AF5: Found one issue while CreateCardPayment API - (Payment is not getting paid - Error type-1 - (Not found))
A6: 5 | B6: GGO Donor Wave | C6: 46072 | D6: 46086 | E6: GGO 8.3.0 Sprint 2 [Stretch] | F6: Vishnu | G6: GDON-88 | H6: Donor API - Common credit card model for both OnlineBidding and CreditCard APIs* | I6: Being Developed | J6: 3 | L6: 6.5 | M6: 46086

Sheet GGO 8.3.0 Sprint 1-Status
A1: S.No | B1: Application Name | C1: Sprint Start Date | D1: Sprint End Date | E1: Sprint | F1: Developer | G1: Story ID / Defect ID | H1: Description | I1: Status | J1: Estimated (sp) | K1: Actual (sp) | L1: Actual Hours Worklog | M1: Dev Start Date | N1: Dev End Date | O1: Unit testing | P1: Peer Tested By | Q1: Peer Tested Defects, if any | R1: Peer Reviewed By | S1: Peer Code Review Comments, if any | T1: PR Number/Link | U1: PR Created Date | V1: PR Approved Date | W1: Reviewer 1 | X1: Code Review Comments, if any | Y1: Reviewer 2 | Z1: Approved Date | AA1: Code Review Comments, if any2 | AB1: Internal PO - POV Comments | AC1: Client PO - POV Comments | AD1: Tester Comments | AE1: Developer comments | AF1: Remarks
A2: 1 | B2: GGO Donor Wave | C2: 46058 | D2: 46072 | E2: GGO 8.3.0 Sprint 1 | F2: Vishnu | G2: GDON-72 | H2: Create GGO Donor Project Settings | I2: Completed | J2: 5 | K2: 5 | L2: x | M2: 46058 | N2: 46065 | O2: Done | P2: Charles | Q2: View Donor Project Settings is enabled for all the Projects | R2: Rajesh | T2: https://dev.azure.com/greatergiving/Greater%20Giving/_git/GGO/pullrequest/9273 | U2: 46065 | V2: 46065 | W2: Rajesh | Y2: Mccarty, Joseph | Z2: 46065 | AD2: Testing activity in TST env., Completed on 16/02/2026 / 17:00 | AE2: Dev completed on 12-Feb-2026 | AF2: Issue found is fixed and verified again in TST env., - (View Donor Project Settings is enabled for all the Projects)
A3: 2 | B3: GGO Donor Wave | C3: 46058 | D3: 46072 | E3: GGO 8.3.0 Sprint 1 | F3: Rajesh | G3: GDON-80 | H3: Donor Checkout - Generate Receipt | I3: Peer Review | J3: 3 | L3: 36.5 | M3: 46065 | N3: 46071 | O3: Done | P3: Charles | R3: Rajesh | U3: 46072 | W3: Rajesh | Y3: Mccarty, Joseph | AD3: Testing activity in DEV env., Completed on 19/02/2026 / 12:30 | AE3: Dev completed on 18-Feb-2026
A4: 3 | B4: GGO Donor Wave | C4: 46058 | D4: 46072 | E4: GGO 8.3.0 Sprint 1 | F4: Vishnu | G4: GDON-83 | H4: Donor API - Update GetCheckout API to include Convenience Fee and Sale Payment Association flag | I4: Completed | J4: 3 | K4: 3 | L4: 32.5 | M4: 46066 | N4: 46070 | O4: Done | P4: Charles | R4: Rajesh | T4: https://dev.azure.com/greatergiving/Greater%20Giving/_git/GGO/pullrequest/9296 | U4: 46070 | V4: 46070 | W4: Rajesh | Y4: Mccarty, Joseph | Z4: 46070 | AD4: Testing activity in TST env., Completed on 18/02/2026 / 15:00 | AE4: Dev completed on 17-Feb-2026
A5: 4 | B5: GGO Donor Wave | C5: 46058 | D5: 46072 | E5: GGO 8.3.0 Sprint 1 | F5: Vishnu | G5: GDON-85 | H5: View Donor Project Settings is enabled for all the Projects | I5: Completed | J5: 1 | K5: 1 | M5: 46066 | N5: 46066 | O5: Done | P5: Charles | R5: Rajesh | T5: https://dev.azure.com/greatergiving/Greater%20Giving/_git/GGO/pullrequest/9285 | U5: 46066 | V5: 46066 | W5: Rajesh | Y5: Mccarty, Joseph | Z5: 46066 | AD5: Testing activity in TST env., Completed on 16/02/2026 / 17:00 | AE5: Dev completed on 13-Feb-2026

Sheet GGO 8.3.0 Sprint 1-Defect
A1: S.No | B1: Sprint | C1: Story/Defect ID | D1: Parent Story | E1: Developer | F1: Issue Type | G1: Issue Description | H1: Priority | I1: Defect Source | J1: Type | K1: Status | L1: Root Cause Category | M1: Comments | N1: Found By | O1: RCA Comment | AD1: Tester Comments | AE1: Developer comments | AF1: Remarks
G2: No Defects | AE2: Dev Started on 05-Feb-2026

Sheet GGO 8.2.0 Sprint 4-Status
A1: S.No | B1: Application Name | C1: Sprint Start Date | D1: Sprint End Date | E1: Sprint | F1: Developer | G1: Story ID / Defect ID | H1: Description | I1: Status | J1: Estimated (sp) | K1: Actual (sp) | L1: Actual Hours Worklog | M1: Dev Start Date | N1: Dev End Date | O1: Unit testing | P1: Peer Tested By | Q1: Peer Tested Defects, if any | R1: Peer Reviewed By | S1: Peer Code Review Comments, if any | T1: PR Number/Link | U1: PR Created Date | V1: PR Approved Date | W1: Reviewer 1 | X1: Code Review Comments, if any | Y1: Reviewer 2 | Z1: Approved Date | AA1: Code Review Comments, if any2 | AB1: Internal PO - POV Comments | AC1: Client PO - POV Comments | AD1: Tester Comments | AE1: Developer comments | AF1: Remarks
A2: 1 | B2: GGO Donor Wave | C2: 46044 | D2: 46058 | E2: GGO 8.2.0 Sprint 4 | F2: Vishnu | G2: GDON-71 | H2: Create GGO Org Settings | I2: Completed | J2: 5 | K2: 5 | L2: 53.5 | M2: 46045 | N2: 46051 | O2: Done | P2: Charles | R2: Rajesh | T2: https://dev.azure.com/greatergiving/Greater%20Giving/_git/GGO/pullrequest/9227 | U2: 46050 | V2: 46052 | W2: Rajesh | Y2: Mccarty, Joseph | Z2: 46052 | AD2: Testing activity has been completed in the DEV env., Done on 01/30/2026 - 17:30PM Testing activity has been completed in the TST env., Done on 02/02/2026 - 16:00PM | AE2: Dev completed on 29-Jan-2026 | AF2: Found few existing issues - when we go back from organization level
A3: 2 | B3: GGO Donor Wave | C3: 46044 | D3: 46058 | E3: GGO 8.2.0 Sprint 4 | F3: Vishnu | G3: GDON-82 | H3: Donor Checkout - Charge CC, create Payment record/association | I3: Completed | J3: 5 | K3: 5 | M3: 46052 | N3: 46056 | O3: Done | P3: Charles | R3: Rajesh | T3: https://dev.azure.com/greatergiving/Greater%20Giving/_git/GGO/pullrequest/9253 | U3: 46056 | V3: 46056 | W3: Rajesh | Y3: Mccarty, Joseph | Z3: 46056 | AD3: Testing activity has been completed in the TST env., Done on 02/05/2026 - 17:00PM | AE3: Dev completed on 03-Feb-2026
A4: 3 | B4: GGO Donor Wave | C4: 46044 | D4: 46058 | E4: GGO 8.2.0 Sprint 4 [Stretch] | F4: Vishnu | G4: GDON-72 | H4: Create GGO Donor Project Settings | I4: Being Developed | J4: 5 | L4: 12.5 | M4: 46058 | AE4: Dev Started on 05-Feb-2026

Sheet GGO 8.2.0 Sprint 4-Defect
A1: S.No | B1: Sprint | C1: Story/Defect ID | D1: Parent Story | E1: Developer | F1: Issue Type | G1: Issue Description | H1: Priority | I1: Defect Source | J1: Type | K1: Status | L1: Root Cause Category | M1: Comments | N1: Found By | O1: RCA Comment | AD1: Tester Comments | AE1: Developer comments | AF1: Remarks
G2: No Defects | AE2: Dev Started on 05-Feb-2026

Sheet GGO 8.2.0 Sprint 3-Status
A1: S.No | B1: Application Name | C1: Sprint Start Date | D1: Sprint End Date | E1: Sprint | F1: Developer | G1: Story ID / Defect ID | H1: Description | I1: Status | J1: Estimated (sp) | K1: Actual (sp) | L1: Actual Hours Worklog | M1: Dev Start Date | N1: Dev End Date | O1: Unit testing | P1: Peer Tested By | Q1: Peer Tested Defects, if any | R1: Peer Reviewed By | S1: Peer Code Review Comments, if any | T1: PR Number/Link | U1: PR Created Date | V1: PR Approved Date | W1: Reviewer 1 | X1: Code Review Comments, if any | Y1: Reviewer 2 | Z1: Approved Date | AA1: Code Review Comments, if any2 | AB1: Internal PO - POV Comments | AC1: Client PO - POV Comments | AD1: Tester Comments | AE1: Developer comments | AF1: Remarks
A2: 1 | B2: GGO Donor Wave | C2: 46030 | D2: 46044 | E2: GGO 8.2.0 Sprint 3 | F2: Vishnu | G2: GDON-68 | H2: Donor API - Include AddressTypeId and CompanyName in the GetProfileCreditCards API * | I2: Completed | J2: 1 | K2: 1 | L2: 12.5 | M2: 46027 | N2: 46030 | O2: Done | P2: Charles | R2: Rajesh | T2: https://dev.azure.com/greatergiving/Greater%20Giving/_git/GGO/pullrequest/9155 | U2: 46030 | V2: 46030 | W2: Rajesh | Y2: Mccarty, Joseph | Z2: 46030 | AD2: Testing activity has been completed in the TST env., Done on 01/09/2026 - 19:00PM
A3: 2 | B3: GGO Donor Wave | C3: 46030 | D3: 46044 | E3: GGO 8.2.0 Sprint 3 | F3: Vishnu | G3: GDON-73 | H3: Create GG API to send Checkout information to Donor Platform | I3: Completed | J3: 5 | K3: 5 | L3: 53.5 | M3: 46031 | N3: 46038 | O3: Done | P3: Charles | R3: Rajesh | T3: https://dev.azure.com/greatergiving/Greater%20Giving/_git/GGO/pullrequest/9178 | U3: 46038 | V3: 46041 | W3: Rajesh | Y3: Mccarty, Joseph | Z3: 46041 | AD3: Testing activity has been completed in the TST env., Done on 01/19/2026 - 21:00PM
A4: 3 | B4: GGO Donor Wave | C4: 46030 | D4: 46044 | E4: GGO 8.2.0 Sprint 3 | F4: Vishnu | G4: GDON-75 | H4: Donor API - Add Donation Sale for Donor | I4: Completed | J4: 3 | K4: 3 | L4: 33.5 | M4: 46038 | N4: 46042 | O4: Done | P4: Charles | R4: Rajesh | T4: https://dev.azure.com/greatergiving/Greater%20Giving/_git/GGO/pullrequest/9188 | U4: 46042 | V4: 46042 | W4: Rajesh | Y4: Mccarty, Joseph | Z4: 46042 | AD4: Testing activity has been completed in the DEV env., Done on 01/20/2026 - 19:20PM Testing activity has been completed in the TST env., Done on 01/21/2026 - 15:00PM
A5: 4 | B5: GGO Donor Wave | C5: 46030 | D5: 46044 | E5: GGO 8.2.0 Sprint 3 | F5: Vishnu | G5: GDON-79 | H5: GetOrCreateAccount API throws error when sending resettokenutc as null* | I5: Completed | J5: 2 | K5: 2 | L5: 19 | M5: 46043 | N5: 46044 | O5: Done | P5: Charles | R5: Rajesh | T5: https://dev.azure.com/greatergiving/Greater%20Giving/_git/GGO/pullrequest/9200 | U5: 46042 | V5: 46043 | W5: Rajesh | Y5: Mccarty, Joseph | Z5: 46043 | AD5: Testing activity has been completed in the TST env., Done on 01/22/2026 - 18:00PM

Sheet GGO 8.2.0 Sprint 3-Defect
A1: S.No | B1: Sprint | C1: Story/Defect ID | D1: Parent Story | E1: Developer | F1: Issue Type | G1: Issue Description | H1: Priority | I1: Defect Source | J1: Type | K1: Status | L1: Root Cause Category | M1: Comments | N1: Found By | O1: RCA Comment | AD1: Tester Comments | AE1: Developer comments | AF1: Remarks
G2: No Defects | AE2: Dev Started on 05-Feb-2026

Sheet GGO 8.2.0 Sprint 1-Status
A1: S.No | B1: Application Name | C1: Sprint Start Date | D1: Sprint End Date | E1: Sprint | F1: Developer | G1: Story ID / Defect ID | H1: Description | I1: Status | J1: Estimated (sp) | K1: Actual (sp) | L1: Actual Hours Worklog | M1: Dev Start Date | N1: Dev End Date | O1: Unit testing | P1: Peer Tested By | Q1: Peer Tested Defects, if any | R1: Peer Reviewed By | S1: Peer Code Review Comments, if any | T1: PR Number/Link | U1: PR Created Date | V1: PR Approved Date | W1: Reviewer 1 | X1: Code Review Comments, if any | Y1: Reviewer 2 | Z1: Approved Date | AA1: Code Review Comments, if any2 | AB1: Internal PO - POV Comments | AC1: Client PO - POV Comments | AD1: Comments | AE1: Remarks
A2: 1 | B2: GGO Donor Wave | C2: 46002 | D2: 46030 | E2: GGO 8.2.0 Sprint 1 | F2: Vishnu | G2: GDON-66 | H2: Donor API - Create Online Bidding Activity without Credit Card Info* | I2: Completed | J2: 5 | K2: 5 | L2: 66.5 | M2: 45996 | N2: 46009 | P2: Charles | R2: Rajesh | T2: https://dev.azure.com/greatergiving/Greater%20Giving/_git/GGO/pullrequest/9104 | U2: 46006 | V2: 46014 | W2: Rajesh | Y2: Mccarty, Joseph | Z2: 46014 | AD2: Testing activity has been completed in the DEV env., Done on 12/18/2025 - 17:00PM Testing activity has been completed in the TST env., Done on 12/24/2025 - 16:00PM | AE2: Coordinated with UI team and verified the following scenarios oba add profile update profile create account organization mapping process save credit card get credit card
A3: 2 | B3: GGO Donor Wave | C3: 46002 | D3: 46030 | E3: GGO 8.2.0 Sprint 1 | F3: Vishnu | G3: GDON-67 | H3: Disabled the Online Bidding activity creation process and hide the display of OB activities in GGAM based on flag | I3: Completed | J3: 5 | K3: 5 | L3: 105 | M3: 46010 | N3: 46024 | P3: Charles | R3: Rajesh | T3: https://dev.azure.com/greatergiving/Greater%20Giving/_git/GGO/pullrequest/9133 | U3: 46015 | V3: 46029 | W3: Rajesh | Y3: Mccarty, Joseph | Z3: 46029 | AD3: Testing activity has been completed in the DEV env., Done on 01/05/2026 - 18:00PM Testing activity has been completed in the TST env., Done on 01/07/2026 - 20:00PM
A4: 3 | B4: GGO Donor Wave | C4: 46002 | D4: 46030 | E4: GGO 8.2.0 Sprint 1 | F4: Vishnu | G4: GDON-68 | H4: Donor API - Include AddressTypeId and CompanyName in the GetProfileCreditCards API * | I4: Verify | J4: 2 | K4: 2 | L4: 19.5 | M4: 46027 | N4: 46030 | P4: Charles | R4: Rajesh

Sheet GGO 8.2.0 Sprint 1-Defect
A1: S.No | B1: Sprint | C1: Story/Defect ID | D1: Parent Story | E1: Developer | F1: Issue Type | G1: Issue Description | H1: Priority | I1: Defect Source | J1: Type | K1: Status | L1: Root Cause Category | M1: Comments | N1: Found By | O1: RCA Comment | AD1: Tester Comments | AE1: Developer comments | AF1: Remarks
G2: No Defects | AE2: Dev Started on 05-Feb-2026

Sheet GGO 8.1.0 Sprint 4-Status
A1: S.No | B1: Application Name | C1: Sprint Start Date | D1: Sprint End Date | E1: Sprint | F1: Developer | G1: Story ID / Defect ID | H1: Description | I1: Status | J1: Estimated (sp) | K1: Actual (sp) | L1: Actual Hours Worklog | M1: Dev Start Date | N1: Dev End Date | O1: Unit testing | P1: Peer Tested By | Q1: Peer Tested Defects, if any | R1: Peer Reviewed By | S1: Peer Code Review Comments, if any | T1: PR Number/Link | U1: PR Created Date | V1: PR Approved Date | W1: Reviewer 1 | X1: Code Review Comments, if any | Y1: Reviewer 2 | Z1: Approved Date | AA1: Code Review Comments, if any2 | AB1: Internal PO -POV Comments | AC1: Client PO -POV Comments | AD1: Comments | AE1: Remarks
A2: 1 | B2: GGO Donor Wave | C2: 45988 | D2: 46002 | E2: GGO 8.1.0 Sprint 4 | F2: Vishnu | G2: GDON-63 | H2: Create Donor Admin Page | I2: Completed | J2: 5 | K2: 5 | M2: 45988 | N2: 45994 | P2: Charles | R2: Rajesh | T2: https://dev.azure.com/greatergiving/Greater%20Giving/_git/GGO/pullrequest/9066 | U2: 45994 | V2: 45994 | W2: Rajesh | Y2: Mccarty, Joseph | Z2: 45994 | AD2: Testing activity has been completed in the TST env., Done on 12/04/2025 - 12:30PM
A3: 2 | B3: GGO Donor Wave | C3: 45988 | D3: 46002 | E3: GGO 8.1.0 Sprint 4 | F3: Vishnu | G3: GDON-65 | H3: Donor API - Validate Online Bidding activity and Card address before creating OB activity | I3: Completed | J3: 2 | K3: 2 | M3: 45994 | N3: 45995 | P3: Charles | R3: Rajesh | T3: https://dev.azure.com/greatergiving/Greater%20Giving/_git/GGO/pullrequest/9076 | U3: 45995 | V3: 45996 | W3: Rajesh | Y3: Mccarty, Joseph | Z3: 45996 | AD3: Testing activity has been completed in the TST env., Done on 12/09/2025 - 13:00PM
A4: 3 | B4: GGO Donor Wave | C4: 45988 | D4: 46002 | E4: GGO 8.1.0 Sprint 4 | F4: Vishnu | G4: GDON-66 | H4: Donor API - Create Online Bidding Activity without Credit Card Info* | I4: Being Developed | J4: 3 | M4: 45996 | P4: Charles | R4: Rajesh

Sheet GGO 8.1.0 Sprint 3-Status
A1: S.No | B1: Application Name | C1: Sprint Start Date | D1: Sprint End Date | E1: Sprint | F1: Developer | G1: Story ID / Defect ID | H1: Description | I1: Status | J1: Estimated (sp) | K1: Actual (sp) | L1: Actual Hours Worklog | M1: Dev Start Date | N1: Dev End Date | O1: Unit testing | P1: Peer Tested By | Q1: Peer Tested Defects, if any | R1: Peer Reviewed By | S1: Peer Code Review Comments, if any | T1: PR Number/Link | U1: PR Created Date | V1: PR Approved Date | W1: Reviewer 1 | X1: Code Review Comments, if any | Y1: Reviewer 2 | Z1: Approved Date | AA1: Code Review Comments, if any2 | AB1: Internal PO -POV Comments | AC1: Client PO -POV Comments | AD1: Comments | AE1: Remarks
A2: 1 | B2: GGO Donor Wave | C2: 45974 | D2: 45988 | E2: GGO 8.1.0 Sprint 3 | F2: Vishnu | G2: GDON-59 | H2: Donor API - Update the Response code for all the donor API based | I2: Completed | J2: 3 | M2: 45982 | N2: 45986 | P2: Charles | R2: Rajesh | T2: https://dev.azure.com/greatergiving/Greater%20Giving/_git/GGO/pullrequest/9048 | U2: 45986 | V2: 45986 | W2: Rajesh | Y2: Mccarty, Joseph | Z2: 45986 | AD2: Testing activity has been completed in the TST env., Done on 11/26/2025 - 17:30PM
