Workbook
Name Status: Config!$L$2:$L$5

Sheet Dashboard
A1: BOH

Sheet Scorecard
A1: Project Name | B1: GGO Web
A2: Engagement Model | B2: Relevantz Co Owned
A3: Overall Score | B3: =SUM(C8:C13) -> 0.99
A5: Current Sprint | B5: GGO 8.4.0 Sprint 2 (16-Apr-2026 to 30-Apr-2026)
A7: Metrics | B7: UnWeighted | C7: Weighted | D7: Notes | V7: Target
A8: Commitment Index | B8: =VLOOKUP($B$5,Table_1[#All],4) -> 1 | C8: ='QualityMetrics-Definition'!D2*B8 -> 0.25 | D8: =_xlfn.XLOOKUP($B$5,Data!A:A,Data!O:O) -> Merged GGO web and GGO Donor wave team report: GGO Donor wave: Completed all the assigned stories and more GGO Web: Completed all assigned stories. | K8: 0.25 | V8: 1
A9: Velocity | B9: =IF((VLOOKUP($B$5,Table_1[#Data],5)/Data!AK37)>1,"100%",(VLOOKUP($B$5,Table_1[#Data],5)/Data!AK37)) -> 100% | C9: ='QualityMetrics-Definition'!D3*B9 -> 0.2 | K9: 0.2 | V9: 0.95
A10: Defect-free Rate | B10: =1-IFERROR((VLOOKUP($B$5,Data!A1:N84,9)+VLOOKUP($B$5,Data!A1:N84,10))/VLOOKUP($B$5,Data!A1:N84,5),0) -> 1 | C10: =(B10)*'QualityMetrics-Definition'!D4 -> 0.2 | K10: 0.2 | V10: 1
A11: Code Quality Index | B11: =1-(VLOOKUP($B$5,Data!A1:N89,7)+VLOOKUP($B$5,Data!A1:N89,8))/VLOOKUP($B$5,Data!A1:N89,3) -> 1 | C11: =(B11)*'QualityMetrics-Definition'!D5 -> 0.15 | K11: 0.15 | V11: 1
A12: Unit Testing | B12: =VLOOKUP($B$5,Table_1[],6) -> 0.9 | C12: ='QualityMetrics-Definition'!D6*B12 -> 0.09 | K12: 0.1 | V12: 0.9
A13: Backlog Health | B13: =IF((VLOOKUP($B$5,Table_1[#All],11)/Data!K2)>1,"100%",(VLOOKUP($B$5,Table_1[#All],11)/Data!K2)) -> 1 | C13: ='QualityMetrics-Definition'!D7*B13 -> 0.1 | K13: 0.1 | V13: 1

Sheet Data
A1: Sprint | B1: Committed | C1: Delivered | D1: Commitment Index | E1: Velocity | F1: Code Coverage | G1: Code Review Comments - Internal | H1: Code Review Comments - External | I1: QA Defects | J1: Escaped Defects | K1: Backlog Health | L1: Last Sprint? | M1: Planned Leaves | N1: Availed Leaves | O1: Remarks | AF1: CommitmentIndex | AG1: Goal | AH1: Risk | AI1: Issue | AJ1: Velocity | AK1: Goal | AL1: Code Coverage | AM1: Goal | AN1: Backlog Health | AO1: Goal
A2: 7.17.0 Sprint 1 (22-Mar-2024 to 4-Apr-2024) | B2: 14 | C2: 11 | D2: =IF((C2/B2)>1,1,(C2/B2)) -> 0.78571429 | E2: 20 | F2: 0.9 | G2: 0 | H2: 0 | I2: 1 | J2: 0 | K2: 30 | L2: No | O2: 1 story got carried. Development completed and testing inprogress. Required Salesforce client team support for QA. | AG2: =Config!$J$2 -> 1 | AH2: =Config!$J$3 -> 0.9 | AI2: =Config!$J$4 -> 0.8 | AK2: =Config!$J$7 -> 20 | AM2: =Config!$J$10 -> 0.9 | AO2: 30
A3: 7.17.0 Sprint 2 (05-Apr -2024 to 18-Apr-2024) | B3: 19 | C3: 17 | D3: =IF((C3/B3)>1,1,(C3/B3)) -> 0.89473684 | E3: 20 | F3: 0.9 | G3: 0 | H3: 0 | I3: 0 | J3: 0 | K3: 30 | L3: No | O3: The scope of 1 carried story is only for testing and verified from our end in QA environment. Few scenarios having client dependancy to test in PAPI environment. | AG3: =Config!$J$2 -> 1 | AH3: =Config!$J$3 -> 0.9 | AI3: =Config!$J$4 -> 0.8 | AK3: =Config!$J$7 -> 20 | AM3: =Config!$J$10 -> 0.9 | AO3: 30
A4: 7.17.0 Sprint 3 (19-Apr-2024 to 02-May-2024) | B4: 18 | C4: 11 | D4: =IF((C4/B4)>1,1,(C4/B4)) -> 0.61111111 | E4: 20 | F4: 0.9 | G4: 0 | H4: 0 | I4: 0 | J4: 0 | K4: 25 | L4: No | O4: 2 stories got carried. 1. Due to salesforce team confirmed they can't do any changes. 2. Onshore Testing is pending | AG4: =Config!$J$2 -> 1 | AH4: =Config!$J$3 -> 0.9 | AI4: =Config!$J$4 -> 0.8 | AK4: =Config!$J$7 -> 20 | AM4: =Config!$J$10 -> 0.9 | AO4: 30
A5: 7.17.0 Sprint 4 (03-May -2024 to 16-May-2024) | B5: 14 | C5: 3 | D5: =IF((C5/B5)>1,1,(C5/B5)) -> 0.21428571 | E5: =AVERAGE(C2:C5) -> 10.5 | F5: 0.9 | G5: 0 | H5: 0 | I5: 0 | J5: 0 | K5: 25 | L5: No | O5: 3 stories got carried. | AG5: =Config!$J$2 -> 1 | AH5: =Config!$J$3 -> 0.9 | AI5: =Config!$J$4 -> 0.8 | AK5: =Config!$J$7 -> 20 | AM5: =Config!$J$10 -> 0.9 | AO5: 30
A6: 7.18.0 Sprint 1 (17-May-2024 to 30-May-2024) | B6: 15 | C6: 14 | D6: =IF((C6/B6)>1,1,(C6/B6)) -> 0.93333333 | E6: =AVERAGE(C3:C6) -> 11.25 | F6: 0.9 | G6: 0 | H6: 1 | I6: 0 | J6: 0 | K6: 25 | L6: No | AG6: =Config!$J$2 -> 1 | AH6: =Config!$J$3 -> 0.9 | AI6: =Config!$J$4 -> 0.8 | AK6: =Config!$J$7 -> 20 | AM6: =Config!$J$10 -> 0.9 | AO6: 30
A7: 7.18.0 Sprint 2 (31-May-2024 to 13-Jun-2024) | B7: 20 | C7: 16 | D7: =IF((C7/B7)>1,1,(C7/B7)) -> 0.8 | E7: =AVERAGE(C4:C7) -> 11 | F7: 0.9 | G7: 0 | H7: 0 | I7: 0 | J7: 0 | K7: 25 | L7: No | AG7: =Config!$J$2 -> 1 | AH7: =Config!$J$3 -> 0.9 | AI7: =Config!$J$4 -> 0.8 | AK7: =Config!$J$7 -> 20 | AM7: =Config!$J$10 -> 0.9 | AO7: 30
A8: 7.18.0 Sprint 3 (14-Jun-2024 to 27-Jun-2024) | B8: 17 | C8: 15 | D8: =IF((C8/B8)>1,1,(C8/B8)) -> 0.88235294 | E8: =AVERAGE(C5:C8) -> 12 | F8: 0.9 | G8: 0 | H8: 1 | I8: 0 | J8: 0 | K8: 25 | L8: No | AG8: =Config!$J$2 -> 1 | AH8: =Config!$J$3 -> 0.9 | AI8: =Config!$J$4 -> 0.8 | AK8: =Config!$J$7 -> 20 | AM8: =Config!$J$10 -> 0.9 | AO8: 30
A9: 7.18.0 Sprint 4 (28-Jun-2024 to 11-Jul-2024) | B9: 20 | C9: 20 | D9: =IF((C9/B9)>1,1,(C9/B9)) -> 1 | E9: =AVERAGE(C6:C9) -> 16.25 | F9: 0.9 | G9: 0 | H9: 1 | I9: 0 | J9: 0 | K9: 25 | L9: No | AG9: =Config!$J$2 -> 1 | AH9: =Config!$J$3 -> 0.9 | AI9: =Config!$J$4 -> 0.8 | AK9: =Config!$J$7 -> 20 | AM9: =Config!$J$10 -> 0.9 | AO9: 30
A10: 7.19.0 Sprint 1 (12-Jul-2024 to 25-Jul-2024) | B10: 15 | C10: 15 | D10: =IF((C10/B10)>1,1,(C10/B10)) -> 1 | E10: =AVERAGE(C7:C10) -> 16.5 | F10: 0.9 | G10: 0 | H10: 0 | I10: 0 | J10: 0 | K10: 25 | L10: No | AG10: =Config!$J$2 -> 1 | AH10: =Config!$J$3 -> 0.9 | AI10: =Config!$J$4 -> 0.8 | AK10: =Config!$J$7 -> 20 | AM10: =Config!$J$10 -> 0.9 | AO10: 30
A11: 7.19.0 Sprint 2 (26-Jul-2024 to 07-Aug-2024) | B11: 6 | C11: 6 | D11: =IF((C11/B11)>1,1,(C11/B11)) -> 1 | E11: =AVERAGE(C8:C11) -> 14 | F11: 0.9 | G11: 0 | H11: 0 | I11: 0 | J11: 0 | K11: 25 | L11: No | AG11: =Config!$J$2 -> 1 | AH11: =Config!$J$3 -> 0.9 | AI11: =Config!$J$4 -> 0.8 | AK11: =Config!$J$7 -> 20 | AM11: =Config!$J$10 -> 0.9 | AO11: 30
A12: 7.19.0 Sprint 3 (08-Aug-2024 to 22-Aug-2024) | B12: 16 | C12: 16 | D12: =IF((C12/B12)>1,1,(C12/B12)) -> 1 | E12: =AVERAGE(C9:C12) -> 14.25 | F12: 0.9 | G12: 0 | H12: 1 | I12: 0 | J12: 0 | K12: 25 | L12: No | AG12: =Config!$J$2 -> 1 | AH12: =Config!$J$3 -> 0.9 | AI12: =Config!$J$4 -> 0.8 | AK12: =Config!$J$7 -> 20 | AM12: =Config!$J$10 -> 0.9 | AO12: 30
A13: 7.19.0 Sprint 4 (23-Aug-2024 to 5-Sep-2024) | B13: 17 | C13: 14 | D13: =IF((C13/B13)>1,1,(C13/B13)) -> 0.82352941 | E13: =AVERAGE(C10:C13) -> 12.75 | F13: 0.9 | G13: 0 | H13: 0 | I13: 0 | J13: 0 | K13: 30 | L13: No | O13: Automation Regression story got carried over as it was new for Offshore QA and there was some learning curve involved. | AG13: =Config!$J$2 -> 1 | AH13: =Config!$J$3 -> 0.9 | AI13: =Config!$J$4 -> 0.8 | AK13: =Config!$J$7 -> 20 | AM13: =Config!$J$10 -> 0.9 | AO13: 30
A14: 7.20.0 Sprint 1 (5-Sep-2024 to 19-Sep-2024) | B14: 15 | C14: 13 | D14: =IF((C14/B14)>1,1,(C14/B14)) -> 0.86666667 | E14: =AVERAGE(C11:C14) -> 12.25 | F14: 0.9 | G14: 0 | H14: 3 | I14: 0 | J14: 0 | K14: 30 | L14: No | O14: 1 story got carried over to next sprint. Development and testing completed from our end, but onsite QA testing pending. | AG14: =Config!$J$2 -> 1 | AH14: =Config!$J$3 -> 0.9 | AI14: =Config!$J$4 -> 0.8 | AK14: =Config!$J$7 -> 20 | AM14: =Config!$J$10 -> 0.9 | AO14: 30
A15: 7.20.0 Sprint 2 (19-Sep-2024 to 3-Oct-2024) | B15: 19 | C15: 14 | D15: =IF((C15/B15)>1,1,(C15/B15)) -> 0.73684211 | E15: =AVERAGE(C12:C15) -> 14.25 | F15: 0.9 | G15: 0 | H15: 0 | I15: 0 | J15: 0 | K15: 30 | L15: No | O15: GGO-14067 got carried, We are migrating Bid-03 report to new RDLC framework, there is lot of existing logic present in RPT file. we need to exactly replicate same logic in SQL stored procedure for new RDLC format.understanding .rpt file logic is complication involved | AG15: =Config!$J$2 -> 1 | AH15: =Config!$J$3 -> 0.9 | AI15: =Config!$J$4 -> 0.8 | AK15: =Config!$J$7 -> 20 | AM15: =Config!$J$10 -> 0.9 | AO15: 30
A16: 7.20.0 Sprint 3 (3-Oct -2024 to 17-Oct-2024) | B16: 17 | C16: 12 | D16: =IF((C16/B16)>1,1,(C16/B16)) -> 0.70588235 | E16: =AVERAGE(C13:C16) -> 13.25 | F16: 0.9 | G16: 0 | H16: 0 | I16: 0 | J16: 0 | K16: 30 | L16: No | O16: Bid-03 report has a lot of functionalities and turned out to be more complex than planned
A17: 7.20.0 Sprint 4 (17-Oct-2024 to 31-Oct-2024) | B17: 16 | C17: 13 | D17: =IF((C17/B17)>1,1,(C17/B17)) -> 0.8125 | E17: =AVERAGE(C14:C17) -> 13 | F17: 0.9 | G17: 0 | H17: 0 | I17: 1 | J17: 0 | K17: 30 | L17: No | O17: Bid-03 report, Getting Timeout issue for large records
A18: 7.21.0 Sprint 1 (31-Oct-2024 to 14-Nov-2024) | B18: 18 | C18: 17 | D18: =IF((C18/B18)>1,1,(C18/B18)) -> 0.94444444 | E18: =AVERAGE(C15:C18) -> 14 | F18: 0.9 | G18: 0 | H18: 0 | I18: 2 | J18: 0 | K18: 30 | L18: No | O18: Onsite QA testing pending, development was completed on time
A19: 7.21.0 Sprint 2(14-Nov-2024 to 25-Nov-2024) | B19: 14 | C19: 11 | D19: =IF((C19/B19)>1,1,(C19/B19)) -> 0.78571429 | E19: =AVERAGE(C16:C19) -> 13.25 | F19: 0.9 | G19: 0 | H19: 1 | I19: 0 | J19: 0 | K19: 30 | L19: No | O19: Azure CRT testing is blocked because of Azure image access issue and a ticket with Microsoft has been opened
A20: 7.21.0 Sprint 3 (25-Nov-2024 to 12-Dec-2024) | B20: 14 | C20: 14 | D20: =IF((C20/B20)>1,1,(C20/B20)) -> 1 | E20: =AVERAGE(C17:C20) -> 13.75 | F20: 0.9 | G20: 0 | H20: 0 | I20: 0 | J20: 0 | K20: 30 | L20: No
A21: GGO 7.21.0 Sprint 4 (12-Dec -2024 to 9-Jan-2025) | B21: 24 | C21: 19 | D21: =IF((C21/B21)>1,1,(C21/B21)) -> 0.79166667 | E21: =AVERAGE(C18:C21) -> 15.25 | F21: 0.9 | G21: 0 | H21: 0 | I21: 8 | J21: 0 | K21: 30 | L21: No | O21: GGO-14427 - BID-06 - Part-3 story is a huge effort, this has got more than 100 scenario's, so it took more time for testing left out with 2 bugs at the end of sprint (development done for the bugs) only testing pending.
A22: GGO 7.22.0 Sprint 1 (9-Jan-2025 to 23-Jan-2025) | B22: 21 | C22: 17 | D22: =IF((C22/B22)>1,1,(C22/B22)) -> 0.80952381 | E22: =AVERAGE(C19:C22) -> 15.25 | F22: 0.9 | G22: 0 | H22: 0 | I22: 6 | J22: 0 | K22: 30 | L22: No | O22: GGO-14422, PAPI-789 - Development and Testing completed from our end, Pending testing from Nate (Onsite QA) because he was focusing more in CRT regression. GGO-14447 - Automation story completed from our end, pending review from Nate GGO-14450 - A.C change one day prior to Sprint end date, so it got carry forward to next sprint
A23: GGO 7.22.0 Sprint 2 (23-Jan-2025 to 6-Feb-2025) | B23: 18 | C23: 11 | D23: =IF((C23/B23)>1,1,(C23/B23)) -> 0.61111111 | E23: =AVERAGE(C20:C23) -> 15.25 | F23: 0.9 | G23: 0 | H23: 0 | I23: 0 | J23: 1 | K23: 30 | L23: No | O23: Testing is pending by Onsite QA and we completed the stories (GGO-14503, GGO-14450) and deployed to TST 2 days prior Sprint end, that's the reason these stories got rolled over to next sprint. | AG23: =Config!$J$2 -> 1 | AH23: =Config!$J$3 -> 0.9 | AI23: =Config!$J$4 -> 0.8 | AK23: =Config!$J$7 -> 20 | AM23: =Config!$J$10 -> 0.9 | AO23: 30
A24: GGO 7.22.0 Sprint 3 (6-Feb-2025 to 20-Feb-2025) | B24: 18 | C24: 8 | D24: =IF((C24/B24)>1,1,(C24/B24)) -> 0.44444444 | E24: =AVERAGE(C21:C24) -> 13.75 | F24: 0.9 | G24: 0 | H24: 2 | I24: 4 | J24: 1 | K24: 30 | L24: No | O24: 2 stories got carried over GGO-14504 - The story was given Onisite QA for testing 3 days before the end of Sprint but Onsite QA logged bug on the last day of Thesprint. It was fixed and deployed before sprint prep, QA didn't get time to complete it. GGO-14070 - Development took a lot of time and got completed only on 1 day before Sprint end, the offshore QA logged a minor bug on the last day of sprint, fixed the bug and PR created for review. (Saranya worked on the RDLC report for the first time and there was a learning curve involved which took time)
A25: GGO 7.22.0 Sprint 4 (20-Feb-2025 to 6-Mar-2025) | B25: 20 | C25: 15 | D25: =IF((C25/B25)>1,1,(C25/B25)) -> 0.75 | E25: =AVERAGE(C22:C25) -> 12.75 | F25: 0.9 | G25: 0 | H25: 0 | I25: 4 | J25: 0 | K25: 30 | L25: No | O25: 1 Story GGO-14510 - Bootstrap update got rolled over- Development and Testing from Offshore got completed, the automation flow broken with this bootstrap update, so Nate created a automation change ticket under this story and this got carry forwarded to next sprint.
A26: GGO 7.23.0 Sprint 1 (6-Mar-2025 to 20-Mar-2025) | B26: 19 | C26: 19 | D26: =IF((C26/B26)>1,1,(C26/B26)) -> 1 | E26: =AVERAGE(C23:C26) -> 13.25 | F26: 0.9 | G26: 0 | H26: 0 | I26: 0 | J26: 0 | K26: 30 | L26: No | O26: All planned stories completed
A27: GGO 7.23.0 Sprint 2 (20-Mar-2025 to 3-Apr-2025) | B27: 13 | C27: 19 | D27: =IF((C27/B27)>1,1,(C27/B27)) -> 1 | E27: =AVERAGE(C24:C27) -> 15.25 | F27: 0.9 | G27: 0 | H27: 0 | I27: 2 | J27: 0 | K27: 30 | L27: No | O27: 2 Stories has been carried forward and 2 QA defects found 1.GGO-14573 -Hard to reproduce in the lower environements. The offshore developers made several attempts to reproduce the issue, but because it’s related to performance, it took a considerable amount of time to replicate. That’s why it got carried over. 2.PAPI-839[Stretch] -Dependency on Onsite QA to complete it 3. GGO-14626 and GGO-14621- Due to access rule configuration Issue for Quartz job server and Aesop Service bounce email not validated in Send Grid. | AG27: =Config!$J$2 -> 1 | AH27: =Config!$J$3 -> 0.9 | AI27: =Config!$J$4 -> 0.8 | AK27: =Config!$J$7 -> 20 | AM27: =Config!$J$10 -> 0.9 | AO27: 30
A28: GGO 7.23.0 Sprint 3 (3-Apr-2025 to 17-Apr-2025) | B28: 22 | C28: 24 | D28: =IF((C28/B28)>1,1,(C28/B28)) -> 1 | E28: =AVERAGE(C25:C28) -> 19.25 | F28: 0.9 | G28: 0 | H28: 0 | I28: 1 | J28: 0 | K28: 30 | L28: No | O28: "1 assigned and 1 stretch Stories has been carried forward and 1 QA defects found 1.PAPI-840(8spt)and GGO-14644[Stretch] -Development for this story was completed three days ahead of the sprint deadline. However, a last-minute AC request from the client required code modifications, which were implemented the timeline.The story was left in Peer Review upon completion, per the client's request to hold it and maintain this branch separately from the CERT branch.Offshore QA has completed verification in the lower environment. The story is now pending validation from Onsite QA. 2. QA Defect - GGO-14633 Code mistakenly overwritten for GGO-14457.The team addressed the issue promptly, and the defect was resolved and closed on the same day. | AG28: =Config!$J$2 -> 1 | AH28: =Config!$J$3 -> 0.9 | AI28: =Config!$J$4 -> 0.8 | AK28: =Config!$J$7 -> 20 | AM28: =Config!$J$10 -> 0.9 | AO28: 30
A29: GGO 7.23.0 Sprint 4 (17-Apr-2025 to 01-May-2025) | B29: 23 | C29: 27 | D29: =IF((C29/B29)>1,1,(C29/B29)) -> 1 | E29: =AVERAGE(C26:C29) -> 22.25 | F29: 0.9 | G29: 0 | H29: 0 | I29: 1 | J29: 0 | K29: 30 | L29: No | O29: 2 stories has been carried forward additional stretch stories completed by the team to compensate. GGO-13722 and GGO-13723 ->we documented the alternative encryption change, client wanted to add new feature flag based on that need to follow the old and new encryption flow | AG29: =Config!$J$2 -> 1 | AH29: =Config!$J$3 -> 0.9 | AI29: =Config!$J$4 -> 0.8 | AK29: =Config!$J$7 -> 20 | AM29: =Config!$J$10 -> 0.9 | AO29: 30
A30: GGO 7.24.0 Sprint 1 (1-May-2025 to 15-May-2025) | B30: 19 | C30: 16 | D30: =IF((C30/B30)>1,1,(C30/B30)) -> 0.84210526 | E30: =AVERAGE(C27:C30) -> 21.5 | F30: 0.9 | G30: 0 | H30: 0 | I30: 0 | J30: 1 | K30: 30 | L30: No | O30: 2 assigned stories has been carried forward GGO-14628 ->Hard to reproduce in the lower environements. The offshore developers and QA's made several attempts to reproduce the issue, However, on the last day of the sprint,we found one way to reproduce it. But team need to ensure this after providing the solutions and to check whether this the cause of this issue. Team is still working on it.That’s why it got carried over. GGO-14656->Reskin-V2 is a complete overhaul of the existing Master Page. The new layout seamlessly integrates Telerik controls, Bootstrap, and Kendo UI CSS, ensuring an optimized, modern, and adaptive user experience across all devices. As part of this redesign, we need to explore which Telerik control is best suited for the requested layout to achieve the desired functionality and responsiveness. So it is taking more time for the team to complete this story 1 Production Issue - GGO-14678-This is a production issue. The export sale grid functionality broke due to changes in the SLS report. Team completed this on the same day and pushed the code for the CRT testing. | AG30: =Config!$J$2 -> 1 | AH30: =Config!$J$3 -> 0.9 | AI30: =Config!$J$4 -> 0.8 | AK30: =Config!$J$7 -> 20 | AM30: =Config!$J$10 -> 0.9 | AO30: 30
A31: GGO 7.24.0 Sprint 2 (16-May-2025 to 29-May-2025) | B31: 26 | C31: 23 | D31: =IF((C31/B31)>1,1,(C31/B31)) -> 0.88461538 | E31: =AVERAGE(C28:C31) -> 22.5 | F31: 0.9 | G31: 0 | H31: 0 | I31: 0 | J31: 0 | K31: 30 | L31: No | O31: GGO-14628->Hard to reproduce in the lower environements. The offshore developers and QA's made several attempts to reproduce the issue. Team is still working on it.That’s why it was put on hold as it is of low priority | AG31: =Config!$J$2 -> 1 | AH31: =Config!$J$3 -> 0.9 | AI31: =Config!$J$4 -> 0.8 | AK31: =Config!$J$7 -> 20 | AM31: =Config!$J$10 -> 0.9 | AO31: 30
A32: GGO 7.24.0 Sprint 3 (29-May-2025 to 12-Jun-2025) | B32: 23 | C32: 15 | D32: =IF((C32/B32)>1,1,(C32/B32)) -> 0.65217391 | E32: =AVERAGE(C29:C32) -> 20.25 | F32: 0.9 | G32: 0 | H32: 0 | I32: 3 | J32: 0 | K32: 30 | L32: No | O32: GGO web and GGO Donor wave team report: 2 assigned stories has been carried forward GGO-14682 and GGO-14683 - Reskin-V2 is a complete overhaul of the existing Master Page.Its taking more time to complete this since UI design work is new to the development team and it is bit challenging too.Also for GGO-14682 ->Development took a lot of time and got completed only on 1 day before Sprint end, the offshore QA logged a bug on the last day of sprint. One 5 point story GGO-14724 moved to backlog because we do not have access to OneTrust Privay Policy Center and discussions are still ongoing on the client side. So Client has been moved this story to the backlog GGO Donor wave: Completed all the assigned setup stories | AG32: =Config!$J$2 -> 1 | AH32: =Config!$J$3 -> 0.9 | AI32: =Config!$J$4 -> 0.8 | AK32: =Config!$J$7 -> 20 | AM32: =Config!$J$10 -> 0.9 | AO32: 30
A33: GGO 7.24.0 Sprint 4 (12-Jun-2025 to 26-Jun-2025) | B33: 32 | C33: 32 | D33: =IF((C33/B33)>1,1,(C33/B33)) -> 1 | E33: =AVERAGE(C30:C33) -> 21.5 | F33: 0.9 | G33: 0 | H33: 0 | I33: 0 | J33: 0 | K33: 30 | L33: No | O33: GGO web and GGO Donor wave team report: Completed all the assigned stories. No defects and CRC. | AG33: =Config!$J$2 -> 1 | AH33: =Config!$J$3 -> 0.9 | AI33: =Config!$J$4 -> 0.8 | AK33: =Config!$J$7 -> 20 | AM33: =Config!$J$10 -> 0.9 | AO33: 30
A34: GGO 7.25.0 Sprint 1 (26-Jun-2025 to 10-Jul-2025) | B34: 28 | C34: 18 | D34: =IF((C34/B34)>1,1,(C34/B34)) -> 0.64285714 | E34: =AVERAGE(C31:C34) -> 22 | F34: 0.9 | G34: 0 | H34: 0 | I34: 0 | J34: 0 | K34: 30 | L34: No | O34: Merged GGO web and GGO Donor wave team report: GGO Donor wave: Completed all the assigned stories. No defects and CRC. GGO Web: 2 stories has been carried forward as we are currently working on the reskinning of the grid component. Development is taking more time to complete this since UI design work is new to the development team and it is bit challenging too. Once this is completed, the remaining stories for the upcoming sprints are expected to progress quickly. Informed to client as well. No defects and CRC. | AG34: =Config!$J$2 -> 1 | AH34: =Config!$J$3 -> 0.9 | AI34: =Config!$J$4 -> 0.8 | AK34: =Config!$J$7 -> 20 | AM34: =Config!$J$10 -> 0.9 | AO34: 30
A35: GGO 7.25.0 Sprint 2 (10-Jul-2025 to 24-Jul-2025) | B35: 38 | C35: 25 | D35: =IF((C35/B35)>1,1,(C35/B35)) -> 0.65789474 | E35: =AVERAGE(C32:C35) -> 22.5 | F35: 0.9 | G35: 0 | H35: 0 | I35: 3 | J35: 0 | K35: 30 | L35: No | O35: Merged GGO web and GGO Donor wave team report: GGO Donor wave: Completed all the assigned stories. No defects and CRC. GGO Web: 3 stories carried forward GGO-14688 - Can't able to complete the task as planned due to changes in the new layout design, which introduced additional controls and complexity. Also, another story GGO-14687 required more time than anticipated, which impacted the overall timeline." GGO-14802 - Development is completed. During testing,tester found 3 defects. 2 defects and this story also got carried forward. GGO-14724: Client requested to add few more things in the same story at the end of the sprint end. | AG35: =Config!$J$2 -> 1 | AH35: =Config!$J$3 -> 0.9 | AI35: =Config!$J$4 -> 0.8 | AK35: =Config!$J$7 -> 20 | AM35: =Config!$J$10 -> 0.9 | AO35: 30
A36: GGO 7.25.0 Sprint 3 (24-Jul-2025 to 07-Aug-2025) | B36: 37 | C36: 27 | D36: =IF((C36/B36)>1,1,(C36/B36)) -> 0.72972973 | E36: =AVERAGE(C33:C36) -> 25.5 | F36: 0.9 | G36: 0 | H36: 0 | I36: 1 | J36: 0 | K36: 30 | L36: No | O36: Merged GGO web and GGO Donor wave team report: GGO Donor wave: Completed all the assigned stories. No defects and CRC. GGO Web: 2 stories carried forward GGO-14712 and GGO-14851- The design challenges in this story prevent us from reusing existing user controls in every controls | AG36: =Config!$J$2 -> 1 | AH36: =Config!$J$3 -> 0.9 | AI36: =Config!$J$4 -> 0.8 | AK36: =Config!$J$7 -> 20 | AM36: =Config!$J$10 -> 0.9 | AO36: 30
A37: GGO 7.25.0 Sprint 4 (07-Aug-2025 to 21-Aug-2025) | B37: 29 | C37: 28 | D37: =IF((C37/B37)>1,1,(C37/B37)) -> 0.96551724 | E37: =AVERAGE(C34:C37) -> 24.5 | F37: 0.9 | G37: 1 | H37: 1 | I37: 2 | J37: 0 | K37: 30 | L37: No | O37: Merged GGO web and GGO Donor wave team report: GGO Donor wave: 1 story got carried forward. Pending with Onsite client QA. GGO Web : Completed all the assigned stories. | AG37: =Config!$J$2 -> 1 | AH37: =Config!$J$3 -> 0.9 | AI37: =Config!$J$4 -> 0.8 | AK37: =Config!$J$7 -> 20 | AM37: =Config!$J$10 -> 0.9 | AO37: 30
A38: GGO 8.0.0 Sprint 1 (21-Aug-2025 to 04-Sep-2025) | B38: 30 | C38: 31 | D38: =IF((C38/B38)>1,1,(C38/B38)) -> 1 | E38: =AVERAGE(C35:C38) -> 27.75 | F38: 0.9 | G38: 0 | H38: 0 | I38: 1 | J38: 0 | K38: 30 | L38: No | O38: Merged GGO web and GGO Donor wave team report: GGO Donor wave: Completed all the assigned stories. GGO Web :GGO-14875 - Onsite Dev-Mike Wall picked this story earlier did some basic changes due to design difficulties hand overed the story to offshore on 1-sep-25 and also So far, we’ve worked on implementing grid controls across all modules. The team is currently focused on the Create Pages as part of the redesign effort, which is taking additional time due to the complexity of the UI work. GGO - 14854 - Stretch stories - Development and Dev env testing completed from our QA. Pending for Review. | AG38: =Config!$J$2 -> 1 | AH38: =Config!$J$3 -> 0.9 | AI38: =Config!$J$4 -> 0.8 | AK38: =Config!$J$7 -> 20 | AM38: =Config!$J$10 -> 0.9 | AO38: 30
A39: GGO 8.0.0 Sprint 2 (04-Aug-2025 to 18-Sep-2025) | B39: 27 | C39: 26 | D39: =IF((C39/B39)>1,1,(C39/B39)) -> 0.96296296 | E39: =AVERAGE(C36:C39) -> 28 | F39: 0.9 | G39: 0 | H39: 0 | I39: 1 | J39: 0 | K39: 30 | L39: No | O39: Merged GGO web and GGO Donor wave team report: GGO Donor wave: Completed all the assigned stories. GGO Web : 1 assigned story carried forward Due to complications involving multiple user controls on the filter page, some functions within the new user control are not triggering as expected. Additionally, new controls were added which require further integration and testing to ensure smooth functionality. | AG39: =Config!$J$2 -> 1 | AH39: =Config!$J$3 -> 0.9 | AI39: =Config!$J$4 -> 0.8 | AK39: =Config!$J$7 -> 20 | AM39: =Config!$J$10 -> 0.9 | AO39: 30
A40: GGO 8.0.0 Sprint 3 (18-Sep-2025 to 2-Oct-2025) | B40: 22 | C40: 24 | D40: =IF((C40/B40)>1,1,(C40/B40)) -> 1 | E40: =AVERAGE(C37:C40) -> 27.25 | F40: 0.9 | G40: 0 | H40: 0 | I40: 1 | J40: 0 | K40: 30 | L40: No | O40: Merged GGO web and GGO Donor wave team report: GGO Donor wave: Completed all the assigned stories and more GGO Web : Completed all the assigned stories. NO RCA
...

Sheet RCA
H1: 3 Why Analysis
A2: Sl.No | B2: Issue/ Date | C2: Sprint Date (DD-MMM-YY to DD-MMM-YY) | D2: Issue Description | E2: Issue Type | F2: Root Cause category | G2: Sub category | H2: Why 1? | I2: Why 2? | J2: Why 3? | K2: Action ( Issue /Risk mitigation plan) | L2: Owner | M2: Status | N2: Target Date | O2: Comments | W2: Root Cause category
A3: 1 | B3: 45399 | C3: 7.17.0 Sprint 2 (05 Apr to 18 Apr) | D3: 1 Story Testing got carried | E3: Internal | F3: Metric Deviation | G3: Commitment Index Deviation | H3: Few scenarios having client dependancy to test in PAPI environment, which is uncontrol. | K3: Client was well aware of their dependancy to test in PAPI environment and informed in team standup. | L3: Priya | M3: Closed | N3: 45404 | W3: Metric Deviation
A4: 2 | B4: 45428 | C4: 7.17.0 Sprint 4 (03 May to 16 May) | D4: Commitment index 21% acheived. 3 stories got carried. | E4: External | F4: Metric Deviation | G4: Commitment Index Deviation | H4: Client IT team has to do some configuration to resolve the environment issue. | I4: pogo | K4: Similar type of requirement has to identified and informed with client in well advance. | L4: Sathiyabharathi | M4: Closed | N4: 45432 | W4: Metric Deviation
A5: 3 | B5: 45470 | C5: 7.18.0 Sprint 3 (14 Jun to 27 Jun) | D5: Client reported 1 CRC | E5: External | F5: Metric Deviation | G5: Codding STD Missed | H5: Fix typo/misspell privilege. | I5: Cosmetic error | K5: Knowledge share with Team in Stand Up, So that similar type of issue can be mitigated. | L5: Rajesh/Sathiyabharathi | M5: Closed | N5: 45471 | W5: Metric Deviation
A6: 4 | B6: 45454 | C6: 7.18.0 Sprint 3 (28 Jun to 11 Jul) | D6: Client reported 1 CRC | E6: External | F6: Metric Deviation | G6: Codding STD Missed | H6: Replace "" with string.Empty | I6: Cosmetic error | K6: Knowledge share with Team in Stand Up, So that similar type of issue can be mitigated. | L6: Saranya/Sathiyabharathi | M6: Closed | N6: 45455 | W6: Others
A7: 5 | B7: 45525 | C7: 7.19.0 Sprint 3 (08 Aug to 22 Aug) | D7: Client reported 1 CRC | E7: External | F7: Metric Deviation | G7: Code review comment | H7: NVARCHAR(MAX) should not be used with Split. | K7: Knowledge share with Team in Stand Up, So that similar type of issue can be mitigated. | L7: Saranya/Rajesh/Sathiya | M7: Closed | N7: 45525
A8: 6 | B8: 45540 | C8: 7.19.0 Sprint 4 (22 Aug to 5 Sep) | D8: 1 Story got rolled over | E8: Internal | F8: Metric Deviation | H8: Automation Regression story got carried over as it was new for Offshore QA and there was some learning curve involved. | K8: New to Automation regression and part of learning curve | L8: Sathiyabharthi | M8: Closed | N8: 45540
A9: 7 | B9: 45554 | C9: 7.20.0 Sprint 1(5 Sep to 19 Sep) | D9: 1 Story Testing from Onsite QA got carried | E9: External | F9: Metric Deviation | G9: Commitment Index Deviation | H9: We gave the pull request 2 days before the sprint end and offshore also completed testing but Client QA was busy with testing of other stories and couldn't complete this one. | I9: Unplanned PTO for Sathiyabharathi | K9: Dev resource will try assisting client QA to complete the testing | L9: Sathiyabharthi | M9: Closed | N9: 45554
A10: 8 | B10: 45568 | C10: 7.20.0 Sprint 2( 19 Sep to 3 Oct) | D10: 1 Story got rolled over | E10: Internal | F10: Metric Deviation | G10: Commitment Index Deviation | H10: GGO-14067 got carried, We are migrating Bid-03 report to new RDLC framework, there is lot of existing logic present in RPT file. we need to exactly replicate same logic in SQL stored procedure for new RDLC format.understanding .rpt file logic is complication involved | K10: Learning curve involved for the new RDLC tool | L10: Rajesh/Sathiyabharathi | M10: Closed | N10: 45610
A11: 9 | B11: 45582 | C11: 7.20.0 Sprint 3 (3 Oct to 17 Oct) | D11: 1 Story got rolled over | E11: Internal | F11: Metric Deviation | G11: Commitment Index Deviation | H11: GGO-14067 got carried, We are migrating Bid-03 report to new RDLC framework, there is lot of complex functionalities which needs more time | K11: Team continues learning the old reports to implement in the new toolset which requires continuous customer feedback | L11: Rajesh/Sathiyabharathi/ Saranya | M11: Closed | N11: 45610
A12: 10 | B12: 45596 | C12: 7.20.0 Sprint 4 (17 Oct to 31 Oct) | D12: 1 Story got rolled over | E12: Internal | F12: Metric Deviation | G12: Commitment Index Deviation | H12: GGO-14067 got carried, Getting Timeout issue for large records | K12: It is the most complex report and given it is one of the 1st reports the team continues to understand the functionality | L12: Rajesh/Sathiyabharathi/ Saranya | M12: Closed | N12: 45610
A13: 11 | B13: 45610 | C13: 7.21.0 Sprint 1 (31 Oct to 14 Nov) | D13: 1 Story got rolled over | E13: External | F13: Metric Deviation | G13: Commitment Index Deviation | H13: GGO-14295 got carried, Onsite QA testing pending | K13: Onsite QA dependency | L13: Rajesh | M13: Closed | N13: 45610
A14: 12 | B14: 45621 | C14: 7.21.0 Sprint 2 (14 Nov to 25 Nov) | D14: 1 Story got rolled over | E14: External | F14: Metric Deviation | G14: Commitment Index Deviation | H14: GGO-13319 got carried, blocked by access issue | K14: Onsite DevOps dependency | L14: Priya | M14: Closed | N14: 45621
A15: 13 | B15: 45666 | C15: 7.21.0 Sprint 4 (12 Dec to 9 Jan) | D15: 1 Story got rolled over | E15: Internal | F15: Metric Deviation | G15: Commitment Index Deviation | H15: GGO-14427 - BID-06 - Part-3 story is a huge effort, this has got more than 100 scenario's, so it took more time for testing left out with 2 bugs at the end of sprint (development done for the bugs) only testing pending. | K15: Complex Report with infinite test data combination. Additional testing from Dev to solve QA challenges | L15: Rajesh/Sathiyabharathi/Saranya/Priya | M15: Closed | N15: 45666
A16: 14 | B16: 45680 | C16: 7.22.0 Sprint 1 ( 9 Janto 23 Jan) | D16: 4 Stories got rolled over | E16: External | F16: Metric Deviation | G16: Commitment Index Deviation | H16: GGO-14422, PAPI-789 - Development and Testing completed from our end, Pending testing from Nate (Onsite QA) because he was focusing more in CRT regression. GGO-14447 - Automation story completed from our end, pending review from Nate GGO-14450 - A.C change one day prior to Sprint end date, so it got carry forward to next sprint | K16: Dependent on Onsite QA | L16: Rajesh/Sathiyabharathi/Saranya/Priya | M16: Closed | N16: 45680
A17: 15 | B17: 45694 | C17: 7.22.0 Sprint 2 (23 Jan to 6 Feb) | D17: 2 Stories got rolled over | E17: External | F17: Metric Deviation | G17: Commitment Index Deviation | H17: Testing is pending by Onsite QA and we completed the stories (GGO-14503, GGO-14450) and deployed to TST 2 days prior Sprint end, that's the reason these stories got rolled over to next sprint. | K17: Dependent on Onsite QA and the onsite QA was strecthched because of multiple unplanned PTO's from offshore QA Priya and onsite QA Manager Owen due to family emergency | L17: Rajesh/Sathiyabharathi/Saranya/Priya | M17: Closed | N17: 45694
A18: 16 | B18: 45694 | C18: 7.22.0 Sprint 2 (23 Jan to 6 Feb) | D18: 1 production escalation | E18: Internal/External | F18: Metric Deviation | G18: Defect free Rate | H18: Production Issue for invoice report - GGO 14529 The old report generation handled it but the new report didn't so a miss on testing end | K18: Extended testing needs to be done with a lot more combination of data | L18: Priya | M18: Closed | N18: 45694
A19: 17 | B19: 45708 | C19: 7.22.0 Sprint 3 6 Feb to 20 Feb) | D19: 2 Stories got rolled over | E19: Internal/External | F19: Metric Deviation | G19: Commitment Index Deviation | H19: 1) GGO-14504 - The story was given Onisite QA for testing 3 days before the end of Sprint but Onsite QA logged bug on the last day of Thesprint. It was fixed and deployed before sprint prep, QA didn't get time to complete it. 2)GGO-14070 - Development took a lot of time and got completed only on 1 day before Sprint end, the offshore QA logged a minor bug on the last day of sprint, fixed the bug and PR created for review. (Saranya worked on the RDLC report for the first time and there was a learning curve involved which took time) | K19: Going forward this learning curve will help complete reports on time | L19: Saranya | M19: Closed | N19: 45708 | O19: Beacause of the hotfix the team couldn't complete the testing of tickets
A20: 18 | B20: 45722 | C20: 7.22.0 Sprint 4 20 Feb to 6 Mar) | D20: 1 Stories got rolled over | E20: External | F20: Metric Deviation | G20: Commitment Index Deviation | H20: 1 Story GGO-14510 - Bootstrap update got rolled over- Development and Testing from Offshore got completed, the automation flow broken with this bootstrap update, so Nate created a automation change ticket under this story and this got carry forwarded to next sprint. | K20: Onsite QA needs to fix automation test to complete the final round of testing | M20: Closed | N20: 45728 | O20: Dependency on Onsite QA to complete it
A21: 19 | B21: 45750 | C21: 7.23.0 Sprint 2 (20-Mar-2025 to 3-Apr-2025) | D21: 1 Story got rolled over | E21: Internal/External | F21: Metric Deviation | G21: We took other Stretch tickets and compensated on that | H21: 1 Story GGO-14573 -The offshore developers made several attempts to reproduce the issue, but because it’s related to performance, it took a considerable amount of time to replicate. That’s why it was carried over. | K21: Hard to reproduce in lower environments. To mitigate the issues, Going forward we will enhance performance monitoring and implement parallel testing where possible to reduce dependencies and replicate the issue more efficiently. | L21: Rajesh/Sathiyabharathi/ Saranya | M21: Closed | N21: 45764
A22: 20 | B22: 45764 | C22: 7.23.0 Sprint 3 (3-Apr-2025 to 17-Apr-2025) | D22: 1 assigned Story got rolled over | E22: Internal/External | F22: Metric Deviation | G22: Commitment Index Deviation | H22: 1 Assigned Story PAPI-840(8spt)Development for this story was completed three days ahead of the sprint deadline. However, a last-minute AC request from the client required code modifications, which were implemented the timeline.The story was left in Peer Review upon completion, per the client's request to hold it and maintain this branch separately from the CERT branch.Offshore QA has completed verification in the lower environment. The story is now pending validation from Onsite QA. | I22: Client Requirements got changed | K22: PAPI-840(8spt): Due to last-minute AC changes, it took additional time to complete develpment and testing, and to prevent similar delays in the future, we are enhancing our review and validation process. | L22: Rajesh/Sathiyabharathi/ Saranya/Priya | M22: Closed | N22: 45778
A23: 21 | B23: 45764 | C23: 7.23.0 Sprint 3 (3-Apr-2025 to 17-Apr-2025) | D23: QA Defect | E23: Internal/External | F23: Metric Deviation | G23: Defect | H23: QA Defect - GGO-14633 Code mistakenly overwritten for GGO-14457. The team addressed the issue promptly, and the defect was resolved and closed on the same day. | I23: Minor Changes in the code | K23: QA Defect - GGO-14457 - Going forward team will make sure these kinds of overwrites will not be repeated and will do the review process accordingly . Onsite Reviewer Checklist should have impact of Code - Reviwer checklist has to enahnced | L23: Rajesh/Sathiyabharathi/ Saranya/Priya | M23: Closed | N23: 45778
A24: 22 | B24: 45792 | C24: 7.24.0 Sprint 1 (1-May-2025 to 15-May-2025) | D24: 2 assigned Story got rolled over and 1 QA defect found | E24: Internal | F24: Metric Deviation | G24: Commitment Index Deviation | H24: 2 stories has been carried forward GGO-14656: This issue has proven difficult to reproduce in lower environments. Despite multiple attempts by the offshore developers and QA team throughout the sprint, a reproducible scenario was only identified on the last day. The team now needs to validate the proposed solution and confirm whether this scenario is indeed the root cause. Investigation and testing are still in progress, which is why the story was carried over to the next sprint. GGO-14628: Reskin-V2 involves a comprehensive redesign of the existing Master Page. The new layout integrates Telerik controls, Bootstrap, and Kendo UI CSS to deliver a modern, responsive user experience across devices. As part of the redesign, the team is evaluating the most appropriate Telerik controls to meet layout and functionality requirements. This exploration and implementation process is more time-consuming than anticipated, leading to the story being carried forward. | I24: Unable to Reproduce for one story and Reskin work for the other story | K24: GGO-14656: Prioritize reproducibility with targeted debugging and confirm fix with early QA involvement. GGO-14628: Conduct rapid prototyping of UI components and align frequently with design to avoid delays. | L24: Rajesh/Sathiyabharathi/ Saranya/Priya | M24: Closed | N24: 45806
A25: 23 | B25: 45792 | C25: 7.24.0 Sprint 1 (1-May-2025 to 15-May-2025) | D25: 1 production issue | E25: External | F25: Metric Deviation | G25: Defect free Rate | H25: GGO-14678-This is a production issue. The export sale grid functionality broke due to changes in the SLS report. Team completed this on the same day and pushed the code for the CRT testing. | I25: Minor DB changes impacted the other part of front end UI | K25: For every small change implemented, a complete regression testing cycle must be performed to ensure system stability. This includes updating both automation and manual test cases to reflect any new or impacted scenarios. Additionally, thorough verification of all buttons across all application pages must be included, and corresponding scenarios should be documented and maintained in the manual test cases to ensure comprehensive coverage. | L25: Rajesh/Sathiyabharathi/ Saranya/Priya | M25: Closed | N25: 45806
A26: 24 | B26: 45806 | C26: 7.24.0 Sprint 2 (16-May-2025 to 29-May-2025) | D26: 1 Story got rolled over | E26: internal/External | F26: Metric Deviation | G26: Commitment Index Deviation | H26: GGO-14628 Issue not reproduceable in Dev and TST.Need to check query execution CRT | K26: The work around has been provided and ticket has been put on hold for now as it only impacts only one client/org and is of low priority | L26: Rajesh | M26: Closed
A27: 25 | B27: 45820 | C27: 7.24.0 Sprint 2 (29-May-2025 to 12-June-2025) | D27: 2 assigned Story got rolled over | E27: Internal | F27: Metric Deviation | G27: Commitment Index Deviation | H27: GGO-14682 and GGO-14683 - Reskin-V2 is a complete overhaul of the existing Master Page.Its taking more time to complete this since UI design work is new to the development team and it is bit challenging too.Also for GGO-14682 ->Development took a lot of time and got completed only on 1 day before Sprint end, the offshore QA logged a bug on the last day of sprint. One 5 point story GGO-14724 moved to backlog because we do not have access to OneTrust Privay Policy Center and discussions are still ongoing on the client side. So Client has been moved this stroy to the backlog | I27: Application Reskin | K27: Team continues learning the UI design to implement the same | L27: Rajesh/Sathiyabharathi/ Saranya/Priya | M27: Closed | N27: 45834
A28: 26 | B28: 45820 | C28: 7.24.0 Sprint 2 (29-May-2025 to 12-June-2025) | D28: 1 Internal Defects | E28: Internal | F28: Metric Deviation | G28: Defect free Rate | H28: GGO-14763 ->UI design work is new to the development team and it is bit challenging too. | I28: Cosmetic error | K28: Team continues learning the UI design to implement the same | L28: Rajesh/Sathiyabharathi/ Saranya/Priya | M28: Closed | N28: 45834
A29: 27 | B29: 45848 | C29: 7.25.0 Sprint 1 (26-Jun-2025 to 10-Jul-2025) | D29: 2 assigned Stories got rolled over | E29: Internal | F29: Metric Deviation | G29: Commitment Index Deviation | H29: 2 stories has been carried forward as we are currently working on the reskinning of the grid component. Development is taking more time to complete this since UI design work is new to the development team and it is bit challenging too. Once this is completed, the remaining stories for the upcoming sprints are expected to progress quickly. Informed to client as well. No defects and CRC. | I29: Application Reskin | K29: Reskin - Team continues learning the UI design to implement the same | L29: Rajesh/Sathiyabharathi/ Saranya/Priya | M29: Closed | N29: 45862
A30: 28 | B30: 45862 | C30: 7.25.0 Sprint 2 (10-Jul-2025 to 24-Jul-2025) | D30: 2 assigned Stories got rolled over | E30: Internal | F30: Metric Deviation | G30: Commitment Index Deviation | H30: 3 stories carried forward GGO-14688 - Can't able to complete the task as planned due to changes in the new layout design, which introduced additional controls and complexity. Also, another story GGO-14687 required more time than anticipated, which impacted the overall timeline." GGO-14802 - Development is completed. During testing,tester found 3 defects. 2 defects and this story also got carried forward. GGO-14724: Client requested to add few more things in the same story at the end of the sprint end. | I30: Application Reskin | K30: Team is continuing development on the supporter grid, which remains challenging as this is the base work for the ongoing redesign. Additionally, Tester have reported a few bugs, and the team is actively working on resolving them. We have already communicated these updates to the client. | L30: Rajesh/Sathiyabharathi/ Saranya/Priya | M30: Closed | N30: 45876
A31: 29 | B31: 45862 | C31: 7.25.0 Sprint 2 (10-Jul-2025 to 24-Jul-2025) | D31: 1 Internal Defects | E31: Internal | F31: Metric Deviation | G31: Defect free Rate | H31: GGO-14802 -UI design work is new to the development team and it is bit challenging too. During testing,tester found 3 defects. 2 defects and this story also got carried forward. | I31: Application Reskin | K31: Moving forward, Developers will also do proper Unit testing before pushing this to TST env.These defects will be prioritized early in the next sprint with better coordination to avoid future defects. | L31: Rajesh/Sathiyabharathi/ Saranya/Priya | M31: Closed | N31: 45876
A32: 30 | B32: 45876 | C32: 7.25.0 Sprint 3 (24-Jul-2025 to 7-Aug-2025) | D32: 2 assigned Stories got rolled over | E32: Internal | F32: Metric Deviation | G32: Commitment Index Deviation | H32: Mergerd GGO web and GGO Donor wave team report: GGO Donor wave: Completed all the assigned stories. No defects and CRC. GGO Web: 2 stories carried forward GGO-14712 and GGO-14851- The design challenges in this story prevent us from reusing existing user controls in every controls | I32: Application Reskin | K32: Team is continuing development on the supporter page and filters page, which remains challenging as this is the base work for the ongoing redesign. | L32: Rajesh/Sathiyabharathi/ Saranya/Priya | M32: Closed | N32: 45890
A33: 31 | B33: 45890 | C33: 7.25.0 Sprint 4 (7-Aug-2025 to 21-Aug-2025) | D33: 1 assigned Story got rolled over | E33: Internal | F33: Metric Deviation | G33: Commitment Index Deviation | H33: Mergerd GGO web and GGO Donor wave team report: GGO Donor wave: 1 story got carried forward. Pending with Onsite client QA. | I33: Pending with onsite client QA | K33: Don 18 -will be prioritized early in the next sprint with better coordination to avoid future delays. | L33: Vishnu,Charles | M33: Closed | N33: 45904
A34: 32 | B34: 45890 | C34: 7.25.0 Sprint 4 (7-Aug-2025 to 21-Aug-2025) | D34: 5 internal and 1 external CRC - Considering all the cosmetic comments as "1" and External as 1 | E34: Internal/External | F34: Metric Deviation | G34: Code review comment | H34: Considering all the cosmetic comments as "5" 1. Correct the params here 2. Correct the param here 3. Don't we have to check teamCoordinator is not null here before accessing its property 4. correct the param name here 5. Why are we keeping empty class here? remove it if not needed 1 External : Remove Semicolon | I34: Cosmetic Errors,Developers missed to follow coding standards | K34: . The CRC comments are addressed and resolved. Team was informed. Knowledge share with Team in Stand Up, So that similar type of suggestion can be mitigated | L34: Vishnu,Charles,Kannan,Ubaithula | M34: Closed | N34: 45890
A35: 33 | B35: 45904 | C35: GGO 8.0.0 Sprint 1 (21-Aug-2025 to 04-Sep-2025) | D35: 1 assigned Story got rolled over | E35: Internal | F35: Metric Deviation | G35: Commitment Index Deviation | H35: GGO Web :GGO-14875 - Onsite Dev-Mike Wall picked this story earlier did some basic changes due to design difficulties hand overed the story to offshore on 1-sep-25 and also So far, we’ve worked on implementing grid controls across all modules. The team is currently focused on the Create Pages as part of the redesign effort, which is taking additional time due to the complexity of the UI work. | K35: GGO-14875-will be prioritized early in the next sprint with better coordination to avoid future delays. | L35: Rajesh/Sathiyabharathi/ Saranya/Priya | M35: Closed | N35: 45918
A36: 34 | B36: 45918 | C36: GGO 8.0.0 Sprint 2 (04-Aug-2025 to 18-Sep-2025) | D36: 1 assigned Story got rolled over | E36: Internal | F36: Metric Deviation | G36: Commitment Index Deviation | H36: GGO Web :1 assigned story carried forward Due to complications involving multiple user controls on the filter page, some functions within the new user control are not triggering as expected. Additionally, new controls were added which require further integration and testing to ensure smooth functionality. | K36: GGO-14980 -will be prioritized early in the next sprint with better coordination to avoid future delays. | L36: Rajesh/Sathiyabharathi/ Saranya/Priya | M36: Closed | N36: 45918
A37: 35 | B37: 45960 | C37: GGO 8.1.0 Sprint 1 (16-Oct-2025 to 30-Oct-2025) | D37: 1 assigned Story got rolled over | E37: Internal | F37: Metric Deviation | G37: Commitment Index Deviation | H37: Pending: 1 assigned story carried forward GGO-14901 - Since the design is more complex and focused on group items by household functionality in the view supporters filter | K37: Team is continuing development on the Manage Images popup. will be prioritized and close this one in the next sprint | L37: Rajesh/Sathiyabharathi/ Saranya/Priya | M37: Closed | N37: 45974
A38: 36 | B38: 45960 | C38: GGO 8.1.0 Sprint 1 (16-Oct-2025 to 30-Oct-2025) | D38: 1 External Defects | E38: External | F38: Metric Deviation | G38: Defect free Rate | H38: Incorrect data report generated for end customers | I38: The issue occurred due to improper synchronization logic in the backend. A static component was used by the developer instead of an object-based approach. Static methods and variables do not maintain session-specific state, leading to data overlap when multiple users accessed the system simultaneously. Specifically, when two users logged in with different organization IDs, the shared static component failed to isolate data correctly, resulting in cross-org data contamination. | K38: Replace the static component with a session-specific object-based implementation, correct impacted data, and enforce coding standards with automated checks to prevent future cross-organization data contamination. | L38: Rajesh/Sathiyabharathi/ Saranya/Priya | M38: Closed | N38: 45967
A39: 37 | B39: 46044 | C39: GGO 8.2.0 Sprint 3 (08-Jan-2026 to 22-Jan-2026) | D39: 2 assigned Story got rolled over | E39: Internal | F39: Metric Deviation | G39: Commitment Index Deviation | H39: 2 assigned stories carried forward GGO-14628 Hard to reproduce the the Print invoice/receipt page issue in lower environment GGO-15135 Development and testing is completed by our end. Settings to be updated by Jscramber IT team | K39: a temporary fix has been provided by the offshore development team | L39: Rajesh/Sathiyabharathi/ Saranya/Priya | M39: Inprogress | N39: 46058
A40: 38 | B40: 46058 | C40: GGO 8.2.0 Sprint 4 (22-Jan-2026 to 05-Feb-2026) | D40: 2 assigned Story got rolled over | E40: Internal | F40: Metric Deviation | G40: Commitment Index Deviation | H40: : 2 assigned stories carried forward GGO-14628 - For this issue, a temporary fix has been provided by the offshore development team. However, the client has requested a permanent fix with a different approach, so the story has been carried forward GGO-15140 - CRT regression testing has been completed by the offshore QA team. The onsite QA requested that this story be put on hold, as WAF testing is still pending on his side. Therefore, the story has been carried forward | K40: Ensure early alignment with clients by validating the proposed technical approach | L40: Rajesh/Sathiyabharathi/ Saranya/Onsite QA | M40: Inprogress | N40: 46072

Sheet QualityMetrics-Definition
A1: Key Performance Indicator | B1: Description | C1: Formula | D1: Weightage | E1: Green | F1: Amber | G1: Red | H1: Client Approved
A2: Commitment Index | B2: Indicates the percentage of story points fulfilled relative to the commitment for each sprint. | C2: Completed Story Points/ Planned Story Points | D2: 0.25 | E2: 100 | F2: 81-99 | G2: <=80%
A3: Velocity | B3: Denotes the overall count of story points accomplished in each sprint. | C3: Completed Story Points/Average of 4 sprints (4 sprints after the team completely onboarded and started the project related activities) The above formulae is customized and should not be below the value derived from 8*1(2 Weeks Sprint)*(Number of Team Members) | D3: 0.2 | E3: 0.95 | F3: 80-94 | G3: <80%
A4: Defect-free Rate | B4: The number of defects identified post-development | C4: (Internal+Escaped) Defects Found/ Size (actual in Story Points) | D4: 0.2 | E4: 1 | F4: 99-80 | G4: >20%
A5: Code Quality Index | B5: Evaluate the code quality across various dimensions, whether through manual code review or automated analysis using tools like SonarCube. Assess aspects such as correctness, readability, maintainability, efficiency, consistency, testability, scalability, security, documentation, and adherence to established standards. | C5: (Peer + Client) Code Review/ Size (actual in Story Points) | D5: 0.15 | E5: >=80 | F5: 79-65 | G5: <65%
A6: Unit Testing & Code Coverage | B6: Unit Test Results should be >85% Code Coverage should be >85% | C6: Average of Unit Test & Code Coverage | D6: 0.1 | E6: >=90 | F6: 71-89 | G6: <=70%
A7: Backlog Health | B7: Shows the health of backlog in as total number of Story Points available in backlog Vs Average Velocity (last 6 Sprints) | C7: No. Of stories points (Velocity of the Team) ready for (N+1)th Sprint | D7: 0.1 | E7: 100 | F7: 81-99 | G7: <=80%
A8: Delivery Score | C8: Sum of all the scores from different metrics | D8: NA | E8: >=90% | F8: 81-89 | G8: <=80%
C10: =6/50 -> 0.12 | D10: =(100%-12%) -> 0.88

Sheet Config
A1: Sprint | B1: =_xlfn.XLOOKUP("Yes",Data!L1:L64,Data!A1:A64,0,0) -> GGO 8.4.0 Sprint 3 (30-Apr-2026 to 14-May-2026) | C1: =Scorecard!B1 -> GGO Web | I1: Commitment Index | L1: Status | O1: Less Than | P1: Greater Than
A2: Metrics | B2: UnWeighted | C2: Weighted | I2: Goal | J2: 1 | L2: Ready | N2: Below Avg | O2: 5
A3: =Scorecard!A8 -> Commitment Index | B3: =VLOOKUP($B$1,Table_1[#All],4) -> 1 | C3: =B3*'QualityMetrics-Definition'!D2 -> 0.25 | I3: Risk | J3: 0.9 | L3: Committed | N3: Avg | O3: 10 | P3: 15
A4: =Scorecard!A9 -> Velocity | B4: =IF((VLOOKUP($B$1,Table_1[#Data],5)/Data!AK37)>1,"100%",(VLOOKUP($B$1,Table_1[#Data],5)/Data!AK37)) -> 100% | C4: =B4*'QualityMetrics-Definition'!D3 -> 0.2 | I4: Issue | J4: 0.8 | L4: Done | N4: Good | O4: 15 | P4: 20
A5: =Scorecard!A10 -> Defect-free Rate | B5: =1-IFERROR((VLOOKUP($B$1,Table_1[],9)+VLOOKUP($B$1,Table_1[],10))/VLOOKUP($B$1,Table_1[],5),0) -> 0.96153846 | C5: =(B5)*'QualityMetrics-Definition'!D4 -> 0.19230769 | L5: CF | N5: Excellent | P5: 25
A6: =Scorecard!A11 -> Code Quality Index | B6: =1-(VLOOKUP($B$1,Table_1[],7)+VLOOKUP($B$1,Table_1[],8))/VLOOKUP($B$1,Table_1[],3) -> 1 | C6: =(B6)*'QualityMetrics-Definition'!D5 -> 0.15 | I6: Velocity
A7: =Scorecard!A12 -> Unit Testing | B7: =VLOOKUP($B$1,Table_1[],6) -> 0.9 | C7: =B7*'QualityMetrics-Definition'!D6 -> 0.09 | I7: Goal | J7: 20
A8: =Scorecard!A13 -> Backlog Health | B8: =IF((VLOOKUP($B$1,Table_1[#All],11)/Data!K2)>1,"100%",(VLOOKUP($B$1,Table_1[#All],11)/Data!K2)) -> 1 | C8: =B8*'QualityMetrics-Definition'!D7 -> 0.1
I9: Code Coverage
I10: Goal | J10: 0.9
I21: Backlog Health - Categories | L21: Story Point Labels | O21: Backlog Health - Achieved
I22: Below Avg | J22: 15 | L22: Labels | M22: Values | O22: Story Points | P22: =VLOOKUP(Scorecard!B5,Table_1[#All],11) -> 30
I23: Avg | J23: 20 | L23: 5 | M23: 10 | O23: Thickness | P23: 1
I24: Good | J24: 25 | L24: 10 | M24: 10 | O24: Indicator | P24: 30
I25: Excellent | J25: 30 | L25: 15 | M25: 10
I26: Total | J26: =SUM(J22:J25) -> 90 | L26: 20 | M26: 10
L27: 25 | M27: 10
M28: =SUM(M23:M27) -> 50

Sheet Instructions
A1: Instructions
A2: 1. Define the metrics that are required for the project in the "QualityMetrics-Defintion" sheet 2. For the defined metrics, update the Data in the "Data" sheet. 3. Update the Goals in the "Data" sheet from Column AC to AL - Add/Delete the required goals as necessary - This is used in the Scorecard metrics calculation 4. Update the Project details in the "Scorecard" sheet 5. As per the goals defined, update the formulae required to calculate the metrics 6. As per the goals defined, update the "Conditional Formatting" rules to reflect the correct color coding as per the defined goals 7. To update the Dashboard charts, Open the document in desktop version and select the required sprints (cycles) to display the data
