Workbook

Sheet Dashboard
A1: Current Sprint | B1: {=INDEX($B$2:$B$102,MATCH(1,(($D$2:$D$102 >=TODAY())*($C$2:$C$102<=TODAY())),0))} -> OB-OP 8.6.0 Sprint 4 | C1: Current Sprint Sheet | D1: =CONCATENATE(B1,"-Status") -> OB-OP 8.6.0 Sprint 4-Status | E1: Sprint Start Date | F1: =VLOOKUP($B$1,$B$1:$C$102,2) -> 46149 | G1: Sprint End Date | H1: =VLOOKUP($B$1,$B$1:$D$102,3) -> 46163 | I1: Application Name | J1: OnlineBidding | K1: Users | L1: karthi.rajendran@relevantz.com;preethi.muthu@relevantz.com;prabu.pandiya@relevantz.com;mercy.hameed@relevantz.com;nivetha.murugadass@relevantz.com | M1: Teams Name(GP-GGO.OnlineBidding) | N1: 19:f86125062bb647689bca347bf687e022@thread.v2
A2: Sprint Type | B2: Sprint # | C2: Sprint Start Date | D2: Sprint End Date | E2: Assigned SP | F2: Completed SP | G2: Story points introduced/removed | H2: Sprint Summary | I2: Accomplishments | J2: Remarks | K2: Retro Points (Internal & External) | L2: Data sanity Audit Status | M2: AuditDate | N2: Planned Leaves | O2: Availed Leaves | P2: Backlog Health
A3: =IF(AND($D$1>=C3,$D$1<=D3),"CurrentSprint","NA") -> NA | B3: OBOP 7.10.0 Sprint 4 | C3: 45296 | D3: 45309 | E3: 12 | F3: 9 | G3: 5/0 | J3: Offshore team faced some challenges while implementing the Rich textbox. | K3: Internal: External:
A4: =IF(AND($D$1>=C4,$D$1<=D4),"CurrentSprint","NA") -> NA | B4: OBOP 7.11.0 Sprint 1,2 | C4: 45310 | D4: 45337 | E4: 25 | F4: 23 | G4: 0/0 | J4: Offshore team got appreciations for more than expected story points completed. Prabhu and Rajesh for helping with the hotfix as well. | K4: Internal: External:
A5: =IF(AND($D$1>=C5,$D$1<=D5),"CurrentSprint","NA") -> NA | B5: OBOP 7.11.0 Sprint 3 | C5: 45338 | D5: 45351 | E5: 13 | F5: 13 | G5: 0 | J5: Overall good sprint, Prabhu and offshore team got appreciated for DNN libraries documentation. | K5: Internal: External:
A6: =IF(AND($D$1>=C6,$D$1<=D6),"CurrentSprint","NA") -> NA | B6: OBOP 7.11.0 Sprint 4 | C6: 45352 | D6: 45365 | E6: 9 | F6: 9 | G6: 0/0 | J6: Offshore team got appreciations for investigating the AHA templates-DNN7(OP) and group filter story(OB). | K6: Internal: External:
A7: =IF(AND($D$1>=C7,$D$1<=D7),"CurrentSprint","NA") -> NA | B7: OBOP 7.12.0 Sprint 1 | C7: 45366 | D7: 45379 | E7: 11 | F7: 11 | G7: 2/0 | J7: Appreciated for completing all the work with good production release. | K7: Internal: External:
A8: =IF(AND($D$1>=C8,$D$1<=D8),"CurrentSprint","NA") -> NA | B8: OBOP 7.12.0 Sprint 2 | C8: 45380 | D8: 45393 | E8: 13 | F8: 10 | G8: 5/0 | J8: 2 DNN-7 story getting carried. Prabhu and Offshore team got appreciated for doing great job in learning and updating AHA templates. | K8: Internal: External:
A9: =IF(AND($D$1>=C9,$D$1<=D9),"CurrentSprint","NA") -> NA | B9: OBOP 7.12.0 Sprint 3 | C9: 45394 | D9: 45407 | E9: 7 | F9: 7 | G9: 0/0 | J9: Client appreciated for completing Recaptcha DNN9 conversion. Addition to this development completed for one stretch story. | K9: Internal: External:
A10: =IF(AND($D$1>=C10,$D$1<=D10),"CurrentSprint","NA") -> NA | B10: OBOP 7.12.0 Sprint 4 | C10: 45408 | D10: 45421 | E10: 15 | F10: 15 | G10: 6/0 | J10: Overall good sprint, Team completed more than expected story points. | K10: Internal: External:
A11: =IF(AND($D$1>=C11,$D$1<=D11),"CurrentSprint","NA") -> NA | B11: OBOP 7.13.1 Sprint 1 | C11: 45422 | D11: 45435 | E11: 17 | F11: 17 | G11: 0/0 | J11: Prabhu got appriciated for getting all AHA fixes completed and Mercy got appriciated for finding lot of issues. | K11: Internal: External:
A12: =IF(AND($D$1>=C12,$D$1<=D12),"CurrentSprint","NA") -> NA | B12: OBOP 7.13.1 Sprint 2 | C12: 45436 | D12: 45449 | E12: 28 | F12: 23 | G12: 8/0 | J12: Completed most of assigned stories/defects | K12: Internal: External:
A13: =IF(AND($D$1>=C13,$D$1<=D13),"CurrentSprint","NA") -> NA | B13: OBOP 7.13.1 Sprint 3 | C13: 45450 | D13: 45463 | E13: 17 | F13: 16 | G13: 5/0 | J13: Appreciated for completing all the work | K13: Internal: External:
A14: =IF(AND($D$1>=C14,$D$1<=D14),"CurrentSprint","NA") -> NA | B14: OBOP 7.13.1 Sprint 4 | C14: 45464 | D14: 45476 | E14: 8 | F14: 8 | G14: 1/0 | J14: Appreciated dev team for Investigation stories and Mercy for finding defect. | K14: Internal: External:
A15: =IF(AND($D$1>=C15,$D$1<=D15),"CurrentSprint","NA") -> NA | B15: OBOP 7.14.0 Sprint 1 | C15: 45477 | D15: 45491 | E15: 13 | F15: 13 | G15: 3/0 | J15: Appreciated Mercy for good testing | K15: Internal: External:
A16: =IF(AND($D$1>=C16,$D$1<=D16),"CurrentSprint","NA") -> NA | B16: OBOP 7.14.0 Sprint 2 | C16: 45492 | D16: 45505 | E16: 12 | F16: 12 | G16: 0/0 | J16: Completing another sprint successfully, Appriciated Prabhu and offshore for completing the work on messaging | K16: Internal: External:
A17: =IF(AND($D$1>=C17,$D$1<=D17),"CurrentSprint","NA") -> NA | B17: OBOP 7.14.0 Sprint 3 | C17: 45506 | D17: 45519 | E17: 11 | F17: 8 | G17: 0/0 | J17: Couldn't complete testing because of release pipeline certificate issue. | K17: Internal: External:
... A19: =IF(AND($D$1>=C19,$D$1<=D19),"CurrentSprint","NA") -> NA | B19: OBOP 8.2.0 Sprint 1 | C19: 45534 | D19: 45547 | E19: 12 | F19: 12 | G19: 0/0 | J19: Appreciated Prabhu for providing KT to quick invoice team | K19: Internal: External:
A20: =IF(AND($D$1>=C20,$D$1<=D20),"CurrentSprint","NA") -> NA | B20: OBOP 8.2.0 Sprint 2 | C20: 45548 | D20: 45561 | E20: 20 | F20: 15 | G20: 5/0 | K20: Internal: External:
A21: =IF(AND($D$1>=C21,$D$1<=D21),"CurrentSprint","NA") -> NA | B21: OBOP 8.2.0 Sprint 3 | C21: 45562 | D21: 45575 | E21: 20 | F21: 17 | G21: 3/3 | J21: TST was down which lead to rolling over one story Peer CRC: 0 Onsite CRC: 2 Client CRC: 0 Internal Defects :2 External Defects:0 Appreciated i)Prabhu for helping Alice on providing info on some stories ii)Mercy for helping out while Alice was unavailable iii) Rajesh and Prabhu for helping Joe set up GGO locally. iv) Lot of challenges while developing the OP page module and offshore continued working through it v) Rajesh for helping Prabhu and team with testing of OP stories. vi) Rajkumar and Prabhu for good coordination for getting the entire flow end to end on Quick invoicing | K21: Internal: External:
A22: =IF(AND($D$1>=C22,$D$1<=D22),"CurrentSprint","NA") -> NA | B22: OBOP 8.2.0 Sprint 4 | C22: 45576 | D22: 45589 | E22: 17 | F22: 17 | G22: 0/0 | I22: 1.Import quick invoice payment page designed, created in GGO and placed in between Registrations & RSVPs 2. Added new convenience fee sale and made reconcile with sale payment association 3.Pending quick invoice imports count included in existing left nav notification counter | J22: i) Appreciated the team for completing all the quick invoice stories. ii) Kudos to Farhath and Mercy for helping with the test planning and testing which made it easier for Alice. iii) Kudos to Prabhu and Rajkumar for coordinating with offshore teams and completing all the planned stories for the sprint iv) Appreciated Offshore for finishing the planned stories and meeting the deadline v) Rajesh and Prabhu helped Rajkumar & offshore with the OP and GGO integration. Peer CRC: 2 Onsite CRC: 0 Client CRC: 0 Internal Defects :0 External Defects:0
A23: =IF(AND($D$1>=C23,$D$1<=D23),"CurrentSprint","NA") -> NA | B23: OBOP 8.3.0 Sprint 1 | C23: 45590 | D23: 45603 | E23: 11 | F23: 8 | G23: 0/0 | I23: 1.Quick Invoice feature release into CRT 2.Added Privacy Police notice on both OB & OP 3.Default application text css changes & Text updates | J23: Nice job with the privacy policy implementation. One story has been moved to next sprint for testing alone Kudos to Offshore QA - has been very helpful , making sure all gaps are covered Peer CRC: 0 Onsite CRC: 0 Client CRC: 0 Internal Defects:2 External Defects: 0
A24: =IF(AND($D$1>=C24,$D$1<=D24),"CurrentSprint","NA") -> NA | B24: OBOP 8.3.0 Sprint 2 | C24: 45604 | D24: 45617 | E24: 14 | F24: 14 | G24: 3/0 | I24: 1.OP 8.2.0 release to CRT & PRD 2.App help url updates 3.Invoicing feature updates - Collected from pilot user's feedback 4.Escalation support | J24: Kudos shared to Mercy for the support in making a lot of test plans and doing thorough testing that really helped out with all the small areas we have to verify, especially with all of the stories we added during the quick invoice effort. Rajkumar and team for the merge field completion. Rajesh for helping with the merge strategies and Prabhu was very helpful for a couple of tickets Joe had. Peer CRC:0 Onsite CRC:0 Client CRC: 6 Internal Defects:2 External Defects: 0 A 3 point story was added towards the end of the Sprint as part of the strech goal and was rolled over to the next sprint
A25: =IF(AND($D$1>=C25,$D$1<=D25),"CurrentSprint","NA") -> NA | B25: OB-OP 8.3.0 Sprint 3 | C25: 45618 | D25: 45631 | E25: 21 | F25: 21 | G25: Ten/0 | I25: 1. We had 8.2.2 OP CRT release 2. completed final set of pending invoicing tasks 3.Macroscope fixes | J25: Kudos to Rajkumar and team for taking invoicing project to finish line, Offshore QA - Mercy and Farhath for putting some good notes for Alice which was helpful when she got back and Preethi and Karthi for managing all the dev work during the US thanksgiving holidays when everyone was away Kalai and Rajiv are very dynamic and all the deliveries were on time Prabhu and Rajesh for the KT and support to the invoicing team Peer CRC:0 Onsite CRC:2 Client CRC: 2 Internal Defects:1 External Defects: 0 A 2 point story was added towards the end of the Sprint as part of the strech goal and was rolled over to the next sprint
A26: =IF(AND($D$1>=C26,$D$1<=D26),"CurrentSprint","NA") -> NA | B26: OB-OP 8.3.0 Sprint 4 | C26: 45632 | D26: 45659 | E26: 11 | F26: 13 | G26: 15/0 | I26: 1.OB 7.12.1 release to CRT& PRD 2. OP 8.2.2 PRD Release 3.Complete Invoicing 4.Macroscope fix | J26: Kudos Offshore in general and offshore QA for keeping up with things when Onsite was away for holidays +2 Mercy for keeping up with test plans when Alice was out Raj kumar and team for a great impact on past few sprints +1 Peer CRC:0 Onsite CRC:1 Client CRC: 0 Internal Defects:0 External Defects: 0 Some of the stories are stretch and got carry forwarded because of client resources unavailability due to holidays
A27: =IF(AND($D$1>=C27,$D$1<=D27),"CurrentSprint","NA") -> NA | B27: OB-OP 8.4.0 Sprint 1 | C27: 45660 | D27: 45673 | E27: 16 | F27: 13 | G27: 0/0 | I27: 1. Release 8.3.0 to CRT and PRD 2. Macroscope fix in OP and OB | J27: Kudos to Given the release, towards the end of the sprint we were seeing a bunch of issues in OP and OB and Mercy was very helpful in testing those Given the product overlap across both teams and the staggered release for both teams, it was confusing but the team did a great job overall staying on top of everything Rajesh for helping Joe set up for the portals To the team on a great job on the overall Invoice project and release Peer CRC:0 Onsite CRC:2 Client CRC: 0 Internal Defects:0 External Defects: 0 3 point story carry forwarded to next sprint. Part of the performance improvement done.Restrictions on DNN9 core functionality prevents us from finding performance improvements. But there is more room left for improvements. So Story was carry forwarded
A28: =IF(AND($D$1>=C28,$D$1<=D28),"CurrentSprint","NA") -> NA | B28: OB-OP 8.4.0 Sprint 2 | C28: 45674 | D28: 45687 | E28: 16 | F28: 10 | G28: 5/0 | I28: RSVP enhancements, continuing with Macroscope work,OP MFA login production hotfix | J28: Peer CRC:0 Onsite CRC:0 Client CRC: 0 Internal Defects:1 External Defects: 0 2 RSVP stories got carried over to the next sprint, RSVP Multiple attendee dynamic control creation has been challenging. Completed major functionalities, local testing and dev testing is in progress and a 3 point story is dependent on that 8 point story so we couldn't proceed that without completing the main story
A29: =IF(AND($D$1>=C29,$D$1<=D29),"CurrentSprint","NA") -> NA | B29: OB-OP 8.4.0 Sprint 3 | C29: 45688 | D29: 45701 | E29: 14 | F29: 12 | G29: 1/0 | I29: Continue RSVP enhancements, Supported OP 8.3.2 Hotfix testing support for delay in OP site creation, RSVP index table update and Apigee threading exception | J29: Kudos to i) Rajesh to take the big feature and manage it +1 ii) Joe,Mike , Rajesh, Derek was handling all the rapid change in the sprint goal iii) Rajesh for handling all on both teams GGO and OB/OP iv) Offshore dev and QA for working hard on multiple attendees and getting all the scenarios covered Peer CRC:2 Onsite CRC:2 Client CRC: 0 Internal Defects:0 External Defects: 2 3 pt bug has been carry forwarded to next sprint as we couldn't able to reproduce the bug in our environment and trying to find the root cause for it
A30: =IF(AND($D$1>=C30,$D$1<=D30),"CurrentSprint","NA") -> NA | B30: OB-OP 8.4.0 Sprint 4 | C30: 45702 | D30: 45715 | E30: 9 | F30: 9 | G30: 6/3 | I30: New card type added with existing ones, OP 8.3.3 and 8.4.0 release to CRT | J30: Kudos to i) Everyone in the team for all the hard work this sprint ii) Joe , Rajesh, Mike and Carlos for all of the release stuff iii) Offshore for taking care of all the sprint stories Peer CRC:0 Onsite CRC:0 Client CRC: 0 Internal Defects:1 External Defects: 3 3 pt bug has been flagged in JIRA as blocker and removed from sprint during sprint end and another 3 pt bug which is in stretch has been carry forwarded to next sprint, in which we have completed the fix for 1 report, need to check for remaining 3 reports
A31: =IF(AND($D$1>=C31,$D$1<=D31),"CurrentSprint","NA") -> NA | B31: OB-OP 8.5.0 Sprint 1 | C31: 45716 | D31: 45729 | E31: 14 | F31: 11 | G31: 0/0 | I31: Release OP 8.4 to PRD, begin investigating OB UX and QoL fixes | J31: Kudos i) Prabhu and Rajesh on assisting Joe on a ticket related to convenience fee ii) Offshore QA Mercy for the test plan put together for catalog verification, very good testing and makes it more secure iii) Karthi and Preethi for great documentation on the investigation stories Peer CRC:0 Onsite CRC:0 Client CRC: 0 Internal Defects:0 External Defects: 2 One of the story got completed at the last minute because the fix wasn't working so the team had to coninue trying out different aproaches till it worked. It was sent for peer review on the last day and hence got carry forwarded to the next sprint for testing
A32: =IF(AND($D$1>=C32,$D$1<=D32),"CurrentSprint","NA") -> NA | B32: OB-OP 8.5.0 Sprint 2 | C32: 45729 | D32: 45743 | E32: 14 | F32: 19 | G32: 7/0 | I32: Begin work on OB UX settings and layouts | J32: Kudos i) We did a stretch AC on the layout and Prabhu assisted Joe on that ii) Prabhu for helping Alice with testing iii) Rajesh for helping Alice on the email issue +1 iv) Offshore for completing all the planned stories and adding some stretch stories Peer CRC:0 Onsite CRC:0 Client CRC: 1 Internal Defects:0 External Defects: 0 OB UX settings and layout implementation Escalation support for investigating the max bid label update Fixed Max Bid label OP negative payment fix
A33: =IF(AND($D$1>=C33,$D$1<=D33),"CurrentSprint","NA") -> NA | B33: OB-OP 8.5.0 Sprint 3 | C33: 45743 | D33: 45757 | E33: 14 | F33: 11 | G33: 0/0 | I33: Continue OB UX and high value OP items Accompolishments: Added new settings in Online bidding settings page Feature flag implementation for OB - sending data from GGO to OB | J33: Peer CRC:0 Onsite CRC:0 Client CRC: 0 Internal Defects:1 External Defects: 2 Pending reason One 3-point story was carried over to the next sprint. While development, local testing, and DEV testing were completed from our side, the peer review and testing for OB-3731 were delayed. This was primarily due to the extended time required for development and testing of OB-3708 (an 8-point story). As a result, OB-3731 has been moved to the next sprint. | K33: What went well? Offshore doing testing in Dev before going to TST helps mitigate issues later in the Sprint What didn’t go well? The development for OB settings page was a little challenging Kudos 1. Nice job team on OB settings page, the mockups really look good 2. Great QA team for being a sport , working last minute to test the stories +1 3. Offshore QA Mercy for finding the issues before it hit TST and helped in not sending it back to Dev later 4. Prabhu and Rajesh for their support to Alice 5. Prabhu, Offshore dev Preethi and Karthi for completing the OB settings page for spending extended hours in completing it +2
A34: =IF(AND($D$1>=C34,$D$1<=D34),"CurrentSprint","NA") -> NA | B34: OB-OP 8.5.0 Sprint 4 | C34: 45757 | D34: 45771 | E34: 11 | F34: 14 | G34: 5/0 | I34: Release and test OP 8.5 and OB 7.13 to CRT. Donor Project continuing work Accomplishment 1. Tested OP 8.5 and OB 7.13 in CRT 2. Upgraded Angular 12 to 13, version got upgraded but facing few routing issues | J34: Peer CRC:0 Onsite CRC:0 Client CRC: 0 Internal Defects:0 External Defects: 0 Pending reason 1 Bug has been carry forwarded to next sprint since it is taking more time than expected. Also PM cannot remember what this report looked like working in Prod, so we may need to do some discovery and explanation in order to come up with a good solution | K34: What went well? 1. CRT testing completed on time 2. Great progress on Angular update 3. Good initial progress on Donor project 4. Completed more stories than planned What didn’t go well? 1. The package dependency made the Angular update challenging 2. Fixing the section report issue has been more complex than planned Kudos Prabhu and Rajesh for supporting the CRT issue fix, Carlos as well Rajesh for leading the way on Donor Project +2 Offshore for the Angular update , that was a big jump +2
A35: =IF(AND($D$1>=C35,$D$1<=D35),"CurrentSprint","NA") -> NA | B35: OB-OP a7.14.0 Sprint 1 | C35: 45771 | D35: 45785 | E35: 15 | F35: 11 | G35: 0/0 | I35: OB & OP PRD release, continue with OB UX and Donor project Accomplishment 1. Passed the new settings value from GGO to OB and mapped the header values in OB side UI 2. Upgraded Angular 12 to 13, Updated node version from 14 to 16, fixing the errors | J35: Peer CRC:0 Onsite CRC:0 Client CRC: 3 Internal Defects:0 External Defects: 0 Pending reason OP-2747-It has been carry forwarded to next sprint since it is taking more time than expected. Also PM cannot remember what this report looked like working in Prod, so we may need to do some discovery and explanation in order to come up with a good solution OB-3680 - Story has been carry forwarded to next sprint - Dependent on OB-3755. Development and peer review is completed, Since PR was shared in the last day testing will be done in next sprint | K35: What went well? The new Donor platform setup went well On pace with OB UX What didn’t go well? Last minute unplanned PTO for team member led to delay in closing a few tickets New OB page and design turned out to be a little challenging Kudos Preethi for updating the node and Angular version as it requires a lot of tracking and patience. Thanks for doing it
A36: =IF(AND($D$1>=C36,$D$1<=D36),"CurrentSprint","NA") -> NA | B36: OB-OP 8.0 Sprint 2 | C36: 45785 | D36: 45799 | E36: 15 | F36: 15 | G36: 0/0 | I36: OB & OP PRD release, continue with OB UX and Donor project Accomplishment 1. The team completed all they planned for and more (initially firebase was spike later converted to story) 2. Fixed the warnings while compiling angular 13, ended up with 1 console error while running application | J36: Peer CRC:0 Onsite CRC:1 Client CRC: 0 Internal Defects:1 External Defects: 0 Escaped defect RCA - Should do proper code review and local testing,DEV testing covering all scenarios Review Comment - Add try catch block here when you connecting with DB to make operations | K36: What went well? The team completed all they planned for and more PRD releases were long and it went well What didn’t go well? Firebase notification was a little tricky to configure Handling Aesgcn decryption for existing URLs cost a little extra time to complete Docker desktop is not authorized so it forced the team to find a different way to communicate with the database Kudos Offshore and Dev Prabhu for completing the investigation and implementation of Firebase notification +2
A37: =IF(AND($D$1>=C37,$D$1<=D37),"CurrentSprint","NA") -> NA | B37: OB-OP 8.0 Sprint 3 | C37: 45800 | D37: 45814 | E37: 16 | F37: 14 | G37: 6/0 | I37: Continue OB UX work, setup for donor platform Accomplishment 1. Updated Node js to version 16 and then to 18, trying to fix the errors 2. Firebase notification is coming correctly to the bidders who are outbidden 3. New team members setup is completed and started the design story | J37: Peer CRC:0 Onsite CRC:0 Client CRC: 2 Internal Defects:0 External Defects: 0 Review comment - 1. Macroscope will ding us for putting apikeys or secrets in the repo. We need to add these as variables, even for local testing the same way we do for the SMS test keys 2. Let's add a general exception catch as well. Pending reason 1. OB-3675 -During the sprint, a few high-priority security issues were introduced that required quick attention. Addressing them took some time away from our originally planned work. Development work has been completed successfully, and dev environment testing was verified by the Relevantz offshore QA team. However, during deployment to the TST environment, we encountered issues related to pipeline variables. As a result, only testing is pending for this story. 2. DON-20 - Stretch story - Development completed, local testing is in progress, Once done will raise the PR in next sprint | K37: What went well? Onboarding went well What didn’t go well? 2 Security issues took about a week of 2 of the team members time New developers onboarding For multiple bidders, Firebase notification is not getting sent randomly Angular upgrade has been challenging Escalation support for OP Login issue Kudos Prabhu nice job get everybody onboarded +3 Takeaways 6/5/2025 Angular Update timebox effort should be significantly lowered - 10 hrs a Sprint Escalation Support should be filtered by Derek Anderson and Mike Horihan so that team can focus on OB UX overhaul and Donor project
A38: =IF(AND($D$1>=C38,$D$1<=D38),"CurrentSprint","NA") -> NA | B38: OB-OP 8.0 Sprint 4 | C38: 45813 | D38: 45826 | E38: 20 | F38: 13 | G38: 1/0 | I38: CRT Release and testing for OB and OP, continue with OB UX and Donor project Accomplishment Completed the firebase notification story and updated the sponsor bar design for new UI | J38: Peer CRC:1 Onsite CRC:1 Client CRC: 0 Internal Defects:0 External Defects: 0 Review comment Rename the css class Move all the numbers to constant file Pending reason 1. OP-2766 - Was having CRT certificate issue so couldn't complete testing 2. OB-3684 - Testing completed from offshore QA end and added comments in JIRA, since onsite QA was occupied with CRT testing, couldn't give signoff to this ticket. We shared the PR on 17/06(Tues) | K38: Overall it was a good sprint even though we didn't meet the Sprint forecast this time. The onsite QA needs to signoff on those tickets before closing and given this was a regression sprint, the onsite QA had her hands full with CRT testing. A special shout out to the new Donor team for coming up to speed very fast and taking control right away. Well done! What went well? Very productive sprint inspite our story point completion What didn’t go well? Cross site scripting was a distraction from our planned work Issues in PAPI CRT caused testing delays Kudos Alice for a lot of of help with initial cross site testing Joe, Rajesh and Prabhu with fixing the update script to get to CRT without a lot of issues New Donor team for completing a lot of the design work +1 Rajesh for helping with the CRT issue +1 Preethi, Karthi and Mercy for completing the Firebase notification and Sponsor bar design
A39: =IF(AND($D$1>=C39,$D$1<=D39),"CurrentSprint","NA") -> NA | B39: OB-OP 8.1 Sprint 1 | C39: 45826 | D39: 45841 | E39: 17 | F39: 17 | G39: 5/0 | I39: Release OB/OP to PRD, continue OB UX and Donor Platform Accomplishment Completed all the sprint stories and took stretch stories and made good progress on that as well | J39: Peer CRC:0 Onsite CRC:0 Client CRC: 0 Internal Defects:0 External Defects: 0 | K39: Great in meeting the Sprint Goal What went well? All planned stories got completed and more Quick turn around on the Hot Fix What didn’t go well? A number of security issues came through which was unplanned and high priority for some old modules The arc review is preventing us from implementing B2C Kudos Offshore team did a great job on OB and Donor work, completed everything +1 Appreciate Rajesh stepping in and covering for Prabhu Joe and Prabhu giving assistance on couple of stories for testing to Alice( specially on Donor project) Quick turn around on the Hot Fix Alice and Offshore QA team has done a great job on automation testing which made both the prod release testing quick +1
A40: =IF(AND($D$1>=C40,$D$1<=D40),"CurrentSprint","NA") -> NA | B40: OB-OP 8.1 Sprint 2 | C40: 45841 | D40: 45855 | E40: 17 | F40: 16 | G40: 2/0 | I40: More OB UX, Donor Platform infrastructure, and OP security remediation. Accomplishment Completed OB UX stories,took a stretch story and completed that as well | J40: Peer CRC:0 Onsite CRC:0 Client CRC: 0 Internal Defects:1 External Defects: 0 Pending reason OB-3784 - Due to few escalation and production login issue couldn't work on this before, but Development is completed, need to do local and DEV testing Internal Defect OB-3790 - Missed in local and DEV testing, need to compare all the scenarios with Old UI | K40: Completed the design stories in OB pages What went well? Design story in OB page is completed along with one more stretch story What didn’t go well? One design story that needs to be updated in GGO page is carry forwarded to next sprint as testing is pending Kudos Offshore team did a great job on OB and Donor work
A41: =IF(AND($D$1>=C41,$D$1<=D41),"CurrentSprint","NA") -> NA | B41: OB-OP 8.1 Sprint 3 | C41: 45855 | D41: 45869 | E41: 13 | F41: 3 | G41: 0/0 | I41: Continue OB UX (Package Cards, Donation Modal), Platform work, Security remediation Accomplishment Implemented the package design in browse page by mapping with API and also the search functionality | J41: Peer CRC:0 Onsite CRC:0 Client CRC: 0 Internal Defects:0 External Defects: 0 Pending reason OB-3689, OB-3724 - Development completed, local testing by pointing DEV DB is done, Peer review for one story is completed(OB 3689), OB 3724 can be reviewed only when the previous story is deployed as it is the dependent story - OB certificate issue blocked testing in Dev | K41: Well Done Team for another great Sprint. The Sprint goal wasn't met because of the certificate issue which is out of our hands. What went well? Donor app progress was good A lot of positive comments from CS on the Donor Platform progress - well done team! “The login page looks great and it will be one of the most visited page” What didn’t go well? OB certificate issue blocked testing in Dev, TST and CRT OB build Pipeline issue The fixes for WhiteHat security findings was challenging Kudos Prabhu for supporting Alice with Donor platform testing Mercy for cross site scripting testing and bringing up some issues Prabhu, Rajesh, Mike H and Joe for getting the Certificate issue resolved, it is very close to getting done Arivalagan - the code he delivered for Don 39 and Don 40 is of high quality
...

Sheet Unplanned Leaves
B1: Resource Name
A2: Sprint Name | B2: Preethi Muthu | C2: Nivetha | D2: Karthi Rajendran | E2: Prabu Sankar | F2: Total UnPlanned Leaves | G2: Total Planned Leaves | H2: Remarks
A3: OB-OP 8.5 Sprint 1 (29-Jan-26 to 12-Feb-2026) | B3: 0 | C3: 0 | D3: 0.5 | E3: 0 | F3: 0.5 | G3: 1 | H3: Karthi - Personal Emergency Mercy had a planned leave but she didnt take that
A4: OB-OP 8.5 Sprint 2 (12-Jan-26 to 26-Feb-2026) | B4: 0 | C4: 0 | D4: 0 | E4: 0 | F4: 0 | G4: 1 | H4: No unplanned leaves
A5: OB-OP 8.5 Sprint 3 (26-Feb-26 to 12-Mar-2026) | B5: 0 | C5: 1 | D5: 0 | E5: 0 | F5: 1 | G5: 1 | H5: Mercy - Daughter not well
A6: OB-OP 8.5 Sprint 4 (12-Mar-26 to 26-Mar-2026) | B6: 0 | C6: 0 | D6: 0.5 | E6: 0 | F6: 0.5 | G6: 0 | H6: Karthi - Not well, ear and nose problem
A7: OB-OP 8.6.0 Sprint 1 (26-Mar-26 to 09-Apr-2026) | B7: 0 | C7: 0 | D7: 0 | E7: 2 | F7: 2 | G7: 5.5 | H7: Prabu - Personal emergency Preethi - didnt take half day planned leave
A8: OB-OP 8.6.0 Sprint 2 (09-Apr-26 to 23-Apr-20260 | B8: 0 | C8: 1 | D8: 0 | E8: 0 | F8: 1 | G8: 1 | H8: Nivetha - Personal reason
A9: OB-OP 8.6.0 Sprint 3 (24-Apr-26 to 07-May-2026) | B9: 0 | C9: 0 | D9: 0 | E9: 0 | F9: 0 | G9: 0 | H9: No unplanned leaves
A10: OB-OP 8.6.0 Sprint 4 (07-May-26 to 21-May-2026) | B10: 0 | C10: 1 | D10: 0 | E10: 0 | F10: 1 | G10: 2 | H10: Nivetha - Not well

Sheet OB-OP 8.6.0 Sprint 4-Status
A1: S.No | B1: Application Name | C1: Sprint Start Date | D1: Sprint End Date | E1: Sprint | F1: Developer | G1: Story ID/Defect ID | H1: Description | I1: Status | J1: Estimated(hrs/sp) | K1: Actual(hrs/sp) | L1: Actual Hours Worklog | M1: Dev Start Date | N1: Dev End Date | O1: Unit testing | P1: Peer Tested By | Q1: Peer Tested Defects, if any | R1: Peer Reviewed By | S1: Peer Code Review Comments, if any | T1: PR Number/Link | U1: PR Created Date | V1: PR Approved Date | W1: Onsite Lead Code Review | X1: Code Review Comments, if any | Y1: Client Code Review | Z1: Approved Date | AA1: Code Review Comments, if any2 | AB1: Internal PO -POV Comments | AC1: Client PO -POV Comments | AD1: Comments | AE1: QA Comments
A2: 1 | B2: OnlineBidding | C2: 46149 | D2: 46163 | E2: OB-OP 8.6.0 Sprint 4 | F2: Nivetha - [TESTING ONLY] | G2: OB-3993 | H2: OB 8.6.0 CRT release | I2: Refinement | J2: 3
A3: 2 | B3: OnlineBidding | C3: 46149 | D3: 46163 | E3: OB-OP 8.6.0 Sprint 4 | F3: Preethi/Karthi | G3: OB-3985 | H3: OB Dashboard failing to open on Safari/iPad | I3: Completed | J3: 3 | M3: 46153 | N3: 46155 | O3: Done | P3: Nivetha | Q3: Nil | R3: Karthi | S3: Nil | T3: https://greatergiving.visualstudio.com/Greater%20Giving/_git/OnlineBidding/pullrequest/9555 | U3: 46155 | V3: 46156 | W3: Rajesh | X3: Nil | Y3: Joe | Z3: 46156 | AA3: Nil | AB3: Nil | AC3: Nil | AD3: Development not yet started, checking on to reproduce the issue using browser stack or some other options as we dont have iOS devices to check 5/8/2026 Trying to fix the issue and check after deployment - 5/11/2026 Fixed the issue and checked in safari browser in mac, but need to check in ipad also, but we dont have the device, so asked mobile QA's help and also will ping alice to test from her side in DEV itself - 5/12/2026 | AE3: DEV testing completed for safari browser alone, need to confirm in ipad as well - 5/12/2026
A4: 3 | B4: OnlineBidding | C4: 46149 | D4: 46163 | E4: OB-OP 8.6.0 Sprint 4 | F4: Preethi | G4: OB-3986 | H4: Bid Assistant - Need to log out | I4: Being Developed | J4: 2 | AD4: Checked with mobile team, but we couldn't find the option of logout bidder in their screen, checking other options as well - 5/8/2026 Checking with mobile team for reproducing the issue - 5/12/2026
A5: 4 | B5: OnlineBidding | C5: 46149 | D5: 46163 | E5: OB-OP 8.6.0 Sprint 4 | F5: Karthi | G5: OB-3962 | H5: Build Switch control between Individual and Household | I5: Being Developed | J5: 3 | M5: 46153 | O5: Done | AD5: Started to analyse and checking if we have all the APIs needed for this or need to check with GDON - 5/8/2026 Started with UI design changes - 5/11/2026 Made the code changes with mock data, as we need new/updated API from GDON side to fetch the bidder info like name, bidder etc if the given bidder key is household - 5/12/2026
A6: 5 | B6: OnlineBidding | C6: 46149 | D6: 46163 | E6: OB-OP 8.6.0 Sprint 4 | F6: Rajesh | G6: OP-2805 | H6: OP Transactions - PST to UTC conversion | I6: Completed | J6: 3 | M6: 46155 | N6: 46155 | O6: Done | P6: Preethi | Q6: Nil | R6: Preethi | S6: Nil | T6: https://greatergiving.visualstudio.com/Greater%20Giving/_git/OP/pullrequest/9451 | U6: 46155 | V6: 46156 | W6: Nil | X6: Nil | Y6: Joe | Z6: 46156 | AA6: Nil | AB6: Nil | AC6: Nil | AD6: Already shared the analysis done so far from our side to client, need to check the scenario in PROD once after Carlos is available 5/8/2026 As carlos was on PTO, rajesh will check with him today and try to reproduce in prod environment if possible - 5/12/2026
A7: 6 | B7: OnlineBidding | C7: 46149 | D7: 46163 | E7: OB-OP 8.6.0 Sprint 4 | F7: Preethi | G7: OB-3996 | H7: Add Checkout Link to OB | I7: Completed | J7: 5 | M7: 46153 | N7: 46154 | O7: Done | P7: Nivetha | Q7: Checkout button is not required for Donor disabled users | R7: Karthi | S7: Nil | T7: https://greatergiving.visualstudio.com/Greater%20Giving/_git/OnlineBidding/pullrequest/9557 | U7: 46154 | V7: 46156 | W7: Rajesh | X7: Nil | Y7: Joe | Z7: 46156 | AA7: Nil | AB7: Nil | AC7: Nil | AD7: Need to check with Rajesh, if only these changes need to be addressed in OB side for this ticket - 5/11/2026 Updated the code to show the button only for donor enabled projects, deployed in DEV for testing - 5/12/2026 | AE7: Dev testing completed 5/12/2026
A8: 7 | B8: OnlineBidding | C8: 46149 | D8: 46163 | E8: OB-OP 8.6.0 Sprint 4 - [SPIKE] | F8: Preethi | G8: OB-3995 | H8: Research Repeated Sent Email | I8: Being Developed | J8: 1 | M8: Its not development task, its an investigation ticket | AD8: Analysed and noted down the points related to sending email and shared to Joe as a document, he attached that document in the JIRA ticket - 5/11/2026 We gave the qquery, waiting for the result, as Sarah was on PTO yesterday, we might get the result today - 5/12/2026

Sheet OB-OP 8.6.0 Sprint 4-Defect
A1: S.No | B1: Sprint | C1: Story/Defect ID | D1: Parent Story | E1: Developer | F1: Issue Type | G1: Issue Description | H1: Priority | I1: Defect Source | J1: Type | K1: Status | L1: Root Cause Category | M1: Comments | N1: Found By | O1: RCA Comment

Sheet OB-OP 8.6.0 Sprint 3-Status
A1: S.No | B1: Application Name | C1: Sprint Start Date | D1: Sprint End Date | E1: Sprint | F1: Developer | G1: Story ID/Defect ID | H1: Description | I1: Status | J1: Estimated(hrs/sp) | K1: Actual(hrs/sp) | L1: Actual Hours Worklog | M1: Dev Start Date | N1: Dev End Date | O1: Unit testing | P1: Peer Tested By | Q1: Peer Tested Defects, if any | R1: Peer Reviewed By | S1: Peer Code Review Comments, if any | T1: PR Number/Link | U1: PR Created Date | V1: PR Approved Date | W1: Onsite Lead Code Review | X1: Code Review Comments, if any | Y1: Client Code Review | Z1: Approved Date | AA1: Code Review Comments, if any2 | AB1: Internal PO -POV Comments | AC1: Client PO -POV Comments | AD1: Comments | AE1: QA Comments
A2: 1 | B2: OnlineBidding | C2: 46135 | D2: 46149 | E2: OB-OP 8.6.0 Sprint 3 | F2: Preethi | G2: OB-3980 | H2: Update Featured Packages (Large) to match Package Browse | I2: Completed | J2: 2 | K2: 2 | M2: 46136 | N2: 46136 | O2: Done | P2: Nivetha | Q2: Nil | R2: Karthi | S2: Nil | T2: https://greatergiving.visualstudio.com/Greater%20Giving/_git/OnlineBidding/pullrequest/9506 | U2: 46139 | V2: 46140 | W2: Rajesh | X2: Nil | Y2: Joe | Z2: 46140 | AA2: Nil | AB2: Nil | AC2: Nil | AD2: Development and local testing completed 4/27/2026 | AE2: Dev testing completed 4/27/2026 TST testing completed 4/28/2026
A3: 2 | B3: OnlineBidding | C3: 46135 | D3: 46149 | E3: OB-OP 8.6.0 Sprint 3 | F3: Karthi | G3: OB-3964 | H3: Add Table # to slide out menu | I3: Completed | J3: 2 | K3: 2 | M3: 46139 | N3: 46148 | O3: Done | P3: Nivetha | Q3: Nil | R3: Preethi | S3: Nil | T3: https://greatergiving.visualstudio.com/Greater%20Giving/_git/OnlineBidding/pullrequest/9541 | U3: 46148 | V3: 46149 | W3: Nil | X3: Nil | Y3: Joe | Z3: 46149 | AA3: Nil | AB3: Nil | AC3: Nil | AD3: Checked with GGO team for the API - 4/27/2026 Starting with integrating existing GDON API - 4/28/2026 Having dependency on GDON API, they have to write new API, once done will resume the work on this, story has been flagged in JIRA, client also knows about this - 4/30/2026 Updated the coe by integreating GDON API, tested in local and DEV and created PR - 5/6/2026 Joe made few changes in this PR and deployed in DEV for our testing, we need to review and confirm this today, and he will complete the PR in our evening - 5/7/2026 | AE3: DEV testing completed 5/6/2026 TST testing completed 5/7/2026
A4: 3 | B4: OnlineBidding | C4: 46135 | D4: 46149 | E4: OB-OP 8.6.0 Sprint 3 | F4: Preethi | G4: OB-3983 | H4: Send Project Key with SignIn/Sign Up | I4: Completed | J4: 2 | K4: 2 | M4: 46139 | N4: 46140 | O4: Donr | P4: Nivetha | Q4: Nil | R4: Karthi | S4: Nil | T4: https://greatergiving.visualstudio.com/Greater%20Giving/_git/OnlineBidding/pullrequest/9511 | U4: 46142 | V4: 46147 | W4: Rajesh | X4: Nil | Y4: Joe | Z4: 46147 | AA4: Nil | AB4: Nil | AC4: Nil | AD4: Started analysis and shared with Rajesh - 4/27/2026 Started development and tested in local by hardcoding values - 4/28/2026 Rajesh approved the PR, waiting for Joe's approval - 5/4/2026 Need some changes in GDON API, so need to implement this in OB - 5/5/2026 | AE4: DEV testing completed 5/4/2026 TST testing completed 5/6/2026
A5: 4 | B5: OnlineBidding | C5: 46135 | D5: 46149 | E5: OB-OP 8.6.0 Sprint 3 | F5: Karthi | G5: OP-2809 | H5: OP - Synk remediation | I5: Completed | J5: 1 | K5: 1 | M5: Only testing needs to be done in this sprint | O5: Done | P5: Nivetha | Q5: Nil | R5: Preethi | S5: Nil | T5: https://greatergiving.visualstudio.com/Greater%20Giving/_git/OP/pullrequest/9497 | U5: 46139 | V5: 46140 | W5: Rajesh | X5: Nil | Y5: Joe | Z5: 46140 | AA5: Nil | AB5: Nil | AC5: Nil | AD5: Local and DEV testing completed 4/27/2026 Defect was added for not able to create project website, worked on that and will be creating PR today - 4/30/2026 Alice tested the sub defect and closed it and said final regression alone pending for this story She was on unplanned PTO on may 1st, so it will be closed today - 5/4/2026 | AE5: Dev testing completed 4/27/2026 TST testing completed 4/28/2026
A6: 5 | B6: OnlineBidding | C6: 46135 | D6: 46149 | E6: OB-OP 8.6.0 Sprint 3 | F6: Preethi/Rajesh | G6: OP-2805 | H6: OP Transactions - PST to UTC conversion | I6: Being Developed | J6: 3 | AD6: Need help from Prabu''s end so kept on hold till he is back, trying to put multiple transactions today and check one more time in TST - 5/4/2026 Rajesh will try to check this in prod and let us know today if possible - 5/5/2026 This will be carry forwarded to next sprint as we cant reproduce this in TST and need to check in production with the help of carlos. Client is also aware of this - 5/6/2026
A7: 6 | B7: OnlineBidding | C7: 46135 | D7: 46149 | E7: OB-OP 8.6.0 Sprint 3 | F7: Preethi/Karthi | G7: OP-2811 - [Defect] | H7: Creating Project Websites Always Fails | I7: Completed | M7: 46141 | N7: 46141 | O7: Done | P7: Karthi | Q7: Nil | R7: Karthi | S7: Nil | T7: https://greatergiving.visualstudio.com/Greater%20Giving/_git/OP/pullrequest/9518 | U7: 46142 | V7: 46142 | W7: Rajesh | X7: NIl | Y7: Joe | Z7: 46142 | AA7: Nil | AB7: Nil | AC7: Nil | AD7: Fixed the bug and tested in local 4/29/2026 Tested in DEV - 4/30/2026 | AE7: TST testing completed 5/4/2026
A8: 7 | B8: OnlineBidding | C8: 46135 | D8: 46149 | E8: OB-OP 8.6.0 Sprint 3 - [Stretch] | F8: Preethi | G8: OB-3990 | H8: OB Filters - Apply button function is not working after when we see “No Packages found.” and then make changes to the filters | I8: Completed | J8: 3 | K8: 3 | M8: 46142 | N8: 46142 | O8: Done | P8: Nivetha | Q8: Nil | R8: Karthi | S8: Nil | T8: https://greatergiving.visualstudio.com/Greater%20Giving/_git/OnlineBidding/pullrequest/9528 | U8: 46146 | V8: 46147 | W8: Rajesh | X8: Nil | Y8: Joe | Z8: 46147 | AA8: Nil | AB8: Nil | AC8: Nil | AD8: Fixed the issue in local and testing multiple scenarios related to filter and search combination - 4/30/2026 | AE8: Devtesting completed 5/4/2026 TST testing completed 5/6/2026
A9: 8 | B9: OnlineBidding | C9: 46135 | D9: 46149 | E9: OB-OP 8.6.0 Sprint 3 - [Stretch] | F9: Preethi | G9: OB-3987 | H9: Update OB Footer to not be hardcoded date | I9: Completed | J9: 1 | K9: 1 | M9: 46142 | N9: 46142 | O9: Done | P9: Preethi | Q9: Nil | R9: Karthi | S9: Nil | T9: https://greatergiving.visualstudio.com/Greater%20Giving/_git/OnlineBidding/pullrequest/9523 | U9: 46142 | V9: 46143 | W9: Rajesh | X9: Nil | Y9: Joe | Z9: 46143 | AA9: Nil | AB9: Nil | AC9: Nil | AD9: Updated the code and tested in local 4/30/2026 | AE9: TST testing completed 5/4/2026
A10: 9 | B10: OnlineBidding | C10: 46135 | D10: 46149 | E10: OB-OP 8.6.0 Sprint 3 - [Stretch] | F10: Preethi | G10: OB-3992 | H10: SMS Null Delivery Status | I10: Completed | J10: 1 | K10: 1 | M10: This is not development ticket, its investigation ticket | AD10: This is an investigation ticket, so no PR has been raised for this, analysed on the points given from PO and shared the analysis along with screenshot and added it in JIRA comments as well. Joe will have a look on it and it will be closed today - 5/7/2026 | AE10: No testing efforts needed for this ticket
A11: 10 | B11: OnlineBidding | C11: 46135 | D11: 46149 | E11: OB-OP 8.6.0 Sprint 3 | F11: Rajesh | G11: OP-2810 | H11: Determine production use case | I11: Completed | J11: 2 | K11: 2 | M11: This is not development ticket, its investigation ticket | AD11: This is an investigation ticket, so no PR has been raised for this, analysed on the points given from PO and shared the analysis along with screenshot and added it in JIRA comments

Sheet OB-OP 8.6.0 Sprint 3-Defect 
A1: S.No | B1: Sprint | C1: Story/Defect ID | D1: Parent Story | E1: Developer | F1: Issue Type | G1: Issue Description | H1: Priority | I1: Defect Source | J1: Type | K1: Status | L1: Root Cause Category | M1: Comments | N1: Found By | O1: RCA Comment
B2: OB-OP 8.6.0 Sprint 3 | C2: OP-2811 | D2: OP-2809 | E2: Preethi | F2: Defect | G2: Creating Project Websites Always Fails | H2: Significant | I2: Manual | J2: Internal | K2: Closed | L2: Development | M2: Created many pages and checked but new project website got failed | N2: Alice | O2: Checked all pages in OP as well as GGO to OP flow, but missed to check in the new project by creating new project website
B3: OB-OP 8.6.0 Sprint 3 | C3: OB-3990 | D3: Regression | E3: Preethi | F3: Defect | G3: OB Filters - Apply button function is not working after when we see “No Packages found.” and then make changes to the filters | H3: Significant | I3: Manual | J3: Internal | K3: Closed | L3: Existing_Issues | M3: This was broken as part of doing something else as we were working on mutltiple scenarios of filter and search | N3: Nivetha | O3: This was broken as part of doing something else as we were working on mutltiple scenarios of filter and search

Sheet OB-OP 8.6.0 Sprint 2-Status
A1: S.No | B1: Application Name | C1: Sprint Start Date | D1: Sprint End Date | E1: Sprint | F1: Developer | G1: Story ID/Defect ID | H1: Description | I1: Status | J1: Estimated(hrs/sp) | K1: Actual(hrs/sp) | L1: Actual Hours Worklog | M1: Dev Start Date | N1: Dev End Date | O1: Unit testing | P1: Peer Tested By | Q1: Peer Tested Defects, if any | R1: Peer Reviewed By | S1: Peer Code Review Comments, if any | T1: PR Number/Link | U1: PR Created Date | V1: PR Approved Date | W1: Onsite Lead Code Review | X1: Code Review Comments, if any | Y1: Client Code Review | Z1: Approved Date | AA1: Code Review Comments, if any2 | AB1: Internal PO -POV Comments | AC1: Client PO -POV Comments | AD1: Comments | AE1: QA Comments
A2: 1 | B2: OnlineBidding | C2: 46121 | D2: 46135 | E2: OB-OP 8.6.0 Sprint 2 | F2: Karthi/Preethi/Rajesh | G2: OP-2805 | H2: OP Transactions - PST to UTC conversion | I2: Being Developed | J2: 3 | AD2: Need Rajesh's help on this to test thorugh TST DB, so will be doing this in next week - 4/10/2026 Couldn't find the place as mentioned in the AC, so need Prabu's help as well on this, hence this will be carry forwarded 4/23/2026
A3: 2 | B3: OnlineBidding | C3: 46121 | D3: 46135 | E3: OB-OP 8.6.0 Sprint 2 | F3: Preethi | G3: OB-3978 | H3: Fix: Bidder Link appearing as anonymous | I3: Completed | J3: 2 | K3: 2 | M3: 46122 | N3: 46122 | O3: Done | P3: Nivetha | Q3: Nil | R3: Karthi | S3: Nil | T3: https://greatergiving.visualstudio.com/Greater%20Giving/_git/OnlineBidding/pullrequest/9458 | U3: 46122 | V3: 46123 | W3: Rajesh | X3: Nil | Y3: Joe | Z3: 46123 | AA3: Nil | AB3: Nil | AC3: Nil | AD3: Completed development and tested in local, Deployed in DEV for testing 4/10/2026 | AE3: Dev testing completed 4/10/2026 TST testing completed 4/13/2026
A4: 3 | B4: OnlineBidding | C4: 46121 | D4: 46135 | E4: OB-OP 8.6.0 Sprint 2 | F4: Preethi | G4: OB-3974 | H4: Outbid texts no longer go to that specific package | I4: Completed | J4: 3 | K4: 3 | M4: 46122 | N4: 46122 | O4: Done | P4: Nivetha | Q4: Nil | R4: Karthi | S4: Nil | T4: https://greatergiving.visualstudio.com/Greater%20Giving/_git/OnlineBidding/pullrequest/9468 | U4: 46126 | V4: 46127 | W4: Rajesh | X4: Nil | Y4: Joe | Z4: 46127 | AA4: Nil | AB4: Nil | AC4: Nil | AD4: Completed development, not getting mail in DEV so deployment cant be done for testing 4/10/2026 Mail received and checked in DEV and created PR - 4/14/2026 | AE4: Dev testing completed 4/15/2026 TST testing completed 4/16/2026
A5: 4 | B5: OnlineBidding | C5: 46121 | D5: 46135 | E5: OB-OP 8.6.0 Sprint 2 | F5: Karthi | G5: OP-2809 | H5: OP - Synk remediation | I5: Being Developed | J5: 3 | M5: 46122 | AD5: Started analysis Fixing the issues one by one 4/17/2026 Tested in local, except pages option rest all working today, 4/22/2026 Deployed in DEV for testing today, once all pages are working, then PR will be sent out today 4/23/2026
A6: 5 | B6: OnlineBidding | C6: 46121 | D6: 46135 | E6: OB-OP 8.6.0 Sprint 2 | F6: Preethi | G6: OB-3977 | H6: OB - SNYK remediation | I6: Completed | J6: 3 | K6: 3 | M6: 46126 | N6: 46129 | O6: Done | P6: Nivetha | Q6: Nil | R6: Karthi | S6: Nil | T6: https://greatergiving.visualstudio.com/Greater%20Giving/_git/OnlineBidding/pullrequest/9484 | U6: 46129 | V6: 46130 | W6: Rajesh | X6: Nil | Y6: Joe | Z6: 46130 | AA6: Nil | AB6: Nil | AC6: Nil | AD6: Trying to fix the sync points 4/17/2026 Updated the points and deployed in DEV for testing, for other points shared the reason 4/17/2026 | AE6: Dev testing completed 4/17/2026 TST testing completed 4/21/2026
A7: 6 | B7: OnlineBidding | C7: 46121 | D7: 46135 | E7: OB-OP 8.6.0 Sprint 2 - [Stretch] | F7: Preethi | G7: OB-3984 | H7: Featured Packages - Should follow order of Packages in OB Settings | I7: Completed | J7: 2 | K7: 2 | M7: 46133 | N7: 46133 | O7: Done | P7: Nivetha | Q7: Nil | R7: Karthi | S7: Nil | T7: https://greatergiving.visualstudio.com/Greater%20Giving/_git/OnlineBidding/pullrequest/9492 | U7: 46133 | V7: 46134 | W7: Rajesh | X7: Nil | Y7: Joe | Z7: 46134 | AA7: Nil | AB7: Nil | AC7: Nil | AD7: Development and local testing completed 4/21/2026 | AE7: Dev testing completed 4/21/2026
A8: 7 | B8: OnlineBidding | C8: 46121 | D8: 46135 | E8: OB-OP 8.6.0 Sprint 2 - [Stretch] | F8: Preethi | G8: OB-3965 | H8: Swap Apply and Clear in filters area | I8: Completed | J8: 2 | K8: 2 | M8: 46134 | N8: 46134 | O8: Done | P8: Nivetha | Q8: Nil | R8: Karthi | S8: Nil | T8: https://dev.azure.com/greatergiving/Greater%20Giving/_git/OnlineBidding/pullrequest/9498 | U8: 46134 | V8: 46135 | W8: Rajesh | X8: Nil | Y8: Joe | Z8: 46135 | AA8: Nil | AB8: Nil | AC8: Nil | AD8: Development and local testing completed 4/22/2026 | AE8: Dev testing completed 4/22/2026

Sheet OB-OP 8.6.0 Sprint 2-Defect
A1: S.No | B1: Sprint | C1: Story/Defect ID | D1: Parent Story | E1: Developer | F1: Issue Type | G1: Issue Description | H1: Priority | I1: Defect Source | J1: Type | K1: Status | L1: Root Cause Category | M1: Comments | N1: Found By | O1: RCA Comment
B2: OB-OP 8.6.0 Sprint 2 | C2: OB-3978 | E2: Preethi | F2: Defect | G2: Fix: Bidder Link appearing as anonymous | H2: Significant | I2: Manual | J2: External | K2: Closed | L2: Development | M2: When no package is created, bidder info is not seen | N2: Client | O2: We have written the code to call bidder only after the success of package API, so when no package was there, bidder API wasn't called
B3: OB-OP 8.6.0 Sprint 2 | C3: OB-3974 | E3: Preethi | F3: Defect | G3: Outbid texts no longer go to that specific package | H3: Significant | I3: Manual | J3: External | K3: Closed | L3: Development | M3: We have changed the routes for new UI and missed to test email scenarios | N3: Client | O3: We have changed the routes for new UI and missed to test email scenarios

Sheet OB-OP 8.6.0 Sprint 1-Status
A1: S.No | B1: Application Name | C1: Sprint Start Date | D1: Sprint End Date | E1: Sprint | F1: Developer | G1: Story ID/Defect ID | H1: Description | I1: Status | J1: Estimated(hrs/sp) | K1: Actual(hrs/sp) | L1: Actual Hours Worklog | M1: Dev Start Date | N1: Dev End Date | O1: Unit testing | P1: Peer Tested By | Q1: Peer Tested Defects, if any | R1: Peer Reviewed By | S1: Peer Code Review Comments, if any | T1: PR Number/Link | U1: PR Created Date | V1: PR Approved Date | W1: Onsite Lead Code Review | X1: Code Review Comments, if any | Y1: Client Code Review | Z1: Approved Date | AA1: Code Review Comments, if any2 | AB1: Internal PO -POV Comments | AC1: Client PO -POV Comments | AD1: Comments | AE1: QA Comments
A2: 1 | B2: OnlineBidding | C2: 46107 | D2: 46121 | E2: OB-OP 8.6.0 Sprint 1 | F2: Prabu | G2: OP-2807 | H2: Update OP splash page | I2: Completed | J2: 2 | K2: 2 | L2: 71.75 | M2: 46108 | N2: 46120 | O2: Done | P2: Nivetha | Q2: Nil | R2: Preethi | S2: Nil | T2: No PR, only SQL queries, those are updated in the JIRA ticket | U2: Nil | V2: Nil | W2: Rajesh | X2: Nil | Y2: Joe | Z2: Nil | AA2: Nil | AB2: Nil | AC2: Nil | AD2: Need to find an approach to update the css 3/27/2026 Found the table in DB and updated in local, when trying to update in DEV , getting error before login page itself, analysing on that - 4/7/2026 | AE2: Tested in TST 4/8/2026 Tested in TST 4/9/2026
A3: 2 | B3: OnlineBidding | C3: 46107 | D3: 46121 | E3: OB-OP 8.6.0 Sprint 1 | F3: Preethi | G3: OB-3968 | H3: OB - Read Donation Settings | I3: Completed | J3: 3 | K3: 3 | L3: 61.75 | M3: 46108 | N3: 46113 | O3: Done | P3: Nivetha | Q3: Nil | R3: Karthi | S3: Nil | T3: https://greatergiving.visualstudio.com/Greater%20Giving/_git/OnlineBidding/pullrequest/9421 | U3: 46113 | V3: 46115 | W3: Prabu | X3: Nil | Y3: Joe | Z3: 46115 | AA3: Nil | AB3: Nil | AC3: Nil | AD3: Started development, added migration script to add new column and updated the condition to show/hide based on the new parameter 3/27/2026 Updated the code by refactoring few approaches 3/30/2026 Prabu suggested to make 2 methods into single method, updated that and tested in local as well as in DEV 4/1/2026 | AE3: Tested in TST 4/3/2026
A4: 3 | B4: OnlineBidding | C4: 46107 | D4: 46121 | E4: OB-OP 8.6.0 Sprint 1 | F4: Karthi/Preethi | G4: OP-2805 | H4: OP Transactions - PST to UTC conversion | I4: Being Developed | J4: 2 | L4: 46 | M4: 46111 | AD4: Started analysis, trying to find the location 3/30/2026 Still analysing to find the place from where the changes are being happening, as far we are saving the value from PAPI to OP,so need to confirm in PAPI as well - 4/7/2026
A5: 4 | B5: OnlineBidding | C5: 46107 | D5: 46121 | E5: OB-OP 8.6.0 Sprint 1 - [Stretch] | F5: Preethi | G5: OB-3969 | H5: UI Artifact around "Show Item Donor Name" selection | I5: Completed | J5: 1 | K5: 1 | L5: 16.75 | M5: 46114 | N5: 46114 | O5: Done | P5: Nivetha | Q5: Nil | R5: Karthi | S5: Nil | T5: https://greatergiving.visualstudio.com/Greater%20Giving/_git/OnlineBidding/pullrequest/9428 | U5: 46115 | V5: 46119 | W5: Prabu | X5: Nil | Y5: Joe | Z5: 46119 | AA5: Nil | AB5: Nil | AC5: Nil | AD5: Development and local testing completed 4/3/2026 Tested in DEV and created PR - 4/3/2026 | AE5: Tested in DEV 4/3/2026 Tested in TST 4/7/2026
A6: 5 | B6: OnlineBidding | C6: 46107 | D6: 46121 | E6: OB-OP 8.6.0 Sprint 1 - [Stretch] | F6: Preethi | G6: OB-3954 | H6: Missing Font resources | I6: Completed | J6: 1 | K6: 1 | L6: 18.5 | M6: 46115 | N6: 46118 | O6: Done | P6: Nivetha | Q6: Nil | R6: Karthi | S6: Nil | T6: https://greatergiving.visualstudio.com/Greater%20Giving/_git/OnlineBidding/pullrequest/9435 | U6: 46119 | V6: 46119 | W6: Prabu | X6: Nil | Y6: Joe | Z6: 46119 | AA6: Nil | AB6: Nil | AC6: Nil | AD6: Updated the code, when checked in DEV, for me and karthi console error is not coming, but for nivetha its coming, so rechecking on that 4/6/2026 | AE6: Tested in DEV - 4/6/2026 Tested in TST - 4/6/2026

Sheet OB-OP 8.6.0 Sprint 1-Defect
A1: S.No | B1: Sprint | C1: Story/Defect ID | D1: Parent Story | E1: Developer | F1: Issue Type | G1: Issue Description | H1: Priority | I1: Defect Source | J1: Type | K1: Status | L1: Root Cause Category | M1: Comments | N1: Found By | O1: RCA Comment
B2: OB-OP 8.6.0 Sprint 1 - [Stretch] | C2: OB-3969 | E2: Preethi | F2: Defect | G2: UI Artifact around "Show Item Donor Name" selection | H2: Significant | I2: Manual | J2: External | K2: Closed | L2: Requirements | M2: We have already added this point in the observation sheet and shared with derek | N2: Client | O2: We already found the missing things in new UI and shared the document with PO, they missed to create story for that

Sheet OB-OP 8.5 Sprint 4-Status
A1: S.No | B1: Application Name | C1: Sprint Start Date | D1: Sprint End Date | E1: Sprint | F1: Developer | G1: Story ID/Defect ID | H1: Description | I1: Status | J1: Estimated(hrs/sp) | K1: Actual(hrs/sp) | L1: Actual Hours Worklog | M1: Dev Start Date | N1: Dev End Date | O1: Unit testing | P1: Peer Tested By | Q1: Peer Tested Defects, if any | R1: Peer Reviewed By | S1: Peer Code Review Comments, if any | T1: PR Number/Link | U1: PR Created Date | V1: PR Approved Date | W1: Onsite Lead Code Review | X1: Code Review Comments, if any | Y1: Client Code Review | Z1: Approved Date | AA1: Code Review Comments, if any2 | AB1: Internal PO -POV Comments | AC1: Client PO -POV Comments | AD1: Comments | AE1: QA Comments
A2: 1 | B2: OnlineBidding | C2: 46093 | D2: 46107 | E2: OB-OP 8.5 Sprint 4 | F2: Karthi | G2: OP-2803 | H2: Add link to privacy policy and terms of use on OP login | I2: Completed | J2: 1 | K2: 1 | L2: 11.75 | M2: Development done in last sprint, only testing in this sprint | N2: Development done in last sprint, only testing in this sprint | O2: Done | P2: Mercy | Q2: Nil | R2: Preethi | S2: Nil | T2: https://greatergiving.visualstudio.com/Greater%20Giving/_git/OP/pullrequest/9346 | U2: 46093 | V2: 46100 | W2: Prabu | X2: Nil | Y2: Joe | Z2: 46100 | AA2: Nil | AB2: Nil | AC2: Nil | AD2: Updated the HTML in azure but seeing console error and we cant able to login to OP after that, since OB CRT release is priority now, it will be done after that 3/13/2026 DEV testing completed 3/20/2026 | AE2: TST testing completed 3/20/2026
A3: 2 | B3: OnlineBidding | C3: 46093 | D3: 46107 | E3: OB-OP 8.5 Sprint 4 | F3: Karthi | G3: OP-2807 | H3: Update OP splash page | I3: Being Developed | J3: 2 | L3: 66.75 | AD3: Updated the splash page in DEV and TST but still the changes didnt get reflected, this will be done after OB CRT release 3/13/2026 Found a table from where the content was coming in UI, tried updating the content and it got worked, but the style changes are not able to be added inside the html content 3/26/2026
A4: 3 | B4: OnlineBidding | C4: 46093 | D4: 46107 | E4: OB-OP 8.5 Sprint 4 | F4: Preethi | G4: OP-2799 | H4: RSVP Receipts showing data tags for certain email clients | I4: Completed | J4: 3 | K4: 3 | L4: 33 | M4: Development done in last sprint, only testing in this sprint | N4: Development done in last sprint, only testing in this sprint | O4: Done | P4: Mercy | Q4: Nil | R4: Karthi | S4: Nil | T4: https://greatergiving.visualstudio.com/Greater%20Giving/_git/OP/pullrequest/9357 | U4: 46101 | V4: 46105 | W4: Prabu | X4: Nil | Y4: Joe | Z4: 46105 | AA4: Nil | AB4: Nil | AC4: Nil | AD4: Not receiving emails in DEV, need to check the email queue in server, but this can be done after OB CRT release as that is the priority for now 3/13/2026 Mail is receiving now, tested in DEV 3/20/2026 | AE4: DEV testing in progress 3/20/2026
A5: 4 | B5: OnlineBidding | C5: 46093 | D5: 46107 | E5: OB-OP 8.5 Sprint 4 | F5: Karthi | G5: OB-3951 | H5: Ensure Package Images are consistent | I5: Completed | J5: 3 | K5: 3 | L5: 41.25 | M5: 46094 | N5: 46100 | O5: Done | P5: Mercy | Q5: 1. overlapping with the banner is seen for an image 2. In mobile view some images seems to be stretched | R5: Preethi | S5: Nil | T5: https://greatergiving.visualstudio.com/Greater%20Giving/_git/OnlineBidding/pullrequest/9391 | U5: 46100 | V5: 46100 | W5: Prabu | X5: Nil | Y5: Joe | Z5: 46100 | AA5: Nil | AB5: Nil | AC5: Nil | AD5: Checking the images in browse, detail, deatured packages and comparing the codes 3/13/2026 Updated the code for browse, detail pages, checked for featured packages 3/16/2026 | AE5: Tested in TST 3/18/2026
A6: 5 | B6: OnlineBidding | C6: 46093 | D6: 46107 | E6: OB-OP 8.5 Sprint 4 | F6: Prabu | G6: OB-3956 | H6: Terms of Use and Privacy Policy Update | I6: Completed | J6: 1 | K6: 1 | L6: 5.75 | M6: 46098 | N6: 46098 | O6: Done | P6: Prabu | Q6: Nil | R6: Nil | S6: Nil | T6: https://greatergiving.visualstudio.com/Greater%20Giving/_git/OnlineBidding/pullrequest/9386 | U6: 46099 | V6: 46099 | W6: Nil | X6: Nil | Y6: Joe | Z6: 46099 | AA6: Nil | AB6: Nil | AC6: Nil | AD6: Development completed and local testing done 3/17/2026 | AE6: Tested in TST 3/18/2026
A7: 6 | B7: OnlineBidding | C7: 46093 | D7: 46107 | E7: OB-OP 8.5 Sprint 4 | F7: Preethi | G7: OB-3957 | H7: Closed packages w/o bids still show bid buttons | I7: Completed | J7: 3 | K7: 3 | L7: 17.5 | M7: 46094 | N7: 46099 | O7: Done | P7: Mercy | Q7: Nil | R7: Karthi | S7: Nil | T7: https://greatergiving.visualstudio.com/Greater%20Giving/_git/OnlineBidding/pullrequest/9378 | U7: 46098 | V7: 46100 | W7: Prabu | X7: Nil | Y7: Joe | Z7: 46100 | AA7: Nil | AB7: Nil | AC7: Nil | AD7: Tried to reproduce by pointing DEV and TST and adding console logs, but working as expected. Added some more safer checks in code to not to display buttons and timer 3/13/2026 Updated the code related to timezone issue and deployed in DEV for testing 3/16/2026 Both OB-3960 and OB-3957 have the same fix so will be raising the same PR | AE7: Trying to reproduce the issue in multiple environments 3/13/2026 Dev testing completed 3/17/2026 Dev testing completed 3/18/2026 TST testing completed 3/20/2026
A8: 7 | B8: OnlineBidding | C8: 46093 | D8: 46107 | E8: OB-OP 8.5 Sprint 4 | F8: Mercy | G8: OB-3959 | H8: OB 8.5.0 Release to CRT. | I8: Completed | J8: 3 | K8: 3 | L8: 53 | AE8: Deployed in CRT and testing started 3/20/2026
A9: 8 | B9: OnlineBidding | C9: 46093 | D9: 46107 | E9: OB-OP 8.5 Sprint 4 - [STRETCH] | F9: Preethi | G9: OB-3960 | H9: Ensure Ob Start Times are using pre-UX logic | I9: Completed | J9: 2 | K9: 2 | L9: 34.25 | M9: 46097 | N9: 46099 | O9: Done | P9: Mercy | Q9: Nil | R9: Karthi | S9: Nil | T9: https://greatergiving.visualstudio.com/Greater%20Giving/_git/OnlineBidding/pullrequest/9378 | U9: 46098 | V9: 46100 | W9: Prabu | X9: Nil | Y9: Joe | Z9: 46100 | AA9: Nil | AB9: Nil | AC9: Nil | AD9: Updated the code, checked with different timezones, we have 2 clarification, need to check with PO 3/16/2026 Worked on the 2 points after confirming from PO, deployed in DEV for testing 3/17/2026 Worked on the point suggested by prabu regarding time interval, updated that and deployed in DEV for testing 3/18/2026 | AE9: Dev testing completed for timezone issue and shared the result with prabu 3/16/2026 TST testing completed 3/18/2026
