Workbook

Sheet Dashboard
A1: Current Sprint | B1: {=INDEX($B$2:$B$97,MATCH(1,(($D$2:$D$97 >=TODAY())*($C$2:$C$97<=TODAY())),0))} -> MCS 26 Sprint 9 | C1: Current Sprint Sheet | D1: =CONCATENATE(B1,"-Status") -> MCS 26 Sprint 9-Status | E1: Sprint Start Date | F1: =VLOOKUP($B$1,$B$1:$C$97,2) -> 46150 | G1: Sprint End Date | H1: =VLOOKUP($B$1,$B$1:$D$97,3) -> 46163 | I1: Application Name | J1: MCS | K1: Users | L1: ganesh.vaidyanath@relevantz.com;hariharan.dhandapani@relevantz.com;shriveni.baskaran@relevantz.com;vaishnavi.vinoth@relevantz.com;florina.barani@relevantz.com;kalaivani.vijaya@relevantz.com;sathishkumar.velusamy@relevantz.com;srinivasu.ponnaganti@relevantz.com;jayapriya.suresh@relevantz.com | M1: Teams Name(GP-HSS_MCS Product) | N1: 19:3b0279a924ab4f35985570b471228dd7@thread.v2
A2: Sprint Type | B2: Sprint # | C2: Sprint Start Date | D2: Sprint End Date | E2: Assigned | F2: Completed | G2: Story points introduced/removed | H2: Sprint Summary | I2: Accomplishments | J2: Remarks | K2: Retro Points (Internal & External) | L2: Unplanned Leaves | M2: Data sanity Audit Status | N2: AuditDate | O2: Backlog Health | P2: Completed Stretch
A3: =IF(AND($D$1>=C3,$D$1<=D3),"CurrentSprint","NA") -> NA | B3: MCS 24 Sprint 17 | C3: 45520 | D3: 45533 | E3: 3 | F3: 3 | G3: Nil | I3: 1.Change Cafe Enterprise application export image format to JPG 2. UserName Length issue in the MCS Tool fixed | J3: Onboarding Sprint - Worked on access related items. Hariharan and BoobalaKrishnan has only got the access. Dinesh has not got access to the Client Tools. | K3: Internal: External:
A4: =IF(AND($D$1>=C4,$D$1<=D4),"CurrentSprint","NA") -> NA | B4: MCS 24 Sprint 18 | C4: 45534 | D4: 45547 | E4: 19 | F4: 13 | G4: 45689 and 45690 tasks has been moved to the next sprint (6SP) | I4: 1. Meal Pattern Flexibility. 2. SFTP sent to orders method. | J4: Dinesh has not still got the access to the code repo hence no points picked by him. | K4: Internal: External:
A5: =IF(AND($D$1>=C5,$D$1<=D5),"CurrentSprint","NA") -> NA | B5: MCS 24 Sprint 19 | C5: 45548 | D5: 45561 | E5: 12 | F5: 12 | G5: New ACs were added for #45900 - 1SP | I5: 1. New ACs for Meal Pattern Flexibility. 2. MCS - FR - Add "Test Email" button to SMTP settings 3. 2 user defect were closed. | J5: #45900(New ACs) is Moved to Sprint Stretch. #45444 is moved to Sprint Stretch | K5: Internal: External:
A6: =IF(AND($D$1>=C6,$D$1<=D6),"CurrentSprint","NA") -> NA | B6: MCS 24 Sprint 20 | C6: 45562 | D6: 45575 | E6: 18 | F6: 18 | G6: 6 (Assigned from Sprint Strech) Carry forwarded to next sprint | I6: 1. Report Layout Overrides. 2. Total Sugar Vaidation across application | J6: #45539 - Product Expiration Report. #45908 - MCS - ED - Inventory On Hand report. Pulled from the sprint strech, will move to sprint 20 | K6: Internal: External: Relevanz team for quickly becoming comfortable in the codebase and the quality work we did for this sprint
A7: =IF(AND($D$1>=C7,$D$1<=D7),"CurrentSprint","NA") -> NA | B7: MCS 24 Sprint 21 | C7: 45576 | D7: 45589 | E7: 11 | F7: 11 | G7: 3 (Assigned from Sprint Strech) | I7: 1. Report Layout Override - Group by. 2. Product Expiration Report. 3. Inventory On-hand Report | J7: #46255 - Pulled from the sprint strech, will move to sprint 22 | K7: Internal: External:Relevantz team members contributions & ramp up going well
A8: =IF(AND($D$1>=C8,$D$1<=D8),"CurrentSprint","NA") -> NA | B8: MCS 24 - Sprint 22 | C8: 45590 | D8: 45603 | E8: 11 | F8: 11 | G8: Nil | I8: 1. FOH/BOH Integration calculation issues 2. Cafeteria Filter Dashboard Refresh. 3. Balance Recolination Discripency | J8: Completed as planned. This Sprint Involved tasks with More analysis. | K8: External : Good Team Work
A9: =IF(AND($D$1>=C9,$D$1<=D9),"CurrentSprint","NA") -> NA | B9: MCS 24 Sprint 23 | C9: 45604 | D9: 45617 | E9: 13 | F9: 7 | I9: 1. Layout Override for Student Rooster Report 2. Newton Dashboard loading faster 3. Permissions for Employee and Special Adult key in Newton POS 4. Leftover calculations fixed in Edison report | J9: Internal CRC - 0 External CRC - 2 QA Defects - 1 Escaped Defects - 1 | K9: Internal: External:
A10: =IF(AND($D$1>=C10,$D$1<=D10),"CurrentSprint","NA") -> NA | B10: MCS 24 Sprint 24 | C10: 45618 | D10: 45636 | E10: 25 (9 +16) | F10: 12 | G10: 1+8+8 | I10: 1. POS - Function Keys Enable or Disable. 2. Production Escalation - Breakfast POS Hotfix. | J10: 1. POV is delayed due to unavailabilty of PO- Josh. 2. Since only one QA was available for this sprint, stories for this sprint was backloged in testing. (Milan - Client QA is on Vacation) 3. Introduced new stories in the last few of days of sprint closure (client) Internal CRC - 0 External CRC - 4 QA Defects - 0 Escaped Defects - 0 | K10: Internal: External: Relevanz team for quickly becoming comfortable in the codebase and the quality work we did for this sprint
A11: =IF(AND($D$1>=C11,$D$1<=D11),"CurrentSprint","NA") -> NA | B11: MCS 24 Sprint 25 | C11: 45637 | D11: 45659 | E11: 30 (25+5) | F11: 12 | G11: 5 | I11: 1. Completed the Production Escalation Task for Item Importers. 2.Completed Grouping and Sorting for Layout Overrides in Student Roster and Student Barcode Roster Report. 3. Price Contract Import UI part was completed. 4. Oauth2.0 R&D was completed successfully. 5. Analysis for POS Optimization. | J11: FYI SRX25080 - was introduced as a new production escalation task from Josh. Requested to Prioritize and release it as a HotFix. Client was out for last week hence PR approval and confirmation for any blockers were on-hold. Since Client QA(Milan) was on leave for the entire month. Only 1 QA - Andrews was available for testing. He was Involved in testing Client DEV stories as well. Internal CRC - 0 External CRC - 4 QA Defects - 2 Escaped Defects - 0 | K11: Internal: External: Relevantz team was very productive during holidays.
A12: =IF(AND($D$1>=C12,$D$1<=D12),"CurrentSprint","NA") -> NA | B12: MCS 25 Sprint 1 | C12: 45660 | D12: 45673 | E12: 22 (17 +5) | F12: 9 | G12: 5 | I12: 1.Completed the role importers. 2.Completed the GSDN Item importer. | J12: OAuth integration has dependency on SMTP approval from Relevantz for dev testing to be done. Import proce contracts - UI has been completed after initial POV approval and working on backend for the same Optiomazation of cafeteria permission - Need to combine the cafeteria category based user role permissions into the fetch query while login Internal CRC - 0 External CRC - 4 QA Defects - 0 Escaped Defects - 0 | K12: Internal: Andrews for handling testing effort on his plate External: Relevantz team provided Good dev support this sprint
A13: =IF(AND($D$1>=C13,$D$1<=D13),"CurrentSprint","NA") -> NA | B13: MCS 25 Sprint 2 | C13: 45674 | D13: 45687 | E13: 9 | F13: 9 | G13: 5 | I13: 1. Optimized Cafeteria Cache Permissions: Improved efficiency and security of the cafeteria system by optimizing cache permissions, ensuring smoother operations. 2. Implemented OAuth2.0: Successfully integrated OAuth2.0 for secure and seamless authentication, which was demonstrated effectively, showcasing our system's enhanced security measures. 3. Developed Import Price Contracts: Completed development changes for the implementation of import price contracts, paving the way for streamlined contract management. A Proof of Value (POV) has been scheduled to demonstrate the impact and effectiveness of these changes. | J13: Not able to close the stories within the sprint as planned since we have less bandwidth in testing New AC's were introduced at mid of the sprint that caused delay in executing the stories.(#45301 and #46563) Internal CRC - 1 External CRC - 2 QA Defects - 0 Escaped Defects - 0 | K13: Internal: Onboarded wave team successfully. Completed business KT sessions for all applications in MCS. External: Appreciation received from client team(Andrea, Rudy, Milan and Patrick) for Hari for Oauth implemention.
A14: =IF(AND($D$1>=C14,$D$1<=D14),"CurrentSprint","NA") -> NA | B14: MCS 25 Sprint 3 | C14: 45688 | D14: 45701 | E14: 26 | F14: 23 | G14: 4 | I14: 1. Bootstrap Migration Research: Completed the research and documented the findings. Identified the affected pages from this migration and created stories to fix the layout issues to complete the migration. 2. New ACs for Oauth2.0 Integration: New ACs for the Oauth2.0 Integration for the FRANKLIN application is completed. 3. New AC Developed Import Price Contracts: Completed development changes for the implementation of import price contracts, paving the way for streamlined contract management. 4. New Field for Item Importer: New field "Generate Recipe" for item importer has added. 5. Wave Team completed the analysis on SQLite Migration. | J14: Two Storieds #45301 and #46563 has its testign effort of 3SP carry forwarded to next sprint. #47119 and #21529 was was picked from the Sprint Stretch. Internal CRC - 0 External CRC - 1 QA Defects - 1 Escaped Defects - 0 | K14: Internal: Overall Team Collabration was good. External: Patrick mentioned in the retro that wave Team Ramp-up was good
A15: =IF(AND($D$1>=C15,$D$1<=D15),"CurrentSprint","NA") -> NA | B15: MCS 25 Sprint 4 | C15: 45702 | D15: 45715 | E15: 34 | F15: 29 | G15: 2 | I15: 1. Bootstrap Migration: Completed the implementations of the bootstrap changes for the following pages. Home, Application Pages (8 sub modules) 2. New ACs for Oauth2.0 Integration: New ACs for the Oauth2.0 Integration for the FRANKLIN application is completed. 3.Named Site Filter Defect: Script fix for the defect named side filter is completed. 4. New Field for Item Importer: New field "Generate Recipe" for item importer has been completed. which was demonstrated successfully. 5. Wave Team completed the SQLite Task as planned for this sprint. 6.Accessability Fix: Identified the places where we need to fix WCAG2.2 issues on MSA Web using Wave and AC Lite plugin | J15: Story #47120 has its testing pending so carry forwarded to next sprint. Story #46563 has its testing pending so carry forwarded to next sprint. Internal CRC - 1 External CRC - 1 QA Defects - 0 Escaped Defects - 1 | K15: Internal: Overall Team Collabration was good. Sprint went well as we were able to complete assigned tasks. External: Clients mentioned Sprint went well as we were able to complete assigned tasks.
A16: =IF(AND($D$1>=C16,$D$1<=D16),"CurrentSprint","NA") -> NA | B16: MCS 25 Sprint 5 | C16: 45716 | D16: 45729 | E16: 38 | F16: 35 | G16: 5 | I16: 1. Bootstrap Migration: Completed the implementations of the bootstrap changes for the following pages. Home, Application Pages (8 sub modules) 2.New Item Importing to price contract: New item adding to price contract has been completed. which was demonstrated successfully. 3. New Field for Item Importer: New field "Generate Recipe" for item importer has been completed. which was demonstrated successfully. 4. Wave Team completed the SQLite Task as planned for this sprint. | J16: "Story #47120 has its testing pending so carry forwarded to next sprint. Story #46563 has its testing pending so carry forwarded to next sprint. Hari had a laptop replacement which took 3 days and had to setup the entire environment from the scratch. Internal CRC - 1 External CRC - 5 QA Defects - 0 Escaped Defects - 1 | K16: Internal: Overall Team Collabration was good. Sprint went well as we were able to complete assigned tasks. External: Clients mentioned Sprint went well as we were able to complete assigned tasks.
A17: =IF(AND($D$1>=C17,$D$1<=D17),"CurrentSprint","NA") -> NA | B17: MCS 25 Sprint 6 | C17: 45730 | D17: 45743 | E17: 54 | F17: 40 | G17: 3 | I17: 1. Wave Team completed the Unit testing in xUnit (unit testing frameworks) for the Admin colsole and MCS Application Server and Started to analyze and create the Approach Document for the Newtom POS 2. Boostrap Migration changes completed for Admin Pages. 3. Price Contracts Import Implementation is completed. 4. Oauth 2.0 Integration for SMTP in POS is completed. | J17: Internal CRC - 1 External CRC - 1 QA Defects - 0 Escaped Defects - 0 | K17: Internal: Overall Team Collabration was good. Transition for Shriveni and Rajesh was smooth. External: Testing team has to sync-up with DEV for task inputs. Patrick Mentioned Wave Team shows good Progress. Andrea Mentioned Bootstrap Migration by Krish is going excellent
A18: =IF(AND($D$1>=C18,$D$1<=D18),"CurrentSprint","NA") -> NA | B18: MCS 25 Sprint 7 | C18: 45744 | D18: 45757 | E18: 36 | F18: 31 | G18: 8 | I18: 1. Wave Team completed the Development for Admin console and MCS Application server for Sqlite Migration. 2. Boostrap Migration changes completed for - Admin - Audit Logs and WCAG related changes have been done. 3. Production Defect for Production Bulk editor is fixed. | J18: Internal CRC - 0 External CRC - 1 QA Defects - 0 Escaped Defects - 0 | K18: Internal: Overall Team Collabration was good.. External: Patrick Mentioned Overall Relevantz team shows good progress.
A19: =IF(AND($D$1>=C19,$D$1<=D19),"CurrentSprint","NA") -> NA | B19: MCS 25 Sprint 8 | C19: 45758 | D19: 45771 | E19: 12 | F19: 25 | G19: 34 | I19: 1. Wave Team Started Newton POS i Started working on the Newton POS application and the development is inprogress . DB has been completed for writting the scripts for SQLite for Newtom POS 2. Boostrap Migration changes completed for Admin Pages 3. Price Contracts Import Implementation is completed. 4. Oauth 2.0 Integration for SMTP in POS is completed. | J19: Internal CRC - 0 External CRC - 1 QA Defects - 2 Escaped Defects - 0 | K19: Internal: Overall Team Collabration was good.. External: Patrick Mentioned Overall Relevantz team shows good progress. And RJ has mentioned the Wave team has the visibility of what they are working
A20: =IF(AND($D$1>=C20,$D$1<=D20),"CurrentSprint","NA") -> NA | B20: MCS 25 Sprint 9 | C20: 45772 | D20: 45785 | E20: 2 | F20: 2 | G20: 21 | I20: 1. Defects for the production bulk editor is completed. 2. Shriveni is working on the tesing backlogs on MSA. 3. Vaishnavi's onboarding was completed. | J20: Internal CRC - 0 External CRC - 1 QA Defects - 2 Escaped Defects - 0 | K20: Internal: Overall Team Collabration was good.. External: Vaishnavi's KT and onboarding was smooth and started to work on the stories. Defects on the bulk editor was closed
A21: =IF(AND($D$1>=C21,$D$1<=D21),"CurrentSprint","NA") -> NA | B21: MCS 25 Sprint 10 | C21: 45786 | D21: 45799 | E21: 2 | F21: 2 | G21: 13 | I21: 1.Shriveni-Completed the defect-User-Defined Report is Truncating Generic SQL Queries -Edison and Newton Application 2.Vaishnavi working on the story #47496 3.Hariharan Completed on the story #48013 | J21: Internal CRC - 0 External CRC - 0 QA Defects - 2 Escaped Defects - 0 | K21: Overall Team Collaboration was good.. Ganesh-Good communication for Pre-POV- by Josh
A22: =IF(AND($D$1>=C22,$D$1<=D22),"CurrentSprint","NA") -> NA | B22: MCS 25 Sprint 11 | C22: 45800 | D22: 45813 | E22: 16 | F22: 3 | G22: 12 | I22: 1.Shriveni-Completed the testing-48112, other two story back to develop. 2.Vaishnavi-working on the story #48520, and 47496-Ready for testing. 3..Hariharan - Send Approved Orders to vendor task was integreated in scheduled Job. 4. Hariharan - TLS encryption was integrated to Newton SMTP Email Configuration. | J22: "Internal CRC - 4 External CRC - 0 QA Defects - 0 Escaped Defects - 0 " | K22: Overall Team Collaboration was good..
A23: NA | B23: MCS 25 Sprint 12 | C23: 45814 | D23: 45828 | E23: 19 | F23: 10 | G23: 4 | I23: 1. Hariharan - Completed the Cherry Creek Production Report and Delivered to the Customer. 2. Hariharan - Completed the SQL Alert changes Version Update.. 3. Vaishnavi - Completed the Scrub Scripts Update for the apps. 4. Shriveni - MSA Client Testing has been completed. | J23: "Internal CRC - 1 External CRC - 3 QA Defects - 0 Escaped Defects - 0 " | K23: Overall Team Collaboration was good.. Shriveni Was helping a lot on the testing Progress.
A24: NA | B24: MCS 25 Sprint 13 | C24: 45831 | D24: 45841 | E24: 18 | F24: 9 | G24: 9 | I24: 1 Hari- Completed the Apply security changes to Email for Permissive TLS. 2.Shriveni - Completed the testing for Apply security changes to Email for Permissive TLS 3. Vaishnavi - Completed the Scrub Scripts Update2 for the apps. 4.Vaishnavi - Completed Permissions for Ad-Hoc Inventory. 5.Hariharan - Account Balances Affecting Adjustments Export. | J24: "Internal CRC - 2 External CRC - 0 QA Defects - 0 Escaped Defects - 0 " | K24: Overall Team Collaboration was good..
A25: NA | B25: MCS 25 Sprint 14 | C25: 45842 | D25: 45855 | E25: 18 | F25: 10 | G25: 8 | I25: 1.Hariharan - Completed Alert for SQL Version older than 2016. 2.Hariharan - Delivered CSUSA Plugin for Account Balance Adjustments Export 3.Hariharan - Completed LAUSD Production Plugin. 4.Shriveni - Completed the testing for Add ability to schedule sending orders to vendor. 5.Shriveni - Custom Report Changes for Elk Grove | J25: "Internal CRC - 3 External CRC - 5 QA Defects - 0 Escaped Defects - 0 " | K25: Internal: Overall Team Collabration was good. External: Successful sprint on completed the assigned task.
A26: NA | B26: MCS 25 Sprint 15 | C26: 45856 | D26: 45869 | E26: 13 | F26: 3 | G26: 7 | I26: 1.Hariharan - Completed Defect on the POS Batches. 2. Vaishnavi - Completed the Nebulizer SSO Parameter with Testing. 3. Progressing on the MCS DC SFTP. | J26: "Internal CRC - 5 External CRC - 1 QA Defects - 0 Escaped Defects - 0 " | K26: Internal: Overall Team Collabration was good. External: Vaishnavi on building up good rapo with Codebase
A27: NA | B27: MCS 25 Sprint 16 | C27: 45870 | D27: 45883 | E27: 12 | F27: 2 | G27: 6 | I27: 1.Completed Defect -Inventory On Hand is showing a parameter window. 2.Hariharan - Completed Apply mapping changes to PeopleSoft export | J27: "Internal CRC - 2 External CRC - 0 QA Defects - 0 Escaped Defects - 0 " | K27: Internal: Overall Team Collabration was good.
A28: NA | B28: MCS 25 Sprint 17 | C28: 45884 | D28: 45897 | E28: 16 | F28: 6 | G28: 6 | I28: 1.Vaishnavi-Completed the story -Add new bid group as a copy of existing bid group 2.Hariharan - Completed the story -Custom Report Changes (additional) for Elk Grove. 3.Hariharan -Completed the story -Apply mapping changes to Peoplesoft Export 4.Hariharan -Completed the story -Add an LaSIDs Export File to the Louisiana Plugin 5.-Shriveni -Completed the story(testing) -Add Support for Added Sugars Analysis | J28: "Internal CRC - 2 External CRC - 0 QA Defects - 0 Escaped Defects - 0 " | K28: Internal: Overall Team Collabration was good.
A29: NA | B29: MCS 25 Sprint 18 | C29: 45898 | D29: 45911 | E29: 12 | F29: 9 | G29: 6 | I29: 1.Vaishnavi-Completed the story -LAUSD Production Record Enhancement 2.Vaishnavi-Completed the story -Add SQL Version to District Details Report 3.Vaishnavi-Completed the story -Allow overwriting of default Captions and Tool Tips 4.Hariharan -Completed the story -City Paid Meals and Export to SAP | J29: "Internal CRC - 2 External CRC - 0 QA Defects - 0 Escaped Defects - 0 " | K29: Internal: Overall Team Collabration was good.
A30: NA | B30: MCS 25 Sprint 19 | C30: 45912 | D30: 45924 | E30: 8 | F30: 2 | G30: 0 | I30: 1.Hariharan -Completed the defect-Item Importer change detection not recognizing allergen changes | J30: "Internal CRC - 2 External CRC - 0 QA Defects - 0 Escaped Defects - 0 " | K30: Internal: Overall Team Collabration was good.
A31: NA | B31: MCS 25 Sprint 20 | C31: 45925 | D31: 45939 | E31: 4 | F31: 2 | G31: 10 | I31: 1.Vaishnavi-Completed the story -Add Sorting for Allergen Filter in Item Allergen Report 2.Vaishnavi-Completed the defect-Line Details Not Sorting Properly | J31: "Internal CRC - 10 External CRC - 1 QA Defects - 0 Escaped Defects - 0 " | K31: Internal: Overall Team Collabration was good.
A32: NA | B32: MCS 25 Sprint 21 | C32: 45940 | D32: 45953 | E32: 6 | F32: 2 | G32: 10 | I32: 1.Vaishnavi-Completed the story -Cherry Creek Production Report Change. | J32: "Internal CRC - 0 External CRC - 0 QA Defects - 0 Escaped Defects - 0 " | K32: Internal: Overall Team Collabration was good.
A33: NA | B33: MCS 25 Sprint 22 | C33: 45954 | D33: 45967 | E33: 6 | F33: 6 | G33: 5 | I33: 1.Hariharan-Completed the story -Improve Handling of Unconfirmed/Canceled In-Person Credit Card Transactions 2.Hariharan-Completed the story -Prevent Managers from Zeroing out Production Quantities | J33: "Internal CRC - 5 External CRC - 5 QA Defects - 0 Escaped Defects - 0 " | K33: Internal: Overall Team Collabration was good.
A34: NA | B34: MCS 25 Sprint 23 | C34: 45968 | D34: 45981 | E34: 8 | F34: 5 | G34: 11 | I34: 1.Hariharan -Completed the story-Plugin - CCSD Claim Plugin Update Needed 2.Vaishnavi-Completed the defect-Production Report Numbers are Not Correct | J34: "Internal CRC - 0 External CRC - 3 QA Defects - 0 Escaped Defects - 0 " | K34: Internal: The team collaborated well overall
A35: NA | B35: MCS 25 Sprint 24 | C35: 45982 | D35: 46009 | E35: 14 | F35: 12 | G35: 10 | I35: 1.Hariharan -Completed the story-Plugin - Implement Generic ERP Export. 2.Hariharan -Completed the story-Cannot print request for bid quote bid period. 3.Vaishnavi-Completed the story-Add support for District Tags. 4.Vaishnavi-Completed the story-Lee County PSD Export (Revert Changes) | J35: "Internal CRC - 0 External CRC -2 QA Defects - 0 Escaped Defects - 0 "
A36: NA | B36: MCS 25 Sprint 25 | C36: 46010 | D36: 46037 | E36: 9 | F36: 4 | G36: 12 | I36: 1.Vaishnavi-Completed the story-Link Privacy Statement in T&C's 2.Vaishnavi-Completed the story- Update Customer support link | J36: "Internal CRC - 0 External CRC -0 QA Defects - 0 Escaped Defects - 0 "
A37: NA | B37: MCS 26 Sprint 1 | C37: 46038 | D37: 46051 | E37: 9 | F37: 3 | G37: 7 | I37: 1.Vaishnavi-Completed the story-Add Buy American exception dropdown in Item-Specifics 2.Vaishnavi-Completed the story- Add Support for "Bulk Production" preference to the checklist 3.Hariharan -Completed the story- Plugin - Add Support for Non-Reimbursable Snack to GA Claim Export | J37: "Internal CRC - 4 External CRC -1 QA Defects - 0 Escaped Defects - 0 " | K37: External:Hari received kudos from Kalai for his support with clarifications, handling struggles, and bounce back, and from Joshua for his excellent communication. Internal: The team collaborated smoothly and efficiently. | P37: 2
A38: NA | B38: MCS 26 Sprint 2 | C38: 46052 | D38: 46065 | E38: 6 | F38: 4 | G38: 5 | I38: 1.Vaishnavi-Completed the story-Checklists Visibility Settings. 2.Hariharan -Completed the story- Plugin - Import Price Contract Update - Append and Inactivate | J38: "Internal CRC - 2 External CRC -1 QA Defects - 0 Escaped Defects - 0 " | K38: Internal: Hari– Successfully completed the Buy American initiative.He managed to continue the story even though the acceptance criteria were unclear. The attendance report work was delayed due to Vaishnavi’s unplanned PTO, but he adjusted and kept moving forward. He also faced bouncebacks on Import Price Contracts and updates, yet completed the task successfully. he had trouble validating Sioux City Schools at first because of missing details, but he followed up and got the needed information. Florina – Effectively executed the changes to test cases from writing. External: The team collaborated smoothly and efficiently.. | L38: Hari - Vaishnavi - 6 Florina - Ganesh - | P38: 0
A39: NA | B39: MCS 26 Sprint 3 | C39: 46066 | D39: 46079 | E39: 8 | F39: 5 | G39: 8 | I39: 1.Vaishnavi-Completed the story-Fix sorting in Allergen Reports. 2.Vaishnavi-Completed the story-Apply USDA Feedback to Meal Planning Reports. 3.Hariharan -Completed the story-Enable SmartSense Integration in System Settings. 4.Hariharan -Completed the story-Plugin - Generic ERP Export SFTP support | J39: "Internal CRC - 1 External CRC -0 QA Defects - 0 Escaped Defects - 0 | K39: Internal: Overall Team Collabration was good.. External: Teams should regularly practice Git, rebasing, and merging to establish these as standard habits. | L39: Hari - Vaishnavi - Florina - 1 Ganesh - | P39: 1
A40: NA | B40: MCS 26 Sprint 4 | C40: 46080 | D40: 46093 | E40: 4 | F40: 4 | G40: 7 | I40: 1.Hariharan -Completed the story-Atlanta Report Request Built off of Record of Attendance Report. 2.Hariharan -Completed the story-Buy American Tracking Report. 3.Hariharan -Completed the defect-Log File is Almost 200 gig. | J40: "Internal CRC - 0 External CRC -0 QA Defects - 0 Escaped Defects - 2 | K40: Internal: Overall Team Collabration was good.. External: All code changes need peer review. If changes are requested, the PR creator must ask for another review after updates | L40: Hari - Vaishnavi - Florina - Ganesh - | P40: 1
...

Sheet Defect-template
A1: S.No | B1: Sprint # | C1: Story/Defect ID | D1: Parent Story | E1: Developer | F1: Issue Type | G1: Issue Description | H1: Priority | I1: Defect Source | J1: Type | K1: Status | L1: Root Cause Category | M1: Comments

Sheet Unlplanned Leaves
A2: Total Unplanned Leaves | B2: =SUM(B18:E18) -> 9.5
B3: Resource Name
A4: Sprint Name | B4: Hariharan Dhandapani | C4: Vaishnavi Vinothkumar | D4: Florina Bharani Kumar | E4: Ganesh Vaidyanathan | F4: Remarks
A5: MCS 26 Sprint 2 (30-Jan-26 to 12-Feb-26) | C5: 6 | F5: Vaishnavi was on leave between 4th and 12th February because of a family emergency.
A6: MCS 26 Sprint 3 (13-Feb-26 to 26-Feb-26) | D6: 1 | F6: Florina was on leave on 23 February due to the passing of her uncle
A7: MCS 26 Sprint 4 (27-Feb-26 to 12-Mar-26)
A8: MCS 26 Sprint 5 (13-Mar-26 to 26-Mar-26)
A9: MCS 26 Sprint 6 (27-Mar-26 to 09-Apr-26)
A10: MCS 26 Sprint 6 (09-Apr-26 to 23-Apr-26 ) | D10: 1 | E10: 1.5 | F10: Florina was on leave on 23rd Apr due to voting And Ganesh was on leave on 14th Apr(half day) and 20th Apr due to mother's health
A11: MCS 26 Sprint 6 (24-Apr-26 to 07-May-26 )
A18: Total | B18: =SUM(B5:B17) -> 0 | C18: =SUM(C5:C17) -> 6 | D18: =SUM(D5:D17) -> 2 | E18: =SUM(E5:E17) -> 1.5

Sheet MCS 26 Sprint 9-Status
A1: S.No | B1: Application Name | C1: Sprint Start Date | D1: Sprint End Date | E1: Sprint | F1: Developer | G1: Story ID/Defect ID | H1: Description | I1: Status | J1: Estimated(hrs/sp) | K1: Actual(hrs/sp) | L1: Actual Hours (Worklog) | M1: Dev Start Date | N1: Dev End Date | O1: Unit testing | P1: Peer Tested By | Q1: Peer Tested Defects, if any | R1: Peer Reviewed By | S1: Peer Code Review Comments, if any | T1: PR Number/Link | U1: PR Created Date | V1: Reviewer 1 | W1: PR Approved Date | X1: Code Review Comments, if any | Y1: Reviewer 2 | Z1: Approved Date | AA1: Code Review Comments, if any2 | AB1: Internal PO -POV Comments | AC1: Client PO -POV Comments | AD1: Comments | AE1: Column1
A2: =ROW() - ROW(Table1459678101112314151316171920211823[[#Headers],[S.No]]) -> 1 | B2: =Dashboard!$J$1 -> MCS | C2: 46150 | D2: 46163 | E2: MCS 26 Sprint 9 | F2: Vaishnavi | G2: 51826 | H2: Safety Check in Franklin for MSA (Web) | I2: Story Ready For Testing | J2: 3 | K2: =Table14596781011123141513161719202118232224252627282930313233343536373839[[#This Row],[Estimated(hrs/sp)]] * 4 -> 12 | L2: 25 | M2: 46150 | N2: Nil | O2: Nil | P2: Nil | Q2: Nil | R2: Nil | S2: Nil | T2: https://dev.azure.com/heartlandschools/MCS/_git/Franklin/pullrequest/48851 | U2: 46147 | V2: Hari | W2: 46147 | X2: Nil | Y2: Andrea | Z2: 46148 | AA2: Nil | AB2: Nil | AC2: Nil
A3: =ROW() - ROW(Table1459678101112314151316171920211823[[#Headers],[S.No]]) -> 2 | B3: =Dashboard!$J$1 -> MCS | C3: 46150 | D3: 46163 | E3: MCS 26 Sprint 9 | F3: Vaishnavi | G3: 43179 | H3: Align Edison Fact Label with FDA Food Fact Label | I3: Story Ready For Testing | J3: 1 | K3: =Table14596781011123141513161719202118232224252627282930313233343536373839[[#This Row],[Estimated(hrs/sp)]] * 4 -> 4 | L3: 17 | M3: 46150 | N3: Nil | O3: Nil | P3: Nil | Q3: Nil | R3: Nil | S3: Nil | T3: https://dev.azure.com/heartlandschools/MCS/_git/Edison/pullrequest/48965 | U3: 46153 | V3: Hari | W3: 46154 | X3: Nil | Y3: Andrea | Z3: 46154 | AA3: Nil | AB3: Nil | AC3: Nil
A4: =ROW() - ROW(Table1459678101112314151316171920211823[[#Headers],[S.No]]) -> 3 | B4: =Dashboard!$J$1 -> MCS | C4: 46150 | D4: 46163 | E4: MCS 26 Sprint 9 Stretch | F4: Hariharan Dhandapani | G4: 53117 | H4: Improve Handling of Incomplete In-Person Credit Card Transactions | I4: Story Being Developed | J4: 1 | K4: =Table14596781011123141513161719202118232224252627282930313233343536373839[[#This Row],[Estimated(hrs/sp)]] * 4 -> 4 | L4: 10 | M4: 46150 | N4: Nil | O4: Nil | P4: Nil | Q4: Nil | R4: Nil | S4: Nil | T4: Nil | U4: Nil | V4: Nil | W4: Nil | X4: Nil | Y4: Nil | Z4: Nil | AA4: Nil | AB4: Nil | AC4: Nil
A5: =ROW() - ROW(Table1459678101112314151316171920211823[[#Headers],[S.No]]) -> 4 | B5: =Dashboard!$J$1 -> MCS | C5: 46150 | D5: 46163 | E5: MCS 26 Sprint 9 | F5: Vaishnavi | G5: 52692 | H5: Add Start/End Date to Price Contract in Item Usage Repo | I5: Story Peer Review | J5: 1 | K5: =Table14596781011123141513161719202118232224252627282930313233343536373839[[#This Row],[Estimated(hrs/sp)]] * 4 -> 4 | L5: 17 | M5: 46153 | N5: Nil | O5: Nil | P5: Nil | Q5: Nil | R5: Nil | S5: Nil | T5: https://dev.azure.com/heartlandschools/MCS/_git/Edison/pullrequest/49035 | U5: 46155 | V5: Hari | W5: Nil | X5: Nil | Y5: Nil | Z5: Nil | AA5: Nil | AB5: Nil | AC5: Nil
A6: =ROW() - ROW(Table1459678101112314151316171920211823[[#Headers],[S.No]]) -> 5 | B6: =Dashboard!$J$1 -> MCS | C6: 46150 | D6: 46163 | E6: MCS 26 Sprint 9 | F6: Vaishnavi | G6: 51328 | H6: Sort "orders available to receive" by Delivery Date | I6: Story Being Developed | J6: 2 | K6: =Table14596781011123141513161719202118232224252627282930313233343536373839[[#This Row],[Estimated(hrs/sp)]] * 4 -> 8 | L6: 6 | M6: 46153 | N6: Nil | O6: Nil | P6: Nil | Q6: Nil | R6: Nil | S6: Nil | T6: Nil | U6: Nil | V6: Nil | W6: Nil | X6: Nil | Y6: Nil | Z6: Nil | AA6: Nil | AB6: Nil | AC6: Nil

Sheet MCS 26 Sprint 9-Defects
A1: S.No | B1: Sprint # | C1: Story/Defect ID | D1: Parent Story | E1: Developer | F1: Issue Type | G1: Issue Description | H1: Priority | I1: Defect Source | J1: Type | K1: Status | L1: Root Cause Category | M1: Comments

Sheet MCS 26 Sprint 8-Status
A1: S.No | B1: Application Name | C1: Sprint Start Date | D1: Sprint End Date | E1: Sprint | F1: Developer | G1: Story ID/Defect ID | H1: Description | I1: Status | J1: Estimated(hrs/sp) | K1: Actual(hrs/sp) | L1: Actual Hours (Worklog) | M1: Dev Start Date | N1: Dev End Date | O1: Unit testing | P1: Peer Tested By | Q1: Peer Tested Defects, if any | R1: Peer Reviewed By | S1: Peer Code Review Comments, if any | T1: PR Number/Link | U1: PR Created Date | V1: Reviewer 1 | W1: PR Approved Date | X1: Code Review Comments, if any | Y1: Reviewer 2 | Z1: Approved Date | AA1: Code Review Comments, if any2 | AB1: Internal PO -POV Comments | AC1: Client PO -POV Comments | AD1: Comments | AE1: Column1
A2: =ROW() - ROW(Table1459678101112314151316171920211823[[#Headers],[S.No]]) -> 1 | B2: =Dashboard!$J$1 -> MCS | C2: 46136 | D2: 46149 | E2: MCS 26 Sprint 8 | F2: Hariharan Dhandapani | G2: 52664 | H2: Add Permissions to Add/Remove Inventory Used for Production | I2: Story Completed | J2: 2 | K2: =Table145967810111231415131617192021182322242526272829303132333435363738[[#This Row],[Estimated(hrs/sp)]] * 4 -> 8 | L2: Nil | M2: Nil | N2: Nil | O2: Done | P2: Ganesh | Q2: Nil | R2: Nil | S2: Nil | T2: https://dev.azure.com/heartlandschools/MCS/_git/Edison/pullrequest/48565?tracking_data=ew0KICAic291cmNlIjogIlNsYWNrUmVwb3NBcHAiLA0KICAic291cmNlX2V2ZW50X25hbWUiOiAiZ2l0LnB1bGxyZXF1ZXN0LmNyZWF0ZWQiDQp9 | U2: 46133 | V2: Andrea | W2: 46134 | X2: Nil | Y2: Nil | Z2: Nil | AA2: Nil | AB2: Nil | AC2: Nil
A3: =ROW() - ROW(Table1459678101112314151316171920211823[[#Headers],[S.No]]) -> 2 | B3: =Dashboard!$J$1 -> MCS | C3: 46136 | D3: 46149 | E3: MCS 26 Sprint 8 Stretch | F3: Vaishnavi | G3: 51826 | H3: Safety Check in Franklin for MSA (Web) | I3: Story Ready For Testing | J3: 3 | K3: =Table145967810111231415131617192021182322242526272829303132333435363738[[#This Row],[Estimated(hrs/sp)]] * 4 -> 12 | L3: 25 | M3: 46136 | N3: 46149 | O3: Nil | P3: Nil | Q3: Nil | R3: Nil | S3: Nil | T3: https://dev.azure.com/heartlandschools/MCS/_git/Franklin/pullrequest/48851 | U3: 46147 | V3: Hari | W3: 46148 | X3: 1. Change the button order . 2. Follow the existing validation and query format. 3. No need the bool datatype(sql) for Enum type. | Y3: Andrea | Z3: 46148 | AA3: Suggested a variable name | AB3: Nil | AC3: Nil
A4: =ROW() - ROW(Table1459678101112314151316171920211823[[#Headers],[S.No]]) -> 3 | B4: =Dashboard!$J$1 -> MCS | C4: 46136 | D4: 46149 | E4: MCS 26 Sprint 8 Stretch | F4: Hariharan Dhandapani | G4: 52660 | H4: MSA Client - Add Generic SunBucks/Summer EBT Notification | I4: Story Completed | J4: 1 | K4: =Table145967810111231415131617192021182322242526272829303132333435363738[[#This Row],[Estimated(hrs/sp)]] * 4 -> 4 | L4: 5 | M4: 46136 | N4: 46140 | O4: Nil | P4: Nil | Q4: Nil | R4: Nil | S4: Nil | T4: https://dev.azure.com/heartlandschools/MCS/_git/MSAClient/pullrequest/48660 | U4: 46139 | V4: Rudy | W4: 46139 | X4: Nil | Y4: Nil | Z4: Nil | AA4: Nil | AB4: Nil | AC4: Nil
A5: =ROW() - ROW(Table1459678101112314151316171920211823[[#Headers],[S.No]]) -> 4 | B5: =Dashboard!$J$1 -> MCS | C5: 46136 | D5: 46149 | E5: MCS 26 Sprint 8 Stretch | F5: Vaishnavi | G5: 43179 | H5: Align Edison Fact Label with FDA Food Fact Label | I5: Story Being Developed | J5: 3 | K5: =Table145967810111231415131617192021182322242526272829303132333435363738[[#This Row],[Estimated(hrs/sp)]] * 4 -> 12 | L5: 17 | M5: 46136 | N5: 46149 | O5: Nil | P5: Nil | Q5: Nil | R5: Nil | S5: Nil | T5: Nil | U5: Nil | V5: Nil | W5: Nil | X5: Nil | Y5: Nil | Z5: Nil | AA5: Nil | AB5: Nil | AC5: Nil
A6: =ROW() - ROW(Table1459678101112314151316171920211823[[#Headers],[S.No]]) -> 5 | B6: =Dashboard!$J$1 -> MCS | C6: 46136 | D6: 46149 | E6: MCS 26 Sprint 8 Stretch | F6: Hariharan Dhandapani | G6: 52971 | H6: Add MenuPlanSequence Number to Dataset for Production Reports (Table, Long, Standard) | I6: Story Completed | J6: 2 | K6: =Table145967810111231415131617192021182322242526272829303132333435363738[[#This Row],[Estimated(hrs/sp)]] * 4 -> 8 | L6: 27 | M6: 46136 | N6: 46149 | O6: Nil | P6: Nil | Q6: Nil | R6: Nil | S6: Nil | T6: https://dev.azure.com/heartlandschools/MCS/_git/Edison/pullrequest/48823 | U6: 46146 | V6: Andrea | W6: 46147 | X6: To add a space before parentheses. | Y6: Nil | Z6: Nil | AA6: Nil | AB6: Nil | AC6: Nil
A7: =ROW() - ROW(Table1459678101112314151316171920211823[[#Headers],[S.No]]) -> 6 | B7: =Dashboard!$J$1 -> MCS | C7: 46136 | D7: 46149 | E7: MCS 26 Sprint 8 Stretch | F7: Hariharan Dhandapani | G7: 53117 | H7: Improve Handling of Incomplete In-Person Credit Card Transactions | I7: Story Being Developed | J7: 1 | K7: =Table145967810111231415131617192021182322242526272829303132333435363738[[#This Row],[Estimated(hrs/sp)]] * 4 -> 4 | L7: 10 | M7: 46147 | N7: 46149 | O7: Nil | P7: Nil | Q7: Nil | R7: Nil | S7: Nil | T7: Nil | U7: Nil | V7: Nil | W7: Nil | X7: Nil | Y7: Nil | Z7: Nil | AA7: Nil | AB7: Nil | AC7: Nil

Sheet MCS 26 Sprint 8-Defects
A1: S.No | B1: Sprint # | C1: Story/Defect ID | D1: Parent Story | E1: Developer | F1: Issue Type | G1: Issue Description | H1: Priority | I1: Defect Source | J1: Type | K1: Status | L1: Root Cause Category | M1: Comments

Sheet MCS 26 Sprint 7-Status
A1: S.No | B1: Application Name | C1: Sprint Start Date | D1: Sprint End Date | E1: Sprint | F1: Developer | G1: Story ID/Defect ID | H1: Description | I1: Status | J1: Estimated(hrs/sp) | K1: Actual(hrs/sp) | L1: Actual Hours (Worklog) | M1: Dev Start Date | N1: Dev End Date | O1: Unit testing | P1: Peer Tested By | Q1: Peer Tested Defects, if any | R1: Peer Reviewed By | S1: Peer Code Review Comments, if any | T1: PR Number/Link | U1: PR Created Date | V1: Reviewer 1 | W1: PR Approved Date | X1: Code Review Comments, if any | Y1: Reviewer 2 | Z1: Approved Date | AA1: Code Review Comments, if any2 | AB1: Internal PO -POV Comments | AC1: Client PO -POV Comments | AD1: Comments | AE1: Column1
A2: =ROW() - ROW(Table1459678101112314151316171920211823[[#Headers],[S.No]]) -> 1 | B2: =Dashboard!$J$1 -> MCS | C2: 46122 | D2: 46135 | E2: MCS 26 Sprint 7 | F2: Vaishnavi | G2: 50607 | H2: Add support for Hyperlinks to Email | I2: Story Completed | J2: 2 | K2: =Table1459678101112314151316171920211823222425262728293031323334353637[[#This Row],[Estimated(hrs/sp)]] * 4 -> 8 | L2: 8 | M2: 46128 | N2: 46132 | O2: Done | P2: Ganesh | Q2: Nil | R2: Nil | S2: Nil | T2: https://dev.azure.com/heartlandschools/MCS/_git/Franklin/pullrequest/47949 | U2: 46104 | V2: Hariharan Dhandapani | W2: 46105 | X2: Nil | Y2: Rudy | Z2: 46112 | AA2: Nil | AB2: Nil | AC2: Nil
A3: =ROW() - ROW(Table1459678101112314151316171920211823[[#Headers],[S.No]]) -> 2 | B3: =Dashboard!$J$1 -> MCS | C3: 46122 | D3: 46135 | E3: MCS 26 Sprint 7 | F3: Vaishnavi | G3: 52486 | H3: Edison Report Layout Override - Additional Data Field Additions Needed | I3: Story Completed | J3: 1 | K3: =Table1459678101112314151316171920211823222425262728293031323334353637[[#This Row],[Estimated(hrs/sp)]] * 4 -> 4 | L3: 6 | M3: 46126 | N3: 46126 | O3: Done | P3: Ganesh | Q3: Nil | R3: Nil | S3: Nil | T3: https://dev.azure.com/heartlandschools/MCS/_git/Edison/pullrequest/48380 | U3: 46125 | V3: Hariharan Dhandapani | W3: 46128 | X3: 1.Use the function intead of select query and avoid the unwanted code | Y3: Andrea | Z3: 46128 | AA3: Nil | AB3: Nil | AC3: Nil
A4: =ROW() - ROW(Table1459678101112314151316171920211823[[#Headers],[S.No]]) -> 3 | B4: =Dashboard!$J$1 -> MCS | C4: 46122 | D4: 46135 | E4: MCS 26 Sprint 7 | F4: Vaishnavi | G4: 52669 | H4: Expand Temperature Log Records that are Required on Recipe | I4: Story Completed | J4: 2 | K4: =Table1459678101112314151316171920211823222425262728293031323334353637[[#This Row],[Estimated(hrs/sp)]] * 4 -> 8 | L4: 12 | M4: 46125 | N4: 46132 | O4: Done | P4: Ganesh | Q4: Nil | R4: Nil | S4: Nil | T4: https://dev.azure.com/heartlandschools/MCS/_git/Edison/pullrequest/48381 | U4: 46127 | V4: Hariharan Dhandapani | W4: 46133 | X4: 1.Place it in a sorted order. 2.To follow the exsiting same functionality. 3.To avoid unwanted automatically generated UI code. | Y4: Andrea | Z4: 46134 | AA4: Nil | AB4: Nil | AC4: Nil
A5: =ROW() - ROW(Table1459678101112314151316171920211823[[#Headers],[S.No]]) -> 4 | B5: =Dashboard!$J$1 -> MCS | C5: 46122 | D5: 46135 | E5: MCS 26 Sprint 7 Stretch | F5: Hariharan Dhandapani | G5: 52664 | H5: Add Permissions to Add/Remove Inventory Used for Production | I5: Story Ready For Testing | J5: 3 | K5: =Table1459678101112314151316171920211823222425262728293031323334353637[[#This Row],[Estimated(hrs/sp)]] * 4 -> 12 | L5: 12 | M5: 46125 | N5: 46134 | O5: Done | P5: Ganesh | Q5: Nil | R5: Nil | S5: Nil | T5: https://dev.azure.com/heartlandschools/MCS/_git/Edison/pullrequest/48565?tracking_data=ew0KICAic291cmNlIjogIlNsYWNrUmVwb3NBcHAiLA0KICAic291cmNlX2V2ZW50X25hbWUiOiAiZ2l0LnB1bGxyZXF1ZXN0LmNyZWF0ZWQiDQp9 | U5: 46133 | V5: Andrea | W5: 46134 | X5: Nil | Y5: Nil | Z5: Nil | AA5: Nil | AB5: Nil | AC5: Nil
A6: =ROW() - ROW(Table1459678101112314151316171920211823[[#Headers],[S.No]]) -> 5 | B6: =Dashboard!$J$1 -> MCS | C6: 46122 | D6: 46135 | E6: MCS 26 Sprint 7 Stretch | F6: Vaishnavi | G6: 51826 | H6: Safety Check in Franklin for MSA (Web) | I6: Story Being Developed | J6: 3 | K6: =Table1459678101112314151316171920211823222425262728293031323334353637[[#This Row],[Estimated(hrs/sp)]] * 4 -> 12 | L6: 21 | M6: 46128 | N6: 46135 | O6: Nil | P6: Nil | Q6: Nil | R6: Nil | S6: Nil | T6: Nil | U6: Nil | V6: Nil | W6: Nil | X6: Nil | Y6: Nil | Z6: Nil | AA6: Nil | AB6: Nil | AC6: Nil
A7: =ROW() - ROW(Table1459678101112314151316171920211823[[#Headers],[S.No]]) -> 6 | B7: =Dashboard!$J$1 -> MCS | C7: 46122 | D7: 46135 | E7: MCS 26 Sprint 7 Stretch | F7: Hariharan Dhandapani | G7: 52660 | H7: Client - Add Generic SunBucks/Summer EBT Notification | I7: Story Being Developed | J7: 1 | K7: =Table1459678101112314151316171920211823222425262728293031323334353637[[#This Row],[Estimated(hrs/sp)]] * 4 -> 4 | L7: 10 | M7: 46133 | N7: 46134 | O7: Nil | P7: Nil | Q7: Nil | R7: Nil | S7: Nil | T7: Nil | U7: Nil | V7: Nil | W7: Nil | X7: Nil | Y7: Nil | Z7: Nil | AA7: Nil | AB7: Nil | AC7: Nil

Sheet MCS 26 Sprint 7-Defects
A1: S.No | B1: Sprint # | C1: Story/Defect ID | D1: Parent Story | E1: Developer | F1: Issue Type | G1: Issue Description | H1: Priority | I1: Defect Source | J1: Type | K1: Status | L1: Root Cause Category | M1: Comments

Sheet MCS 26 Sprint 6-Status 
A1: S.No | B1: Application Name | C1: Sprint Start Date | D1: Sprint End Date | E1: Sprint | F1: Developer | G1: Story ID/Defect ID | H1: Description | I1: Status | J1: Estimated(hrs/sp) | K1: Actual(hrs/sp) | L1: Actual Hours (Worklog) | M1: Dev Start Date | N1: Dev End Date | O1: Unit testing | P1: Peer Tested By | Q1: Peer Tested Defects, if any | R1: Peer Reviewed By | S1: Peer Code Review Comments, if any | T1: PR Number/Link | U1: PR Created Date | V1: Reviewer 1 | W1: PR Approved Date | X1: Code Review Comments, if any | Y1: Reviewer 2 | Z1: Approved Date | AA1: Code Review Comments, if any2 | AB1: Internal PO -POV Comments | AC1: Client PO -POV Comments | AD1: Comments | AE1: Column1
A2: =ROW() - ROW(Table1459678101112314151316171920211823[[#Headers],[S.No]]) -> 1 | B2: =Dashboard!$J$1 -> MCS | C2: 46108 | D2: 46121 | E2: MCS 26 Sprint 6 Stretch | F2: Vaishnavi | G2: 50607 | H2: Add support for Hyperlinks to Email | I2: Story Ready For Testing | J2: 2 | K2: =Table14596781011123141513161719202118232224252627282930313233343536[[#This Row],[Estimated(hrs/sp)]] * 4 -> 8 | L2: 2 | M2: 46111 | N2: 46111 | O2: Done | P2: Ganesh | Q2: Nil | R2: Hariharan Dhandapani | S2: Nil | T2: https://dev.azure.com/heartlandschools/MCS/_git/Franklin/pullrequest/47949 | U2: 46104 | V2: Hariharan Dhandapani | W2: 46105 | X2: Nil | Y2: Rudy | Z2: 46112 | AA2: 1.Use ParserTemplate function and include nested tokens 2.Constructor and reuse it during the lifetime of the object | AB2: Nil | AC2: Nil
A3: =ROW() - ROW(Table1459678101112314151316171920211823[[#Headers],[S.No]]) -> 2 | B3: =Dashboard!$J$1 -> MCS | C3: 46108 | D3: 46121 | E3: MCS 26 Sprint 6 | F3: Vaishnavi | G3: 52340 | H3: Add a new custom token for the Application Approval Result Status | I3: Story Completed | J3: 2 | K3: =Table14596781011123141513161719202118232224252627282930313233343536[[#This Row],[Estimated(hrs/sp)]] * 4 -> 8 | L3: Nil | M3: Nil | N3: Nil | O3: Done | P3: Ganesh | Q3: Nil | R3: Hariharan Dhandapani | S3: Nil | T3: https://dev.azure.com/heartlandschools/MCS/_git/Franklin/pullrequest/47906 | U3: 46100 | V3: Hariharan Dhandapani | W3: 46106 | X3: Nil | Y3: Andrea | Z3: 46107 | AA3: Nil | AB3: Nil | AC3: Nil
A4: =ROW() - ROW(Table1459678101112314151316171920211823[[#Headers],[S.No]]) -> 3 | B4: =Dashboard!$J$1 -> MCS | C4: 46108 | D4: 46121 | E4: MCS 26 Sprint 6 | F4: Hariharan Dhandapani | G4: 52337 | H4: SunBucks & Summer EBT Printable Notification Letter | I4: Story Completed | J4: 2 | K4: =Table14596781011123141513161719202118232224252627282930313233343536[[#This Row],[Estimated(hrs/sp)]] * 4 -> 8 | L4: 15 | M4: 46111 | N4: 46115 | O4: Done | P4: Ganesh | Q4: Nil | R4: Nil | S4: Nil | T4: https://dev.azure.com/heartlandschools/MCS/_git/MSAClient/pullrequest/48234 | U4: 46119 | V4: Andrea | W4: 46120 | X4: Uuse var instead of string | Y4: Nil | Z4: Nil | AA4: Nil | AB4: Nil | AC4: Nil
A5: =ROW() - ROW(Table1459678101112314151316171920211823[[#Headers],[S.No]]) -> 4 | B5: =Dashboard!$J$1 -> MCS | C5: 46108 | D5: 46121 | E5: MCS 26 Sprint 6 Stretch | F5: Vaishnavi | G5: 52486 | H5: Edison Report Layout Override - Additional Data Field Additions Needed | I5: Story Peer Review | J5: 2 | K5: =Table14596781011123141513161719202118232224252627282930313233343536[[#This Row],[Estimated(hrs/sp)]] * 4 -> 8 | L5: 24 | M5: 46113 | N5: 46118 | O5: Nil | P5: Nil | Q5: Nil | R5: Nil | S5: Nil | T5: Nil | U5: Nil | V5: Nil | W5: Nil | X5: Nil | Y5: Nil | Z5: Nil | AA5: Nil | AB5: Nil | AC5: Nil
A6: =ROW() - ROW(Table1459678101112314151316171920211823[[#Headers],[S.No]]) -> 5 | B6: =Dashboard!$J$1 -> MCS | C6: 46108 | D6: 46121 | E6: MCS 26 Sprint 6 Stretch | F6: Hariharan Dhandapani | G6: 52672 | H6: Update Receiving Screen to Prioritize Vendor Item Number | I6: Story Completed | J6: 1 | K6: =Table14596781011123141513161719202118232224252627282930313233343536[[#This Row],[Estimated(hrs/sp)]] * 4 -> 4 | L6: 2 | M6: 46118 | N6: 46118 | O6: Done | P6: Ganesh | Q6: Nil | R6: Nil | S6: Nil | T6: https://dev.azure.com/heartlandschools/MCS/_git/Edison/pullrequest/48247 | U6: 46118 | V6: Andrea | W6: 46119 | X6: To set the propertie name. | Y6: Nil | Z6: Nil | AA6: Nil | AB6: Nil | AC6: Nil
A7: =ROW() - ROW(Table1459678101112314151316171920211823[[#Headers],[S.No]]) -> 6 | B7: =Dashboard!$J$1 -> MCS | C7: 46108 | D7: 46121 | E7: MCS 26 Sprint 6 Stretch | F7: Vaishnavi | G7: 52669 | H7: Expand Temperature Log Records that are Required on Recipe | I7: Product Owner - Verify | J7: 2 | K7: =Table14596781011123141513161719202118232224252627282930313233343536[[#This Row],[Estimated(hrs/sp)]] * 4 -> 8 | L7: 12 | M7: 46119 | N7: 46120 | O7: Nil | P7: Nil | Q7: Nil | R7: Nil | S7: Nil | T7: Nil | U7: Nil | V7: Nil | W7: Nil | X7: Nil | Y7: Nil | Z7: Nil | AA7: Nil | AB7: Nil | AC7: Nil
A8: =ROW() - ROW(Table1459678101112314151316171920211823[[#Headers],[S.No]]) -> 7 | B8: =Dashboard!$J$1 -> MCS | C8: 46108 | D8: 46121 | E8: MCS 26 Sprint 6 Stretch | F8: Hariharan Dhandapani | G8: SRX28855 | H8: Georgia Plugin DE0118 report error after Newton 26.3 release | I8: Story Completed | J8: 1 | K8: =Table14596781011123141513161719202118232224252627282930313233343536[[#This Row],[Estimated(hrs/sp)]] * 4 -> 4 | L8: 4 | M8: 46118 | N8: 46118 | O8: Done | P8: Ganesh | Q8: Nil | R8: Nil | S8: Nil | T8: https://dev.azure.com/heartlandschools/MCS/_git/Newton/pullrequest/48249 | U8: 46118 | V8: Nil | W8: Nil | X8: Nil | Y8: Nil | Z8: Nil | AA8: Nil | AB8: Nil | AC8: Nil

Sheet MCS 26 Sprint 6-Defects
A1: S.No | B1: Sprint # | C1: Story/Defect ID | D1: Parent Story | E1: Developer | F1: Issue Type | G1: Issue Description | H1: Priority | I1: Defect Source | J1: Type | K1: Status | L1: Root Cause Category | M1: Comments
B2: MCS 26 Sprint 6 | C2: 26756 | E2: Vaishnavi | F2: Defect | G2: Benefits Explanation Letter for CEP Schools Needs to Show Status From Processed Application | H2: Minor | I2: Manual | J2: External | K2: Story Completed | L2: Existing Issue
B3: MCS 26 Sprint 6 | C3: 26994 | E3: Vaishnavi | F3: Defect | G3: Production Report Duplicating Discarded | H3: Minor | I3: Manual | J3: External | K3: Story Completed | L3: Existing Issue | M3: Suggested to enough the one new line for sql query

Sheet MCS 26 Sprint 5-Status
A1: S.No | B1: Application Name | C1: Sprint Start Date | D1: Sprint End Date | E1: Sprint | F1: Developer | G1: Story ID/Defect ID | H1: Description | I1: Status | J1: Estimated(hrs/sp) | K1: Actual(hrs/sp) | L1: Actual Hours (Worklog) | M1: Dev Start Date | N1: Dev End Date | O1: Unit testing | P1: Peer Tested By | Q1: Peer Tested Defects, if any | R1: Peer Reviewed By | S1: Peer Code Review Comments, if any | T1: PR Number/Link | U1: PR Created Date | V1: Reviewer 1 | W1: PR Approved Date | X1: Code Review Comments, if any | Y1: Reviewer 2 | Z1: Approved Date | AA1: Code Review Comments, if any2 | AB1: Internal PO -POV Comments | AC1: Client PO -POV Comments | AD1: Comments | AE1: Column1
A2: =ROW() - ROW(Table1459678101112314151316171920211823[[#Headers],[S.No]]) -> 1 | B2: =Dashboard!$J$1 -> MCS | C2: 46094 | D2: 46107 | E2: MCS 26 Sprint 5 Stretch | F2: Vaishnavi | G2: 50607 | H2: Add support for Hyperlinks to Email | I2: Story Peer Review | J2: 2 | K2: =Table145967810111231415131617192021182322242526272829303132333435[[#This Row],[Estimated(hrs/sp)]] * 4 -> 8 | L2: 2 | M2: 46100 | N2: 46100 | O2: Done | P2: Ganesh | Q2: Nil | R2: Nil | S2: Nil | T2: https://dev.azure.com/heartlandschools/MCS/_git/Franklin/pullrequest/47949 | U2: 46104 | V2: Hariharan Dhandapani | W2: 46105 | X2: 1.Remove inline comments. 2. Call the reference directly instead of importing. 3.Replace separately and Avoid Regex . | Y2: Rudy | Z2: 46105 | AA2: Create a reusable method for repeated functions. | AB2: Nil | AC2: Nil | AD2: Done With POV.
A3: =ROW() - ROW(Table1459678101112314151316171920211823[[#Headers],[S.No]]) -> 2 | B3: =Dashboard!$J$1 -> MCS | C3: 46094 | D3: 46107 | E3: MCS 26 Sprint 5 Stretch | F3: Hariharan Dhandapani | G3: 43641 | H3: Federal Edit Check - Flag when Attendance < total claim | I3: Story Completed | J3: 1 | K3: =Table145967810111231415131617192021182322242526272829303132333435[[#This Row],[Estimated(hrs/sp)]] * 4 -> 4 | L3: 14 | M3: 46100 | N3: 46100 | O3: Done | P3: Ganesh | Q3: Nil | R3: Nil | S3: Nil | T3: https://dev.azure.com/heartlandschools/MCS/_git/Newton/pullrequest/47592 | U3: 46057 | V3: Andrea | W3: 46057 | X3: Nil | Y3: Nil | Z3: Nil | AA3: Nil | AB3: Nil | AC3: Nil
A4: =ROW() - ROW(Table1459678101112314151316171920211823[[#Headers],[S.No]]) -> 3 | B4: =Dashboard!$J$1 -> MCS | C4: 46094 | D4: 46107 | E4: MCS 26 Sprint 5 Stretch | F4: Vaishnavi | G4: 52340 | H4: MCS - FR - Add a new custom token for the Application Approval Result Status | I4: Story Ready For Testing | J4: 2 | K4: =Table145967810111231415131617192021182322242526272829303132333435[[#This Row],[Estimated(hrs/sp)]] * 4 -> 8 | L4: 12 | M4: 46094 | N4: 46106 | O4: Done | P4: Ganesh | Q4: Nil | R4: Hariharan Dhandapani | S4: Avoid DB call and Include description. | T4: https://dev.azure.com/heartlandschools/MCS/_git/Franklin/pullrequest/47906 | U4: 46100 | V4: Hariharan Dhandapani | W4: 46106 | X4: Nil | Y4: 46107 | Z4: Nil | AA4: Nil | AB4: Nil | AC4: Nil
A5: =ROW() - ROW(Table1459678101112314151316171920211823[[#Headers],[S.No]]) -> 4 | B5: =Dashboard!$J$1 -> MCS | C5: 46094 | D5: 46107 | E5: MCS 26 Sprint 5 Stretch | F5: Hariharan Dhandapani | G5: 52337 | H5: SunBucks & Summer EBT Printable Notification Letter | I5: Story Being Developed | J5: 8 | K5: =Table145967810111231415131617192021182322242526272829303132333435[[#This Row],[Estimated(hrs/sp)]] * 4 -> 32 | L5: 35 | M5: 46100 | N5: 46100 | O5: Nil | P5: Nil | Q5: Nil | R5: Nil | S5: Nil | T5: Nil | U5: Nil | V5: Nil | W5: Nil | X5: Nil | Y5: Nil | Z5: Nil | AA5: Nil | AB5: Nil | AC5: Nil

Sheet MCS 26 Sprint 5-Defects
A1: S.No | B1: Sprint # | C1: Story/Defect ID | D1: Parent Story | E1: Developer | F1: Issue Type | G1: Issue Description | H1: Priority | I1: Defect Source | J1: Type | K1: Status | L1: Root Cause Category | M1: Comments
B2: MCS 26 Sprint 5 Stretch | C2: 26756 | E2: Vaishnavi | F2: Defect | G2: Benefits Explanation Letter for CEP Schools Needs to Show Status From Processed Application | H2: Minor | I2: Manual | J2: External | K2: Story Peer Review | L2: Existing Issue | M2: The analysis took longer because the changes were made about 15 years ago, and it took extra time to get the functionality working. They asked for a second round POV.
B3: MCS 26 Sprint 5 Stretch | C3: 26994 | E3: Vaishnavi | F3: Defect | G3: Production Report Duplicating Discarded | H3: Minor | I3: Manual | J3: External | K3: Defect Being Fixed | L3: Existing Issue | M3: The defect was taken mid‑sprint. The implementation was completed, and dev testing is in progress.

Sheet MCS 26 Sprint 4-Status
A1: S.No | B1: Application Name | C1: Sprint Start Date | D1: Sprint End Date | E1: Sprint | F1: Developer | G1: Story ID/Defect ID | H1: Description | I1: Status | J1: Estimated(hrs/sp) | K1: Actual(hrs/sp) | L1: Actual Hours (Worklog) | M1: Dev Start Date | N1: Dev End Date | O1: Unit testing | P1: Peer Tested By | Q1: Peer Tested Defects, if any | R1: Peer Reviewed By | S1: Peer Code Review Comments, if any | T1: PR Number/Link | U1: PR Created Date | V1: Reviewer 1 | W1: PR Approved Date | X1: Code Review Comments, if any | Y1: Reviewer 2 | Z1: Approved Date | AA1: Code Review Comments, if any2 | AB1: Internal PO -POV Comments | AC1: Client PO -POV Comments | AD1: Comments | AE1: Column1
A2: =ROW() - ROW(Table1459678101112314151316171920211823[[#Headers],[S.No]]) -> 1 | B2: =Dashboard!$J$1 -> MCS | C2: 46080 | D2: 46093 | E2: MCS 26 Sprint 4 | F2: Hariharan Dhandapani | G2: 50900 | H2: Atlanta Report Request Built off of Record of Attendance Report | I2: Story Completed | J2: 1 | K2: =Table1459678101112314151316171920211823222425262728293031323334[[#This Row],[Estimated(hrs/sp)]] * 4 -> 4 | L2: Nil | M2: Nil | N2: Nil | O2: Done | P2: Vaishnavi | Q2: Nil | R2: Nil | S2: Nil | T2: https://dev.azure.com/heartlandschools/MCS/_git/Newton/pullrequest/47309 | U2: 46072 | V2: Nil | W2: 46072 | X2: Nil | Y2: Nil | Z2: Nil | AA2: Nil | AB2: Nil | AC2: Nil
A3: =ROW() - ROW(Table1459678101112314151316171920211823[[#Headers],[S.No]]) -> 2 | B3: =Dashboard!$J$1 -> MCS | C3: 46080 | D3: 46093 | E3: MCS 26 Sprint 4 | F3: Hariharan Dhandapani | G3: 49673 | H3: Buy American Tracking Report | I3: Story Completed | J3: 3 | K3: =Table1459678101112314151316171920211823222425262728293031323334[[#This Row],[Estimated(hrs/sp)]] * 4 -> 12 | L3: 4 | M3: Nil | N3: Nil | O3: Nil | P3: Nil | Q3: Nil | R3: Nil | S3: Nil | T3: https://dev.azure.com/heartlandschools/MCS/_git/Edison/pullrequest/47308 | U3: 46071 | V3: Andrea | W3: 46071 | X3: Nil | Y3: Nil | Z3: Nil | AA3: Nil | AB3: Nil | AC3: Nil | AD3: Current sprint focuses only on testing.
A4: =ROW() - ROW(Table1459678101112314151316171920211823[[#Headers],[S.No]]) -> 3 | B4: =Dashboard!$J$1 -> MCS | C4: 46080 | D4: 46093 | E4: MCS 26 Sprint 4 Stretch | F4: Vaishnavi | G4: 50607 | H4: Add support for Hyperlinks to Email | I4: Story Peer Review | J4: 2 | K4: =Table1459678101112314151316171920211823222425262728293031323334[[#This Row],[Estimated(hrs/sp)]] * 4 -> 8 | L4: 30 | M4: 46080 | N4: 46056 | O4: Done | P4: Ganesh | Q4: Nil | R4: Nil | S4: Nil | T4: Nil | U4: Nil | V4: Nil | W4: Nil | X4: Nil | Y4: Nil | Z4: Nil | AA4: Nil | AB4: Nil | AC4: Nil | AD4: Done With POV, Created PR
A5: =ROW() - ROW(Table1459678101112314151316171920211823[[#Headers],[S.No]]) -> 4 | B5: =Dashboard!$J$1 -> MCS | C5: 46080 | D5: 46093 | E5: MCS 26 Sprint 4 Stretch | F5: Hariharan Dhandapani | G5: 43641 | H5: Federal Edit Check - Flag when Attendance < total claim | I5: Story Being Tested | J5: 2 | K5: =Table1459678101112314151316171920211823222425262728293031323334[[#This Row],[Estimated(hrs/sp)]] * 4 -> 8 | L5: 14 | M5: 46080 | N5: 46057 | O5: Done | P5: Nil | Q5: Nil | R5: Nil | S5: Nil | T5: https://dev.azure.com/heartlandschools/MCS/_git/Newton/pullrequest/47592 | U5: 46057 | V5: Andrea | W5: 46057 | X5: Nil | Y5: Nil | Z5: Nil | AA5: Nil | AB5: Nil | AC5: Nil

Sheet MCS 26 Sprint 4-Defects
A1: S.No | B1: Sprint # | C1: Story/Defect ID | D1: Parent Story | E1: Developer | F1: Issue Type | G1: Issue Description | H1: Priority | I1: Defect Source | J1: Type | K1: Status | L1: Root Cause Category | M1: Comments
B2: MCS 26 Sprint 4 Stretch | C2: 26756 | E2: Vaishnavi | F2: Defect | G2: Benefits Explanation Letter for CEP Schools Needs to Show Status From Processed Application | H2: Minor | I2: Manual | J2: External | K2: Product Owner - Verify | L2: Existing Issue | M2: The development work has been completed, and we are now waiting for the Product Owner to verify and provide feedback before moving forward
B3: MCS 26 Sprint 4 Stretch | C3: 26820 | E3: Hariharan Dhandapani | F3: Defect | G3: Log File is Almost 200 gig | H3: Minor | I3: Manual | J3: External | K3: Defect Fixed | L3: Existing Issue

Sheet MCS 26 Sprint 3-Status
A1: S.No | B1: Application Name | C1: Sprint Start Date | D1: Sprint End Date | E1: Sprint | F1: Developer | G1: Story ID/Defect ID | H1: Description | I1: Status | J1: Estimated(hrs/sp) | K1: Actual(hrs/sp) | L1: Actual Hours (Worklog) | M1: Dev Start Date | N1: Dev End Date | O1: Unit testing | P1: Peer Tested By | Q1: Peer Tested Defects, if any | R1: Peer Reviewed By | S1: Peer Code Review Comments, if any | T1: PR Number/Link | U1: PR Created Date | V1: Reviewer 1 | W1: PR Approved Date | X1: Code Review Comments, if any | Y1: Reviewer 2 | Z1: Approved Date | AA1: Code Review Comments, if any2 | AB1: Internal PO -POV Comments | AC1: Client PO -POV Comments | AD1: Comments | AE1: Column1
A2: =ROW() - ROW(Table1459678101112314151316171920211823[[#Headers],[S.No]]) -> 1 | B2: =Dashboard!$J$1 -> MCS | C2: 46066 | D2: 46079 | E2: MCS 26 Sprint 3 | F2: Vaishnavi | G2: 51943 | H2: Fix sorting in Allergen Reports | I2: Story Completed | J2: 1 | K2: =Table14596781011123141513161719202118232224252627282930313233[[#This Row],[Estimated(hrs/sp)]] * 4 -> 4 | L2: 10 | M2: 46066 | N2: 46072 | O2: Done | P2: Ganesh | Q2: Nil | R2: Nil | S2: Follow the correct boolean format | T2: https://dev.azure.com/heartlandschools/MCS/_git/Edison/pullrequest/47359 | U2: 46072 | V2: Hariharan Dhandapani | W2: 46073 | X2: Nil | Y2: Andrea | Z2: 46073 | AA2: Nil | AB2: Nil | AC2: Nil
A3: =ROW() - ROW(Table1459678101112314151316171920211823[[#Headers],[S.No]]) -> 2 | B3: =Dashboard!$J$1 -> MCS | C3: 46066 | D3: 46079 | E3: MCS 26 Sprint 3 Stretch | F3: Hariharan Dhandapani | G3: 50900 | H3: Atlanta Report Request Built off of Record of Attendance Report | I3: Story Ready For Testing | J3: 2 | K3: =Table14596781011123141513161719202118232224252627282930313233[[#This Row],[Estimated(hrs/sp)]] * 4 -> 8 | L3: 6 | M3: 46066 | N3: 46072 | O3: Done | P3: Vaishnavi | Q3: Nil | R3: Nil | S3: Nil | T3: https://dev.azure.com/heartlandschools/MCS/_git/Newton/pullrequest/47309 | U3: 46072 | V3: Nil | W3: 46072 | X3: Nil | Y3: Nil | Z3: Nil | AA3: Nil | AB3: Nil | AC3: Nil
A4: =ROW() - ROW(Table1459678101112314151316171920211823[[#Headers],[S.No]]) -> 3 | B4: =Dashboard!$J$1 -> MCS | C4: 46066 | D4: 46079 | E4: MCS 26 Sprint 3 | F4: Vaishnavi | G4: 51542 | H4: Apply USDA Feedback to Meal Planning Reports | I4: Story Completed | J4: 1 | K4: =Table145967810111231415131617192021182322242526272829303132[[#This Row],[Estimated(hrs/sp)]] * 4 -> 8 | L4: Nil | M4: Nil | N4: Nil | O4: Done | P4: Ganesh | Q4: Nil | R4: Nil | S4: 1.Handle the repeated code in a common way. 2. Avoid Margins and use same verson for report UI. 3. Use common functions for repeated condition. | T4: https://dev.azure.com/heartlandschools/MCS/_git/Edison/pullrequest/46873 | U4: 46049 | V4: Hariharan Dhandapani | W4: 46051 | X4: Suggested variable name | Y4: Andrea | Z4: 46058 | AA4: Nil | AB4: Nil | AC4: Nil
A5: =ROW() - ROW(Table1459678101112314151316171920211823[[#Headers],[S.No]]) -> 4 | B5: =Dashboard!$J$1 -> MCS | C5: 46066 | D5: 46079 | E5: MCS 26 Sprint 3 | F5: Hariharan Dhandapani | G5: 49673 | H5: Buy American Tracking Report | I5: Story Being Tested | J5: 3 | K5: =Table14596781011123141513161719202118232224252627282930313233[[#This Row],[Estimated(hrs/sp)]] * 4 -> 12 | L5: Nil | M5: Nil | N5: Nil | O5: Done | P5: Done | Q5: Nil | R5: Nil | S5: Nil | T5: https://dev.azure.com/heartlandschools/MCS/_git/Edison/pullrequest/47308 | U5: 46071 | V5: Andrea | W5: 46071 | X5: Nil | Y5: Nil | Z5: Nil | AA5: Nil | AB5: Nil | AC5: Nil | AD5: Current sprint focuses only on testing. The Testing Team has not yet begun actual test execution. they have only started preparing test cases and have been engaged on another story.
A6: =ROW() - ROW(Table1459678101112314151316171920211823[[#Headers],[S.No]]) -> 5 | B6: =Dashboard!$J$1 -> MCS | C6: 46066 | D6: 46079 | E6: MCS 26 Sprint 3 Stretch | F6: Vaishnavi | G6: 50607 | H6: Add support for Hyperlinks to Email | I6: Story Being Developed | J6: 5 | K6: =Table14596781011123141513161719202118232224252627282930313233[[#This Row],[Estimated(hrs/sp)]] * 4 -> 20 | L6: 42 | M6: 46069 | N6: Nil | O6: Nil | P6: Nil | Q6: Nil | R6: Nil | S6: Nil | T6: Nil | U6: Nil | V6: Nil | W6: Nil | X6: Nil | Y6: Nil | Z6: Nil | AA6: Nil | AB6: Nil | AC6: Nil
