Workbook

Sheet Dashboard
A1: Current Sprint | B1: {=INDEX($B$2:$B$101,MATCH(1,(($D$2:$D$101 >=TODAY())*($C$2:$C$101<=TODAY())),0))} -> 2.5 KaleidaNutrition S24 | C1: Current Sprint Sheet | D1: =CONCATENATE(B1,"-Status") -> 2.5 KaleidaNutrition S24-Status | E1: Sprint Start Date | F1: =VLOOKUP($B$1,$B$1:$C$101,2) -> 46157 | G1: Sprint End Date | H1: =VLOOKUP($B$1,$B$1:$D$101,3) -> 46170 | I1: Application Name | J1: Meal Order | K1: Users | L1: charu.sharma@relevantz.com;kiruthiga.ganapathi@relevantz.com;sudheer.dokku@relevantz.com;rubansanthosh.stephen@relevantz.com;karthikeyan.elumalai@relevantz.com;vidhya.subramaniam@relevantz.com;ganesh.veerannan@relevantz.com;shikha.p@relevantz.com;nathiya.palanisamy@relevantz.com | M1: Teams Name(GP -Meal Orders) | N1: 19:33c225e109bb48d58dd1e9a89b0261a7@thread.v2
A2: Sprint Type | B2: Sprint # | C2: Sprint Start Date | D2: Sprint End Date | E2: Assigned | F2: Completed | G2: Story points introduced/removed | H2: Sprint Summary | I2: Accomplishments | J2: Remarks | K2: Retro Points (Internal & External) | L2: Unplanned Leaves | M2: Data sanity Audit Status | N2: AuditDate | O2: Backlog Health
A3: =IF(AND($D$1>=C3,$D$1<=D3),"CurrentSprint","NA") -> NA | B3: 1.8 Sprint 3 | C3: 45303 | D3: 45316 | E3: 27 | F3: 29 | G3: 0 | J3: Regression Sprint - Release 1/2/2024 In addition completed one stretch story (2 sp). | K3: Internal: External:
A4: =IF(AND($D$1>=C4,$D$1<=D4),"CurrentSprint","NA") -> NA | B4: 1.9 Sprint 1 | C4: 45317 | D4: 45330 | E4: 25 | F4: 33 | G4: 0 | J4: New Version 1.9 - One Story from Stretch and Two defects from the Stretch was completed One Story was carry-forward due to additional AC after completing the story | K4: Internal: External:
A5: =IF(AND($D$1>=C5,$D$1<=D5),"CurrentSprint","NA") -> NA | B5: 1.9 Sprint 2 | C5: 45331 | D5: 45344 | E5: 22 | F5: 30 | G5: 0 | J5: Ruban will be unavailable for the next three weeks, Compensating the 8sp with a 9sp from stretch (since the 8sp couldn't be completed as it involves more effort). Refer to story number 40282 for more info | K5: Internal: External:
A6: =IF(AND($D$1>=C6,$D$1<=D6),"CurrentSprint","NA") -> NA | B6: 1.9 Sprint 3 | C6: 45345 | D6: 45358 | E6: 19 | F6: 19 | G6: 0 | J6: Ruban will be unavailable for the first half of the Sprint. Addition to this, development completed for 2 stretch stories and testing is in progress. | K6: Internal: External:
A7: =IF(AND($D$1>=C7,$D$1<=D7),"CurrentSprint","NA") -> NA | B7: 1.9 Sprint 4 | C7: 45359 | D7: 45372 | E7: 37 | F7: =40+13 -> 53 | G7: 0 | J7: Regression Sprint -- Release Targeted on March 20, 21 (Cert, Prod) | K7: Internal: External:
A8: =IF(AND($D$1>=C8,$D$1<=D8),"CurrentSprint","NA") -> NA | B8: 2.0 Sprint 1 | C8: 45373 | D8: 45386 | E8: 11 | F8: 29 | G8: 18SP | J8: New Version - Commit has Two Project Unite Discovery Stories for Clients (13+13) Relevantz has 4 Defects and 1 Story in the Commit | K8: Internal: External:
A9: =IF(AND($D$1>=C9,$D$1<=D9),"CurrentSprint","NA") -> NA | B9: 2.0 Sprint 2 | C9: 45387 | D9: 45400 | E9: 15 | F9: 36 | G9: 21SP | J9: Relevantz has 2 Stories and 1 Defects in the Commit. Relevantz completed 2 Commit Stories, 1 Commit Defect and 4 Stretch Stories | K9: Internal: External:
A10: =IF(AND($D$1>=C10,$D$1<=D10),"CurrentSprint","NA") -> NA | B10: 2.0 Sprint 3 | C10: 45401 | D10: 45414 | E10: 13 | F10: 18 | G10: 10SP | J10: Due to scope change one main commit story spilled over.ST #44162 | K10: Internal: External:
A11: =IF(AND($D$1>=C11,$D$1<=D11),"CurrentSprint","NA") -> NA | B11: 2.0 Sprint 4 | C11: 45415 | D11: 45428 | E11: 10 | F11: 22 | G11: 12SP | J11: Completed more than committed Completed - 2 Commit Stories and 4 Stretch Stories and 3 Stories are Code Completed and in PR | K11: Internal: External:
A12: =IF(AND($D$1>=C12,$D$1<=D12),"CurrentSprint","NA") -> NA | B12: 2.0 Sprint 5 | C12: 45429 | D12: 45442 | E12: 12 | F12: 16 | G12: 4SP | J12: We had additional requirements, requests and enhancements from the Client after the POV (New AC) Completed Dev in a short period targeting release and release goal Found one Critical issue in the Prod and gave fix on the same day and had release on the next day | K12: Internal: External:
A13: =IF(AND($D$1>=C13,$D$1<=D13),"CurrentSprint","NA") -> NA | B13: 2.0 Sprint 6 | C13: 45443 | D13: 45456 | E13: 13 | F13: 17 | G13: Introduced - 18SP Removed - 9SP | J13: Release Goal have been changed. So new requirement has been captured and the team is currently working on that. Reason - A New Schedule Printer is needed. On going Progress Hot-fix for Order Price Mismatch | K13: Internal: External:
A14: =IF(AND($D$1>=C14,$D$1<=D14),"CurrentSprint","NA") -> NA | B14: 2.0 Sprint 7 | C14: 45457 | D14: 45470 | E14: 34 | F14: 18 | J14: The Stories commited are new requirment which is different from the release goal. Completed two reports fully. The Third report is in progress (UI Completed) | K14: Internal: External:
A15: =IF(AND($D$1>=C15,$D$1<=D15),"CurrentSprint","NA") -> NA | B15: 2.0 Sprint 8 | C15: 45471 | D15: 45484 | E15: 39 | F15: 26 | J15: Regression Sprint Order Receipts was carry forwarded (Dev Completed) | K15: Internal: External:
A16: =IF(AND($D$1>=C16,$D$1<=D16),"CurrentSprint","NA") -> NA | B16: 2.1 | K16: Internal: External:
A17: =IF(AND($D$1>=C17,$D$1<=D17),"CurrentSprint","NA") -> NA | B17: 2.1 Sprint 1 | C17: 45485 | D17: 45498 | E17: 25 | F17: 30 | G17: 5 | J17: The Release was in mid sprint, the team started to work on Prod Defects and Stock Management by Sarath. Ruban and Kiruthiga are working on finding solution for Cloud Print (Automatic Receipt Scheduler) | K17: Internal: External:
A18: =IF(AND($D$1>=C18,$D$1<=D18),"CurrentSprint","NA") -> NA | B18: 2.1 Sprint 2 | C18: 45499 | D18: 45512 | E18: 13 | F18: 24 | G18: 11 | J18: Receipt Scheduler will be on hold until we find a feasible approach. Will be moving to 2.2 Release. | K18: Internal: External:
A19: =IF(AND($D$1>=C19,$D$1<=D19),"CurrentSprint","NA") -> NA | B19: 2.1 Sprint 3 | C19: 45513 | D19: 45526 | E19: 14 | F19: 20 | G19: 6 | J19: Targeting Stock Management, NSLP and Defect Clean up
A20: =IF(AND($D$1>=C20,$D$1<=D20),"CurrentSprint","NA") -> NA | B20: 2.1 Sprint 4 | C20: 45527 | D20: 45540 | E20: 33 | F20: 20 | G20: Removed - 13 | J20: The Stories are carry forwarded for Admin Integration with Individual and Teacher Ordering
A21: =IF(AND($D$1>=C21,$D$1<=D21),"CurrentSprint","NA") -> NA | B21: 2.1 Sprint 5 | C21: 45541 | D21: 45554 | E21: 38 | F21: 17 | G21: Removed - 21 | J21: Regression Sprint There was a scope creep for Stock Management, rather than regression was on-going. We found few issues that the team is fixing related to Site and Site groups. | K21: Internal: External: Team Collaboration
A22: =IF(AND($D$1>=C22,$D$1<=D22),"CurrentSprint","NA") -> NA | B22: 2.1 Sprint 6 | C22: 45555 | D22: 45568 | E22: 29 | F22: 50 | G22: Introduced - 21 | J22: Regression Sprint Ruban and Sudheer were involved in Regression Testing Ruban was involved in Escalation Internal CRC - 0, External CRC - 0, QA Defects - 11, Escaped Defects - 0 | K22: Internal: External:
A23: =IF(AND($D$1>=C23,$D$1<=D23),"CurrentSprint","NA") -> NA | B23: 2.2
A24: =IF(AND($D$1>=C24,$D$1<=D24),"CurrentSprint","NA") -> NA | B24: 2.2 Sprint 0 | C24: 45569 | D24: 45582 | E24: 15 | F24: 20 | G24: Introduced - 5 | I24: Performance Optimization in Cart for Individual and Teacher Ordering | J24: Internal CRC - 0 External CRC - 0 QA Defects - 4 Escaped Defects - 0
A25: =IF(AND($D$1>=C25,$D$1<=D25),"CurrentSprint","NA") -> NA | B25: 2.2 Sprint 1 | C25: 45583 | D25: 45596 | E25: 20 | F25: 17 | G25: Carry Forwarded - 3 | I25: Adding First Name, Last Name and Copy Email to the Order Details | J25: Due to Build Issues and ChromeDriver Issue one Regression Automation Story was carry forwarded Internal CRC - 0 External CRC - 0 QA Defects - 2 Escaped Defects - 0
A26: =IF(AND($D$1>=C26,$D$1<=D26),"CurrentSprint","NA") -> NA | B26: 2.2 Sprint 2 | C26: 45597 | D26: 45610 | E26: 23 | F26: 23 | I26: Stock Management UI Changes for Admin and Soft Refresh of Stock Items in End User | J26: Internal CRC - 0 External CRC - 0 QA Defects - 3 Escaped Defects - 0
A27: =IF(AND($D$1>=C27,$D$1<=D27),"CurrentSprint","NA") -> NA | B27: 2.2 Sprint 3 | C27: 45611 | D27: 45638 | E27: 41 | F27: 53 | I27: Stock Management Complete Changes, Stock Report, Regression Automation | J27: 4 - Weeks Sprint Internal CRC - 0 External CRC - 0 QA Defects - 5 Escaped Defects - 0
A28: =IF(AND($D$1>=C28,$D$1<=D28),"CurrentSprint","NA") -> NA | B28: 2.2 Sprint 4 | C28: 45639 | D28: 45666 | E28: 36 | F28: 51 | I28: Stock Management Complete Changes, Stock Report | J28: 4 Weeks Sprint. Two stories were Carry Forwarded - Development is completed, Testing is in Progress. End - End Testing is required for this EPIC Feature Internal CRC - 0 External CRC - 0 QA Defects - 4 Escaped Defects - 0
A29: =IF(AND($D$1>=C29,$D$1<=D29),"CurrentSprint","NA") -> NA | B29: 2.2 Sprint 5 | C29: 45667 | D29: 45680 | E29: 42 | F29: 43 | I29: Regression Sprint - Stock Management Complete Changes, Stock Report | J29: Will be carry forwarded to continue other reports. We have 13 reports with run reports and schedule reports with report inbox. Sentral had a new PR for CSV Format, so we will re running the tests We have completed Order Management, Menu Item, Menu Template, Menu Calendar, Settings Module. We have Stock Management Module inprogress for regression. Internal CRC - 0 External CRC - 0 QA Defects - 4 Escaped Defects - 9 | K29: External - Rachel appreciated Preethi, Ruban for their extensive support in the absence of Tino
A30: =IF(AND($D$1>=C30,$D$1<=D30),"CurrentSprint","NA") -> NA | B30: 2.2 Sprint 6 | C30: 45681 | D30: 45694 | E30: 20 | F30: 27 | I30: Regression Sprint - Stock Management Complete Changes, Stock Report and Analysis on Bulk Order Cancellation/Open, Menu Template Report and Student Fullfillment Enhancement | J30: Internal CRC - 0 External CRC - 0 QA Defects - 3 Escaped Defects - 1 | K30: External - Received appreciation mail from Tino, Director/PM for our commitment, coordination and attitude. Ruban has been assigned as an PR approver to merge PR
B31: 2.3
A32: =IF(AND($D$1>=C32,$D$1<=D32),"CurrentSprint","NA") -> NA | B32: 2.3 Sprint 1 | C32: 45695 | D32: 45708 | E32: 7 | F32: 25.75 | I32: Analysis on Bulk Order Cancellation/Open, Menu Template Report and Student Fullfillment Enhancement | J32: Internal CRC - 0 External CRC - 0 QA Defects - 1 Escaped Defects - 1 | K32: External - Received appreciation on the overall team work & Ruban has been appreciated for the support provided to Rachel.
A33: =IF(AND($D$1>=C33,$D$1<=D33),"CurrentSprint","NA") -> NA | B33: 2.3 Sprint 2 | C33: 45709 | D33: 45722 | E33: 18 | F33: 27 | I33: Bulk order open/cancellation, Menu Template Report & Student fulfillment enhancement, Report Headers | J33: Internal CRC - 0 External CRC - 0 QA Defects - 6 Escaped Defects - 0 | K33: External: Rachel, Tino and other Clients appreciated Ruban for his commitment towards Sentral and Heartland
A34: =IF(AND($D$1>=C34,$D$1<=D34),"CurrentSprint","NA") -> NA | B34: 2.3 Sprint 3 | C34: 45723 | D34: 45736 | E34: 21 | F34: 34 | I34: Enhancement to Report Headers,Customer Count Report, Student Fulfillmen report & Stock Management code refactoring | J34: Internal CRC - 0 External CRC - 0 Bouncebacks-2 QA Defects - 2 Escaped Defects - 1 | K34: Team was appreciated for the overall work & co-ordination.
A35: =IF(AND($D$1>=C35,$D$1<=D35),"CurrentSprint","NA") -> NA | B35: 2.3 Sprint 4 | C35: 45737 | D35: 45750 | E35: 35 | F35: 35 | I35: Regression - Stock Management, Report Enhancements, Order management changes, Complete Teacher, Parent & Admin. Student Product Sales Report changes | J35: Internal CRC - 0 External CRC - 0 Bouncebacks- 0 QA Defects - 9 Escaped Defects - 0 | K35: Entire team was commended for their work & efforts during the regression.
B36: 2.4
A37: =IF(AND($D$1>=C37,$D$1<=D37),"CurrentSprint","NA") -> NA | B37: 2.4 Sprint 0 | C37: 45751 | D37: 45764 | E37: 23 | F37: 32 | I37: Tech Debt work [Added API settings to the tenant cache, Job added for item type update, Unsplash update to use thumbnail URL] & Multiple defect fixes | J37: Internal CRC - 0 External CRC - 0 Bouncebacks- 0 QA Defects - 7 Escaped Defects - 0
A38: =IF(AND($D$1>=C38,$D$1<=D38),"CurrentSprint","NA") -> NA | B38: 2.4 Sprint 1 | C38: 45765 | D38: 45778 | E38: 29 | F38: 29 | I38: User information display on order cancellation, Menu items export, Regression automation fixes & defect fixes | J38: Internal CRC - 0 External CRC - 0 Bouncebacks- 0 QA Defects - 1 Escaped Defects - 1 | K38: Good team effort in completing the stories .
A39: =IF(AND($D$1>=C39,$D$1<=D39),"CurrentSprint","NA") -> NA | B39: 2.4 Sprint 2 | C39: 45779 | D39: 45792 | E39: 16 | F39: 10 | G39: Carry forwarded - 6 | I39: Import config settings, Nutritional unit update, sample script for item type [automation], Timeboxed Discovery for Localization Language Translation | J39: Internal CRC - 0 External CRC - 0 Bouncebacks- 0 QA Defects - 1 Escaped Defects - 0 | K39: Owen appreciated Sudheer for his work regarding the newly automated framework.
A40: =IF(AND($D$1>=C40,$D$1<=D40),"CurrentSprint","NA") -> NA | B40: 2.4 Sprint 3 | C40: 45793 | D40: 45806 | E40: 24 | F40: 24 | G40: Carry forwarded - 2 | I40: Regression | J40: Internal CRC - 0 External CRC - 0 Bouncebacks- 0 QA Defects - 2 Escaped Defects - 0 | K40: 1. Ken appreciated Sudheer for his efforts in Regression testing. 2. Hunter appreciated Charu in helping him align the requirements & documentation. 3. Ruban was appreciated by the client team for his prompt and effective handling of the escalation.
...

Sheet Unplanned Leaves
A1: Total Leaves | B1: =SUM(B21:D21) -> 0
B2: Resource Name
A3: Sprint | B3: Rupan Santhosh | C3: Kiruthiga Ganapathi | D3: Sudheer Dokku | E3: Charu Sharma | F3: Nathiya | G3: Kathikeyan Elumalai | H3: Ganesh Veerannan | I3: Shikha Pradhan | J3: Vidhaya Subramaniam | K3: Total | L3: Remarks
A4: Sprint 17 (6-Feb-2026 to 19-Feb-2026) | B4: 0 | C4: 0 | D4: 0 | E4: 1 | F4: 0 | G4: 1 | H4: 0 | I4: 0 | J4: 1 | K4: 3
A5: Sprint 18 (20-Feb-2026 to 5-Mar-2026) | B5: 0 | C5: 0 | D5: 0 | E5: 0 | F5: 0 | G5: 0 | H5: 0 | I5: 0 | J5: 0 | K5: 0
A6: Sprint 19 (6Mar-2026 to 19-Mar-2026) | B6: 0 | C6: 0 | D6: 0 | E6: 0 | F6: 0 | G6: 4 | H6: 0 | I6: 0 | J6: 0 | K6: 4
A7: Sprint 20 (20Mar-2026 to 2-Apr-2026) | B7: 0 | C7: 0 | D7: 0 | E7: 0 | F7: 0 | G7: 0 | H7: 0 | I7: 0 | J7: 0 | K7: 0
A8: Sprint 21 (3-Apr-2026 to 16-Apr-2026) | B8: 0 | C8: 0 | D8: 1 | E8: 1 | F8: 0 | G8: 0 | H8: 0 | I8: 0 | J8: 0 | K8: 2
A9: Sprint 22 (17-Apr-2026 to 30-Apr-2026) | B9: 0 | C9: 0 | D9: 1 | E9: 3 | F9: 0 | G9: 0 | H9: 0 | I9: 0 | J9: 0 | K9: 4
A10: Sprint 23 (1-May-2026 to 14-May-2026) | B10: 0 | C10: 0 | D10: 0 | E10: 0 | F10: 0 | G10: 1 | H10: 0 | J10: 0 | K10: 1

Sheet 2.5 KaleidaNutrition S24-Status
A1: S.No | B1: Application Name | C1: Sprint Start Date | D1: Sprint End Date | E1: Sprint | F1: Developer | G1: Story ID/Defect ID | H1: Description | I1: Status | J1: Estimated(sp) | K1: Actual(sp) | L1: Actual Hours Worklog | M1: Dev Start Date | N1: Dev End Date | O1: Unit testing | P1: Peer Tested By | Q1: Peer Tested Defects, if any | R1: Peer Reviewed By | S1: Peer Code Review Comments, if any | T1: PR Number/Link | U1: PR Created Date | V1: PR Approved Date | W1: Reviewer 1 | X1: Code Review Comments, if any | Y1: Reviewer 2 | Z1: Approved Date | AA1: Code Review Comments, if any2 | AB1: Internal PO -POV Comments | AC1: Client PO -POV Comments | AD1: Comments | AE1: Does this story meets expectations
A2: 1 | B2: Meal Order | C2: 46157 | D2: 46170 | E2: 2.5 KaleidaNutrition S24 Stretch | F2: Sudheer | G2: 53109 | H2: Meal Orders - Automation - Settings - Meal Pricing Template | I2: Story Being Developed | J2: 8 | M2: 46154
A3: 2 | B3: Meal Order | C3: 46157 | D3: 46170 | E3: 2.5 KaleidaNutrition S24 | F3: Kiruthiga | G3: 53298 | H3: [WAVE] Mosaic FOH - Update to login behavior | I3: Story Being Developed | J3: 8 | M3: 46157
A4: 3 | B4: Meal Order | C4: 46157 | D4: 46170 | E4: 2.5 KaleidaNutrition S24 | F4: Nathiya | G4: 53023 | H4: [WAVE] Mosaic BOH Kaleida - Interior Pages Update - Reports - Ingredients List/print | I4: Story Being Developed | J4: 8 | M4: 46154

Sheet 2.5 KaleidaNutrition S23-Status
A1: S.No | B1: Application Name | C1: Sprint Start Date | D1: Sprint End Date | E1: Sprint | F1: Developer | G1: Story ID/Defect ID | H1: Description | I1: Status | J1: Estimated(sp) | K1: Actual(sp) | L1: Actual Hours Worklog | M1: Dev Start Date | N1: Dev End Date | O1: Unit testing | P1: Peer Tested By | Q1: Peer Tested Defects, if any | R1: Peer Reviewed By | S1: Peer Code Review Comments, if any | T1: PR Number/Link | U1: PR Created Date | V1: PR Approved Date | W1: Reviewer 1 | X1: Code Review Comments, if any | Y1: Reviewer 2 | Z1: Approved Date | AA1: Code Review Comments, if any2 | AB1: Internal PO -POV Comments | AC1: Client PO -POV Comments | AD1: Comments | AE1: Does this story meets expectations
A2: 1 | B2: Meal Order | C2: 46143 | D2: 46156 | E2: 2.5 KaleidaNutrition S23 Stretch | F2: Sudheer | G2: 52478 | H2: Meal Orders - Automation - Settings - Taxes Test Cases | I2: Story Completed | J2: 11 | K2: 11 | L2: 44 | M2: 46150 | N2: 46153 | O2: Completed | P2: Sudheer | Q2: None | R2: None | S2: None | T2: https://dev.azure.com/heartlandschools/Meal%20Orders/_git/MealOrdersAutomation/pullrequest/48688 | U2: 46153 | V2: 46153 | W2: Owen | X2: None | Y2: Owen | Z2: 46153 | AA2: None | AB2: None | AC2: None | AE2: Meets Expectations
A3: 2 | B3: Meal Order | C3: 46143 | D3: 46156 | E3: 2.5 KaleidaNutrition S23 | F3: Kiruthiga | G3: 52987 | H3: [WAVE] Mosaic Boh Kaleida - Interior Pages Updates - Recipes Component List | I3: Story Completed | J3: 8 | K3: 7 | L3: 26 | M3: 46146 | N3: 46150 | O3: Completed | P3: Nathiya | Q3: None | R3: Nathiya | S3: None | T3: https://dev.azure.com/heartlandschools/Mosaic/_git/BOH/pullrequest/48933 | U3: 46150 | V3: 46153 | W3: Ruban | X3: None | Y3: Charles | Z3: 46153 | AA3: None | AB3: None | AC3: None | AE3: Meets Expectations
A4: 3 | B4: Meal Order | C4: 46143 | D4: 46156 | E4: 2.5 KaleidaNutrition S23 | F4: Nathiya | G4: 52981 | H4: [WAVE] MOsaic BOH Kaleida - Interior Pages Update - Reports - Recipes - Recipe Allergen list | I4: Story Completed | J4: 8 | K4: 8 | L4: 36 | M4: 46146 | N4: 46153 | O4: Completed | P4: Sudheer | Q4: None | R4: Kiruthiga | S4: None | T4: https://dev.azure.com/heartlandschools/Mosaic/_git/BOH/pullrequest/48968 | U4: 46153 | V4: 46153 | W4: Ruban | X4: None | Y4: Charles | Z4: 46153 | AA4: None | AB4: None | AC4: None | AE4: Meets Expectations
A5: 4 | B5: Meal Order | C5: 46143 | D5: 46156 | E5: 2.5 KaleidaNutrition S23 | F5: Ruban | G5: 53059 | H5: Kaleida Mosaic BOH - Allergen Search Screen(Move Status Toggle to Edit Screen) | I5: Story Completed | J5: 2 | K5: 2 | L5: 12 | M5: 46135 | N5: 46142 | O5: Completed | P5: Ken | Q5: None | R5: Kiruthiga | S5: None | T5: https://dev.azure.com/heartlandschools/Mosaic/_git/BOH/pullrequest/48758 | U5: 46142 | V5: 46142 | W5: Charles | X5: None | Y5: Charles | Z5: 46142 | AA5: None | AB5: None | AC5: None | AE5: Meets Expectations
A6: 5 | B6: Meal Order | C6: 46143 | D6: 46156 | E6: 2.5 KaleidaNutrition S23 Stretch | F6: Sudheer | G6: 53109 | H6: Meal Orders - Automation - Settings - Meal Pricing Template | I6: Story Being Developed | J6: 8 | M6: 46154
A7: 6 | B7: Meal Order | C7: 46143 | D7: 46156 | E7: 2.5 KaleidaNutrition S23 | F7: Kiruthiga | G7: 27109 | H7: [WAVE] Mosaic FOH (LogIn Screen) - Label must be correctly associated with a form control | I7: Defect Fixed | J7: 1 | K7: 1 | L7: 4 | M7: 46155 | N7: 46155 | O7: Completed | P7: Nathiya | Q7: None | R7: Nathiya | S7: None | T7: https://dev.azure.com/heartlandschools/Mosaic/_git/FOH/pullrequest/49025 | U7: 46155 | V7: 46155 | W7: Ruban | X7: None | Y7: Charles | Z7: 46155 | AA7: None | AB7: None | AC7: None | AE7: Meets Expectations

Sheet 2.5Kaleida Nutrition S23-Defect
A1: Sprint # | B1: Story/Defect ID | C1: Parent Story | D1: Developer | E1: Issue Type | F1: Issue Description | G1: Priority | H1: Defect Source | I1: Type | J1: Found By | K1: Status | L1: Root Cause Category | M1: RCA Comment *
A2: 2.5 KaleidaNutrition S23 | B2: 52987 | D2: Kiruthiga | E2: Minor | F2: Numeric Range Start and End fields unable to be edited after inputting 6 characters | G2: low | H2: Gap in unit testing | I2: External | J2: Onsite QA | K2: Completed | L2: New Issue | M2: It an edge case not a blocker or harmful one. Missed it to notice in unit testing

Sheet 2.5 KaleidaNutrition S22-Status
A1: S.No | B1: Application Name | C1: Sprint Start Date | D1: Sprint End Date | E1: Sprint | F1: Developer | G1: Story ID/Defect ID | H1: Description | I1: Status | J1: Estimated(sp) | K1: Actual(sp) | L1: Actual Hours Worklog | M1: Dev Start Date | N1: Dev End Date | O1: Unit testing | P1: Peer Tested By | Q1: Peer Tested Defects, if any | R1: Peer Reviewed By | S1: Peer Code Review Comments, if any | T1: PR Number/Link | U1: PR Created Date | V1: PR Approved Date | W1: Reviewer 1 | X1: Code Review Comments, if any | Y1: Reviewer 2 | Z1: Approved Date | AA1: Code Review Comments, if any2 | AB1: Internal PO -POV Comments | AC1: Client PO -POV Comments | AD1: Comments | AE1: Does this story meets expectations
A2: 1 | B2: Meal Order | C2: 46129 | D2: 46142 | E2: 2.5 KaleidaNutrition S22 | F2: Kiruthiga | G2: 52843 | H2: [WAVE] Mosaic BOH - Interior pages update - Setup - Sites Search | I2: Story Completed | J2: 8 | K2: 8 | L2: 32 | M2: 46129 | N2: 46140 | O2: Completed | P2: Nathiya | Q2: None | R2: None | S2: None | T2: https://dev.azure.com/heartlandschools/Mosaic/_git/BOH/pullrequest/48694 | U2: 46140 | V2: 46140 | W2: Ruban | Y2: Charles | Z2: 46140 | AA2: None | AB2: None | AD2: 28th Apr : Client POV is completed. But there is a finding on unit testing, Once it is fixed branch will be shared for testing around 3PM (28th Apr) | AE2: Meets Expectations
A3: 2 | B3: Meal Order | C3: 46129 | D3: 46142 | E3: 2.5 KaleidaNutrition S22 Stretch | F3: Nathiya | G3: 52621 | H3: [WAVE] Mosaic BOH Kaleida - Interior Pages Update - Setup - Users add/edit | I3: Story Completed | J3: 13 | K3: 13 | L3: 52 | M3: 46127 | N3: 46141 | O3: Completed | P3: Sudheer | Q3: None | R3: Kiruthiga | S3: None | T3: https://dev.azure.com/heartlandschools/Mosaic/_git/BOH/pullrequest/48730 | U3: 46141 | V3: 46141 | W3: Ruban | X3: None | Y3: Richard | Z3: 46141 | AA3: None | AB3: None | AC3: Suggestion to remove the Edit icon in User Maintenance page and show the Actions column only when delete action applicable. | AD3: 04/28 : Client POV completed. 04/29 : Shared branch for peer testing. | AE3: Meets Expectations
A4: 3 | B4: Meal Order | C4: 46129 | D4: 46142 | E4: 2.5 KaleidaNutrition S22 Stretch | F4: sudheer | G4: 52478 | H4: Meal Orders - Automation - Settings - Taxes Test Cases | I4: Story Being Developed | J4: 8 | K4: 8 | L4: 40 | M4: 46129 | N4: 46140 | O4: Completed | P4: Sudheer | Q4: None | R4: None | S4: None | T4: https://dev.azure.com/heartlandschools/Meal%20Orders/_git/MealOrdersAutomation/pullrequest/48688 | U4: 46140 | W4: Owen | Y4: Owen | AD4: That is a Pendo guide that was added by the Pendo team. We didn't add it ourselves but yes, it is expected to be there. We need to update the scripts
A5: 4 | B5: Meal Order | C5: 46129 | D5: 46142 | E5: 2.5 KaleidaNutrition S22 Stretch | F5: Ruban | G5: 52610 | H5: [WAVE] Mosaic BOH Kaleida - Interior Pages Update - Setup- Import/Export execute | I5: Story Completed | J5: 8 | K5: 8 | L5: 40 | M5: 46129 | N5: 46140 | O5: Completed | P5: Vidhya | Q5: None | R5: None | S5: None | T5: https://dev.azure.com/heartlandschools/Mosaic/_git/BOH/pullrequest/48674 | U5: 46139 | V5: 46140 | W5: Charles | Y5: Charles | Z5: 46140 | AA5: None | AB5: None | AE5: Meets Expectations
A6: 5 | B6: Meal Order | C6: 46129 | D6: 46142 | E6: 2.5 KaleidaNutrition S22 | F6: Kiruthiga | G6: 27107 | H6: WAVE] Mosaic FOH - Image must have alternative text | I6: Defect Fixed | J6: 2 | K6: 1 | L6: 4 | M6: 46141 | N6: 46141 | O6: Completed | P6: Shikha | Q6: None | R6: Shikha | S6: None | T6: https://dev.azure.com/heartlandschools/Mosaic/_git/FOH/pullrequest/48724 | U6: 46141 | V6: 46141 | W6: Ruban | Y6: Charles | Z6: 46141 | AA6: None | AB6: None

Sheet 2.5Kaleida Nutrition S22-Defect
A1: Sprint # | B1: Story/Defect ID | C1: Parent Story | D1: Developer | E1: Issue Type | F1: Issue Description | G1: Priority | H1: Defect Source | I1: Type | J1: Found By | K1: Status | L1: Root Cause Category | M1: RCA Comment *
A2: 2.5 KaleidaNutrition S22 Stretch | B2: 52621 | D2: Nathiya | F2: Linking to a POS Menu Product not always successful in QA. Console error received | G2: Medium | H2: Manual | I2: External | J2: Ken | K2: Completed | L2: New Issue | M2: The issue reported in 52419. The root cause of this issue - In changes for 52621 - User Add/Edit, there was an bunding issue due to which we get the console errors. We fixed and closed the issue.

Sheet 2.5 KaleidaNutrition S21-Status
A1: S.No | B1: Application Name | C1: Sprint Start Date | D1: Sprint End Date | E1: Sprint | F1: Developer | G1: Story ID/Defect ID | H1: Description | I1: Status | J1: Estimated(sp) | K1: Actual(sp) | L1: Actual Hours Worklog | M1: Dev Start Date | N1: Dev End Date | O1: Unit testing | P1: Peer Tested By | Q1: Peer Tested Defects, if any | R1: Peer Reviewed By | S1: Peer Code Review Comments, if any | T1: PR Number/Link | U1: PR Created Date | V1: PR Approved Date | W1: Reviewer 1 | X1: Code Review Comments, if any | Y1: Reviewer 2 | Z1: Approved Date | AA1: Code Review Comments, if any2 | AB1: Internal PO -POV Comments | AC1: Client PO -POV Comments | AD1: Comments | AE1: Does this story meets expectations
A2: 1 | B2: Meal Order | C2: 46115 | D2: 46128 | E2: 2.5 KaleidaNutrition S21 | F2: Kiruthiga | G2: 52850 | H2: [WAVE] Mosaic BOH Kaleida - Interior Pages Update - Setup - System Settings | I2: Story Completed | J2: 8 | K2: 8 | L2: 32 | M2: 46115 | N2: 46126 | O2: Done | P2: Sudheer | Q2: None | R2: Ruban | S2: None | T2: https://dev.azure.com/heartlandschools/Mosaic/_git/BOH/pullrequest/48407 | U2: 46126 | V2: 46126 | W2: Ruban | X2: None | Y2: Richard | Z2: 46126 | AA2: None | AB2: None | AC2: Suggested to remove search feture from the drop down | AE2: Meets Expectations
A3: 2 | B3: Meal Order | C3: 46115 | D3: 46128 | E3: 2.5 KaleidaNutrition S21 | F3: Nathiya | G3: 52222 | H3: [WAVE] Mosaic BOH Kaleida - Interior Pages Update - Setup - Mealviewer Display Groups | I3: Story Completed | J3: 5 | K3: 5 | L3: 42 | M3: 46106 | N3: 46121 | O3: Done | P3: Vidhya | Q3: None | R3: Kiruthiga | S3: None | T3: https://dev.azure.com/heartlandschools/Mosaic/_git/BOH/pullrequest/48383 | U3: 46125 | V3: 46125 | W3: Ruban | X3: None | Y3: Charles | Z3: 46125 | AA3: None | AB3: None | AC3: Deactivate and Activate button should be grouped along with the other buttons. | AE3: Meets Expectations
A4: 3 | B4: Meal Order | C4: 46115 | D4: 46128 | E4: 2.5 KaleidaNutrition S21 | F4: Ruban | G4: 52568 | H4: [WAVE] Mosaic FOH - Updating the Apply Filters with a Search button on Vega updated screens | I4: Story Completed | J4: 3 | K4: 3 | L4: 12 | M4: 46115 | N4: 46122 | O4: Done | P4: Vidhya | Q4: None | R4: Kiruthiga | S4: None | T4: https://dev.azure.com/heartlandschools/Mosaic/_git/FOH/pullrequest/48362 | U4: 46123 | V4: 46123 | W4: Charles | X4: None | Y4: Charles | Z4: 46123 | AA4: None | AB4: None | AC4: None
A5: 4 | B5: Meal Order | C5: 46115 | D5: 46128 | E5: 2.5 KaleidaNutrition S21 Stretch | F5: sudheer | G5: 52478 | H5: Meal Orders - Automation - Settings - Taxes Test Cases | I5: Story Being Developed | J5: 8 | L5: 8 | M5: 46115
A6: 5 | B6: Meal Order | C6: 46115 | D6: 46128 | E6: 2.5 KaleidaNutrition S21 Stretch | F6: Ruban | G6: 52610 | H6: [WAVE] Mosaic BOH Kaleida - Interior Pages Update - Setup- Import/Export execute | I6: Story Being Developed | J6: 8 | M6: 46115
A7: 6 | B7: Meal Order | C7: 46115 | D7: 46128 | E7: 2.5 KaleidaNutrition S21 Stretch | F7: Nathiya | G7: 27191 | H7: [WAVE] Mosaic BOH - Blank option missing in some dropdowns | I7: Defect Fixed | J7: 2 | K7: 1 | L7: 6 | M7: 46126 | N7: 46126 | O7: Done | P7: Sudheer | Q7: None | R7: Kiruthiga | S7: None | T7: https://dev.azure.com/heartlandschools/Mosaic/_git/BOH/pullrequest/48432 | U7: 46127 | V7: 46127 | W7: Ruban | X7: None | Y7: Richard | Z7: 46127 | AA7: None | AB7: None | AC7: None | AE7: Meets Expectations
A8: 7 | B8: Meal Order | C8: 46115 | D8: 46128 | E8: 2.5 KaleidaNutrition S21 Stretch | F8: Kiruthiga | G8: 27205 | H8: [WAVE] Mosaic BOH Kaleida - Update the date picker implementation | I8: Defect Fixed | J8: 2 | K8: 2 | L8: 8 | M8: 46127 | N8: 46127 | O8: Done | P8: Sudheer | Q8: None | R8: Kiruthiga | S8: None | T8: https://dev.azure.com/heartlandschools/Mosaic/_git/BOH/pullrequest/48431 | U8: 46127 | V8: 46127 | W8: Ruban | X8: None | Y8: Richard | Z8: 46127 | AA8: None | AB8: None | AC8: None
A9: 8 | B9: Meal Order | C9: 46115 | D9: 46128 | E9: 2.5 KaleidaNutrition S21 Stretch | F9: Nathiya | G9: 52621 | H9: [WAVE] Mosaic BOH Kaleida - Interior Pages Update - Setup - Users add/edit | I9: Story Being Developed | J9: 13 | M9: 46127

Sheet 2.5 KaleidaNutrition S20-Status
A1: S.No | B1: Application Name | C1: Sprint Start Date | D1: Sprint End Date | E1: Sprint | F1: Developer | G1: Story ID/Defect ID | H1: Description | I1: Status | J1: Estimated(sp) | K1: Actual(sp) | L1: Actual Hours Worklog | M1: Dev Start Date | N1: Dev End Date | O1: Unit testing | P1: Peer Tested By | Q1: Peer Tested Defects, if any | R1: Peer Reviewed By | S1: Peer Code Review Comments, if any | T1: PR Number/Link | U1: PR Created Date | V1: PR Approved Date | W1: Reviewer 1 | X1: Code Review Comments, if any | Y1: Reviewer 2 | Z1: Approved Date | AA1: Code Review Comments, if any2 | AB1: Internal PO -POV Comments | AC1: Client PO -POV Comments | AD1: Comments | AE1: Does this story meets expectations
A2: 1 | B2: Meal Order | C2: 46101 | D2: 46114 | E2: 2.5 KaleidaNutrition S20 | F2: Kiruthiga | G2: 52041 | H2: [WAVE] Mosaic BOH Kaleida - Interior Pages Update - Reports - Price Lists Report | I2: Story Completed | J2: 5 | K2: 4 | L2: 15 | M2: 46087 | N2: 46108 | O2: Done | P2: Sudheer | Q2: None | R2: Ruban | T2: https://dev.azure.com/heartlandschools/Mosaic/_git/BOH/pullrequest/48101 | U2: 46111 | V2: 46111 | W2: Ruban | X2: None | Y2: Richard | Z2: 46111 | AA2: None | AB2: None | AC2: None | AE2: Meets Expectations
A3: 2 | B3: Meal Order | C3: 46101 | D3: 46114 | E3: 2.5 KaleidaNutrition S20 | F3: Nathiya | G3: 52042 | H3: [WAVE] Mosaic BOH Kaleida - Interior Pages Update - Reports - Product Notes Report | I3: Story Completed | J3: 5 | K3: 4 | L3: 16 | M3: 46087 | N3: 46105 | O3: Done | P3: Sudheer | Q3: None | R3: Kiruthiga | S3: Move Navigation logic to common file | T3: https://dev.azure.com/heartlandschools/Mosaic/_git/BOH/pullrequest/48030 | U3: 46106 | V3: 46107 | W3: Charles | X3: None | Y3: Charles | Z3: 46107 | AA3: None | AB3: None | AC3: None | AE3: Meets Expectations
A4: 3 | B4: Meal Order | C4: 46101 | D4: 46114 | E4: 2.5 KaleidaNutrition S20 | F4: Ruban | G4: 52553 | H4: [WAVE] Mosaic BOH - Kaleida - Interior Pages Update - Import/Export Search | I4: Story Completed | J4: 3 | K4: 3 | L4: 12 | M4: 46104 | N4: 46113 | O4: Done | P4: Vidhya | Q4: None | R4: Kiruthiga | T4: https://dev.azure.com/heartlandschools/Mosaic/_git/BOH/pullrequest/48072 | U4: 46113 | V4: 46113 | W4: Charles | X4: None | Y4: Charles | Z4: 46113 | AA4: None | AB4: None | AC4: None | AE4: Meets Expectations
A5: 4 | B5: Meal Order | C5: 46101 | D5: 46114 | E5: 2.5 KaleidaNutrition S20 | F5: Ruban | G5: 52198 | H5: [WAVE] Mosaic BOH Kaleida - Interior Pages Update - Setup- Import/Export | I5: Story Completed | J5: 5 | K5: 5 | L5: 45 | M5: 46093 | N5: 46108 | O5: Done | P5: Vidhya | Q5: None | R5: Kiruthiga | T5: https://dev.azure.com/heartlandschools/Mosaic/_git/BOH/pullrequest/48116 | U5: 46108 | V5: 46109 | W5: Charles | X5: None | Y5: Charles | Z5: 46109 | AA5: None | AB5: None | AC5: None | AE5: Meets Expectations
A6: 5 | B6: Meal Order | C6: 46101 | D6: 46114 | E6: 2.5 KaleidaNutrition S20 Stretch | F6: Nathiya | G6: 52222 | H6: [WAVE] Mosaic BOH Kaleida - Interior Pages Update - Setup - Mealviewer Display Groups | I6: Story Being Developed | J6: 8 | M6: 46106
A7: 6 | B7: Meal Order | C7: 46101 | D7: 46114 | E7: 2.5 KaleidaNutrition S20 Stretch | F7: Ruban | G7: 52427 | H7: [WAVE] Mosaic BOH - Updating the Apply Filters with a Search button on Vega updated screens | I7: Story Completed | J7: 3 | K7: 3 | L7: 12 | M7: 46104 | N7: 46105 | O7: Done | P7: Vidhya | Q7: None | R7: Kiruthiga | T7: https://dev.azure.com/heartlandschools/Mosaic/_git/BOH/pullrequest/47977?_a=files | U7: 46105 | V7: 46105 | W7: Charles | X7: None | Y7: Charles | Z7: 46105 | AA7: None | AB7: None | AC7: None | AE7: Meets Expectations

Sheet 2.5Kaleida Nutrition S21-Defect
A1: Sprint # | B1: Story/Defect ID | C1: Parent Story | D1: Developer | E1: Issue Type | F1: Issue Description | G1: Priority | H1: Defect Source | I1: Type | J1: Found By | K1: Status | L1: Root Cause Category | M1: RCA Comment *
A2: 2.5 KaleidaNutrition S21 | B2: 52850 | D2: Kiruthiga | F2: .Breadcrumb (“Setup > System Settings”) sits slightly left of the page title container, while the title is padded inside a white card. | G2: Medium | H2: Manual | I2: Internal | J2: Sudheer | K2: Completed | L2: New Issue | M2: The misalignment occurred because both the page content container and the Vega tab were using white backgrounds. This created an unnecessary extra background layer that did not align properly with the breadcrumb. To resolve this, we applied CSS changes to ensure proper alignment.

Sheet 2.5Kaleida Nutrition S20-Defect
A1: Sprint # | B1: Story/Defect ID | C1: Parent Story | D1: Developer | E1: Issue Type | F1: Issue Description | G1: Priority | H1: Defect Source | I1: Type | J1: Found By | K1: Status | L1: Root Cause Category | M1: RCA Comment *
A2: 2.5 KaleidaNutrition S20 | B2: 52553 | D2: Ruban | E2: Bounceback | F2: After deleting the grid data, I received a success message. Subsequently, when I opened another data set, an additional success message was displayed. | G2: Medium | H2: Manual | I2: External | J2: Vidhya | K2: Not Fixed | M2: Based on my earlier observations, I did not see this behavior before. Previously, after deleting the grid data, I would only receive the single expected success message, and opening another data set did not trigger an additional success notification. The extra success message is something I noticed only recently.

Sheet 2.5 KaleidaNutrition S19-Status
A1: S.No | B1: Application Name | C1: Sprint Start Date | D1: Sprint End Date | E1: Sprint | F1: Developer | G1: Story ID/Defect ID | H1: Description | I1: Status | J1: Estimated(sp) | K1: Actual(sp) | L1: Actual Hours Worklog | M1: Dev Start Date | N1: Dev End Date | O1: Unit testing | P1: Peer Tested By | Q1: Peer Tested Defects, if any | R1: Peer Reviewed By | S1: Peer Code Review Comments, if any | T1: PR Number/Link | U1: PR Created Date | V1: PR Approved Date | W1: Reviewer 1 | X1: Code Review Comments, if any | Y1: Reviewer 2 | Z1: Approved Date | AA1: Code Review Comments, if any2 | AB1: Internal PO -POV Comments | AC1: Client PO -POV Comments | AD1: Comments | AE1: Does this story meets expectations
A2: 1 | B2: Meal Order | C2: 46087 | D2: 46100 | E2: 2.5 KaleidaNutrition S19 Stretch | F2: Kiruthiga | G2: 52041 | H2: [WAVE] Mosaic BOH Kaleida - Interior Pages Update - Reports - Price Lists Report | I2: Story Being Tested | J2: 8 | M2: 46087
A3: 2 | B3: Meal Order | C3: 46087 | D3: 46100 | E3: 2.5 KaleidaNutrition S19 Stretch | F3: Nathiya | G3: 52042 | H3: [WAVE] Mosaic BOH Kaleida - Interior Pages Update - Reports - Product Notes Report | I3: Story Being Developed | J3: 13 | M3: 46087
A4: 3 | B4: Meal Order | C4: 46087 | D4: 46100 | E4: 2.5 KaleidaNutrition S19 Stretch | F4: Sudheer | G4: 51890 | H4: Meal Orders - Automation - Settings - Item Type Test Cases | I4: Story Completed | J4: 11 | K4: 11 | L4: 44 | M4: 46087 | N4: 46094 | O4: Sudheer | P4: Sudheer | T4: https://dev.azure.com/heartlandschools/Meal%20Orders/_git/MealOrdersAutomation/pullrequest/47595 | U4: 46093 | V4: 46094 | W4: owen | Y4: owen | Z4: 46094 | AE4: Meets Expectations
A5: 4 | B5: Meal Order | C5: 46087 | D5: 46100 | E5: 2.5 KaleidaNutrition S19 | F5: Sudheer | G5: 52197 | H5: Meal Orders - Regression - Admin Mode | I5: Story Completed | J5: 8 | K5: 8 | L5: 36 | M5: 46090 | N5: 46097 | P5: None | U5: None | V5: None | W5: None | Y5: None | Z5: None | AD5: Regression story | AE5: Meets Expectations
A6: 5 | B6: Meal Order | C6: 46087 | D6: 46100 | E6: 2.5 KaleidaNutrition S19 | F6: Sudheer | G6: 52223 | H6: Meal Orders(26.3) - Regression - Reports | I6: Story Completed | J6: 2 | K6: 2 | L6: 12 | M6: 46097 | N6: 46100 | P6: None | U6: None | V6: None | W6: None | Y6: None | Z6: None | AD6: Regression story | AE6: Meets Expectations
A7: 6 | B7: Meal Order | C7: 46087 | D7: 46100 | E7: 2.5 KaleidaNutrition S19 | F7: Ruban | G7: 52143 | H7: [WAVE] Mosaic BOH Kaleida - Interior Pages - HACCP - Categories | I7: Story Completed | J7: 5 | K7: 6 | L7: 24 | M7: 46097 | N7: 46100 | O7: Completed | P7: Vidhya | T7: https://dev.azure.com/heartlandschools/Mosaic/_git/BOH/pullrequest/47828 | U7: 46097 | V7: 46097 | W7: Ruban | Y7: Richard | Z7: 46097 | AE7: Meets Expectations

Sheet 2.5Kaleida Nutrition S18-Defect
A1: Sprint # | B1: Story/Defect ID | C1: Parent Story | D1: Developer | E1: Issue Type | F1: Issue Description | G1: Priority | H1: Defect Source | I1: Type | J1: Found By | K1: Status | L1: Root Cause Category | M1: RCA Comment *
A2: 2.5 KaleidaNutrition S18 | B2: 52007 | D2: Kiruthiga | E2: Bounceback | F2: The Ingredients module is displaying an incorrect page name. The main Maintenance section name has unexpectedly changed to “Search,” resulting in inconsistent menu labeling compared to previous versions and other related modules. | G2: Medium | H2: Manual | I2: External | J2: Sudheer | K2: Defect Fixed | L2: New Issue | M2: When navigating through the application, the labels displayed in the Ingredients and Products menu tiles do not match the expected configuration. In the Slack screenshot, the UI shows two cards labeled “Ingredients” and “Products,” each containing buttons such as Maintenance, Ingredient Search, and Bulk Fulfillment. However, the conversation indicates that the name of the main Maintenance section has unexpectedly changed to “Search.” This behavior suggests that the page title is being replaced incorrectly, resulting in inconsistent UI naming across the module.
A3: 2.5 KaleidaNutrition S18 | B3: 51818 | D3: Nathiya | E3: Bounceback | F3: Allergen dropdown flickering & Table Container Overlapping Header and Double Scroll Appearing Across All BOH Screens | G3: Medium | H3: Manual | I3: Internal | J3: Vidhya | K3: Defect Fixed | L3: New Issue | M3: A UI issue is observed in all BOH (Back of House) screens where a double scroll bar appears. When this double scroll is present, the table container shifts upward and overlaps or hides the page header. This behavior disrupts the layout structure and impacts readability and navigation across all implemented BOH screens.

Sheet 2.5 KaleidaNutrition S18-Status
A1: S.No | B1: Application Name | C1: Sprint Start Date | D1: Sprint End Date | E1: Sprint | F1: Developer | G1: Story ID/Defect ID | H1: Description | I1: Status | J1: Estimated(sp) | K1: Actual(sp) | L1: Actual Hours Worklog | M1: Dev Start Date | N1: Dev End Date | O1: Unit testing | P1: Peer Tested By | Q1: Peer Tested Defects, if any | R1: Peer Reviewed By | S1: Peer Code Review Comments, if any | T1: PR Number/Link | U1: PR Created Date | V1: PR Approved Date | W1: Reviewer 1 | X1: Code Review Comments, if any | Y1: Reviewer 2 | Z1: Approved Date | AA1: Code Review Comments, if any2 | AB1: Internal PO -POV Comments | AC1: Client PO -POV Comments | AD1: Comments | AE1: Does this story meets expectations
A2: 1 | B2: Meal Order | C2: 46073 | D2: 46086 | E2: 2.5 KaleidaNutrition S18 | F2: Kiruthiga | G2: 52007 | H2: [WAVE] - Mosaic BOH Kaleida - Left Navigation - Update Root Menus - Ingredients, Menus, Recipes, Products, Inventory, Ordering | I2: Story Completed | J2: 8 | K2: 8 | L2: 40 | M2: 46073 | N2: 46083 | O2: Completed | P2: Sudheer | Q2: None | T2: https://dev.azure.com/heartlandschools/Mosaic/_git/BOH/pullrequest/47555?_a=files | U2: 46083 | V2: 46084 | W2: Ruban | X2: None | Y2: Richard | Z2: 46084 | AA2: None | AB2: None | AE2: Meets Expectations
A3: 2 | B3: Meal Order | C3: 46073 | D3: 46086 | E3: 2.5 KaleidaNutrition S18 | F3: Kiruthiga | G3: 26813 | H3: BOH - App switcher - App tray underline issues | I3: Defect Fixed | J3: 1 | K3: 1 | L3: 2 | M3: 46073 | N3: 46073 | O3: Completed | P3: Vidhya | Q3: None | T3: https://dev.azure.com/heartlandschools/Mosaic/_git/BOH/pullrequest/47367 | U3: 46073 | V3: 46073 | W3: Ruban | X3: None | Y3: Richard | Z3: 46073 | AA3: None | AB3: None | AE3: Meets Expectations
A4: 3 | B4: Meal Order | C4: 46073 | D4: 46086 | E4: 2.5 KaleidaNutrition S18 | F4: Kiruthiga | G4: 26813 | H4: FOH - App switcher - App tray underline issues | I4: Defect Fixed | J4: 1 | K4: 1 | L4: 2 | M4: 46073 | N4: 46073 | O4: Completed | P4: Vidhya | Q4: None | T4: https://dev.azure.com/heartlandschools/Mosaic/_git/FOH/pullrequest/47362 | U4: 46073 | V4: 46073 | W4: Ruban | X4: None | Y4: Richard | Z4: 46073 | AA4: None | AB4: None | AE4: Meets Expectations
A5: 4 | B5: Meal Order | C5: 46073 | D5: 46086 | E5: 2.5 KaleidaNutrition S18 | F5: Nathiya | G5: 51818 | H5: [WAVE] - Mosaic BOH Kaleida - Interior Pages Update - Reports - Ingredients Allergens List | I5: Story Completed | J5: 5 | K5: 13 | L5: 60 | M5: 46073 | N5: 46084 | O5: Completed | P5: Vidhya | Q5: None | R5: Kiruthiga | S5: Code optimization to have a common function to set/get element values. | T5: https://dev.azure.com/heartlandschools/Mosaic/_git/BOH/pullrequest/47586 | U5: 46084 | V5: 46084 | W5: Ruban | X5: None | Y5: Richard | Z5: 46084 | AA5: None | AB5: None | AC5: Use Vega Combo box instead of Vega Input Select | AD5: We included additional functionalities - Retain filters on page refresh which required additional efforts | AE5: Meets Expectations
A6: 5 | B6: Meal Order | C6: 46073 | D6: 46086 | E6: 2.5 KaleidaNutrition S18 Stretch | F6: Sudheer | G6: 51890 | H6: Meal Orders - Automation - Settings - Item Type Test Cases | I6: Story Being Developed | J6: 8 | K6: 8 | L6: 40 | M6: 46076 | N6: 46085 | O6: Completed | P6: Sudheer | T6: https://dev.azure.com/heartlandschools/Meal%20Orders/_git/MealOrdersAutomation/pullrequest/47595 | U6: 46085 | W6: Owen | Y6: Owen | AD6: Few validations are missing , after creating the test data

Sheet 2.5 KaleidaNutrition S17-Status
A1: S.No | B1: Application Name | C1: Sprint Start Date | D1: Sprint End Date | E1: Sprint | F1: Developer | G1: Story ID/Defect ID | H1: Description | I1: Status | J1: Estimated(sp) | K1: Actual(sp) | L1: Actual Hours Worklog | M1: Dev Start Date | N1: Dev End Date | O1: Unit testing | P1: Peer Tested By | Q1: Peer Tested Defects, if any | R1: Peer Reviewed By | S1: Peer Code Review Comments, if any | T1: PR Number/Link | U1: PR Created Date | V1: PR Approved Date | W1: Reviewer 1 | X1: Code Review Comments, if any | Y1: Reviewer 2 | Z1: Approved Date | AA1: Code Review Comments, if any2 | AB1: Internal PO -POV Comments | AC1: Client PO -POV Comments | AD1: Comments | AE1: Does this story meets expectations
A2: 1 | B2: Meal Order | C2: 46059 | D2: 46072 | E2: 2.5 KaleidaNutrition S17 | F2: Ruban | G2: 26741 | H2: Mosaic FOH- App switcher issues with item availability | I2: Defect Fixed | J2: 2 | K2: 2 | L2: 5 | M2: 46058 | N2: 46059 | O2: Completed | P2: Kiruthiga | R2: Kiruthiga | T2: https://dev.azure.com/heartlandschools/Mosaic/_git/FOH/pullrequest/47117?_a=files | U2: 46059 | V2: 46059 | W2: Ruban | Y2: Steven | Z2: 46059
A3: 2 | B3: Meal Order | C3: 46059 | D3: 46072 | E3: 2.5 KaleidaNutrition S17 | F3: Kiruthiga | G3: 26742 | H3: Mosaic BOH- App switcher issues with item availability | I3: Defect Fixed | J3: 2 | K3: 2 | L3: 5 | M3: 46058 | N3: 46059 | O3: Completed | P3: Ruban | R3: Ruban | T3: https://dev.azure.com/heartlandschools/Mosaic/_git/BOH/pullrequest/47124?_a=files | U3: 46059 | V3: 46059 | W3: Ruban | Y3: Richard | Z3: 46059
A4: 3 | B4: Meal Order | C4: 46059 | D4: 46072 | E4: 2.5 KaleidaNutrition S17 | F4: Dhivyalakshmi | G4: 51380 | H4: [WAVE] - BOH Kaleida - Interior Pages Update - Setup - Inventory Adjustment Reasons | I4: Story Completed | J4: 3 | K4: 6 | L4: 24 | M4: 46050 | N4: 46064 | O4: Completed | P4: Vidya | R4: Kiruthiga | T4: https://dev.azure.com/heartlandschools/Mosaic/_git/BOH/pullrequest/47204 | U4: 46064 | V4: 46064 | W4: Ruban | Y4: Richard | Z4: 46064
A5: 4 | B5: Meal Order | C5: 46059 | D5: 46072 | E5: 2.5 KaleidaNutrition S17 | F5: Kiruthiga | G5: 50603 | H5: [WAVE] - Meal Orders - Add Search Functionality to the District selector | I5: Story Completed | J5: 5 | K5: 5 | L5: 20 | M5: 46062 | N5: 46065 | O5: Completed | P5: Sudheer | R5: Ruban | T5: https://dev.azure.com/heartlandschools/Meal%20Orders/_git/Meal%20Orders/pullrequest/47226 | U5: 46065 | V5: 46066 | W5: Ruban | Y5: Ruban | Z5: 46066
A6: 5 | B6: Meal Order | C6: 46059 | D6: 46072 | E6: 2.5 KaleidaNutrition S17 Stretch | F6: Sudheer | G6: 51890 | H6: Meal Orders - Automation - Settings - Item Type Test Cases | I6: Story Being Developed | J6: 8 | M6: 46065
A7: 6 | B7: Meal Order | C7: 46059 | D7: 46072 | E7: 2.5 KaleidaNutrition S17 Stretch | F7: Sudheer | G7: 51384 | H7: Meal Orders - Automation - Settings - Serving Periods And data related issue fixes | I7: Story Completed | J7: 13 | K7: 13 | L7: 60 | M7: 46045 | N7: 46062 | O7: Completed | P7: Sudheer | R7: Owen | T7: https://dev.azure.com/heartlandschools/Meal%20Orders/_git/MealOrdersAutomation/pullrequest/46761 | U7: 46062 | V7: 46063 | W7: Owen | Y7: Owen | Z7: 46063
A8: 7 | B8: Meal Order | C8: 46059 | D8: 46072 | E8: 2.5 KaleidaNutrition S17 Stretch | F8: Kiruthiga | G8: 51917 | H8: Meal Orders - App switcher - listing apptray item based on logged in user | I8: Story Peer Review | J8: 3 | K8: 3 | L8: 12 | M8: 46065 | N8: 46072 | O8: Completed | P8: Sudheer | T8: https://dev.azure.com/heartlandschools/Meal%20Orders/_git/Meal%20Orders/pullrequest/47358 | U8: 46072
A9: 8 | B9: Meal Order | C9: 46059 | D9: 46072 | E9: 2.5 KaleidaNutrition S17 Stretch | F9: Ruban | G9: 51731 | H9: [WAVE] - Mosaic BOH Kaleida - Interior Pages Update - Vendors Search | I9: Story Completed | J9: 8 | K9: 8 | L9: 36 | M9: 46059 | N9: 46066 | O9: Completed | P9: ken/Sudheer | R9: Kiruthiga | T9: https://dev.azure.com/heartlandschools/Meal%20Orders/_git/Meal%20Orders/pullrequest/47226 | U9: 46066 | V9: 46069 | W9: Ruban | Y9: Steven | Z9: 46069

Sheet 2.5Kaleida Nutrition S17-Defect
A1: Sprint # | B1: Story/Defect ID | C1: Parent Story | D1: Developer | E1: Issue Type | F1: Issue Description | G1: Priority | H1: Defect Source | I1: Type | J1: Found By | K1: Status | L1: Root Cause Category | M1: RCA Comment *
A2: 2.5 KaleidaNutrition S17 | B2: 51380 | D2: Dhivyalakshmi / Nathiya | E2: Bounceback | F2: 1.Page title briefly flashes during load: “Inventory Adjustment Reasons” is visible before UI is ready and Row background color mismatches on row ends when adding a new Adjustment Reason | G2: Medium | H2: Manual | I2: External | J2: Vidhya | K2: Defect Fixed | L2: New Issue
A3: 2.5 KaleidaNutrition S17 | B3: 51380 | D3: Dhivyalakshmi / Nathiya | E3: Bounceback | F3: 2.Input row not visible when +Add is clicked on page >1; user must be navigated to page 1 | G3: Medium | H3: Manual | I3: External | J3: Vidhya | K3: Defect Fixed | L3: New Issue
A4: 2.5 KaleidaNutrition S17 Stretch | B4: 51731 | D4: Ruban | E4: Bounceback | F4: Reset button disabled when filter applied | G4: Medium | H4: Manual | I4: External | J4: Sudheer | K4: Defect Fixed | L4: New Issue

Sheet 2.5 KaleidaNutrition S16-Status
A1: S.No | B1: Application Name | C1: Sprint Start Date | D1: Sprint End Date | E1: Sprint | F1: Developer | G1: Story ID/Defect ID | H1: Description | I1: Status | J1: Estimated(sp) | K1: Actual(sp) | L1: Actual Hours Worklog | M1: Dev Start Date | N1: Dev End Date | O1: Unit testing | P1: Peer Tested By | Q1: Peer Tested Defects, if any | R1: Peer Reviewed By | S1: Peer Code Review Comments, if any | T1: PR Number/Link | U1: PR Created Date | V1: PR Approved Date | W1: Reviewer 1 | X1: Code Review Comments, if any | Y1: Reviewer 2 | Z1: Approved Date | AA1: Code Review Comments, if any2 | AB1: Internal PO -POV Comments | AC1: Client PO -POV Comments | AD1: Comments | AE1: Does this story meets expectations
A2: 1 | B2: Meal Order | C2: 46045 | D2: 46058 | E2: 2.5 KaleidaNutrition S16 | F2: Kiruthiga | G2: 51246 | H2: [WAVE] - App switcher - Install on Meal Orders | I2: Story Completed | J2: 8 | K2: 6 | L2: 24 | M2: 46045 | N2: 46056 | O2: Completed | P2: Sudheer | T2: https://dev.azure.com/heartlandschools/Meal%20Orders/_git/Meal%20Orders/pullrequest/47029 | U2: 46056 | V2: 46056 | W2: Ruba | Y2: Mike | Z2: 46056 | AD2: 30/1: There is an issue with Cosmo DB installation. It has been resolved now.
A3: 2 | B3: Meal Order | C3: 46045 | D3: 46058 | E3: 2.5 KaleidaNutrition S16 | F3: Ruban | G3: 51377 | H3: [WAVE] - Mosaic BOH Kaleida - Interior Pages Update - Setup - Allergens - Search & Add | I3: Story Completed | J3: 8 | K3: 8 | L3: 36 | M3: 46031 | N3: 46051 | O3: Completed | P3: Vidhya | T3: https://dev.azure.com/heartlandschools/Mosaic/_git/BOH/pullrequest/46960 | U3: 46051 | V3: 46052 | W3: Richard | Y3: Richard | Z3: 46052 | AC3: We have Active as the filter at the top and Enabled at the bottom.
A4: 3 | B4: Meal Order | C4: 46045 | D4: 46058 | E4: 2.5 KaleidaNutrition S16 | F4: Dhivyalakshmi | G4: 51359 | H4: [WAVE] MSB Accounting Kaleida - Update Login screen | I4: Story Completed | J4: 3 | K4: 8 | L4: 12 | M4: 46023 | N4: 46050 | O4: Completed | P4: Vidhya | T4: https://dev.azure.com/heartlandschools/Accounting/_git/MSBAccounting-NewSchoolBooks/pullrequest/469… | U4: 46050 | V4: NA | W4: NA | Y4: NA | Z4: NA | AD4: Draft PR has been created, Due to priority change it been hold and we have less possibilty to close this story
A5: 4 | B5: Meal Order | C5: 46045 | D5: 46058 | E5: 2.5 KaleidaNutrition S16 Stretch | F5: Dhivyalakshmi | G5: 51380 | H5: [WAVE] - BOH Kaleida - Interior Pages Update - Setup - Inventory Adjustment Reasons | I5: Story Being Developed | J5: 8 | M5: 46050
A6: 5 | B6: Meal Order | C6: 46045 | D6: 46058 | E6: 2.5 KaleidaNutrition S16 Stretch | F6: Sudheer | G6: 51384 | H6: Meal Orders - Automation - Settings - Serving Periods And data related issue fixes | I6: Story Being Developed | J6: 8 | M6: 46028 | T6: https://dev.azure.com/heartlandschools/Meal%20Orders/_git/MealOrdersAutomation/pullrequest/46761 | U6: 46043 | W6: Owen | Y6: Owen | AD6: PR created. After the login loop code changes, when executing the test scripts multiple times, a few tests failed due to data-related issues. After discussion, we decided to fix these issues as part of this PR, and the story points were increased accordingly.

Sheet 2.5 KaleidaNutrition S15-Status
A1: S.No | B1: Application Name | C1: Sprint Start Date | D1: Sprint End Date | E1: Sprint | F1: Developer | G1: Story ID/Defect ID | H1: Description | I1: Status | J1: Estimated(sp) | K1: Actual(sp) | L1: Actual Hours Worklog | M1: Dev Start Date | N1: Dev End Date | O1: Unit testing | P1: Peer Tested By | Q1: Peer Tested Defects, if any | R1: Peer Reviewed By | S1: Peer Code Review Comments, if any | T1: PR Number/Link | U1: PR Created Date | V1: PR Approved Date | W1: Reviewer 1 | X1: Code Review Comments, if any | Y1: Reviewer 2 | Z1: Approved Date | AA1: Code Review Comments, if any2 | AB1: Internal PO -POV Comments | AC1: Client PO -POV Comments | AD1: Comments | AE1: Does this story meets expectations
A2: 1 | B2: Meal Order | C2: 46031 | D2: 46044 | E2: 2.5 KaleidaNutrition S15 | F2: Kiruthiga | G2: 50838 | H2: [WAVE] - Web - BOH Kaleida - App switcher | I2: Story Completed | J2: 8 | K2: 6 | L2: 29 | M2: 46031 | N2: 46042 | O2: Completed | P2: Vidhya | T2: https://dev.azure.com/heartlandschools/Mosaic/_git/BOH/pullrequest/46745 | U2: 46042 | V2: 46042 | W2: Ruban | Y2: Richard | Z2: 46042 | AD2: Dev changes has been completed but still need a confirmation about the reflection of feature flag update as it requires logout action
A3: 2 | B3: Meal Order | C3: 46031 | D3: 46044 | E3: 2.5 KaleidaNutrition S15 Stretch | F3: Sudheer | G3: 51384 | H3: Meal Orders - Automation - Settings - Serving Periods | I3: Story Being Developed | J3: 8 | K3: 8 | L3: 32 | M3: 46028 | N3: 46043 | O3: Completed | P3: Sudheer | T3: https://dev.azure.com/heartlandschools/Meal%20Orders/_git/MealOrdersAutomation/pullrequest/46761 | U3: 46043 | W3: Owen | Y3: Owen | AD3: PR is ceated but one of the test got failed for owen due to date related issue, looking into issue.
A4: 3 | B4: Meal Order | C4: 46031 | D4: 46044 | E4: 2.5 KaleidaNutrition S15 | F4: Sudheer | G4: 51122 | H4: Meal Orders - Automation - Settings - Special Diet | I4: Story Completed | J4: 8 | K4: 8 | L4: 32 | M4: 46031 | N4: 46042 | O4: Completed | P4: Sudheer | T4: https://dev.azure.com/heartlandschools/Meal%20Orders/_git/MealOrdersAutomation/pullrequest/46399 | U4: 46031 | V4: 46043 | W4: Owen | Y4: Owen | Z4: 46043
A5: 4 | B5: Meal Order | C5: 46031 | D5: 46044 | E5: 2.5 KaleidaNutrition S15 Stretch | F5: Ruban | G5: 51377 | H5: [WAVE] - Mosaic BOH Kaleida - Interior Pages Update - Setup - Allergens - Search & Add | I5: Story Being Developed | J5: 13 | M5: 46031
A6: 5 | B6: Meal Order | C6: 46031 | D6: 46044 | E6: 2.5 KaleidaNutrition S15 Stretch | F6: Dhivyalakshmi | G6: 51359 | H6: [WAVE] MSB Accounting Kaleida - Update Login screen | I6: Story Being Developed | J6: 8 | K6: 11 | L6: 52 | M6: 46037

Sheet 2.5Kaleida Nutrition S14-Defect
A1: Sprint # | B1: Story/Defect ID | C1: Parent Story | D1: Developer | E1: Issue Type | F1: Issue Description | G1: Priority | H1: Defect Source | I1: Type | J1: Found By | K1: Status | L1: Root Cause Category | M1: RCA Comment *

Sheet 2.5 KaleidaNutrition S14-Status
A1: S.No | B1: Application Name | C1: Sprint Start Date | D1: Sprint End Date | E1: Sprint | F1: Developer | G1: Story ID/Defect ID | H1: Description | I1: Status | J1: Estimated(sp) | K1: Actual(sp) | L1: Actual Hours Worklog | M1: Dev Start Date | N1: Dev End Date | O1: Unit testing | P1: Peer Tested By | Q1: Peer Tested Defects, if any | R1: Peer Reviewed By | S1: Peer Code Review Comments, if any | T1: PR Number/Link | U1: PR Created Date | V1: PR Approved Date | W1: Reviewer 1 | X1: Code Review Comments, if any | Y1: Reviewer 2 | Z1: Approved Date | AA1: Code Review Comments, if any2 | AB1: Internal PO -POV Comments | AC1: Client PO -POV Comments | AD1: Comments | AE1: Does this story meets expectations
A2: 1 | B2: Meal Order | C2: 46003 | D2: 46030 | E2: 2.5 KaleidaNutrition S14 | F2: Sudheer | G2: 50670 | H2: Meal Orders - Automation - Regression - Allergens | I2: Story Completed | J2: 1 | K2: 1 | L2: 4 | M2: 46003 | N2: 46009 | O2: Sudheer | R2: Owen | T2: https://dev.azure.com/heartlandschools/Meal%20Orders/_git/MealOrdersAutomation/pullrequest/46004 | U2: 46009 | V2: 46009 | W2: Owen | Y2: NA
A3: 2 | B3: Meal Order | C3: 46003 | D3: 46030 | E3: 2.5 KaleidaNutrition S14 | F3: Kiruthiga | G3: 50839 | H3: [WAVE] - Web - FOH Kaleida - App switcher | I3: Story Completed | J3: 8 | K3: 8 | L3: 41 | M3: 46003 | N3: 46024 | O3: Completed | P3: Vidhya | R3: Ruban | T3: https://dev.azure.com/heartlandschools/Mosaic/_git/FOH/pullrequest/46412 | U3: 46027 | V3: 46027 | W3: Ruban | Y3: Ying | Z3: 46027
A4: 3 | B4: Meal Order | C4: 46003 | D4: 46030 | E4: 2.5 KaleidaNutrition S14 | F4: Dhivyalakshmi | G4: 49084 | H4: [WAVE] MSB Accounting - Update Page Footer - Webview | I4: Story Completed | J4: 8 | K4: 15 | L4: 70 | M4: 46003 | N4: 46027 | O4: Completed | P4: Kiruthiga | R4: Kiruthiga | T4: https://dev.azure.com/heartlandschools/Accounting/_git/MSBAccounting-NewSchoolBooks/pullrequest/46416 | U4: 46027 | V4: 46027 | W4: Ruban | Y4: Qadir | Z4: 46027
A5: 4 | B5: Meal Order | C5: 46003 | D5: 46030 | E5: 2.5 KaleidaNutrition S14 | F5: Ruban/Karthikeyan | G5: 50980 | H5: [WAVE] - Mosaic FOH - Interior Pages - Close day Reports search | I5: Story Completed | J5: 8 | K5: 22 | L5: 90 | M5: 46003 | N5: 46029 | O5: Completed | P5: Vidhya | R5: Kiruthiga | T5: https://dev.azure.com/heartlandschools/Mosaic/_git/FOH/pullrequest/46489 | U5: 46029 | V5: 46029 | W5: Ruban | Y5: Ying | Z5: 46030 | AD5: There was a delay on testing this story because of the deployment issue also story was under estimated
A6: 5 | B6: Meal Order | C6: 46003 | D6: 46030 | E6: 2.5 KaleidaNutrition S14 Stretch | F6: Sudheer | G6: 51122 | H6: Meal Orders - Automation - Settings - Special Diet | I6: Story Peer Review | J6: 8 | K6: 8 | L6: 36 | M6: 46022 | O6: Completed | P6: Sudheer | R6: Owen | T6: https://dev.azure.com/heartlandschools/Meal%20Orders/_git/MealOrdersAutomation/pullrequest/46399
A7: 6 | B7: Meal Order | C7: 46003 | D7: 46030 | E7: 2.5 KaleidaNutrition S14 Stretch | F7: Sudheer | G7: 51384 | H7: Meal Orders - Automation - Settings - Serving Periods | I7: Story Being Developed | J7: 8 | K7: 8 | L7: 40 | M7: 46028
F9: Wave | G9: MealOrders | H9: Total
E10: Completed Story Points | F10: 8 | G10: 19 | H10: 27

Sheet Defect-template
A1: S.No | B1: Sprint # | C1: Story/Defect ID | D1: Parent Story | E1: Developer | F1: Issue Type | G1: Issue Description | H1: Priority | I1: Defect Source | J1: Type | K1: Status | L1: Root Cause Category | M1: Comments
F2: None

Sheet 2.5 KaleidaNutrition S13-Status
A1: S.No | B1: Application Name | C1: Sprint Start Date | D1: Sprint End Date | E1: Sprint | F1: Developer | G1: Story ID/Defect ID | H1: Description | I1: Status | J1: Estimated(sp) | K1: Actual(sp) | L1: Actual Hours Worklog | M1: Dev Start Date | N1: Dev End Date | O1: Unit testing | P1: Peer Tested By | Q1: Peer Tested Defects, if any | R1: Peer Reviewed By | S1: Peer Code Review Comments, if any | T1: PR Number/Link | U1: PR Created Date | V1: PR Approved Date | W1: Reviewer 1 | X1: Code Review Comments, if any | Y1: Reviewer 2 | Z1: Approved Date | AA1: Code Review Comments, if any2 | AB1: Internal PO -POV Comments | AC1: Client PO -POV Comments | AD1: Comments | AE1: Does this story meets expectations
A2: 1 | B2: Meal Order | C2: 45975 | D2: 46002 | E2: 2.5 KaleidaNutrition S13 | F2: Kiruthiga | G2: 50774 | H2: [WAVE] FOH Kaleida - Login - Update server-side validation error message UI | I2: Story Completed | J2: 2 | K2: 2 | L2: 8 | M2: 45975 | N2: 45978 | O2: Completed | P2: Vidhya | R2: Ruban | T2: https://dev.azure.com/heartlandschools/Mosaic/_git/FOH/pullrequest/45763 | U2: 45978 | V2: 45978 | W2: Ruban | Y2: Ying | Z2: 45978 | AE2: Meets Expectation
A3: 2 | B3: Meal Order | C3: 45975 | D3: 46002 | E3: 2.5 KaleidaNutrition S13 | F3: Kiruthiga/Dhivya/Shikha | G3: 50756 | H3: [WAVE] - MSB Accounting (Setup/Discovery) | I3: Story Completed | J3: 13 | K3: 13 | L3: 52 | M3: 45975 | N3: 46001 | O3: Completed | P3: NA | R3: NA | T3: NA | AD3: It is a discovery story, Completed dev setup for the new project to update Kaleida changes | AE3: Meets Expectation
A4: 3 | B4: Meal Order | C4: 45975 | D4: 46002 | E4: 2.5 KaleidaNutrition S13 | F4: Ruban | G4: 50463 | H4: [WAVE] Mosaic FOH Kaleida - Interior Pages update - Catering - Add Catering Menus | I4: Story Completed | J4: 8 | K4: 8 | L4: 32 | M4: 45975 | N4: 45995 | O4: Completed | P4: Vidhya | R4: NA | T4: https://dev.azure.com/heartlandschools/Mosaic/_git/FOH/pullrequest/46084 | U4: 45995 | V4: 45995 | W4: Ruban | Y4: Ying | Z4: 45995 | AE4: Meets Expectation
