Workbook

Sheet Dashboard
A1: Current Sprint | B1: {=INDEX($B$2:$B$112,MATCH(1,(($D$2:$D$112 >=TODAY())*($C$2:$C$112<=TODAY())),0))} -> 26.6 Sprint S1 | C1: Current Sprint Sheet | D1: =CONCATENATE(B1,"-Status") -> 26.6 Sprint S1-Status | E1: Sprint Start Date | F1: =VLOOKUP($B$1,$B$1:$C$112,2) -> 46148 | G1: Sprint End Date | H1: =VLOOKUP($B$1,$B$1:$D$112,3) -> 46161 | I1: Application Name | J1: MSB Activities | K1: Users | L1: allen.xavier@relevantz.com;kanchanamala.umakanthan@relevantz.com;manjunathan.dharman@relevantz.com;athinarayanan.ramar@relevantz.com;ramprabu.sakthivel@relevantz.com | M1: Teams Name(GP- MSB Activities) | N1: 19:1e38c92221534f43aaff617f2f44a82e@thread.v2
A2: Sprint Type | B2: Sprint # | C2: Sprint Start Date | D2: Sprint End Date | E2: Assigned | F2: Completed | G2: Story points introduced/removed | H2: Sprint Summary | I2: Accomplishments | J2: Remarks | K2: Client Appreciations | L2: Retro Points (Internal & External) | M2: Unplanned Leaves | N2: Data sanity Audit Status | O2: AuditDate | P2: Backlog Health
A3: =IF(AND(#REF!>=C3,#REF!<=D3),"CurrentSprint","NA") -> #REF! | B3: 2.9 Sprint S1 | C3: 45294 | D3: 45307 | E3: 9 (47 sp - assigned) | F3: 9 - Development completed 4 - Testing completed 2 - Testing in progress 3 - Peer review (23 sp - completed) | J3: 42924, 42923, 42989 - Story peer review, 22646, 37677, 22653, 22655 - Testing completed , 22642, 42917 - Testing in progress. | L3: Internal: External:
A4: =IF(AND(#REF!>=C4,#REF!<=D4),"CurrentSprint","NA") -> #REF! | B4: 2.9 Sprint S2 | C4: 45308 | D4: 45321 | E4: 5 (31 sp - assigned) | F4: 4 - Testing completed [22682, 22676, 22657,43155] 2 - defect/story carried from last sprint for testing [22642, 42917] - Testing Completed (19 sp - completed) | J4: 2 - client peer review [42924, 42923], 2 - Testing [22642, 42917] - Carried from last sprint [2.9 sprint s1] 5 - Development [22682, 22676, 22657,43155, 43149- timeboxed] - Current sprint [2.9 sprint s2] | L4: Internal: External:
A5: =IF(AND(#REF!>=C5,#REF!<=D5),"CurrentSprint","NA") -> #REF! | B5: 2.9 Sprint S3 | C5: 45322 | D5: 45335 | E5: 9 (31 sp - assigned) | F5: Development completed (8) -22756, 43550, 43336,43335,43334,43388, 43536,43486 Development inprogress -42874 | J5: 2 - Testing pending [42924, 42923], 1- stretch [ 43313 ] - Testing pending - Carried from last sprint [2.9 sprint s2] Total 9 - [43334 (Main -1), [Stretch -22756, 43486, 43336,43335,43550,43388, 42874,43536=8] This Regressin sprint,team worked on stretch stories | L5: Internal: External:
A6: =IF(AND(#REF!>=C6,#REF!<=D6),"CurrentSprint","NA") -> #REF! | B6: 2.9.5 Sprint S1 | C6: 45336 | D6: 45349 | E6: 5 Total - 46 Sp (7+5) | F6: 21 Sp | G6: 2 sp | J6: Carried from last sprint for client Peer review and Testing: 43633,22756,43550,43586,43335,43336,43486 = 7 Current Sprint stories assigned Main :42874,43531,43659; Stretch: 43629,43582 Total:5 Introduced story in stretch - 43208 | L6: Internal: External:
A7: =IF(AND(#REF!>=C7,#REF!<=D7),"CurrentSprint","NA") -> #REF! | B7: 2.9.5 Sprint S2 | C7: 45350 | D7: 45363 | E7: 9 [50 Sp] | F7: 53 sp | J7: Carried from last sprint for client Peer review and Testing: =3 Current Sprint stories assigned Main and stretch : 9 Total: 9+3 = 12 | L7: Internal: External:
A8: =IF(AND(#REF!>=C8,#REF!<=D8),"CurrentSprint","NA") -> #REF! | B8: 2.9.5 Sprint S3 | C8: 45364 | D8: 45377 | E8: 7 [ 33 Sp] | F8: 26.5 Sp | J8: Regression Sprint | L8: Internal: External:
A9: =IF(AND(#REF!>=C9,#REF!<=D9),"CurrentSprint","NA") -> #REF! | B9: 3.0 Sprint S1 | C9: 45378 | D9: 45391 | E9: 14 | F9: 9 | J9: One of the offshore developer is on planned leave for the entire Sprint. Development completed for all 4 committed stories. (3 - Closed, 1 - Client POV pending) Development completed for 3 out of 4 stretch stories. (3 - PR approval pending from client, 1 - Development in progress) | L9: Internal: External:
A10: =IF(AND(#REF!>=C10,#REF!<=D10),"CurrentSprint","NA") -> #REF! | B10: 3.0 Sprint S2 | C10: 45392 | D10: 45405 | E10: 9 [37 Sp] | F10: 22 Sp | J10: 2 development story 1 Automation and 6 - testing =9 | L10: Internal: External:
A11: =IF(AND(#REF!>=C11,#REF!<=D11),"CurrentSprint","NA") -> #REF! | B11: 3.0 Sprint S3 | C11: 45406 | D11: 45419 | E11: 31 sp | F11: 31 Sp | J11: Regression Sprint | L11: Internal: External:
A12: =IF(AND(#REF!>=C12,#REF!<=D12),"CurrentSprint","NA") -> #REF! | B12: 3.1 Sprint S1 | C12: 45420 | D12: 45433 | E12: 29 Sp | F12: 16 Sp | L12: Internal: External:
A13: =IF(AND(#REF!>=C13,#REF!<=D13),"CurrentSprint","NA") -> #REF! | B13: 3.1 Sprint S2 | C13: 45434 | D13: 45447 | E13: 23 Sp | F13: 23 Sp | J13: Testing will be covered in next sprint for 3 stories. | L13: Internal: External:
A14: =IF(AND(#REF!>=C14,#REF!<=D14),"CurrentSprint","NA") -> #REF! | B14: 3.1 Sprint S3 | C14: 45448 | D14: 45461 | E14: 29 Sp | F14: 29 Sp | J14: Regression Sprint | L14: Internal: External:
A15: =IF(AND(#REF!>=C15,#REF!<=D15),"CurrentSprint","NA") -> #REF! | B15: 3.2 Sprint S1 | C15: 45462 | D15: 45475 | E15: 30 Sp | F15: 14 sp | L15: Internal: External:
A16: =IF(AND(#REF!>=C16,#REF!<=D16),"CurrentSprint","NA") -> #REF! | B16: 3.2 Sprint S2 | C16: 45476 | D16: 45489 | E16: 26 Sp | F16: 26 Sp | J16: Completed all committed stories with testing and 45114 and 45203 took more efforts than the initial estimation in closing out along with testing. | K16: 3.2 Sprint S2 Retro Appreciation : Assignees: Kristy MacCheyne - Client PO Kudos to everyone on the team. This was an awesome sprint. Allen - Leadership ensuring the team is all on the same page working toward our goals, helping out with getting stories completed to make 3.2 even better. His research for upcoming efforts and suggestions for how to best handle everything. Hari - Always extremely grateful for all of Hari's efforts. I can always trust that anything Hari takes on will be great. Kanchana - Kanchana continuously does an incredible job in this role ensuring we are all communicating effectively and that if/when there are questions we are able to discuss them to get on the same page. Her efforts to ensure we have stories written up for Refinements based on prioritized efforts is greatly appreciated. I also appreciate her collaboration with my new Business Analyst for my other team, Kanchana models how helpful her role can be to Product Management and I appreciate her willingness to provide guidance to my other team's BA. Kaliammal - Great work on wrapping up her first stories since getting access figured out. Manjunathan - Attention to detail and catching impressive finds while testing stories (ie: the final bounceback on 44444), ensuring testing wrapped up on everything heading into Planning for Regression. | L16: Internal: External:
A17: =IF(AND(#REF!>=C17,#REF!<=D17),"CurrentSprint","NA") -> #REF! | B17: 3.2 Sprint S3 | C17: 45490 | D17: 45503 | E17: 29 Sp | F17: 29 Sp | G17: 14 | J17: Regression Sprint | L17: Internal: External:
A18: =IF(AND(#REF!>=C18,#REF!<=D18),"CurrentSprint","NA") -> #REF! | B18: 3.3 Sprint S1 | C18: 45504 | D18: 45517 | E18: 24 Sp | F18: 24 | K18: 3.3 Sprint S1 Retro Appreciation : Assignees: Kristy MacCheyne - Client PO Manjunathan - Did a great job at staying on top of the large testing effort we had for Sprint 1. Manjunathan and Jeff both made this sprint look easy despite a lot of work being on their shoulders. Kaliammal - Kaliammal is doing a great job getting up to speed, she did great work on the No Cost Retainer Fee story. Hari - Thank you Hari for always doing an exceptional job with whatever story you take on. You are always ready to take on stories/epics for our Release Goals and I really appreciate it. Kanchana - I appreciate all of Kanchana's efforts. She does an exceptional job in this role and allows me to jump back and forth between teams and spend time supporting my other team when they had escalations coming up. Kanchana is always extremely thoughtful, detail oriented, and a true team player Allen - Thank you for your incredible ideas and suggestions for approach, Allen really helped me ahead of our last Planning meeting to ensure we were setting QA up for success with a large number of stories ready for testing. Allen's leadership is always greatly appreciated. . | L18: Internal: External:
A19: =IF(AND(#REF!>=C19,#REF!<=D19),"CurrentSprint","NA") -> #REF! | B19: 3.3 Sprint S2 | C19: 45518 | D19: 45531 | E19: 32 Sp | F19: 19 Sp | J19: Completed most of the committed stories with one story 45116 in QA which will be carry forwarded to next sprint for QA. | L19: Internal: External:
A20: =IF(AND(#REF!>=C20,#REF!<=D20),"CurrentSprint","NA") -> #REF! | B20: 3.3 Sprint S3 | C20: 45532 | D20: 45545 | E20: 21 Sp | F20: 19 Sp | J20: 23905, 44143 - Client moved to next release 10-Sep-2024 Peer CRC: 0 Onsite CRC: 0 Client CRC: 2 Internal Defects: 5 External Defects: 1 | N20: Completed
A21: =IF(AND(#REF!>=C21,#REF!<=D21),"CurrentSprint","NA") -> #REF! | B21: 3.4 Sprint S1 | C21: 45546 | D21: 45559 | E21: 23 Sp | F21: 23 Sp | G21: 18 Sp | J21: 24-Sep-2024 Peer CRC: 0 Onsite CRC: 0 Client CRC: 1 Internal Defects: 2 External Defects: 0 | N21: Completed
A22: =IF(AND(#REF!>=C22,#REF!<=D22),"CurrentSprint","NA") -> #REF! | B22: 3.4 Sprint S2 | C22: 45560 | D22: 45573 | E22: 22 Sp | F22: 21 Sp | J22: 09-Oct-2024 Peer CRC: 2 Onsite CRC: 0 Client CRC: 2 Internal Defects: 3 External Defects: 0
A23: =IF(AND(#REF!>=C23,#REF!<=D23),"CurrentSprint","NA") -> #REF! | B23: 3.4 Sprint S3 | C23: 45574 | D23: 45587 | E23: 14 Sp | F23: 22 Sp | G23: Introduced - 8 | J23: Regression Sprint 23-Oct-2024 Peer CRC: 0 Onsite CRC: 1 Client CRC: 0 Internal Defects: 0 External Defects: 0
A24: =IF(AND(#REF!>=C24,#REF!<=D24),"CurrentSprint","NA") -> #REF! | B24: 3.5 Sprint S1 | C24: 45588 | D24: 45601 | E24: 24 Sp | F24: 11 Sp | I24: Completed 46329 - Bulk Copy Enrollment Common component creation which is pre-requisite for two other stories | J24: Reason for not Completing the Story Points --- 46323 - Testing not completed due to PTO of both offshore and client QA 46336 - PR delayed due to existing issues in related component Regression Sprint 46355 - Timebox story 46032 - Stretch story Peer CRC: 0 Onsite CRC: 1 Client CRC: 0 Internal Defects: 0 External Defects: 0 | K24: Client PO Appreciations for the team : Kanchana - Partnering with Kanchana also brings me joy - she has a desire to learn, grow, and take on whatever task comes up. She inspires me with her organization skills and attention to detail and helps make everything much smoother and easier for me (and the team)! Hari - I appreciate your thoroughness, great questions, and agility. You're always ready to take on challenging efforts. Kaliammal - I appreciate that you are always ready to take on whatever story/defect requires attention. You're a great addition to our team! Manjunathan - I appreciate seeing your growth on this team! Your attention to detail and thoughtfulness in testing is really appreciated as well! Jeff always speaks highly of you and both of you collaborating on testing efforts! Allen - I appreciate your dedication, steadiness, and thoughtful approach to solving problems. You always have great ideas, and it helps with each effort we take on (especially ones that have been hanging out in the backlog without a clear path for us).
A25: =IF(AND(#REF!>=C25,#REF!<=D25),"CurrentSprint","NA") -> #REF! | B25: 3.5 Sprint S2 | C25: 45602 | D25: 45615 | E25: 29 | F25: 37 | G25: Story points introduced in the mid of the sprint : 46499 -3sp 46511 - 5sp 46557 - 8 sp Defect points introduced : 24286 - 1sp 24301 - 1sp Total Introduced - 18 Total Completed - 8 | I25: Completed Enrollment Plans - Selected Actions Bulk Edit (Seminole) and Capacity Report - Dropdown Tree for Activity and EP Filters (Seminole) | J25: Peer CRC: 0 Onsite CRC: 0 Client CRC: 0 Internal Defects: 2 External Defects: 1 (Production Issue - Minor) | K25: Excellent communication skills, frequent check-ins, excellent collaboration, and always working to build an environment where we can share ideas to work towards common goals! The great discussions, sharing of ideas, collaboration, and identifying new paths to solve problems that have left us stuck in the past. Hearing positivity from internal stakeholders and customers (and then sharing with the team) about how our work has helped product growth and quality of life.
A26: =IF(AND(#REF!>=C26,#REF!<=D26),"CurrentSprint","NA") -> #REF! | B26: 3.5 Sprint S3 | C26: 45616 | D26: 45629 | E26: 21 Sp | F26: 39 sp | G26: Stories Introduced Introduced - 5sp Defects Introduced Introduced - 3sp Total Introduced - 8 Total Completed - 8 | I26: 1.Completed Enrollment Plan Maintenance - Limit number for Selected Actions & Config Prop, 2.Capacity Report - Total "All Enrollment Plans" count in Excel Output Format, 3.Attendance Report - Group By Grade, 4.Update "Description" to Item Name [UI Labels Only](PR & QA) | J26: Peer CRC: 1 Onsite CRC:1 Client CRC: 2 Internal Defects: 6 External Defects: 0 | K26: The team continues to do a great job and accomplish everything they set out to do despite any disruptions. This sprint we had a ton of Client PTO and difficult timing to work around and the team still managed to close out the commit and make some progress in the stretch despite all of that. It's exciting to see the team continuing to knock it out of the park. I’m just so proud of this team! Keep up the great work!
A27: =IF(AND(#REF!>=C27,#REF!<=D27),"CurrentSprint","NA") -> #REF! | B27: 3.5 Sprint S4 | C27: 45630 | D27: 45659 | E27: 24 | F27: 55 | G27: Total Introduced: 31 | I27: 1.Completed the development work for React conversion stories for Users, Home page and District level. 2.Completed the development work for Enrollment Plan/Activity - Update "Description" to Item Name in SQL Tables (SYSTEM). 3. Completed the development work for Spilt billing audit log and Term Capture Attendance Calendar modifications in Audit Log | J27: Peer CRC: 6 Onsite CRC:0 Client CRC: 0 Internal Defects: 7 External Defects: 0 | K27: Keep up the great work and continue efforts we started in 3.5 Sprint 4 (with the intention of holding for 3.6)
A28: =IF(AND(#REF!>=C28,#REF!<=D28),"CurrentSprint","NA") -> #REF! | B28: 3.6 Sprint S1 | C28: 45660 | D28: 45671 | E28: 14 | F28: 32 | I28: 1.Modified the common component Date Selector to Display as an Expanded Calendar Overlay 2.Fixed production defect regarding the billing Prepaid Billing Used Instead of Drop In - Logic defect fixed 3.Admin Home Page has been converted to react 4.Students page to Server Side sorting | J28: Few Stories are moved to 3.7 that Contains DataBase Column Name Changes - Slated for 3.7 release. One Story is On hold by Client QA Peer CRC: 1 Onsite CRC:1 Client CRC: 1 Internal Defects: 2 External Defects: 2
A29: =IF(AND(#REF!>=C29,#REF!<=D29),"CurrentSprint","NA") -> #REF! | B29: 3.6 Sprint S2 | C29: 45672 | D29: 45685 | E29: 43 | F29: 50 | G29: Introduced - 10 | I29: 1.Completion of District level view of Open Operating Days 2.Completion of React conversion for Tenant and Heartland Staff users 3.Fixed Production defect regarding Operating day checkout errors 4.Updated Enrollment Plan - Update "Required Forms" page with Sorting and Pagination. 5 Updated the.MSB Invoice Profile - Remove filter by Provider for GL Codes | J29: Peer CRC: 0 Onsite CRC:0 Client CRC: 2 Internal Defects: 7 External Defects: 2 | K29: Feedback from Beth Boyack, Payments Account Specialist after using this for the first time: "Hey! I'm using the copy enrollment plan for the first time. Yay!! Definitely helps!" & "I was only copying 4 plans and the performance was good, no lag or anything". Great feedback on the new Selected Actions effort! | L29: Kristy MacCheyne Product Manager - MSB Activities & MSB Tickets - "I think we have great commitment to our team, as well as to our sprint goals. If we are struggling on one story/defect, we communicate with each other and identify a path forward. I think the strong individual commitment to the sprint is a side effect of our commitment to our team and collective goals."
A30: =IF(AND(#REF!>=C30,#REF!<=D30),"CurrentSprint","NA") -> #REF! | B30: 3.6 Sprint S3 | C30: 45686 | D30: 45699 | E30: 20 | F30: 31 | I30: 1.Completed Filter By Registration status for Custom Registration with highlighting updated fields for Updated Registrations 2.Completion of Performance improvement to reduce the time taken to copy large number of Enrollment plans which required Framework level changes. 3.Completed converting Description Table column to Name for SecurityGroup, Kiosk, District, Custom Fields and Dynamic Report 4.Fixed existing production defect in Custom Registration Report | J30: Peer CRC: 0 Onsite CRC:1 Client CRC: 0 Internal Defects: 7 External Defects:1 | L30: Kristy MacCheyne Product Manager - MSB Activities & MSB Tickets - "The team did an excellent job at working through Regression testing, identifying and resolving defects, making progress on some Performance Improvements, updating description to item names in SQL tables, Automation, and had some great discussions for some upcoming larger efforts. I think we also have been doing a great job at communicating and relaying concerns/needs to re-estimate certain efforts as we learn more and have been able to reforecast as needed to ensure we are capturing as much of the full picture of these efforts as we can.Also, we are seeing things pick up on the sales side for Activities and I have been working closely with the new dedicated sales rep for Activities (Ed), we are partnering for an upcoming webinar that I am really excited about."
A31: =IF(AND(#REF!>=C31,#REF!<=D31),"CurrentSprint","NA") -> #REF! | B31: 3.7 Sprint S1 | C31: 45700 | D31: 45713 | E31: 23 | F31: 37 | G31: Introduced - 5 Removed - 8 | I31: 1.Completed Customizable column headers for the Datatable in Parent Accounts. 2.Completed Description change to Item Name for Activity, Enrollment plan, Security Group, Kiosk and District Maintenance. 3.Development completed to Improve performance for Bulk edit of Enrollment plans. | J31: Peer CRC: 0 Onsite CRC:0 Client CRC: 2 Internal Defects:2 External Defects:1 | K31: Feedback from Ramsey Whitley, Implementation Coordinator Ramsey's comment was towards the customizable parent table column headers in the sprint demo review, like this is a wonderful feature. | L31: Kristy MacCheyne Product Manager - MSB Activities & MSB Tickets - Dedication, determination, and collaboration from the team! We had some great discussions to ensure we are all on the same page. We also got some really great new features added this Sprint. I loved Hari's approach for displaying Students in the Student column (Customizable Columns for Parents). Shoutout to Andy for his patience and determination as we made various changes to the District view of Terms. Jeff and Manjunathan did a great job at getting things over the finish line this sprint. Brian Newby, Senior Manager, Software Development Mentioned: "The team is communicating well and doing great work".
A32: =IF(AND(#REF!>=C32,#REF!<=D32),"CurrentSprint","NA") -> #REF! | B32: 3.7 Sprint S2 | C32: 45714 | D32: 45727 | E32: 23 | F32: 38 | G32: Introduced - 7 | I32: 1.Completed the Other Contacts Customizable column Header. 2.Completed updating Setup icons, text position, order for tiles and, page headers. 3.Completed the Custom Registration Report - Include Student Number for Output Format. 4.Completed Description change to Item Name for Term and Site. 5.Completed the Performance Improvements for Enrollment Plan for Bulk Edit. 6. Fixed existing PROD defects. | J32: Peer CRC: 0 Onsite CRC:1 Client CRC:5 Internal Defects:2 External Defects:3 | K32: Feedback from Beth Boyack, Payments Account Specialist "OMG I just used the Dynamic Report Generator for Updated Student Counts and it's AMAZING!! I don't think I can thank you enough for this!" Feedback from Kristy MacCheyne Product Manager - MSB Activities & MSB Tickets @Allen Xavier : all the time you have spent on the dynamic report generator is paying off! | L32: Kristy MacCheyne Product Manager - MSB Activities & MSB Tickets - I think the number 1 thing we do that we do well/should continue doing is communicating with each other. This team does an exceptional job at communicating progress, challenges, etc. I think the team's collaborative approach helps ensure we are successful each sprint - we discuss problems/challenges as a team, share ideas to fix/improve, and work together each step of the way to make it happen. I find the discussions with the team the most fulfilling for my day to day.
A33: =IF(AND(#REF!>=C33,#REF!<=D33),"CurrentSprint","NA") -> #REF! | B33: 3.7 Sprint S3 | C33: 45728 | D33: 45741 | E33: 15 | F33: 25 | I33: 1.Completed Research for Split billing improvements to upload invoices by MSB UserId 2.Development completion of Next set of Description changes for Fees,FormTypes,Discounts,Custom Fields and Dynamic Report. 3.Development completion of enhancement in the Datatable to show total Entries | J33: Peer CRC: 0 Onsite CRC:0 Client CRC:1 Internal Defects:0 External Defects:0
A34: =IF(AND(#REF!>=C34,#REF!<=D34),"CurrentSprint","NA") -> #REF! | B34: 3.8 Sprint S1 | C34: 45742 | D34: 45755 | E34: 36 | F34: 28 | I34: 1.Development completion of Split billing improvements to invoice by MSB User ID 2.UI Enhancement - Ability to select multiple fields of Student, Parent and Contact fields in Enrollment plan 3.Reports - Improve Student Filter Multi-Select dropdowns | J34: Peer CRC: 5 Onsite CRC:1 Client CRC:0 Internal Defects:3 External Defects:0 | K34: Feedback from Kristy MacCheyne about the team Product Manager - MSB Activities & MSB Tickets Ganapathi Sent: Hello team, I just got off a call with Kristy where in she was so happy with the team's transformation and progress. I've no words to express the excitement that she expressed talking about everyone on the team under Allen's leadership. Kudos to your hardwork and commitment | L34: Kristy MacCheyne: Product Manager - MSB Activities & MSB Tickets Kanchana's attention to detail always helps us be prepared. I also think our Refinements and discussions at standups helped us keep momentum. I also think that the new process for Pendo guides worked well this sprint. Jeff Dean - QA Team collaboration is always a great line for success with this team. Each strand in our team does great work in completing and making sure we are successful.
A35: =IF(AND(#REF!>=C35,#REF!<=D35),"CurrentSprint","NA") -> #REF! | B35: 3.8 Sprint S2 | C35: 45756 | D35: 45769 | E35: 29 | F35: 27 | G35: Introduced - 22 | I35: 1.Student Filter Improvements in Report 2.Enhancement in Field Selection in EnrollmentPlan 3.Split Billing Updates 4.Tile Icon updates in Registration Page 5.New SearchableSelect Component creation to be reused across the application | J35: Peer CRC: 2 Onsite CRC:0 Client CRC:2 Internal Defects:0 External Defects:2 | L35: Kristy MacCheyne: Product Manager - MSB Activities & MSB Tickets Kudos to the entire team! Everyone did really great work this sprint from Allen cruising through the split billing story, Hari providing great ideas for UI and calling out scenarios we may not think of, Kaliammal also did great work and showcased that getting quick feedback during POVs in 2nd rounds. Manjunathan did a great job working with Jeff to get through a LOT of testing efforts, Kanchana always does a fantastic job at supporting the team, her attention to detail is great - catching some defects that we have been able to fix before anyone notices, and keeping things moving.
A36: =IF(AND(#REF!>=C36,#REF!<=D36),"CurrentSprint","NA") -> #REF! | B36: 3.8 Sprint S3 | C36: 45770 | D36: 45783 | E36: 9 | F36: 19 | G36: 16 | I36: 1.Completed Regression testing with no regression defect 2.Completed Research to display Split billing invoices under purchases 3.Completed Research on tracking split billing changes in Audit log 4.Completed Research on Custom registration report to support multiple enrollmentplans | J36: Peer CRC: 2 Onsite CRC:1 Client CRC:1 Internal Defects:0 External Defects:0 | K36: NIL | L36: NIL
A37: =IF(AND(#REF!>=C37,#REF!<=D37),"CurrentSprint","NA") -> #REF! | B37: 3.9 Sprint S1 | C37: 45784 | D37: 45797 | E37: 26 | F37: 23 | G37: 9 | I37: Conversion of Auditlog view into a Grid with search,sort and customisable column header functionality, Improvements in Add tenant Page, Split Billing settings which was displayed as a Popup/Modal has been converted in to a separate page for ease of access. | J37: Peer CRC: 1 Onsite CRC:1 Client CRC:2 Internal Defects:4 External Defects:0 | K37: We have implemented the existing audit log in a table grid format for student maintenance. Feedback from Jeff Dean - QA This makes me happy: I'm sure our support members will LOVE it as much as I am, if not more! makes it SO MUCH easier to find information Feedback from Brian Newby:Senior Manager Good stuff. Sometimes its hard to step back and see the impact that our work is having. Thanks for all you you guys do. | L37: Kristy MacCheyne: Product Manager - MSB Activities & MSB Tickets We made great progress on updating the display of audit logging for student maintenance - the new grid view looks great! We also made excellent progress on split billing updates for audit logging, displaying split billing as a separate tab from the Student record (instead of needing to drill into editing the student details to find the split billing setup), improving and expediting the add district/tenant process, automation, and tech debt. Overall, it was a great sprint for the team with great communication. Excellent communication, trust, determination, and Kanchana 😂 (I don’t think I need to say much more than her name - she helps lock in on our goal and help guide everyone forward).
A38: =IF(AND(#REF!>=C38,#REF!<=D38),"CurrentSprint","NA") -> #REF! | B38: 3.9 Sprint S2 | C38: 45798 | D38: 45811 | E38: 24 | F38: 29 | G38: Introduced - 20 | I38: 1.Inclusion of Splitbilling invoices in Purchases, 2.Relocation of Splitbilling settings to a separate tab with readonly and edit view 3.Additional fields in Tenant Add/Edit page | J38: Peer CRC: 5 Onsite CRC:0 Client CRC:0 Internal Defects:3 External Defects:3 | K38: NIL | L38: Jeff Dean - QA Analyst: Manjunathan and Kanchana’s attention to detail, Allens willingness to go above and beyond (and check in late at night lol). Being ourselves. Kristy MacCheyne: : Product Manager - MSB Activities & MSB Tickets The team is always great at working together and providing support in whatever area needs it most. This sprint I had to take some unexpected time off for my health and the team did a great job at filling in and keeping everything moving in the right direction. Shout out to Kanchana!
A39: =IF(AND(#REF!>=C39,#REF!<=D39),"CurrentSprint","NA") -> #REF! | B39: 3.9 Sprint S3 | C39: 45812 | D39: 45825 | E39: 32 | F39: 52 | G39: Introduced - 20 | I39: 1.Regression went well. 2.Fixed Regression Split Billing Defects. 3.Completed People - Update Icons and Tile Layout 4.Split Billing Audit Log changes and UI Changes. 5.Converted Tile layout pages, Admin Header & Left Navigation Menu to React. 6.Good Progress on Vega UI updates on Admin Header and Left Navigation Menu 7.Completed few discovery stories like Notification Hub & Registration - Specific URLs 8.Conversion of Functional Components | J39: Peer CRC:0 Onsite CRC:0 Client CRC:0 Internal Defects:2 External Defects:2 | K39: NIL | L39: Kristy MacCheyne: : Product Manager - MSB Activities & MSB Tickets The team had some great conversations this sprint during standups, refinement, and planning prep calls. The team also made great progress on converting the admin header and left nav to React, and getting a start on implementing the new vega components with the new designs (exceeded my expectations for where I thought we would be)! The team also did a great job with regression (as usual). The team has done a great job at focusing on what is within our control though, and providing great feedback to help make the designs better for everyone (not just our team). Shoutout to Allen for his attention to detail/eye for the customer UX in pointing out risks with the District/Site dropdown placement within the new design.Shoutout to Kanchana for her great ideas of upcoming improvements to the Parent UX.
A40: =IF(AND(#REF!>=C40,#REF!<=D40),"CurrentSprint","NA") -> #REF! | B40: 4.0 Sprint S1 | C40: 45826 | D40: 45839 | E40: 13 | F40: 13 | G40: Introduced - 5 | I40: 1. Completed development for Multi Selection Enrollment Plan Filter in Custom Registration Report. 2. Completed Split Billing - Partial Invoice Upload Failures 3. Completed updating Tile Layout Pages to React 4. Added a new "State" column in Districts maintenance table grid page. | J40: Peer CRC:2 Onsite CRC:0 Client CRC:1 Internal Defects:0 External Defects:0 | K40: NIL | L40: Brian Newby: Senior Manager, Software Development Making progress on Azure AD group and Notification Hub integration. Vega stuff looks good. Kristy MacCheyne: Product Manager - MSB Activities & MSB Tickets Great progress on the Kaleida designs, worked together as a team to identify the best path forward for our District/Site selector (despite it being different from the initial designs, I feel that we are making the right decision and the design team and platform PM are aligned on our approach.
...

Sheet Defect-template
A1: S.No | B1: Sprint # | C1: Story/Defect ID | D1: Parent Story | E1: Developer | F1: Issue Type | G1: Issue Description | H1: Priority | I1: Defect Source | J1: Type | K1: Status | L1: Root Cause Category | M1: Comments

Sheet Unplanned Leaves
A1: Total Leaves | B1: =SUM(B20:F20) -> 0
B2: Resource Name
A3: Sprint | B3: Allen Xavier | C3: Athinarayanana Ramar | D3: Ramprabhu Sakthivel | E3: Manjunathan Dharaman | F3: Kanchana Umakanthan | G3: Remarks
A4: 26.3 Sprint S1(26-Jan-2026 to 10-Feb-2026)
A5: 26.3 Sprint S2(11-Feb-2026 to 24-Feb-2026)
A6: 26.3 Sprint S3(25-Feb-2026 to 10-Mar-2026)
A7: 26.5 Sprint S1(11-Mar-2026 to 24-Mar-2026)
A8: 26.5 Sprint S2(25-Mar-2026 to 07-Apr-2026)
A9: 26.5 Sprint S3( 08-Apr-2026 to 21-Apr-2026
A10: 26.5 Sprint S4( 22-Apr-2026 to 05-May-2026)
A20: Total | B20: =SUM(B4:B19) -> 0 | C20: =SUM(C4:C19) -> 0 | D20: =SUM(D4:D19) -> 0 | E20: =SUM(E4:E19) -> 0 | F20: =SUM(F4:F19) -> 0

Sheet 26.6 Sprint S1-Status
A1: S.No | B1: Application Name | C1: Sprint Start Date | D1: Sprint End Date | E1: Sprint | F1: Developer | G1: Story ID/Defect ID | H1: Description | I1: Status | J1: Estimated(sp) | K1: Actual(sp) | L1: Actual Hours Worklog | M1: Dev Start Date | N1: Dev End Date | O1: Unit testing | P1: Peer Tested By | Q1: Peer Tested Comments, if any | R1: Peer Reviewed By | S1: Peer Code Review Comments, if any | T1: PR Number/Link | U1: PR Created Date | V1: PR Approved Date | W1: Onsite Lead Code Review | X1: Onsite Lead Code Review Comments, if any | Y1: Client Code Review | Z1: PR Approved Date2 | AA1: Client Code Review Comments, if any | AB1: Internal PO -POV Comments | AC1: Client PO -POV Comments | AD1: Comments | AE1: Does this story Meet Expectations?
A2: =ROW() - ROW(Table1456789101214161817222426283132333637394143454749515355575961636567[[#Headers],[S.No]]) - 1 -> 0
A3: =ROW() - ROW(Table1456789101214161817222426283132333637394143454749515355575961636567[[#Headers],[S.No]]) - 1 -> 1 | B3: MSB Activities | C3: 46148 | D3: 46161 | E3: 26.6 Sprint S1 | F3: Athi | G3: 27161 | H3: Activities - Admin - Pending Registration not showing updated weeks | I3: Defect Fixed | J3: 5 | K3: 3 | L3: 12 | M3: 46149 | N3: 46153 | O3: Done | P3: Ram | Q3: Nil | R3: Ram | S3: Nil | T3: https://dev.azure.com/heartlandschools/Activities/_git/Activities/pullrequest/48962 | U3: 46153 | V3: 46153 | W3: Allen | X3: Nil | Y3: Ethan | Z3: 46153 | AA3: Nil | AB3: NA | AC3: NA | AD3: NA | AE3: Meets Expectation
A4: =ROW() - ROW(Table1456789101214161817222426283132333637394143454749515355575961636567[[#Headers],[S.No]]) - 1 -> 2 | B4: MSB Activities | C4: 46148 | D4: 46161 | E4: 26.6 Sprint S1 | F4: Allen | G4: 52738 | H4: Activities - Admin - Place cursor in search box for expanded Site selector | I4: Story Completed | J4: 2 | K4: 2 | L4: 8 | M4: 46153 | N4: 46153 | O4: Done | P4: Athi | Q4: Nil | R4: Athi | S4: Nil | T4: https://dev.azure.com/heartlandschools/Activities/_git/Activities/pullrequest/49000 | U4: 46154 | V4: 46154 | W4: Allen | X4: Nil | Y4: Ethan | Z4: 46154 | AA4: Nil | AB4: Approved | AC4: Approved | AE4: Meets Expectation
A5: =ROW() - ROW(Table1456789101214161817222426283132333637394143454749515355575961636567[[#Headers],[S.No]]) - 1 -> 3 | B5: MSB Activities | C5: 46148 | D5: 46161 | E5: 26.6 Sprint S1 | F5: Athi | G5: 53146 | H5: Activities - Parent - Hide download/print schedule from Enrollments page [26.5] | I5: Story Completed | J5: 2 | K5: 1 | L5: 4 | M5: 46148 | N5: 46148 | O5: Done | P5: Ram | Q5: Nil | R5: Ram | S5: Nil | T5: https://dev.azure.com/heartlandschools/Activities/_git/Activities/pullrequest/48873 | U5: 46148 | V5: 46148 | W5: Allen | X5: Nil | Y5: Andy | Z5: 46148 | AA5: Nil | AB5: Approved | AC5: Approved | AE5: Meets Expectation
A6: =ROW() - ROW(Table1456789101214161817222426283132333637394143454749515355575961636567[[#Headers],[S.No]]) - 1 -> 4 | B6: MSB Activities | C6: 46148 | D6: 46161 | E6: 26.6 Sprint S1 | F6: Allen | G6: 27358 | H6: Activities - Fake parent login is not working | I6: Defect Being Fixed | J6: 1 | M6: 46148 | N6: 46153 | O6: Done | P6: Athi | Q6: Nil | R6: Athi | S6: Nil | T6: https://dev.azure.com/heartlandschools/Activities/_git/Activities/pullrequest/48794 | U6: 46153 | AB6: NA | AC6: NA | AD6: Its not release canditate | AE6: Meets Expectation
A7: =ROW() - ROW(Table1456789101214161817222426283132333637394143454749515355575961636567[[#Headers],[S.No]]) - 1 -> 5 | B7: MSB Activities | C7: 46148 | D7: 46161 | E7: 26.6 Sprint S1 | F7: Allen | G7: 52940 | H7: Activities - Pendo - Move Pendo into global config prop settings so that it can be accessed prior to a tenant being selected | I7: Story Completed | J7: 1 | M7: 46143 | N7: 46146 | O7: Done | P7: Athi | Q7: Nil | R7: Athi | S7: Nil | T7: https://dev.azure.com/heartlandschools/Activities/_git/Activities/pullrequest/49068 | U7: 46157 | V7: 46157 | W7: Allen | X7: Nil | Y7: Andy | Z7: 46157 | AA7: Nil | AB7: NA | AC7: NA | AE7: Meets Expectation
A8: =ROW() - ROW(Table1456789101214161817222426283132333637394143454749515355575961636567[[#Headers],[S.No]]) - 1 -> 6 | B8: MSB Activities | C8: 46148 | D8: 46161 | E8: 26.6 Sprint S1 | F8: Ram | G8: 52700 | H8: Activities - Kaleida - Update Parent Registration Design (Forms) | I8: Story Being Tested | J8: 8 | K8: 4 | L8: 21 | M8: 46148 | N8: 46153 | O8: Done | P8: Athi | Q8: Nil | R8: Athi | S8: Nil | T8: https://dev.azure.com/heartlandschools/Activities/_git/Activities/pullrequest/48987 | U8: 46154 | V8: 46154 | W8: Allen | X8: Nil | Y8: Andy | Z8: 46154 | AA8: Nil | AB8: Approved | AC8: Approved | AE8: Meets Expectation
A9: =ROW() - ROW(Table1456789101214161817222426283132333637394143454749515355575961636567[[#Headers],[S.No]]) - 1 -> 7 | B9: MSB Activities | C9: 46148 | D9: 46161 | E9: 26.6 Sprint S1 | F9: Athi | G9: 52689 | H9: Activities - Kaleida - Update delete registration confirmation modals (Parent) | I9: Story Completed | J9: 2 | K9: 1 | L9: 4 | M9: 46154 | N9: 46154 | O9: Done | P9: Ram | Q9: Nil | R9: Ram | S9: Nil | T9: https://dev.azure.com/heartlandschools/Activities/_git/Activities/pullrequest/48997 | U9: 46154 | V9: 46154 | W9: Allen | X9: Nil | Y9: Ethan | Z9: 46154 | AA9: Nil | AB9: Approved | AC9: Approved | AE9: Meets Expectation
A10: =ROW() - ROW(Table1456789101214161817222426283132333637394143454749515355575961636567[[#Headers],[S.No]]) - 1 -> 8 | B10: MSB Activities | C10: 46148 | D10: 46161 | E10: 26.6 Sprint S1 | F10: Allen | G10: 27298 | H10: Activities - Admin - District Settings - Edit screen save validation when Provider ID blank is not working | I10: Defect Fixed | J10: 1 | K10: 1 | L10: 4 | M10: 46147 | N10: 46148 | O10: Done | P10: Athi | Q10: Nil | R10: Athi | S10: Nil | T10: https://dev.azure.com/heartlandschools/Activities/_git/Activities/pullrequest/48835 | U10: 46148 | V10: 46148 | W10: Allen | X10: Nil | Y10: Andy | AA10: What if both the password and providerid are blank, wouldn't this hide the validation about the password? We are going to circle back on this discussion - it seems like perhaps the actual solution here is to just remove the X (unselect) option from the dropdown and never allow this to be unset | AB10: NA | AC10: NA | AE10: Meets Expectation
A11: =ROW() - ROW(Table1456789101214161817222426283132333637394143454749515355575961636567[[#Headers],[S.No]]) - 1 -> 9 | B11: MSB Activities | C11: 46148 | D11: 46161 | E11: 26.6 Sprint S1 Stretch | F11: Allen | G11: 53123 | H11: Activities - Pendo - Registration Student Source Event Tagging | I11: Story Completed | J11: 2 | M11: 46148 | N11: 46153 | O11: Done | P11: Athi | Q11: Nil | R11: Athi | S11: Nil | T11: https://dev.azure.com/heartlandschools/Activities/_git/Activities/pullrequest/48834 | U11: 46156 | V11: 46156 | W11: Allen | X11: Nil | Y11: Andy | Z11: 46156 | AA11: Nil | AB11: NA | AC11: NA | AE11: Meets Expectation
A12: 10 | B12: MSB Activities | C12: 46148 | D12: 46161 | E12: 26.6 Sprint S1 Stretch | F12: Ram | G12: 52786 | H12: Activities - Parent - Place cursor in search box for District & Site selector | I12: Story Completed | J12: 2 | K12: 1 | L12: 4 | M12: 46155 | N12: 46155 | O12: Done | P12: Athi | Q12: Nil | R12: Athi | S12: Nil | T12: https://dev.azure.com/heartlandschools/Activities/_git/Activities/pullrequest/49049 | U12: 46156 | V12: 46156 | W12: Allen | X12: Nil | Y12: Ethan | Z12: 46156 | AA12: Nil | AB12: Approved | AC12: Approved | AE12: Meets Expectation
A13: =ROW() - ROW(Table1456789101214161817222426283132333637394143454749515355575961636567[[#Headers],[S.No]]) - 1 -> 11 | B13: MSB Activities | C13: 46148 | D13: 46161 | E13: 26.6 Sprint S1 Stretch | F13: Ram | G13: 52455 | H13: Activities - Parent - Update Default Relationship Field Selection to "Parent" | I13: Story Being Tested | J13: 3 | K13: 1 | L13: 6 | M13: 46154 | N13: 46154 | O13: Done | P13: Athi | Q13: Nil | R13: Athi | S13: Nil | T13: https://dev.azure.com/heartlandschools/Activities/_git/Activities/pullrequest/49050 | U13: 46156 | V13: 46156 | W13: Allen | X13: Nil | Y13: Ethan | Z13: 46156 | AA13: Nil | AB13: Approved | AC13: Approved | AE13: Meets Expectation
A14: =ROW() - ROW(Table1456789101214161817222426283132333637394143454749515355575961636567[[#Headers],[S.No]]) - 1 -> 12 | B14: MSB Activities | C14: 46148 | D14: 46161 | E14: 26.6 Sprint S1 Stretch | F14: Athi | G14: 27410 | H14: Activities - Reject Updated Registration modal is formatted poorly | I14: Defect Fixed | J14: 1 | K14: 1 | L14: 2 | M14: 46156 | N14: 46156 | O14: Done | P14: Ram | Q14: Nil | R14: Ram | S14: Nil | T14: https://dev.azure.com/heartlandschools/Activities/_git/Activities/pullrequest/49057 | U14: 46156 | V14: 46156 | W14: Allen | X14: Nil | Y14: Ethan | Z14: 46156 | AA14: Nil | AB14: NA | AC14: NA | AE14: Meets Expectation
A15: =ROW() - ROW(Table1456789101214161817222426283132333637394143454749515355575961636567[[#Headers],[S.No]]) - 1 -> 13 | B15: MSB Activities | C15: 46148 | D15: 46161 | E15: 26.6 Sprint S1 Stretch | F15: Athi | G15: 27416 | H15: Activities - Admin - Clear Discount Modal triggering when no discount exists | I15: Defect Fixed | J15: 1 | K15: 1 | L15: 4 | M15: 46157 | N15: 46157 | O15: Done | P15: Ram | Q15: Nil | R15: Ram | S15: Nil | T15: https://dev.azure.com/heartlandschools/Activities/_git/Activities/pullrequest/49082 | U15: 46157 | V15: 46157 | W15: Allen | X15: Nil | Y15: Ethan | Z15: 46157 | AA15: Nil | AB15: NA | AC15: NA | AE15: Meets Expectation
A16: =ROW() - ROW(Table1456789101214161817222426283132333637394143454749515355575961636567[[#Headers],[S.No]]) - 1 -> 14 | B16: MSB Activities | C16: 46148 | D16: 46161 | E16: 26.6 Sprint S1 Stretch | F16: Athi | G16: 52834 | H16: Activities - SYSTEM - TECH DEBT - Database - Investigate usage of LOCKs in DB queries [26.6] | I16: Story Being Developed | J16: 8 | K16: 0 | L16: 2 | M16: 46156 | AB16: NA | AC16: NA | AE16: Meets Expectation

Sheet 26.6 Sprint 1 - Defects 
A1: S.No | B1: Sprint # | C1: Story/Defect ID | D1: Parent Story | E1: Developer | F1: Issue Type | G1: Issue Description | H1: Root Cause Analysis | I1: Priority | J1: Defect Source | K1: Type | L1: Status | M1: Root Cause Category | N1: Comments | O1: Defect Raised
A2: 1 | B2: 26.6 Sprint S1 | C2: 27298 Activities - Admin - District Settings - Edit screen save validation when Provider ID blank is not working | E2: Allen | F2: Defect | G2: If you go into a district in Hss Staff - Districts and proceed to the edit screen, remove the MSB Provider Id (setting it to not set) then try to save. The button does nothing and there is no validation messaging. | I2: Minor | J2: Manual | K2: External | L2: Defect Fixed | M2: Existing_Issues | O2: Offshore PO - Kanchana
A3: 2 | B3: 26.6 Sprint S1 | C3: 27161 Activities - Admin - Pending Registration not showing updated weeks | E3: Athi | F3: Defect | G3: Defect: 1 - When using the weekly calendar. If you update the weeks on a pending registration and then navigate to that registration in Admin. We are not showing the update. Defect: 2 - I verified in the integration environment that in the parent, I scheduled only for one week (weekly calendar) and submitted my registration. When I viewed it as an admin on the pending/waitlist/View all/ Student enrollment pages, it showed all the weeks as selected. | I3: Major | J3: Manual | K3: External | L3: Defect Fixed | M3: Existing_Issues | O3: Offshore PO - Kanchana
A4: 3 | B4: 26.6 Sprint S1 | C4: 27358 Activities - Fake parent login is not working | E4: Allen | F4: Defect | G4: The fake parent login is not working | I4: Minor | J4: Manual | K4: Internal | L4: Defect Being Fixed | M4: Development | O4: Onshore Manager - Ethan
A5: 4 | B5: 26.6 Sprint S1 Stretch | C5: 27410 - Activities - Reject Updated Registration modal is formatted poorly | E5: Athi | F5: Defect | G5: The Reject Updated Registration modal formatting could be improved. | I5: Minor | J5: Manual | K5: External | L5: Defect Fixed | M5: Existing_Issues | O5: Onsite QA - Jeff
A6: 5 | B6: 26.6 Sprint S1 Stretch | C6: 27416 Activities - Admin - Clear Discount Modal triggering when no discount exists | E6: Athi | F6: Defect | G6: In admin, it looks like once a discount is set, and then removed. If you change the pricing of the enrollment plan, it triggers the "Clear Discounts" modal, even though a discount does not exist. Most likely we are not updating the state of the prop once a discount has been set. | I6: Significant | J6: Manual | K6: External | L6: Defect Fixed | M6: Existing_Issues | O6: Onsite QA - Jeff

Sheet 26.5 Sprint S4-Status
A1: S.No | B1: Application Name | C1: Sprint Start Date | D1: Sprint End Date | E1: Sprint | F1: Developer | G1: Story ID/Defect ID | H1: Description | I1: Status | J1: Estimated(sp) | K1: Actual(sp) | L1: Actual Hours Worklog | M1: Dev Start Date | N1: Dev End Date | O1: Unit testing | P1: Peer Tested By | Q1: Peer Tested Comments, if any | R1: Peer Reviewed By | S1: Peer Code Review Comments, if any | T1: PR Number/Link | U1: PR Created Date | V1: PR Approved Date | W1: Onsite Lead Code Review | X1: Onsite Lead Code Review Comments, if any | Y1: Client Code Review | Z1: PR Approved Date2 | AA1: Client Code Review Comments, if any | AB1: Internal PO -POV Comments | AC1: Client PO -POV Comments | AD1: Comments | AE1: Does this story Meet Expectations?
A2: =ROW() - ROW(Table14567891012141618172224262831323336373941434547495153555759616365[[#Headers],[S.No]]) - 1 -> 0
A3: =ROW() - ROW(Table14567891012141618172224262831323336373941434547495153555759616365[[#Headers],[S.No]]) - 1 -> 1 | B3: MSB Activities | C3: 46134 | D3: 46147 | E3: 26.5 Sprint S4 | F3: Athi | G3: 27238 | H3: Activities - Regression - Parent - Not able to see Screen "No Student Yet" when no student are available for a parent. | I3: Defect Fixed | J3: 0 | K3: 1 | L3: 3 | M3: 46132 | N3: 46133 | O3: Done | P3: Ram | Q3: Nil | R3: Ram | S3: Nil | T3: https://dev.azure.com/heartlandschools/Activities/_git/Activities/pullrequest/48541 | U3: 46133 | V3: 46134 | W3: Allen | X3: Nil | Y3: Andy | Z3: 46134 | AA3: Nil | AB3: NA | AC3: NA | AD3: Carried from last sprint - Testing effort only:This defect found on end of the sprint, its low priority, and development effort is completed in the last sprint. | AE3: Meets Expectation
A4: =ROW() - ROW(Table14567891012141618172224262831323336373941434547495153555759616365[[#Headers],[S.No]]) - 1 -> 2 | B4: MSB Activities | C4: 46134 | D4: 46147 | E4: 26.5 Sprint S4 | F4: Ram | G4: 27267 | H4: Activities - Regression - Student Card - The data-testid field is displaying the UID instead of the Student Name | I4: Defect Fixed | J4: 0 | K4: 1 | L4: 2 | M4: 46134 | N4: 46134 | O4: Done | P4: Athi | Q4: Nil | R4: Athi | S4: Nil | T4: https://dev.azure.com/heartlandschools/Activities/_git/Activities/pullrequest/48574 | U4: 46134 | V4: 46134 | W4: Allen | X4: Nil | Y4: Ethan | Z4: 46134 | AA4: Nil | AB4: NA | AC4: NA | AE4: Meets Expectation
A5: =ROW() - ROW(Table14567891012141618172224262831323336373941434547495153555759616365[[#Headers],[S.No]]) - 1 -> 3 | B5: MSB Activities | C5: 46134 | D5: 46147 | E5: 26.5 Sprint S4 | F5: Ram | G5: 27266 | H5: Activities - Regression - Site Selector - The data-testid field is displaying the UID instead of the Site Name | I5: Defect Fixed | J5: 0 | K5: 1 | L5: 2 | M5: 46134 | N5: 46134 | O5: Done | P5: Athi | Q5: Nil | R5: Athi | S5: Nil | T5: https://dev.azure.com/heartlandschools/Activities/_git/Activities/pullrequest/48573 | U5: 46134 | V5: 46134 | W5: Allen | X5: Nil | Y5: Ethan | Z5: 46134 | AA5: Nil | AB5: NA | AC5: NA | AE5: Meets Expectation
A6: =ROW() - ROW(Table14567891012141618172224262831323336373941434547495153555759616365[[#Headers],[S.No]]) - 1 -> 4 | B6: MSB Activities | C6: 46134 | D6: 46147 | E6: 26.5 Sprint S4 | F6: Ram | G6: 52882 | H6: Activities - Parent - Disable Next button when no eligible students | I6: Story Completed | J6: 2 | K6: 2 | L6: 2 | M6: 46129 | N6: 46132 | O6: Done | P6: Athi | Q6: Nil | R6: Athi | S6: Nil | T6: https://dev.azure.com/heartlandschools/Activities/_git/Activities/pullrequest/48583 | U6: 46134 | V6: 46134 | W6: Allen | X6: Nil | Y6: Ethan | Z6: 46134 | AA6: Nil | AB6: Approved | AC6: Approved | AE6: Meets Expectation
A7: =ROW() - ROW(Table14567891012141618172224262831323336373941434547495153555759616365[[#Headers],[S.No]]) - 1 -> 5 | B7: MSB Activities | C7: 46134 | D7: 46147 | E7: 26.5 Sprint S4 | F7: Athi | G7: 52883 | H7: Activities - Parent - Adjust registration status chip display [26.5?] | I7: Story Completed | J7: 2 | K7: 2 | L7: 2 | M7: 46128 | N7: 46132 | O7: Done | P7: Ram | Q7: Nil | R7: Ram | S7: Nil | T7: https://dev.azure.com/heartlandschools/Activities/_git/Activities/pullrequest/48579 | U7: 46134 | V7: 46134 | W7: Allen | X7: Nil | Y7: Ethan | Z7: 46134 | AA7: Nil | AB7: Approved | AC7: Approved | AE7: Meets Expectation
A8: =ROW() - ROW(Table14567891012141618172224262831323336373941434547495153555759616365[[#Headers],[S.No]]) - 1 -> 6 | B8: MSB Activities | C8: 46134 | D8: 46147 | E8: 26.5 Sprint S4 | F8: Allen | G8: 52939 | H8: Activities - Pendo - Registration Student Source Event Tagging (Discovery) | I8: Story Completed | J8: 5 | K8: 5 | L8: 5 | M8: 46134 | O8: NA | P8: NA | Q8: NA | R8: NA | S8: NA | T8: NA | U8: NA | V8: NA | W8: NA | X8: NA | Y8: NA | Z8: NA | AA8: NA | AB8: NA | AC8: NA | AD8: Its Discovery story | AE8: Meets Expectation
A9: =ROW() - ROW(Table14567891012141618172224262831323336373941434547495153555759616365[[#Headers],[S.No]]) - 1 -> 7 | B9: MSB Activities | C9: 46134 | D9: 46147 | E9: 26.5 Sprint S4 | F9: Athi | G9: 27272 | H9: Activities - REGRESSION - Admin - Missing breadcrumb link in Config Props - Add and Roles – Edit | I9: Defect Fixed | J9: 0 | K9: 1 | L9: 3 | M9: 46135 | N9: 46135 | O9: Done | P9: Ram | Q9: Nil | R9: Ram | S9: Nil | T9: https://dev.azure.com/heartlandschools/Activities/_git/Activities/pullrequest/48610 | U9: 46135 | V9: 46135 | W9: Allen | X9: Nil | Y9: Ethan | Z9: 46135 | AA9: Very minor, but this should be an "else if" | AB9: NA | AC9: NA | AD9: Minor suggestion in CRC | AE9: Meets Expectation
A10: =ROW() - ROW(Table14567891012141618172224262831323336373941434547495153555759616365[[#Headers],[S.No]]) - 1 -> 8 | B10: MSB Activities | C10: 46134 | D10: 46147 | E10: 26.5 Sprint S4 | F10: Athi | G10: 27306 | H10: Activities - Regression - Admin - Universal search is not filtering when we provide invalid date and Amount Field. | I10: Defect Fixed | J10: 0 | K10: 1 | L10: 3 | M10: 46140 | N10: 46140 | O10: Done | P10: Ram | Q10: Nil | R10: Ram | S10: Nil | T10: https://dev.azure.com/heartlandschools/Activities/_git/Activities/pullrequest/48689 | U10: 46142 | V10: 46143 | W10: Allen | X10: Nil | Y10: Andy | Z10: 46143 | AA10: Nil | AB10: NA | AC10: NA | AE10: Meets Expectation
A11: =ROW() - ROW(Table14567891012141618172224262831323336373941434547495153555759616365[[#Headers],[S.No]]) - 1 -> 9 | B11: MSB Activities | C11: 46134 | D11: 46147 | E11: 26.5 Sprint S4 | F11: Athi | G11: 27311 | H11: Activities - REGRESSION - Parent - Removed day still showing in parent after removing it from the schedule | I11: Defect Fixed | J11: 0 | K11: 1 | L11: 3 | M11: 46141 | N11: 46141 | O11: Done | P11: Ram | Q11: Nil | R11: Ram | S11: Nil | T11: https://dev.azure.com/heartlandschools/Activities/_git/Activities/pullrequest/48716 | U11: 46141 | V11: 46141 | W11: Allen | X11: Nil | Y11: Andy | Z11: 46141 | AA11: Nil | AB11: NA | AC11: NA | AE11: Meets Expectation
A12: 10 | B12: MSB Activities | C12: 46134 | D12: 46147 | E12: 26.5 Sprint S4 | F12: Ram | G12: 27308 | H12: Activities - Regression - Parent - Custom Field Email Validation is not working | I12: Defect Fixed | J12: 0 | K12: 1 | L12: 3 | M12: 46140 | N12: 46140 | O12: Done | P12: Athi | Q12: Nil | R12: Athi | S12: Nil | T12: https://dev.azure.com/heartlandschools/Activities/_git/Activities/pullrequest/48680 | U12: 46140 | V12: 46140 | W12: Allen | X12: Nil | Y12: Ethan | Z12: 46140 | AA12: Nil | AB12: Nil | AC12: Nil | AE12: Meets Expectation
A13: =ROW() - ROW(Table14567891012141618172224262831323336373941434547495153555759616365[[#Headers],[S.No]]) - 1 -> 11 | B13: MSB Activities | C13: 46134 | D13: 46147 | E13: 26.5 Sprint S4 | F13: Athi | G13: 27317 | H13: Activities - Regression - Parent - Incorrect display of Download & Print schedule data on Enrollments page card details | I13: Defect Fixed | J13: 0 | K13: 1 | L13: 3 | M13: 46142 | N13: 46142 | O13: Done | P13: Ram | Q13: Nil | R13: Ram | S13: Nil | T13: https://dev.azure.com/heartlandschools/Activities/_git/Activities/pullrequest/48772 | U13: 46142 | V13: 46143 | W13: Allen | X13: Nil | Y13: Andy | Z13: 46143 | AA13: Nil | AB13: NA | AC13: NA | AE13: Meets Expectation
A14: =ROW() - ROW(Table14567891012141618172224262831323336373941434547495153555759616365[[#Headers],[S.No]]) - 1 -> 12 | B14: MSB Activities | C14: 46134 | D14: 46147 | E14: 26.5 Sprint S4 | F14: Ram | G14: 27325 | H14: Activities - Regression - Parent - Page is not responding while changing the custom field Radio button values. | I14: Defect Fixed | J14: 0 | K14: 1 | L14: 4 | M14: 46142 | N14: 46142 | O14: Done | P14: Athi | Q14: Nil | R14: Athi | S14: Nil | T14: https://dev.azure.com/heartlandschools/Activities/_git/Activities/pullrequest/48768 | U14: 46142 | V14: 46142 | W14: Allen | X14: Nil | Y14: Andy | Z14: 46142 | AA14: Nil | AB14: NA | AC14: NA | AE14: Meets Expectation
A15: =ROW() - ROW(Table14567891012141618172224262831323336373941434547495153555759616365[[#Headers],[S.No]]) - 1 -> 13 | B15: MSB Activities | C15: 46134 | D15: 46147 | E15: 26.5 Sprint S4 Stretch | F15: Athi | G15: 52834 | H15: Activities - SYSTEM - TECH DEBT - Database - Investigate usage of LOCKs in DB queries [26.6] | I15: Story Being Developed | J15: 8 | K15: 1 | L15: 6 | M15: 46134 | N15: NA | O15: NA | P15: NA | Q15: NA | R15: NA | S15: NA | T15: NA | U15: NA | V15: NA | W15: NA | X15: NA | Y15: NA | Z15: NA | AA15: NA | AB15: NA | AC15: NA | AD15: Its Tech debt story | AE15: Meets Expectation
A19: =ROW() - ROW(Table14567891012141618172224262831323336373941434547495153555759616365[[#Headers],[S.No]]) - 1 -> 17
A20: =ROW() - ROW(Table14567891012141618172224262831323336373941434547495153555759616365[[#Headers],[S.No]]) - 1 -> 18

Sheet 26.5 Sprint 4 - Defects 
A1: S.No | B1: Sprint # | C1: Story/Defect ID | D1: Parent Story | E1: Developer | F1: Issue Type | G1: Issue Description | H1: Root Cause Analysis | I1: Priority | J1: Defect Source | K1: Type | L1: Status | M1: Root Cause Category | N1: Comments | O1: Defect Raised
A2: 1 | B2: 26.5 Sprint S4 | C2: Activities - Regression - Site Selector - The data-testid field is displaying the UID instead of the Site Name | E2: Ram | F2: Defect | G2: In the Site Selector, the data-testid field is displaying the UID instead of the Site Name | H2: Datatest Id renamed in the UI compenent which is used for automation test | I2: Minor | J2: Manual | K2: Internal | L2: Defect Fixed | M2: Existing_Issues | O2: Onshore - QA - Jeff
A3: 2 | B3: 26.5 Sprint S4 | C3: 27267 Activities - Regression - Student Card - The data-testid field is displaying the UID instead of the Student Name | E3: Ram | F3: Defect | G3: On the updated Student Cart, the data-testid field is displaying the UID instead of the Student Name | H3: Datatest Id renamed in the UI compenent which is used for automation test | I3: Minor | J3: Manual | K3: Internal | L3: Defect Fixed | M3: Existing_Issues | O3: Onshore - Manager - Ethan
A4: 3 | B4: 26.5 Sprint S4 | C4: 27272 Activities - REGRESSION - Admin - Missing breadcrumb link in Config Props - Add and Roles – Edit | E4: Athinarayanan | F4: Defect | G4: Missing breadcrumb link issue in Config Props Add and Roles – Edit Config Props > Add (Home> Heartland Staff ) Roles > Edit. (Home > Setup > Roles) | H4: This breadcrumb path is missed in the AC point. | I4: Minor | J4: Manual | K4: Internal | L4: Defect Fixed | M4: QA | O4: Ram - Offshore Developer
A5: 4 | B5: 26.5 Sprint S4 | C5: 27238 - Activities - Regression - Parent - Not able to see Screen "No Student Yet" when no student are available for a parent. | E5: Athinarayanan | F5: Defect | G5: Not able to see Screen "No Student Yet" when no student are available for a parent. | H5: Student count validation is missed | I5: Minor | J5: Manual | K5: Internal | L5: Defect Fixed | M5: Development | N5: Carried from last sprint - Testing effort only:This defect found on end of the sprint, its low priority, and development effort is completed in the last sprint. | O5: Athinarayanan - Offshore Developer
A6: 5 | B6: 26.5 Sprint S4 | C6: 27311 Activities - REGRESSION - Parent - Removed day still showing in parent after removing it from the schedule | E6: Athinarayanan | F6: Defect | G6: In parent with daily calendar on, if you put in that you will be attending everyday. Then deselect all of a specific day (remove Mondays by deselecting it). In the Schedules section it still shows Monday as being part of the schedule. This is occurring with updating an accepted registration as well. | H6: Model Validation is missed | I6: Minor | J6: Manual | K6: Internal | L6: Defect Fixed | M6: Development | N6: . | O6: Offshore QA - manjunath
A7: 6 | B7: 26.5 Sprint S4 | C7: 27308 Activities - Regression - Parent - Custom Field Email Validation is not working | E7: Ram | F7: Defect | G7: Custom Field Email Validation is not working Custom Field Email Validation is missing for students Info screen, Contacts screen and parent info Screen. | H7: Email validation for custom field is missed. | I7: Minor | J7: Manual | K7: Internal | L7: Defect Fixed | M7: Development | N7: . | O7: Offshore QA - manjunath
A8: 7 | B8: 26.5 Sprint S4 | C8: 27325 Activities - Regression - Parent - Page is not responding while changing the custom field Radio button values. | E8: Ram | F8: Defect | G8: Page is not responding while changing the Radio button values. This happens for Student info, parent Info and contacts info screen. | H8: Sync event handling which affected the performance of the page. | I8: Significant | J8: Manual | K8: Internal | L8: Defect Fixed | M8: Development | N8: . | O8: Offshore QA - manjunath
A9: 8 | B9: 26.5 Sprint S4 | C9: 27306 Activities - Regression - Admin - Purchases Universal search is not filtering when we provide invalid date and Amount Field | E9: Athinarayanan | F9: Defect | G9: Universal search is not filtering when we provide invalid date and Amount Field | H9: Invalid or edge case validation are missed in the query builder. | I9: Significant | J9: Manual | K9: Internal | L9: Defect Fixed | M9: Development | O9: Ram - Offshore Developer
A10: 9 | B10: 26.5 Sprint S4 | C10: 27317 Activities - Regression - Parent - Incorrect display of Download & Print schedule data on Enrollments page card details | F10: Defect | G10: Defect:1 Validation message persists after clearing To Date in Payment History Report In the Payment History Report, when a user enters a From Date later than the To Date (e.g., From Date: 05/02/2026, To Date: 04/28/2026), the system correctly displays a validation message indicating the invalid date range. However, after clearing the To Date field, the validation message continues to persist even though the input is now valid. This suggests that the validation logic is not being reset when the To Date field is cleared. Defect: 2: Incorrect display of Download and Print schedule data on Enrollments & Registration page card details On the Enrollments & Registration page, the enrollment card details section is showing incorrect data for the Download and Print schedule options. The information displayed does not match the actual schedule data, leading to inconsistencies between what is downloaded/printed and what is shown on the schedule page. | H10: Clearing error message was missed after proper date.Updated scheduled date are not printed in the sheet. | I10: Significant | J10: Manual | K10: Internal | L10: Defect Fixed | M10: Development | O10: Kanchana - Offshore PO

Sheet 26.5 Sprint S3-Status
A1: S.No | B1: Application Name | C1: Sprint Start Date | D1: Sprint End Date | E1: Sprint | F1: Developer | G1: Story ID/Defect ID | H1: Description | I1: Status | J1: Estimated(sp) | K1: Actual(sp) | L1: Actual Hours Worklog | M1: Dev Start Date | N1: Dev End Date | O1: Unit testing | P1: Peer Tested By | Q1: Peer Tested Comments, if any | R1: Peer Reviewed By | S1: Peer Code Review Comments, if any | T1: PR Number/Link | U1: PR Created Date | V1: PR Approved Date | W1: Onsite Lead Code Review | X1: Onsite Lead Code Review Comments, if any | Y1: Client Code Review | Z1: PR Approved Date2 | AA1: Client Code Review Comments, if any | AB1: Internal PO -POV Comments | AC1: Client PO -POV Comments | AD1: Comments | AE1: Does this story Meet Expectations?
A2: =ROW() - ROW(Table145678910121416181722242628313233363739414345474951535557596163[[#Headers],[S.No]]) - 1 -> 0
