Workbook

Sheet Dashboard-2025
A1: Current Sprint | B1: {=INDEX($B$2:$B$65,MATCH(1,(($D$2:$D$65 >=TODAY())*($C$2:$C$65<=TODAY())),0))} -> #N/A | C1: Current Sprint Sheet | D1: =CONCATENATE(B1,"-Status") -> #N/A | E1: Sprint Start Date | F1: =VLOOKUP($B$1,$B$1:$C$110,2) -> #N/A | G1: Sprint End Date | I1: =VLOOKUP($B$1,$B$1:$D$65,3) -> #N/A | J1: Application Name | K1: FOH Wave | L1: Users | M1: sabir.shaikh@relevantz.com;subbulakshmi.namasivayam@relevantz.com;vidhya.subramani@relevantz.com;balamurugan.kandasamy@relevantz.com | N1: Teams Name
A2: Sprint Type | B2: Sprint # | C2: Sprint Start Date | D2: Sprint End Date | E2: Assigned | F2: Completed | G2: Story points introduced/removed | H2: Sprint Summary | I2: Accomplishments | J2: Remarks | K2: Retro Points (Internal & External) | L2: Planned Leave | M2: Total Leave | N2: Data sanity Audit Status | O2: AuditDate
A3: =IF(AND($D$1>=C3,$D$1<=D3),"CurrentSprint","NA") -> #N/A | B3: 4.22 - Sprint 2 | C3: 45786 | D3: 45799 | E3: 30 | F3: 38 | G3: Introduced - 8 | I3: Adding new templates to Custom Reports, Tier Model, State Level EIG updates, and Admin View of Real Time Transactions updates. | J3: CRC Internal -- 1 CRC External -- 0 QA Defects -- 1 Escaped Defects -- 0 Stretch Story: 0 | K3: Internal: External:
A4: =IF(AND($D$1>=C4,$D$1<=D4),"CurrentSprint","NA") -> #N/A | B4: 4.22 - Sprint 3 | C4: 45800 | D4: 45813 | E4: 40 | F4: 37.75 | G4: Nil | I4: Cutom Report for Eligibility Student Listing | J4: CRC Internal -- 0 CRC External -- 0 QA Defects -- 0 Escaped Defects -- 0 Stretch Story: 3 | K4: Internal: External:
A5: =IF(AND($D$1>=C5,$D$1<=D5),"CurrentSprint","NA") -> #N/A | B5: 4.23 - Sprint 1 | C5: 45814 | D5: 45826 | E5: 10 | F5: 10 | G5: Introduced - 21 | J5: CRC Internal -- 2 CRC External -- 0 QA Defects -- 0 Escaped Defects -- 0 Stretch Story: 4 | K5: Internal: External:
A6: =IF(AND($D$1>=C6,$D$1<=D6),"CurrentSprint","NA") -> #N/A | B6: 4.23 - Sprint 2 | C6: 45827 | D6: 45841 | E6: 20 | F6: 20 | G6: Introduced - 16 | I6: Supplemental Programs Claim Report | J6: CRC Internal -- 1 CRC External -- 0 QA Defects -- 1 Escaped Defects -- 0 Stretch Story: 3 | K6: Internal: External:
A7: =IF(AND($D$1>=C7,$D$1<=D7),"CurrentSprint","NA") -> #N/A | B7: 4.23 - Sprint 3 | C7: 45842 | D7: 45855 | E7: 14 | F7: 14 | G7: Introduced-7 | I7: Custom Report for Transaction History, Modifications to Louisiana SFS-8C Report | J7: CRC Internal -- 4 CRC External -- 0 QA Defects -- 1 Escaped Defects -- 0 Stretch Story: 4 | K7: Internal: External: What went well: Successfully completed the assigned stories What didn't go well: Nil
A8: =IF(AND($D$1>=C8,$D$1<=D8),"CurrentSprint","NA") -> #N/A | B8: 4.23 - Sprint 4 | C8: 45856 | D8: 45869 | E8: 14 | F8: 16 | G8: Introduced - 17 | I8: Defect fixes and 4.23 Regression testing | J8: CRC Internal -- 2 CRC External -- 0 QA Defects -- 1 Escaped Defects -- 0 Stretch Story: 7 | K8: Internal: External: What went well: Successfully completed the Regression testing, Completed the assigned stories What didn't go well: Nil
A9: =IF(AND($D$1>=C9,$D$1<=D9),"CurrentSprint","NA") -> #N/A | B9: 4.24 - Sprint 1 | C9: 45870 | D9: 45883 | E9: 12 | F9: 15 | G9: Introduced - 15 | I9: Support for Credit Card in Additional Meal Programs for Reports,Delete functionality for User Custom Report | J9: CRC Internal -- 11 CRC External -- 0 QA Defects -- 1 Escaped Defects -- 0 Stretch Story: 6 | K9: Internal: External: What went well: Successfully completed the assigned stories What didn't go well: Nil
A10: =IF(AND($D$1>=C10,$D$1<=D10),"CurrentSprint","NA") -> #N/A | B10: 4.24 - Sprint 2 | C10: 45884 | D10: 45897 | E10: 10 | F10: 13 | G10: Introduced - 22 | I10: Dashboard feature for copy and enlarge wiidgets, implemented new datasource in custom report. | J10: CRC Internal -- 1 CRC External -- 0 QA Defects -- 1 Escaped Defects -- 0 Stretch Story: 5 | K10: Internal: External: What went well: Successfully completed the assigned stories. Successfully completed the dashboard related features. What didn't go well: Nil
A11: =IF(AND($D$1>=C11,$D$1<=D11),"CurrentSprint","NA") -> #N/A | B11: 4.24 - Sprint 3 | C11: 45898 | D11: 45911 | E11: 8 | F11: 18 | G11: Introduced - 28 | I11: New Template for Daily Sales Summary Report,Daily Sales By Serving Line Report,Dashboard UI Enhancement and Other Reports Improvements, Automation | J11: CRC Internal -- 1 CRC External -- 0 Peer Testing - 1 POV Comments - 4 QA Defects -- 1 Escaped Defects -- 0 Stretch Story: 7 | K11: Internal: External: What went well: Completed Forecast and lot more, Automation progress, Hosted platforms - SYSU, All schools back in session, Esclation down from previous years (Note: Esclations from coustomer support are handled by client developer Steve) What didn't go well: Lost Ying to BOH team Esclations
A12: =IF(AND($D$1>=C12,$D$1<=D12),"CurrentSprint","NA") -> #N/A | B12: 4.24 - Sprint 4 | C12: 45912 | D12: 45925 | E12: 14 | F12: 15 | G12: Introduced - 11 | I12: Defect fixes and 4.24 Regression testing | J12: "CRC Internal --0 CRC External -- 0 Peer Testing - 3 POV Comments - QA Defects -- 0 Escaped Defects -- 0 Stretch Story: 4" | K12: Internal: External: What went well: Offshore Completed regression and defects including testing, Completed Forecast and more, Defects fixed into releases What didn't go well: Esclations (Note: Esclations from coustomer support are handled by client developer Steve), Added items in last minute to include in release
A13: =IF(AND($D$1>=C13,$D$1<=D13),"CurrentSprint","NA") -> #N/A | B13: 4.25 - Sprint 1 | C13: 45926 | D13: 45939 | E13: 13 | F13: 13 | G13: Introduced - 16 | I13: Modifications to Operating Days, new filter for ‘Participation by’ to Standard Claim Report, and New Template to ‘Daily Sales By Serving Line Report’. | J13: CRC Internal -- 3 CRC External -- 0 Peer Testing - 2 POV Comments - 4 QA Defects -- 1 Escaped Defects -- 0 Stretch Story: 4 | K13: Internal: External: What went well: Completed more than Forecast , Esclations (not too bad this week), mike completed testing before PTO, Team completed rest of testing after Mike PTO What didn't go well: Apigee issue (platformops and apigee team)
A14: =IF(AND($D$1>=C14,$D$1<=D14),"CurrentSprint","NA") -> #N/A | B14: 4.25 - Sprint 2 | C14: 45940 | D14: 45953 | E14: 15 | F14: 21 | G14: Introduced - 18 | H14: New Dashboard Widgets, Ability to flip between Apigee & Existing endpoints, ‘Participation By’ filter to Supplemental Programs Claim Report, Tyler Munis Export Modifications, update to VA SNP-12 Report, Add Active Flag to Student Export Setup, and 4.24 Release Prep | I14: New Dashboard Widgets, ‘Participation By’ filter to Supplemental Programs Claim Report, Updating report format to meet Mosaic standards | J14: CRC Internal -- 0 CRC External -- 0 Peer Testing - 6 POV Comments - 6 QA Defects -- 1 Escaped Defects -- 0 Stretch Story: 6 | K14: Internal: External: What went well: Completed more than Forecast What didn't go well: NA
A15: =IF(AND($D$1>=C15,$D$1<=D15),"CurrentSprint","NA") -> #N/A | B15: 4.25 - Sprint 3 | C15: 45954 | D15: 45967 | E15: 12 | F15: 23 | G15: Introduced - 23 | H15: Adding a Student Debt Chart to the Dashboard, Replacing Master Serving Period with Serving Period Program, New ‘Group By School’ filter to Students w/out an Elig. Determination Report, DC Import Improvements, and NJ Master Eligibility List report Modifications | I15: Export 'User Created Custom Reports', 'User Assignments Report' to meet Mosaic Standard, Legacy imports are moved to Utilities | J15: CRC Internal -- 0 CRC External -- 0 Peer Testing - 1 POV Comments - 6 QA Defects -- 0 Escaped Defects -- 0 Stretch Story: 10 | K15: Internal: External: What went well: Releases, Exceeded Forecast What didn't go well: Esclations (Note: Esclations from coustomer support are handled by client developer Steve)
A16: =IF(AND($D$1>=C16,$D$1<=D16),"CurrentSprint","NA") -> #N/A | B16: 4.25 - Sprint 4 | C16: 45968 | D16: 45981 | E16: 10 | F16: 12 | G16: Introduced - 36 | H16: IL WINS Export Scheduler Task, Importing Custom Report Format, Added new data source to report designer | I16: IL WINS Export Scheduler Task, Importing Custom Report Format, NSS ID in Visual Report, Added new datasource to the Report designer | J16: CRC Internal -- 15 CRC External -- 1 Peer Testing - 3 POV Comments - 2 QA Defects -- 2 Escaped Defects -- 0 Stretch Story: 10 | K16: Internal: External: What went well: Hit Forecast, SNYK progress in stretch What didn't go well: CPS Release, Apigee work, MSB Endpoint Change.
A17: =IF(AND($D$1>=C17,$D$1<=D17),"CurrentSprint","NA") -> #N/A | B17: 4.25 - Sprint 5 | C17: 45982 | D17: 46009 | E17: 23 | F17: 37 | G17: Introduced - 37 | H17: New Templates for Custom Reports, New Data Sources for Report Designer, and 4.25 Regression Testing | I17: Completed 4.25 regression testing with defect fixes. | J17: CRC Internal -- 2 CRC External -- 0 QA Defects -- 2 Escaped Defects -- 0 Stretch Story: 8 Defects RC: 1. Calculation mismatch not captured in unit testing. 2. It is the data issue which occurred in other developer's DB. It is handled now. Internal CRC comments RC: 1. Missed to ensure SQL script file naming standards 2. Misunderstood the acceptance criteria | K17: Internal: External: What went well: Insane no.of stories completed(Sp's), started using Browser Stack for automation. What didn't go well: Escalations, MSB Endpoint Change.

Sheet Defect-template
A1: S.No | B1: Sprint # | C1: Story/Defect ID | D1: Parent Story | E1: Developer | F1: Issue Type | G1: Issue Description | H1: Priority | I1: Defect Source | J1: Type | K1: Status | L1: Root Cause Category | M1: Comments

Sheet Dashboard
A1: Current Sprint | B1: {=INDEX($B$2:$B$48,MATCH(1,(($D$2:$D$48 >=TODAY())*($C$2:$C$48<=TODAY())),0))} -> 26.07 Sprint 1 | C1: Current Sprint Sheet | D1: =CONCATENATE(B1,"-Status") -> 26.07 Sprint 1-Status | E1: Sprint Start Date | F1: =VLOOKUP($B$1,$B$1:$C$120,2) -> 46136 | G1: Sprint End Date | H1: =VLOOKUP($B$1,$B$1:$D$120,3) -> 46163 | I1: Application Name | J1: FOH Wave | K1: Users | L1: sabir.shaikh@relevantz.com;subbulakshmi.namasivayam@relevantz.com;vidhya.subramani@relevantz.com;balamurugan.kandasamy@relevantz.com | M1: Teams Name(GP - FOH Acceleration Initiative) | N1: 19:e340939441a74ca5938ca3ad602ee553@thread.v2
A2: Sprint Type | B2: Sprint # | C2: Sprint Start Date | D2: Sprint End Date | E2: Assigned | F2: Completed | G2: Story points introduced/removed | H2: Sprint Summary | I2: Accomplishments | J2: Remarks | K2: Retro Points (Internal & External) | L2: Planned Leaves | M2: Total Leaves | N2: Data sanity Audit Status | O2: AuditDate | P2: Backlog Health
A3: =IF(AND($D$1>=C3,$D$1<=D3),"CurrentSprint","NA") -> NA | B3: 26.1 - Sprint 1 | C3: 46010 | D3: 46037 | E3: 27 | F3: 32 | G3: Introduced - 30 | H3: Support for Multiple Languages in SL, Automation, Meal Count Entry Audit Report, Feature flag changes | I3: Completed Support for Multiple Languages in SL, Automation, Meal Count Entry Audit Report, Feature flag changes | J3: CRC Internal -- 24 CRC External -- 2 QA Defects -- 4 Escaped Defects -- 0 Stretch Story: 9 Defects RC: 1. Missed UI validation for the textbox. 2. Missed to handle the scenario of enable/disable Language feature flag. 3. Missed to test around the UI changes 4. Missed to check Parent table column's lenght and Language tables column's length Internal CRC comments RC: 1. Missed UI validations 2. Missed SQL script file standards 3. Missed to ensure date format 4. Not keeping common table name in SQL script 5. Some implicit stuff needs to be incorporated as part of the requirement which I'm not aware of 6. I missed to clean up or refactor some portion of the SQL code | K3: What went well: Completed the forecast and almost the same in the stretch. 2. Holidays. 3. 502 gateway Apigee issues solving (prod) What didn't go well: 365 migration, MSB from www to etransfer issue.
A4: =IF(AND($D$1>=C4,$D$1<=D4),"CurrentSprint","NA") -> NA | B4: 26.1 - Sprint 2 | C4: 46038 | D4: 46051 | E4: 17 | F4: 17 | G4: Introduced - 0 | H4: Updates to Meal Report and User Report, Mosaic BOH Knowledge transfer | I4: Completed the Mosaic Standards for User Reports and Meals Reports, Mosaic BOH Knowledge transfer | J4: CRC Internal -- 0 CRC External --0 QA Defects -- 1 Escaped Defects -- 0 Stretch Story: 0 Defects RC: 1. Pre existing UI design which was there originally. PO wanted to fix it as part of this story hence it was fixed. Internal CRC comments RC: None | K4: Internal: External: What went well: Completed commit and stretch items. 2. 4.24 Hot fix/4.25 Beta 3. BOH KT What didn't go well: 1. Vending QA, 2. Missing App switcher script in 4.25 Beta 3. App switcher button is not always working. Recieved appretiaton from QA during retro that offshore helped to close the testing stories during the sprint end.
A5: =IF(AND($D$1>=C5,$D$1<=D5),"CurrentSprint","NA") -> NA | B5: 26.1 - Sprint 3 | C5: 46052 | D5: 46065 | E5: 5 | F5: 16 | G5: Introduced - 30 | H5: Modified Prepay Report to Mosaic Standard, Defect Fixes, Hide Tier Feature from UI BOH Reverse KT, Automation | I5: Completed the Prepay Report to meet Mosaic Standard, BOH Reverse KT | J5: CRC Internal -- 0 Peer testing - 1 CRC External -- 0 QA Defects -- 2 Escaped Defects -- 0 POV Comments - 5 Stretch Story: 13 CRC RC: Nil Defects RC: 1. css styling not handled and so improper visual spacing between UI components occured 2. Missed to show proper version format | K5: "Internal: External: What went well: 1. Exceeded the forcast story points. 2. 4.25 release. What didn't go well: 1. Escalations, 2. 4.25 rused out(App switcher not working), 3. Dashboard issues." | L5: 0 | M5: 1
A6: =IF(AND($D$1>=C6,$D$1<=D6),"CurrentSprint","NA") -> NA | B6: 26.1 - Sprint 4 | C6: 46066 | D6: 46079 | E6: 2 | F6: 4 | G6: Introduced - 26 | H6: Add New Security page for Report Designer, Edit Report button to the Custom Reports UI, Automation | I6: Completed the Report Designer feature in Security Page | J6: CRC Internal -- 0 Peer testing - 0 CRC External -- 0 QA Defects -- 0 Escaped Defects -- 0 POV Comments - 0 Stretch Story: 4 CRC RC: Nil Defects RC: Nil | K6: Internal: External: What went well: 1. Offshore work on regression, 2. Hosted Test environment(Mike getting builds up) What didn't go well: 1. SQL cypher(Not working with .460) | L6: 1 | M6: 5
A7: =IF(AND($D$1>=C7,$D$1<=D7),"CurrentSprint","NA") -> NA | B7: 26.05 Sprint 1 | C7: 46080 | D7: 46093 | E7: 6 | F7: 8 | G7: Introduced - 20 | H7: User Tasks Maintenance and Setup, Automation | I7: Added User Tasks Maintenance and Setup screen, Automation | J7: CRC Internal -- 5 Peer testing - 3 CRC External -- 0 QA Defects -- 15 Escaped Defects -- 0 POV Comments - 6 Stretch Story: 4 CRC RC: 1. Missed to follow localization support (2) 2. Missed to follow exsiting coding standards (1) 3. unwanted code (1) 4. returning entity directly (1) Defects RC: 1. UI validations should be added properly (4) 2. UI design issues (8) 3. Data issue (3) | K7: Internal: External: What went well: 1. Exceeded commit, 2. SQLCypher progress, 3. Regression completed on time | L7: 3 | M7: 5
A8: =IF(AND($D$1>=C8,$D$1<=D8),"CurrentSprint","NA") -> NA | B8: 26.05 Sprint 2 | C8: 46094 | D8: 46107 | E8: 13 | F8: 13 | G8: Introduced - 27 | H8: User Assignment in User Task, Mosaic BOH - Transfers - Bulk Replace, Automation | I8: User Assignment in User Task, Mosaic BOH - Transfers - Bulk Replace, Add, Delete | J8: "CRC Internal -- 1 Peer testing - 4 CRC External -- 0 QA Defects -- 3 Escaped Defects -- 0 POV Comments - 11 Stretch Story: 6 CRC RC: 1. Missed to remove the unwanted code Defects RC: 1. UI design issues 2. Backend validation did not match the UI validation. (2) POV RC: Cosmetic changes (4) Sugeestions (3) Data issue (2) | K8: Internal: External: What went well: 1. 26.1 Release 2. Exceeded commit What didn't go well: Apigee & WAF issues | L8: 3 | M8: 4.5
A9: =IF(AND($D$1>=C9,$D$1<=D9),"CurrentSprint","NA") -> NA | B9: 26.05 Sprint 3 | C9: 46108 | D9: 46121 | E9: 20 | F9: 12 | G9: Introduced - 16 | H9: Review Task in User Task,Bidding - Allow vendors to indicate "No Response",ER Improve the Search functionality,Automation | I9: Review Task in User Task,Bidding - Allow vendors to indicate "No Response",ER Improve the Search functionality | J9: "CRC Internal -- 0 Peer testing - 1 CRC External -- 0 QA Defects -- 4 Escaped Defects -- 0 POV Comments - 3 Stretch Story: 2 CRC RC: NIL Defects RC: 1. UI design issues 2. Add more than 40 user then it gives an error in QA envirornment POV RC: Missed adding logic for bottom-line bidding and checkbox visibility control (2) Data issue (2) Missed to save the value of checkebox | K9: What went well: 1. Exceeded Commit 2. Migration Work 3. Multi Language on POS 4. Offshore Support on QA 5. Defect fixes for 26.1 What didn't go so well? 1. AG's workable | L9: 2 | M9: 2
A10: =IF(AND($D$1>=C10,$D$1<=D10),"CurrentSprint","NA") -> NA | B10: 26.05 Sprint 4 | C10: 46122 | D10: 46135 | E10: 9 | F10: 20 | G10: Introduced - 40 | H10: Review Task in User Task, Ingredients - Search Functionality, 26.5 Regression Testing, Bidding | I10: Completed 26.5 Regression Testing for Setup, User Tasks for Review Task, Ingredients - Search Functionality, Bidding Issues, Transfers - Bulk Add - UI | J10: CRC Internal -- 0 Peer testing - 0 CRC External -- 0 QA Defects -- 0 Escaped Defects -- 0 POV Comments - 0 Stretch Story: 5 CRC RC: Nil Defects RC: Nil POV RC: Nil | K10: What went well: 1. Completed Regression stories assigned in the sprint 2. Fixed all the regression defects 3. No review comments What didn't go well: Nil | L10: 2 | M10: 2
A11: =IF(AND($D$1>=C11,$D$1<=D11),"CurrentSprint","NA") -> NA | B11: 26.07 Sprint 1 | C11: 46136 | D11: 46163

Sheet 26.07 Sprint 1-Status
A1: S.No | B1: Application Name | C1: Sprint Start Date | D1: Sprint End Date | E1: Sprint | F1: Developer/Tester | G1: Story ID/Defect ID | H1: Description | I1: Story Being Developed | J1: Estimated(hrs/sp) | K1: Actual(hrs/sp) | L1: Actual Worklog (Hours) | M1: Dev Start Date | N1: Dev End Date | O1: Unit testing | P1: Peer Tested By | Q1: Peer Tested Comments, if any | R1: Peer Reviewed By | S1: Peer Code Review Comments, if any | T1: PR Number/Link | U1: PR Created Date | V1: PR Approved Date | W1: Onsite Lead Code Review | X1: Code Review Comments, if any | Y1: Client Code Review | Z1: Approved Date | AA1: Code Review Comments, if any2 | AB1: Internal PO -POV Comments | AC1: Client PO -POV Comments | AD1: Comments | AE1: Does this story meet expectations?
A2: 1 | B2: ='Dashboard-2025'!$K$1 -> FOH Wave | C2: 46136 | D2: 46163 | E2: 26.07 Sprint 1 | F2: Balamurugan | G2: 52062 | H2: [Wave]Mosaic BOH - Transfers - Bulk Add (2) - UI Only | I2: Story Being Tested | J2: 8 | K2: 7.5 | L2: 30 | M2: 46142 | N2: 46149 | O2: Balamurugan | P2: Rajiv Gandhi Sugumaran | Q2: NA | R2: Rajiv Gandhi Sugumaran | S2: NA | T2: 48943 | U2: 46150 | V2: 46154 | W2: Charles | X2: NA | Y2: NA | Z2: NA | AA2: NA | AB2: NA | AC2: NA
A3: 2 | B3: FOH Wave | C3: 46136 | D3: 46163 | E3: 26.07 Sprint 1 | F3: Sabir | G3: 47770 | H3: [WAVE] Mosaic BOH - (7) User Task List - End User UI | I3: Story Peer Review | J3: 8 | K3: 7.5 | L3: 30 | M3: 46136 | N3: 46149 | O3: Sabir | P3: Krupa Bhatkar | R3: Krupa Bhatkar | T3: 49014 | U3: 46154
A4: 3 | B4: FOH Wave | C4: 46136 | D4: 46163 | E4: 26.07 Sprint 1 | F4: Balamurugan | G4: 52178 | H4: [Wave]Mosaic BOH - Transfers - Bulk Add (2) - Data Retrieval | I4: Story Being Tested | J4: 8 | K4: 7.5 | L4: 30 | M4: 46136 | N4: 46149 | O4: Balamurugan | P4: Rajiv Gandhi Sugumaran | Q4: NA | R4: Rajiv Gandhi Sugumaran | S4: NA | T4: 48943 | U4: 46150 | V4: 46154 | W4: Charles | X4: NA | Y4: NA | Z4: NA | AA4: NA | AB4: NA | AC4: NA
A5: 4 | B5: FOH Wave | C5: 46136 | D5: 46163 | E5: 26.07 Sprint 1 | F5: Subbulakshmi | G5: 52915 | H5: Add an 'Aramark Financial Export' Scheduler Task Step | I5: Story Completed | J5: 2 | K5: 1 | L5: 4 | M5: 46139 | N5: 46155 | O5: NA | P5: NA | Q5: NA | R5: NA | S5: NA | T5: NA | U5: NA | V5: NA | W5: NA | X5: NA | Y5: NA | Z5: NA | AA5: NA | AB5: NA | AC5: NA | AD5: NA | AE5: NA
A6: 5 | B6: FOH Wave | C6: 46136 | D6: 46163 | E6: 26.07 Sprint 1 | F6: Subbulakshmi | G6: 52827 | H6: Update Federal IEGs (2026-27) | I6: Story Completed | J6: 1 | K6: 1 | L6: 4 | M6: 46140 | N6: 46140 | O6: NA | P6: NA | Q6: NA | R6: NA | S6: NA | T6: NA | U6: NA | V6: NA | W6: NA | X6: NA | Y6: NA | Z6: NA | AA6: NA | AB6: NA | AC6: NA | AD6: NA | AE6: NA
A7: 6 | B7: FOH Wave | C7: 46136 | D7: 46163 | E7: 26.07 Sprint 1 Stretch | F7: Pradeepa | G7: 47412 | H7: [WAVE] Mosaic BOH - Vendor Invoice Management - Create new Vendor Invoice Import Template 1 | I7: Story Being Developed | J7: 8 | K7: 12 | L7: 48 | M7: 46140
A8: 7 | B8: FOH Wave | C8: 46136 | D8: 46163 | E8: 26.07 Sprint 1 | F8: Subbulakshmi | G8: 52256 | H8: Open Previous Day Maintenance - Add Multiselect Site & Convert Screen to Vega | I8: Story Being Tested | J8: 1 | K8: 1 | L8: 4 | M8: 46141 | AD8: Need to test in Hosted Environment
A9: 8 | B9: FOH Wave | C9: 46136 | D9: 46163 | E9: 26.07 Sprint 1 Stretch | F9: Subbulakshmi | G9: 53098 | H9: MFOH [BAU] - Automation (46670) | I9: Story Being Developed | J9: 2 | K9: 2 | L9: 8 | M9: 46142
A10: 9 | B10: FOH Wave | C10: 46136 | D10: 46163 | E10: 26.07 Sprint 1 Stretch | F10: Sabir | G10: 29833 | H10: [WAVE] Mosaic BOH - Recipes - Search for Recipes that Contain or Do Not Contain Specified Allergens (CPS C0030) | I10: Story Being Developed | J10: 8 | K10: 7.5 | L10: 30 | M10: 46147
A11: 10 | B11: FOH Wave | C11: 46136 | D11: 46163 | E11: 26.07 Sprint 1 Stretch | F11: Subbulakshmi | G11: 53138 | H11: MFOH - Automation (51180) | I11: Story Completed | J11: 2 | K11: 2 | L11: 8 | M11: 46147 | N11: 46147 | O11: Subbulakshmi | P11: NA | Q11: NA | R11: NA | S11: NA | T11: 48897 | U11: 05/072026 | V11: 46147 | W11: NA | X11: NA | Y11: Steve | Z11: NA | AA11: NA | AB11: NA | AC11: NA | AD11: NA | AE11: NA
A12: 11 | B12: FOH Wave | C12: 46136 | D12: 46163 | E12: 26.07 Sprint 1 Stretch | F12: Balamurugan | G12: 45251 | H12: Mosaic BOH - Vendors - Add a setting to make invoice # mandatory on receiving orders | I12: Story Peer Review | J12: 5 | K12: 4.5 | L12: 18 | M12: 46150 | N12: 46155 | O12: Balamurugan | P12: Rajiv Gandhi Sugumaran | Q12: 1. Add the below script in Script.PostDeployment1.Sql - A script for adding a new column has been included in PostDeployment1.sql. | R12: Rajiv Gandhi Sugumaran | S12: NA | T12: 49027 | U12: 05/132026 | AB12: NA | AC12: NA
A13: 12 | B13: FOH Wave | C13: 46136 | D13: 46163 | E13: 26.07 Sprint 1 Stretch | F13: Subbulakshmi | G13: 53172 | H13: MFOH [WAVE] - Automation (51785) | I13: Story Completed | J13: 1 | K13: 1 | L13: 4 | M13: 46154 | N13: 46155 | O13: Subbulakshmi | P13: NA | Q13: NA | R13: NA | S13: NA | T13: 49052 | U13: 46156 | V13: 46156 | W13: NA | X13: NA | Y13: Ying | Z13: NA | AA13: NA | AB13: NA | AC13: NA | AD13: NA | AE13: NA
A14: 13 | B14: FOH Wave | C14: 46136 | D14: 46163 | E14: 26.07 Sprint 1 Stretch | F14: Sabir | G14: 52731 | H14: [WAVE] Mosaic BOH - Ingredients - Contains no known Allergens impacts | I14: Story Being Developed | J14: 8 | K14: 3 | L14: 12 | M14: 46155
A15: 14 | B15: FOH Wave | C15: 46136 | D15: 46163 | E15: 26.07 Sprint 1 Stretch | F15: Balamurugan | G15: 52146 | H15: Mosaic BOH - Transfers - Bulk Remove Item (3) | I15: Story Approved | J15: 13 | M15: 46155

Sheet 26.07 Sprint 1-Defect
A1: S.No | B1: Sprint # | C1: Story/Defect ID | D1: Parent Story | E1: Developer | F1: Issue Type | G1: Issue Description | H1: Priority | I1: Defect Source | J1: Type | K1: Status | L1: Dev Start Date | M1: Dev End Date | N1: Root Cause Category | O1: Comments
B2: 26.07 Sprint 1 | C2: 52256 | D2: 52256 | E2: Venkatesan | F2: Bounceback/Sub-Defect | G2: Schools listed based on School Group (1-All Schools), but School Group is not available in Open Previous day Maintenance screen. | H2: Significant | I2: Manual | J2: Internal | K2: Story Being Developed | L2: 46141 | N2: Data Issue
B3: 26.07 Sprint 1 | C3: 52062 | D3: 52062 | E3: Balamurugan | F3: Bounceback/Sub-Defect | G3: 1. Asterisk symbol is missing in Sending Site Field 2. If I click on Find and select a product, then reset and cancel it, the Products popup appears again. | H3: Minor | I3: Manual | J3: Internal | K3: Story Being Developed | L3: 46156 | N3: Design Issue

Sheet 26.05 Sprint 4-Status
A1: S.No | B1: Application Name | C1: Sprint Start Date | D1: Sprint End Date | E1: Sprint | F1: Developer/Tester | G1: Story ID/Defect ID | H1: Description | I1: Story Being Tested | J1: Estimated(hrs/sp) | K1: Actual(hrs/sp) | L1: Actual Worklog (Hours) | M1: Dev Start Date | N1: Dev End Date | O1: Unit testing | P1: Peer Tested By | Q1: Peer Tested Comments, if any | R1: Peer Reviewed By | S1: Peer Code Review Comments, if any | T1: PR Number/Link | U1: PR Created Date | V1: PR Approved Date | W1: Onsite Lead Code Review | X1: Code Review Comments, if any | Y1: Client Code Review | Z1: Approved Date | AA1: Code Review Comments, if any2 | AB1: Internal PO -POV Comments | AC1: Client PO -POV Comments | AD1: Comments | AE1: Does this story meet expectations?
A2: 1 | B2: FOH Wave | C2: 46122 | D2: 46135 | E2: 26.05 Sprint 4 | F2: Subbulakshmi | G2: 51845 | H2: [WAVE] Mosaic BOH - (6) User Tasks - Review Task Setup | I2: Story Completed | J2: 1 | K2: 1 | L2: 4 | M2: 46122 | N2: 46125 | O2: NA | P2: NA | Q2: NA | R2: NA | S2: NA | T2: NA | U2: NA | V2: NA | W2: NA | X2: NA | Y2: NA | Z2: NA | AA2: NA | AB2: NA | AC2: NA | AD2: NA | AE2: NA
A3: 2 | B3: FOH Wave | C3: 46122 | D3: 46135 | E3: 26.05 Sprint 4 | F3: Subbulakshmi | G3: 52797 | H3: Mosaic - FOH 26.5(Regression) - Setup | I3: Story Completed | J3: 8 | K3: 5.75 | L3: 23 | M3: 46125 | N3: 46129 | O3: NA | P3: NA | Q3: NA | R3: NA | S3: NA | T3: NA | U3: NA | V3: NA | W3: NA | X3: NA | Y3: NA | Z3: NA | AA3: NA | AB3: NA | AC3: NA | AD3: NA | AE3: NA
A4: 3 | B4: ='Dashboard-2025'!$K$1 -> FOH Wave | C4: 46122 | D4: 46135 | E4: 26.05 Sprint 4 Stretch | F4: Balamurugan | G4: 52062 | H4: [Wave]Mosaic BOH - Transfers - Bulk Add (2) - UI Only | I4: Story Being Developed | J4: 8 | K4: =Table245689102121314111617111819202115222324252627282930313233343536[[#This Row],[Actual Worklog (Hours)]] / 4 -> 6 | L4: 24 | M4: 46122 | N4: NA | O4: NA | P4: NA | Q4: NA | R4: NA | S4: NA | T4: NA | U4: NA | V4: NA | W4: NA | X4: NA | Y4: NA | Z4: NA | AA4: NA | AB4: NA | AC4: NA | AD4: NA | AE4: NA
A5: 4 | B5: ='Dashboard-2025'!$K$1 -> FOH Wave | C5: 46122 | D5: 46135 | E5: 26.05 Sprint 4 Stretch | F5: Sabir | G5: 52044 | H5: [WAVE] Mosaic BOH - Ingredients - Search for Ingredients that Do Not Contain Specified Allergens | I5: Story Completed | J5: 8 | K5: 4 | L5: 16 | M5: 46122 | N5: 46127 | O5: Sabir | P5: Rajiv | Q5: NA | R5: Rajiv | S5: NA | T5: 48420 | U5: 46127 | V5: 46129 | W5: Charles | X5: NA | Y5: NA | Z5: 46129 | AA5: NA | AB5: NA | AC5: NA | AD5: NA | AE5: meet expectation
A6: 5 | B6: FOH Wave | C6: 46122 | D6: 46135 | E6: 26.05 Sprint 4 Stretch | F6: Balamurugan | G6: 27176 | H6: MFOH - BOH WAVE - Fix the issues in bidding that showed up from the changes done in 52172 | I6: Defect Fixed | J6: 3 | K6: 3 | L6: 12 | M6: 46125 | N6: 46129 | O6: Balamurugan | P6: NA | Q6: NA | R6: NA | S6: NA | T6: 48489 | U6: 46129 | V6: 46132 | W6: Charles | X6: NA | Y6: NA | Z6: NA | AA6: NA | AB6: NA | AC6: NA | AD6: NA | AE6: NA
A7: 6 | B7: FOH Wave | C7: 46122 | D7: 46135 | E7: 26.05 Sprint 4 Stretch | F7: Sabir | G7: 47770 | H7: [WAVE] Mosaic BOH - (7) User Task List - End User UI | I7: Story Being Developed | J7: 13 | K7: 5 | L7: 20 | M7: 46128 | N7: NA | O7: NA | P7: NA | Q7: NA | R7: NA | S7: NA | T7: NA | U7: NA | V7: NA | W7: NA | X7: NA | Y7: NA | Z7: NA | AA7: NA | AB7: NA | AC7: NA | AD7: NA | AE7: NA
A8: 7 | B8: FOH Wave | C8: 46122 | D8: 46135 | E8: 26.05 Sprint 4 Stretch | F8: Balamurugan | G8: 52178 | H8: [Wave]Mosaic BOH - Transfers - Bulk Add (2) - Data Retrieval | I8: Story Being Developed | J8: 8 | K8: 4.5 | L8: 18 | M8: 46133 | N8: NA | O8: NA | P8: NA | Q8: NA | R8: NA | S8: NA | T8: NA | U8: NA | V8: NA | W8: NA | X8: NA | Y8: NA | Z8: NA | AA8: NA | AB8: NA | AC8: NA | AD8: NA | AE8: NA

Sheet 26.05 Sprint 4-Defect
A1: S.No | B1: Sprint # | C1: Story/Defect ID | D1: Parent Story | E1: Developer | F1: Issue Type | G1: Issue Description | H1: Priority | I1: Defect Source | J1: Type | K1: Status | L1: Dev Start Date | M1: Dev End Date | N1: Root Cause Category | O1: Comments

Sheet 26.5 - Sprint 3-Status
A1: S.No | B1: Application Name | C1: Sprint Start Date | D1: Sprint End Date | E1: Sprint | F1: Developer/Tester | G1: Story ID/Defect ID | H1: Description | I1: Story Being Tested | J1: Estimated(hrs/sp) | K1: Actual(hrs/sp) | L1: Actual Worklog (Hours) | M1: Dev Start Date | N1: Dev End Date | O1: Unit testing | P1: Peer Tested By | Q1: Peer Tested Comments, if any | R1: Peer Reviewed By | S1: Peer Code Review Comments, if any | T1: PR Number/Link | U1: PR Created Date | V1: PR Approved Date | W1: Onsite Lead Code Review | X1: Code Review Comments, if any | Y1: Client Code Review | Z1: Approved Date | AA1: Code Review Comments, if any2 | AB1: Internal PO -POV Comments | AC1: Client PO -POV Comments | AD1: Comments | AE1: Does this story meet expectations?
A2: 1 | B2: FOH Wave | C2: 46108 | D2: 46121 | E2: 26.5 - Sprint 3 | F2: Subbulakshmi | G2: 26993 | H2: [Wave]Mosaic BOH - Fix the alignment issues with the User Tasks List Search Screen | I2: Defect Fixed | J2: 1 | K2: =Table2456891021213141116171118192021152223242526272829303132333435[[#This Row],[Actual Worklog (Hours)]] / 4 -> 0.5 | L2: 2 | M2: 46108 | N2: 46118 | O2: NA | P2: NA | Q2: NA | R2: NA | S2: NA | T2: NA | U2: NA | V2: NA | W2: NA | X2: NA | Y2: NA | Z2: NA | AA2: NA | AB2: NA | AC2: NA | AD2: NA | AE2: NA
A3: 2 | B3: FOH Wave | C3: 46108 | D3: 46121 | E3: 26.5 - Sprint 3 | F3: Subbulakshmi | G3: 52329 | H3: MFOH - Automation - Kaleida changes update to the Setup - Annual Setup - Nondiscrimination Statement | I3: Story Completed | J3: 1 | K3: =Table2456891021213141116171118192021152223242526272829303132333435[[#This Row],[Actual Worklog (Hours)]] / 4 -> 1 | L3: 4 | M3: 46108 | N3: 46112 | O3: Subbulakshmi | P3: NA | Q3: NA | R3: NA | S3: NA | T3: 48145 | U3: 46112 | V3: 46112 | W3: NA | X3: NA | Y3: Steve | Z3: 46112 | AA3: NA | AB3: NA | AC3: NA | AD3: NA | AE3: NA
A4: 3 | B4: FOH Wave | C4: 46108 | D4: 46121 | E4: 26.5 - Sprint 3 | F4: Sabir | G4: 43501 | H4: [WAVE] Mosaic BOH - ER - Improve the Search functionality | I4: Story Completed | J4: 1 | K4: =Table2456891021213141116171118192021152223242526272829303132333435[[#This Row],[Actual Worklog (Hours)]] / 4 -> 0 | M4: 46108 | N4: 46108 | O4: Sabir | P4: Deepika | Q4: NA | R4: Deepika | S4: NA | T4: 48014 | U4: 46112 | V4: 46112 | W4: Charles | X4: NA | Y4: NA | Z4: 46112 | AA4: NA | AB4: NA | AC4: NA | AD4: NA | AE4: meet expectation
A5: 4 | B5: FOH Wave | C5: 46108 | D5: 46121 | E5: 26.5 - Sprint 3 | F5: Balamurugan | G5: 52172 | H5: [WAVE] Mosaic BOH - Bidding - Allow vendors to indicate "No Response" on line items | I5: Story Completed | J5: 5 | K5: =Table2456891021213141116171118192021152223242526272829303132333435[[#This Row],[Actual Worklog (Hours)]] / 4 -> 7.5 | L5: 30 | M5: 46108 | N5: 46114 | O5: Balamurugan | P5: Deepika | Q5: NA | R5: Deepika | S5: NA | T5: 48197 | U5: 46114 | V5: 46119 | W5: Charles | X5: NA | Y5: NA | Z5: 46119 | AA5: NA | AB5: POV Comments: 1. If decline to respond -> yes -> though data is filled, then the check box should not be visible in bid analysis 2. Bottom Line -> When declined to respond is checked, though the vendor quoted price is added, it should not consider that item for responded items | AC5: NA | AD5: NA | AE5: NA
A6: 5 | B6: FOH Wave | C6: 46108 | D6: 46121 | E6: 26.5 - Sprint 3 | F6: Vidhya | G6: 51845 | H6: [WAVE] Mosaic BOH - (6) User Tasks - Review Task Setup | I6: Story Being Tested | J6: 8 | K6: 5.5 | L6: 22 | M6: 46108 | N6: 46114 | O6: Sabir | P6: Deepika | Q6: User list grid doen't retain the checked specific User's | R6: Deepika | S6: NA | T6: 48240 | U6: 46119 | V6: 46119 | W6: Charles | X6: NA | Y6: NA | Z6: 46119 | AA6: NA | AB6: NA | AC6: NA | AD6: NA | AE6: meet expectation
A7: 6 | B7: ='Dashboard-2025'!$K$1 -> FOH Wave | C7: 46108 | D7: 46121 | E7: 26.5 - Sprint 3 | F7: Sabir | G7: 52169 | H7: [WAVE] Mosaic BOH - Ingredient Allergens - Add "Contains No Allergens" option | I7: Story Completed | J7: 3 | K7: 2 | L7: 8 | M7: 46108 | N7: 46111 | O7: Sabir | P7: Mohammad Zawahir | Q7: None | R7: Mohammad Zawahir | S7: None | T7: 48091 | U7: 46173 | V7: 46114 | W7: Charles | X7: None | Y7: NA | Z7: 46114 | AA7: None | AB7: POV Comments: Saved changes are not reflected for the checkbox "This ingredient contains no known allergens." | AD7: NA | AE7: meet expectation
A8: 7 | B8: ='Dashboard-2025'!$K$1 -> FOH Wave | C8: 46108 | D8: 46121 | E8: 26.5 - Sprint 3 | F8: Subbulakshmi | G8: 51891 | H8: MFOH [WAVE] - Modify the Dashboard Setup Maintenance (Allow to add Widgets one by one) | I8: Story Completed | J8: 1 | K8: 0.5 | L8: 2 | M8: 46108 | N8: 46113 | O8: NA | P8: NA | Q8: NA | R8: NA | S8: NA | T8: NA | U8: NA | V8: NA | W8: NA | X8: NA | Y8: NA | Z8: NA | AA8: NA | AB8: NA | AC8: NA | AD8: NA | AE8: NA
A9: 8 | B9: ='Dashboard-2025'!$K$1 -> FOH Wave | C9: 46108 | D9: 46121 | E9: 26.5 - Sprint 3 Stretch | F9: Balamurugan | G9: 52062 | H9: [Wave]Mosaic BOH - Transfers - Bulk Add (2) - UI Only | I9: Story Being Developed | J9: 8 | K9: =Table2456891021213141116171118192021152223242526272829303132333435[[#This Row],[Actual Worklog (Hours)]] / 4 -> 6 | L9: 24 | M9: 46118 | N9: NA | O9: NA | P9: NA | Q9: NA | R9: NA | S9: NA | T9: NA | U9: NA | V9: NA | W9: NA | X9: NA | Y9: NA | Z9: NA | AA9: NA | AB9: NA | AC9: NA | AD9: NA | AE9: NA
A10: 9 | B10: ='Dashboard-2025'!$K$1 -> FOH Wave | C10: 46108 | D10: 46121 | E10: 26.5 - Sprint 3 Stretch | F10: Sabir | G10: 52044 | H10: [WAVE] Mosaic BOH - Ingredients - Search for Ingredients that Do Not Contain Specified Allergens | I10: Story Approved | J10: 8 | K10: 3 | L10: 12 | M10: 46118 | N10: NA | O10: NA | P10: NA | Q10: NA | R10: NA | S10: NA | T10: NA | U10: NA | V10: NA | W10: NA | X10: NA | Y10: NA | Z10: NA | AA10: NA | AB10: NA | AC10: NA | AD10: NA | AE10: NA

Sheet 26.5 - Sprint 3-Defect
A1: S.No | B1: Sprint # | C1: Story/Defect ID | D1: Parent Story | E1: Developer | F1: Issue Type | G1: Issue Description | H1: Priority | I1: Defect Source | J1: Type | K1: Status | L1: Dev Start Date | M1: Dev End Date | N1: Root Cause Category | O1: Comments
B2: 26.5 - Sprint 3 | C2: 51845 | D2: 51845 | E2: Vidhya/Sabir | F2: Bounceback/Sub-Defect | G2: 1. Task Type tool tip is showing incorrectly 2. Tool tip issue in Task Name 3. End Date is not showing for Daily Recurrence 4. Getting on Exception error while Added more than 40 Users(Workking fine in Local, issue only is QA Test) | H2: Minor | I2: Manual | J2: Internal | K2: Story Completed | L2: 46120 | M2: 46121 | N2: UI Issue | O2: Tool tip issues in Task Type, Task Name, Recurrence

Sheet 26.5 - Sprint 2-Status
A1: S.No | B1: Application Name | C1: Sprint Start Date | D1: Sprint End Date | E1: Sprint | F1: Developer/Tester | G1: Story ID/Defect ID | H1: Description | I1: Status | J1: Estimated(hrs/sp) | K1: Actual(hrs/sp) | L1: Actual Worklog (Hours) | M1: Dev Start Date | N1: Dev End Date | O1: Unit testing | P1: Peer Tested By | Q1: Peer Tested Comments, if any | R1: Peer Reviewed By | S1: Peer Code Review Comments, if any | T1: PR Number/Link | U1: PR Created Date | V1: PR Approved Date | W1: Onsite Lead Code Review | X1: Code Review Comments, if any | Y1: Client Code Review | Z1: Approved Date | AA1: Code Review Comments, if any2 | AB1: Internal PO -POV Comments | AC1: Client PO -POV Comments | AD1: Comments | AE1: Does this story meet expectations?
A2: 1 | B2: FOH Wave | C2: 46094 | D2: 46107 | E2: 26.5 - Sprint 2 | F2: Vidhya | G2: 47929 | H2: [WAVE] Mosaic BOH - (5) User Tasks - Assigning Users | I2: Story Completed | J2: 8 | K2: =Table24568910212131411161711181920211522232425262728293031323334[[#This Row],[Actual Worklog (Hours)]] / 4 -> 9 | L2: 36 | M2: 46094 | N2: 46101 | O2: Vidhya | P2: Mohammed Jawahir | Q2: 1. After pagination, continue button turned disable mode. 2. Show Selected Only is not working correctly 3. I was added task with due date 23rd, then edit the same task it shows 22nd. 4. I can able to add task for past dates. | R2: Jawahir | S2: None | T2: 47942 | U2: 46101 | V2: 46105 | W2: Charles | X2: None | Y2: NA | Z2: 46105 | AA2: None | AB2: POV comments: 1. Either Site Group/ site should be selected to apply filters 2. User Assignment - space required 3. Uncheck any selected users when selecting yes in the pop-up | AC2: NA | AD2: NA | AE2: NA
A3: 2 | B3: FOH Wave | C3: 46094 | D3: 46107 | E3: 26.5 - Sprint 2 | F3: Subbulakshmi | G3: 52330 | H3: Kaleida changes update to the Global Report Layout File for Kaleida Reports | I3: Story Completed | J3: 2 | K3: =Table24568910212131411161711181920211522232425262728293031323334[[#This Row],[Actual Worklog (Hours)]] / 4 -> 2.25 | L3: 9 | M3: 46094 | N3: 46098 | O3: Subbulakshmi | P3: NA | Q3: NA | R3: NA | S3: NA | T3: 47876 | U3: 46099 | V3: 46099 | W3: NA | X3: NA | Y3: NA | Z3: 46099 | AA3: NA | AB3: NA | AC3: NA | AD3: NA | AE3: NA
A4: 3 | B4: FOH Wave | C4: 46094 | D4: 46107 | E4: 26.5 - Sprint 2 | F4: Balamurugan | G4: 52099 | H4: [Wave]Mosaic BOH - Transfers - Bulk Replace (1) | I4: Story Completed | J4: 3 | K4: 6.5 | L4: 26 | M4: 46094 | N4: 46099 | O4: Balamurugan | P4: Mohammed Jawahir | Q4: None | R4: Mohammed Jawahir | S4: 1. Please remove unused variables | T4: 47875 | U4: 46099 | V4: 46100 | W4: Charles Antonysamy | X4: NA | Y4: NA | Z4: 46101 | AA4: NA | AB4: 1) Parent Menu -> Icon and underline 2) add, remove -> Add “Coming soon” text 3) Replace position edit.. in view only mode 4) comment box position -> check image 5) append the existing comments | AC4: NA | AD4: Internal POV done on 03/17/2026. Working on POV 4 design comments and one 1 suggestion. Get POV confirmation after share the screen shot design changes on 03/17/2026 Reasons for story points exceeded: Since this is first story with BOH, it took time to align with existing application's coding standards and structure | AE4: NA
A5: 4 | B5: FOH Wave | C5: 46094 | D5: 46107 | E5: 26.5 - Sprint 2 Stretch | F5: Sabir | G5: 26993 | H5: [Wave]Mosaic BOH - Fix the alignment issues with the User Tasks List Search Screen | I5: Defect Being Tested | J5: 3 | K5: 2 | L5: 12 | M5: 46097 | N5: 46099 | O5: Sabir | P5: Krupa Bhatkar | Q5: NA | R5: Krupa Bhatkar | S5: NA | T5: 47865 | U5: 46099 | V5: 46105 | W5: Charles Antonysamy | X5: NA | Y5: NA | Z5: 46105 | AA5: NA | AB5: POV comments: 1. Tool tip Do not Repeat- Due on June 28- correction show the exact date in saved format 03/25/2026 Daily - Every 5 Days until 03/18/2026 Weekly - On Monday, Tuesday until 03/18/2026 Monthly - On the 1st Sunday until 09/22/2029 Annually - On June 28 until 09/22/2030 2. When opening a task from the search screen, the saved selection is not retained 3. Security Group, Site Group, and Site - List all the values | AC5: NA | AD5: NA | AE5: NA
A6: 5 | B6: FOH Wave | C6: 46094 | D6: 46107 | E6: 26.5 - Sprint 2 Stretch | F6: Subbulakshmi | G6: 52329 | H6: MFOH - Automation - Kaleida changes update to the Setup - Annual Setup - Nondiscrimination Statement | I6: Story Being Developed | J6: 1 | K6: =Table24568910212131411161711181920211522232425262728293031323334[[#This Row],[Actual Worklog (Hours)]] / 4 -> 1 | L6: 4 | M6: 46099 | N6: NA | O6: NA | P6: NA | Q6: NA | R6: NA | S6: NA | T6: NA | U6: NA | V6: NA | W6: NA | X6: NA | Y6: NA | Z6: NA | AA6: NA | AB6: None | AC6: NA | AD6: NA | AE6: NA
A7: 6 | B7: FOH Wave | C7: 46094 | D7: 46107 | E7: 26.5 - Sprint 2 Stretch | F7: Sabir | G7: 43501 | H7: [WAVE] Mosaic BOH - ER - Improve the Search functionality | I7: Story Being Developed | J7: 5 | K7: 3 | L7: 12 | M7: 46099 | N7: 46105 | O7: Sabir | P7: Rajiv | Q7: NA | R7: Rajiv | S7: NA | T7: NA | U7: NA | V7: NA | W7: NA | X7: NA | Y7: NA | Z7: NA | AA7: NA | AB7: NA | AC7: NA | AD7: NA | AE7: NA
A8: 7 | B8: FOH Wave | C8: 46094 | D8: 46107 | E8: 26.5 - Sprint 2 Stretch | F8: Balamurugan | G8: 52172 | H8: [WAVE] Mosaic BOH - Bidding - Allow vendors to indicate "No Response" on line items | I8: Story Being Developed | J8: 8 | K8: =Table24568910212131411161711181920211522232425262728293031323334[[#This Row],[Actual Worklog (Hours)]] / 4 -> 8 | L8: 32 | M8: 46100 | N8: 46107 | O8: Balamurugan | P8: NA | Q8: NA | R8: NA | S8: NA | T8: NA | U8: NA | V8: NA | W8: NA | X8: NA | Y8: NA | Z8: NA | AA8: NA | AB8: NA | AC8: NA | AD8: NA | AE8: NA
A9: 8 | B9: FOH Wave | C9: 46094 | D9: 46107 | E9: 26.5 - Sprint 2 Stretch | F9: Vidhya | G9: 51845 | H9: [WAVE] Mosaic BOH - (6) User Tasks - Review Task Setup | I9: Story Being Developed | J9: 5 | K9: =Table24568910212131411161711181920211522232425262728293031323334[[#This Row],[Actual Worklog (Hours)]] / 4 -> 4 | L9: 16 | M9: 46106 | N9: NA | O9: NA | P9: NA | Q9: NA | R9: NA | S9: NA | T9: NA | U9: NA | V9: NA | W9: NA | X9: NA | Y9: NA | Z9: NA | AA9: NA | AB9: NA | AC9: NA | AD9: NA | AE9: NA
A10: 9 | B10: ='Dashboard-2025'!$K$1 -> FOH Wave | C10: 46094 | D10: 46107 | E10: 26.5 - Sprint 2 Stretch | F10: Sabir | G10: 52169 | H10: [WAVE] Mosaic BOH - Ingredient Allergens - Add "Contains No Allergens" option | I10: Story Being Developed | J10: 5 | K10: 2 | L10: 8 | M10: 46106 | N10: NA | O10: NA | P10: NA | Q10: NA | R10: NA | S10: NA | T10: NA | U10: NA | V10: NA | W10: NA | X10: NA | Y10: NA | Z10: NA | AA10: NA | AB10: NA | AC10: NA | AD10: NA | AE10: Na

Sheet 26.5 - Sprint 2-Defect
A1: S.No | B1: Sprint # | C1: Story/Defect ID | D1: Parent Story | E1: Developer | F1: Issue Type | G1: Issue Description | H1: Priority | I1: Defect Source | J1: Type | K1: Status | L1: Dev Start Date | M1: Dev End Date | N1: Root Cause Category | O1: Comments
B2: 26.5 - Sprint 1 | C2: 52099 | D2: 52099 | E2: Balamurugan | F2: Bounceback/Sub-Defect | G2: 1. Comment is not appended when I added the text length is 4000 2. UI issue in Comment text box scroll 3. Getting an Exception error while I replace the transfer in MenuPlanningPlannedMenu file | H2: Minor | I2: Manual | J2: Internal | K2: Story Completed | L2: 46094 | M2: 46099 | N2: UI Validations
B3: 26.5 - Sprint 2 Stretch | C3: 26993 | D3: 26993 | E3: Sabir | F3: Bounceback/Sub-Defect | G3: 1. If I open the Task in new tab, data is not showing for Annually and Monthly Recurrence 2. Space needed between Custom and Link/Simple and Task – Previously showing correctly. 3. Fluctuation issue in Assigned To User tooltip 4. Continue button is enabled when I’m not filling the Mandatory field – Previously its working 5. Need to Display all the Site Groups and Site Name irrespective of the logged in User | H3: Minor | I3: Manual | J3: Internal | K3: Story Completed | L3: 46104 | M3: 46106 | N3: UI Validations

Sheet 26.5 - Sprint 1-Status
A1: S.No | B1: Application Name | C1: Sprint Start Date | D1: Sprint End Date | E1: Sprint | F1: Developer/Tester | G1: Story ID/Defect ID | H1: Description | I1: Status | J1: Estimated(hrs/sp) | K1: Actual(hrs/sp) | L1: Actual Worklog (Hours) | M1: Dev Start Date | N1: Dev End Date | O1: Unit testing | P1: Peer Tested By | Q1: Peer Tested Comments, if any | R1: Peer Reviewed By | S1: Peer Code Review Comments, if any | T1: PR Number/Link | U1: PR Created Date | V1: PR Approved Date | W1: Onsite Lead Code Review | X1: Code Review Comments, if any | Y1: Client Code Review | Z1: Approved Date | AA1: Code Review Comments, if any2 | AB1: Internal PO -POV Comments | AC1: Client PO -POV Comments | AD1: Comments | AE1: Does this story meet expectations?
A2: 1 | B2: FOH Wave | C2: 46080 | D2: 46093 | E2: 26.5 - Sprint 1 | F2: Vidhya | G2: 51349 | H2: [WAVE] Mosaic BOH - (3) User Tasks - Add/Edit Tasks | I2: Story Completed | J2: 3 | K2: =Table245689102121314111617111819202115222324252627282930313233[[#This Row],[Actual Worklog (Hours)]] / 4 -> 10.5 | L2: 42 | M2: 46080 | N2: 46087 | O2: Vidhya | P2: Deepika (BOH) | Q2: 1. At first time without any clicks on the submenus, there is an spacing at right side 2. When O&I is disabled.. Inventory has different submenu’s | R2: Deepika (BOH) | S2: 1. Remove the hard-coded value in controller instead use resource files 2. Revert this blank Line | T2: 47641 | U2: 46087 | V2: 46092 | W2: Charles (BOH) | X2: Suggested to cover unit test cases. Should add dedicated files for scripts and styles | Y2: NA | Z2: 46092 | AA2: None | AB2: 1. Custom Url is empty -> Click eye icon. Navigating to empty page 2. Daily recurrence - Set default value to 1 3. Monthly recurrence - Change 5th to Last 4. Breadcrumb - Change Add Task to Edit task after save | AC2: NA | AD2: Internal POV done on 03/04/2026. Working on POV comments. Next POV happened on 06/04/2026. Reasons for story points exceeded: 1. Initially, development started using Kendo controls, but later it was confirmed to proceed with Vega controls which causes revisiting part of the implementations again 2. As this was the first time implementing Vega controls, some additional time was required to understand it. 3. The requirement included a specific dropdown behavior that needed customization using Vega controls to match the expected UI design 4. Additional effort was spent ensuring the UI matched the design specifications 5. Since this is first story with BOH, it took time to align with existing application's coding standards and structure | AE2: NA
A3: 2 | B3: FOH Wave | C3: 46080 | D3: 46093 | E3: 26.5 - Sprint 1 | F3: Sabir | G3: 21786 | H3: [WAVE] Mosaic BOH - (2) User Tasks - Add to the Setup - UI Implementation | I3: Story Completed | J3: 3 | K3: 7.5 | L3: 30 | M3: 46080 | N3: 46090 | O3: Sabir | P3: Rajiv (BOH) | Q3: When O&I is disabled.. Inventory has different submenu’s | R3: Rajiv (BOH) | S3: 1. Remove the hard-coded value in controller instead use resource files 2. Revert this blank Line 3. Remove the hard-coded value in contants instead use resource files 4. Lable name should displayed from resource file. 5. use seperate css file from styles. | T3: 47657 | U3: 46090 | V3: 46091 | W3: Charles (BOH) | X3: None | Y3: NA | Z3: 46091 | AA3: None | AB3: 1. User Task list under setup - need to change the position 2. "Links User To" - Rename it | AC3: NA | AD3: Reasons for story points exceeded: 1. Initially, development started using Kendo controls, but later it was confirmed to proceed with Vega vontrols which causes revisiting part of the implementations again 2. As this was the first time implementing Vega controls, some additional time was required to understand it. 3. The requirement included a specific dropdown behavior that needed customization using Vega controls to match the expected UI design 4. Additional effort was spent ensuring the UI matched the design specifications 5. Since this is first story with BOH, it took time to align with existing application's coding standards and structure | AE3: NA
A4: 3 | B4: FOH Wave | C4: 46080 | D4: 46093 | E4: 26.5 - Sprint 1 Stretch | F4: Subbulakshmi | G4: 51803 | H4: MFOH - Automation (Smoke) - Kaleida changes update to the close day search screen & close day maintenance screen | I4: Story Completed | J4: 2 | K4: =Table245689102121314111617111819202115222324252627282930313233[[#This Row],[Actual Worklog (Hours)]] / 4 -> 3.5 | L4: 14 | M4: 46087 | N4: 46091 | O4: NA | P4: NA | Q4: NA | R4: NA | S4: NA | T4: 47738 | U4: 46091 | V4: 46092 | W4: NA | X4: NA | Y4: NA | Z4: 46092 | AA4: NA | AB4: NA | AC4: NA | AD4: None | AE4: NA
A5: 4 | B5: FOH Wave | C5: 46080 | D5: 46093 | E5: 26.5 - Sprint 1 Stretch | F5: Balamurugan | G5: 52099 | H5: [Wave]Mosaic BOH - Transfers - Bulk Replace (1) | I5: Story Being Developed | J5: 5 | K5: =Table245689102121314111617111819202115222324252627282930313233[[#This Row],[Actual Worklog (Hours)]] / 4 -> 7 | L5: 28 | M5: 46087 | N5: NA | O5: NA | P5: NA | Q5: NA | R5: NA | S5: NA | T5: NA | U5: NA | V5: NA | W5: NA | X5: NA | Y5: NA | Z5: NA | AA5: NA | AB5: NA | AC5: NA | AD5: None | AE5: NA
A6: 6 | B6: FOH Wave | C6: 46080 | D6: 46093 | E6: 26.5 - Sprint 1 Stretch | F6: Vidhya | G6: 47929 | H6: [WAVE] Mosaic BOH - (5) User Tasks - Assigning Users | I6: Story Being Developed | J6: 5 | K6: =Table245689102121314111617111819202115222324252627282930313233[[#This Row],[Actual Worklog (Hours)]] / 4 -> 2.25 | L6: 9 | M6: 46093 | N6: NA | O6: NA | P6: NA | Q6: NA | R6: NA | S6: NA | T6: NA | U6: NA | V6: NA | W6: NA | X6: NA | Y6: NA | Z6: NA | AA6: NA | AB6: NA | AC6: NA | AD6: None | AE6: NA
A7: 7 | B7: FOH Wave | C7: 46080 | D7: 46093 | E7: 26.5 - Sprint 1 Stretch | F7: Sabir | G7: 52062 | H7: [Wave]Mosaic BOH - Transfers - Bulk Add (2) - UI Only | I7: Story Being Developed | J7: 8 | K7: 1.5 | L7: 6 | M7: 46093 | N7: NA | O7: NA | P7: NA | Q7: NA | R7: NA | S7: NA | T7: NA | U7: NA | V7: NA | W7: NA | X7: NA | Y7: NA | Z7: NA | AA7: NA | AB7: NA | AC7: NA | AD7: None | AE7: NA

Sheet Dashboard (2)
A1: Current Sprint | B1: {=INDEX($B$2:$B$96,MATCH(1,(($D$2:$D$96 >=TODAY())*($C$2:$C$96<=TODAY())),0))} -> #N/A | C1: Current Sprint Sheet | D1: =CONCATENATE(B1,"-Status") -> #N/A | E1: Sprint Start Date | F1: =VLOOKUP($B$1,$B$1:$C$96,2) -> #N/A | G1: Sprint End Date | I1: =VLOOKUP($B$1,$B$1:$D$96,3) -> #N/A | J1: Application Name | K1: FOH Wave | L1: sabir.shaikh@relevantz.com;subbulakshmi.namasivayam@relevantz.com;vidhya.subramani@relevantz.com;balamurugan.kandasamy@relevantz.com | N1: hemanath.jayaraman@relevantz.com;sabir.shaikh@relevantz.com;subbulakshmi.namasivayam@relevantz.com;vidhya.subramani@relevantz.com | O1: satarupa.mohanty@relevantz.com;ashwin.majella@relevantz.com;ganapathiraman.balasubramanian@relevantz.com;subhasri.ponnappan@relevantz.com;hemanath.jayaraman@relevantz.com;subbulakshmi.namasivayam@relevantz.com;vidhya.subramani@relevantz.com;sabir.shaikh@relevantz.com
A2: Sprint Type | B2: Sprint # | C2: Sprint Start Date | D2: Sprint End Date | E2: Assigned | F2: Completed | G2: Story points introduced/removed | H2: Sprint Summary | I2: Accomplishments | J2: Remarks | K2: Retro Points (Internal & External) | L2: Planned Leave | M2: Total Leave | N2: Data sanity Audit Status | O2: AuditDate
A3: =IF(AND($D$1>=C3,$D$1<=D3),"CurrentSprint","NA") -> #N/A | B3: 4.15 - Sprint 4 | C3: 45296 | D3: 45309 | E3: 28 | F3: 28 | G3: 0 | J3: Regression Sprint so completed all the modules testing, No code review comments / Defects applicable. Also we fixed few regression defects. | K3: Internal: External:
A4: =IF(AND($D$1>=C4,$D$1<=D4),"CurrentSprint","NA") -> #N/A | B4: 4.16 - Sprint 1 | C4: 45310 | D4: 45323 | E4: 26 | F4: 23 | G4: 0 | J4: Developers supported to clear the QA backlogs. [Testing Stories = 18, Development Stories = 8 Total Sprint Stories =20 completed = 20; Stretch Stories = 6 completed = 3] | K4: Internal: External:
A5: =IF(AND($D$1>=C5,$D$1<=D5),"CurrentSprint","NA") -> #N/A | B5: 4.16 - Sprint 2 | C5: 45324 | D5: 45337 | E5: 41 | F5: 39 | G5: 0 | J5: Developers supported to clear the QA backlogs. | K5: Internal: External:
A6: =IF(AND($D$1>=C6,$D$1<=D6),"CurrentSprint","NA") -> #N/A | B6: 4.16 - Sprint 3 | C6: 45338 | D6: 45351 | E6: 35 | F6: 35 | G6: 0 | J6: Got appreciation for a feature developed in the sprint and also in the sprint review demo from stake holder (#42670) | K6: Internal: External:
A7: =IF(AND($D$1>=C7,$D$1<=D7),"CurrentSprint","NA") -> #N/A | B7: 4.16 - Sprint 4 | C7: 45352 | D7: 45365 | E7: 19 | F7: 30 | G7: 0 | J7: Stretch Story: 11-SP | K7: Internal: External:
A8: =IF(AND($D$1>=C8,$D$1<=D8),"CurrentSprint","NA") -> #N/A | B8: 4.16 - Sprint 5 | C8: 45366 | D8: 45379 | E8: 38 | F8: 38 | G8: 0 | J8: Regression Sprint so completed all the modules testing, No code review comments / Defects applicable. Also we fixed few regression defects. Appreciation on Retro:Regression went well | K8: Internal: External:
A9: =IF(AND($D$1>=C9,$D$1<=D9),"CurrentSprint","NA") -> #N/A | B9: 4.17 - Sprint 1 | C9: 45380 | D9: 45393 | E9: 32 | F9: 32 | J9: Regression wrap up was done in this sprint and along with that completed few stretch stories(Sprint Story only 13SP for the regression wrap up). | K9: Internal: External:
A10: =IF(AND($D$1>=C10,$D$1<=D10),"CurrentSprint","NA") -> #N/A | B10: 4.17 - Sprint 2 | C10: 45394 | D10: 45407 | E10: 21 | F10: 39 | G10: 0 | J10: Completed all the assigned stories and addition to that completed Stretch Stories - 18 SP. | K10: Internal: External:
A11: =IF(AND($D$1>=C11,$D$1<=D11),"CurrentSprint","NA") -> #N/A | B11: 4.17 - Sprint 3 | C11: 45408 | D11: 45421 | E11: 29 | F11: 10 | G11: 0 | J11: Completed all the stories - 29 SP in Sprint and 10 SP in stretch. Onsite team was on PTO, so no one there to approve the PR. Carryforwading 21 SP in sprint and 8 SP in stretch to next sprint as per Gary's suggestion. | K11: Internal: External:
A12: =IF(AND($D$1>=C12,$D$1<=D12),"CurrentSprint","NA") -> #N/A | B12: 4.17 - Sprint 4 | C12: 45422 | D12: 45435 | E12: 13 | F12: 13 | G12: 0 | J12: Regression Sprint(Targeted) so completed all the modules testing, Also we fixed few regression defects. Stretch Story: 5-SP Appreciation on Retro:Regression went well | K12: Internal: External:
A13: =IF(AND($D$1>=C13,$D$1<=D13),"CurrentSprint","NA") -> #N/A | B13: 4.18 - Sprint 1 | C13: 45436 | D13: 45449 | E13: 40 | F13: 32 | G13: 0 | J13: Carryforwaded one story 8 SP, as POV with onsite team need to done. | K13: Internal: External:
A14: =IF(AND($D$1>=C14,$D$1<=D14),"CurrentSprint","NA") -> #N/A | B14: 4.18 - Sprint 2 | C14: 45450 | D14: 45463 | E14: 13 | F14: 21 | G14: 0 | J14: Completed all the committed stories. Stretch Story: 8-SP | K14: Internal: External:
A15: =IF(AND($D$1>=C15,$D$1<=D15),"CurrentSprint","NA") -> #N/A | B15: 4.18 - Sprint 3 | C15: 45464 | D15: 45491 | E15: 44 | F15: 44 | G15: 22 | J15: Completed all the committed stories. Supported to clear the QA backlogs. Stretch Story: 22-SP. Appreciation on Retro: For helping on QA backlogs | K15: Internal: External:
A16: =IF(AND($D$1>=C16,$D$1<=D16),"CurrentSprint","NA") -> #N/A | B16: 4.18 - Sprint 4 | C16: 45492 | D16: 45505 | E16: 37 | F16: 37 | G16: 37 | J16: No delevopment stories added to sprint. Supported to clear the QA backlogs. Stretch Story: 37-SP. | K16: Internal: External:
A17: =IF(AND($D$1>=C17,$D$1<=D17),"CurrentSprint","NA") -> #N/A | B17: 4.18 - Sprint 5 | C17: 45506 | D17: 45519 | E17: 15 | F17: 15 | G17: 3 | J17: Completed the committed stories. Supported to clear the QA backlogs. 14-SP completed development and waiting to raise PR. Stretch Story: 3-SP. | K17: Internal: External:
A18: =IF(AND($D$1>=C18,$D$1<=D18),"CurrentSprint","NA") -> #N/A | B18: 4.18 - Sprint 6 | C18: 45520 | D18: 45533 | E18: 21 | F18: 21 | G18: 7 | J18: Completed the committed stories. Supported to clear the QA backlogs. Stretch Story: 11-SP. | K18: Internal: External:
A19: =IF(AND($D$1>=C19,$D$1<=D19),"CurrentSprint","NA") -> #N/A | B19: 4.18 - Sprint 7 | C19: 45534 | D19: 45547 | E19: 38 | F19: 38 | G19: 8 | J19: Note: 1. Related to fix for 4.17: There was an issue with Student Import potential match catch logic. From Steve: a parsing issue - the birthdate of 09112009 fails to parse w/the code being used. It's trying to parse with only this pattern MM/dd/yyyy (hardcoded) 2. Related to hotfix for CPS: There was an issue found at MSB end in their API. Data is not being sent to Mosaic due an issue with the date. It can be fixed at either end (MSB or Mosaic) but if is fixed in Mosaic it will be a simple fix because if MSB team fix it may take much more time. The real issue is MSB is expecting for a date time for start and end date. Currently we send only date and due to that data is not pulled properly. Completed all regression stories in sprint. Stretch Story: 8-SP | K19: Internal: External:
A20: =IF(AND($D$1>=C20,$D$1<=D20),"CurrentSprint","NA") -> #N/A | B20: 4.19 - Sprint 1 | C20: 45548 | D20: 45561 | E20: 31 | F20: 31 | G20: 0 | J20: CRC Internal -- 2 CRC External -- 0 QA Defects -- 3 (1-Rejected) Escaped Defects -- 0 Completed all the committed stories. Supported to clear the QA backlogs. Stretch Story: 18-SP. 45834 is POC which is Carry Forwarded | K20: Internal: External: Appreciation on Retro: For helping on QA backlogs
A21: =IF(AND($D$1>=C21,$D$1<=D21),"CurrentSprint","NA") -> #N/A | B21: 4.19 - Sprint 2 | C21: 45562 | D21: 45589 | E21: 33 | F21: 45.5 | G21: Introduced - 12.5 | J21: CRC Internal -- 4 CRC External -- 0 QA Defects -- 8 (2-Rejected) Escaped Defects -- 0 Supported to clear the QA backlogs. Stretch Story: 20-SP. | K21: Internal: Alpha recieved appreciation for support in dashboard. Jagan and Arvinth recieved appreciation for good presentation in sprint review. External: Recieved appreciation from Tino for Dashbord Story done by Subha. Appreciation on Retro: For helping on QA backlogs
A22: =IF(AND($D$1>=C22,$D$1<=D22),"CurrentSprint","NA") -> #N/A | B22: 4.19 - Sprint 3 | C22: 45590 | D22: 45603 | E22: 16 | F22: 35 | G22: Introduced - 19 | I22: Feature Flags, Student Barcode Report Update, Louisiana SFS-8A Report update, and Defects | J22: CRC Internal -- 0 CRC External -- 1 QA Defects -- 2 Escaped Defects -- 0 Supported to clear the QA backlogs. Stretch Story: 19-SP. | K22: Internal: External:
A23: =IF(AND($D$1>=C23,$D$1<=D23),"CurrentSprint","NA") -> #N/A | B23: 4.19 - Sprint 4 | C23: 45604 | D23: 45617 | E23: 25 | F23: 33 | G23: Introduced - 8 | I23: Improvements to Scheduler Task, Showing Actual Bank Deposit Amount in Online Payment Detail Report, Update to Alachua Meal Count export(2 decimal places to labor hours), and Defects | J23: CRC Internal -- 0 CRC External -- 0 QA Defects -- 3 (2-Rejected) Escaped Defects -- 0 Stretch Story: 8-SP. | K23: Internal: Online payment report story done without any deviation. External:
A24: =IF(AND($D$1>=C24,$D$1<=D24),"CurrentSprint","NA") -> #N/A | B24: 4.19 - Sprint 5 | C24: 45618 | D24: 45645 | E24: 60 | F24: 70 | G24: Introduced - 10 | I24: Add Ability to Print Machine Info, Add date of inactive to Student Maintenance, Add Notes to Elig Record Report, Add Active Filter to User Assignments Report, Defects, and then begin 4.19 Regression Testing. | J24: CRC Internal -- 2 CRC External -- 1 QA Defects -- 3 Escaped Defects -- 0 Stretch Story: 10-SP. | K24: Internal:Change comment,Change in adding the SQL paramer External:Merge conflict with revision history
A25: =IF(AND($D$1>=C25,$D$1<=D25),"CurrentSprint","NA") -> #N/A | B25: 4.20 - Sprint 1 | C25: 45646 | D25: 45673 | E25: 35 | F25: 46 | G25: Introduced - 12 | I25: multiple Defects for 4.19 and complete 4.19 Regression, Add report for “Schools not in School Group”, and Add new report type to POS Roster Reports | J25: Release Date - March 2025 (Tentative) CRC Internal -- 1 CRC External -- 0 QA Defects -- 15 (1-Rejected) Escaped Defects -- 0 Stretch Story: 12-SP. | K25: Internal: External: Appreciation on Retro: For helping on QA backlogs
A26: =IF(AND($D$1>=C26,$D$1<=D26),"CurrentSprint","NA") -> #N/A | B26: 4.20 - Sprint 2 | C26: 45674 | D26: 45687 | E26: 22 | F26: 27 | G26: Introduced - 5 | I26: Menu Management Improvements(Assign POS Menus to multiple POS numbers & Re-Alphabetize Menu Products), Dashboard update(CPS), Speed-e Mode option to fulfill Meal Order or not, and use CEP Reimbursement Calculations in Claim Report(KDE) | J26: Release Date - March 2025 (Tentative) CRC Internal -- 0 CRC External -- 0 QA Defects -- 0 Escaped Defects -- 0 Stretch Story: 5-SP. | K26: Internal: External: Appreciation on Retro: Mike(QA) appreciated for helping on QA backlogs
