Workbook

Sheet BOH Wave Team
A1: S.no | B1: Application Name | C1: Developer | D1: Description | E1: Status | F1: Comments
A2: 1 | B2: Extensions AI | C2: Rajiv / Deepika / Joel | D2: Extensions AI packages in console application | E2: Completed
A3: 2 | B3: Extensions AI | C3: Rajiv / Deepika / Joel | D3: Extensions AI packages integration in BOH application | E3: Completed
A4: 3 | B4: Extensions AI | C4: Rajiv / Deepika / Joel | D4: Extensions AI packages integration in BOH application with OpenAI | E4: Completed
A5: 4 | B5: Extensions AI | C5: Rajiv / Deepika / Joel | D5: Extensions AI packages integration in BOH application with AzureAI | E5: Completed
A6: 5 | B6: Extensions AI | C6: Rajiv / Deepika / Joel | D6: Extensions AI packages integration in BOH application with Vertex AI | E6: Completed | F6: Vertex not supported
A7: 6 | B7: Sementic Kernal | C7: Rajiv / Deepika / Joel | D7: Using Sementic Kernal In Console application | E7: Completed
A8: 7 | B8: Sementic Kernal | C8: Rajiv / Deepika / Joel | D8: Using Sementic Kernal In BOH application with Openai | E8: Completed
A9: 8 | B9: Sementic Kernal | C9: Rajiv / Deepika / Joel | D9: Using Sementic Kernal In BOH application with Azureai | E9: Completed
A10: 9 | B10: Sementic Kernal | C10: Rajiv / Deepika / Joel | D10: Using Sementic Kernal In BOH application with Vertexai | E10: Completed
A11: 10 | B11: Prompt Optimization | C11: Rajiv / Deepika / Joel | D11: Optimized prompt using sementic kernal in console application | E11: Completed
A12: 11 | B12: Prompt Optimization | C12: Rajiv / Deepika / Joel | D12: Optimized prompt using sementic kernal with Vertex & Openai | E12: Completed
A13: 12 | B13: API | C13: Rajiv / Deepika / Joel | D13: New API using sementic kernal with multiple LLM's | E13: Completed
A14: 13 | B14: API | C14: Rajiv / Deepika / Joel | D14: New API without using sementic kernal with multiple LLM's | E14: Completed
A15: 14 | B15: BOH AI Connectivity | C15: Rajiv / Deepika / Joel | D15: Creating new option in existing AI menu | E15: Completed
A16: 15 | B16: BOH AI Connectivity | C16: Rajiv / Deepika / Joel | D16: Consume the new API to integrate with existing BOH | E16: Completed
A17: 16 | B17: BOH AI Connectivity | C17: Rajiv / Deepika / Joel | D17: UI Changes to pass the LLM | E17: Completed
A18: 17 | B18: BOH AI Connectivity | C18: Rajiv / Deepika / Joel | D18: Pass Token counts and display to the AI connectivity output | E18: Completed
... A39: 38 | B39: Story - 46935 | C39: Joel & Rajiv | D39: Additional Instructions Improvements | E39: Completed

Sheet Defect-template
A1: S.No | B1: Sprint # | C1: Story/Defect ID | D1: Parent Story | E1: Developer | F1: Issue Type | G1: Issue Description | H1: Priority | I1: Defect Source | J1: Type | K1: Status | L1: Root Cause Category | M1: Comments

Sheet Dashboard
A1: Current Sprint | B1: {=INDEX($B$2:$B$108,MATCH(1,(($D$2:$D$108 >=TODAY())*($C$2:$C$108<=TODAY())),0))} -> 26.06 Sprint 4 | C1: Current Sprint Sheet | D1: =CONCATENATE(B1,"-Status") -> 26.06 Sprint 4-Status | E1: Sprint Start Date | F1: =VLOOKUP($B$1,$B$1:$C$108,2) -> 46155 | G1: Sprint End Date | H1: =VLOOKUP($B$1,$B$1:$D$108,3) -> 46168 | I1: Application Name | J1: BOH | K1: Users | L1: suresh.perumal@relevantz.com;shenbagavalli.srinivasan@relevantz.com;charles.antonysamy@relevantz.com;mohamed.mohamed@relevantz.com;ganapathiraman.balasubramanian@relevantz.com;kavitha.j@relevantz.com;rajivgandhi.sugumaran@relevantz.com;deepika.saravanan@relevantz.com;priyadharsini.kamalakannan@relevantz.com;krupa.bhatkar@relevantz.com;pradeepa.shanmugham@relevantz.com | M1: Teams Name(GP-Mosaic.BOH) | N1: 19:530ff4bdea8f4bbd9ac5dabcec987b9e@thread.v2
A2: Sprint Type | B2: Sprint # | C2: Sprint Start Date | D2: Sprint End Date | E2: Assigned | F2: Completed | G2: Story points introduced/removed | H2: Sprint Summary | I2: Accomplishments (Sprint Goal) | J2: Remarks | K2: Retro Points | L2: Planned Leave | M2: Total Leave | N2: Data sanity Audit Status | O2: AuditDate | P2: Backlog Health
A3: =IF(AND($D$1>=C3,$D$1<=D3),"CurrentSprint","NA") -> NA | B3: 3.18 Sprint 7 | C3: 45300 | D3: 45314 | E3: 25 | F3: 22 | J3: Regression sprint | K3: Internal: External:
A4: =IF(AND($D$1>=C4,$D$1<=D4),"CurrentSprint","NA") -> NA | B4: 3.18 Sprint 8 | C4: 45315 | D4: 45328 | E4: 26 | F4: 21 | J4: 43230 - Story carried due to reports validation pending in Regression | K4: Internal: External:
A5: =IF(AND($D$1>=C5,$D$1<=D5),"CurrentSprint","NA") -> NA | B5: 3.18 Sprint 9 | C5: 45329 | D5: 45342 | E5: 16 | F5: 16 | J5: Regression sprint | K5: Internal: External:
A6: =IF(AND($D$1>=C6,$D$1<=D6),"CurrentSprint","NA") -> NA | B6: 3.19 Sprint 1 | C6: 45343 | D6: 45356 | E6: 23 | F6: 16 | J6: Took a long time for regression of the production record and production record formats. Dev and QA focusing on 3.18 release, so not started testing 3.19 release stories. | K6: Internal: External:
A7: =IF(AND($D$1>=C7,$D$1<=D7),"CurrentSprint","NA") -> NA | B7: 3.19 Sprint 2 | C7: 45357 | D7: 45370 | E7: 20 | F7: 26 | J7: 1 story carry forwarded and completed 4 stories from stretch. | K7: Internal: External:
A8: =IF(AND($D$1>=C8,$D$1<=D8),"CurrentSprint","NA") -> NA | B8: 3.19 Sprint 3 | C8: 45371 | D8: 45384 | E8: 22 | F8: 17 | J8: 1 Story carried due to lot of testing scope involved and underestimated the effort. 2 Stretch stories completed. | K8: Internal: External:
A9: =IF(AND($D$1>=C9,$D$1<=D9),"CurrentSprint","NA") -> NA | B9: 3.19 Sprint 4 | C9: 45385 | D9: 45398 | E9: 21 | F9: 27 | J9: Addition to current sprint, completed 3 stories from stretch | K9: Internal: External:
A10: =IF(AND($D$1>=C10,$D$1<=D10),"CurrentSprint","NA") -> NA | B10: 3.19 Sprint 5 | C10: 45399 | D10: 45412 | E10: 18 | F10: 18 | J10: One 13 SP carried to next sprint, Client CRC fix is inprogress. | K10: Internal: External:
A11: =IF(AND($D$1>=C11,$D$1<=D11),"CurrentSprint","NA") -> NA | B11: 3.19 Sprint 6 | C11: 45413 | D11: 45426 | E11: 36 | F11: 36 | J11: Regression sprint | K11: Internal: External:
A12: =IF(AND($D$1>=C12,$D$1<=D12),"CurrentSprint","NA") -> NA | B12: 3.19 Sprint 7 | C12: 45427 | D12: 45440 | E12: 30 | F12: 30 | J12: Regression sprint | K12: Internal: External:
A13: =IF(AND($D$1>=C13,$D$1<=D13),"CurrentSprint","NA") -> NA | B13: 3.19 Sprint 8 | C13: 45441 | D13: 45454 | E13: 14 | F13: 14 | J13: Regression sprint and worked on regression defects(which doesn't have sp) | K13: Internal: External:
A14: =IF(AND($D$1>=C14,$D$1<=D14),"CurrentSprint","NA") -> NA | B14: 3.20 Sprint 1 | C14: 45455 | D14: 45468 | E14: 18 | F14: 18 | J14: Completed all the assigned stories | K14: Internal: External:
... A17: =IF(AND($D$1>=C17,$D$1<=D17),"CurrentSprint","NA") -> NA | B17: 3.20 Sprint 4 | C17: 45511 | D17: 45524 | E17: 19 | F17: 24 | J17: Addition to current sprint, completed 1 story from stretch | K17: Internal: External:
A18: =IF(AND($D$1>=C18,$D$1<=D18),"CurrentSprint","NA") -> NA | B18: 3.20 Sprint 5 | C18: 45525 | D18: 45538 | E18: 17 | F18: 17 | J18: Due to Public Holiday(2 Days) and onsite QA PTO, dev scope was reduced in the sprint and team worked and completed development on stretch stories. Even though development completed, those stories are pending for onsite QA testing, so carried to the next sprint. 03-Sep-24: CRC Peer - 0, Onsite - 0, Client - 1. Internal Defect - 0, External Defect - 1. | K18: Internal: External: | N18: Completed
A19: =IF(AND($D$1>=C19,$D$1<=D19),"CurrentSprint","NA") -> NA | B19: 3.20 Sprint 6 | C19: 45539 | D19: 45552 | E19: 23 | F19: 37 | G19: 14 sp - Introduced | J19: Addition to current sprint, completed 2 stories from stretch 17-Sep-24: CRC Peer - 0, Onsite - 0, Client - 0. Internal Defect - 0, External Defect - 2. | K19: Internal: External: | N19: Completed
A20: =IF(AND($D$1>=C20,$D$1<=D20),"CurrentSprint","NA") -> NA | B20: 3.20 Sprint 7 | C20: 45553 | D20: 45566 | E20: 8 | F20: 20 | J20: Addition to current sprint, completed 3 stories and 1 defect from stretch 01-Oct-24: CRC Peer - 0, Onsite - 0, Client - 0. Internal Defect - 0, External Defect - 1. | K20: Internal: External: | N20: Completed
A21: =IF(AND($D$1>=C21,$D$1<=D21),"CurrentSprint","NA") -> NA | B21: 3.20 Sprint 8 | C21: 45567 | D21: 45580 | E21: 18 | F21: 15 | J21: "Addition to current sprint, completed 1 stories from stretch and 2 Stories in QA 15-Oct-24: CRC Peer - 1, Onsite - 0, Client - 0. Internal Defect - 0, External Defect - 0." | K21: Internal: External: | N21: Completed
A22: =IF(AND($D$1>=C22,$D$1<=D22),"CurrentSprint","NA") -> NA | B22: 3.20 Sprint 9 | C22: 45581 | D22: 45594 | E22: 25 | F22: 30 | J22: Addition to current sprint, completed 1 stories from stretch 29-Oct-24: CRC Peer - 0, Onsite - 0, Client - 0. Internal Defect - 0, External Defect - 0. | K22: Internal: External: Completed sprint and stretch stories | N22: Completed
A23: =IF(AND($D$1>=C23,$D$1<=D23),"CurrentSprint","NA") -> NA | B23: 3.20 Sprint 10 | C23: 45595 | D23: 45608 | E23: 30 | F23: 30 | G23: 4/3 | I23: Completed regression on "Recipes",''Ingredients","Products" and "Inventory" Modules | J23: "46411" Mosaic BOH - 3.20 Regression - Ordering (Big Module) - Currently being in progress was removed and introduced 46412 and 46413. Development Cum Regression sprint CRC Peer - 0, CRC Onsite - 0, CRC Client - 0. Internal Defect - 0, External Defect - 0. | K23: Internal: External: | N23: Completed
A24: NA | B24: 3.20 Sprint 11 | C24: 45609 | D24: 45636 | E24: 25 | F24: 20 | I24: Completed Regression and Regression defects and worked on few production defects | J24: The development for story "46525"-Mosaic BOH - Bidding - Add the ability to attach any doc in bid analysis - is completed however the testing and review is incomplete due to hot fix release and one of the hot fix change was affecting the story. Until that is fixed it could not be pushed Development Cum Regression sprint CRC Peer - 0, CRC Onsite - 0, CRC Client - 0. Internal Defect - 2 Regression Defect- 10 External Defect - 0. | K24: Internal: External: Performance issue after 3.20 release | N24: Completed
A25: =IF(AND($D$1>=C25,$D$1<=D25),"CurrentSprint","NA") -> NA | B25: 3.21 Sprint 1 | C25: 45637 | D25: 45664 | E25: 25 | F25: 25 | I25: Completed committed stories on time and worked on a few production defects. | J25: The development for story "46743" - is in progress as we have to update the Kendo controls to latest version and fix affected components across the application.The story could spill over few more sprints as the same was done earlier (story 35612) which took total 316 hrs. It is a Development ---- Working control wise,once done with one will move to next control CRC Peer - 1, CRC Onsite - 0, CRC Client - 0. Internal Defect - 1 External Defect - 0. | K25: External: Kendo Update broke many screens Completed a few defects from stretch Completed the committed stories other than Kendo | N25: Completed
A26: =IF(AND($D$1>=C26,$D$1<=D26),"CurrentSprint","NA") -> NA | B26: 3.21 Sprint 2 | C26: 45665 | D26: 45678 | E26: 20 | F26: 20 | I26: Bidding - Ability to Edit Bid Pricelist, Adding Substitute Recipes(by site in Production Qtys), Adding User Visibility/Last Modified details to Menus and Vendors, and Defects. | J26: 46674 - Fixed the failed test cases in the Product and Ingredient Module 43702 - Development completed and in QA CRC Peer - 1, CRC Onsite - 1, CRC Client - 0. Internal Defect - 2 External Defect - 2. | K26: External: Automation parallel execution Substitution Recipe Story progress | N26: Completed
A27: =IF(AND($D$1>=C27,$D$1<=D27),"CurrentSprint","NA") -> NA | B27: 3.21 Sprint 3 | C27: 45679 | D27: 45692 | E27: 15 | F27: 47.25 | I27: Add substitute recipe in the Production Quantities for a site for a menu date - (Step 3), Adding Privacy Policy and Terms of Use, Combining “copy” buttons to dropdown option on Menu/Production Qty’s page, and Defect fixes for 3.21.. | J27: Addition to current sprint, completed 2 stories from stretch and 2 more stories in QA 46674 - Fixed the failed test cases in the Inventory Module (10.75 StP) CRC Peer - 0, CRC Onsite -1, CRC Client - 0. Internal Defect - 0 External Defect - 0. | K27: Internal: External: Completed sprint and stretch stories.Client appreciated for completing all the stories and defect in the actual commit | N27: Completed
A28: =IF(AND($D$1>=C28,$D$1<=D28),"CurrentSprint","NA") -> NA | B28: 3.21 Sprint 4 | C28: 45693 | D28: 45706 | E28: 16 | F28: 17 | I28: Adding Substituted Recipes in Production Record Report, Adding note to Bid Analysis Page, and begin 3.21 Regression Testing. WAVE(Gen AI) - UI Design. | J28: Addition to current sprint, worked on stories from stretch and 1 story in QA CRC Peer - 0, CRC Onsite -0, CRC Client - 0. Internal Defect - 3 External Defect - 0. | K28: Internal: External: Completed Regression, Completed committed stories and a few from stretch | N28: Completed
A29: =IF(AND($D$1>=C29,$D$1<=D29),"CurrentSprint","NA") -> NA | B29: 3.22 Sprint 1 | C29: 45707 | D29: 45720 | E29: 13 | F29: 26 | I29: Substitute Recipes - Updating Inventory Usage, Tech Debt(Updating 3rd parties), Separating Order Quantities(Vendor, Warehouse, & CK), and Defects. | J29: Addition to current sprint, worked on stories from stretch and 2 stories in QA CRC Peer - 0, CRC Onsite -0, CRC Client - 0. Internal Defect - 2 External Defect - 1. | K29: Internal: External: Completed sprint and stretch stories.Craig and Richard B appreciated for completing all the stories and defect in the actual commit | N29: Completed
A30: =IF(AND($D$1>=C30,$D$1<=D30),"CurrentSprint","NA") -> NA | B30: 3.22 Sprint 2 | C30: 45721 | D30: 45734 | E30: 21 | F30: 38 | I30: Substitute Recipes - Include in MealViewer, Auto-Generate Production Planning Recap, Add Product Status in Product List report, and Tiered Access Levels(WAVE Acceleration) . | J30: Addition to current sprint, completed 1 story from the stretch 46857 - Carry over to next sprint, due to the lot of scenarios to cover from menu planning screen to meal viewer sync. We completed menus and working on meal viewer sync.Also Unplanned PTO. Krupa working on Stretch story 46743 - Kendo Update, this requires more dev hours to fix the broken component and test all over the application, we keep the stories in stretch and working on. The effort we put into this was not included. CRC Peer - 0, CRC Onsite -1, CRC Client - 1. Internal Defect - 0 External Defect - 1. | K30: Internal: External: Richard Boutin and Andrew - Got lot of work completed and reviewed. What didn't go well: Unplanned PTO MV - Substitute recipe story. | N30: Completed
A31: =IF(AND($D$1>=C31,$D$1<=D31),"CurrentSprint","NA") -> NA | B31: 3.22 Sprint 3 | C31: 45735 | D31: 45748 | E31: 32 | F31: 50 | I31: Substitute Recipes (Include in MealViewer and Add to Production Costing Report), Location change for Vendor Orders Export Formats, Defects, and WAVE GenAI: Importing Suggested Menus | J31: 47441 -[WAVE]Mosaic BOH - Gen AI (Initiative #37515) - Import Suggested Menus Carry over to next sprint due to amount of work and testing involved. Underestimated the effort during planning. CRC Peer - 0, CRC Onsite -0, CRC Client - 0. Internal Defect - 3 External Defect - 1. Considerd 47615 and 47461 - 13sp/ each for automation coverage | K31: Internal: External: Richard Boutin and Andrew - Got lot of work completed and reviewed. What didn't go well: MV - Substitute recipe story. Underestimated AI story (47441) | N31: Completed
A32: =IF(AND($D$1>=C32,$D$1<=D32),"CurrentSprint","NA") -> NA | B32: 3.22 Sprint 4 | C32: 45749 | D32: 45762 | E32: 37 | F32: 34 | I32: CN2025 Updates, Tech Debt(Kendo Update), Substitute Recipes - Include in MealViewer, and WAVE GenAI(QR Code Login, Import Suggested Menus, and Implement AI Abstraction Layer). | J32: CRC Peer - 1, CRC Onsite -3, CRC Client - 3. Internal Defect - 0 External Defect - 0. | K32: Internal: External: What went well : Gen AI work Kendo ready for testing What didn’t go well : AI story not compatible with . Net | N32: Completed
A33: =IF(AND($D$1>=C33,$D$1<=D33),"CurrentSprint","NA") -> NA | B33: 3.22 Sprint 5 | C33: 45763 | D33: 45776 | E33: 35 | F33: 32 | I33: Tech Debt(Kendo Update), WAVE GenAI, and begin 3.22 Regression Testing | J33: 47441 - story got carry forwarded - Issues found by the team and needs rework 47902 - Dev completed, Testing pending CRC Peer - 0, CRC Onsite -1, CRC Client - 0, Internal Defect - 0 External Defect - 0. | K33: Internal: External: What went well : 1)Regression Testing 2)AI Development What didn’t go well : 1)COVID(unexpected PTO) 2)Accidental workflow step changes(defect marked for POV when was PR) 3)Underestimated work Wave/UI - Andrew's story | N33: Completed
A34: =IF(AND($D$1>=C34,$D$1<=D34),"CurrentSprint","NA") -> NA | B34: 3.22 Sprint 6 | C34: 45777 | D34: 45790 | E34: 24 | F34: 31 | G34: Introduced - 10 SP 48174 - 5 SP 48175 - 5 SP | I34: 3.22 Regression Testing and WAVE GenAI | J34: CRC Peer - 0, CRC Onsite -0, CRC Client - 0, Internal Defect - 0 External Defect - 0. | K34: Internal: External: What went well : 1) Defects fixed turnaround. 2)Regression time reduced 3) AI development What didn’t go well : 1)Regression defects found(Most caused by Kendo updates) 2)Web server authentication issues with AI. 3)Craig locked out of computer/system | N34: Completed
A35: =IF(AND($D$1>=C35,$D$1<=D35),"CurrentSprint","NA") -> NA | B35: 3.23 Sprint 1 | C35: 45791 | D35: 45804 | E35: 15 | F35: 21 | I35: 3.22 Regression Testing, Defect fixes for 3.22.1 Interim release, and WAVE GenAI & Tier Model. | J35: CRC Peer - 0, CRC Onsite -0, CRC Client - 0, Internal Defect - 0 External Defect - 0. | K35: Internal: External: What went well :Completed many defects What didn’t go well : Nil | N35: Completed
A36: =IF(AND($D$1>=C36,$D$1<=D36),"CurrentSprint","NA") -> NA | B36: 3.23 Sprint 2 | C36: 45805 | D36: 45818 | E36: 27 | F36: 28 | I36: Fixed a lot of defects, Good progress in the AI work | J36: CRC Peer - 0, CRC Onsite -0, CRC Client - 0, Internal Defect - 0 External Defect - 0. | K36: Internal: External: What went well : Completed many defects and good progress in the AI work What didn’t go well : Could not test wave stories, no test environment due to interim release | N36: Completed
A37: =IF(AND($D$1>=C37,$D$1<=D37),"CurrentSprint","NA") -> NA | B37: 3.23 Sprint 3 | C37: 45819 | D37: 45832 | E37: 17 | F37: 11.75 | I37: Five defect fixes, 3.22.1 Interim Release Prep/Checkout, and WAVE GenAI & Tier Model. | J37: Two defects were completed but not tested, so got spilled over.And completed one defect from stretch. CRC Peer - 0, CRC Onsite -0, CRC Client - 0, Internal Defect - 0 External Defect - 0 | K37: Internal: External: What went well :1)Fixed Lot of Defects(Total 5) 2)Interim release (no major issues reported post release) 3)Good progress in Jmeter What didn’t go well : | N37: Completed
A38: =IF(AND($D$1>=C38,$D$1<=D38),"CurrentSprint","NA") -> NA | B38: 3.23 Sprint 4 | C38: 45833 | D38: 45846 | E38: 18 | F38: 17 | H38: Ability to set fulfillment for each item under a product, and Defect fixes.Tier Model , Nutrition Facts Labels, Create Ingredient, Creative Recipe - Portion size - Update the original response, Parent Data Table - Child Data Table , Add Allergens details to the Get Creative Recipes , Nutrients - measurement conversion | I38: Ability to set fulfillment for each item under a product, and 2 Defect fixes and also completed two stories from stretch | J38: CRC Peer - 0, CRC Onsite -1, CRC Client - 0, Internal Defect - 0 External Defect - 0. | K38: Internal: External: What went well : Load testing went well What didn’t go well : Issues in VDI Setup | N38: Completed
A39: =IF(AND($D$1>=C39,$D$1<=D39),"CurrentSprint","NA") -> NA | B39: 3.23 Sprint 5 | C39: 45847 | D39: 45860 | E39: 15 | F39: 12 | G39: 5 sp introduced Defect ID -25534 | H39: Kendo - All Scrollable Grid screens - print issue, Recipes - The nutrients don't update on the menu, Recipe checkbox deselect on load, CSV file report, Ability to set fulfilment for each item level. Tier Model - Feature/Menus visibility based on the Tier levels, Nutrition Facts Label-Attach Image, Filter Task by list, Adjust background to Full screen, Physical Count worksheet. | I39: 1) Kendo scroll grid - print screen issue, CSV report, and few stories and defects completed from stretch. 2) Completed AI Implementation Tickets. Tier Level, Image attachment from nutrition fact label | J39: Committed Stories: Total 2 stories, 1 story completed, and 1 story development completed, testing spilled over to next sprint. Stretch: 1 story completed. Committed Defects: Total 2 defects,1 defect completed and 1 defect spilled over to next sprint. Introduced during sprint: 1 defect completed (5 SP) Stretch: 1 defect completed. CRC Peer - 0, CRC Onsite -0, CRC Client - 0, Internal Defect - 0 External Defect - 0 | K39: What went well : CSV report, few stories and defects completed from stretch. Tier Models, Introduction of grooming session What didn’t go well : Kendo update changes caused a few issues, Unplanned leave. Test Data was not clear, Due to introduction of Vega Components issue in testing DOM elements Story 49064 under estimated and Defect 25472 (initially not able to reproduce) | N39: Completed
A40: =IF(AND($D$1>=C40,$D$1<=D40),"CurrentSprint","NA") -> NA | B40: 3.23 Sprint 6 | C40: 45861 | D40: 45874 | E40: 7 | F40: 9 | H40: Bidding - Setup for Discounts, ER - Display "Number of Items" in Requisition, DC Central Kitchen Export - Add Reimbursable served quantity to the export data,Deactivated on-hand products not appearing on End of Month Inventory report,Mosaic BOH (CPS C0026) - Add Meal Totals to the Production Recap report Iterative AI call to parse Inventory Worksheet images, UI for verification and Editing the AI Response of the Inventory Parsing, Model switching, Ability to upload images from the system for nutrition fact label | I40: WAVE GenAI, devlopment for Ability to Set fulfillment to Item Level ,Bidding - Setup for Discounts, Bidding - Add Price per S/U to the Bid Analysis, and DC central kitchen export completed,Display number of item in requisition completed. | J40: Stories: 1 story completed from main commit, and 1 story completed from stretch. Note: 4 stories development completed from stretch and ready for testing Defects: (Total 2 defects Completed) Main commit defect - 1, Stretch defect - 1 CRC Peer - 0, CRC Onsite -0, CRC Client - 0, Internal Defect - 0 External Defect - 4 | K40: What went well: Development was completed for committed stories and defects, including stretch items. A few committed stories and defects were completed What didn’t go well: Onsite QA was on leave, so testing and completion of stories were not possible.
A41: =IF(AND($D$1>=C41,$D$1<=D41),"CurrentSprint","NA") -> NA | B41: 4.0 Sprint 1 | C41: 45875 | D41: 45888 | E41: 13 | F41: 25 | H41: Added Sugar Target values in Menus, Cycle Menus Setup, Weekly Nutrients check popup in Menus,Cycle Menus,Nutrient Breakdown Report, Menu Names & Nutrient Standards Report, Menus and Cycle Menu Spreadsheets, Bidding - Setup for Discounts, AI Assistant - Add the ability to upload images from the system, Improve Quality of Breakfast Menu Suggestions, Offer More Recipe Variety, Model switching - UI, Rework on the Mobile experience for Image/doc upload. | I41: Complete Gen AI, adding notes to indicate Added Sugars (<10% coming in July 2027) on multiple screens & reports (USDA requirement), Set Fulfillment by Item | J41: Stories: 5 stories completed from main commit, and 3 stories completed from stretch. Defects: (Total 4 defects Completed) Main commit defect - 1, Stretch defect - 3 CRC Peer - 0, CRC Onsite -0, CRC Client - 0, Internal Defect - 1 External Defect - 3 | K41: What went well: Completed committed stories and defects, including 3 stretch items. Wave Team: Completed all the committed stories and some stretch stories: What didn’t go well: Offshore unplanned leave and a bounceback
A42: =IF(AND($D$1>=C42,$D$1<=D42),"CurrentSprint","NA") -> NA | B42: 4.0 Sprint 2 | C42: 45889 | D42: 45902 | E42: 6 | F42: 14 | H42: Added Sugars Cals% into the Menus and Cycle Menus, Add Meal Totals to the Production Recap report and Bidding stories Rework on the Mobile experience for Image/doc upload, Import AI-extracted Physical Count values into products/items,User Ratings, UI Refresh (Import Menu Popup Changes), Submit physical count, AI Entry Point screen 4 columns, UI Refresh (Nutrition Facts Labels Edit Screen), Gen AI Assistant and Tasks Pages | I42: Gen AI(Performance Improvements, Importing Physical Count, and Mobile), Added Sugars Cals% into Menus/Cycle Menus, and Adding Meal Totals to Production Recap report, Bidding stories | J42: Stories: 2 stories completed from main commit, and 3 stories completed from stretch. Defects: (Total 1 defect Completed) Stretch defect - 1 CRC Peer - 0, CRC Onsite -0, CRC Client - 0, Internal Defect - 1 External Defect - 1 | K42: What went well: Completed 2 committed stories, and 4 stretch items. Wave Team: Completed all the committed stories and 2 stretch stories. What didn’t go well: Added sugars AC change
...

Sheet 26.06 Sprint 4-Status
A1: S.No | B1: Application Name | C1: Sprint Start Date | D1: Sprint End Date | E1: Sprint | F1: Developer | G1: Story ID/Defect ID | H1: Description | I1: Status | J1: Estimated(sp) | K1: Actual(sp) | L1: Actual Hours Worklog | M1: Dev Start Date | N1: Dev End Date | O1: Unit testing | P1: Peer Tested By | Q1: Peer Tested Comments, if any | R1: Peer Reviewed By | S1: Peer Code Review Comments, if any | T1: PR Number/Link | U1: PR Created Date | V1: PR Approved Date | W1: Reviewer 1 | X1: Code Review Comments, if any | Y1: Reviewer 2 | Z1: Approved Date | AA1: Code Review Comments, if any2 | AB1: Internal PO -POV Comments | AC1: Client PO -POV Comments | AD1: Comments | AE1: Does this story meet expectations?
A2: 1 | B2: BOH | C2: 46155 | D2: 46168 | E2: 26.06 Sprint 4 | F2: Mohamed | G2: 52618 | H2: [WAVE] Mosaic BOH - Inventory - Bulk Adjustments - 4 - Managing Bulk Adjustments | I2: Story Being Developed | J2: 5 | K2: =L2/4 -> 1.75 | L2: 7 | M2: 46155 | AB2: When changing any data in the bulk adjustment and clicking cancel should ask for saving the work
A3: 2 | B3: BOH | C3: 46155 | D3: 46168 | E3: 26.06 Sprint 4 | F3: Mohamed | G3: 52828 | H3: Mosaic BOH - Report - Production Entry Audit Report - CPS (C0009) | I3: Story Being Developed | J3: 5 | K3: =L3/4 -> 0.75 | L3: 3 | M3: 46156
A4: 3 | B4: BOH | C4: 46155 | D4: 46168 | E4: 26.06 Sprint 4 | F4: Kavitha | G4: 53250 | H4: Mosaic BOH - USDA - Whole Milk - Menu Screen Updates (1 - Breakfast) | I4: Story Being Developed | J4: 2 | K4: 1 | L4: 3 | M4: 46155
A5: 4 | B5: BOH | C5: 46155 | D5: 46168 | E5: 26.06 Sprint 4 | F5: Kavitha | G5: 53253 | H5: Mosaic BOH - USDA - Whole Milk - Cycle Menu Screen Updates (2 - Breakfast) | I5: Story Being Developed | J5: 2 | K5: 0.5 | L5: 1 | M5: 46155
A6: 5 | B6: BOH | C6: 46155 | D6: 46168 | E6: 26.06 Sprint 5 | F6: Kavitha | G6: 53256 | H6: Mosaic BOH - USDA - Whole Milk - Menu - Reimburse Meal Groups(3) (Breakfast) | I6: Story Being Developed | J6: 2 | K6: 1 | L6: 3
A7: 5 | B7: BOH | C7: 46155 | D7: 46168 | E7: 26.06 Sprint 4 Stretch | F7: Suresh | G7: 53268 | H7: Mosaic BOH - Update Automation Testcases based on Vega Component changes & adding new Testcases | I7: Story Being Developed | J7: 13 | K7: 3 | L7: 12 | M7: 46155

Sheet 26.06 Sprint 4 - Defect Tracker
A1: Sprint # | B1: Story/Defect ID | C1: Parent Story | D1: Developer | E1: Issue Type | F1: Issue Description | G1: Priority | H1: Defect Source | I1: Type | J1: Status | K1: Estimated(sp) | L1: Actual(sp) | M1: Actual Hours Worklog | N1: Root Cause Category | O1: Comments

Sheet 26.06 Sprint 3-Status
A1: S.No | B1: Application Name | C1: Sprint Start Date | D1: Sprint End Date | E1: Sprint | F1: Developer | G1: Story ID/Defect ID | H1: Description | I1: Status | J1: Estimated(sp) | K1: Actual(sp) | L1: Actual Hours Worklog | M1: Dev Start Date | N1: Dev End Date | O1: Unit testing | P1: Peer Tested By | Q1: Peer Tested Comments, if any | R1: Peer Reviewed By | S1: Peer Code Review Comments, if any | T1: PR Number/Link | U1: PR Created Date | V1: PR Approved Date | W1: Reviewer 1 | X1: Code Review Comments, if any | Y1: Reviewer 2 | Z1: Approved Date | AA1: Code Review Comments, if any2 | AB1: Internal PO -POV Comments | AC1: Client PO -POV Comments | AD1: Comments | AE1: Does this story meet expectations?
A2: 1 | B2: BOH | C2: 46141 | D2: 46154 | E2: 26.06 Sprint 3 | F2: Mohamed | G2: 52862 | H2: Mosaic BOH - Menus - Menu Calendar Report to display Daily, Weekly and Average in the same page | I2: Story Completed | J2: 5 | K2: =L2/4 -> 2 | L2: 8 | M2: 46141 | N2: 46142 | O2: Done | P2: Suresh | Q2: Nil | R2: Kavitha | S2: Nil | T2: https://dev.azure.com/heartlandschools/Mosaic/_git/BOH/pullrequest/48718 | U2: 46141 | V2: 46141 | W2: Charles | X2: Nil | Y2: NA | Z2: NA | AA2: Nil | AB2: Nil | AC2: Nil | AD2: Nil | AE2: Meets Expectation
A3: 2 | B3: BOH | C3: 46141 | D3: 46154 | E3: 26.06 Sprint 3 | F3: Charles | G3: 51709 | H3: Mosaic BOH - USDA Guidance - Menu Spreadsheet Report - Update Sodium Guidelines | I3: Story Completed | J3: 3 | K3: 2.5 | L3: 10 | M3: 46141 | N3: 46146 | O3: Done | P3: Suresh | Q3: Nil | R3: Mohammed | S3: Nil | T3: https://dev.azure.com/heartlandschools/Mosaic/_git/BOH/pullrequest/48863 | U3: 46148 | V3: 46148 | W3: Charles | X3: Nil | Y3: NA | Z3: NA | AA3: Nil | AB3: Nil | AC3: Nil | AD3: Nil | AE3: Meets Expectation
A4: 3 | B4: BOH | C4: 46141 | D4: 46154 | E4: 26.06 Sprint 3 | F4: Charles | G4: 52873 | H4: Mosaic BOH - USDA - Display Combined M/MA & Grains Component for HHFKA Breakfast Menus (Reimbursable Meal Group) | I4: Story Being Tested | J4: 13 | K4: =L4/4 -> 8 | L4: 32 | M4: 46141 | N4: 46143 | O4: Done | P4: Suresh | Q4: Nil | R4: Mohammed | S4: Nil | T4: https://dev.azure.com/heartlandschools/Mosaic/_git/BOH/pullrequest/48918 | U4: 46149 | V4: 46149 | W4: Charles | X4: Nil | Y4: Em | Z4: NA | AA4: Nil | AB4: Nil | AC4: Nil | AD4: Development completed and moved to testing, Onsite QA took vacation and needs to test more scenarios so testing only carry forward to next sprint. | AE4: Meets Expectation
A5: 4 | B5: BOH | C5: 46141 | D5: 46154 | E5: 26.06 Sprint 3 Stretch | F5: Suresh | G5: 53065 | H5: Mosaic BOH - Adding Automation Testcases in Products | I5: Story Completed | J5: 13 | K5: =L5/4 -> 12 | L5: 48 | M5: 46141 | N5: 46154 | O5: NA | P5: NA | Q5: NA | R5: NA | S5: NA | T5: https://dev.azure.com/heartlandschools/Mosaic/_git/BOH/pullrequest/49021 | U5: 46154 | V5: 46154 | W5: Charles | X5: NA | Y5: NA | Z5: NA | AA5: NA | AB5: NA | AC5: NA | AD5: NA | AE5: NA
A6: 5 | B6: BOH | C6: 46141 | D6: 46154 | E6: 26.06 Sprint 3 Stretch | F6: Mohamed | G6: 53078 | H6: Mosaic BOH - Price List - Save vs. Save & Close | I6: Story Completed | J6: 1 | K6: 1 | L6: 4 | M6: 46147 | N6: 46147 | O6: Done | P6: Kavitha | Q6: Nil | R6: Kavitha | S6: Nil | T6: https://dev.azure.com/heartlandschools/Mosaic/_git/BOH/pullrequest/48818 | U6: 46147 | V6: 46147 | W6: Charles | X6: Nil | Y6: NA | Z6: NA | AA6: Nil | AB6: Nil | AC6: Nil | AD6: Nil | AE6: Meets Expectation
A7: 6 | B7: BOH | C7: 46141 | D7: 46154 | E7: 26.06 Sprint 3 Stretch | F7: Charles | G7: 53196 | H7: Mosaic BOH - Update Employee SSO Hint | I7: Story Completed | J7: 1 | K7: 0.5 | L7: 2 | M7: 46150 | N7: 46150 | O7: Done | P7: Suresh | Q7: Nil | R7: Kavitha | S7: Nil | T7: https://dev.azure.com/heartlandschools/Mosaic/_git/BOH/pullrequest/48946 | U7: 46150 | V7: 46150 | W7: Charles | X7: Nil | Y7: Em | Z7: NA | AA7: Nil | AB7: Nil | AC7: Nil | AD7: Nil | AE7: Meets Expectation
A8: 7 | B8: BOH | C8: 46141 | D8: 46154 | E8: 26.06 Sprint 3 Stretch | F8: Kavitha | G8: 42397 | H8: Mosaic BOH - Production Qtys screen - Add the Ability to Calculate Reimbursable Served Qty | I8: Story Ready For Testing | J8: 5 | K8: =L8/4 -> 2.5 | L8: 10 | M8: 46148 | N8: 46149 | O8: Done | P8: Mohammed | Q8: Nil | R8: Mohammed | S8: Nil | T8: https://dev.azure.com/heartlandschools/Mosaic/_git/BOH/pullrequest/48895 | U8: 46149 | V8: 46150 | W8: Charles | X8: Nil | Y8: NA | Z8: NA | AA8: Nil | AB8: Nil | AC8: Nil | AD8: Nil | AE8: Meets Expectation
A9: 8 | B9: BOH | C9: 46141 | D9: 46154 | E9: 26.06 Sprint 3 Stretch | F9: Kavitha | G9: 48508 | H9: Mosaic BOH - Include substitute recipes in the Production Summary | I9: Story Ready For Testing | J9: 5 | K9: =L9/4 -> 3 | L9: 12 | M9: 46141 | N9: 46147 | O9: Done | P9: Suresh | Q9: Nil | R9: Mohammed | S9: Nil | T9: https://dev.azure.com/heartlandschools/Mosaic/_git/BOH/pullrequest/48819 | U9: 46146 | V9: 46147 | W9: Charles | X9: Nil | Y9: NA | Z9: NA | AA9: Nil | AB9: Nil | AC9: Nil | AD9: Nil | AE9: Meets Expectation
A10: 9 | B10: BOH | C10: 46141 | D10: 46154 | E10: 26.06 Sprint 3 Stretch | F10: Kavitha | G10: 53163 | H10: [WAVE] Mosaic BOH - Recipes - Add "Needs Attention" flag | I10: Story Peer Review | J10: 3 | K10: =L10/4 -> 3.75 | L10: 15 | M10: 46150 | N10: 46154 | O10: Done | P10: Suresh | Q10: 1) Need Attentipn Search filter is not working.2) Suggested the validation popup change. | T10: https://dev.azure.com/heartlandschools/Mosaic/_git/BOH/pullrequest/48981 | AB10: 1.Need some space in Notes tab 2.Need to include Deactivate and Delete check (new AC)
A11: 10 | B11: BOH | C11: 46141 | D11: 46154 | E11: 26.06 Sprint 3 Stretch | F11: Mohamed | G11: 52828 | H11: Mosaic BOH - Report - Production Entry Audit Report - CPS (C0009) | I11: Story Being Developed | J11: 8 | K11: =L11/4 -> 2 | L11: 8 | M11: 46141
A12: 11 | B12: BOH | C12: 46141 | D12: 46154 | E12: 26.06 Sprint 3 Stretch | F12: Mohamed | G12: 52235 | H12: [WAVE] Mosaic BOH - Receiving - Add 'View Report' option (West Hartford) | I12: Story Being Developed | J12: 8 | K12: =L12/4 -> 2.5 | L12: 10 | M12: 46147

Sheet 26.06 Sprint 3 - Defect Tracker
A1: Sprint # | B1: Story/Defect ID | C1: Parent Story | D1: Developer | E1: Issue Type | F1: Issue Description | G1: Priority | H1: Defect Source | I1: Type | J1: Status | K1: Estimated(sp) | L1: Actual(sp) | M1: Actual Hours Worklog | N1: Root Cause Category | O1: Comments

Sheet 26.06 Sprint 2-Status
A1: S.No | B1: Application Name | C1: Sprint Start Date | D1: Sprint End Date | E1: Sprint | F1: Developer | G1: Story ID/Defect ID | H1: Description | I1: Status | J1: Estimated(sp) | K1: Actual(sp) | L1: Actual Hours Worklog | M1: Dev Start Date | N1: Dev End Date | O1: Unit testing | P1: Peer Tested By | Q1: Peer Tested Comments, if any | R1: Peer Reviewed By | S1: Peer Code Review Comments, if any | T1: PR Number/Link | U1: PR Created Date | V1: PR Approved Date | W1: Reviewer 1 | X1: Code Review Comments, if any | Y1: Reviewer 2 | Z1: Approved Date | AA1: Code Review Comments, if any2 | AB1: Internal PO -POV Comments | AC1: Client PO -POV Comments | AD1: Comments | AE1: Does this story meet expectations?
A2: 1 | B2: BOH | C2: 46127 | D2: 46140 | E2: 26.06 Sprint 2 | F2: Mohamed | G2: 25871 | H2: Mosaic BOH - Reports - Menu Calendar - Ability to Select Weekly/Daily/Average Nutrients | I2: Story Completed | J2: 5 | K2: =L2/4 -> 3 | L2: 12 | M2: 46127 | N2: 46132 | O2: Done | P2: Suresh | Q2: Nil | R2: Kavitha | S2: Nil | T2: https://dev.azure.com/heartlandschools/Mosaic/_git/BOH/pullrequest/48488 | U2: 46132 | V2: 46136 | W2: Charles | X2: Nil | Y2: NA | Z2: NA | AA2: NA | AB2: Nil | AC2: NA | AD2: Nil | AE2: Meets Expectation
A3: 3 | B3: BOH | C3: 46127 | D3: 46140 | E3: 26.06 Sprint 2 | F3: Kavitha | G3: 52861 | H3: Mosaic BOH - Report - Add Tooltip Description and Preview Image for Buy American report | I3: Story Completed | J3: 2 | K3: 1.5 | L3: 6 | M3: 46129 | N3: 46129 | O3: Nil | P3: Nil | Q3: Nil | R3: Mohammed | S3: Nil | T3: https://dev.azure.com/heartlandschools/Mosaic/_git/BOH/pullrequest/48494 | U3: 46129 | V3: 46132 | W3: Charles | X3: Nil | Y3: NA | Z3: NA | AA3: NA | AB3: Nil | AC3: NA | AD3: Nil | AE3: Meets Expectation
A4: 4 | B4: BOH | C4: 46127 | D4: 46140 | E4: 26.06 Sprint 2 | F4: Charles | G4: 52173 | H4: Mosaic BOH - Pendo Snippet Updates, Phase 1 | I4: Story Completed | J4: 3 | K4: =L4/4 -> 1.5 | L4: 6 | M4: 46128 | N4: 46129 | O4: Nil | P4: Nil | Q4: Nil | R4: Mohammed | S4: Nil | T4: https://dev.azure.com/heartlandschools/Mosaic/_git/BOH/pullrequest/48517 | U4: 46129 | V4: 46129 | W4: NA | X4: NA | Y4: Richard | Z4: 46132 | AA4: Nil | AB4: Nil | AC4: Nil | AD4: Nil | AE4: Meets Expectation
A5: 5 | B5: BOH | C5: 46127 | D5: 46140 | E5: 26.06 Sprint 2 | F5: Charles | G5: 43904 | H5: Mosaic BOH - Pendo - Changes Needed | I5: Story Completed | J5: 5 | K5: =L5/4 -> 2.5 | L5: 10 | M5: 46132 | N5: 46136 | O5: Nil | P5: Nil | Q5: Nil | R5: Mohammed | S5: Nil | T5: https://dev.azure.com/heartlandschools/Mosaic/_git/BOH/pullrequest/48625 | U5: 46136 | V5: 46136 | W5: NA | X5: NA | Y5: Em | Z5: 46136 | AA5: Nil | AB5: Nil | AC5: Nil | AD5: Nil | AE5: Meets Expectation
A6: 6 | B6: BOH | C6: 46127 | D6: 46140 | E6: 26.06 Sprint 2 | F6: Charles | G6: 52609 | H6: [WAVE] Mosaic BOH - Item Maintenance - 1 - Add to Feature Flag list | I6: Story Completed | J6: 1 | K6: 1 | L6: 1 | M6: 46127 | N6: 46127 | O6: Nil | P6: Nil | Q6: Nil | R6: Mohammed | S6: Nil | T6: https://dev.azure.com/heartlandschools/Mosaic/_git/BOH/pullrequest/48450 | U6: 46127 | V6: 46128 | W6: NA | X6: NA | Y6: Em | Z6: 46127 | AA6: Nil | AB6: Nil | AC6: Nil | AD6: Nil | AE6: Meets Expectation
A7: 7 | B7: BOH | C7: 46127 | D7: 46140 | E7: 26.06 Sprint 2 | F7: Charles | G7: 52608 | H7: [WAVE] Mosaic BOH - Item Maintenance - 2 - Create Security Group | I7: Story Completed | J7: 2 | K7: =L7/4 -> 1.125 | L7: 4.5 | M7: 46129 | N7: 46132 | O7: Nil | P7: Nil | Q7: Nil | R7: Mohammed | S7: Nil | T7: https://dev.azure.com/heartlandschools/Mosaic/_git/BOH/pullrequest/48520 | U7: 46132 | V7: 46132 | W7: NA | X7: NA | Y7: Richard | Z7: 46132 | AA7: Nil | AB7: Nil | AC7: Nil | AD7: Nil | AE7: Meets Expectation
A8: 9 | B8: BOH | C8: 46127 | D8: 46140 | E8: 26.06 Sprint 2 Stretch | F8: Suresh | G8: 52875 | H8: Mosaic BOH - Adding Automation Testcases in SetUp-Allergens | I8: Story Completed | J8: 13 | K8: 12 | L8: 48 | M8: 46127 | N8: 46140 | O8: Nil | P8: Nil | Q8: Nil | R8: Charles | T8: https://dev.azure.com/heartlandschools/Mosaic/_git/BOH/pullrequest/48691 | U8: 46140 | V8: 46140 | W8: Charles | X8: Nil | Y8: NA | Z8: NA | AA8: Nil | AB8: Nil | AC8: Nil | AD8: Nil | AE8: Meets Expectation
A9: 11 | B9: BOH | C9: 46127 | D9: 46140 | E9: 26.06 Sprint 2 | F9: Charles | G9: 52875 | H9: Mosaic BOH - (USDA) (4.3) Display Combined M/MA & Grains Component for HHFKA Breakfast Menus | I9: Story Completed | J9: 2 | K9: 1 | L9: 4 | M9: 46129 | N9: 46133 | O9: Nil | P9: Nil | Q9: Nil | R9: Mohammed | S9: Nil | T9: https://dev.azure.com/heartlandschools/Mosaic/_git/BOH/pullrequest/48559 | U9: 46133 | V9: 46140 | W9: NA | X9: NA | Y9: Richard | Z9: 46133 | AA9: Nil | AB9: Nil | AC9: Nil | AD9: Nil | AE9: Meets Expectation

Sheet 26.06 Sprint 2 - Defect Tracker
A1: Sprint # | B1: Story/Defect ID | C1: Parent Story | D1: Developer | E1: Issue Type | F1: Issue Description | G1: Priority | H1: Defect Source | I1: Type | J1: Status | K1: Estimated(sp) | L1: Actual(sp) | M1: Actual Hours Worklog | N1: Root Cause Category | O1: Comments
A2: 26.06 - Sprint 2 | B2: 26988 | D2: Kavitha | E2: Defect | F2: Mosaic BOH - Recipes - Maintenance - Water - Missing Nutrients (N/A) showing as *0* in the totals. | G2: Minor | H2: Manual | I2: External | J2: Defect Fixed | K2: 3 | L2: 2 | M2: 0.8 | N2: Existing_Issues | O2: Existing Production Issue, defect was not identified in the previous test cycles
A3: 26.06 - Sprint 2 | B3: 27147 | D3: Kavitha | E3: Defect | F3: Mosaic BOH - Menus - Maintenance & Cycle - Breakfast Menus - Not flagging 2% and Whole milk as being restricted | G3: Minor | H3: Manual | I3: External | J3: Defect Fixed | K3: 3 | L3: 2.5 | M3: 10 | N3: Existing_Issues | O3: Existing Production Issue, defect was not identified in the previous test cycles

Sheet 26.06 Sprint 1-Status
A1: S.No | B1: Application Name | C1: Sprint Start Date | D1: Sprint End Date | E1: Sprint | F1: Developer | G1: Story ID/Defect ID | H1: Description | I1: Status | J1: Estimated(sp) | K1: Actual(sp) | L1: Actual Hours Worklog | M1: Dev Start Date | N1: Dev End Date | O1: Unit testing | P1: Peer Tested By | Q1: Peer Tested Comments, if any | R1: Peer Reviewed By | S1: Peer Code Review Comments, if any | T1: PR Number/Link | U1: PR Created Date | V1: PR Approved Date | W1: Reviewer 1 | X1: Code Review Comments, if any | Y1: Reviewer 2 | Z1: Approved Date | AA1: Code Review Comments, if any2 | AB1: Internal PO -POV Comments | AC1: Client PO -POV Comments | AD1: Comments | AE1: Does this story meet expectations?
A2: 1 | B2: BOH | C2: 46113 | D2: 46126 | E2: 26.06 Sprint 1 | F2: Kavitha | G2: 52276 | H2: Mosaic BOH - VOEF - Add the Added By and Last Modified By details | I2: Story Completed | J2: 3 | K2: 2.5 | L2: 12 | M2: 46113 | N2: 46118 | O2: Done | P2: Suresh | Q2: Nil | R2: Mohammed | S2: Nil | T2: https://dev.azure.com/heartlandschools/Mosaic/_git/BOH/pullrequest/48263 | U2: 46119 | V2: 46120 | W2: Charles | X2: Nil | Y2: NA | Z2: NA | AA2: NA | AB2: NIL | AC2: NIL | AD2: NIL | AE2: Meets Expectation
A3: 2 | B3: BOH | C3: 46113 | D3: 46126 | E3: 26.06 Sprint 1 Stretch | F3: Suresh | G3: 52619 | H3: Mosaic BOH - Adding Automation Testcases in SetUp | I3: Story Completed | J3: 13 | K3: 10 | L3: 40 | M3: 46113 | N3: 46125 | O3: Nil | P3: Nil | Q3: Nil | R3: Charles | S3: Nil | T3: https://dev.azure.com/heartlandschools/Mosaic/_git/BOH/pullrequest/48417 | U3: 46125 | V3: 46126 | W3: Charles | X3: Nil | Y3: NA | Z3: NA | AA3: NA | AB3: NIL | AC3: NIL | AD3: NIL
A4: 3 | B4: BOH | C4: 46113 | D4: 46126 | E4: 26.06 Sprint 1 | F4: Charles | G4: 51421 | H4: Mosaic BOH(Tech Debt) - Update Report schema to the latest version - Products | I4: Story Completed | J4: 3 | K4: 2 | L4: 8 | M4: 46113 | N4: 46115 | O4: Done | P4: Suresh | Q4: Nil | R4: Mohammed | S4: Nil | T4: https://dev.azure.com/heartlandschools/Mosaic/_git/BOH/pullrequest/48215 | U4: 46114 | V4: 46114 | W4: NA | X4: NA | Y4: Richard | Z4: 46114 | AA4: NA | AB4: NA | AC4: NA | AD4: NIL | AE4: Meets Expectation

Sheet 26.06 Sprint 1 - Defect Tracker
A1: Sprint # | B1: Story/Defect ID | C1: Parent Story | D1: Developer | E1: Issue Type | F1: Issue Description | G1: Priority | H1: Defect Source | I1: Type | J1: Status | K1: Estimated(sp) | L1: Actual(sp) | M1: Actual Hours Worklog | N1: Root Cause Category | O1: Comments
A2: 26.06 - Sprint 1 Stretch | B2: 27116 | D2: Charles | E2: Defect | F2: Mosaic BOH [Wave] - Ordering - Central Kitchen Orders invalid date format not showing error message | G2: Minor | H2: Manual | I2: External | J2: Defect Fixed | K2: 1 | L2: 1 | M2: 4 | N2: Existing_Issues | O2: The recent Kendo update changed the way it pulls the element for error validation. It was found during testing and fixed as a defect.
A3: 26.06 - Sprint 1 | B3: 27101 | D3: Charles | E3: Defect | F3: Mosaic BOH - Adjustments - Single or Bulk - Program allows you to change Adjustment Type after adjustment is committed | G3: Minor | H3: Manual | I3: External | J3: Defect Fixed | K3: 1 | L3: 1 | M3: 4 | N3: Existing_Issues | O3: The recent Kendo update changed the way it pulls the element for error validation. It was found during testing and fixed as a defect.
A4: 26.06 - Sprint 1 Stretch | B4: 27131 | D4: Charles | E4: Defect | F4: Mosaic BOH [Wave] -Inventory- Physical count P/U & S/U Quantity values allowing to type decimal values even Inventory - Allow Partial Stock Units asNO | G4: Minor | H4: Manual | I4: External | J4: Defect Fixed | K4: 1 | L4: 1 | M4: 4 | N4: Existing_Issues | O4: Existing production Issue, It's an edge case where user will copy paste decimal point where it shouldn't allow.

Sheet 26.3 Sprint 4-Status
A1: S.No | B1: Application Name | C1: Sprint Start Date | D1: Sprint End Date | E1: Sprint | F1: Developer | G1: Story ID/Defect ID | H1: Description | I1: Status | J1: Estimated(sp) | K1: Actual(sp) | L1: Actual Hours Worklog | M1: Dev Start Date | N1: Dev End Date | O1: Unit testing | P1: Peer Tested By | Q1: Peer Tested Comments, if any | R1: Peer Reviewed By | S1: Peer Code Review Comments, if any | T1: PR Number/Link | U1: PR Created Date | V1: PR Approved Date | W1: Reviewer 1 | X1: Code Review Comments, if any | Y1: Reviewer 2 | Z1: Approved Date | AA1: Code Review Comments, if any2 | AB1: Internal PO -POV Comments | AC1: Client PO -POV Comments | AD1: Comments | AE1: Does this story meet expectations?
A2: 1 | B2: BOH | C2: 46085 | D2: 46112 | E2: 26.3 Sprint 4 | F2: Team | G2: 52154 | H2: Mosaic BOH - 26.3 Regression - Menus/Cycle Menus | I2: Story Completed | J2: 13 | K2: =L2/4 -> 31.5 | L2: 126 | M2: 46086 | N2: 46098 | O2: NA | P2: NA | Q2: NA | R2: NA | S2: NA | T2: NA | U2: NA | V2: NA | W2: NA | X2: NA | Y2: NA | Z2: NA | AA2: NA | AB2: NA | AC2: NA | AD2: It's regression story, where several test cases are missing data. Consequently, we setup the data and execute the tests, and actual working hours including regression defects. | AE2: NA
A3: 2 | B3: BOH | C3: 46085 | D3: 46112 | E3: 26.3 Sprint 4 | F3: Team | G3: 52160 | H3: Mosaic BOH - 26.3 Regression - Ordering | I3: Story Completed | J3: 3 | K3: =L3/4 -> 10 | L3: 40 | M3: 46098 | N3: 46100 | O3: NA | P3: NA | Q3: NA | R3: NA | S3: NA | T3: NA | U3: NA | V3: NA | W3: NA | X3: NA | Y3: NA | Z3: NA | AA3: NA | AB3: NA | AC3: NA | AD3: It's regression story, where several test cases are missing data. Consequently, we setup the data and execute the tests, and actual working hours including regression defects. | AE3: NA
A4: 3 | B4: BOH | C4: 46085 | D4: 46112 | E4: 26.3 Sprint 4 | F4: Team | G4: 52155 | H4: Mosaic BOH - 26.3 Regression - Reports | I4: Story Completed | J4: 13 | K4: =L4/4 -> 10.5 | L4: 42 | M4: 46099 | N4: 46101 | O4: NA | P4: NA | Q4: NA | R4: NA | S4: NA | T4: NA | U4: NA | V4: NA | W4: NA | X4: NA | Y4: NA | Z4: NA | AA4: NA | AB4: NA | AC4: NA | AD4: NIL | AE4: NA
A5: 4 | B5: BOH | C5: 46085 | D5: 46112 | E5: 26.3 Sprint 4 | F5: Team | G5: 52156 | H5: Mosaic BOH - 26.3 Regression - Setup | I5: Story Completed | J5: 13 | K5: =L5/4 -> 6 | L5: 24 | M5: 46101 | N5: 46104 | O5: NA | P5: NA | Q5: NA | R5: NA | S5: NA | T5: NA | U5: NA | V5: NA | W5: NA | X5: NA | Y5: NA | Z5: NA | AA5: NA | AB5: NA | AC5: NA | AD5: NIL | AE5: NA
A6: 5 | B6: BOH | C6: 46085 | D6: 46112 | E6: 26.3 Sprint 4 | F6: Charles | G6: 52110 | H6: Mosaic BOH - Kendo update to version 2026.1.212 | I6: Story Completed | J6: 3 | K6: =L6/4 -> 6 | L6: 24 | M6: 46086 | N6: 46091 | O6: NA | P6: Suresh | Q6: NIL | R6: Mohammed | S6: NIL | T6: https://dev.azure.com/heartlandschools/Mosaic/_git/BOH/pullrequest/47693 | U6: 46090 | V6: 46090 | W6: NIL | X6: NIL | Y6: Em | Z6: 46090 | AA6: NIL | AB6: NIL | AC6: NIL | AD6: NIL | AE6: Meets Expectation
A7: 6 | B7: BOH | C7: 46085 | D7: 46112 | E7: 26.3 Sprint 4 Stretch | F7: Suresh | G7: 52224 | H7: Mosaic BOH - Adding Automation Testcases in SetUp | I7: Story Completed | J7: 13 | K7: 10 | L7: 40 | M7: 46086 | N7: 46112 | O7: NA | P7: NA | Q7: NA | R7: Charles | S7: NIL | T7: https://heartlandschools.visualstudio.com/Mosaic/_git/BOH/pullrequest/48133 | U7: 46112 | V7: 46112 | W7: Charles | X7: NIL | Y7: NIL | Z7: NIL | AA7: NIL | AB7: NIL | AC7: NIL | AD7: NIL | AE7: NIL
A8: 7 | B8: BOH | C8: 46085 | D8: 46112 | E8: 26.3 Sprint 4 Stretch | F8: Charles | G8: 52203 | H8: Mosaic BOH - Refactor asset handling for Vega UI | I8: Story Completed | J8: 3 | K8: 3 | L8: 12 | M8: 46085 | O8: NA | P8: NA | Q8: NA | T8: https://dev.azure.com/heartlandschools/Mosaic/_git/BOH/pullrequest/47618 | U8: 46087 | V8: 46087 | W8: NIL | X8: NIL | Y8: Em | Z8: 46087 | AA8: NIL | AB8: NIL | AC8: NIL | AD8: NIL | AE8: Meets Expectation

Sheet 26.3 Sprint 4 - Defect Tracker
A1: Sprint # | B1: Story/Defect ID | C1: Parent Story | D1: Developer | E1: Issue Type | F1: Issue Description | G1: Priority | H1: Defect Source | I1: Type | J1: Status | K1: Estimated(sp) | L1: Actual(sp) | M1: Actual Hours Worklog | N1: Root Cause Category | O1: Comments
A2: 26.3 Sprint 4 Stretch | B2: 26894 | D2: Mohamed | E2: Defect | F2: Mosaic BOH - Vendor Order Template - "Gold Star Food" having issue when Exporting in Vendor Bulk Approal | G2: Minor | H2: Manual | I2: External | J2: Defect Fixed | K2: 1 | L2: =M2/4 -> 1.25 | M2: 5 | N2: Existing_Issues | O2: Existing Issue, defect was not identified in the previous test cycles
A3: 26.3 Sprint 4 Stretch | B3: 26932 | D3: Charles | E3: Defect | F3: Mosaic BOH - AI - Scan Inventory Worksheets pulling from the wrong column | G3: Significant | H3: Manual | I3: External | J3: Defect Fixed | K3: 1 | L3: 1 | M3: 3 | N3: Enhancements | O3: AI Prompt Improvement
A4: 26.3 Sprint 4 | B4: 26667 | D4: Mohamed | E4: Defect | F4: Mosaic BoH - Multiple - Weekly Check report different than Weekly Certification Report | G4: Significant | H4: Manual | I4: External | J4: Defect Fixed | K4: 1 | L4: =M4/4 -> 0.75 | M4: 3 | N4: Existing_Issues | O4: Existing Issue, defect was not identified in the previous test cycles
A5: 26.3 Sprint 4 | B5: 26931 | D5: Mohamed | E5: Defect | F5: Mosaic BOH - Regression - Menus - Adding menu items can't be done as fast as it used to be | G5: Minor | H5: Manual | I5: External | J5: Defect Fixed | K5: NA | L5: NA | M5: NA | N5: Existing_Issues | O5: Existing Issue, defect was not identified in the previous test cycles
A6: 26.3 Sprint 4 | B6: 27013 | D6: Mohamed | E6: Defect | F6: Mosaic BOH - Regression - Reports - Recipes - Recipe List By Menu - You can select Site Group and Site dropdowns | G6: Minor | H6: Manual | I6: External | J6: Defect Fixed | K6: NA | L6: NA | M6: NA | N6: Existing_Issues | O6: Existing Issue, defect was not identified in the previous test cycles
A7: 26.3 Sprint 4 | B7: 27037 | D7: Mohamed | E7: Defect | F7: Mosaic BOH - Regression - Production Records - Header and Footer are showing over the menu items | G7: Significant | H7: Manual | I7: External | J7: Defect Fixed | K7: NA | L7: NA | M7: NA | N7: Existing_Issues | O7: Existing Issue, defect was not identified in the previous test cycles
A8: 26.3 Sprint 4 | B8: 27029 | D8: Charles | E8: Defect | F8: Mosaic BOH - Regression - Bidding - Analysis - Icon for legend is not showing correctly | G8: Minor | H8: Manual | I8: External | J8: Defect Fixed | K8: NA | L8: NA | M8: NA | N8: Development | O8: CSS issue from the kaleida team
A9: 26.3 Sprint 4 | B9: 27082 | D9: Charles | E9: Defect | F9: Mosaic BOH - Regression - Menus - Maintenance - Copy screen - dropdown not showing full scroll bar | G9: Minor | H9: Manual | I9: External | J9: Defect Fixed | K9: NA | L9: NA | M9: NA | N9: Development | O9: The Kendo update resulted in a few minor UI issues, with no functional impact. We completed full regression testing as planned, addressed some design and alignment issues, and found nothing critical.
A10: 26.3 Sprint 4 | B10: 27054 | D10: Charles | E10: Defect | F10: Mosaic BOH - Regression - Inv - Physical Count - Validation highlight not showing on Site and Site Group dropdowns | G10: Minor | H10: Manual | I10: External | J10: Defect Fixed | K10: NA | L10: NA | M10: NA | N10: Development | O10: The Kendo update resulted in a few minor UI issues, with no functional impact. We completed full regression testing as planned, addressed some design and alignment issues, and found nothing critical.
A11: 26.3 Sprint 4 | B11: 27062 | D11: Charles | E11: Defect | F11: Mosaic BOH - Regression - Setup - Allergens - Search filters don't stay when you open and then cancel an allergen | G11: Minor | H11: Manual | I11: External | J11: Defect Fixed | K11: NA | L11: NA | M11: NA | N11: Development | O11: CSS issue from the kaleida team
A12: 26.3 Sprint 4 | B12: 27044 | D12: Charles | E12: Defect | F12: Mosaic BOH - Regression - Setup - Security Groups - If you have Add Only rights to menus you should not be able to change values | G12: Minor | H12: Manual | I12: External | J12: Defect Fixed | K12: NA | L12: NA | M12: NA | N12: Existing_Issues | O12: Existing Issue, defect was not identified in the previous test cycles
A13: 26.3 Sprint 4 | B13: 27043 | D13: Charles | E13: Defect | F13: Mosaic BOH - Regression - Setup - Security Groups - WH Hot Shot Transfers - Clicking Cancel on Edit Fields edit page deselects other check boxes | G13: Minor | H13: Manual | I13: External | J13: Defect Fixed | K13: NA | L13: NA | M13: NA | N13: Existing_Issues | O13: The Kendo update resulted in a few minor UI issues, with no functional impact. We completed full regression testing as planned, addressed some design and alignment issues, and found nothing critical.
A14: 26.3 Sprint 4 | B14: 27039 | D14: Charles | E14: Defect | F14: Mosaic BOH - Regression - Setup - Storage Locations - Enter on keyboard doesn't initiate search | G14: Minor | H14: Manual | I14: External | J14: Defect Fixed | K14: NA | L14: NA | M14: NA | N14: Development | O14: The Kendo update resulted in a few minor UI issues, with no functional impact. We completed full regression testing as planned, addressed some design and alignment issues, and found nothing critical.
A15: 26.3 Sprint 4 | B15: 27040 | D15: Charles | E15: Defect | F15: Mosaic BOH - Regression - Setup - Warehouse Delivery routes - Search - Active column sorting doesn't work | G15: Minor | H15: Manual | I15: External | J15: Defect Fixed | K15: NA | L15: NA | M15: NA | N15: Development | O15: Existing Issue, defect was not identified in the previous test cycles
A16: 26.3 Sprint 4 | B16: 27005 | D16: Charles | E16: Defect | F16: Mosaic BOH - Regression - Vendor Order Bulk Approval - Sending Via SFTP - Failure not shown in popup. Is in the Log though | G16: Minor | H16: Manual | I16: External | J16: Defect Fixed | K16: NA | L16: NA | M16: NA | N16: Development | O16: The Kendo update resulted in a few minor UI issues, with no functional impact. We completed full regression testing as planned, addressed some design and alignment issues, and found nothing critical.
A17: 26.3 Sprint 4 | B17: 27018 | D17: Charles | E17: Defect | F17: Mosaic BOH - Regression - Bidding - User with View Only permissions can add items to a bid (Not Save though) | G17: Minor | H17: Manual | I17: External | J17: Defect Fixed | K17: NA | L17: NA | M17: NA | O17: Existing Issue, defect was not identified in the previous test cycles
A18: 26.3 Sprint 4 | B18: 27020 | D18: Charles | E18: Defect | F18: Mosaic BOH - Setup - Vendors - Order Export Template dropdown - Need to show full description or offer tooltip | G18: Minor | H18: Manual | I18: External | J18: Defect Fixed | K18: NA | L18: NA | M18: NA | N18: Development | O18: The Kendo update resulted in a few minor UI issues, with no functional impact. We completed full regression testing as planned, addressed some design and alignment issues, and found nothing critical.
A19: 26.3 Sprint 4 | B19: 27025 | D19: Charles | E19: Defect | F19: Mosaic BOH - Ingredients - Validation not showing on dropdowns. | G19: Minor | H19: Manual | I19: External | J19: Defect Fixed | K19: NA | L19: NA | M19: NA | N19: Development | O19: The Kendo update resulted in a few minor UI issues, with no functional impact. We completed full regression testing as planned, addressed some design and alignment issues, and found nothing critical.
A20: 26.3 Sprint 4 | B20: 26997 | D20: Charles | E20: Defect | F20: Mosaic BOH - Mealviewer Tab - Need to expand Site dropdown | G20: Minor | H20: Manual | I20: External | J20: Defect Fixed | K20: NA | L20: NA | M20: NA | N20: Development | O20: The Kendo update resulted in a few minor UI issues, with no functional impact. We completed full regression testing as planned, addressed some design and alignment issues, and found nothing critical.
A21: 26.3 Sprint 4 | B21: 26981 | D21: Charles | E21: Defect | F21: Mosaic BOH - Regression - Bidding - Responses - Bid Response # field not searching correctly | G21: Minor | H21: Manual | I21: External | J21: Defect Fixed | K21: NA | L21: NA | M21: NA | N21: Development | O21: The Kendo update resulted in a few minor UI issues, with no functional impact. We completed full regression testing as planned, addressed some design and alignment issues, and found nothing critical.
A22: 26.3 Sprint 4 | B22: 26929 | D22: Charles | E22: Defect | F22: Mosaic BOH - Regression - Reports - Weekly Requirement - Two issues | G22: Minor | H22: Manual | I22: External | J22: Defect Fixed | K22: NA | L22: NA | M22: NA | N22: Development | O22: The Kendo update resulted in a few minor UI issues, with no functional impact. We completed full regression testing as planned, addressed some design and alignment issues, and found nothing critical.
A23: 26.3 Sprint 4 | B23: 26934 | D23: Charles | E23: Defect | F23: Mosaic BOH - Recipes - Maintenance - Report tab - We should show the full labels in the dropdown | G23: Minor | H23: Manual | I23: External | J23: Defect Fixed | K23: NA | L23: NA | M23: NA | N23: Development | O23: The Kendo update resulted in a few minor UI issues, with no functional impact. We completed full regression testing as planned, addressed some design and alignment issues, and found nothing critical.
A24: 26.3 Sprint 4 | B24: 26943 | D24: Charles | E24: Defect | F24: Mosaic BOH - Menus - Maintenance and Cycles - Have to scroll down to get to buttons. | G24: Minor | H24: Manual | I24: External | J24: Defect Fixed | K24: NA | L24: NA | M24: NA | N24: Development | O24: The Kendo update resulted in a few minor UI issues, with no functional impact. We completed full regression testing as planned, addressed some design and alignment issues, and found nothing critical.
A25: 26.3 Sprint 4 | B25: 26969 | D25: Charles | E25: Defect | F25: Mosaic BOH - Regression - Recipes - Maintenance - Print Report - Vitamin C label is cut off | G25: Minor | H25: Manual | I25: External | J25: Defect Fixed | K25: NA | L25: NA | M25: NA | N25: Development | O25: The Kendo update resulted in a few minor UI issues, with no functional impact. We completed full regression testing as planned, addressed some design and alignment issues, and found nothing critical.
A26: 26.3 Sprint 4 | B26: 26970 | D26: Charles | E26: Defect | F26: Mosaic BOH - Regression - Recipes - Maintenance - If screen resized large portions of screen are shifted to the right | G26: Minor | H26: Manual | I26: External | J26: Defect Fixed | K26: NA | L26: NA | M26: NA | N26: Development | O26: The Kendo update resulted in a few minor UI issues, with no functional impact. We completed full regression testing as planned, addressed some design and alignment issues, and found nothing critical.

Sheet 26.3 Sprint 3-Status
A1: S.No | B1: Application Name | C1: Sprint Start Date | D1: Sprint End Date | E1: Sprint | F1: Developer | G1: Story ID/Defect ID | H1: Description | I1: Status | J1: Estimated(sp) | K1: Actual(sp) | L1: Actual Hours Worklog | M1: Dev Start Date | N1: Dev End Date | O1: Unit testing | P1: Peer Tested By | Q1: Peer Tested Comments, if any | R1: Peer Reviewed By | S1: Peer Code Review Comments, if any | T1: PR Number/Link | U1: PR Created Date | V1: PR Approved Date | W1: Reviewer 1 | X1: Code Review Comments, if any | Y1: Reviewer 2 | Z1: Approved Date | AA1: Code Review Comments, if any2 | AB1: Internal PO -POV Comments | AC1: Client PO -POV Comments | AD1: Comments | AE1: Does this story meet expectations?
A2: 1 | B2: BOH | C2: 46071 | D2: 46084 | E2: 26.3 Sprint 3 | F2: Mohamed | G2: 51614 | H2: Mosaic BOH - USDA - Whole Milk - Weekly Nutrients Check (6) | I2: Story Completed | J2: 5 | K2: =L2/4 -> 4 | L2: 16 | M2: 46071 | N2: 46076 | O2: Done | P2: Suresh | Q2: Nil | R2: Kavitha | S2: Nil | T2: https://dev.azure.com/heartlandschools/Mosaic/_git/BOH/pullrequest/47480 | U2: 46078 | V2: 46078 | W2: Charles | X2: Nil | Y2: NA | Z2: NA | AA2: NA | AB2: Nil | AC2: Nil | AD2: Nil | AE2: Meets Expectation
