Workbook
Name Status: Config!$L$2:$L$5

Sheet QualityMetrics-Definition
A1: Key Performance Indicator | B1: Description | C1: Formula | D1: Weightage | E1: Green | F1: Amber | G1: Red | H1: Client Approved
A2: Commitment Index | B2: Indicates the percentage of story points fulfilled relative to the commitment for each sprint. | C2: Completed Story Points/ Planned Story Points | D2: 0.25 | E2: 100 | F2: 81-99 | G2: <=80%
A3: Velocity | B3: Denotes the overall count of story points accomplished in each sprint. | C3: Completed Story Points/Average of 4 sprints (4 sprints after the team completely onboarded and started the project related activities) The above formulae is customized and should not be below the value derived from 8*1(2 Weeks Sprint)*(Number of Team Members) | D3: 0.2 | E3: 0.95 | F3: 80-94 | G3: <80%
A4: Defect-free Rate | B4: The number of defects identified post-development | C4: (Internal+Escaped) Defects Found/ Size (actual in Story Points) | D4: 0.2 | E4: 1 | F4: 99-80 | G4: >20%
A5: Code Quality Index | B5: Evaluate the code quality across various dimensions, whether through manual code review or automated analysis using tools like SonarCube. Assess aspects such as correctness, readability, maintainability, efficiency, consistency, testability, scalability, security, documentation, and adherence to established standards. | C5: (Peer + Client) Code Review/ Size (actual in Story Points) | D5: 0.15 | E5: >=80 | F5: 79-65 | G5: <65%
A6: Unit Testing & Code Coverage | B6: Unit Test Results should be >85% Code Coverage should be >85% | C6: Average of Unit Test & Code Coverage | D6: 0.1 | E6: >=90 | F6: 71-89 | G6: <=70%
A7: Backlog Health | B7: Shows the health of backlog in as total number of Story Points available in backlog Vs Average Velocity (last 6 Sprints) | C7: No. Of stories points (Velocity of the Team) ready for (N+1)th Sprint | D7: 0.1 | E7: 100 | F7: 81-99 | G7: <=80%
A8: Delivery Score | C8: Sum of all the scores from different metrics | D8: NA | E8: >=90% | F8: 81-89 | G8: <=80%

Sheet Dashboard
A1: Meal Orders

Sheet Scorecard
A1: Project Name | B1: MealOrders - US
A2: Engagement Model | B2: Relevantz Co Owned
A3: Overall Score | B3: =SUM(C8:C13) -> 0.97383838
A5: Current Sprint | B5: 2.5 KaleidaNutrition S23 (1-May-2026 to 14-May-2026)
A7: Metrics | B7: UnWeighted | C7: Weighted | D7: Notes | V7: Target
A8: Commitment Index | B8: =VLOOKUP($B$5,Data!A1:O54,4) -> 1 | C8: =K8*B8 -> 0.25 | D8: =VLOOKUP($B$5,Table_1[#All],13) -> 0 | K8: 0.25 | V8: 1
A9: Velocity | B9: =IF((VLOOKUP($B$5,Table_1[#Data],5)/Data!AK27)>1,1,(VLOOKUP($B$5,Table_1[#Data],5)/Data!AK27)) -> 1 | C9: =K9*B9 -> 0.2 | K9: 0.2 | V9: 0.95
A10: Defect-free Rate | B10: =1-IFERROR((VLOOKUP($B$5,Data!A1:L52,9)+VLOOKUP($B$5,Data!A1:L66,10))/VLOOKUP($B$5,Data!A1:L63,5),0) -> 0.91919192 | C10: =(B10)*K10 -> 0.18383838 | K10: 0.2 | V10: 1
A11: Code Quality Index | B11: =1-(VLOOKUP($B$5,Data!A1:L52,7)+VLOOKUP($B$5,Data!A1:L52,8))/VLOOKUP($B$5,Table_1[],3) -> 1 | C11: =(B11)*K11 -> 0.15 | K11: 0.15 | V11: 1
A12: Unit Testing & Code Coverage | B12: =VLOOKUP($B$5,Table_1[],6) -> 0.9 | C12: =K12*B12 -> 0.09 | K12: 0.1 | V12: 0.9
A13: Backlog Health | B13: =IF((VLOOKUP($B$5,Table_1[#All],11)/Data!K2)>1,"100%",(VLOOKUP($B$5,Table_1[#All],11)/Data!K2)) -> 1 | C13: =K13*B13 -> 0.1 | K13: 0.1 | V13: 1

Sheet Data
A1: Sprint | B1: Committed | C1: Delivered | D1: Commitment Index | E1: Velocity | F1: Code Coverage | G1: Code Review Comments - Internal | H1: Code Review Comments - External | I1: QA Defects | J1: Escaped Defects | K1: Backlog Health | L1: Last Sprint? | M1: Planned Leaves | N1: Availed Leaves | O1: Remarks | AF1: CommitmentIndex | AG1: Goal | AH1: Risk | AI1: Issue | AJ1: Velocity | AK1: Goal | AL1: Code Coverage | AM1: Goal | AN1: Backlog Health | AO1: Goal
A2: 2.0 Sprint 1 (22-Mar-2024 to 4-Apr-2024) | B2: 21 | C2: 21 | D2: =IF((C2/B2)>1,1,(C2/B2)) -> 1 | E2: 20 | F2: 0.9 | G2: 0 | H2: 0 | I2: 8 | J2: 0 | K2: 30 | L2: No | AG2: =Config!$J$2 -> 1 | AH2: =Config!$J$3 -> 0.9 | AI2: =Config!$J$4 -> 0.8 | AK2: =Config!$J$7 -> 20 | AM2: =Config!$J$10 -> 0.9 | AO2: 30
A3: 2.0 Sprint 2 (5-Apr-2024 to 18-Apr-2024) | B3: 15 | C3: 18 | D3: =IF((C3/B3)>1,1,(C3/B3)) -> 1 | E3: 28 | F3: 0.9 | G3: 0 | H3: 0 | I3: 1 | J3: 0 | K3: 30 | L3: No | AG3: =Config!$J$2 -> 1 | AH3: =Config!$J$3 -> 0.9 | AI3: =Config!$J$4 -> 0.8 | AK3: =Config!$J$7 -> 20 | AM3: =Config!$J$10 -> 0.9 | AO3: 30
A4: 2.0 Sprint 3 (Apr-19-2024 to May-2-2024) | B4: 13 | C4: 18 | D4: =IF((C4/B4)>1,1,(C4/B4)) -> 1 | E4: 32 | F4: 0.85 | G4: 1 | H4: 1 | I4: 1 | J4: 0 | K4: 30 | L4: No | AG4: =Config!$J$2 -> 1 | AH4: =Config!$J$3 -> 0.9 | AI4: =Config!$J$4 -> 0.8 | AK4: =Config!$J$7 -> 20 | AM4: =Config!$J$10 -> 0.9 | AO4: 30
A5: 2.0 Sprint 4 (May-3-2024 to May-16-2024) | B5: 10 | C5: 22 | D5: =IF((C5/B5)>1,1,(C5/B5)) -> 1 | E5: 20 | F5: 1 | G5: 1 | H5: 0 | I5: 0 | J5: 0 | K5: 30 | L5: No | AG5: =Config!$J$2 -> 1 | AH5: =Config!$J$3 -> 0.9 | AI5: =Config!$J$4 -> 0.8 | AK5: =Config!$J$7 -> 20 | AM5: =Config!$J$10 -> 0.9 | AO5: 30
A6: 2.0 Sprint 5 (May-17-2024 to May-30-2024) | B6: 12 | C6: 16 | D6: =IF((C6/B6)>1,1,(C6/B6)) -> 1 | E6: 19 | F6: 1 | G6: 0 | H6: 0 | I6: 0 | J6: 0 | K6: 30 | L6: NO | AG6: =Config!$J$2 -> 1 | AH6: =Config!$J$3 -> 0.9 | AI6: =Config!$J$4 -> 0.8 | AK6: =Config!$J$7 -> 20 | AM6: =Config!$J$10 -> 0.9 | AO6: 30
A7: 2.0 Sprint 6 (May-31-2024 to Jun-13-2024) | B7: 13 | C7: 17 | D7: =IF((C7/B7)>1,1,(C7/B7)) -> 1 | E7: 18 | F7: 0.9 | G7: 0 | H7: 1 | I7: 1 | J7: 0 | K7: 30 | L7: NO | AG7: =Config!$J$2 -> 1 | AH7: =Config!$J$3 -> 0.9 | AI7: =Config!$J$4 -> 0.8 | AK7: =Config!$J$7 -> 20 | AM7: =Config!$J$10 -> 0.9 | AO7: 30
A8: 2.0 Sprint 7 (Jun-14-2024 to Jun-27-2024) | B8: 34 | C8: 18 | D8: =IF((C8/B8)>1,1,(C8/B8)) -> 0.52941176 | E8: 18 | F8: 0.7 | G8: 0 | H8: 0 | I8: 0 | J8: 0 | K8: 30 | L8: NO | AG8: =Config!$J$2 -> 1 | AH8: =Config!$J$3 -> 0.9 | AI8: =Config!$J$4 -> 0.8 | AK8: =Config!$J$7 -> 20 | AM8: =Config!$J$10 -> 0.9 | AO8: 30
A9: 2.0 Sprint 8 (Jun-28-2024 to Jul-11-2024) | B9: 39 | C9: 26 | D9: =IF((C9/B9)>1,1,(C9/B9)) -> 0.66666667 | E9: 19 | F9: 0.8 | G9: 0 | H9: 0 | I9: 0 | J9: 0 | K9: 30 | L9: No | AG9: =Config!$J$2 -> 1 | AH9: =Config!$J$3 -> 0.9 | AI9: =Config!$J$4 -> 0.8 | AK9: =Config!$J$7 -> 20 | AM9: =Config!$J$10 -> 0.9 | AO9: 30
A10: 2.1 Sprint 1 (Jul-12-2024 to Jul-25-2024) | B10: 25 | C10: 30 | D10: =IF((C10/B10)>1,1,(C10/B10)) -> 1 | E10: 23 | F10: 1 | G10: 0 | H10: 0 | I10: 5 | J10: 0 | K10: 30 | L10: No | O10: NA | AG10: =Config!$J$2 -> 1 | AH10: =Config!$J$3 -> 0.9 | AI10: =Config!$J$4 -> 0.8 | AK10: =Config!$J$7 -> 20 | AM10: =Config!$J$10 -> 0.9 | AO10: 30
A11: 2.1 Sprint 2 (Jul-26-2024 to Aug-8-2024) | B11: 13 | C11: 24 | D11: =IF((C11/B11)>1,1,(C11/B11)) -> 1 | E11: 25 | F11: 1 | G11: 1 | H11: 0 | I11: 6 | J11: 0 | K11: 30 | L11: No | AG11: =Config!$J$2 -> 1 | AH11: =Config!$J$3 -> 0.9 | AI11: =Config!$J$4 -> 0.8 | AK11: =Config!$J$7 -> 20 | AM11: =Config!$J$10 -> 0.9 | AO11: 30
A12: 2.1 Sprint 3 (Aug-9-2024 to Aug-22-2024) | B12: 14 | C12: 20 | D12: =IF((C12/B12)>1,1,(C12/B12)) -> 1 | E12: 25 | F12: 1 | G12: 0 | H12: 0 | I12: 6 | J12: 0 | K12: 30 | L12: No | AG12: =Config!$J$2 -> 1 | AH12: =Config!$J$3 -> 0.9 | AI12: =Config!$J$4 -> 0.8 | AK12: =Config!$J$7 -> 20 | AM12: =Config!$J$10 -> 0.9 | AO12: 30
A13: 2.1 Sprint 4 (Aug-23-2024 to Sep-5-2024) | B13: 33 | C13: 20 | D13: =IF((C13/B13)>1,1,(C13/B13)) -> 0.60606061 | E13: 24 | F13: 1 | G13: 1 | H13: 4 | I13: 3 | J13: 0 | K13: 30 | L13: No | AG13: =Config!$J$2 -> 1 | AH13: =Config!$J$3 -> 0.9 | AI13: =Config!$J$4 -> 0.8 | AK13: =Config!$J$7 -> 20 | AM13: =Config!$J$10 -> 0.9 | AO13: 30
A14: 2.1 Sprint 5 (Sep-6-2024 to Sep-19-2024) | B14: 38 | C14: 17 | D14: =IF((C14/B14)>1,1,(C14/B14)) -> 0.44736842 | E14: 20 | F14: 1 | G14: 0 | H14: 0 | I14: 3 | J14: 0 | K14: 30 | L14: No | O14: Regression Sprint There was a scope creep for Stock Management, rather than regression was on-going. | AG14: =Config!$J$2 -> 1 | AH14: =Config!$J$3 -> 0.9 | AI14: =Config!$J$4 -> 0.8 | AK14: =Config!$J$7 -> 20 | AM14: =Config!$J$10 -> 0.9 | AO14: 30
A15: 2.1 Sprint 6 (Sep-20-2024 to Oct-3-2024) | B15: 29 | C15: 50 | D15: =IF((C15/B15)>1,1,(C15/B15)) -> 1 | E15: 27 | F15: 1 | G15: 0 | H15: 0 | I15: 11 | J15: 0 | K15: 30 | L15: Yes | O15: Regression Sprint | AG15: =Config!$J$2 -> 1 | AH15: =Config!$J$3 -> 0.9 | AI15: =Config!$J$4 -> 0.8 | AK15: =Config!$J$7 -> 20 | AM15: =Config!$J$10 -> 0.9 | AO15: 30
A16: 2.2 Sprint 0 (Oct-4-2024 to Oct-17-2024) | B16: 15 | C16: 20 | D16: =IF((C16/B16)>1,1,(C16/B16)) -> 1 | E16: 27 | F16: 1 | G16: 0 | H16: 0 | I16: 4 | J16: 0 | K16: 30 | L16: No | AG16: =Config!$J$2 -> 1 | AH16: =Config!$J$3 -> 0.9 | AI16: =Config!$J$4 -> 0.8 | AK16: =Config!$J$7 -> 20 | AM16: =Config!$J$10 -> 0.9 | AO16: 30
A17: 2.2 Sprint 1 (Oct-18-2024 to Oct-31-2024) | B17: 20 | C17: 17 | D17: =IF((C17/B17)>1,1,(C17/B17)) -> 0.85 | E17: 26 | F17: 1 | G17: 0 | H17: 0 | I17: 2 | J17: 0 | K17: 30 | L17: No | O17: Due to Build Issues and ChromeDriver Issue one Regression Automation Story was carry forwarded | AG17: =Config!$J$2 -> 1 | AH17: =Config!$J$3 -> 0.9 | AI17: =Config!$J$4 -> 0.8 | AK17: =Config!$J$7 -> 20 | AM17: =Config!$J$10 -> 0.9 | AO17: 30
A18: 2.2 Sprint 2 (Nov-1-2024 to Nov-14-2024) | B18: 23 | C18: 23 | D18: =IF((C18/B18)>1,1,(C18/B18)) -> 1 | E18: 27.5 | F18: 1 | G18: 0 | H18: 0 | I18: 3 | J18: 0 | K18: 30 | L18: No | AG18: =Config!$J$2 -> 1 | AH18: =Config!$J$3 -> 0.9 | AI18: =Config!$J$4 -> 0.8 | AK18: =Config!$J$7 -> 20 | AM18: =Config!$J$10 -> 0.9 | AO18: 30
A19: 2.2 Sprint 3 (Nov-15-2024 to Dec-12-2024) | B19: 41 | C19: 53 | D19: =IF((C19/B19)>1,1,(C19/B19)) -> 1 | E19: 28.25 | F19: 1 | G19: 0 | H19: 0 | I19: 5 | J19: 0 | K19: 30 | L19: No | AG19: =Config!$J$2 -> 1 | AH19: =Config!$J$3 -> 0.9 | AI19: =Config!$J$4 -> 0.8 | AK19: =Config!$J$7 -> 20 | AM19: =Config!$J$10 -> 0.9 | AO19: 30
A20: 2.2 Sprint 4 (13-Dec-2024 to 09-Jan-2025) | B20: 36 | C20: 51 | D20: =IF((C20/B20)>1,1,(C20/B20)) -> 1 | E20: 30.75 | F20: 1 | G20: 0 | H20: 0 | I20: 4 | J20: 0 | K20: 30 | L20: No | O20: 4 Week Sprint. Development is completed, Testing is in Progress. End - End Testing is required | AG20: =Config!$J$2 -> 1 | AH20: =Config!$J$3 -> 0.9 | AI20: =Config!$J$4 -> 0.8 | AK20: =Config!$J$7 -> 20 | AM20: =Config!$J$10 -> 0.9 | AO20: 30
A21: 2.2 Sprint 5 (10-Jan-2025 to 23-Jan-2025) | B21: 42 | C21: 43 | D21: =IF((C21/B21)>1,1,(C21/B21)) -> 1 | E21: 42.5 | F21: 1 | G21: 0 | H21: 0 | I21: 4 | J21: 9 | K21: 30 | L21: No | AG21: =Config!$J$2 -> 1 | AH21: =Config!$J$3 -> 0.9 | AI21: =Config!$J$4 -> 0.8 | AK21: =Config!$J$7 -> 20 | AM21: =Config!$J$10 -> 0.9 | AO21: 30
A22: 2.2 Sprint 6 (24-Jan-2025 to 6-Feb-2025) | B22: 20 | C22: 27 | D22: =IF((C22/B22)>1,1,(C22/B22)) -> 1 | E22: 43.5 | F22: 1 | G22: 0 | H22: 0 | I22: 3 | J22: 1 | K22: 30 | L22: No | AG22: =Config!$J$2 -> 1 | AH22: =Config!$J$3 -> 0.9 | AI22: =Config!$J$4 -> 0.8 | AK22: =Config!$J$7 -> 20 | AM22: =Config!$J$10 -> 0.9 | AO22: 30
A23: 2.3 Sprint 1 (07-Feb-2025 to 20-Feb-2025) | B23: 7 | C23: 25.75 | D23: =IF((C23/B23)>1,1,(C23/B23)) -> 1 | E23: 37 | F23: 1 | G23: 0 | H23: 0 | I23: 1 | J23: 1 | K23: 30 | L23: No | AG23: =Config!$J$2 -> 1 | AH23: =Config!$J$3 -> 0.9 | AI23: =Config!$J$4 -> 0.8 | AK23: =Config!$J$7 -> 20 | AM23: =Config!$J$10 -> 0.9 | AO23: 30
A24: 2.3 Sprint 2 (21-Feb-2025 to 06-Mar-2025) | B24: 18 | C24: 27 | D24: =IFERROR(C24/B24,0) -> 1.5 | E24: 31 | F24: 1 | G24: 0 | H24: 0 | I24: 6 | J24: 0 | K24: 30 | L24: No | AG24: =Config!$J$2 -> 1 | AH24: =Config!$J$3 -> 0.9 | AI24: =Config!$J$4 -> 0.8 | AK24: =Config!$J$7 -> 20 | AM24: =Config!$J$10 -> 0.9 | AO24: 30
A25: 2.3 Sprint 3 (07-Mar-2025 to 20-Mar-2025) | B25: 21 | C25: 34 | D25: =IFERROR(C25/B25,0) -> 1.6190476 | E25: 28 | F25: 0.9 | G25: 0 | H25: 0 | I25: 4 | J25: 1 | K25: 30 | L25: No | AG25: =Config!$J$2 -> 1 | AH25: =Config!$J$3 -> 0.9 | AI25: =Config!$J$4 -> 0.8 | AK25: =Config!$J$7 -> 20 | AM25: =Config!$J$10 -> 0.9 | AO25: 30
A26: 2.3 Sprint 4 (21-Mar-2025 to 03-Apr-2025) | B26: 35 | C26: 35 | D26: =IFERROR(C26/B26,0) -> 1 | E26: 31 | F26: 0.9 | G26: 0 | H26: 0 | I26: 9 | J26: 0 | K26: 30 | L26: No | O26: 2 Defects have been rolled over. 24915 - Functional issue with respect to column order change - Reported Sentral & 24882 - Team is currently analysing this defect.
A27: 2.4 Sprint 0 (04-Apr-2025 to 17-Apr-2025) | B27: 23 | C27: 32 | D27: =IFERROR(C27/B27,0) -> 1.3913043 | E27: 32 | F27: 0.9 | G27: 0 | H27: 0 | I27: 7 | J27: 0 | K27: 30 | L27: No | O27: 1 defect has been rolled over. 24944 - Admin - Item/Grade restrictions radio button issue on first add | AG27: =Config!$J$2 -> 1 | AH27: =Config!$J$3 -> 0.9 | AI27: =Config!$J$4 -> 0.8 | AK27: =Config!$J$7 -> 20 | AM27: =Config!$J$10 -> 0.9 | AO27: 30
A28: 2.4 Sprint 1 (18-Apr-2025 to 01-May-2025) | B28: 29 | C28: 29 | D28: =IFERROR(C28/B28,0) -> 1 | E28: 32.5 | F28: 0.95 | G28: 0 | H28: 0 | I28: 1 | J28: 1 | K28: 30 | L28: No | O28: Two Issues (existing) have been occured; (1) 24944 - Only for the first hit when there is no grade restriction added; (2) 22944 - Due to API limitation. | AG28: =Config!$J$2 -> 1 | AH28: =Config!$J$3 -> 0.9 | AI28: =Config!$J$4 -> 0.8 | AK28: =Config!$J$7 -> 20 | AM28: =Config!$J$10 -> 0.9 | AO28: 30
A29: 2.4 Sprint 2 (02-May-2025 to 15-May-2025) | B29: 16 | C29: 10 | D29: =IFERROR(C29/B29,0) -> 0.625 | E29: 26.5 | F29: 0.9 | G29: 0 | H29: 0 | I29: 1 | J29: 0 | K29: 30 | L29: No | O29: One existing-issue (25206) has occured during user's Primary Role is set to (None) and saved, a success toast message is shown but not updating user's role when User Type = District Level
A30: 2.4 Sprint 3 (16-May-2025 to 29-May-2025) | B30: 24 | C30: 24 | D30: =IFERROR(C30/B30,0) -> 1 | E30: 23.75 | F30: 0.9 | G30: 0 | H30: 0 | I30: 2 | J30: 0 | K30: 30 | L30: Yes | O30: 1 defect got carried forward. Defect ID: 25162 This defect presents some challenges. Although the originally reported issue has been resolved, there is still room for improvement—specifically in displaying the browser URL correctly upon re-login. The team is actively working on enhancing this aspect. Also,Team found two more defects while doing the regression and successfully fixed the issues in the sprint itself. | AG30: =Config!$J$2 -> 1 | AH30: =Config!$J$3 -> 0.9 | AI30: =Config!$J$4 -> 0.8 | AK30: =Config!$J$7 -> 20 | AM30: =Config!$J$10 -> 0.9 | AO30: 30
A31: 2.5 Sprint 1 ( 30-May-2025 to 12-June-2025) | B31: 36 | C31: 36 | D31: =IFERROR(C31/B31,0) -> 1 | E31: 24.75 | F31: 0.9 | G31: 0 | H31: 0 | I31: 2 | J31: 0 | K31: 30 | L31: No | O31: Completed all the assigned stories. And team is working on the stretch stories and defects. Also, Completed dev and testing for all the defects for this sprint.
A32: 2.5 Sprint 2 ( 13-June-2025 to 26-Jun-2025) | B32: 11 | C32: 21 | D32: =IFERROR(C32/B32,0) -> 1.9090909 | E32: 24.75 | F32: 0.9 | G32: 0 | H32: 0 | I32: 2 | J32: 0 | K32: 30 | L32: No | O32: Completed all the assigned stories. And team is working on the stretch stories and defects. Also, Completed dev and testing for all the defects for this sprint.
A33: 2.5 KN Sprint 3 (27-June-2025 to 10-Jul-2025) | B33: 15 | C33: 28 | D33: =IFERROR(C33/B33,0) -> 1.8666667 | E33: 24.75 | F33: 0.9 | G33: 0 | H33: 0 | I33: 3 | J33: 0 | K33: 30 | L33: No | O33: Updated Footer for BOH Kaleida work, Completed Admin side District messages, Export changes to text qualifier, completed automation for admin settings.
A34: 2.5 KN Sprint 4 (11-Jul-2025 to 24-Jul-2025) | B34: 41 | C34: 41 | D34: =IFERROR(C34/B34,0) -> 1 | E34: 35 | F34: 1 | G34: 0 | H34: 0 | I34: 0 | J34: 0 | K34: 30 | L34: No | O34: Regression Sprint
A35: 2.5 KN Sprint 6 (8-Aug-2025 to 21-Aug-2025) | B35: 18 | C35: 21 | D35: =IFERROR(C35/B35,0) -> 1.1666667 | E35: 30 | F35: 1 | G35: 0 | H35: 0 | I35: 0 | J35: 0 | K35: 30 | L35: No | O35: FOH Dashboard UI & breadcrumb issue fixes
A36: 2.5 KN Sprint 7 (22-Aug-2025 to 04-Sep-2025) | B36: 19 | C36: 22 | D36: =IFERROR(C36/B36,0) -> 1.1578947 | E36: 30 | F36: 1 | G36: 1 | H36: 1 | I36: 0 | J36: 0 | K36: 30 | L36: No | O36: MSA Kaleida Breadcrumbs updates & BOH Breadcrumb issue fixes
A37: 2.5 KN Sprint 8 (05-Sep-2025 to 18-Sep-2025) | B37: 23 | C37: 28 | D37: =IFERROR(C37/B37,0) -> 1.2173913 | E37: 30 | F37: 1 | G37: 0 | H37: 0 | I37: 0 | J37: 0 | K37: 30 | L37: No | O37: Kaleida work progress has been excellent
A38: 2.5 KN Sprint 9 (19-Sep-2025 to 02-Oct-2025) | B38: 37 | C38: 36 | D38: =IFERROR(C38/B38,0) -> 0.97297297 | E38: 30 | F38: 1 | G38: 0 | H38: 0 | I38: 0 | J38: 0 | K38: 30 | L38: No | O38: Interim Release fixes
A39: 2.5 KN Sprint 10 (03-Oct-2025 to 16-Oct-2025) | B39: 21 | C39: 26 | D39: =IFERROR(C39/B39,D400) -> 1.2380952 | E39: 30 | F39: 1 | G39: 0 | H39: 0 | I39: 0 | J39: 0 | K39: 30 | L39: No | O39: Interim Release fixes
A40: 2.5 KN Sprint 11 (17-Oct-2025 to 30-Oct-2025) | B40: 18 | C40: 26 | D40: =IF((C40/B40)>1,1,(C40/B40)) -> 1 | E40: 30 | F40: 1 | G40: 0 | H40: 0 | I40: 0 | J40: 0 | K40: 30 | L40: Yes
...

Sheet RCA
H1: 3 Why Analysis
A2: Sl.No | B2: Issue/ Date | C2: Sprint Date (DD-MMM-YY to DD-MMM-YY) | D2: Issue Description | E2: Issue Type | F2: Root Cause category | G2: Sub category | H2: Why 1? | I2: Why 2? | J2: Why 3? | K2: Action ( Issue /Risk mitigation plan) | L2: Owner | M2: Status | N2: Target Date | O2: Comments | W2: Root Cause category
A3: 1 | B3: 45498 | C3: 2.1 Sprint 1(July-12 to July-25) | D3: 5 QA Defects | E3: Internal | F3: Metric Deviation | G3: 5 Internal Defects | H3: All the defects are carry forwarded from last regression that are minor design and logic issues | K3: Knowledge share with Team in Stand Up, So that similar type of Defect can be mitigated. | L3: Sarath | M3: Closed | N3: 45498 | W3: Not adhered to Policy
A4: 2 | B4: 45512 | C4: 2.1 Sprint 2(July-26 to Aug-8) | D4: 1 Internal CRC and 6 QA Defects | E4: Internal | F4: Metric Deviation | G4: Code Review Comment and Defects | H4: The team is concentrating on the Design and Logical issues that are carry fprwarded from last release that are minor | I4: 1 Internal CRC - Points --1. Code optimization 2. Remove unused and commented line 3. Condition and access modifier change. | K4: Knowledge share with Team in Stand Up, So that similar type of Defect can be mitigated. | L4: Sarath/Kiruthiga | M4: Closed | N4: 45512 | W4: Metric Deviation
A5: 3 | B5: 45526 | C5: 2.1 Sprint 3(Aug-9 to Aug-22) | D5: 6 QA Defects | E5: Internal | F5: Metric Deviation | G5: 6 Internal Defects | H5: All the defects are carry forwarded from last regression that are minor design and logic issues. All are design issues | I5: 1 Defect was worked by Client Dev and we tested it | K5: Knowledge share with Team in Stand Up, So that similar type of Defect can be mitigated. | L5: Kiruthiga | M5: Closed | N5: 45526
A6: 4 | B6: 45540 | C6: 2.1 Sprint 4(Aug-23 to Sep-5) | D6: 1 Internal CRC, 4 External CRC and 3 QA Defects | E6: Internal/External | F6: Metric Deviation | G6: Code Review Comment and Defects | H6: 1 Internal CRC - Unused code and storybook mock data update | I6: 4 External CRC - 1. Code optimzation 2. Different approach for conditions and return types | J6: 3 QA Defects - Internal Findings related to Design and Logical Issues | K6: Knowledge share with Team in Stand Up, So that similar type of Defect can be mitigated. | L6: Sarath/Ruban/Kiruthiga | M6: Closed | N6: 45540
A7: 5 | B7: 45554 | C7: 2.1 Sprint 5(Sep-6 to Sep-19) | D7: 3 QA Defects | E7: Internal | F7: Metric Deviation | G7: 3 Internal Defects | H7: 3 QA Defects - Internal Findings related to Design and Logical Issues | K7: Knowledge share with Team in Stand Up, So that similar type of Defect can be mitigated. | L7: Kiruthiga/Ruban | M7: Closed | N7: 45554
A8: 6 | B8: 45568 | C8: 2.1 Sprint 6(Sep-20 to Oct-3) | D8: 11 QA Defects | E8: Internal | F8: Metric Deviation | G8: 11 Internal Defects | H8: Regression Findings | K8: Knowledge share with Team in Stand Up, So that similar type of Defect can be mitigated. | L8: Sarath/Ruban/Kiruthiga | M8: Closed | N8: 45568
A9: 7 | B9: 45582 | C9: 2.2 Sprint 0(Oct-4 to Oct-17) | D9: 3 QA Defects | E9: Internal | F9: Metric Deviation | G9: 3 Internal Defects | H9: 3 QA Defects - All the defects are carry forwarded from last regression that are minor design and logic issues | K9: Knowledge share with Team in Stand Up, So that similar type of Defect can be mitigated. | L9: Kiruthiga & Sarath | M9: Closed | N9: 45582
A10: 8 | B10: 45596 | C10: 2.2 Sprint 1(Oct-18 to Oct-31) | D10: 2 QA Defects | E10: Internal | F10: Metric Deviation | G10: 2 Internal Defects | H10: 2 Internal Existing Design and Logical Issue | K10: Knowledge share with Team in Stand Up, So that similar type of Defect can be mitigated. | L10: Kiruthiga | M10: Closed | N10: 45596
A11: 9 | B11: 14/11/2024 | C11: 2.2 Sprint 2 (Nov-1 to Nov-14) | D11: 3 Defects Reported Internally | E11: Internal/External | F11: Metric Deviation | G11: 3 Defects Reported by Offshore QA and Customer | H11: One Defect was reported by the Client for missing parameters in a report | I11: 2 Other defects were internal findings concerning Stock Managament new changes | K11: Knowledge share with Team in Stand Up, So that similar type of Defect can be mitigated. | L11: Kiruthiga & Sarath | M11: Closed | N11: 45610 | O11: The Defects were closed and the Clients were well informed about the new changes
A12: 10 | B12: 45638 | C12: 2.2 Sprint 3 (Nov-15 to Dec-12) | D12: 5 Internal Defects reported | E12: Internal | F12: Metric Deviation | G12: 5 Defects were reported by Onshore and Offshore QA | H12: Production existing UI issue and Relevantz developed it. This is minor UI change and Functional Change that needs slight modification | K12: These Defects are UI change based on Project Unite. Knowledge share with Team in Stand Up, So that similar type of Defect can be mitigated. | L12: Dhivya, Ruban | M12: Closed | N12: 45638
A13: 11 | B13: 45666 | C13: 2.2 Sprint 4 (Dec-13 to Jan-09) | D13: 4 QA Defects, 2 Story Carry Forwarded | E13: Internal/External | F13: Metric Deviation | G13: 4 QA Defects | H13: Production existing UI issue and Relevantz developed it. This is minor UI change, logical and Functional Change that needs slight modification | I13: 2 Story Carry Forwarded Development is completed, Testing is in Progress. End - End Testing is required | K13: Defects were UI related that needs some font style changes, and other issues were logical and functional. Knowledge share with Team in Stand Up, So that similar type of Defect can be mitigated. | L13: Dhivya, Ruban | M13: Closed | N13: 45680 | O13: Client is informed
A14: 12 | B14: 45680 | C14: 2.2 Sprint 5 (10-Jan to 23-Jan) | D14: 13 Defects Reported, Two Regression Stories were carry forwarded | E14: Internal/External | F14: Metric Deviation | G14: 4 QA Defects, 9 Escaped Defects, 2 Stories were carry forwarded | H14: 4 QA Defects - were internal findings on Stock Management - We need to fix this issue due to last minute changes from PO | I14: 9 Escaped Defects - These were UI fixes, Existing Functionality Issues, Logical Issues.Customer didn't report this, the team took the initiative in fixing all the issues | J14: Will be carry forwarded to continue other reports. We have 13 reports with run reports and schedule reports with report inbox. Sentral had a new PR for CSV Format, so we will re running the tests We have completed Order Management, Menu Item, Menu Template, Menu Calendar, Settings Module. We have Stock Management Module inprogress for regression. | K14: All the defects were internal as well as external, the team took the initiative to fix the issues they found during testing. No defects were initiated by the customer. Knowledge share with Team in Stand Up, So that similar type of Defect can be mitigated. | L14: Ruban,Kiruthiga/Dhivya | M14: Closed | N14: 45680 | O14: Client is informed
A15: 13 | B15: 45694 | C15: 2.2 Sprint 6 (24-Jan to 6-Feb) | D15: 4 Defects | E15: Internal/External | F15: Metric Deviation | G15: 3 Internal Defects and 1 Production Issue | H15: 3 Internal Defects was One Bounceback for existing STock Management Functionality, the other 2 internal defects were found as a part of regression | I15: 1 Prioduction Issue was found after the release - Production Release (Jan 30th) was rolled back due to an issue with Parent Login, the issue was fixed and the release is postponed on Feb 06th. The issue was Sentral AUS had made change Household API to include new fields(Which is not applicable for US)). There was no proper null checks for enrollments for these fields. When a Parent has inactive enrollments for a student then causes to error and prevent Parent Login | K15: All the defects were fixed and the PRoduction issue were resolved. The team mitigated the issue in repro by finding some solution by having regular sync up call with Sentral and Ruban will review their PR | L15: Ruban,Kiruthiga/Dhivya | M15: Closed | N15: 45694
A16: 14 | B16: 45708 | C16: 2.3 Sprint 1 (07-Feb-2025 to 20-Feb-2025) | D16: 1 External Defect and 1 Internal Defect | E16: Internal/External | F16: Metric Deviation | G16: 1 External Defect and 1 Internal Defect | H16: 1 Bounceback - Related to Data Renention Issue. | I16: 1 External Defect it is an existing issue which was in backlog the team worked in this sprint | K16: All the defects were fixed and the team had a sync to mitigate this in future | L16: Kiruthiga/Ruban | M16: Closed | N16: 45708
A17: 15 | B17: 45722 | C17: 2.3 Sprint 2(21-Feb-2025 to 06-Mar-2025) | D17: 6 Defects | E17: Internal | F17: Metric Deviation | G17: 6 Internal Defects | H17: 6 Internal Defects which were minor existing issues. The Team committed to work the backlog defects which was minor and doesn't affect/break the functionalities. One Significant - but not a showstopper. | K17: All the defects were fixed. The Team came up with a mitigation plan where once the Dev Team starts working on the Story, the QA team will work on the Test case, once the Dev Team completes their unit testing they will work QA team and BA Team internally to see any deviation in AC and Test cases, this way the team is trying to mitigate the bounceback and defects | L17: Kiruthiga/Ruban/Dhivya | M17: Closed | N17: 45722
A18: 16 | B18: 45736 | C18: 2.3 Sprint 3 (07-Mar-2025 to 20-Mar-2025) | D18: 5 Defects and 1 Story Carry Forwarded | E18: Internal/External | F18: Metric Deviation | G18: 4 Internal Defects and 1 External Defect and 1 Story Carry Forwarded | H18: 2 Internal Defects which were Retaining issue in the Dropdown Value 2 Bouncebacks for Code Refactoring | I18: 1 External Defect it is an existing issue which was identified as a part of another feature. Not a showstopper | J18: 1 Story Carry forwared Due to the suggested changes in the Report Header story(46826) made a delay in starting the Student Product sales report work item | K18: All the issues are fixed. | L18: Kiruthiga/Ruban/Dhivya | M18: Closed | N18: 45750 | O18: Please note: The Team is supporting Onsite Client Dev Feature for Release
A19: 17 | B19: 45750 | C19: 2.3 Sprint 4 (21-Mar-2025 to 03-Apr-2025) | D19: 2 defects got rolled over | E19: Internal | F19: Metric Deviation | G19: 2 Internal Defects | H19: 24915 - Functional issue with respect to column order change - Reported Sentral & 24882 - Team is currently analysing this defect. | K19: Team is analyzing the defect and also related to column order change (Reported Sentral), and will implement necessary actions based on findings. | L19: Kiruthiga/Ruban/Dhivya | M19: Closed | N19: 45764
A20: 18 | B20: 45764 | C20: 2.4 Sprint 0 (04-Apr-2025 to 17-Apr-2025) | D20: 1 defect got rolled over | E20: External | F20: Metric Deviation | G20: 1 External Defects | H20: 24944 - Admin - Item/Grade restrictions radio button issue on first add | I20: Issue Occured first time , without there is no grade restriction table data. | L20: Kiruthiga/Ruban/Dhivya | M20: Closed | N20: 45778
A21: 19 | B21: 45778 | C21: 2.4 Sprint 1 (18-Apr-2025 to 01-May-2025) | D21: 2 defects have been reported | E21: Internal | F21: Metric Deviation | G21: 2 Internal Defects | H21: 24944 - Admin - Item/Grade restrictions radio button issue on first add 22944 - Menu Items - Unsplash Results not showing last page | I21: Issue Occured first time , without there is no grade restriction table data & Because of the API limitation this issue is occured | L21: Kiruthiga/Dhivya | M21: Closed | N21: 45792
A22: 20 | B22: 45792 | C22: 2.4 Sprint 2 (02-May-2025 to 15-May-2025) | D22: 1 defects has been reported | E22: Internal | F22: Metric Deviation | G22: 1 Internal Defects | H22: 25206 - When a user's Primary Role is set to (None) and saved, a success toast message is shown but the user's role is not actually updated. | I22: This issue only occurs for users whose User Type = District Level | L22: Ruban | M22: Closed | N22: 45813
A23: 21 | B23: 45792 | C23: 2.4 Sprint 2 (02-May-2025 to 15-May-2025) | D23: Committment Index Deviation | E23: Internal/External | F23: Metric Deviation | G23: Esitimation Devition | H23: 47562 - Meal Orders [v?]- Import Menu Items - Template Settings | I23: Story was under estimated, During planning story was assigned with 5 Story Points(20 hrs) But the actual effort needed for this story is 79 hours (nearly 20 Story Points) | K23: Communicated to client in the mid of sprint about the actual effort that was required for completing the story. Client has accepted the delay as the story needs additional efforts to complete. | L23: Ruban | M23: Closed | N23: 45807
A24: 22 | B24: 45806 | C24: 2.4 Sprint 3 (16-May-2025 to 29-May-2025) | D24: 1 defect got rolled over | E24: Internal/External | F24: Metric Deviation | G24: Defect | H24: Defect ID: 25162 This defect presents some challenges. Although the originally reported issue has been resolved, there is still room for improvement—specifically in displaying the browser URL correctly upon re-login. The team is actively working on it | I24: Fix deployed, with ongoing work to refine browser URL behavior post-login. | K24: 1.This defect will be prioritized early in the next sprint with better coordination to avoid future delays. 2. Implementing a fix to ensure consistent browser URL display post-login in the next sprint. | L24: Kiruthiga | M24: Closed | N24: 45820
A25: 23 | B25: 45904 | C25: 2.5 Kaleida Nutrition S7 (22-Aug-2025) to (04-Sep-2025) | D25: Received 1 Client Review Code comment | E25: Internal/External | F25: Metric Deviation | G25: Code Review Comment | H25: The client recommended adding conditional logic to a specific code block so that it only executes in the local environment. | I25: Addressed the feedback by implementing the condition in the code. | K25: Since its not required due to the oversight the developer missed. After the review comments we have fixed the review comments | L25: Ruben | M25: Closed | N25: 45926
A26: 24 | B26: 45973 | C26: 2.5 Sprint 12 (31-Oct-2025) to (13-Nov-2025) | D26: 1 Story carry forwarded in testing phase due to delay in POV from Client. | E26: External | F26: Metric Deviation | G26: 1 Story | H26: POV's at times could not be completed due to limitations in client availability which eventually delayed testing so 1 story carry forwarded. | K26: Although the development changes were completed on time and a recording of the changes was shared, the client expected a POV to test all scenarios. However, due to the client's unavailability, there was a delay in presenting the POV and receiving feedback, which resulted in a delay in testing. Will prioritize and close it in next sprint. | L26: Kiruthiga | M26: Inprogress

Sheet Config
A1: Sprint | B1: =_xlfn.XLOOKUP("Yes",Data!L1:L52,Data!A1:A52,0,0) -> 2.1 Sprint 6 (Sep-20-2024 to Oct-3-2024) | I1: Commitment Index | L1: Status | O1: Less Than | P1: Greater Than
A2: Metrics | B2: UnWeighted | C2: Weighted | I2: Goal | J2: 1 | L2: Ready | N2: Below Avg | O2: 5
A3: =Scorecard!A8 -> Commitment Index | B3: =VLOOKUP($B$1,Table_1[#All],4) -> 1 | C3: =B3*'QualityMetrics-Definition'!D2 -> 0.25 | I3: Risk | J3: 0.9 | L3: Committed | N3: Avg | O3: 10 | P3: 15
A4: =Scorecard!A9 -> Velocity | B4: =IF((VLOOKUP($B$1,Table_1[#Data],5)/Data!AK27)>1,"100%",(VLOOKUP($B$1,Table_1[#Data],5)/Data!AK27)) -> 100% | C4: =B4*'QualityMetrics-Definition'!D3 -> 0.2 | I4: Issue | J4: 0.8 | L4: Done | N4: Good | O4: 15 | P4: 20
A5: =Scorecard!A10 -> Defect-free Rate | B5: =1-IFERROR((VLOOKUP($B$1,Table_1[],9)+VLOOKUP($B$1,Table_1[],10))/VLOOKUP($B$1,Table_1[],5),0) -> 0.59259259 | C5: =(B5)*'QualityMetrics-Definition'!D4 -> 0.11851852 | L5: CF | N5: Excellent | P5: 25
A6: =Scorecard!A11 -> Code Quality Index | B6: =1-(VLOOKUP($B$1,Table_1[],7)+VLOOKUP($B$1,Table_1[],8))/VLOOKUP($B$1,Table_1[],3) -> 1 | C6: =(B6)*'QualityMetrics-Definition'!D5 -> 0.15 | I6: Velocity
A7: =Scorecard!A12 -> Unit Testing & Code Coverage | B7: =VLOOKUP($B$1,Table_1[],6) -> 1 | C7: =B7*'QualityMetrics-Definition'!D6 -> 0.1 | I7: Goal | J7: 20
A8: =Scorecard!A13 -> Backlog Health | B8: =IF((VLOOKUP($B$1,Table_1[#All],11)/Data!K2)>1,"100%",(VLOOKUP($B$1,Table_1[#All],11)/Data!K2)) -> 1 | C8: =B8*'QualityMetrics-Definition'!D7 -> 0.1
I9: Code Coverage
I10: Goal | J10: 0.9
I21: Backlog Health - Categories | L21: Story Point Labels | O21: Backlog Health - Achieved
I22: Below Avg | J22: 15 | L22: Labels | M22: Values | O22: Story Points | P22: =VLOOKUP(Scorecard!B5,Table_1[#All],11) -> 30
I23: Avg | J23: 20 | L23: 5 | M23: 10 | O23: Thickness | P23: 1
I24: Good | J24: 25 | L24: 10 | M24: 10 | O24: Indicator | P24: 30
I25: Excellent | J25: 30 | L25: 15 | M25: 10
I26: Total | J26: =SUM(J22:J25) -> 90 | L26: 20 | M26: 10
L27: 25 | M27: 10
M28: =SUM(M23:M27) -> 50

Sheet Instructions
A1: Instructions
A2: 1. Define the metrics that are required for the project in the "QualityMetrics-Defintion" sheet 2. For the defined metrics, update the Data in the "Data" sheet. 3. Update the Goals in the "Data" sheet from Column AC to AL - Add/Delete the required goals as necessary - This is used in the Scorecard metrics calculation 4. Update the Project details in the "Scorecard" sheet 5. As per the goals defined, update the formulae required to calculate the metrics 6. As per the goals defined, update the "Conditional Formatting" rules to reflect the correct color coding as per the defined goals 7. To update the Dashboard charts, Open the document in desktop version and select the required sprints (cycles) to display the data
